File: LT data/Frome/L5/248-FC-ZFC-RTSIRM-contsweepwithloop-MsT-AC.dat
[Header]
; MPMS3 Data File (default extension .dat)
; Copyright (c) 2007, Quantum Design, Inc. All rights reserved.
TITLE,
FILEOPENTIME,3866209684.47066,07/05/2022,8:05 pm
BYAPP,MPMS3 w/ AC,1.0,1.1
INFO,MPMS3 Measurement Release 1.1.16 Build 424, MultiVu Release 2.3.4.19,APPNAME
INFO,Linear Motor Servo Controller,MOTOR_MODULE_NAME
INFO,3101-100 N2,MOTOR_HW_VERSION
INFO,,MOTOR_SERIAL_NUMBER
INFO,01.04.28,MOTOR_SOFTWARE_VERSION
INFO,Quantum Design Squid Module,SQUID_MODULE_NAME
INFO,3101-501 B0,SQUID_HW_VERSION
INFO,SQM327,SQUID_SERIAL_NUMBER
INFO,01.03.04,SQUID_SOFTWARE_VERSION
INFO,Quantum Design VSM Oven,OVEN_MODULE_NAME
INFO,3101-201 A3,OVEN_HW_VERSION
INFO,OVB365,OVEN_SERIAL_NUMBER
INFO,01.07.07,OVEN_SOFTWARE_VERSION
INFO,SQUID AC,AC_MODULE_NAME
INFO,3101-401 G0,AC_HW_VERSION
INFO,SAC220,AC_SERIAL_NUMBER
INFO,SQUID AC 00.95.07,AC_SOFTWARE_VERSION
INFO,TCI344,COIL_SERIAL_NUMBER
INFO,0,MOMENT_UNITS
INFO,lmst,SAMPLE_MATERIAL
INFO,,SAMPLE_COMMENT
INFO,122.4,SAMPLE_MASS
INFO,,SAMPLE_VOLUME
INFO,,SAMPLE_MOLECULAR_WEIGHT
INFO,,SAMPLE_SIZE
INFO,,SAMPLE_SHAPE
INFO,Straw,SAMPLE_HOLDER
INFO,Standard,SAMPLE_HOLDER_DETAIL
INFO,61.89,SAMPLE_OFFSET
DATATYPE,COMMENT,1
DATATYPE,TIME,2
STARTUPAXIS,X,2
STARTUPAXIS,Y1,5
FIELDGROUP, VSM,2,3,4,5,6,8,9,10,11,14,15
FIELDGROUP, DC, 2,3,4,14,56,57,58,59,60,61,62,63,64,65,66,67,68,69
FIELDGROUP, AC, 2,3,4,11,16,17,18,19,20,21,22,23,24,25,26,27,28,29,30
STARTUPGROUP, All
[Data]
Comment,Time Stamp (sec),Temperature (K),Magnetic Field (Oe),Moment (emu),M. Std. Err. (emu),Transport Action,Averaging Time (sec),Frequency (Hz),Peak Amplitude (mm),Center Position (mm),Lockin Signal' (V),Lockin Signal (V),Range,M. Quad. Signal (emu),AC Moment (emu),AC M. Std Err. (emu),AC Phase (deg),AC Phase Std. Err. (deg),AC Susceptibility (emu/Oe),AC Suscept. Std Err. (emu/Oe),AC X' (emu/Oe),AC X' Std Err. (emu/Oe),AC X'' (emu/Oe),AC X'' Std Err. (emu/Oe),AC Drive (Oe),AC Frequency (Hz),AC Averaging Time (sec),AC Cycles,AC Range,AC Measure Type,AC Signal' (V),AC Signal'' (V),AC Trim Coil Ratio,AC Trim Coil Phase,Min. Temperature (K),Max. Temperature (K),Min. Field (Oe),Max. Field (Oe),Mass (grams),Motor Lag (deg),Pressure (Torr),Measure Count,Measurement Number,SQUID Status (code),Motor Status (code),Measure Status (code),Motor Current (amps),Motor Temp. (C),Temp. Status (code),Field Status (code),Chamber Status (code),Chamber Temp (K),Redirection State,Average Temp (K),Rotation Angle (deg),Rotator state,DC Moment Fixed Ctr (emu),DC Moment Err Fixed Ctr (emu),DC Moment Free Ctr (emu),DC Moment Err Free Ctr (emu),DC Fixed Fit,DC Free Fit,DC Calculated Center (mm),DC Calculated Center Err (mm),DC Scan Length (mm),DC Scan Time (s),DC Number of Points,DC Squid Drift,DC Min V (V),DC Max V (V),DC Scans per Measure,Map 01,Map 02,Map 03,Map 04,Map 05,Map 06,Map 07,Map 08,Map 09,Map 10,Map 11,Map 12,Map 13,Map 14,Map 15,Map 16
,3866210665.82854,100.001319885254,49999.75,0.0368450118922442,9.69816820563968E-6,1,2,12.9061126708984,4.97618905196956,40.7800003886223,47.7931737981241,6.98299861487972,100,-2.89377399173655E-5,,,,,,,,,,,,,,,,,,,,,100.001319885254,100.001319885254,49999.75,49999.75,49.9824081049957,5.38049458086968,7.13870286941528,26,1,0,0,1,0.28717041015625,30.3030319213867,1,1,1,100.001327514648,0,100.001319885254,,,,,,,,,,,,,,,,,,,,,,,,,,,,,,,,,
,3866210746.23744,89.9293251037598,49999.75,0.0408281598966661,1.44678749979243E-5,1,2,12.9061126708984,4.97577549650464,40.7500006258488,52.9529448716238,7.74203409627575,100,-2.81798174963532E-5,,,,,,,,,,,,,,,,,,,,,89.8321990966797,90.0264511108398,49999.75,49999.75,50.0128916172457,5.38187238126652,7.08019733428955,26,1,0,0,1,0.288619995117188,31.2805480957031,2,1,1,89.8321990966797,0,89.9293251037598,,,,,,,,,,,,,,,,,,,,,,,,,,,,,,,,,
,3866210862.82319,70.7734832763672,49999.75,0.052492161304152,2.48072283397265E-5,1,2,12.9061126708984,4.97549705613958,40.6999997794628,68.0700184061879,9.990055348751,100,-7.68148477309351E-6,,,,,,,,,,,,,,,,,,,,,70.5879516601562,70.9590148925781,49999.75,49999.75,49.9765458911014,5.38366601893144,6.99960947036743,26,1,0,0,1,0.289382934570313,31.7693061828613,2,1,1,70.5879516601562,0,70.7734832763672,,,,,,,,,,,,,,,,,,,,,,,,,,,,,,,,,
,3866210984.06329,50.1973094940186,49999.75,0.0741328353503165,3.2458025442383E-5,1,2,12.9061126708984,4.97534146898659,40.6400002539158,96.1321810401032,14.0840528559738,100,-2.93035055636908E-5,,,,,,,,,,,,,,,,,,,,,50.1089935302734,50.2856254577637,49999.75,49999.75,49.9898335759284,5.38431851857586,6.83079957962036,24,1,64,0,0,0.279464721679687,31.2805480957031,2,1,1,50.1089935302734,0,50.1973094940186,,,,,,,,,,,,,,,,,,,,,,,,,,,,,,,,,
,3866211120.69665,27.0235509872437,49999.75,0.127922617520064,0.000106016686784894,1,2,12.9061126708984,4.9753702395804,40.6000018119812,165.89253264035,24.2572167612508,1000,-8.62195871614317E-5,,,,,,,,,,,,,,,,,,,,,26.8430099487305,27.2040920257568,49999.75,49999.75,50.1246644954957,5.384673723634,6.38804388046265,26,1,0,0,1,0.278701782226562,31.7693061828613,2,1,1,26.8430099487305,0,27.0235509872437,,,,,,,,,,,,,,,,,,,,,,,,,,,,,,,,,
,3866211189.70497,15.6709952354431,49999.75,0.184263248985645,0.000133066674486623,1,2,12.9061126708984,4.97542214811674,40.5699983239174,238.959739198333,34.9407692770928,1000,-0.00012458208706233,,,,,,,,,,,,,,,,,,,,,15.5352506637573,15.8067398071289,49999.75,49999.75,50.198528390563,5.38533956327932,5.72362375259399,25,1,64,0,0,0.26763916015625,31.7693061828613,2,1,1,15.5352506637573,0,15.6709952354431,,,,,,,,,,,,,,,,,,,,,,,,,,,,,,,,,
,3866211261.76489,5.17136287689209,49999.75,0.285371382514978,0.000198399767191908,1,2,12.9061126708984,4.97552062375689,40.5699983239174,370.08234018496,54.1737840390047,1000,-0.00014747481947743,,,,,,,,,,,,,,,,,,,,,4.957688331604,5.38503742218018,49999.75,49999.75,50.6120098772361,5.38748087187168,4.00469875335693,26,1,0,0,1,0.289688110351562,31.2805480957031,6,1,1,4.957688331604,0,5.17136287689209,,,,,,,,,,,,,,,,,,,,,,,,,,,,,,,,,
,3866211330.37032,2.2550128698349,49999.75,0.312889060786768,3.37909908951847E-5,1,2,12.9061126708984,4.97570323142316,40.5699983239174,405.781028210866,59.4580196707037,1000,-0.000117494882861419,,,,,,,,,,,,,,,,,,,,,2.25334930419922,2.25667643547058,49999.75,49999.75,50.9821109810919,5.38895815470003,2.64204907417297,26,1,0,0,1,0.277786254882813,31.2805480957031,6,1,1,2.25334930419922,0,2.2550128698349,,,,,,,,,,,,,,,,,,,,,,,,,,,,,,,,,
,3866211399.98385,2.11700820922852,49999.75,0.313639398280964,5.02066369206428E-5,1,2,12.9061126708984,4.97574034697533,40.5699983239174,406.762058845902,59.576318366147,1000,-0.000136987262523236,,,,,,,,,,,,,,,,,,,,,2.11194038391113,2.1220760345459,49999.75,49999.75,50.9461560692073,5.38846076845888,2.54389548301697,26,1,0,0,1,0.278549194335938,31.7693061828613,2,1,1,2.11194038391113,0,2.11700820922852,,,,,,,,,,,,,,,,,,,,,,,,,,,,,,,,,
,3866211469.19362,2.1787269115448,49999.75,0.313368319715554,2.91771286568787E-5,1,2,12.9061126708984,4.97565515197789,40.5699983239174,406.406981521226,59.480652623067,1000,-0.000169826855490146,,,,,,,,,,,,,,,,,,,,,2.17790198326111,2.17955183982849,49999.75,49999.75,50.9864099379477,5.38788320097771,2.58089780807495,26,1,0,0,1,0.287628173828125,31.2805480957031,2,1,1,2.17955183982849,0,2.1787269115448,,,,,,,,,,,,,,,,,,,,,,,,,,,,,,,,,
,3866211539.9505,1.9998796582222,49999.75,0.314355501677844,4.28866116879688E-5,1,2,12.9061126708984,4.9756490715369,40.5699983239174,407.684683338796,59.6806712643475,1000,-0.000160534861383583,,,,,,,,,,,,,,,,,,,,,1.99985826015472,1.99990105628967,49999.75,49999.75,50.9356040841977,5.38877810693041,2.46898365020752,26,1,0,0,1,0.288009643554687,30.7917900085449,5,1,1,1.99985826015472,0,1.9998796582222,,,,,,,,,,,,,,,,,,,,,,,,,,,,,,,,,
,3866211952.19276,9.45254516601562,26.2244052886963,0.000182367471674315,4.77850574669794E-7,1,5,12.9061126708984,5.00609913543864,40.5699983239174,0.238548634261025,0.0348887850919384,10,-1.17216894964385E-7,,,,,,,,,,,,,,,,,,,,,9.45254516601562,9.45254516601562,26.2244052886963,26.2244052886963,50.1184114673418,5.38466118028503,4.59533929824829,65,1,0,0,1,0.268173217773438,31.7693061828613,6,1,1,9.45254516601562,0,9.45254516601562,,,,,,,,,,,,,,,,,,,,,,,,,,,,,,,,,
,3866212149.76214,40.0003395080566,26.2244052886963,3.49476132752636E-5,1.42011776224058E-8,1,5,12.9061126708984,5.00602073602833,40.5800007283688,0.0457154493767261,0.00666747343938269,1,-3.63933969051562E-8,,,,,,,,,,,,,,,,,,,,,40.0003395080566,40.0003395080566,26.2244052886963,26.2244052886963,50.1344348519861,5.38485368112228,6.24204111099243,65,1,0,0,1,0.268173217773438,30.7917900085449,2,1,1,40.0003395080566,0,40.0003395080566,,,,,,,,,,,,,,,,,,,,,,,,,,,,,,,,,
,3866212351.74637,72.0262298583984,26.2244052886963,2.67823973982585E-5,8.12108440233998E-9,1,5,12.9061126708984,5.0058730145265,40.6199991703033,0.0350340904315195,0.00510185609109314,1,-3.37070035819811E-8,,,,,,,,,,,,,,,,,,,,,72.0262298583984,72.0262298583984,26.2244052886963,26.2244052886963,50.0523638574668,5.38511961086915,6.63880729675293,63,1,64,0,0,0.278854370117187,31.2805480957031,2,1,1,72.0262298583984,0,72.0262298583984,,,,,,,,,,,,,,,,,,,,,,,,,,,,,,,,,
,3866212547.93438,104.009735107422,26.2244052886963,2.05484169802038E-5,9.93224911479528E-9,1,5,12.9061126708984,5.00590857043168,40.6799986958504,0.0268791319614503,0.00391809160411178,1,-2.30126910428541E-8,,,,,,,,,,,,,,,,,,,,,104.009735107422,104.009735107422,26.2244052886963,26.2244052886963,50.0738586417457,5.38559860269363,6.81040477752686,64,1,64,0,0,0.278091430664062,31.2805480957031,2,1,1,104.009735107422,0,104.009735107422,,,,,,,,,,,,,,,,,,,,,,,,,,,,,,,,,
,3866212741.82656,136.034866333008,26.2244052886963,1.56327807792133E-5,7.23857895924019E-9,1,5,12.9061126708984,5.00585954115337,40.7599993050098,0.0204476343408139,0.00298847584957434,1,-1.16052594609875E-8,,,,,,,,,,,,,,,,,,,,,136.034866333008,136.034866333008,26.2244052886963,26.2244052886963,50.1977467620438,5.38580979866716,6.91964101791382,65,1,0,0,1,0.268707275390625,31.7693061828613,2,1,1,136.034866333008,0,136.034866333008,,,,,,,,,,,,,,,,,,,,,,,,,,,,,,,,,
,3866212935.80001,168.201675415039,26.2244052886963,1.35869068924697E-5,7.2464605762388E-9,1,5,12.9061126708984,5.00569164214788,40.8600009977818,0.0177721184716042,0.00258829548148127,1,-1.69334110758162E-8,,,,,,,,,,,,,,,,,,,,,168.201675415039,168.201675415039,26.2244052886963,26.2244052886963,50.1309175236495,5.38635897035591,7.00987577438354,63,1,64,0,0,0.269088745117187,31.2805480957031,2,1,1,168.201675415039,0,168.201675415039,,,,,,,,,,,,,,,,,,,,,,,,,,,,,,,,,
,3866213128.19777,200.03596496582,26.2244052886963,1.16209049179402E-5,6.96816097883952E-9,1,5,12.9061126708984,5.00482744694972,40.9899987280369,0.0151985615058133,0.00220160139414553,1,-2.33838652655744E-8,,,,,,,,,,,,,,,,,,,,,200.03596496582,200.03596496582,26.2244052886963,26.2244052886963,50.1598377788611,5.38976879167529,7.06502437591553,63,1,64,0,0,0.268325805664062,31.7693061828613,2,1,1,200.03596496582,0,200.03596496582,,,,,,,,,,,,,,,,,,,,,,,,,,,,,,,,,
,3866213321.08997,232.089553833008,26.2244052886963,1.00077938087735E-5,6.62994222928732E-9,1,5,12.9061126708984,5.00465184449376,41.1400012671947,0.0130875495018141,0.00190025549819148,1,-1.68076816084637E-8,,,,,,,,,,,,,,,,,,,,,232.089553833008,232.089553833008,26.2244052886963,26.2244052886963,50.0984799401015,5.39101023658399,7.17992734909058,63,1,64,0,0,0.267333984375,32.2580642700195,2,1,1,232.089553833008,0,232.089553833008,,,,,,,,,,,,,,,,,,,,,,,,,,,,,,,,,
,3866213515.29867,264.289215087891,26.2244052886963,8.58368681220791E-6,8.04217272444458E-9,1,5,12.9061126708984,5.00380148534596,41.3100011646748,0.0112219163863049,0.00163360279651076,1,-1.12480143201998E-8,,,,,,,,,,,,,,,,,,,,,264.289215087891,264.289215087891,26.2244052886963,26.2244052886963,50.1574928933034,5.39441211981957,7.35286903381348,64,1,64,0,0,0.26763916015625,31.2805480957031,2,1,1,264.289215087891,0,264.289215087891,,,,,,,,,,,,,,,,,,,,,,,,,,,,,,,,,
,3866213707.18885,296.071990966797,26.2244052886963,7.43700287804202E-6,6.79482042427398E-9,1,5,12.9061126708984,5.00411288001655,41.4899997413158,0.00972530609313817,0.00140416463509209,1,-1.84130576118622E-8,,,,,,,,,,,,,,,,,,,,,296.071990966797,296.071990966797,26.2244052886963,26.2244052886963,50.0726861989668,5.39331728749489,7.25625419616699,64,1,64,0,0,0.269393920898438,31.7693061828613,2,1,1,296.071990966797,0,296.071990966797,,,,,,,,,,,,,,,,,,,,,,,,,,,,,,,,,
,3866215318.30298,2.00005149841309,41380.990234375,0.297137679938595,4.29375773865622E-5,1,2,12.9061126708984,4.98611281609695,40.5699983239174,386.477984732402,56.6930115012947,1000,-6.38497340681671E-5,,,,,,,,,,,,,,,,,,,,,2.0000364780426,2.00006651878357,41286.203125,41475.77734375,50.8038996787073,5.38919107768098,2.52333331108093,24,1,68,0,0,0.268096923828125,31.2805480957031,1,6,1,2.00006651878357,0,2.00005149841309,,,,,,,,,,,,,,,,,,,,,,,,,,,,,,,,,
,3866215389.10483,1.99981993436813,34312.27734375,0.279752197719174,3.66343069944106E-5,1,2,12.9061126708984,4.98611832920383,40.5699983239174,363.873624323666,53.322595083228,1000,-0.000101170504145738,,,,,,,,,,,,,,,,,,,,,1.99973320960999,1.99990665912628,34247.41796875,34377.13671875,50.6104466201977,5.38846239816646,2.51968836784363,26,1,0,0,1,0.270767211914062,30.7917900085449,1,6,1,1.99990665912628,0,1.99981993436813,,,,,,,,,,,,,,,,,,,,,,,,,,,,,,,,,
,3866215457.28963,1.99993586540222,27503.6162109375,0.257752710645591,4.71062774895594E-5,1,2,12.9061126708984,4.98605614134523,40.5699983239174,335.264413829255,49.0509586750212,1000,-0.000152825140427448,,,,,,,,,,,,,,,,,,,,,1.99993097782135,1.99994075298309,27408.71484375,27598.517578125,50.4466954454188,5.38782979545566,2.5121648311615,26,1,0,0,1,0.27862548828125,31.2805480957031,1,6,1,1.99993097782135,0,1.99993586540222,,,,,,,,,,,,,,,,,,,,,,,,,,,,,,,,,
,3866215525.79257,2.00004559755325,20664.919921875,0.227665922021214,6.6897504228851E-5,1,2,12.9061126708984,4.98600413520065,40.5699983239174,296.114872153921,43.3974344928748,1000,-7.908969663355E-5,,,,,,,,,,,,,,,,,,,,,1.99991405010223,2.00017714500427,20569.92578125,20759.9140625,50.3544632801496,5.38697871969925,2.51842927932739,26,1,0,0,1,0.270538330078125,32.2580642700195,1,6,1,1.99991405010223,0,2.00004559755325,,,,,,,,,,,,,,,,,,,,,,,,,,,,,,,,,
,3866215597.69391,1.99995827674866,13487.1040039062,0.18103767593626,9.22694764258087E-5,1,2,12.9061126708984,4.98588376539281,40.5699983239174,235.465797965185,34.4659618927193,1000,-9.52440779181207E-5,,,,,,,,,,,,,,,,,,,,,1.99993598461151,1.9999805688858,13332.4267578125,13641.78125,50.2403455163418,5.3867266342335,2.51738572120666,26,1,0,0,1,0.278701782226562,31.2805480957031,1,6,1,1.99993598461151,0,1.99995827674866,,,,,,,,,,,,,,,,,,,,,,,,,,,,,,,,,
,3866215666.82257,2.00004422664642,6577.2490234375,0.112406645395445,0.0001363143308404,1,2,12.9061126708984,4.98586926814061,40.5699983239174,146.201568737282,21.3931331172671,1000,-6.43368627070959E-5,,,,,,,,,,,,,,,,,,,,,1.99987721443176,2.00021123886108,6487.34375,6667.154296875,50.1270093810534,5.38647746608216,2.51166009902954,26,1,0,0,1,0.269775390625,32.2580642700195,1,6,1,1.99987721443176,0,2.00004422664642,,,,,,,,,,,,,,,,,,,,,,,,,,,,,,,,,
,3866215741.33628,1.99987649917603,-868.182006835938,-0.0173785051912267,0.000232294769216234,1,2,12.9061126708984,4.98585281230617,40.5699983239174,-22.601628018343,-3.31833170467504,100,1.57683168291217E-6,,,,,,,,,,,,,,,,,,,,,1.99986469745636,1.99988830089569,-957.968017578125,-778.39599609375,50.0758127130438,5.38575604649475,2.50839614868164,26,1,0,0,1,0.278854370117187,32.2580642700195,1,6,1,1.99986469745636,0,1.99987649917603,,,,,,,,,,,,,,,,,,,,,,,,,,,,,,,,,
,3866215830.34186,1.9999104142189,-9766.1904296875,-0.146631374620652,0.000112895540578286,1,2,12.9061126708984,4.98588893463464,40.5699983239174,-190.688826523957,-28.0985329123804,100,-6.34162747359331E-5,,,,,,,,,,,,,,,,,,,,,1.99985194206238,1.99996888637543,-9886.3125,-9646.068359375,50.1961835050053,5.38636431001586,2.49290013313293,26,1,0,0,1,0.271987915039062,31.2805480957031,1,6,1,1.99996888637543,0,1.9999104142189,,,,,,,,,,,,,,,,,,,,,,,,,,,,,,,,,
,3866215912.61969,2.00008976459503,-17991.5341796875,-0.212193772504708,7.27258623521848E-5,1,2,12.9061126708984,4.98588686449294,40.5699983239174,-276.005504831971,-40.2856182820037,1000,0.000197659293142422,,,,,,,,,,,,,,,,,,,,,2.00008320808411,2.00009632110596,-18086.640625,-17896.427734375,50.3286695390149,5.38722103750183,2.48453855514526,26,1,0,0,1,0.268478393554687,31.2805480957031,1,6,1,2.00008320808411,0,2.00008976459503,,,,,,,,,,,,,,,,,,,,,,,,,,,,,,,,,
,3866215981.20509,1.99996954202652,-24857.2705078125,-0.246971650123516,5.27980934601339E-5,1,2,12.9061126708984,4.98597089187469,40.5699983239174,-321.219430518893,-47.0942522611856,1000,7.25550651853012E-5,,,,,,,,,,,,,,,,,,,,,1.99988996982574,2.0000491142273,-24937.177734375,-24777.36328125,50.4763973291496,5.3871299794578,2.47348856925964,26,1,0,0,1,0.270538330078125,31.7693061828613,1,6,1,1.99988996982574,0,1.99996954202652,,,,,,,,,,,,,,,,,,,,,,,,,,,,,,,,,
,3866216047.73976,1.99999707937241,-31523.0146484375,-0.271209040220293,4.94484823592898E-5,1,2,12.9061126708984,4.98588869990744,40.5699983239174,-352.719054689881,-51.8247649297039,1000,-4.87186736828697E-6,,,,,,,,,,,,,,,,,,,,,1.9999715089798,2.00002264976501,-31598.115234375,-31447.9140625,50.5604223949669,5.38826169963555,2.45154237747192,26,1,0,0,1,0.27069091796875,32.2580642700195,1,6,1,1.9999715089798,0,1.99999707937241,,,,,,,,,,,,,,,,,,,,,,,,,,,,,,,,,
,3866216118.08936,1.99970501661301,-38565.708984375,-0.290608443368944,4.59804378491956E-5,1,2,12.9061126708984,4.98587054631188,40.5699983239174,-377.954367925147,-55.4805203547432,1000,3.3957029684377E-5,,,,,,,,,,,,,,,,,,,,,1.99950551986694,1.99990451335907,-38660.890625,-38470.52734375,50.6549994457938,5.38908426665831,2.44824361801147,26,1,0,0,1,0.269927978515625,31.7693061828613,1,6,1,1.99990451335907,0,1.99970501661301,,,,,,,,,,,,,,,,,,,,,,,,,,,,,,,,,
,3866216186.72558,1.99929797649384,-45442.8828125,-0.305381486308017,5.83116525819368E-5,1,2,12.9061126708984,4.98590665591289,40.5699983239174,-397.164149739338,-58.3526446166506,1000,-3.67395912072905E-6,,,,,,,,,,,,,,,,,,,,,1.99912571907043,1.99947023391724,-45553.14453125,-45332.62109375,50.7698988381208,5.39015725930569,2.42106747627258,26,1,0,0,1,0.2691650390625,31.2805480957031,1,6,1,1.99912571907043,0,1.99929797649384,,,,,,,,,,,,,,,,,,,,,,,,,,,,,,,,,
,3866216257.06459,2.00001090764999,-48200.212890625,-0.310629446023346,4.42072554785831E-5,1,2,12.9061126708984,4.98590141562244,40.5699983239174,-403.995129124608,-59.3122063167972,1000,2.94310298210289E-5,,,,,,,,,,,,,,,,,,,,,1.99986112117767,2.00016069412231,-48295.1640625,-48105.26171875,50.8683840315438,5.38981068918607,2.41110754013062,26,1,0,0,1,0.271377563476562,32.2580642700195,1,6,1,1.99986112117767,0,2.00001090764999,,,,,,,,,,,,,,,,,,,,,,,,,,,,,,,,,
,3866216325.55334,1.97846263647079,-41363.578125,-0.297285411450203,4.22637577179136E-5,1,2,12.9061126708984,4.98588644032437,40.5699983239174,-386.638576930434,-56.7645693223816,1000,2.7752255008198E-5,,,,,,,,,,,,,,,,,,,,,1.96455669403076,1.99236857891083,-41458.265625,-41268.890625,50.6499188604188,5.38973679837401,2.38338851928711,26,1,0,0,1,0.27191162109375,31.2805480957031,1,6,1,1.96455669403076,0,1.97846263647079,,,,,,,,,,,,,,,,,,,,,,,,,,,,,,,,,
,3866216396.20277,2.00040853023529,-34311.29296875,-0.279822890039755,4.90720427908897E-5,1,2,12.9061126708984,4.98584222115544,40.5699983239174,-363.94610207838,-53.2717924374995,1000,0.000147430430872248,,,,,,,,,,,,,,,,,,,,,1.99976229667664,2.00105476379395,-34391.11328125,-34231.47265625,50.6045844063034,5.3887843896196,2.39628052711487,26,1,0,0,1,0.272216796875,31.2805480957031,5,6,1,1.99976229667664,0,2.00040853023529,,,,,,,,,,,,,,,,,,,,,,,,,,,,,,,,,
,3866216464.56846,2.00007271766663,-27489.650390625,-0.257806770918365,4.65232676802262E-5,1,2,12.9061126708984,4.98578598327773,40.5699983239174,-335.286950725124,-49.2090543122791,1000,3.63326830627735E-5,,,,,,,,,,,,,,,,,,,,,1.99996781349182,2.00017762184143,-27584.462890625,-27394.837890625,50.4052691338996,5.38858494246641,2.3977575302124,26,1,0,0,1,0.269775390625,31.2805480957031,1,6,1,2.00017762184143,0,2.00007271766663,,,,,,,,,,,,,,,,,,,,,,,,,,,,,,,,,
,3866216535.13329,2.00000083446503,-20451.6396484375,-0.22674489653368,6.63202668280746E-5,1,2,12.9061126708984,4.9857557495567,40.5699983239174,-294.892101327871,-43.2474387498132,1000,5.67834471177916E-5,,,,,,,,,,,,,,,,,,,,,1.99971795082092,2.00028371810913,-20546.3828125,-20356.896484375,50.2966227697265,5.38787741640062,2.39047193527222,26,1,0,0,1,0.2703857421875,31.7693061828613,1,6,1,1.99971795082092,0,2.00000083446503,,,,,,,,,,,,,,,,,,,,,,,,,,,,,,,,,
,3866216605.92368,1.99995267391205,-13379.6997070312,-0.181227873084022,9.43916439452449E-5,1,2,12.9061126708984,4.98574484626287,40.5699983239174,-235.708512643012,-34.4697857174592,1000,0.000119208760534483,,,,,,,,,,,,,,,,,,,,,1.99960732460022,2.00029802322388,-13439.7578125,-13319.6416015625,50.1684356925726,5.38713242174536,2.39977097511291,26,1,0,0,1,0.269851684570313,31.7693061828613,1,6,1,2.00029802322388,0,1.99995267391205,,,,,,,,,,,,,,,,,,,,,,,,,,,,,,,,,
,3866216674.08257,2.00006192922592,-6570.28540039063,-0.112551748615994,0.000134223682213826,1,2,12.9061126708984,4.98571105755474,40.5699983239174,-146.381450805622,-21.4356013914955,1000,5.22651873641704E-5,,,,,,,,,,,,,,,,,,,,,1.99992048740387,2.00020337104797,-6665.19873046875,-6475.3720703125,50.2176782892842,5.38669190041284,2.40092492103577,26,1,0,0,1,0.27679443359375,31.7693061828613,1,6,1,1.99992048740387,0,2.00006192922592,,,,,,,,,,,,,,,,,,,,,,,,,,,,,,,,,
,3866216763.06926,1.99993908405304,2323.64282226562,0.0455641940534955,0.000202925461482458,1,2,12.9061126708984,4.98571189968692,40.5699983239174,59.253760903496,8.71645798086034,100,8.60454042400482E-6,,,,,,,,,,,,,,,,,,,,,1.99988317489624,1.99999499320984,2208.56640625,2438.71923828125,50.1660908070149,5.38679453408712,2.39815139770508,25,1,68,0,0,0.272445678710938,31.2805480957031,1,6,1,1.99999499320984,0,1.99993908405304,,,,,,,,,,,,,,,,,,,,,,,,,,,,,,,,,
,3866216839.46495,2.00006914138794,9963.67578125,0.149199591560125,0.000114563000066224,1,2,12.9061126708984,4.98569696578414,40.5699983239174,194.01884331606,28.5848029935292,100,6.12023480900494E-5,,,,,,,,,,,,,,,,,,,,,1.99978494644165,2.00035333633423,9888.70703125,10038.64453125,50.157883707563,5.38771786812378,2.38706517219543,26,1,0,0,1,0.269851684570313,31.7693061828613,1,6,1,1.99978494644165,0,2.00006914138794,,,,,,,,,,,,,,,,,,,,,,,,,,,,,,,,,
,3866216924.05115,1.99989557266235,18425.1953125,0.21498639007606,7.15153800059735E-5,1,2,12.9061126708984,4.98565364596243,40.5699983239174,279.612573588209,40.8606683090337,1000,-0.000163700755735054,,,,,,,,,,,,,,,,,,,,,1.99956369400024,2.00022745132446,18350.201171875,18500.189453125,50.3392215240246,5.38780850943451,2.37011694908142,26,1,0,0,1,0.269241333007813,31.2805480957031,1,6,1,2.00022745132446,0,1.99989557266235,,,,,,,,,,,,,,,,,,,,,,,,,,,,,,,,,
,3866216988.5989,2.00016343593597,24881.087890625,0.24727152509822,5.85931025020762E-5,1,2,12.9061126708984,4.98565469894012,40.5699983239174,321.583015051274,47.1322498287943,1000,-8.41660833007395E-5,,,,,,,,,,,,,,,,,,,,,1.99996042251587,2.00036644935608,24761.2421875,25000.93359375,50.3165542969669,5.38846202323862,2.37167406082153,26,1,0,0,1,0.272064208984375,31.2805480957031,1,6,1,1.99996042251587,0,2.00016343593597,,,,,,,,,,,,,,,,,,,,,,,,,,,,,,,,,
,3866217058.84879,1.99957191944122,31918.5419921875,0.272688689669476,4.90284533638404E-5,1,2,12.9061126708984,4.98569648302418,40.5699983239174,354.638976549414,52.0041082221192,1000,-7.24412644935979E-5,,,,,,,,,,,,,,,,,,,,,1.99906826019287,2.00007557868958,31823.390625,32013.693359375,50.5193868977073,5.38958464310606,2.36791610717773,26,1,0,0,1,0.271072387695313,32.2580642700195,1,6,1,1.99906826019287,0,1.99957191944122,,,,,,,,,,,,,,,,,,,,,,,,,,,,,,,,,
,3866217127.35462,1.9999058842659,38783.224609375,0.29127758279759,4.4885131769348E-5,1,2,12.9061126708984,4.98566283022483,40.5699983239174,378.825826386162,55.4459608632032,1000,-0.000156339466871584,,,,,,,,,,,,,,,,,,,,,1.99984836578369,1.99996340274811,38688.04296875,38878.40625,50.6850921437842,5.39044435228185,2.36018514633179,26,1,0,0,1,0.271987915039062,31.7693061828613,1,6,1,1.99996340274811,0,1.9999058842659,,,,,,,,,,,,,,,,,,,,,,,,,,,,,,,,,
,3866217199.86369,2.00022184848785,46047.775390625,0.306728360111897,3.77592332704255E-5,1,2,12.9061126708984,4.98572849392791,40.5699983239174,398.908730940932,58.5190997821445,1000,-6.39503406474794E-5,,,,,,,,,,,,,,,,,,,,,1.99989891052246,2.00054478645325,45952.58203125,46142.96875,50.8554871609765,5.3916748769601,2.35688066482544,26,1,0,0,1,0.267562866210938,31.7693061828613,1,6,1,2.00054478645325,0,2.00022184848785,,,,,,,,,,,,,,,,,,,,,,,,,,,,,,,,,
,3866217661.81122,13.0502700805664,26.4500465393066,5.02505070075656E-5,6.58955406088545E-8,1,5,12.9061126708984,4.98549046251593,40.5699983239174,0.0653559187476562,0.00953108811408576,10,-5.30025388457643E-8,,,,,,,,,,,,,,,,,,,,,13.0502700805664,13.0502700805664,26.4500465393066,26.4500465393066,50.1191930958611,5.3866581423542,4.96316289901733,65,1,0,0,1,0.268630981445313,31.2805480957031,6,1,1,13.0502700805664,0,13.0502700805664,,,,,,,,,,,,,,,,,,,,,,,,,,,,,,,,,
,3866217875.07836,46.1448020935059,26.4500465393066,2.93802170698844E-5,9.76327494701567E-9,1,5,12.9061126708984,4.98539084901341,40.5899994075298,0.0382141217708339,0.00555051550584841,1,-4.78440824891545E-8,,,,,,,,,,,,,,,,,,,,,46.1448020935059,46.1448020935059,26.4500465393066,26.4500465393066,50.0781575986015,5.38706780585714,6.30144548416138,65,1,0,0,1,0.272293090820313,30.7917900085449,2,1,1,46.1448020935059,0,46.1448020935059,,,,,,,,,,,,,,,,,,,,,,,,,,,,,,,,,
,3866218077.03827,78.1430358886719,26.4500465393066,2.32118198567937E-5,1.43399914991651E-8,1,5,12.9061126708984,4.9853447320406,40.6300015747547,0.0301866799465829,0.00441213238600852,1,-1.70289736060679E-8,,,,,,,,,,,,,,,,,,,,,78.1430358886719,78.1430358886719,26.4500465393066,26.4500465393066,50.1086411108515,5.38740126955116,6.65573072433472,65,1,0,0,1,0.271759033203125,31.7693061828613,2,1,1,78.1430358886719,0,78.1430358886719,,,,,,,,,,,,,,,,,,,,,,,,,,,,,,,,,
,3866218271.04581,110.057403564453,26.4500465393066,1.69641110690176E-5,9.07734900577838E-9,1,5,12.9061126708984,4.9854063782286,40.6900011003017,0.022062946521479,0.003218148434786,1,-1.74190170831961E-8,,,,,,,,,,,,,,,,,,,,,110.057403564453,110.057403564453,26.4500465393066,26.4500465393066,50.0984799401015,5.38773456118533,6.81752252578735,64,1,64,0,0,0.27099609375,31.7693061828613,2,1,1,110.057403564453,0,110.057403564453,,,,,,,,,,,,,,,,,,,,,,,,,,,,,,,,,
,3866218464.95024,142.028213500977,26.4500465393066,1.34319112801644E-5,6.19240904367353E-9,1,5,12.9061126708984,4.98528532215421,40.7800003886223,0.0174677614797193,0.00255296177325077,1,-9.96973154101822E-9,,,,,,,,,,,,,,,,,,,,,142.028213500977,142.028213500977,26.4500465393066,26.4500465393066,50.2102528183515,5.3880408918937,6.89999628067017,65,1,0,0,1,0.27313232421875,31.2805480957031,2,1,1,142.028213500977,0,142.028213500977,,,,,,,,,,,,,,,,,,,,,,,,,,,,,,,,,
,3866218649.60851,172.621849060059,26.4500465393066,1.19915470202586E-5,6.63340888327086E-9,1,5,12.9061126708984,4.98498643299683,40.8799983561039,0.0155968691006032,0.00225472066482133,1,-2.7577218251213E-8,,,,,,,,,,,,,,,,,,,,,172.259887695313,172.983810424805,26.4500465393066,26.4500465393066,50.0500189719091,5.38961383629377,6.9668025970459,65,1,0,0,1,0.270919799804687,31.2805480957031,2,1,1,172.983810424805,0,172.621849060059,,,,,,,,,,,,,,,,,,,,,,,,,,,,,,,,,
,3866218838.68842,204.081848144531,26.4500465393066,1.06944029143095E-5,6.42561300436463E-9,1,5,12.9061126708984,4.98433437209868,41.0099998116493,0.0139046610261861,0.00202757288102654,1,-1.14259901403574E-8,,,,,,,,,,,,,,,,,,,,,204.081848144531,204.081848144531,26.4500465393066,26.4500465393066,50.1840682629572,5.39285602723532,7.04562568664551,63,1,64,0,0,0.27252197265625,30.7917900085449,2,1,1,204.081848144531,0,204.081848144531,,,,,,,,,,,,,,,,,,,,,,,,,,,,,,,,,
,3866219032.11486,236.025344848633,26.4500465393066,9.59781141828934E-6,7.07516832472993E-9,1,5,12.9061126708984,4.98401549053733,41.1700010299683,0.0124785254931361,0.00181437437639321,1,-1.42009719471753E-8,,,,,,,,,,,,,,,,,,,,,236.025344848633,236.025344848633,26.4500465393066,26.4500465393066,50.1469409082938,5.39531779292951,7.23620891571045,63,1,64,0,0,0.268630981445313,31.2805480957031,2,1,1,236.025344848633,0,236.025344848633,,,,,,,,,,,,,,,,,,,,,,,,,,,,,,,,,
,3866219224.15859,268.028198242187,26.4500465393066,8.69306192109617E-6,6.94673341057338E-9,1,5,12.9061126708984,4.98351593575647,41.3299985229969,0.0112997671082172,0.00164898450257439,1,-8.34134746483187E-9,,,,,,,,,,,,,,,,,,,,,268.028198242187,268.028198242187,26.4500465393066,26.4500465393066,50.0093742889091,5.39374328183658,7.48160171508789,64,1,64,0,0,0.269622802734375,31.2805480957031,2,1,1,268.028198242187,0,268.028198242187,,,,,,,,,,,,,,,,,,,,,,,,,,,,,,,,,
,3866219498.69736,299.940124511719,26.4500465393066,7.73947501207001E-6,7.59907716438658E-9,1,5,12.9061126708984,4.9833939677293,41.5100008249283,0.0100609288622268,0.00146098567184254,1,-1.28607311834361E-8,,,,,,,,,,,,,,,,,,,,,299.940124511719,299.940124511719,26.4500465393066,26.4500465393066,50.0554903715438,5.39720348732694,7.28705215454102,65,1,0,0,1,0.2691650390625,31.7693061828613,1,1,1,299.940124511719,0,299.940124511719,,,,,,,,,,,,,,,,,,,,,,,,,,,,,,,,,
,3866220202.95088,269.972717285156,26.4500465393066,1.5806986082047E-5,6.18792567543236E-9,1,5,12.9061126708984,4.99292426985715,41.3499996066093,0.0206023671766583,0.00299945412828347,1,-2.04764582344486E-8,,,,,,,,,,,,,,,,,,,,,269.972717285156,269.972717285156,26.4500465393066,26.4500465393066,50.0906636549092,5.39719669182306,7.69707870483398,65,1,0,0,1,0.272369384765625,30.7917900085449,2,1,1,269.972717285156,0,269.972717285156,,,,,,,,,,,,,,,,,,,,,,,,,,,,,,,,,
,3866220398.45396,237.939086914062,26.4500465393066,1.59071005002397E-5,6.4484005552259E-9,1,5,12.9061126708984,4.99346301208625,41.2000007927418,0.0207385541182503,0.00300146115945208,1,-3.39927022293022E-8,,,,,,,,,,,,,,,,,,,,,237.939086914062,237.939086914062,26.4500465393066,26.4500465393066,50.1008248256591,5.39701144202304,7.57009220123291,65,1,0,0,1,0.2734375,32.7468223571777,2,1,1,237.939086914062,0,237.939086914062,,,,,,,,,,,,,,,,,,,,,,,,,,,,,,,,,
,3866220588.30722,205.971603393555,26.4500465393066,1.57466807777353E-5,6.1965317190254E-9,1,5,12.9061126708984,4.99393188509849,41.0900004208088,0.0205296832722683,0.00298812556956968,1,-2.09591631668574E-8,,,,,,,,,,,,,,,,,,,,,205.971603393555,205.971603393555,26.4500465393066,26.4500465393066,50.1207563528995,5.39235268170157,7.48579025268555,63,1,64,0,0,0.270843505859375,31.2805480957031,2,1,1,205.971603393555,0,205.971603393555,,,,,,,,,,,,,,,,,,,,,,,,,,,,,,,,,
,3866220780.14935,173.974243164062,26.4500465393066,1.51518596333804E-5,6.23511412184463E-9,1,5,12.9061126708984,4.99484741397258,40.9800000488758,0.0197599417911894,0.00287138517137108,1,-2.36992981395545E-8,,,,,,,,,,,,,,,,,,,,,173.974243164062,173.974243164062,26.4500465393066,26.4500465393066,50.1379521803226,5.38993702247131,7.41338205337524,65,1,0,0,1,0.280303955078125,31.7693061828613,2,1,1,173.974243164062,0,173.974243164062,,,,,,,,,,,,,,,,,,,,,,,,,,,,,,,,,
,3866220972.94726,141.979019165039,26.4500465393066,1.42452917405843E-5,6.21149836863161E-9,1,5,12.9061126708984,4.99526682672175,40.8799983561039,0.0185803255223379,0.00269666257348578,1,-2.47655147547259E-8,,,,,,,,,,,,,,,,,,,,,141.979019165039,141.979019165039,26.4500465393066,26.4500465393066,50.1551480077457,5.38863746013386,7.33188676834106,63,1,64,0,0,0.270614624023438,31.2805480957031,2,1,1,141.979019165039,0,141.979019165039,,,,,,,,,,,,,,,,,,,,,,,,,,,,,,,,,
,3866221164.44467,109.862022399902,26.4500465393066,1.2287522612975E-5,7.17964475575796E-9,1,5,12.9061126708984,4.99523074854548,40.8000014722347,0.0160255096697284,0.00233357803659776,1,-1.55729154763495E-8,,,,,,,,,,,,,,,,,,,,,109.862022399902,109.862022399902,26.4500465393066,26.4500465393066,50.1027788969572,5.38762823920326,7.24268007278442,64,1,64,0,0,0.279312133789062,30.7917900085449,2,1,1,109.862022399902,0,109.862022399902,,,,,,,,,,,,,,,,,,,,,,,,,,,,,,,,,
,3866221355.73,77.9817581176758,26.4500465393066,1.09003015690677E-5,6.28421738582351E-9,1,5,12.9061126708984,4.99526057472665,40.6999997794628,0.0142164568477755,0.00206976283311464,1,-1.41056002806994E-8,,,,,,,,,,,,,,,,,,,,,77.9817581176758,77.9817581176758,26.4500465393066,26.4500465393066,50.0898820263899,5.38787717904062,7.11387062072754,65,1,0,0,1,0.279312133789062,31.2805480957031,2,1,1,77.9817581176758,0,77.9817581176758,,,,,,,,,,,,,,,,,,,,,,,,,,,,,,,,,
,3866221542.80573,45.9685745239258,26.4500465393066,1.08877208645784E-5,6.28760072855097E-9,1,5,12.9061126708984,4.99519864511569,40.6400002539158,0.0142004977101129,0.00206260219237445,1,-1.77212452552896E-8,,,,,,,,,,,,,,,,,,,,,45.9685745239258,45.9685745239258,26.4500465393066,26.4500465393066,50.0805024841591,5.38780133905188,6.8511962890625,63,1,64,0,0,0.269622802734375,31.7693061828613,2,1,1,45.9685745239258,0,45.9685745239258,,,,,,,,,,,,,,,,,,,,,,,,,,,,,,,,,
,3866221731.7558,13.9657955169678,26.4500465393066,1.18478765073602E-5,6.39910586462819E-9,1,5,12.9061126708984,4.99530695728772,40.5899994075298,0.0154525279195882,0.00224959602111654,1,-1.54259919433256E-8,,,,,,,,,,,,,,,,,,,,,13.9657955169678,13.9657955169678,26.4500465393066,26.4500465393066,50.0926177262072,5.38757670331121,5.88148403167725,65,1,0,0,1,0.269546508789062,31.7693061828613,2,1,1,13.9657955169678,0,13.9657955169678,,,,,,,,,,,,,,,,,,,,,,,,,,,,,,,,,
,3866222309.63296,20.0081958770752,26.4500465393066,1.16069095158143E-5,5.81564598502067E-9,1,5,12.9061126708984,4.99531414210143,40.5699983239174,0.0151379134583268,0.00220633249785259,1,-1.32063870574393E-8,,,,,,,,,,,,,,,,,,,,,20.0081958770752,20.0081958770752,26.4500465393066,26.4500465393066,50.0844106267553,5.38804274986655,5.61668348312378,65,1,0,0,1,0.279083251953125,31.2805480957031,2,1,1,20.0081958770752,0,20.0081958770752,,,,,,,,,,,,,,,,,,,,,,,,,,,,,,,,,
,3866222515.77024,52.1462135314941,26.4500465393066,1.08780253358249E-5,6.7385030334801E-9,1,5,12.9061126708984,4.99515087926422,40.5899994075298,0.0141867142894921,0.00206718838342315,1,-1.27584750965146E-8,,,,,,,,,,,,,,,,,,,,,52.1462135314941,52.1462135314941,26.4500465393066,26.4500465393066,50.1328715949476,5.38851603661437,6.4285478591919,65,1,0,0,1,0.280609130859375,30.7917900085449,2,1,1,52.1462135314941,0,52.1462135314941,,,,,,,,,,,,,,,,,,,,,,,,,,,,,,,,,
,3866222716.04027,84.082405090332,26.4500465393066,1.08201985482106E-5,6.23672866578837E-9,1,5,12.9061126708984,4.99536105419975,40.6400002539158,0.0141129096252333,0.00205102166744937,1,-1.67542437164204E-8,,,,,,,,,,,,,,,,,,,,,84.082405090332,84.082405090332,26.4500465393066,26.4500465393066,50.1559296362649,5.38751543961623,6.74696588516235,65,1,0,0,1,0.268478393554687,31.7693061828613,2,1,1,84.082405090332,0,84.082405090332,,,,,,,,,,,,,,,,,,,,,,,,,,,,,,,,,
,3866222909.74322,116.017715454102,26.4500465393066,1.1436809804646E-5,7.06349151302021E-9,1,5,12.9061126708984,4.99514810820088,40.7099984586239,0.0149146608913562,0.00217873568236996,1,-9.3022570927364E-9,,,,,,,,,,,,,,,,,,,,,116.017715454102,116.017715454102,26.4500465393066,26.4500465393066,50.0863646980534,5.38847027783239,6.89116191864014,65,1,0,0,1,0.270538330078125,31.7693061828613,2,1,1,116.017715454102,0,116.017715454102,,,,,,,,,,,,,,,,,,,,,,,,,,,,,,,,,
,3866223103.54607,148.023056030273,26.4500465393066,1.18226186266218E-5,5.8946209104997E-9,1,5,12.9061126708984,4.99516701074737,40.8000014722347,0.015420195502345,0.00223643730799935,1,-2.17390451649432E-8,,,,,,,,,,,,,,,,,,,,,148.023056030273,148.023056030273,26.4500465393066,26.4500465393066,50.1868039627745,5.38890511845416,6.97463703155518,64,1,64,0,0,0.279998779296875,31.7693061828613,2,1,1,148.023056030273,0,148.023056030273,,,,,,,,,,,,,,,,,,,,,,,,,,,,,,,,,
,3866223290.50264,179.020599365234,26.4500465393066,1.18149464244582E-5,6.47362861014486E-9,1,5,12.9061126708984,4.99502377797483,40.9100018441677,0.0154096301969903,0.00223448084424481,1,-2.20434436167184E-8,,,,,,,,,,,,,,,,,,,,,179.020599365234,179.020599365234,26.4500465393066,26.4500465393066,50.1113768106688,5.38971730865827,7.04385948181152,64,1,64,0,0,0.279998779296875,31.7693061828613,2,1,1,179.020599365234,0,179.020599365234,,,,,,,,,,,,,,,,,,,,,,,,,,,,,,,,,
,3866223483.21529,211.000076293945,26.4500465393066,1.16635115355222E-5,7.23580255415606E-9,1,5,12.9061126708984,4.99439811664824,41.0399995744228,0.0152097004010475,0.002203748758541,1,-2.30686474070779E-8,,,,,,,,,,,,,,,,,,,,,211.000076293945,211.000076293945,26.4500465393066,26.4500465393066,50.1000431971399,5.3914463609486,7.12598943710327,63,1,64,0,0,0.271148681640625,31.7693061828613,2,1,1,211.000076293945,0,211.000076293945,,,,,,,,,,,,,,,,,,,,,,,,,,,,,,,,,
,3866223676.3262,243.004852294922,26.4500465393066,1.13906699198214E-5,7.61518725463958E-9,1,5,12.9061126708984,4.99413344126127,41.1899983882904,0.0148522792106831,0.00215558143390733,1,-1.98100463729659E-8,,,,,,,,,,,,,,,,,,,,,243.004852294922,243.004852294922,26.4500465393066,26.4500465393066,50.1316991521688,5.3918184533433,7.27913808822632,63,1,64,0,0,0.27069091796875,31.7693061828613,2,1,1,243.004852294922,0,243.004852294922,,,,,,,,,,,,,,,,,,,,,,,,,,,,,,,,,
,3866223869.46329,275.011047363281,26.4500465393066,1.10373407656727E-5,7.49188173324363E-9,1,5,12.9061126708984,4.99364721235292,41.3700006902218,0.0143879961491092,0.00209941029980227,1,-1.0772596642458E-8,,,,,,,,,,,,,,,,,,,,,275.011047363281,275.011047363281,26.4500465393066,26.4500465393066,50.0535363002457,5.39506730851036,7.38176155090332,64,1,64,0,0,0.272293090820313,31.7693061828613,2,1,1,275.011047363281,0,275.011047363281,,,,,,,,,,,,,,,,,,,,,,,,,,,,,,,,,
,3866224223.15927,300.007522583008,46807.078125,0.0101138384189619,2.58477849691672E-6,1,2,12.9061126708984,4.99360075494194,41.4999984204769,13.189918650555,1.88323457901474,100,-4.09379519341187E-5,,,,,,,,,,,,,,,,,,,,,300.007507324219,300.007537841797,46717.359375,46896.796875,49.9609133207168,5.39506750336933,7.35867595672607,26,1,0,0,1,0.271530151367187,31.2805480957031,1,6,1,300.007537841797,0,300.007522583008,,,,,,,,,,,,,,,,,,,,,,,,,,,,,,,,,
,3866224299.39274,300.003845214844,39195.08984375,0.00849002956816325,2.63476545053747E-6,1,2,12.9061126708984,4.99357135355369,41.4999984204769,11.0698823549801,1.59625646237505,100,-2.25540492099929E-5,,,,,,,,,,,,,,,,,,,,,300.003570556641,300.004119873047,39120.234375,39269.9453125,50.0011671894572,5.39492865801647,7.4054069519043,26,1,0,0,1,0.27099609375,31.2805480957031,1,6,1,300.004119873047,0,300.003845214844,,,,,,,,,,,,,,,,,,,,,,,,,,,,,,,,,
,3866224369.73391,300.003509521484,32175.7158203125,0.00699855633308555,3.10827275470905E-6,1,2,12.9061126708984,4.99369199053692,41.4999984204769,9.12547499067424,1.3160955394056,100,-1.84273603870688E-5,,,,,,,,,,,,,,,,,,,,,300.003448486328,300.003570556641,32080.97265625,32270.458984375,50.0218803452168,5.39463033194604,7.48459005355835,26,1,0,0,1,0.272750854492187,31.7693061828613,1,6,1,300.003448486328,0,300.003509521484,,,,,,,,,,,,,,,,,,,,,,,,,,,,,,,,,
,3866224440.32448,300.003128051758,25127.5244140625,0.00551068078516486,2.73834448765339E-6,1,2,12.9061126708984,4.99374778313239,41.4999984204769,7.1852282714975,1.03839722495832,100,-1.29108350950401E-5,,,,,,,,,,,,,,,,,,,,,300.002960205078,300.003295898438,25042.65234375,25212.396484375,50.0891003978707,5.39471688191035,7.59189128875732,26,1,0,0,1,0.271072387695313,30.7917900085449,1,6,1,300.003295898438,0,300.003128051758,,,,,,,,,,,,,,,,,,,,,,,,,,,,,,,,,
,3866224510.76054,300.002349853516,18093.91796875,0.00401971795720873,2.73132804372336E-6,1,2,12.9061126708984,4.9937782347973,41.4999984204769,5.24164719231496,0.754730932311246,100,-1.15085772402322E-5,,,,,,,,,,,,,,,,,,,,,300.001953125,300.002746582031,18004.119140625,18183.716796875,50.0433751294957,5.39486694998858,7.748619556427,26,1,0,0,1,0.27191162109375,31.7693061828613,1,6,1,300.002746582031,0,300.002349853516,,,,,,,,,,,,,,,,,,,,,,,,,,,,,,,,,
,3866224581.45005,300.001617431641,11034.5014648438,0.00252693576297455,2.44737620296779E-6,1,2,12.9061126708984,4.99364573869963,41.4999984204769,3.29570422507182,0.469372030921006,100,-1.11173979968011E-5,,,,,,,,,,,,,,,,,,,,,300.00146484375,300.001770019531,10964.3837890625,11104.619140625,50.1145033247457,5.39529559265334,7.90125465393066,26,1,0,0,1,0.271987915039062,31.7693061828613,1,6,1,300.00146484375,0,300.001617431641,,,,,,,,,,,,,,,,,,,,,,,,,,,,,,,,,
,3866224649.01433,300.000991821289,4284.75048828125,0.00106983784650657,2.6125314397406E-6,1,2,12.9061126708984,4.99359599721938,41.4999984204769,1.39735688891079,0.184679353325026,100,-1.5477047506826E-5,,,,,,,,,,,,,,,,,,,,,300.000610351562,300.001373291016,4119.9140625,4449.5869140625,50.1027788969572,5.39489680275656,8.02888298034668,26,1,0,0,1,0.272064208984375,31.7693061828613,1,6,1,300.000610351562,0,300.000991821289,,,,,,,,,,,,,,,,,,,,,,,,,,,,,,,,,
,3866224720.35027,300.000411987305,-2847.02783203125,-0.000763761961352336,2.49493560283212E-6,1,2,12.9061126708984,4.99326613517171,41.4999984204769,-0.994523822352159,-0.151999974193055,100,-4.42664813827216E-6,,,,,,,,,,,,,,,,,,,,,300.000030517578,300.000793457031,-2946.82348632812,-2747.23217773438,50.1430327656976,5.39590311047621,7.97330617904663,26,1,0,0,1,0.27130126953125,31.7693061828613,1,6,1,300.000793457031,0,300.000411987305,,,,,,,,,,,,,,,,,,,,,,,,,,,,,,,,,
,3866224797.05727,300.00080871582,-10515.8803710938,-0.00240908293825788,2.41698216378745E-6,1,2,12.9061126708984,4.9935356318683,41.4999984204769,-3.14012217499463,-0.459568272757189,10,1.31437910794939E-6,,,,,,,,,,,,,,,,,,,,,300.000762939453,300.000854492188,-10625.9990234375,-10405.76171875,50.1664816212745,5.39466201808429,7.92115211486816,26,1,0,0,1,0.270767211914062,31.2805480957031,1,6,1,300.000854492188,0,300.00080871582,,,,,,,,,,,,,,,,,,,,,,,,,,,,,,,,,
,3866224901.72538,300.000518798828,-20981.806640625,-0.00463177593140674,3.06114466499169E-6,1,2,12.9061126708984,4.99338219373577,41.4999984204769,-6.03786347422034,-0.877895604664036,100,6.85934613959601E-6,,,,,,,,,,,,,,,,,,,,,300.000457763672,300.000579833984,-21056.806640625,-20906.806640625,50.056272000063,5.39557226428859,7.88683032989502,26,1,0,0,1,0.2734375,31.7693061828613,1,6,1,300.000579833984,0,300.000518798828,,,,,,,,,,,,,,,,,,,,,,,,,,,,,,,,,
,3866224970.41483,300.00065612793,-27856.228515625,-0.00608283114759528,2.93543160514154E-6,1,2,12.9061126708984,4.99342942911742,41.4999984204769,-7.9296606251448,-1.15202927095424,100,9.70734638814265E-6,,,,,,,,,,,,,,,,,,,,,300.000640869141,300.000671386719,-27911.341796875,-27801.115234375,50.0539271145053,5.39543382933716,7.8645453453064,26,1,0,0,1,0.271835327148438,31.7693061828613,1,6,1,300.000671386719,0,300.00065612793,,,,,,,,,,,,,,,,,,,,,,,,,,,,,,,,,
,3866225038.55465,299.999725341797,-34683.380859375,-0.00753049381142366,2.72377136536268E-6,1,2,12.9061126708984,4.99344375055286,41.4999984204769,-9.81654245835265,-1.42859205842873,100,1.01886040581893E-5,,,,,,,,,,,,,,,,,,,,,299.999572753906,299.999877929687,-34773.51171875,-34593.25,49.9843621762937,5.39467158479038,7.84800910949707,26,1,0,0,1,0.271987915039062,31.7693061828613,1,6,1,299.999877929687,0,299.999725341797,,,,,,,,,,,,,,,,,,,,,,,,,,,,,,,,,
,3866225109.48642,300.000549316406,-41786.6015625,-0.00902492531828265,2.75753854653025E-6,1,2,12.9061126708984,4.99380169916838,41.4999984204769,-11.7652479167226,-1.71619407090451,100,9.19939871547597E-6,,,,,,,,,,,,,,,,,,,,,300.000457763672,300.000640869141,-41896.9453125,-41676.2578125,49.9769367053611,5.39376067499141,7.8379225730896,26,1,0,0,1,0.272293090820313,31.2805480957031,1,6,1,300.000457763672,0,300.000549316406,,,,,,,,,,,,,,,,,,,,,,,,,,,,,,,,,
,3866225191.83411,300.000610351562,-49965.001953125,-0.0107660567990616,2.50110863798229E-6,1,2,12.9061126708984,4.99375833462705,41.4999984204769,-14.0343652860338,-2.05079998145787,100,8.26247612436049E-6,,,,,,,,,,,,,,,,,,,,,300.000610351562,300.000610351562,-49999.34765625,-49930.65625,49.9761550768418,5.39413668389184,7.82232809066772,26,1,0,0,1,0.270767211914062,31.2805480957031,1,6,1,300.000610351562,0,300.000610351562,,,,,,,,,,,,,,,,,,,,,,,,,,,,,,,,,
,3866225264.22132,300.000427246094,-43374.30859375,-0.00938102406592342,3.05174525146278E-6,1,2,12.9061126708984,4.99368623894695,41.4999984204769,-12.2336616179375,-1.75263722960997,100,3.35114818087537E-5,,,,,,,,,,,,,,,,,,,,,300.000244140625,300.000610351562,-43464.09375,-43284.5234375,49.9609133207168,5.39404786928427,7.8133282661438,25,1,68,0,0,0.271224975585938,31.2805480957031,1,6,1,300.000244140625,0,300.000427246094,,,,,,,,,,,,,,,,,,,,,,,,,,,,,,,,,
,3866225332.83786,300.000671386719,-36526.919921875,-0.00793145053518969,2.80719363387318E-6,1,2,12.9061126708984,4.9937181066897,41.4999984204769,-10.3428511067142,-1.48546869195055,100,2.55413160434297E-5,,,,,,,,,,,,,,,,,,,,,300.000457763672,300.000885009766,-36636.67578125,-36417.1640625,50.0277425591111,5.39378803505133,7.80644369125366,26,1,0,0,1,0.27130126953125,31.2805480957031,1,6,1,300.000457763672,0,300.000671386719,,,,,,,,,,,,,,,,,,,,,,,,,,,,,,,,,
,3866225399.42883,299.999633789063,-29880.0458984375,-0.00652429666373735,3.00630473854341E-6,1,2,12.9061126708984,4.99365148933416,41.4999984204769,-8.50719417269296,-1.22548680775167,100,1.82597228003538E-5,,,,,,,,,,,,,,,,,,,,,299.999572753906,299.999694824219,-29989.92578125,-29770.166015625,50.0648699137745,5.39430670769038,7.80705451965332,26,1,0,0,1,0.271148681640625,31.7693061828613,1,6,1,299.999572753906,0,299.999633789063,,,,,,,,,,,,,,,,,,,,,,,,,,,,,,,,,
,3866225467.94389,300.000595092773,-23042.0517578125,-0.00507605622562555,2.80070650504604E-6,1,2,12.9061126708984,4.99364253506767,41.4999984204769,-6.61837996208321,-0.956181368249758,100,1.21148556339904E-5,,,,,,,,,,,,,,,,,,,,,300.000579833984,300.000610351562,-23111.912109375,-22972.19140625,50.1109859964091,5.39467361314612,7.80212593078613,26,1,0,0,1,0.272064208984375,31.2805480957031,1,6,1,300.000610351562,0,300.000595092773,,,,,,,,,,,,,,,,,,,,,,,,,,,,,,,,,
,3866225536.12875,300.000473022461,-16234.0415039062,-0.00362758009404935,2.7331086188205E-6,1,2,12.9061126708984,4.99359767476146,41.4999984204769,-4.73003425802856,-0.681285177562414,100,1.02205475246857E-5,,,,,,,,,,,,,,,,,,,,,300.000427246094,300.000518798828,-16323.83984375,-16144.2431640625,50.0930085404668,5.39486785099626,7.79754734039307,26,1,0,0,1,0.271453857421875,31.7693061828613,1,6,1,300.000518798828,0,300.000473022461,,,,,,,,,,,,,,,,,,,,,,,,,,,,,,,,,
,3866225606.83063,300.000762939453,-9173.32666015625,-0.00213574149482412,2.34715625661263E-6,1,2,12.9061126708984,4.99352020570899,41.4999984204769,-2.78552121183824,-0.395862211124603,100,1.00350382929172E-5,,,,,,,,,,,,,,,,,,,,,300.000366210937,300.001159667969,-9283.23828125,-9063.4150390625,50.0984799401015,5.39546460182607,7.7842845916748,24,1,68,0,0,0.273361206054687,31.2805480957031,1,6,1,300.001159667969,0,300.000762939453,,,,,,,,,,,,,,,,,,,,,,,,,,,,,,,,,
,3866225676.41525,300.00065612793,-2219.12121582031,-0.000610441707033655,2.70195412632935E-6,1,2,12.9061126708984,4.99361062882449,41.4999984204769,-0.799016800862417,-0.0938611064500355,100,1.76666381252522E-5,,,,,,,,,,,,,,,,,,,,,300.00048828125,300.000823974609,-2389.04077148438,-2049.20166015625,50.0699504991495,5.39463777327985,7.78010749816895,26,1,0,0,1,0.271530151367187,31.2805480957031,1,6,1,300.00048828125,0,300.00065612793,,,,,,,,,,,,,,,,,,,,,,,,,,,,,,,,,
,3866225766.07837,300.000350952148,6742.63037109375,0.00160547484640007,2.4263518533694E-6,1,2,12.9061126708984,4.99383253810464,41.4999984204769,2.09224968652,0.31026207768821,100,2.16860258644416E-6,,,,,,,,,,,,,,,,,,,,,300.000274658203,300.000427246094,6657.63916015625,6827.62158203125,50.0988707543611,5.39430701475021,7.77634716033935,26,1,0,0,1,0.271377563476562,31.7693061828613,1,6,1,300.000427246094,0,300.000350952148,,,,,,,,,,,,,,,,,,,,,,,,,,,,,,,,,
,3866225868.66783,299.999298095703,17004.46484375,0.00378777189587009,2.86315970322005E-6,1,2,12.9061126708984,4.99379829220458,41.4999984204769,4.93820100298717,0.718129039149996,10,-5.51735464924796E-6,,,,,,,,,,,,,,,,,,,,,299.999298095703,299.999298095703,16919.29296875,17089.63671875,50.0906636549092,5.39439426128348,7.77116918563843,24,1,68,0,0,0.282058715820313,31.7693061828613,1,6,1,299.999298095703,0,299.999298095703,,,,,,,,,,,,,,,,,,,,,,,,,,,,,,,,,
,3866225961.22621,299.999114990234,26262.74609375,0.00575471346837402,2.84980607600264E-6,1,2,12.9061126708984,4.99363670162756,41.4999984204769,7.50243177623798,1.08945301414271,100,-9.56533332332443E-6,,,,,,,,,,,,,,,,,,,,,299.998931884766,299.999298095703,26172.583984375,26352.908203125,50.0679964278515,5.39518688971296,7.76913595199585,26,1,0,0,1,0.271224975585938,31.7693061828613,1,6,1,299.999298095703,0,299.999114990234,,,,,,,,,,,,,,,,,,,,,,,,,,,,,,,,,
,3866226029.85095,300.000457763672,33136.55859375,0.0072088864608128,2.90091268774844E-6,1,2,12.9061126708984,4.99374522629382,41.4999984204769,9.39827951855488,1.36647255007829,100,-1.06924909418947E-5,,,,,,,,,,,,,,,,,,,,,300.000335693359,300.000579833984,33026.328125,33246.7890625,50.0246160450341,5.39434803024696,7.76400899887085,26,1,0,0,1,0.272445678710938,31.2805480957031,1,6,1,300.000579833984,0,300.000457763672,,,,,,,,,,,,,,,,,,,,,,,,,,,,,,,,,
,3866226106.65433,300.000885009766,40837.69921875,0.00883088708106269,3.02069145219633E-6,1,2,12.9061126708984,4.99369208860233,41.4999984204769,11.5125868406083,1.67482504280751,100,-1.23917483746216E-5,,,,,,,,,,,,,,,,,,,,,300.000427246094,300.001342773438,40722.37890625,40953.01953125,50.0160181313226,5.39464224686702,7.76899290084839,26,1,0,0,1,0.27252197265625,31.2805480957031,1,6,1,300.001342773438,0,300.000885009766,,,,,,,,,,,,,,,,,,,,,,,,,,,,,,,,,
,3866226193.23468,300.000122070313,49515.544921875,0.0107060558041165,7.76675503352122E-5,1,2,12.9061126708984,4.99375099340416,41.4999984204769,13.9429332093202,2.12913154729896,100,6.06522613721793E-5,,,,,,,,,,,,,,,,,,,,,300.000122070313,300.000122070313,49460.40625,49570.68359375,49.9761550768418,5.39394302753813,7.76093101501465,26,1,0,0,1,0.281982421875,31.7693061828613,1,6,1,300.000122070313,0,300.000122070313,,,,,,,,,,,,,,,,,,,,,,,,,,,,,,,,,
,3866231114.66092,91.3969268798828,24.8078861236572,,,5,,,,40.6600013375282,,,,,2.85242664041865E-6,3.78442076920387E-8,-0.109241741930064,0.00932530867710929,9.50808889441361E-7,1.26147360207568E-8,9.50807161237088E-7,8.97302252506242E-9,-1.81283782640148E-9,8.86659075620962E-9,2.99999997065085,1.00057637691498,19.98847910208,20,1,3,0.0100388583790219,0.00010273775039715,0.000288856070255861,292.597953796387,91.3634490966797,91.4001083374023,24.8078861236572,24.8078861236572,,,6.78423500061035,,1,,,,,,1,1,1,91.3987426757812,0,91.3927520455666,,,,,,,,,,,,,,,,,,,,,,,,,,,,,,,,,
,3866235347.52709,190.734153747559,24.8078861236572,,,5,,,,40.9599989652634,,,,,1.41877684723403E-6,3.99350526025027E-9,0.582707118477189,0.00257086510199169,4.72878176744742E-7,1.33103489105372E-9,4.72853721561847E-7,5.3944260544353E-10,4.80916276935659E-9,1.21682190834759E-9,3.00030095911971,100.057640075684,10,1000,1,3,0.00493874718680601,0.00063249071617766,0.0122788352891803,197.703247070313,190.729614257813,190.737991333008,24.8078861236572,24.8078861236572,,,7.08355665206909,,1,,,,,,1,1,1,190.734039306641,0,190.733822698178,,,,,,,,,,,,,,,,,,,,,,,,,,,,,,,,,
,3866239870.47622,299.998550415039,24.8078861236572,,,5,,,,41.5199995040894,,,,,9.69616849504712E-7,1.45564259851531E-8,0.0119671905681207,0.00494877174062733,3.23205970674874E-7,4.85214731209713E-9,3.23205963624884E-7,4.58189074347737E-9,6.75070214345305E-11,1.59675005969242E-9,2.99999671256101,10.005763053894,10,100,1,3,0.00339407695987282,0.000333551344752054,0.00377967115491629,254.801345825195,299.992614746094,300.006286621094,24.8078861236572,24.8078861236572,,,7.86769485473633,,1,,,,,,1,1,1,299.997680664063,0,300.000025335348,,,,,,,,,,,,,,,,,,,,,,,,,,,,,,,,,
,3866239932.26729,299.990737915039,24.8078861236572,,,5,,,,41.5199995040894,,,,,9.72832837588549E-7,4.81571422146443E-9,0.698151685293995,0.00435305858983962,3.24296771482601E-7,1.6053329144141E-9,3.24272696744432E-7,7.6194879259713E-10,3.95147315973273E-9,1.41298542227478E-9,2.99982276462701,100.057640075684,10,1000,1,3,0.00338587990645879,0.000440089859318094,0.0122949676588178,197.738021850586,299.978729248047,299.999816894531,24.8078861236572,24.8078861236572,,,7.86291980743408,,1,,,,,,1,1,1,299.988372802734,0,299.989845742985,,,,,,,,,,,,,,,,,,,,,,,,,,,,,,,,,