File: LT data/Frome/L5/249_FULL_SEQUENCE.dat
[Header]
; MPMS3 Data File (default extension .dat)
; Copyright (c) 2007, Quantum Design, Inc. All rights reserved.
TITLE,
FILEOPENTIME,3874207064.98338,10/06/2022,10:48 am
BYAPP,MPMS3 w/ AC,1.0,1.1
INFO,MPMS3 Measurement Release 1.1.16 Build 424, MultiVu Release 2.3.4.19,APPNAME
INFO,Linear Motor Servo Controller,MOTOR_MODULE_NAME
INFO,3101-100 N0,MOTOR_HW_VERSION
INFO,MMC1047,MOTOR_SERIAL_NUMBER
INFO,01.04.28,MOTOR_SOFTWARE_VERSION
INFO,Quantum Design Squid Module,SQUID_MODULE_NAME
INFO,3101-501 B0,SQUID_HW_VERSION
INFO,SQM278,SQUID_SERIAL_NUMBER
INFO,01.03.04,SQUID_SOFTWARE_VERSION
INFO,Quantum Design VSM Oven,OVEN_MODULE_NAME
INFO,3101-201 A3,OVEN_HW_VERSION
INFO,OVB323,OVEN_SERIAL_NUMBER
INFO,01.07.07,OVEN_SOFTWARE_VERSION
INFO,SQUID AC,AC_MODULE_NAME
INFO,3101-401 G0,AC_HW_VERSION
INFO,SAC258,AC_SERIAL_NUMBER
INFO,SQUID AC 00.95.07,AC_SOFTWARE_VERSION
INFO,TCI127,COIL_SERIAL_NUMBER
INFO,0,MOMENT_UNITS
INFO,249,SAMPLE_MATERIAL
INFO,,SAMPLE_COMMENT
INFO,,SAMPLE_MASS
INFO,,SAMPLE_VOLUME
INFO,,SAMPLE_MOLECULAR_WEIGHT
INFO,,SAMPLE_SIZE
INFO,,SAMPLE_SHAPE
INFO,Straw,SAMPLE_HOLDER
INFO,Standard,SAMPLE_HOLDER_DETAIL
INFO,66.22,SAMPLE_OFFSET
DATATYPE,COMMENT,1
DATATYPE,TIME,2
STARTUPAXIS,X,2
STARTUPAXIS,Y1,5
FIELDGROUP, VSM,2,3,4,5,6,8,9,10,11,14,15
FIELDGROUP, DC, 2,3,4,14,56,57,58,59,60,61,62,63,64,65,66,67,68,69
FIELDGROUP, AC, 2,3,4,11,16,17,18,19,20,21,22,23,24,25,26,27,28,29,30
STARTUPGROUP, All
[Data]
Comment,Time Stamp (sec),Temperature (K),Magnetic Field (Oe),Moment (emu),M. Std. Err. (emu),Transport Action,Averaging Time (sec),Frequency (Hz),Peak Amplitude (mm),Center Position (mm),Lockin Signal' (V),Lockin Signal (V),Range,M. Quad. Signal (emu),AC Moment (emu),AC M. Std Err. (emu),AC Phase (deg),AC Phase Std. Err. (deg),AC Susceptibility (emu/Oe),AC Suscept. Std Err. (emu/Oe),AC X' (emu/Oe),AC X' Std Err. (emu/Oe),AC X'' (emu/Oe),AC X'' Std Err. (emu/Oe),AC Drive (Oe),AC Frequency (Hz),AC Averaging Time (sec),AC Cycles,AC Range,AC Measure Type,AC Signal' (V),AC Signal'' (V),AC Trim Coil Ratio,AC Trim Coil Phase,Min. Temperature (K),Max. Temperature (K),Min. Field (Oe),Max. Field (Oe),Mass (grams),Motor Lag (deg),Pressure (Torr),Measure Count,Measurement Number,SQUID Status (code),Motor Status (code),Measure Status (code),Motor Current (amps),Motor Temp. (C),Temp. Status (code),Field Status (code),Chamber Status (code),Chamber Temp (K),Redirection State,Evercool Status,Average Temp (K),Rotation Angle (deg),Rotator state,DC Moment Fixed Ctr (emu),DC Moment Err Fixed Ctr (emu),DC Moment Free Ctr (emu),DC Moment Err Free Ctr (emu),DC Fixed Fit,DC Free Fit,DC Calculated Center (mm),DC Calculated Center Err (mm),DC Scan Length (mm),DC Scan Time (s),DC Number of Points,DC Squid Drift,DC Min V (V),DC Max V (V),DC Scans per Measure,Map 01,Map 02,Map 03,Map 04,Map 05,Map 06,Map 07,Map 08,Map 09,Map 10,Map 11,Map 12,Map 13,Map 14,Map 15,Map 16
"FC",3874207168.82677
,3874207985.78498,91.3154258728027,49999.6953125,0.0220125966728651,3.00962011714594E-5,1,2,13.1008939743042,2.0087863822611,25.3899991512299,5.38353762125191,0.787392459212644,10,-6.33146625739996E-6,,,,,,,,,,,,,,,,,,,,,91.2407760620117,91.3900756835938,49999.6953125,49999.6953125,51.4319381939093,5.72975156829101,8.10151863098145,25,1,64,0,0,0.1361083984375,31.7693061828613,2,1,1,91.2407760620117,0,2084573184,91.3154258728027,,,,,,,,,,,,,,,,,,,,,,,,,,,,,,,,,
,3874208116.45607,69.8856468200684,49999.6953125,0.0294712062369214,2.75435519708203E-5,1,2,13.1008939743042,2.00989393284256,25.3299996256828,7.21513895940491,1.05561484719385,100,-7.14248091762338E-6,,,,,,,,,,,,,,,,,,,,,69.7868347167969,69.9844589233398,49999.6953125,49999.6953125,51.5390213010439,5.72029434227705,7.89957141876221,25,1,64,0,0,0.133514404296875,29.8142719268799,2,1,1,69.732177734375,0,2084573184,69.8856468200684,,,,,,,,,,,,,,,,,,,,,,,,,,,,,,,,,
,3874208253.21664,46.5354080200195,49999.6953125,0.0450739187725737,2.32925373205542E-5,1,2,13.1008939743042,1.99945992776339,25.2700001001358,10.9288916264168,1.58405837007749,1000,-7.10960579849542E-5,,,,,,,,,,,,,,,,,,,,,46.3749389648438,46.6958770751953,49999.6953125,49999.6953125,51.6023332111016,5.71529098384578,7.49224758148193,26,1,0,0,1,0.132369995117188,30.7917900085449,2,1,1,46.3749389648438,0,2084573184,46.5354080200195,,,,,,,,,,,,,,,,,,,,,,,,,,,,,,,,,
,3874208391.43566,23.1465511322021,49999.6953125,0.0819892307605727,0.000688393811306053,1,2,13.1008939743042,1.99770055950031,25.2400003373623,19.8708857034611,2.70997672702214,1000,-0.000817799731288835,,,,,,,,,,,,,,,,,,,,,23.1465511322021,23.1465511322021,49999.6953125,49999.6953125,51.7703833427362,5.73252458698347,6.62099361419678,26,1,0,0,1,0.12939453125,31.2805480957031,2,1,1,23.1465511322021,0,2084573184,23.1465511322021,,,,,,,,,,,,,,,,,,,,,,,,,,,,,,,,,
,3874208511.26405,4.76161599159241,49999.6953125,0.167278508469803,0.00011137685079708,1,2,13.1008939743042,1.99567546731609,25.2199992537498,40.3993991187025,5.95733031421811,100,0.000148637732028941,,,,,,,,,,,,,,,,,,,,,4.61351442337036,4.90971755981445,49999.6953125,49999.6953125,52.4589980681786,5.75209915328093,4.07737874984741,26,1,0,0,1,0.1348876953125,31.2805480957031,6,1,1,4.61351442337036,0,2084573184,4.76161599159241,,,,,,,,,,,,,,,,,,,,,,,,,,,,,,,,,
,3874208584.71375,2.05042159557343,49999.6953125,0.181422096667332,6.45176804965092E-5,1,2,13.1008939743042,1.99547012651688,25.2199992537498,43.8060202901627,6.46420665089334,100,0.000179578931951885,,,,,,,,,,,,,,,,,,,,,2.0501492023468,2.05069398880005,49999.6953125,49999.6953125,52.8392603427844,5.75476748897095,2.55150151252747,26,1,0,0,1,0.1324462890625,30.7917900085449,2,1,1,2.0501492023468,0,2084573184,2.05042159557343,,,,,,,,,,,,,,,,,,,,,,,,,,,,,,,,,
,3874208650.17434,2.0902715921402,49999.6953125,0.181310674056987,3.20399573382866E-5,1,2,13.1008939743042,1.99531552214221,25.2199992537498,43.7712834652129,6.46887223932129,100,0.000219161709300337,,,,,,,,,,,,,,,,,,,,,2.0899920463562,2.09055113792419,49999.6953125,49999.6953125,52.7794657610633,5.75874739260744,2.55500674247742,26,1,0,0,1,0.132980346679688,32.2580642700195,2,1,1,2.09055113792419,0,2084573184,2.0902715921402,,,,,,,,,,,,,,,,,,,,,,,,,,,,,,,,,
,3874208715.6684,2.09510576725006,49999.6953125,0.181314324438553,8.54535255030584E-5,1,2,13.1008939743042,1.9957904082877,25.2199992537498,43.7936242643684,6.46022838481766,100,0.000170764287128958,,,,,,,,,,,,,,,,,,,,,2.09438538551331,2.09582614898682,49999.6953125,49999.6953125,52.8482490707556,5.75395436196214,2.54649376869202,26,1,0,0,1,0.134735107421875,30.7917900085449,2,1,1,2.09438538551331,0,2084573184,2.09510576725006,,,,,,,,,,,,,,,,,,,,,,,,,,,,,,,,,
,3874208781.11324,2.08957469463348,49999.6953125,0.181300342134967,4.42556035219524E-5,1,2,13.1008939743042,1.99630589347586,25.2199992537498,43.8124653538915,6.45756299532085,100,0.000148699685111648,,,,,,,,,,,,,,,,,,,,,2.08956623077393,2.08958315849304,49999.6953125,49999.6953125,52.8392603427844,5.74929134503483,2.53749942779541,26,1,0,0,1,0.134506225585938,31.2805480957031,2,1,1,2.08958315849304,0,2084573184,2.08957469463348,,,,,,,,,,,,,,,,,,,,,,,,,,,,,,,,,
,3874208846.59841,2.10956716537476,49999.6953125,0.181298189871738,3.19635494115353E-5,1,2,13.1008939743042,1.99608289351824,25.2199992537498,43.8016331339646,6.46320050162241,100,0.000178002986609599,,,,,,,,,,,,,,,,,,,,,2.10939788818359,2.10973644256592,49999.6953125,49999.6953125,52.797052402746,5.75034162765199,2.55034446716309,26,1,0,0,1,0.132293701171875,31.2805480957031,2,1,1,2.10939788818359,0,2084573184,2.10956716537476,,,,,,,,,,,,,,,,,,,,,,,,,,,,,,,,,
,3874208922.07484,2.10115134716034,49999.6953125,0.181266087634237,3.70770475225014E-5,1,2,13.1008939743042,1.99632366050851,25.2199992537498,43.8007761610121,6.48477038471796,100,0.000265840601014473,,,,,,,,,,,,,,,,,,,,,2.10104560852051,2.10125708580017,49999.6953125,49999.6953125,52.7747759899479,5.74772999594296,2.53770518302917,26,1,0,0,1,0.13580322265625,31.2805480957031,2,1,1,2.10104560852051,0,2084573184,2.10115134716034,,,,,,,,,,,,,,,,,,,,,,,,,,,,,,,,,
,3874208987.5406,2.09518694877625,49999.6953125,0.181293264391126,3.76299908892523E-5,1,2,13.1008939743042,1.99644795723081,25.2199992537498,43.812722853778,6.48507062998898,100,0.000259934305380523,,,,,,,,,,,,,,,,,,,,,2.09502530097961,2.09534859657288,49999.6953125,49999.6953125,52.7927534458902,5.74422519508986,2.53053879737854,26,1,0,0,1,0.1318359375,31.2805480957031,2,1,1,2.09534859657288,0,2084573792,2.09518694877625,,,,,,,,,,,,,,,,,,,,,,,,,,,,,,,,,
,3874209053.0367,2.04238128662109,49999.6953125,0.181474835061526,6.39280634344476E-5,1,2,13.1008939743042,1.99653731666062,25.2199992537498,43.8613812675482,6.48489306074933,100,0.000230314474328369,,,,,,,,,,,,,,,,,,,,,2.04205012321472,2.04271245002747,49999.6953125,49999.6953125,52.859973498544,5.7470217258486,2.49489212036133,26,1,0,0,1,0.13519287109375,31.2805480957031,2,1,1,2.04205012321472,0,2084573728,2.04238128662109,,,,,,,,,,,,,,,,,,,,,,,,,,,,,,,,,
,3874209118.58603,2.0122195482254,49999.6953125,0.181616396613565,3.53818521240788E-5,1,2,13.1008939743042,1.99656588803086,25.2199992537498,43.8974746921852,6.48543023644804,100,0.000211062776946293,,,,,,,,,,,,,,,,,,,,,2.01089644432068,2.01354265213013,49999.6953125,49999.6953125,52.7947075171883,5.74413317297446,2.47236490249634,26,1,0,0,1,0.133209228515625,28.8367557525635,6,1,1,2.01354265213013,0,2084574112,2.0122195482254,,,,,,,,,,,,,,,,,,,,,,,,,,,,,,,,,
,3874209183.96091,2.03424274921417,49999.6953125,0.181542194618134,6.45152231562216E-5,1,2,13.1008939743042,1.99650484121956,25.2199992537498,43.8773525444441,6.47998061257304,100,0.000200947733184977,,,,,,,,,,,,,,,,,,,,,2.03341698646545,2.03506851196289,49999.6953125,49999.6953125,52.9021814385825,5.74462787749287,2.48633766174316,26,1,0,0,1,0.133590698242188,31.2805480957031,6,1,1,2.03506851196289,0,2084573952,2.03424274921417,,,,,,,,,,,,,,,,,,,,,,,,,,,,,,,,,
,3874209249.48079,1.99955880641937,49999.6953125,0.181634625279151,5.04389949910778E-5,1,2,13.1008939743042,1.99630600230016,25.2199992537498,43.8902222245642,6.49014164221631,100,0.000234504159395538,,,,,,,,,,,,,,,,,,,,,1.99944829940796,1.99966931343079,49999.6953125,49999.6953125,52.8978824817268,5.74505154493549,2.45854949951172,26,1,0,0,1,0.136489868164062,30.7917900085449,5,1,1,1.99966931343079,0,2084574400,1.99955880641937,,,,,,,,,,,,,,,,,,,,,,,,,,,,,,,,,
,3874209788.58722,29.0108814239502,26.2300281524658,1.845043330122E-5,4.45852221895527E-8,1,2,13.1008939743042,1.9972028683164,25.2199992537498,0.00446215055668264,0.000659910058293329,1,2.41537322691702E-8,,,,,,,,,,,,,,,,,,,,,29.0108814239502,29.0108814239502,26.2300281524658,26.2300281524658,51.6660359354189,5.73652710509522,5.97565269470215,26,1,0,0,1,0.130767822265625,30.7917900085449,2,1,1,29.0108814239502,0,2084574272,29.0108814239502,,,,,,,,,,,,,,,,,,,,,,,,,,,,,,,,,
,3874209999.75842,62.0301208496094,26.2300281524658,7.91759235211925E-6,4.65238578886709E-8,1,2,13.1008939743042,1.9980891976405,25.2500008791685,0.00191781885684886,0.000274036074288974,1,-2.84123171550473E-8,,,,,,,,,,,,,,,,,,,,,62.0301208496094,62.0301208496094,26.2300281524658,26.2300281524658,51.6887031624766,5.72728021554761,6.79170656204224,26,1,0,0,1,0.130615234375,32.2580642700195,2,1,1,62.0301208496094,0,2084574112,62.0301208496094,,,,,,,,,,,,,,,,,,,,,,,,,,,,,,,,,
,3874210204.3278,95.0012969970703,26.2300281524658,5.40862055958448E-6,3.86620387442286E-8,1,2,13.1008939743042,1.99816812109252,25.3100004047155,0.00131005697336847,0.000188102898163881,1,-1.57290701998191E-8,,,,,,,,,,,,,,,,,,,,,95.0012969970703,95.0012969970703,26.2300281524658,26.2300281524658,51.5976434399862,5.73394721977599,7.17508888244629,26,1,0,0,1,0.135421752929688,30.7917900085449,2,1,1,95.0012969970703,0,2084574176,95.0012969970703,,,,,,,,,,,,,,,,,,,,,,,,,,,,,,,,,
,3874210404.39613,128.024444580078,26.2300281524658,3.86574123332715E-6,8.46070949025443E-8,1,2,13.1008939743042,1.9969026261119,25.3800004720688,0.000936666776305261,0.000124429873925221,1,-5.19865543476947E-8,,,,,,,,,,,,,,,,,,,,,128.024444580078,128.024444580078,26.2300281524658,26.2300281524658,51.6851858341401,5.74141839679326,7.3110203742981,26,1,0,0,1,0.130615234375,32.2580642700195,2,1,1,128.024444580078,0,2084574528,128.024444580078,,,,,,,,,,,,,,,,,,,,,,,,,,,,,,,,,
,3874210603.38503,161.038436889648,26.2300281524658,3.09441500220736E-6,4.28563155469595E-8,1,2,13.1008939743042,1.99660716505901,25.4900008440018,0.000748555294788748,0.000106462128337903,1,-1.31241268698527E-8,,,,,,,,,,,,,,,,,,,,,161.038436889648,161.038436889648,26.2300281524658,26.2300281524658,51.7062898041593,5.74138168582068,7.43848657608032,26,1,0,0,1,0.130844116210938,30.7917900085449,2,1,1,161.038436889648,0,2084574144,161.038436889648,,,,,,,,,,,,,,,,,,,,,,,,,,,,,,,,,
,3874210802.60613,194.01806640625,26.2300281524658,2.50506691258423E-6,4.30319321482119E-8,1,2,13.1008939743042,1.99641372106212,25.6099998950958,0.000603710741284032,0.000100955692879699,1,5.05464202327495E-8,,,,,,,,,,,,,,,,,,,,,194.01806640625,194.01806640625,26.2300281524658,26.2300281524658,51.8024301120247,5.74204560441609,7.62371778488159,25,1,64,0,0,0.130615234375,30.7917900085449,2,1,1,194.01806640625,0,2084574304,194.01806640625,,,,,,,,,,,,,,,,,,,,,,,,,,,,,,,,,
,3874211001.33903,227.005966186523,26.2300281524658,2.09877015126711E-6,3.80665005219129E-8,1,2,13.1008939743042,1.99786994084368,25.7600005716085,0.000508475662509717,7.11785903023474E-5,1,-1.35093301110919E-8,,,,,,,,,,,,,,,,,,,,,227.005966186523,227.005966186523,26.2300281524658,26.2300281524658,51.7078530611978,5.72977783994624,7.90916156768799,24,1,64,0,0,0.131378173828125,31.2805480957031,2,1,1,227.005966186523,0,2084574464,227.005966186523,,,,,,,,,,,,,,,,,,,,,,,,,,,,,,,,,
,3874211200.91599,260.060607910156,26.2300281524658,1.80359040191564E-6,4.47987059777171E-8,1,2,13.1008939743042,1.99878367840156,25.9300004690886,0.000435275109060739,7.53123829477853E-5,1,4.6559337258415E-8,,,,,,,,,,,,,,,,,,,,,260.060607910156,260.060607910156,26.2300281524658,26.2300281524658,51.7336468023324,5.71750067225134,8.4733772277832,26,1,0,0,1,0.132980346679688,30.7917900085449,2,1,1,260.060607910156,0,2084574464,260.060607910156,,,,,,,,,,,,,,,,,,,,,,,,,,,,,,,,,
,3874211399.71216,293.037078857422,26.2300281524658,1.69936238412297E-6,4.45670867918613E-8,1,2,13.1008939743042,1.99947389228961,26.1300001293421,0.000411070617627206,6.63575230743922E-5,1,2.46904914612296E-8,,,,,,,,,,,,,,,,,,,,,293.037078857422,293.037078857422,26.2300281524658,26.2300281524658,51.6898756052555,5.71781371872355,8.70130157470703,26,1,0,0,1,0.132522583007812,31.2805480957031,2,1,1,293.097717285156,0,2084574336,293.037078857422,,,,,,,,,,,,,,,,,,,,,,,,,,,,,,,,,
,3874213032.09079,1.99946630001068,42092.486328125,0.174482161023712,5.23158540799987E-5,1,2,13.1008939743042,1.97824356529752,25.2100005745888,41.4630019953385,5.98034023950471,1000,-0.000396406658966867,,,,,,,,,,,,,,,,,,,,,1.99913775920868,1.99979484081268,42002.4921875,42182.48046875,52.5055049650729,5.72986742694708,2.49055743217468,26,1,0,0,1,0.132522583007812,31.2805480957031,1,6,1,1.99979484081268,0,2084573184,1.99946630001068,,,,,,,,,,,,,,,,,,,,,,,,,,,,,,,,,
,3874213097.58627,1.99926924705505,35551.673828125,0.165283874093786,3.75970042458076E-5,1,2,13.1008939743042,1.97828792315744,25.2100005745888,39.275885680306,5.68548599847284,1000,-0.000290589161478555,,,,,,,,,,,,,,,,,,,,,1.99920403957367,1.99933445453644,35461.7734375,35641.57421875,52.4550899255825,5.73018700615744,2.48671388626099,26,1,0,0,1,0.129928588867188,30.7917900085449,1,6,1,1.99933445453644,0,2084573184,1.99926924705505,,,,,,,,,,,,,,,,,,,,,,,,,,,,,,,,,
,3874213163.02632,1.99988198280334,29016.0517578125,0.153368564530517,2.99443460667042E-5,1,2,13.1008939743042,1.97814415765384,25.2100005745888,36.4380148830759,5.28476171026138,1000,-0.000228088828606327,,,,,,,,,,,,,,,,,,,,,1.99982571601868,1.99993824958801,28921.11328125,29110.990234375,52.2542113961401,5.73157129592731,2.48395276069641,26,1,0,0,1,0.129470825195312,30.7917900085449,1,6,1,1.99982571601868,0,2084573184,1.99988198280334,,,,,,,,,,,,,,,,,,,,,,,,,,,,,,,,,
,3874213228.52663,1.99738043546677,22480.7578125,0.13740854778412,3.48546312010902E-5,1,2,13.1008939743042,1.97814201483355,25.2100005745888,32.6447151704315,4.74420428014292,1000,-0.000164774228783121,,,,,,,,,,,,,,,,,,,,,1.99728453159332,1.99747633934021,22390.837890625,22570.677734375,52.018550397592,5.73095289354707,2.48052144050598,26,1,0,0,1,0.1312255859375,30.3030319213867,1,6,1,1.99728453159332,0,2084573184,1.99738043546677,,,,,,,,,,,,,,,,,,,,,,,,,,,,,,,,,
,3874213321.10606,1.99987637996674,13233.220703125,0.104153493762175,7.5752915770321E-5,1,2,13.1008939743042,1.97801682640459,25.2100005745888,24.7397514121054,3.6055015910822,1000,-8.32036141992868E-5,,,,,,,,,,,,,,,,,,,,,1.99987637996674,1.99987637996674,13233.220703125,13233.220703125,51.7668660143997,5.73088692412696,2.48187899589539,26,1,0,0,1,0.128021240234375,30.7917900085449,1,6,1,1.99987637996674,0,2084573184,1.99987637996674,,,,,,,,,,,,,,,,,,,,,,,,,,,,,,,,,
,3874213440.8725,2.00012111663818,1260.03631591797,0.0168906626990754,0.000121660499300711,1,2,13.1008939743042,1.97763155819546,25.2100005745888,4.02121282988393,0.511964478423726,1000,-0.000318976747976788,,,,,,,,,,,,,,,,,,,,,1.99989032745361,2.00035190582275,1169.98034667969,1350.09228515625,51.6445411511401,5.73428544726775,2.47325468063354,26,1,0,0,1,0.12725830078125,31.2805480957031,1,6,1,1.99989032745361,0,2084573184,2.00012111663818,,,,,,,,,,,,,,,,,,,,,,,,,,,,,,,,,
,3874213526.2372,2.00002771615982,-7274.474609375,-0.0684865647967942,7.64644344437246E-5,1,2,13.1008939743042,1.97766330323617,25.2100005745888,-16.2547085074482,-2.42118404846091,100,-0.000160835191848895,,,,,,,,,,,,,,,,,,,,,1.99968588352203,2.00036954879761,-7359.388671875,-7189.560546875,51.6707257065343,5.73428420783201,2.46662449836731,26,1,0,0,1,0.1336669921875,30.7917900085449,1,6,1,2.00036954879761,0,2084573184,2.00002771615982,,,,,,,,,,,,,,,,,,,,,,,,,,,,,,,,,
,3874213591.72401,2.00017046928406,-13826.2827148438,-0.105796947830325,5.31674795606861E-5,1,2,13.1008939743042,1.97754683250155,25.2100005745888,-25.1122887317967,-3.70510787491368,100,-0.00010236965444688,,,,,,,,,,,,,,,,,,,,,2.00015664100647,2.00018429756165,-13911.3935546875,-13741.171875,51.7234856315824,5.7361803578604,2.45478963851929,26,1,0,0,1,0.131607055664062,31.2805480957031,1,6,1,2.00015664100647,0,2084573184,2.00017046928406,,,,,,,,,,,,,,,,,,,,,,,,,,,,,,,,,
,3874213665.13418,2.00004386901855,-21173.6884765625,-0.133266720465056,5.91125586437476E-5,1,2,13.1008939743042,1.97732576313256,25.2100005745888,-31.6266273345799,-4.66107746050554,100,-0.000107642433558581,,,,,,,,,,,,,,,,,,,,,1.99993562698364,2.00015211105347,-21263.787109375,-21083.58984375,51.9130305474959,5.73748734533461,2.44299602508545,26,1,0,0,1,0.127029418945312,30.7917900085449,1,6,1,1.99993562698364,0,2084573184,2.00004386901855,,,,,,,,,,,,,,,,,,,,,,,,,,,,,,,,,
,3874213772.32038,2.00002789497375,-31902.9794921875,-0.158737230058283,3.70865134232273E-5,1,2,13.1008939743042,1.97722826608185,25.2100005745888,-37.667384232012,-5.55368496562295,100,-0.000137830839861883,,,,,,,,,,,,,,,,,,,,,1.99992823600769,2.00012755393982,-31998.208984375,-31807.75,52.1737036586594,5.7382555293136,2.42728710174561,24,1,68,0,0,0.132598876953125,30.7917900085449,1,6,1,1.99992823600769,0,2084573184,2.00002789497375,,,,,,,,,,,,,,,,,,,,,,,,,,,,,,,,,
,3874213897.47561,1.99978798627853,-44449.166015625,-0.176631239351209,0.000269445931476431,1,2,13.1008939743042,1.97717270586375,25.2100005745888,-41.9158352832806,-6.14838311130335,100,-2.26379259897456E-5,,,,,,,,,,,,,,,,,,,,,1.99971747398376,1.9998584985733,-44524.3828125,-44373.94921875,52.7755576184671,5.73957737755446,2.41903781890869,26,1,0,0,1,0.128097534179688,31.2805480957031,1,6,1,1.9998584985733,0,2084573184,1.99978798627853,,,,,,,,,,,,,,,,,,,,,,,,,,,,,,,,,
,3874214000.53676,1.99997025728226,-45779.2734375,-0.178927510200943,7.12699491493501E-5,1,2,13.1008939743042,1.97717710962977,25.2100005745888,-42.4783128621077,-6.10977047624046,1000,0.000476705195883801,,,,,,,,,,,,,,,,,,,,,1.99976480007172,2.0001757144928,-45869.25390625,-45689.29296875,52.7333496784287,5.73915443031617,2.4152467250824,26,1,0,0,1,0.128936767578125,30.7917900085449,1,6,1,1.99976480007172,0,2084573184,1.99997025728226,,,,,,,,,,,,,,,,,,,,,,,,,,,,,,,,,
,3874214066.00749,2.0001118183136,-39244.30859375,-0.170743402846211,5.01505055925903E-5,1,2,13.1008939743042,1.9769116043652,25.2100005745888,-40.5203290442434,-5.86090950934585,1000,0.00031966563088259,,,,,,,,,,,,,,,,,,,,,1.9995219707489,2.0007016658783,-39339.21484375,-39149.40234375,52.5821045599575,5.74208850367017,2.41203761100769,26,1,0,0,1,0.128326416015625,29.8142719268799,1,6,1,2.0007016658783,0,2084573184,2.0001118183136,,,,,,,,,,,,,,,,,,,,,,,,,,,,,,,,,
,3874214131.50807,1.99980038404465,-32705.26953125,-0.160554632783994,6.04566162934651E-5,1,2,13.1008939743042,1.97684114178688,25.2100005745888,-38.0966053030917,-5.53247226093695,1000,0.000209231131719281,,,,,,,,,,,,,,,,,,,,,1.99969756603241,1.99990320205688,-32800.2265625,-32610.3125,52.4347675840825,5.74267150038107,2.41567778587341,26,1,0,0,1,0.129318237304688,30.3030319213867,1,6,1,1.99990320205688,0,2084573184,1.99980038404465,,,,,,,,,,,,,,,,,,,,,,,,,,,,,,,,,
,3874214196.97696,1.99999493360519,-26170.798828125,-0.14702835285416,9.84326927972054E-5,1,2,13.1008939743042,1.97687698215559,25.2100005745888,-34.8855129722326,-5.08538632044282,1000,0.000112213015283314,,,,,,,,,,,,,,,,,,,,,1.99990332126617,2.00008654594421,-26260.421875,-26081.17578125,52.0779541650536,5.74126052284667,2.41749095916748,25,1,68,0,0,0.12786865234375,30.7917900085449,1,6,1,1.99990332126617,0,2084573184,1.99999493360519,,,,,,,,,,,,,,,,,,,,,,,,,,,,,,,,,
,3874214262.54569,2.00015771389008,-19626.09765625,-0.128724834961445,5.19821099379724E-5,1,2,13.1008939743042,1.97699641014534,25.2100005745888,-30.5475864759083,-4.44286799022352,1000,0.000140181495128914,,,,,,,,,,,,,,,,,,,,,2.00007891654968,2.00023651123047,-19710.94921875,-19541.24609375,51.9317896319574,5.74097763942252,2.42122960090637,26,1,0,0,1,0.129318237304688,30.7917900085449,1,6,1,2.00007891654968,0,2084573184,2.00015771389008,,,,,,,,,,,,,,,,,,,,,,,,,,,,,,,,,
,3874214327.97292,1.99992126226425,-13090.75390625,-0.10286774133109,5.51665835897731E-5,1,2,13.1008939743042,1.9771968290715,25.2100005745888,-24.4162640343104,-3.550387441416,1000,0.00011505801492558,,,,,,,,,,,,,,,,,,,,,1.99991977214813,1.99992275238037,-13180.7109375,-13000.796875,51.8391666524286,5.73796560004514,2.42709875106812,26,1,0,0,1,0.132369995117188,31.7693061828613,1,6,1,1.99992275238037,0,2084573184,1.99992126226425,,,,,,,,,,,,,,,,,,,,,,,,,,,,,,,,,
,3874214443.10091,2.00032079219818,-1587.88073730469,-0.0204887059843114,0.00011611912453497,1,2,13.1008939743042,1.9768410179079,25.2100005745888,-4.87133013971007,-0.639516879380969,1000,0.000306983300068577,,,,,,,,,,,,,,,,,,,,,2.00023150444031,2.00041007995605,-1677.90588378906,-1497.85559082031,51.7520150725343,5.7417724767865,2.43204474449158,26,1,0,0,1,0.130081176757812,30.3030319213867,1,6,1,2.00041007995605,0,2084573184,2.00032079219818,,,,,,,,,,,,,,,,,,,,,,,,,,,,,,,,,
,3874214532.49318,2.00038981437683,7351.9658203125,0.0689992005499535,7.51456689656409E-5,1,2,13.1008939743042,1.97679387294912,25.2100005745888,16.363398694034,2.43260260015325,1000,0.000142356396718044,,,,,,,,,,,,,,,,,,,,,2.00037384033203,2.00040578842163,7271.8359375,7432.095703125,51.6461044081785,5.74268773860773,2.43184638023376,26,1,0,0,1,0.128250122070312,30.3030319213867,1,6,1,2.00037384033203,0,2084573184,2.00038981437683,,,,,,,,,,,,,,,,,,,,,,,,,,,,,,,,,
,3874214601.89443,2.00005161762238,14294.3813476563,0.10793930478597,5.68846634612482E-5,1,2,13.1008939743042,1.97666744976331,25.2100005745888,25.5985672664587,3.78113865682751,100,0.000122123217777653,,,,,,,,,,,,,,,,,,,,,1.99994516372681,2.00015807151794,14204.337890625,14384.4248046875,51.8528451515151,5.74489079239447,2.42310547828674,26,1,0,0,1,0.12969970703125,30.7917900085449,1,6,1,2.00015807151794,0,2084573184,2.00005161762238,,,,,,,,,,,,,,,,,,,,,,,,,,,,,,,,,
,3874214667.39276,2.00003004074097,20852.3828125,0.132268918644973,4.286727889337E-5,1,2,13.1008939743042,1.97662262624359,25.2100005745888,31.3673782860373,4.63169717007402,100,0.000143266752437698,,,,,,,,,,,,,,,,,,,,,1.99999117851257,2.00006890296936,20767.654296875,20937.111328125,51.9908025851594,5.74322947837117,2.41454100608826,26,1,0,0,1,0.12908935546875,30.3030319213867,1,6,1,2.00006890296936,0,2084573696,2.00003004074097,,,,,,,,,,,,,,,,,,,,,,,,,,,,,,,,,
,3874214756.63784,1.99994075298309,29788.8232421875,0.154668853775647,5.17596178322697E-5,1,2,13.1008939743042,1.97627390855054,25.2100005745888,36.6672443492981,5.41400627063772,100,0.000166425113003469,,,,,,,,,,,,,,,,,,,,,1.99979567527771,2.00008583068848,29698.953125,29878.693359375,52.1596343453132,5.74900896469111,2.40736818313599,26,1,0,0,1,0.13031005859375,30.3030319213867,1,6,1,2.00008583068848,0,2084573856,1.99994075298309,,,,,,,,,,,,,,,,,,,,,,,,,,,,,,,,,
,3874214871.76447,1.99996250867844,41325.06640625,0.173197660178184,5.34682473069289E-5,1,2,13.1008939743042,1.97623371548165,25.2100005745888,41.0582598870823,6.06242824885684,100,0.000186684449469769,,,,,,,,,,,,,,,,,,,,,1.9998859167099,2.00003910064697,41234.82421875,41415.30859375,52.5508394191883,5.74909632315715,2.39943599700928,26,1,0,0,1,0.130157470703125,30.7917900085449,1,6,1,1.9998859167099,0,2084573984,1.99996250867844,,,,,,,,,,,,,,,,,,,,,,,,,,,,,,,,,
,3874215362.39565,9.00909233093262,26.4896049499512,3.40129598454406E-5,2.55685622942543E-6,1,2,13.1008939743042,1.97569035615511,25.2100005745888,0.00813559378169553,0.000666672004953892,10,-2.17143199555448E-6,,,,,,,,,,,,,,,,,,,,,9.00909233093262,9.00909233093262,26.4896049499512,26.4896049499512,51.632425909092,5.75678378321954,4.49948024749756,26,1,0,0,1,0.131454467773438,30.7917900085449,6,1,1,9.00909233093262,0,2084574336,9.00909233093262,,,,,,,,,,,,,,,,,,,,,,,,,,,,,,,,,
,3874215576.81884,42.0312232971191,26.4896049499512,8.97747885474653E-6,4.75941394830394E-8,1,2,13.1008939743042,1.97682297892376,25.2299997955561,0.00213024637597478,0.000308689688529345,1,-1.44619272943082E-8,,,,,,,,,,,,,,,,,,,,,42.0144958496094,42.0479507446289,26.4896049499512,26.4896049499512,51.5777119127458,5.74520559216279,6.25436019897461,26,1,0,0,1,0.128173828125,30.7917900085449,2,1,1,42.0479507446289,0,2084574048,42.0312232971191,,,,,,,,,,,,,,,,,,,,,,,,,,,,,,,,,
,3874215785.21815,75.0277557373047,26.4896049499512,5.99851515893502E-6,4.62958567751102E-8,1,2,13.1008939743042,1.97559327813917,25.2700001001358,0.00142088760056211,0.000211517958015567,1,1.35616697454691E-8,,,,,,,,,,,,,,,,,,,,,75.0277557373047,75.0277557373047,26.4896049499512,26.4896049499512,51.6558747646689,5.7550517982819,7.27477359771729,24,1,64,0,0,0.131301879882812,30.3030319213867,2,1,1,75.0277557373047,0,2084574272,75.0277557373047,,,,,,,,,,,,,,,,,,,,,,,,,,,,,,,,,
,3874215987.52693,108.008094787598,26.4896049499512,4.40016589530951E-6,3.99758929908419E-8,1,2,13.1008939743042,1.98529639855338,25.3400001674891,0.00105206928820287,0.000156252624471082,1,8.46744236886678E-9,,,,,,,,,,,,,,,,,,,,,108.008094787598,108.008094787598,26.4896049499512,26.4896049499512,51.5382396725247,5.76370542831443,7.47593975067139,26,1,0,0,1,0.136947631835938,30.7917900085449,2,1,1,108.008094787598,0,2084574400,108.008094787598,,,,,,,,,,,,,,,,,,,,,,,,,,,,,,,,,
,3874216186.96026,141.002883911133,26.4896049499512,4.62475442645179E-6,1.22572412921879E-6,1,2,13.1008939743042,1.98513017359367,25.4200007766485,0.00112537303086491,2.92284948067884E-5,1,-5.55542134757586E-7,,,,,,,,,,,,,,,,,,,,,141.002883911133,141.002883911133,26.4896049499512,26.4896049499512,51.7000367760055,5.7688988579117,7.58315372467041,26,1,0,0,1,0.1397705078125,30.7917900085449,2,1,1,141.002883911133,0,2084574240,141.002883911133,,,,,,,,,,,,,,,,,,,,,,,,,,,,,,,,,
,3874216386.3573,174.033676147461,26.4896049499512,2.72312981147254E-6,6.51423553796868E-8,1,2,13.1008939743042,1.98553180156297,25.5399998277426,0.0006483423753112,0.000116496055071099,1,8.79020906352426E-8,,,,,,,,,,,,,,,,,,,,,174.033676147461,174.033676147461,26.4896049499512,26.4896049499512,51.6343799803901,5.76338756105008,7.68991661071777,25,1,64,0,0,0.13946533203125,30.7917900085449,2,1,1,174.033676147461,0,2084574336,174.033676147461,,,,,,,,,,,,,,,,,,,,,,,,,,,,,,,,,
,3874216585.04855,207.0283203125,26.4896049499512,2.24982992785469E-6,3.95114949796152E-8,1,2,13.1008939743042,1.9857064236942,25.6699994206429,0.000539353689701689,7.16410444334717E-5,1,-3.02904409318857E-8,,,,,,,,,,,,,,,,,,,,,207.0283203125,207.0283203125,26.4896049499512,26.4896049499512,51.708634689717,5.76117550719906,7.86727714538574,26,1,0,0,1,0.1373291015625,30.3030319213867,2,1,1,207.0283203125,0,2084574400,207.0283203125,,,,,,,,,,,,,,,,,,,,,,,,,,,,,,,,,
,3874216783.83879,240.013641357422,26.4896049499512,1.93903047385516E-6,4.78060632408663E-8,1,2,13.1008939743042,1.98628137319871,25.8200000971556,0.000463124432843447,7.52636985151935E-5,1,3.02266585961159E-8,,,,,,,,,,,,,,,,,,,,,240.013641357422,240.013641357422,26.4896049499512,26.4896049499512,51.6824501343228,5.75609191071922,8.2910852432251,24,1,64,0,0,0.1385498046875,30.3030319213867,2,1,1,240.05094909668,0,2084574336,240.013641357422,,,,,,,,,,,,,,,,,,,,,,,,,,,,,,,,,
,3874216982.83822,273.066986083984,26.4896049499512,1.72062563506312E-6,3.25815315464583E-8,1,2,13.1008939743042,1.9874715250933,26.0000005364418,0.000408856138071574,8.44045421784065E-5,1,1.00018122172397E-7,,,,,,,,,,,,,,,,,,,,,273.066986083984,273.066986083984,26.4896049499512,26.4896049499512,51.7184050462074,5.74698306167006,8.96555042266846,25,1,64,0,0,0.13519287109375,29.8142719268799,2,1,1,273.066986083984,0,2084574208,273.066986083984,,,,,,,,,,,,,,,,,,,,,,,,,,,,,,,,,
,3874217771.20265,296.949890136719,26.4525241851807,2.14299252299857E-6,4.62132322837333E-8,1,2,13.1008939743042,1.9973268881454,26.1300001293421,0.000517581376598558,8.17898090369729E-5,1,2.40237503688969E-8,,,,,,,,,,,,,,,,,,,,,296.949890136719,296.949890136719,26.4525241851807,26.4525241851807,51.6597829072651,5.73420511244922,9.1996431350708,26,1,0,0,1,0.134124755859375,30.7917900085449,2,1,1,296.949890136719,0,2084573184,296.949890136719,,,,,,,,,,,,,,,,,,,,,,,,,,,,,,,,,
,3874217950.84296,263.977722167969,26.4525241851807,2.17357010005529E-6,4.96521136058679E-8,1,2,13.1008939743042,1.99688000211419,25.9700007736683,0.000523016023480304,9.47124555783017E-5,1,7.3125543932902E-8,,,,,,,,,,,,,,,,,,,,,263.977722167969,263.977722167969,26.4525241851807,26.4525241851807,51.6230463668612,5.74009054733767,9.6538667678833,24,1,64,0,0,0.131607055664062,29.8142719268799,2,1,1,263.977722167969,0,2084574272,263.977722167969,,,,,,,,,,,,,,,,,,,,,,,,,,,,,,,,,
,3874218150.24432,230.984100341797,26.4525241851807,2.16009204004826E-6,3.87799535354638E-8,1,2,13.1008939743042,1.99681473882473,25.8300006389618,0.000520210842914653,9.09111139238907E-5,1,5.94042095093621E-8,,,,,,,,,,,,,,,,,,,,,230.984100341797,230.984100341797,26.4525241851807,26.4525241851807,51.7129336465728,5.73917654747451,9.3337459564209,26,1,0,0,1,0.130691528320312,31.2805480957031,2,1,1,230.984100341797,0,2084574016,230.984100341797,,,,,,,,,,,,,,,,,,,,,,,,,,,,,,,,,
,3874218346.81273,197.952850341797,26.4525241851807,2.11576738299006E-6,4.38834267185248E-8,1,2,13.1008939743042,1.99502288198001,25.7099997252226,0.000510728453742017,7.48487186583849E-5,1,-4.7906318785234E-13,,,,,,,,,,,,,,,,,,,,,197.952850341797,197.952850341797,26.4525241851807,26.4525241851807,51.6910480480343,5.75456771423478,9.11230945587158,26,1,0,0,1,0.132904052734375,31.2805480957031,2,1,1,197.952850341797,0,2084573184,197.952850341797,,,,,,,,,,,,,,,,,,,,,,,,,,,,,,,,,
,3874218544.79437,164.971633911133,26.4525241851807,2.19043169202384E-6,4.12601703184681E-8,1,2,13.1008939743042,1.99554465428374,25.6099998950958,0.000529463074932149,7.44636504357524E-5,1,-1.26908133312559E-8,,,,,,,,,,,,,,,,,,,,,164.971633911133,164.971633911133,26.4525241851807,26.4525241851807,51.6484492937362,5.74968031221583,8.93481826782227,26,1,0,0,1,0.139083862304688,30.7917900085449,2,1,1,164.971633911133,0,2084573728,164.971633911133,,,,,,,,,,,,,,,,,,,,,,,,,,,,,,,,,
,3874218743.28447,131.965950012207,26.4525241851807,2.31549895272126E-6,4.6167606549412E-8,1,2,13.1008939743042,1.99586773895263,25.4999995231628,0.000560065536866274,7.73753291094182E-5,1,-1.90620099147751E-8,,,,,,,,,,,,,,,,,,,,,131.948791503906,131.983108520508,26.4525241851807,26.4525241851807,51.6207014813035,5.74833413074965,8.78097915649414,24,1,64,0,0,0.131988525390625,31.2805480957031,2,1,1,131.948791503906,0,2084573920,131.965950012207,,,,,,,,,,,,,,,,,,,,,,,,,,,,,,,,,
,3874218941.21317,98.9521102905273,26.4525241851807,2.4724974729029E-6,4.19235193929852E-8,1,2,13.1008939743042,1.9952330243845,25.4100002348423,0.000597042530625995,8.69178503718931E-5,1,-2.35410377716819E-9,,,,,,,,,,,,,,,,,,,,,98.9521102905273,98.9521102905273,26.4525241851807,26.4525241851807,51.637506494467,5.75330157216237,8.61731815338135,26,1,0,0,1,0.132904052734375,30.7917900085449,2,1,1,98.9521102905273,0,2084574080,98.9521102905273,,,,,,,,,,,,,,,,,,,,,,,,,,,,,,,,,
,3874219135.17456,65.9818267822266,26.4525241851807,2.86131788495286E-6,4.05892948045887E-8,1,2,13.1008939743042,1.9957020922199,25.3299996256828,0.000691949845159389,9.57891352987409E-5,1,-2.27703874994617E-8,,,,,,,,,,,,,,,,,,,,,65.9818267822266,65.9818267822266,26.4525241851807,26.4525241851807,51.5886547120151,5.74858841636538,8.30331230163574,26,1,0,0,1,0.133590698242188,31.2805480957031,2,1,1,65.9818267822266,0,2084573184,65.9818267822266,,,,,,,,,,,,,,,,,,,,,,,,,,,,,,,,,
,3874219328.11782,32.9896545410156,26.4525241851807,4.11957333060321E-6,4.53924286048791E-8,1,2,13.1008939743042,1.99614432513184,25.2700001001358,0.000995652103846024,0.000144785969490896,1,-4.57760179986309E-9,,,,,,,,,,,,,,,,,,,,,32.9896545410156,32.9896545410156,26.4525241851807,26.4525241851807,51.6937837478516,5.74264346043607,7.5642147064209,26,1,0,0,1,0.133209228515625,31.2805480957031,2,1,1,32.9896545410156,0,2084573184,32.9896545410156,,,,,,,,,,,,,,,,,,,,,,,,,,,,,,,,,
,3874219692.74054,2.10425877571106,26.4525241851807,2.93553627333248E-5,3.96097651342693E-8,1,2,13.1008939743042,1.99378333028382,25.2100005745888,0.00707843815275987,0.00103288331287059,1,-1.82053602470523E-8,,,,,,,,,,,,,,,,,,,,,2.10425877571106,2.10425877571106,26.4525241851807,26.4525241851807,51.4471799500343,5.77361081238561,2.6541531085968,26,1,0,0,1,0.136032104492188,30.7917900085449,6,1,1,2.10425877571106,0,2084574272,2.10425877571106,,,,,,,,,,,,,,,,,,,,,,,,,,,,,,,,,
,3874219912.22988,35.0202445983887,26.4525241851807,4.10478581691425E-6,4.06628372547783E-8,1,2,13.1008939743042,1.99523258174198,25.2199992537498,0.000990505777627962,0.000149011717675452,1,1.5610841778934E-8,,,,,,,,,,,,,,,,,,,,,35.0202445983887,35.0202445983887,26.4525241851807,26.4525241851807,51.5929536688708,5.75577018824878,6.23552942276001,26,1,0,0,1,0.137863159179688,30.7917900085449,2,1,1,35.0202445983887,0,2084574240,35.0202445983887,,,,,,,,,,,,,,,,,,,,,,,,,,,,,,,,,
,3874220121.60698,68.0007476806641,26.4525241851807,2.97479553573441E-6,3.40629294477369E-8,1,2,13.1008939743042,1.99461251251692,25.2599995583296,0.00071597634928859,0.000117713820619762,1,5.18714207794165E-8,,,,,,,,,,,,,,,,,,,,,68.0007476806641,68.0007476806641,26.4525241851807,26.4525241851807,51.6664267496785,5.75886649937298,7.14190912246704,26,1,0,0,1,0.136566162109375,30.7917900085449,2,1,1,68.0007476806641,0,2084574240,68.0007476806641,,,,,,,,,,,,,,,,,,,,,,,,,,,,,,,,,
,3874220325.64464,101.031509399414,26.4525241851807,2.53712225860806E-6,4.02526752012807E-8,1,2,13.1008939743042,1.99386653138103,25.3199990838766,0.00061220441221394,8.66738454650988E-5,1,-1.23692302882805E-8,,,,,,,,,,,,,,,,,,,,,101.031509399414,101.031509399414,26.4525241851807,26.4525241851807,51.5585620140247,5.76905965995367,7.83192300796509,26,1,0,0,1,0.138397216796875,30.7917900085449,2,1,1,101.031509399414,0,2084574368,101.031509399414,,,,,,,,,,,,,,,,,,,,,,,,,,,,,,,,,
,3874220525.41738,134.063125610352,26.4525241851807,2.29490414188813E-6,3.72188702451856E-8,1,2,13.1008939743042,1.99296191924343,25.3999996930361,0.000552827588815311,8.14279625999365E-5,1,1.6634616200085E-9,,,,,,,,,,,,,,,,,,,,,134.063125610352,134.063125610352,26.4525241851807,26.4525241851807,51.6566563931882,5.7788705113805,7.9443736076355,26,1,0,0,1,0.13671875,30.7917900085449,2,1,1,134.063125610352,0,2084574240,134.063125610352,,,,,,,,,,,,,,,,,,,,,,,,,,,,,,,,,
,3874220724.51046,167.020797729492,26.4525241851807,2.11389438685297E-6,4.35845095286143E-8,1,2,13.1008939743042,1.99380268012597,25.5100000649691,0.000509736519507686,7.43439026118129E-5,1,-1.45991548635316E-9,,,,,,,,,,,,,,,,,,,,,167.020797729492,167.020797729492,26.4525241851807,26.4525241851807,51.6488401079959,5.76994873442314,8.05159759521484,26,1,0,0,1,0.13763427734375,30.7917900085449,2,1,1,167.020797729492,0,2084574336,167.020797729492,,,,,,,,,,,,,,,,,,,,,,,,,,,,,,,,,
,3874220923.80174,200.033508300781,26.4525241851807,2.07181400811763E-6,3.7873807424427E-8,1,2,13.1008939743042,1.99375889777935,25.6399996578693,0.000498858978375689,7.7703163099029E-5,1,1.8652884195231E-8,,,,,,,,,,,,,,,,,,,,,200.033508300781,200.033508300781,26.4525241851807,26.4525241851807,51.7856250988613,5.77013914021577,8.18831539154053,24,1,64,0,0,0.135726928710938,30.7917900085449,2,1,1,200.033508300781,0,2084574144,200.033508300781,,,,,,,,,,,,,,,,,,,,,,,,,,,,,,,,,
,3874221121.99658,233.050262451172,26.4525241851807,1.92646020466058E-6,5.07250985444593E-8,1,2,13.1008939743042,1.99447789827127,25.7900003343821,0.000462770376999746,8.19009859163907E-5,1,5.71338597941748E-8,,,,,,,,,,,,,,,,,,,,,233.050262451172,233.050262451172,26.4525241851807,26.4525241851807,51.6863582769189,5.76577252877215,8.42598915100098,26,1,0,0,1,0.135650634765625,30.7917900085449,2,1,1,233.050262451172,0,2084574240,233.050262451172,,,,,,,,,,,,,,,,,,,,,,,,,,,,,,,,,
,3874221321.23421,266.003967285156,26.4525241851807,1.8590238134889E-6,4.78940444498413E-8,1,2,13.1008939743042,1.99509758801265,25.9600002318621,0.000445498031827865,8.8196203858565E-5,1,9.28940704340536E-8,,,,,,,,,,,,,,,,,,,,,266.003967285156,266.003967285156,26.4525241851807,26.4525241851807,51.6797144345055,5.75670202651992,8.87406349182129,25,1,64,0,0,0.133743286132812,30.7917900085449,2,1,1,266.003967285156,0,2084574336,266.003967285156,,,,,,,,,,,,,,,,,,,,,,,,,,,,,,,,,
,3874221530.8776,299.003173828125,26.4525241851807,1.80837758901067E-6,4.87830415337386E-8,1,2,13.1008939743042,1.99575934545743,26.1499993503094,0.000435389275258422,7.38675352159206E-5,1,4.07697751446577E-8,,,,,,,,,,,,,,,,,,,,,299.003173828125,299.003173828125,26.4525241851807,26.4525241851807,51.7117612037939,5.74745597821369,8.83135509490967,26,1,0,0,1,0.1324462890625,30.7917900085449,6,1,1,299.003173828125,0,2084574400,299.003173828125,,,,,,,,,,,,,,,,,,,,,,,,,,,,,,,,,
,3874221855.54506,299.999633789063,40410.22265625,0.00426115321839923,1.48158685564472E-5,1,2,13.1008939743042,1.9761808572347,26.1499993503094,1.02159632900897,0.0706885552284419,100,-0.000326328874509358,,,,,,,,,,,,,,,,,,,,,299.99951171875,299.999755859375,40325.31640625,40495.12890625,51.6789328059862,5.75026320968396,8.78064346313477,25,1,68,0,0,0.129852294921875,32.2580642700195,1,6,1,299.99951171875,0,2084573184,299.999633789063,,,,,,,,,,,,,,,,,,,,,,,,,,,,,,,,,
,3874221920.95878,300.002502441406,33874.361328125,0.00354962053286275,1.5530217876142E-5,1,2,13.1008939743042,1.97611611920949,26.1499993503094,0.850947583654536,0.0589384722500523,100,-0.000271596614602464,,,,,,,,,,,,,,,,,,,,,300.002258300781,300.002746582031,33784.3984375,33964.32421875,51.6343799803901,5.75028634831846,8.84758758544922,24,1,68,0,0,0.130767822265625,31.2805480957031,1,6,1,300.002746582031,0,2084573856,300.002502441406,,,,,,,,,,,,,,,,,,,,,,,,,,,,,,,,,
,3874222004.32396,300.003463745117,25550.68359375,0.00268017210117,3.00813305716118E-5,1,2,13.1008939743042,1.97633959474683,26.1499993503094,0.642469005378224,0.0457696653353986,100,-0.000199765688826773,,,,,,,,,,,,,,,,,,,,,300.003356933594,300.003570556641,25455.794921875,25645.572265625,51.7062898041593,5.74784424610248,8.98686122894287,25,1,68,0,0,0.129318237304688,30.3030319213867,1,6,1,300.003570556641,0,2084573792,300.003463745117,,,,,,,,,,,,,,,,,,,,,,,,,,,,,,,,,
,3874222087.66085,300.002838134766,17227.6015625,0.00182867281428616,3.98674545689599E-5,1,2,13.1008939743042,1.97694349595327,26.1499993503094,0.437549981968148,0.0384717922980071,100,-0.000105846813761554,,,,,,,,,,,,,,,,,,,,,300.002685546875,300.002990722656,17138.05859375,17317.14453125,51.6406330085439,5.74292354759089,9.19063091278076,26,1,0,0,1,0.128402709960938,30.7917900085449,1,6,1,300.002685546875,0,2084573792,300.002838134766,,,,,,,,,,,,,,,,,,,,,,,,,,,,,,,,,
,3874222153.15271,300.000885009766,10690.107421875,0.00116997933444342,2.00417992193629E-5,1,2,13.1008939743042,1.97708417105673,26.1499993503094,0.283900156807737,-0.0021249694891857,100,-0.000180419203706772,,,,,,,,,,,,,,,,,,,,,300.000793457031,300.0009765625,10605.1376953125,10775.0771484375,51.7629578718036,5.74082220324098,9.38387298583984,26,1,0,0,1,0.130462646484375,31.2805480957031,1,6,1,300.0009765625,0,2084573760,300.000885009766,,,,,,,,,,,,,,,,,,,,,,,,,,,,,,,,,
,3874222218.64412,300.000701904297,4149.11535644531,0.000507045711647646,3.1567307719257E-5,1,2,13.1008939743042,1.97725193101842,26.1499993503094,0.128006467481187,-0.0346971014267488,100,-0.000220507107553585,,,,,,,,,,,,,,,,,,,,,300.000549316406,300.000854492188,4059.07788085937,4239.15283203125,51.718795860467,5.73934446017234,9.59601020812988,26,1,0,0,1,0.127639770507812,31.2805480957031,1,6,1,300.000549316406,0,2084573824,300.000701904297,,,,,,,,,,,,,,,,,,,,,,,,,,,,,,,,,
,3874222302.01139,300.000839233398,-4189.91284179687,-0.000377234267266359,4.61745153003772E-5,1,2,13.1008939743042,1.97662171872686,26.1499993503094,-0.082508802393694,-0.0606441698151065,100,-0.000200397100068246,,,,,,,,,,,,,,,,,,,,,300.000793457031,300.000885009766,-4279.95654296875,-4099.869140625,51.6953470048901,5.74693774083693,9.85102653503418,25,1,64,0,0,0.12908935546875,30.7917900085449,1,6,1,300.000793457031,0,2084573184,300.000839233398,,,,,,,,,,,,,,,,,,,,,,,,,,,,,,,,,
,3874222367.47794,300.000991821289,-10740.6889648438,-0.00106591985832651,7.81532804898574E-6,1,2,13.1008939743042,1.97633223555913,26.1499993503094,-0.251034763962003,-0.0487517133727054,100,-4.93854539910401E-5,,,,,,,,,,,,,,,,,,,,,300.000732421875,300.001251220703,-10830.7763671875,-10650.6015625,51.7367733164093,5.75038267986969,10.0513973236084,26,1,0,0,1,0.129470825195312,30.7917900085449,1,6,1,300.001251220703,0,2084573184,300.000991821289,,,,,,,,,,,,,,,,,,,,,,,,,,,,,,,,,
,3874222436.93108,300.000411987305,-17683.0615234375,-0.00180177304521973,5.61749083339648E-6,1,2,13.1008939743042,1.976654756072,26.1499993503094,-0.427336338224266,-0.0628539754541131,10,-9.34885744590813E-7,,,,,,,,,,,,,,,,,,,,,300.000183105469,300.000640869141,-17773.228515625,-17592.89453125,51.7277845884382,5.747446514647,10.2715435028076,25,1,68,0,0,0.1287841796875,30.7917900085449,1,6,1,300.000183105469,0,2084573760,300.000411987305,,,,,,,,,,,,,,,,,,,,,,,,,,,,,,,,,
,3874222516.35859,300.00048828125,-25630.27734375,-0.00260881198449773,5.96973357402947E-6,1,2,13.1008939743042,1.97636207488544,26.1499993503094,-0.61872180219522,-0.0899610854106498,100,2.94984606178471E-6,,,,,,,,,,,,,,,,,,,,,300.000305175781,300.000671386719,-25725.328125,-25535.2265625,51.6734614063516,5.75103974768776,10.2217245101929,26,1,0,0,1,0.129623413085938,31.2805480957031,1,6,1,300.000671386719,0,2084573760,300.00048828125,,,,,,,,,,,,,,,,,,,,,,,,,,,,,,,,,
,3874222581.80626,300.00016784668,-32188.908203125,-0.00327818879990615,6.2396996641083E-6,1,2,13.1008939743042,1.97635878881011,26.1499993503094,-0.777726026456446,-0.111315650311028,100,1.09921496917676E-5,,,,,,,,,,,,,,,,,,,,,300.000152587891,300.000183105469,-32279.236328125,-32098.580078125,51.5659874849574,5.7517492384762,10.1658821105957,26,1,0,0,1,0.129776000976562,31.7693061828613,1,6,1,300.000183105469,0,2084573984,300.00016784668,,,,,,,,,,,,,,,,,,,,,,,,,,,,,,,,,
,3874222655.23633,300.000747680664,-39549.01953125,-0.00401198602475417,7.8297078907635E-6,1,2,13.1008939743042,1.97635947775469,26.1499993503094,-0.951189641478701,-0.140497381263262,100,-4.53140484308506E-6,,,,,,,,,,,,,,,,,,,,,300.000732421875,300.000762939453,-39644.28515625,-39453.75390625,51.6230463668612,5.75001615771757,10.1140460968018,24,1,68,0,0,0.129623413085938,30.7917900085449,1,6,1,300.000732421875,0,2084573856,300.000747680664,,,,,,,,,,,,,,,,,,,,,,,,,,,,,,,,,
,3874222736.61479,300.001022338867,-47701.298828125,-0.00482093085328425,5.81512353120043E-6,1,2,13.1008939743042,1.97647508680384,26.1499993503094,-1.14416211727098,-0.161644372264988,100,2.49173479156072E-5,,,,,,,,,,,,,,,,,,,,,300.000762939453,300.001281738281,-47791.50390625,-47611.09375,51.6058505394382,5.74873701614386,10.0678939819336,26,1,0,0,1,0.130233764648438,31.2805480957031,1,6,1,300.000762939453,0,2084573952,300.001022338867,,,,,,,,,,,,,,,,,,,,,,,,,,,,,,,,,
,3874222804.08586,300.000869750977,-46198.50390625,-0.00493491620685899,1.67476805222934E-5,1,2,13.1008939743042,1.97634087160691,26.1499993503094,-1.19008124651796,-0.0356781974361363,100,0.000572763785398346,,,,,,,,,,,,,,,,,,,,,300.000823974609,300.000915527344,-46288.0703125,-46108.9375,51.5909995975728,5.75090280049134,10.0363492965698,23,1,68,0,0,0.129623413085938,29.8142719268799,1,6,1,300.000915527344,0,2084573984,300.000869750977,,,,,,,,,,,,,,,,,,,,,,,,,,,,,,,,,
,3874222869.58985,300.000228881836,-39659.046875,-0.0041929379719309,2.2641626092159E-5,1,2,13.1008939743042,1.97625485848488,26.1499993503094,-1.00831141590721,-0.04910522718042,100,0.000407382478068287,,,,,,,,,,,,,,,,,,,,,300.000213623047,300.000244140625,-39748.9609375,-39569.1328125,51.5624701566208,5.75214783087253,10.006049156189,24,1,68,0,0,0.130081176757812,31.2805480957031,1,6,1,300.000213623047,0,2084574048,300.000228881836,,,,,,,,,,,,,,,,,,,,,,,,,,,,,,,,,
,3874222935.11513,299.999481201172,-33114.9140625,-0.00354889251288114,5.95926063060599E-5,1,2,13.1008939743042,1.97606876215907,26.1499993503094,-0.850433024152915,-0.0609797835816149,100,0.000262867662143831,,,,,,,,,,,,,,,,,,,,,299.999389648438,299.999572753906,-33199.8828125,-33029.9453125,51.6347707946497,5.7541743108799,9.98424625396729,25,1,68,0,0,0.130386352539062,30.7917900085449,1,6,1,299.999572753906,0,2084573856,299.999481201172,,,,,,,,,,,,,,,,,,,,,,,,,,,,,,,,,
,3874223010.46499,300.000106811523,-25591.5,-0.00316391351280249,0.000408266854627811,1,2,13.1008939743042,1.97599030974998,26.1499993503094,-0.759246710218637,-0.0466867335843852,100,0.000266725912797541,,,,,,,,,,,,,,,,,,,,,299.999877929687,300.000335693359,-25681.408203125,-25501.591796875,51.7531875153132,5.75500890085326,9.96103286743164,25,1,68,0,0,0.130767822265625,30.7917900085449,1,6,1,299.999664306641,0,2084573824,300.000106811523,,,,,,,,,,,,,,,,,,,,,,,,,,,,,,,,,
,3874223085.90013,300.00048828125,-18063.3349609375,-0.00193784832458065,0.000244030907630157,1,2,13.1008939743042,1.97587122703149,26.1499993503094,-0.471009404414126,0.0125926574479383,100,0.000337127881334228,,,,,,,,,,,,,,,,,,,,,300.000457763672,300.000518798828,-18153.044921875,-17973.625,51.5847465694189,5.75590846499064,9.93853855133057,25,1,68,0,0,0.131607055664062,30.7917900085449,1,6,1,300.000518798828,0,2084573920,300.00048828125,,,,,,,,,,,,,,,,,,,,,,,,,,,,,,,,,
,3874223161.29971,300.000396728516,-10532.375,-0.00115078490412361,2.57900959775908E-5,1,2,13.1008939743042,1.97583998643165,26.1499993503094,-0.280148167228587,0.0105427493662031,100,0.000213133781696675,,,,,,,,,,,,,,,,,,,,,300.000305175781,300.00048828125,-10622.3935546875,-10442.3564453125,51.6140576388901,5.75667554637452,9.92125511169434,25,1,68,0,0,0.130691528320312,31.2805480957031,1,6,1,300.00048828125,0,2084573696,300.000396728516,,,,,,,,,,,,,,,,,,,,,,,,,,,,,,,,,
,3874223226.85282,300.000564575195,-3976.41381835937,-0.000617591621601684,9.2027663867105E-5,1,2,13.1008939743042,1.97577093024569,26.1499993503094,-0.157705442970971,0.0559351434555467,100,0.000326531011195106,,,,,,,,,,,,,,,,,,,,,300.000549316406,300.000579833984,-4076.43286132812,-3876.39477539063,51.6867490911785,5.75673193614287,9.9101676940918,24,1,68,0,0,0.129852294921875,31.2805480957031,1,6,1,300.000549316406,0,2084573888,300.000564575195,,,,,,,,,,,,,,,,,,,,,,,,,,,,,,,,,
,3874223310.16707,299.999923706055,4352.47875976562,0.000432153307766335,6.82827268734609E-5,1,2,13.1008939743042,1.97564819155953,26.1499993503094,0.0946770496920689,0.067738320129359,100,0.000222525429701506,,,,,,,,,,,,,,,,,,,,,299.999816894531,300.000030517578,4262.45361328125,4442.50390625,51.703554104342,5.75682106137316,9.89304161071777,26,1,0,0,1,0.130691528320312,31.2805480957031,1,6,1,299.999816894531,0,2084573216,299.999923706055,,,,,,,,,,,,,,,,,,,,,,,,,,,,,,,,,
,3874223375.62942,299.999847412109,10898.3037109375,0.00109360899761093,7.16402328341511E-6,1,2,13.1008939743042,1.97557670491322,26.1499993503094,0.256821879993987,0.0537146442401137,100,6.64220636224691E-5,,,,,,,,,,,,,,,,,,,,,299.999755859375,299.999938964844,10803.408203125,10993.19921875,51.7320835452939,5.75776370314853,9.88193416595459,26,1,0,0,1,0.131607055664062,30.7917900085449,1,6,1,299.999938964844,0,2084573184,299.999847412109,,,,,,,,,,,,,,,,,,,,,,,,,,,,,,,,,
,3874223453.03888,299.999786376953,18646.8837890625,0.00190334437859987,5.69723444052779E-6,1,2,13.1008939743042,1.97605371934293,26.1499993503094,0.450460922904366,0.0711700790107976,10,2.12829947032183E-5,,,,,,,,,,,,,,,,,,,,,299.999572753906,300,18556.765625,18737.001953125,51.6433687083612,5.75381050393648,9.8688907623291,25,1,68,0,0,0.130538940429688,31.2805480957031,1,6,1,300,0,2084574048,299.999786376953,,,,,,,,,,,,,,,,,,,,,,,,,,,,,,,,,
,3874223518.53571,300.000564575195,25199.2744140625,0.00259023777731769,2.56047195176383E-5,1,2,13.1008939743042,1.97573717266942,26.1499993503094,0.613372167236991,0.0931955952877378,10,1.36487141727251E-5,,,,,,,,,,,,,,,,,,,,,300.00048828125,300.000640869141,25109.15625,25289.392578125,51.5734129558901,5.75698177162695,9.86057472229004,24,1,68,0,0,0.13092041015625,31.2805480957031,1,6,1,300.000640869141,0,2084574144,300.000564575195,,,,,,,,,,,,,,,,,,,,,,,,,,,,,,,,,
,3874223584.02084,300.000579833984,31762.701171875,0.00277310071652274,0.000451189362131409,1,2,13.1008939743042,1.97583226208744,26.1499993503094,0.663866105068626,0.0511210153211652,10,-0.000190711611800893,,,,,,,,,,,,,,,,,,,,,300.000335693359,300.000823974609,31672.373046875,31853.029296875,51.5659874849574,5.75517721590301,9.853590965271,25,1,68,0,0,0.132217407226562,30.7917900085449,1,6,1,300.000335693359,0,2084574080,300.000579833984,,,,,,,,,,,,,,,,,,,,,,,,,,,,,,,,,
,3874223663.431,299.999664306641,39721.078125,0.00404046552163615,1.07630964065037E-5,1,2,13.1008939743042,1.97556546359672,26.1499993503094,0.956840359109591,0.143917457373718,100,1.52438584232342E-5,,,,,,,,,,,,,,,,,,,,,299.999572753906,299.999755859375,39631.03515625,39811.12109375,51.6085862392555,5.7577353320853,9.84659481048584,24,1,68,0,0,0.130844116210938,30.7917900085449,1,6,1,299.999572753906,0,2084574272,299.999664306641,,,,,,,,,,,,,,,,,,,,,,,,,,,,,,,,,
,3874223752.72233,300.000701904297,48672.564453125,0.0051006284064029,0.000163829312462768,1,2,13.1008939743042,1.97559399017735,26.1499993503094,1.20838896229749,0.178588832931514,100,6.17947837942665E-6,,,,,,,,,,,,,,,,,,,,,300.000610351562,300.000793457031,48582.3125,48762.81640625,51.5335499014093,5.75822091335126,9.83743286132813,26,1,0,0,1,0.13092041015625,31.2805480957031,1,6,1,300.000885009766,0,2084574144,300.000701904297,,,,,,,,,,,,,,,,,,,,,,,,,,,,,,,,,
,3874223769.05861,300.000625610352,50000.228515625,0.00503940973785358,6.23615496899131E-6,1,2,13.1008939743042,1.97552746996609,26.1499993503094,1.19193303539608,0.189236982995383,100,6.01403456541006E-5,,,,,,,,,,,,,,,,,,,,,300.000518798828,300.000732421875,50000.19140625,50000.265625,51.4893878900727,5.75724918633064,9.836745262146,26,1,0,0,1,0.131301879882812,31.2805480957031,1,4,1,300.000518798828,0,2084573952,300.000625610352,,,,,,,,,,,,,,,,,,,,,,,,,,,,,,,,,