File: LT data/Frome/L5/255_FULL_SEQUENCE.dat
[Header]
; MPMS3 Data File (default extension .dat)
; Copyright (c) 2007, Quantum Design, Inc. All rights reserved.
TITLE,
FILEOPENTIME,3874224826.85694,10/06/2022,3:44 pm
BYAPP,MPMS3 w/ AC,1.0,1.1
INFO,MPMS3 Measurement Release 1.1.16 Build 424, MultiVu Release 2.3.4.19,APPNAME
INFO,Linear Motor Servo Controller,MOTOR_MODULE_NAME
INFO,3101-100 N0,MOTOR_HW_VERSION
INFO,MMC1047,MOTOR_SERIAL_NUMBER
INFO,01.04.28,MOTOR_SOFTWARE_VERSION
INFO,Quantum Design Squid Module,SQUID_MODULE_NAME
INFO,3101-501 B0,SQUID_HW_VERSION
INFO,SQM278,SQUID_SERIAL_NUMBER
INFO,01.03.04,SQUID_SOFTWARE_VERSION
INFO,Quantum Design VSM Oven,OVEN_MODULE_NAME
INFO,3101-201 A3,OVEN_HW_VERSION
INFO,OVB323,OVEN_SERIAL_NUMBER
INFO,01.07.07,OVEN_SOFTWARE_VERSION
INFO,SQUID AC,AC_MODULE_NAME
INFO,3101-401 G0,AC_HW_VERSION
INFO,SAC258,AC_SERIAL_NUMBER
INFO,SQUID AC 00.95.07,AC_SOFTWARE_VERSION
INFO,TCI127,COIL_SERIAL_NUMBER
INFO,0,MOMENT_UNITS
INFO,255,SAMPLE_MATERIAL
INFO,,SAMPLE_COMMENT
INFO,,SAMPLE_MASS
INFO,,SAMPLE_VOLUME
INFO,,SAMPLE_MOLECULAR_WEIGHT
INFO,,SAMPLE_SIZE
INFO,,SAMPLE_SHAPE
INFO,Straw,SAMPLE_HOLDER
INFO,Standard,SAMPLE_HOLDER_DETAIL
INFO,66.71,SAMPLE_OFFSET
DATATYPE,COMMENT,1
DATATYPE,TIME,2
STARTUPAXIS,X,2
STARTUPAXIS,Y1,5
FIELDGROUP, VSM,2,3,4,5,6,8,9,10,11,14,15
FIELDGROUP, DC, 2,3,4,14,56,57,58,59,60,61,62,63,64,65,66,67,68,69
FIELDGROUP, AC, 2,3,4,11,16,17,18,19,20,21,22,23,24,25,26,27,28,29,30
STARTUPGROUP, All
[Data]
Comment,Time Stamp (sec),Temperature (K),Magnetic Field (Oe),Moment (emu),M. Std. Err. (emu),Transport Action,Averaging Time (sec),Frequency (Hz),Peak Amplitude (mm),Center Position (mm),Lockin Signal' (V),Lockin Signal (V),Range,M. Quad. Signal (emu),AC Moment (emu),AC M. Std Err. (emu),AC Phase (deg),AC Phase Std. Err. (deg),AC Susceptibility (emu/Oe),AC Suscept. Std Err. (emu/Oe),AC X' (emu/Oe),AC X' Std Err. (emu/Oe),AC X'' (emu/Oe),AC X'' Std Err. (emu/Oe),AC Drive (Oe),AC Frequency (Hz),AC Averaging Time (sec),AC Cycles,AC Range,AC Measure Type,AC Signal' (V),AC Signal'' (V),AC Trim Coil Ratio,AC Trim Coil Phase,Min. Temperature (K),Max. Temperature (K),Min. Field (Oe),Max. Field (Oe),Mass (grams),Motor Lag (deg),Pressure (Torr),Measure Count,Measurement Number,SQUID Status (code),Motor Status (code),Measure Status (code),Motor Current (amps),Motor Temp. (C),Temp. Status (code),Field Status (code),Chamber Status (code),Chamber Temp (K),Redirection State,Evercool Status,Average Temp (K),Rotation Angle (deg),Rotator state,DC Moment Fixed Ctr (emu),DC Moment Err Fixed Ctr (emu),DC Moment Free Ctr (emu),DC Moment Err Free Ctr (emu),DC Fixed Fit,DC Free Fit,DC Calculated Center (mm),DC Calculated Center Err (mm),DC Scan Length (mm),DC Scan Time (s),DC Number of Points,DC Squid Drift,DC Min V (V),DC Max V (V),DC Scans per Measure,Map 01,Map 02,Map 03,Map 04,Map 05,Map 06,Map 07,Map 08,Map 09,Map 10,Map 11,Map 12,Map 13,Map 14,Map 15,Map 16
"FC",3874224912.74468
,3874225817.35862,88.7315444946289,49999.59765625,0.0347446608139205,9.98431333258821E-6,1,2,13.1008939743042,1.98600907464735,26.6299992799759,8.31445051891359,1.22490828245183,10,2.61784823738904E-5,,,,,,,,,,,,,,,,,,,,,88.5755920410156,88.8874969482422,49999.59765625,49999.59765625,51.5179173310247,5.76134668844577,7.79094696044922,26,1,0,0,1,0.13702392578125,31.7693061828613,2,1,1,88.5755920410156,0,2084573184,88.7315444946289,,,,,,,,,,,,,,,,,,,,,,,,,,,,,,,,,
,3874225952.44938,66.3818473815918,49999.59765625,0.0469318756413198,6.35353454885653E-5,1,2,13.1008939743042,1.98568420234438,26.5699997544289,11.229847267259,1.63725217811858,100,-3.48485584734322E-5,,,,,,,,,,,,,,,,,,,,,66.2368011474609,66.5268936157227,49999.59765625,49999.59765625,51.6253912524189,5.76807724114354,7.59124374389648,24,1,64,0,0,0.139617919921875,31.2805480957031,2,1,1,66.2368011474609,0,2084573184,66.3818473815918,,,,,,,,,,,,,,,,,,,,,,,,,,,,,,,,,
,3874226061.47023,47.7030563354492,49999.59765625,0.0651675197948417,8.70863184463996E-5,1,2,13.1008939743042,1.98571506265461,26.5200007706881,15.5882030845669,2.31117642268324,100,0.000109153138643976,,,,,,,,,,,,,,,,,,,,,47.5447311401367,47.8613815307617,49999.59765625,49999.59765625,51.6789328059862,5.76679586995816,7.30378007888794,24,1,68,0,0,0.140304565429688,30.3030319213867,2,1,1,47.5447311401367,0,2084573184,47.7030563354492,,,,,,,,,,,,,,,,,,,,,,,,,,,,,,,,,
,3874226183.72962,27.0105419158936,49999.59765625,0.106363162643483,0.000535428534162197,1,2,13.1008939743042,1.9854542760453,26.4899991452694,25.4274361633312,3.82932213884764,1000,0.000420942810213271,,,,,,,,,,,,,,,,,,,,,27.0105419158936,27.0105419158936,49999.59765625,49999.59765625,51.7805445134862,5.76924105786366,6.7144021987915,26,1,0,0,1,0.137939453125,29.8142719268799,2,1,1,27.0105419158936,0,2084573184,27.0105419158936,,,,,,,,,,,,,,,,,,,,,,,,,,,,,,,,,
,3874226295.63016,9.50533962249756,49999.59765625,0.198240913219436,0.000416245356713074,1,2,13.1008939743042,1.98583651491064,26.4699999243021,47.4265922931667,7.02148436540753,100,0.000290352967215856,,,,,,,,,,,,,,,,,,,,,9.38605117797852,9.6246280670166,49999.59765625,49999.59765625,52.1987157712748,5.76760567669143,4.94295740127563,26,1,0,0,1,0.139999389648438,30.3030319213867,6,1,1,9.38605117797852,0,2084573184,9.50533962249756,,,,,,,,,,,,,,,,,,,,,,,,,,,,,,,,,
,3874226380.98408,2.00034046173096,49999.59765625,0.262514546608941,5.4948437131109E-5,1,2,13.1008939743042,1.98571171408278,26.4699999243021,62.8014250303715,9.2581419730607,100,0.000222581386686298,,,,,,,,,,,,,,,,,,,,,2.00012755393982,2.00055336952209,49999.59765625,49999.59765625,52.9795626619864,5.76802989735822,2.44397664070129,26,1,0,0,1,0.1324462890625,30.7917900085449,5,1,1,2.00012755393982,0,2084573184,2.00034046173096,,,,,,,,,,,,,,,,,,,,,,,,,,,,,,,,,
,3874226803.74178,16.0203399658203,26.2176666259766,9.76015826883437E-5,1.06318637306729E-7,1,2,13.1008939743042,1.98486373609308,26.4699999243021,0.0233304814121594,0.00343840183376019,1,7.88184012683053E-8,,,,,,,,,,,,,,,,,,,,,16.0203399658203,16.0203399658203,26.2176666259766,26.2176666259766,51.7254397028805,5.77670866635689,5.45894622802734,26,1,0,0,1,0.137939453125,30.7917900085449,2,1,1,16.0203399658203,0,2084573184,16.0203399658203,,,,,,,,,,,,,,,,,,,,,,,,,,,,,,,,,
,3874226996.6256,46.0382347106934,26.2176666259766,2.48743339910961E-5,3.81410453704768E-8,1,2,13.1008939743042,1.9849493091495,26.4800004661083,0.00594774553217873,0.00086715894918568,1,-1.84324191632157E-8,,,,,,,,,,,,,,,,,,,,,46.0382347106934,46.0382347106934,26.2176666259766,26.2176666259766,51.6965194476689,5.77541602746842,6.57942152023315,26,1,0,0,1,0.13671875,30.3030319213867,2,1,1,46.0382347106934,0,2084573184,46.0382347106934,,,,,,,,,,,,,,,,,,,,,,,,,,,,,,,,,
,3874227186.22428,76.0054016113281,26.2176666259766,1.84046799362063E-5,4.85038067797891E-8,1,2,13.1008939743042,1.98494473584895,26.5200007706881,0.00440035237039089,0.000644367814856447,1,-2.11880609935642E-9,,,,,,,,,,,,,,,,,,,,,76.0054016113281,76.0054016113281,26.2176666259766,26.2176666259766,51.6953470048901,5.77817936780879,7.07177782058716,26,1,0,0,1,0.140914916992188,30.7917900085449,2,1,1,76.0054016113281,0,2084573184,76.0054016113281,,,,,,,,,,,,,,,,,,,,,,,,,,,,,,,,,
,3874227369.8551,106.011093139648,26.2176666259766,1.42085660399197E-5,3.9659370304549E-8,1,2,13.1008939743042,1.98492060365611,26.5800002962351,0.00339586662873938,0.000505386121005606,1,3.15761771422894E-8,,,,,,,,,,,,,,,,,,,,,106.011093139648,106.011093139648,26.2176666259766,26.2176666259766,51.7047265471209,5.77676395235934,7.24760484695435,26,1,0,0,1,0.135421752929688,31.2805480957031,2,1,1,106.011093139648,0,2084573824,106.011093139648,,,,,,,,,,,,,,,,,,,,,,,,,,,,,,,,,
,3874227551.33649,136.096145629883,26.2176666259766,1.11788233737238E-5,4.48478646254043E-8,1,2,13.1008939743042,1.98494671061135,26.6699995845556,0.00267233002523104,0.000394155158730484,1,1.03059300193138E-8,,,,,,,,,,,,,,,,,,,,,136.096145629883,136.096145629883,26.2176666259766,26.2176666259766,51.8141545398132,5.77652083977996,7.38004970550537,26,1,0,0,1,0.141830444335938,30.7917900085449,2,1,1,136.096145629883,0,2084573792,136.096145629883,,,,,,,,,,,,,,,,,,,,,,,,,,,,,,,,,
,3874227732.02494,166.024108886719,26.2176666259766,9.53860335384307E-6,4.53965972342374E-8,1,2,13.1008939743042,1.98459865916269,26.7500001937151,0.00227881371012832,0.000340704706574115,1,2.75969807088372E-8,,,,,,,,,,,,,,,,,,,,,166.024108886719,166.024108886719,26.2176666259766,26.2176666259766,51.6828409485824,5.78066228697577,7.49903249740601,26,1,0,0,1,0.142364501953125,30.3030319213867,2,1,1,166.024108886719,0,2084574016,166.024108886719,,,,,,,,,,,,,,,,,,,,,,,,,,,,,,,,,
,3874227913.4821,196.042922973633,26.2176666259766,8.37300958796495E-6,4.5302141504181E-8,1,2,13.1008939743042,1.98427530744714,26.8699992448092,0.00200190459063012,0.000284141489916321,1,-3.78746787334124E-8,,,,,,,,,,,,,,,,,,,,,196.042922973633,196.042922973633,26.2176666259766,26.2176666259766,51.7402906447459,5.78395321736518,7.63319635391235,26,1,0,0,1,0.136642456054688,30.7917900085449,2,1,1,196.042922973633,0,2084574080,196.042922973633,,,,,,,,,,,,,,,,,,,,,,,,,,,,,,,,,
,3874228093.72457,226.006301879883,26.2176666259766,7.45272285386074E-6,3.51091944639038E-8,1,2,13.1008939743042,1.98462349666346,27.0000007003546,0.00178263875163418,0.000251818040108392,1,-3.86376882881136E-8,,,,,,,,,,,,,,,,,,,,,226.006301879883,226.006301879883,26.2176666259766,26.2176666259766,51.7215315602843,5.78067228277629,7.84641599655151,26,1,0,0,1,0.136566162109375,29.8142719268799,2,1,1,226.006301879883,0,2084574176,226.006301879883,,,,,,,,,,,,,,,,,,,,,,,,,,,,,,,,,
,3874228274.98884,256.021057128906,26.2176666259766,6.64825391753279E-6,4.28048847216378E-8,1,2,13.1008939743042,1.98456561494593,27.1600000560284,0.00158980229548705,0.000226842516457915,1,-2.5182901401601E-8,,,,,,,,,,,,,,,,,,,,,256.021057128906,256.021057128906,26.2176666259766,26.2176666259766,51.7656935716209,5.77684128367931,8.2349796295166,26,1,0,0,1,0.135726928710938,30.3030319213867,2,1,1,256.021057128906,0,2084574080,256.021057128906,,,,,,,,,,,,,,,,,,,,,,,,,,,,,,,,,
,3874228455.9847,286.009826660156,26.2176666259766,6.00415978352674E-6,3.99728698394729E-8,1,2,13.1008939743042,1.98405780412359,27.3299999535084,0.0014346011251395,0.000208052289543713,1,-8.9870235169331E-9,,,,,,,,,,,,,,,,,,,,,286.009826660156,286.009826660156,26.2176666259766,26.2176666259766,51.7465436728997,5.78445666572459,8.41857242584228,26,1,0,0,1,0.13458251953125,29.8142719268799,2,1,1,286.049438476562,0,2084574208,286.009826660156,,,,,,,,,,,,,,,,,,,,,,,,,,,,,,,,,
,3874230116.00205,2.00006949901581,43935.75,0.253188805234911,5.12238996802844E-5,1,2,13.1008939743042,1.98394352585209,26.4599993824959,60.4875648270417,8.78175779527114,1000,-0.000339700362404415,,,,,,,,,,,,,,,,,,,,,1.99991393089294,2.00022506713867,43850.78125,44020.71875,52.7720402901306,5.78989374609721,2.47075843811035,26,1,0,0,1,0.135879516601562,30.7917900085449,1,6,1,2.00022506713867,0,2084573184,2.00006949901581,,,,,,,,,,,,,,,,,,,,,,,,,,,,,,,,,
,3874230175.52729,1.99972462654114,37988.7109375,0.242331986515911,5.23641333445579E-5,1,2,13.1008939743042,1.98370132679515,26.4599993824959,57.8785702733165,8.41594569222292,1000,-0.0002719556787098,,,,,,,,,,,,,,,,,,,,,1.99959933757782,1.99984991550446,37899.22265625,38078.19921875,52.5250456780536,5.7935668389769,2.46717977523804,26,1,0,0,1,0.136947631835938,30.7917900085449,1,6,1,1.99984991550446,0,2084573184,1.99972462654114,,,,,,,,,,,,,,,,,,,,,,,,,,,,,,,,,
,3874230235.0108,1.99922895431519,32046.861328125,0.228875540998916,4.19266750369142E-5,1,2,13.1008939743042,1.98321032492267,26.4599993824959,54.6354781006527,7.96869050651536,1000,-0.000157119192132205,,,,,,,,,,,,,,,,,,,,,1.99922323226929,1.99923467636108,31956.861328125,32136.861328125,52.4171809423998,5.79701909750644,2.46416258811951,26,1,0,0,1,0.133514404296875,30.7917900085449,1,6,1,1.99922323226929,0,2084573184,1.99922895431519,,,,,,,,,,,,,,,,,,,,,,,,,,,,,,,,,
,3874230294.61254,1.99961048364639,26100.59375,0.211879570836005,6.78447404350446E-5,1,2,13.1008939743042,1.98300102469731,26.4599993824959,50.5656235822007,7.393045466085,1000,-7.18035604270677E-5,,,,,,,,,,,,,,,,,,,,,1.99938118457794,1.99983978271484,26015.650390625,26185.537109375,52.1490823603036,5.79972069088465,2.46094703674316,25,1,68,0,0,0.137100219726562,30.3030319213867,1,6,1,1.99938118457794,0,2084573184,1.99961048364639,,,,,,,,,,,,,,,,,,,,,,,,,,,,,,,,,
,3874230354.10895,2.00003111362457,20153.5849609375,0.189160234324118,6.41702622477424E-5,1,2,13.1008939743042,1.9828285198388,26.4599993824959,45.1405021543946,6.56947411349301,1000,-0.000188762298856712,,,,,,,,,,,,,,,,,,,,,2.00002408027649,2.00003814697266,20063.646484375,20243.5234375,51.9974464275728,5.80279912697873,2.4607527256012,26,1,0,0,1,0.14068603515625,30.7917900085449,1,6,1,2.00002408027649,0,2084573184,2.00003111362457,,,,,,,,,,,,,,,,,,,,,,,,,,,,,,,,,
,3874230451.35475,2.00007855892181,10440.3227539062,0.130626552876198,9.30298313134657E-5,1,2,13.1008939743042,1.98270692852748,26.4599993824959,31.1643427568635,4.56523003031075,100,-8.21069098948336E-6,,,,,,,,,,,,,,,,,,,,,2.00001668930054,2.00014042854309,10355.248046875,10525.3974609375,51.7836710275632,5.80413613488093,2.46374034881592,26,1,0,0,1,0.1318359375,30.7917900085449,1,6,1,2.00014042854309,0,2084573184,2.00007855892181,,,,,,,,,,,,,,,,,,,,,,,,,,,,,,,,,
,3874230552.54891,1.99997889995575,330.483497619629,0.00860635762202464,0.000213779878719903,1,2,13.1008939743042,1.98252515180904,26.4599993824959,2.06465636845248,0.220591994676695,100,-0.000336499081906265,,,,,,,,,,,,,,,,,,,,,1.99991822242737,2.00003957748413,240.433670043945,420.533325195313,51.6523574363324,5.80430523274231,2.4599461555481,25,1,68,0,0,0.138397216796875,29.8142719268799,1,6,1,2.00003957748413,0,2084573184,1.99997889995575,,,,,,,,,,,,,,,,,,,,,,,,,,,,,,,,,
,3874230631.99606,2.00006198883057,-7614.35302734375,-0.103949416502986,0.000107094787978029,1,2,13.1008939743042,1.98197924507203,26.4599993824959,-24.7760557654976,-3.67471959547548,100,-0.000179494255987965,,,,,,,,,,,,,,,,,,,,,2.00005960464478,2.00006437301636,-7699.4521484375,-7529.25390625,51.642587079842,5.8097916317847,2.44951033592224,25,1,68,0,0,0.135574340820312,29.3255138397217,1,6,1,2.00006437301636,0,2084573184,2.00006198883057,,,,,,,,,,,,,,,,,,,,,,,,,,,,,,,,,
,3874230691.46577,2.00015819072723,-13566.2075195313,-0.15262197366562,8.47773930197444E-5,1,2,13.1008939743042,1.98198369219164,26.4599993824959,-36.3804507822183,-5.37304944202661,100,-0.000169925083380623,,,,,,,,,,,,,,,,,,,,,2.00001311302185,2.00030326843262,-13650.9111328125,-13481.50390625,52.0122973694382,5.8115655091019,2.44002413749695,26,1,0,0,1,0.135116577148438,30.7917900085449,1,6,1,2.00030326843262,0,2084573184,2.00015819072723,,,,,,,,,,,,,,,,,,,,,,,,,,,,,,,,,
,3874230751.01705,1.99997216463089,-19523.2978515625,-0.18567061317078,6.82391024374215E-5,1,2,13.1008939743042,1.98191695893907,26.4599993824959,-44.2550603935777,-6.53854061012491,100,-0.000216926100946118,,,,,,,,,,,,,,,,,,,,,1.99990403652191,2.00004029273987,-19613.49609375,-19433.099609375,52.158852716794,5.8110235873951,2.43029808998108,25,1,68,0,0,0.133132934570312,30.7917900085449,1,6,1,2.00004029273987,0,2084573184,1.99997216463089,,,,,,,,,,,,,,,,,,,,,,,,,,,,,,,,,
,3874230818.49235,2.00006926059723,-26271.11328125,-0.211909115055584,5.96070630149034E-5,1,2,13.1008939743042,1.98178274655579,26.4599993824959,-50.5021437743526,-7.46459556659681,100,-0.000260183159725856,,,,,,,,,,,,,,,,,,,,,2.00006175041199,2.00007677078247,-26365.97265625,-26176.25390625,52.3065805069286,5.81098717856572,2.42114019393921,26,1,0,0,1,0.130996704101562,30.7917900085449,1,6,1,2.00000643730164,0,2084573184,2.00006926059723,,,,,,,,,,,,,,,,,,,,,,,,,,,,,,,,,
,3874230913.74215,1.99992221593857,-35815.802734375,-0.236989305509563,0.000370826064914746,1,2,13.1008939743042,1.98170876606885,26.4599993824959,-56.4641593332833,-8.4231421202274,100,-0.000608484561352543,,,,,,,,,,,,,,,,,,,,,1.99988007545471,1.99996435642242,-35906.11328125,-35725.4921875,52.6786356820825,5.81270928567398,2.41031503677368,25,1,68,0,0,0.137405395507812,30.7917900085449,1,6,1,1.99988007545471,0,2084573184,1.99992221593857,,,,,,,,,,,,,,,,,,,,,,,,,,,,,,,,,
,3874231038.84431,1.99994695186615,-48356.89453125,-0.258671468988223,0.00138776223290943,1,2,13.1008939743042,1.98167989755245,26.4599993824959,-61.6019730042257,-9.37360386716382,1000,-0.00141972563957803,,,,,,,,,,,,,,,,,,,,,1.99982881546021,2.00006508827209,-48442.2109375,-48271.578125,52.7841555321787,5.81162282905115,2.40037536621094,26,1,0,0,1,0.13824462890625,31.2805480957031,1,6,1,1.99982881546021,0,2084573184,1.99994695186615,,,,,,,,,,,,,,,,,,,,,,,,,,,,,,,,,
,3874231126.08113,2.0000267624855,-43822.931640625,-0.252722633793862,6.34128401635511E-5,1,2,13.1008939743042,1.98163863460509,26.4599993824959,-60.2420106307746,-8.75429579964388,1000,0.000305433823611206,,,,,,,,,,,,,,,,,,,,,1.99993598461151,2.0001175403595,-43912.9453125,-43732.91796875,52.8302716148133,5.81531968179408,2.40068101882935,26,1,0,0,1,0.140762329101562,31.7693061828613,1,6,1,2.0001175403595,0,2084573184,2.0000267624855,,,,,,,,,,,,,,,,,,,,,,,,,,,,,,,,,
,3874231185.67952,1.9999805688858,-37877.546875,-0.241753064696951,6.54316497298276E-5,1,2,13.1008939743042,1.98134804643224,26.4599993824959,-57.6058838057754,-8.40783568529656,1000,0.000141691522674311,,,,,,,,,,,,,,,,,,,,,1.99981546401978,2.00014567375183,-37962.49609375,-37792.59765625,52.7161538510056,5.81616727922361,2.40213084220886,26,1,0,0,1,0.13397216796875,30.7917900085449,1,6,1,1.99981546401978,0,2084573184,1.9999805688858,,,,,,,,,,,,,,,,,,,,,,,,,,,,,,,,,
,3874231245.15544,1.99984419345856,-31941.6201171875,-0.228426293722967,0.000141829141537388,1,2,13.1008939743042,1.98140247717858,26.4599993824959,-54.4283091236596,-7.97789747570961,1000,-5.17758877266703E-6,,,,,,,,,,,,,,,,,,,,,1.99983024597168,1.99985814094543,-32031.521484375,-31851.71875,52.4269512988902,5.81607365426724,2.40213942527771,26,1,0,0,1,0.13427734375,30.7917900085449,1,6,1,1.99983024597168,0,2084573184,1.99984419345856,,,,,,,,,,,,,,,,,,,,,,,,,,,,,,,,,
,3874231304.75353,2.00001639127731,-25986.55859375,-0.211516690545569,0.000303129288792727,1,2,13.1008939743042,1.98159343350459,26.4599993824959,-50.4200294225196,-7.30923577731049,1000,0.00032852582432056,,,,,,,,,,,,,,,,,,,,,1.99993407726288,2.00009870529175,-26071.447265625,-25901.669921875,52.2475675537267,5.81432548081831,2.40570306777954,26,1,0,0,1,0.135726928710938,31.7693061828613,1,6,1,2.00009870529175,0,2084573184,2.00001639127731,,,,,,,,,,,,,,,,,,,,,,,,,,,,,,,,,
,3874231364.30319,1.99991774559021,-20040.154296875,-0.188452404987137,0.000120431152398318,1,2,13.1008939743042,1.98184407495856,26.4599993824959,-44.9241331111477,-6.57353924302996,1000,4.2019526652318E-5,,,,,,,,,,,,,,,,,,,,,1.99982857704163,2.00000691413879,-20120.0625,-19960.24609375,52.0967132495151,5.81326111533879,2.41009902954102,26,1,0,0,1,0.133285522460938,31.2805480957031,1,6,1,1.99982857704163,0,2084573184,1.99991774559021,,,,,,,,,,,,,,,,,,,,,,,,,,,,,,,,,
,3874231432.94514,2.00008010864258,-13190.9462890625,-0.151597425292776,7.81013894529466E-5,1,2,13.1008939743042,1.98138822262744,26.4599993824959,-36.1233522534088,-5.28125986016859,1000,5.22999477568373E-5,,,,,,,,,,,,,,,,,,,,,2.00008010864258,2.00008010864258,-13190.9462890625,-13190.9462890625,51.9478130166017,5.81519048364251,2.41599225997925,26,1,0,0,1,0.134353637695312,30.7917900085449,1,6,1,2.00008010864258,0,2084573184,2.00008010864258,,,,,,,,,,,,,,,,,,,,,,,,,,,,,,,,,
,3874231538.91043,1.99989861249924,-2597.62548828125,-0.045758919735214,0.000157368033249712,1,2,13.1008939743042,1.98169965893297,26.4599993824959,-10.915021197017,-1.53921146763882,1000,0.000248163914675413,,,,,,,,,,,,,,,,,,,,,1.99984776973724,1.99994945526123,-2687.66284179687,-2507.58813476562,51.7141060893516,5.8110073351611,2.42228889465332,26,1,0,0,1,0.13427734375,30.7917900085449,1,6,1,1.99984776973724,0,2084573184,1.99989861249924,,,,,,,,,,,,,,,,,,,,,,,,,,,,,,,,,
,3874231602.46967,2.00002986192703,3756.74645996094,0.059152266627202,0.000147460019601812,1,2,13.1008939743042,1.98095126596089,26.4599993824959,14.0794290413707,2.12641432237597,100,0.000259076807711783,,,,,,,,,,,,,,,,,,,,,1.99996030330658,2.00009942054749,3671.69653320313,3841.79638671875,51.8462013091016,5.81945646125896,2.4220654964447,26,1,0,0,1,0.134429931640625,30.7917900085449,1,6,1,1.99996030330658,0,2084573184,2.00002986192703,,,,,,,,,,,,,,,,,,,,,,,,,,,,,,,,,
,3874231669.89807,1.99993103742599,10502.86328125,0.12994107142536,9.29809548482879E-5,1,2,13.1008939743042,1.98076377278771,26.4599993824959,30.934325482547,4.59325134458026,100,0.000245555708276098,,,,,,,,,,,,,,,,,,,,,1.99973046779633,2.00013160705566,10412.7890625,10592.9375,51.7930505697939,5.8219147224977,2.41544103622437,26,1,0,0,1,0.134735107421875,30.7917900085449,1,6,1,1.99973046779633,0,2084573184,1.99993103742599,,,,,,,,,,,,,,,,,,,,,,,,,,,,,,,,,
,3874231729.43858,2.00004708766937,16459.984375,0.170092889604745,6.52169853829258E-5,1,2,13.1008939743042,1.98070736592136,26.4599993824959,40.4936815231968,5.99292346916086,100,0.000240301934152646,,,,,,,,,,,,,,,,,,,,,2.00001215934753,2.00008201599121,16374.904296875,16545.064453125,51.9528936019767,5.82321542050721,2.40592241287231,26,1,0,0,1,0.135498046875,30.7917900085449,1,6,1,2.00001215934753,0,2084573184,2.00004708766937,,,,,,,,,,,,,,,,,,,,,,,,,,,,,,,,,
,3874231796.95942,1.99989449977875,23213.3876953125,0.201007028251826,6.0829046761177E-5,1,2,13.1008939743042,1.98156431269219,26.4599993824959,47.8937368865883,7.080485191509,100,0.000252677886998913,,,,,,,,,,,,,,,,,,,,,1.99979496002197,1.99999403953552,23128.34375,23298.431640625,52.3210406345344,5.81408640712094,2.40022993087769,26,1,0,0,1,0.139846801757812,30.7917900085449,1,6,1,1.99979496002197,0,2084573184,1.99989449977875,,,,,,,,,,,,,,,,,,,,,,,,,,,,,,,,,
,3874231874.3031,1.99983024597168,30960.7568359375,0.225470542019467,7.7174038916027E-5,1,2,13.1008939743042,1.98069800504047,26.4599993824959,53.6768793091741,7.94378305378414,100,0.000317684193444356,,,,,,,,,,,,,,,,,,,,,1.99979388713837,1.99986660480499,30870.46484375,31051.048828125,52.6282206425921,5.82314338145183,2.392991065979,26,1,0,0,1,0.13092041015625,30.7917900085449,1,6,1,1.99979388713837,0,2084573664,1.99983024597168,,,,,,,,,,,,,,,,,,,,,,,,,,,,,,,,,
,3874231963.59617,2.00013208389282,39911.22265625,0.245370487512853,7.12463717766233E-5,1,2,13.1008939743042,1.98087543689768,26.4599993824959,58.4303649086502,8.60505770533458,1000,0.000172263827133466,,,,,,,,,,,,,,,,,,,,,1.99990081787109,2.00036334991455,39820.9140625,40001.53125,52.5598281471594,5.81851025269345,2.38657069206238,26,1,0,0,1,0.132980346679688,30.7917900085449,1,6,1,2.00036334991455,0,2084573888,2.00013208389282,,,,,,,,,,,,,,,,,,,,,,,,,,,,,,,,,
,3874232058.84101,1.99995911121368,49458.845703125,0.260801453179091,5.84421368856724E-5,1,2,13.1008939743042,1.98080003824198,26.4599993824959,62.0884322592696,9.22771757149566,100,0.000528114437374424,,,,,,,,,,,,,,,,,,,,,1.99985098838806,2.00006723403931,49373.59765625,49544.09375,52.9592403204864,5.82044083216522,2.38493466377258,26,1,0,0,1,0.1361083984375,30.7917900085449,1,6,1,1.99985098838806,0,2084573728,1.99995911121368,,,,,,,,,,,,,,,,,,,,,,,,,,,,,,,,,
,3874232528.48708,26.0313558578491,26.1311378479004,2.78412367368029E-5,5.72091826102349E-8,1,2,13.1008939743042,1.98951935170665,26.4699999243021,0.00668625867513643,0.000974868023051385,1,-2.0481596589374E-8,,,,,,,,,,,,,,,,,,,,,26.0119380950928,26.0507736206055,26.1311378479004,26.1311378479004,51.6308626520535,5.8231424039917,5.96169996261597,26,1,0,0,1,0.132293701171875,30.7917900085449,2,1,1,26.0507736206055,0,2084574112,26.0313558578491,,,,,,,,,,,,,,,,,,,,,,,,,,,,,,,,,
,3874232720.97678,56.0647315979004,26.1311378479004,1.99801435256136E-5,7.54844494765873E-7,1,2,13.1008939743042,1.99080190676178,26.4899991452694,0.00481852332221252,0.000602944201892525,1,-4.20318780620546E-7,,,,,,,,,,,,,,,,,,,,,56.0647315979004,56.0647315979004,26.1311378479004,26.1311378479004,51.6250004381593,5.80720478488078,6.84714651107788,26,1,0,0,1,0.131072998046875,30.7917900085449,2,1,1,56.0647315979004,0,2084574240,56.0647315979004,,,,,,,,,,,,,,,,,,,,,,,,,,,,,,,,,
,3874232908.51181,86.0079345703125,26.1311378479004,1.52445179393222E-5,5.55831608848533E-8,1,2,13.1008939743042,1.99051464611989,26.5399999916554,0.00366252776520698,0.000548068774551019,1,4.60815474009257E-8,,,,,,,,,,,,,,,,,,,,,86.0079345703125,86.0079345703125,26.1311378479004,26.1311378479004,51.8219708250055,5.80983752939443,7.43741369247437,26,1,0,0,1,0.135498046875,30.3030319213867,2,1,1,86.0079345703125,0,2084574176,86.0079345703125,,,,,,,,,,,,,,,,,,,,,,,,,,,,,,,,,
,3874233090.36165,116.001441955566,26.1311378479004,1.18246965994149E-5,4.63028259042426E-8,1,2,13.1008939743042,1.99052028802737,26.5999995172024,0.00284165120366217,0.000420158040993855,1,1.50913202299214E-8,,,,,,,,,,,,,,,,,,,,,116.001441955566,116.001441955566,26.1311378479004,26.1311378479004,51.7703833427362,5.80787400571818,7.56984424591064,26,1,0,0,1,0.132980346679688,30.3030319213867,2,1,1,116.001441955566,0,2084574208,116.001441955566,,,,,,,,,,,,,,,,,,,,,,,,,,,,,,,,,
,3874233272.33368,146.036087036133,26.1311378479004,9.83709504611177E-6,4.56287267591517E-8,1,2,13.1008939743042,1.99046046690456,26.6900006681681,0.00236521801283001,0.000340289900970731,1,-2.58244811113568E-8,,,,,,,,,,,,,,,,,,,,,146.036087036133,146.036087036133,26.1311378479004,26.1311378479004,51.6504033650343,5.80756066715796,7.66715621948242,26,1,0,0,1,0.131072998046875,30.7917900085449,2,1,1,146.036087036133,0,2084574272,146.036087036133,,,,,,,,,,,,,,,,,,,,,,,,,,,,,,,,,
,3874233453.29576,176.047821044922,26.1311378479004,8.66594621291676E-6,4.36613684770366E-8,1,2,13.1008939743042,1.99015655593312,26.7900004982948,0.00208264977004831,0.000302253294325063,1,-1.20824374254288E-8,,,,,,,,,,,,,,,,,,,,,176.047821044922,176.047821044922,26.1311378479004,26.1311378479004,51.7270029599189,5.81141559581323,7.76502132415772,26,1,0,0,1,0.132293701171875,30.7917900085449,2,1,1,176.047821044922,0,2084574304,176.047821044922,,,,,,,,,,,,,,,,,,,,,,,,,,,,,,,,,
,3874233634.22066,206.04035949707,26.1311378479004,7.6772648851826E-6,4.85905962131926E-8,1,2,13.1008939743042,1.99011432488571,26.9099995493889,0.00184570745425661,0.000262726926888676,1,-3.16477229070464E-8,,,,,,,,,,,,,,,,,,,,,206.04035949707,206.04035949707,26.1311378479004,26.1311378479004,51.7739006710728,5.81245137993288,7.92616939544678,26,1,0,0,1,0.131912231445312,30.3030319213867,2,1,1,206.04035949707,0,2084574336,206.04035949707,,,,,,,,,,,,,,,,,,,,,,,,,,,,,,,,,
,3874233815.08052,236.034149169922,26.1311378479004,7.00793161855561E-6,5.70274123494135E-8,1,2,13.1008939743042,1.9902859947096,27.0499996840954,0.00168426545035035,0.000245331271403092,1,-6.12320165992835E-9,,,,,,,,,,,,,,,,,,,,,236.034149169922,236.034149169922,26.1311378479004,26.1311378479004,51.7352100593709,5.81281283710616,8.26246356964111,24,1,64,0,0,0.132217407226562,29.8142719268799,2,1,1,236.034149169922,0,2084574304,236.034149169922,,,,,,,,,,,,,,,,,,,,,,,,,,,,,,,,,
,3874233995.68632,266.033111572266,26.1311378479004,6.47267023078695E-6,4.5955328604654E-8,1,2,13.1008939743042,1.98997164453306,27.2100009024143,0.00155429152197352,0.000232427356960717,1,1.891293261785E-8,,,,,,,,,,,,,,,,,,,,,266.033111572266,266.033111572266,26.1311378479004,26.1311378479004,51.7070714326785,5.81618722587452,8.79712581634521,24,1,64,0,0,0.132217407226562,30.7917900085449,2,1,1,266.033111572266,0,2084574464,266.033111572266,,,,,,,,,,,,,,,,,,,,,,,,,,,,,,,,,
,3874234176.50668,296.037780761719,26.1311378479004,5.84233188676728E-6,4.85223977159947E-8,1,2,13.1008939743042,1.98980620383026,27.3899994790554,0.00140343055117594,0.000204817810070279,1,-3.50220267737961E-9,,,,,,,,,,,,,,,,,,,,,296.015258789063,296.060302734375,26.1311378479004,26.1311378479004,51.6660359354189,5.81816259991258,8.79436206817627,24,1,64,0,0,0.134735107421875,28.8367557525635,2,1,1,296.060302734375,0,2084574240,296.037780761719,,,,,,,,,,,,,,,,,,,,,,,,,,,,,,,,,
,3874234926.55826,277.992431640625,26.192943572998,7.98883739148704E-6,4.52537661100819E-8,1,2,13.1008939743042,2.00071424634146,27.2700004279614,0.00193901333226876,0.000283210064547315,1,-3.86568572829554E-9,,,,,,,,,,,,,,,,,,,,,277.992431640625,277.992431640625,26.192943572998,26.192943572998,51.7922689412747,5.82048330792783,9.58624076843262,24,1,64,0,0,0.134506225585938,30.7917900085449,2,1,1,277.992431640625,0,2084573184,277.992431640625,,,,,,,,,,,,,,,,,,,,,,,,,,,,,,,,,
,3874235104.51745,247.983657836914,26.192943572998,8.23182786522626E-6,3.88701169577962E-8,1,2,13.1008939743042,2.00069744148336,27.1499995142221,0.00199641815861057,0.000302333853804214,1,3.93397399255385E-8,,,,,,,,,,,,,,,,,,,,,247.983657836914,247.983657836914,26.192943572998,26.192943572998,51.7414630875247,5.81946514063561,9.34199237823486,24,1,64,0,0,0.1348876953125,30.7917900085449,2,1,1,247.983657836914,0,2084573792,247.983657836914,,,,,,,,,,,,,,,,,,,,,,,,,,,,,,,,,
,3874235283.71817,217.953994750977,26.192943572998,8.36950062718789E-6,4.0955932036128E-8,1,2,13.1008939743042,2.00087077485186,27.0300004631281,0.00203219378709753,0.000293428812962002,1,-1.77274666234795E-8,,,,,,,,,,,,,,,,,,,,,217.953994750977,217.953994750977,26.192943572998,26.192943572998,51.8055566261016,5.81527321566879,9.13329792022705,26,1,0,0,1,0.133056640625,29.8142719268799,2,1,1,217.953994750977,0,2084573184,217.953994750977,,,,,,,,,,,,,,,,,,,,,,,,,,,,,,,,,
,3874235462.45282,187.993698120117,26.192943572998,8.45789917082419E-6,4.99416684666826E-8,1,2,13.1008939743042,2.00089107004366,26.9200000911951,0.00205272428519194,0.000303172695863876,1,9.43566300132327E-9,,,,,,,,,,,,,,,,,,,,,187.993698120117,187.993698120117,26.192943572998,26.192943572998,51.6871399054382,5.81626269859907,8.9696102142334,26,1,0,0,1,0.132980346679688,30.7917900085449,2,1,1,187.993698120117,0,2084573728,187.993698120117,,,,,,,,,,,,,,,,,,,,,,,,,,,,,,,,,
,3874235642.9395,157.951629638672,26.192943572998,8.39827350273124E-6,3.9639560979215E-8,1,2,13.1008939743042,2.00043727120597,26.8399994820356,0.00203777379966844,0.000298202139062714,1,-1.77498682930357E-9,,,,,,,,,,,,,,,,,,,,,157.951629638672,157.951629638672,26.192943572998,26.192943572998,51.6621277928228,5.81730224028141,8.82994079589844,26,1,0,0,1,0.136795043945312,29.8142719268799,2,1,1,157.951629638672,0,2084573760,157.951629638672,,,,,,,,,,,,,,,,,,,,,,,,,,,,,,,,,
,3874235822.85917,127.990280151367,26.192943572998,8.39566178303715E-6,3.68808972585091E-8,1,2,13.1008939743042,2.00096460602494,26.7399996519089,0.00203868025683816,0.00029469157289587,1,-1.6467077037581E-8,,,,,,,,,,,,,,,,,,,,,127.990280151367,127.990280151367,26.192943572998,26.192943572998,51.5952985544285,5.81534269055242,8.70760059356689,26,1,0,0,1,0.135040283203125,30.7917900085449,2,1,1,127.990280151367,0,2084574016,127.990280151367,,,,,,,,,,,,,,,,,,,,,,,,,,,,,,,,,
,3874236002.94427,97.9984283447266,26.192943572998,8.13683420577815E-6,4.34294941260198E-8,1,2,13.1008939743042,2.00111578407502,26.6600009053946,0.00197471063962046,0.000295217397752094,1,2.34569340633711E-8,,,,,,,,,,,,,,,,,,,,,97.9984283447266,97.9984283447266,26.192943572998,26.192943572998,51.6894847909958,5.81145557247245,8.5662317276001,26,1,0,0,1,0.13336181640625,30.7917900085449,2,1,1,97.9984283447266,0,2084573824,97.9984283447266,,,,,,,,,,,,,,,,,,,,,,,,,,,,,,,,,
,3874236179.49758,67.9749984741211,26.192943572998,8.57882360030975E-6,3.85706091600887E-8,1,2,13.1008939743042,2.00166133210358,26.5800002962351,0.0020850350610767,0.000297879024354144,1,-3.09886977732102E-8,,,,,,,,,,,,,,,,,,,,,67.9749984741211,67.9749984741211,26.192943572998,26.192943572998,51.7410722732651,5.81003557253237,8.31472778320312,26,1,0,0,1,0.131759643554688,31.7693061828613,2,1,1,67.9749984741211,0,2084573184,67.9749984741211,,,,,,,,,,,,,,,,,,,,,,,,,,,,,,,,,
,3874236354.53038,37.9991455078125,26.192943572998,9.80982012756643E-6,4.99994334642218E-8,1,2,13.1008939743042,2.0019544185152,26.5200007706881,0.00238217827919349,0.000359173951242629,1,4.05248495712744E-8,,,,,,,,,,,,,,,,,,,,,37.9991455078125,37.9991455078125,26.192943572998,26.192943572998,51.6523574363324,5.80423435071925,7.75418567657471,26,1,0,0,1,0.131912231445312,30.7917900085449,2,1,1,37.9991455078125,0,2084573184,37.9991455078125,,,,,,,,,,,,,,,,,,,,,,,,,,,,,,,,,
,3874236550.52431,7.99942350387573,26.192943572998,1.99573931481595E-5,4.18618141326429E-8,1,2,13.1008939743042,2.0011708106154,26.4800004661083,0.00484738093028497,0.000698794004994181,1,-4.6789698512411E-8,,,,,,,,,,,,,,,,,,,,,7.99942350387573,7.99942350387573,26.192943572998,26.192943572998,51.7395090162266,5.80711318191792,5.19018125534058,26,1,0,0,1,0.132904052734375,31.2805480957031,6,1,1,7.99942350387573,0,2084573184,7.99942350387573,,,,,,,,,,,,,,,,,,,,,,,,,,,,,,,,,
,3874236894.90976,24.014497756958,26.192943572998,1.16378848501832E-5,5.45349302797571E-8,1,2,13.1008939743042,2.00160834935701,26.4599993824959,0.00282940401528551,0.000397096478961483,1,-7.07778330516041E-8,,,,,,,,,,,,,,,,,,,,,24.014497756958,24.014497756958,26.192943572998,26.192943572998,51.6558747646689,5.80446530120697,6.03127717971802,26,1,0,0,1,0.13275146484375,31.7693061828613,2,1,1,24.014497756958,0,2084574208,24.014497756958,,,,,,,,,,,,,,,,,,,,,,,,,,,,,,,,,
,3874237087.56618,54.0365257263184,26.192943572998,9.05464363176806E-6,3.59781832984835E-8,1,2,13.1008939743042,2.00140116987994,26.4899991452694,0.00219974862162982,0.000316984715028303,1,-2.1748760079403E-8,,,,,,,,,,,,,,,,,,,,,54.0365257263184,54.0365257263184,26.192943572998,26.192943572998,51.6519666220728,5.80709553568631,6.82886552810669,26,1,0,0,1,0.133056640625,30.7917900085449,2,1,1,54.0365257263184,0,2084574144,54.0365257263184,,,,,,,,,,,,,,,,,,,,,,,,,,,,,,,,,
,3874237276.29999,84.0313415527344,26.192943572998,8.33247545414782E-6,4.10313974510862E-8,1,2,13.1008939743042,2.00230630994666,26.5299994498491,0.00202457279549359,0.000301954635385913,1,2.11338997630239E-8,,,,,,,,,,,,,,,,,,,,,84.0313415527344,84.0313415527344,26.192943572998,26.192943572998,51.728957031217,5.80014294342339,7.84151887893677,26,1,0,0,1,0.134811401367188,30.7917900085449,2,1,1,84.0313415527344,0,2084574208,84.0313415527344,,,,,,,,,,,,,,,,,,,,,,,,,,,,,,,,,
,3874237457.92023,114.037170410156,26.192943572998,7.9867946041552E-6,4.34260165883949E-8,1,2,13.1008939743042,2.002030490427,26.5999995172024,0.00194112773657213,0.000282169579011664,1,-9.30104313929265E-9,,,,,,,,,,,,,,,,,,,,,114.037170410156,114.037170410156,26.192943572998,26.192943572998,51.718795860467,5.80267780032524,7.97105026245117,26,1,0,0,1,0.131607055664062,31.2805480957031,2,1,1,114.037170410156,0,2084574304,114.037170410156,,,,,,,,,,,,,,,,,,,,,,,,,,,,,,,,,
,3874237639.48589,144.014633178711,26.192943572998,7.78951448715854E-6,4.60735961843219E-8,1,2,13.1008939743042,2.00120997260282,26.6800001263618,0.00189206365084334,0.000272578592318639,1,-1.89866169801558E-8,,,,,,,,,,,,,,,,,,,,,144.000671386719,144.028594970703,26.192943572998,26.192943572998,51.6691624494959,5.80997394773789,8.07296085357666,26,1,0,0,1,0.134353637695312,30.7917900085449,2,1,1,144.028594970703,0,2084574240,144.014633178711,,,,,,,,,,,,,,,,,,,,,,,,,,,,,,,,,
,3874237820.7717,174.059783935547,26.192943572998,7.59794954803206E-6,3.93981462767359E-8,1,2,13.1008939743042,2.00138015980041,26.7799999564886,0.00184520595365555,0.000270176735490624,1,-9.83250988332795E-10,,,,,,,,,,,,,,,,,,,,,174.059783935547,174.059783935547,26.192943572998,26.192943572998,51.7395090162266,5.80978178368607,8.1708288192749,26,1,0,0,1,0.1318359375,30.7917900085449,2,1,1,174.059783935547,0,2084574304,174.059783935547,,,,,,,,,,,,,,,,,,,,,,,,,,,,,,,,,
,3874238001.20304,204.051635742187,26.192943572998,7.38324325035512E-6,4.63762169242121E-8,1,2,13.1008939743042,2.00170585031315,26.9000008702278,0.0017934329157685,0.000263872668241649,1,4.18918629394016E-9,,,,,,,,,,,,,,,,,,,,,204.051635742187,204.051635742187,26.192943572998,26.192943572998,51.6543115076305,5.81022188247017,8.29333591461182,24,1,64,0,0,0.13153076171875,30.7917900085449,2,1,1,204.051635742187,0,2084574400,204.051635742187,,,,,,,,,,,,,,,,,,,,,,,,,,,,,,,,,
,3874238182.31603,234.008010864258,26.192943572998,7.21173493320594E-6,4.37705356715436E-8,1,2,13.1008939743042,2.00168533851393,27.0399991422892,0.00175253821937807,0.000252281475475514,1,-1.83704836295893E-8,,,,,,,,,,,,,,,,,,,,,234.008010864258,234.008010864258,26.192943572998,26.192943572998,51.7027724758228,5.81024947153874,8.51703929901123,26,1,0,0,1,0.136337280273438,30.7917900085449,2,1,1,234.008010864258,0,2084574240,234.008010864258,,,,,,,,,,,,,,,,,,,,,,,,,,,,,,,,,
,3874238363.14186,264.053253173828,26.192943572998,6.98397732754659E-6,4.6475119952684E-8,1,2,13.1008939743042,2.00075940826057,27.2000003606081,0.00169505059152801,0.00024855486045591,1,5.64478045002717E-10,,,,,,,,,,,,,,,,,,,,,264.053253173828,264.053253173828,26.192943572998,26.192943572998,51.7524058867939,5.81458574287012,8.87831401824951,26,1,0,0,1,0.13397216796875,31.2805480957031,2,1,1,264.053253173828,0,2084574336,264.053253173828,,,,,,,,,,,,,,,,,,,,,,,,,,,,,,,,,
,3874238543.6907,294.008941650391,26.192943572998,6.76528529541892E-6,5.3718741431047E-8,1,2,13.1008939743042,2.00065405879459,27.3800007998943,0.00164042852487726,0.000250167505364697,1,3.93616668798563E-8,,,,,,,,,,,,,,,,,,,,,294.008941650391,294.008941650391,26.192943572998,26.192943572998,51.7656935716209,5.81693780980472,8.91004848480225,24,1,64,0,0,0.136337280273438,30.7917900085449,2,1,1,294.008941650391,0,2084574400,294.008941650391,,,,,,,,,,,,,,,,,,,,,,,,,,,,,,,,,
,3874238881.88537,300.002014160156,43606.08984375,0.00775000670787315,9.87390339548551E-6,1,2,13.1008939743042,1.98965353558451,27.4000000208616,1.87727029267167,0.163480016700922,100,-0.000455078780977648,,,,,,,,,,,,,,,,,,,,,300.001708984375,300.002319335937,43521.15234375,43691.02734375,51.6027240253612,5.8237110630006,8.79778575897217,24,1,68,0,0,0.134048461914062,30.7917900085449,1,6,1,300.001708984375,0,2084573184,300.002014160156,,,,,,,,,,,,,,,,,,,,,,,,,,,,,,,,,
,3874238941.43238,300.001510620117,37659.634765625,0.00669695554674268,9.87095307430536E-6,1,2,13.1008939743042,1.98992195132028,27.4000000208616,1.62093334782483,0.152719975119649,100,-0.000345716857749727,,,,,,,,,,,,,,,,,,,,,300.001342773438,300.001678466797,37579.69140625,37739.578125,51.6945653763709,5.82019241117337,8.84618949890137,26,1,0,0,1,0.132827758789062,31.2805480957031,1,6,1,300.001678466797,0,2084573184,300.001510620117,,,,,,,,,,,,,,,,,,,,,,,,,,,,,,,,,
,3874239000.95203,300.002471923828,31717.6943359375,0.00561568260881917,4.53828472590035E-5,1,2,13.1008939743042,1.98991256405545,27.4000000208616,1.35791625647499,0.136885661500789,100,-0.000253162944387253,,,,,,,,,,,,,,,,,,,,,300.002288818359,300.002655029297,31638.1953125,31797.193359375,51.5980342542458,5.82085781702577,8.92924785614014,26,1,0,0,1,0.132598876953125,30.7917900085449,1,6,1,300.002655029297,0,2084573824,300.002471923828,,,,,,,,,,,,,,,,,,,,,,,,,,,,,,,,,
,3874239076.32164,300.002136230469,24188.330078125,0.00433692062605212,1.91297358947114E-5,1,2,13.1008939743042,1.98976367054537,27.4000000208616,1.04883973450661,0.103741965324301,100,-0.000203666954200073,,,,,,,,,,,,,,,,,,,,,300.002105712891,300.002166748047,24098.447265625,24278.212890625,51.6500125507747,5.82077085731096,9.07434177398682,26,1,0,0,1,0.13153076171875,30.7917900085449,1,6,1,300.002105712891,0,2084574080,300.002136230469,,,,,,,,,,,,,,,,,,,,,,,,,,,,,,,,,
,3874239143.77177,300.001388549805,17457.50390625,0.00318546146898173,1.74078294397762E-5,1,2,13.1008939743042,1.99033574739786,27.4000000208616,0.772343299472213,0.0656488898195988,100,-0.000193663757187748,,,,,,,,,,,,,,,,,,,,,300.001342773438,300.001434326172,17367.578125,17547.4296875,51.6488401079959,5.81437837530303,9.25187683105469,24,1,68,0,0,0.133438110351562,31.2805480957031,1,6,1,300.001434326172,0,2084573888,300.001388549805,,,,,,,,,,,,,,,,,,,,,,,,,,,,,,,,,
,3874239213.27606,300.000045776367,10515.607421875,0.0021008800925283,0.0001611343480709,1,2,13.1008939743042,1.98956113058784,27.4000000208616,0.512526642473949,0.0192087740778001,100,-0.000227900700429304,,,,,,,,,,,,,,,,,,,,,299.999908447266,300.000183105469,10425.58203125,10605.6328125,51.8555808513324,5.82072793024951,9.46315383911133,25,1,68,0,0,0.132675170898438,30.7917900085449,1,6,1,299.999908447266,0,2084573792,300.000045776367,,,,,,,,,,,,,,,,,,,,,,,,,,,,,,,,,
,3874239272.81198,300.001510620117,4564.25341796875,0.000993473881167051,1.01738439327403E-5,1,2,13.1008939743042,1.98927583204604,27.4000000208616,0.246581907436207,-0.0201358991658274,100,-0.000229470025834144,,,,,,,,,,,,,,,,,,,,,300.001434326172,300.001586914063,4479.63623046875,4648.87060546875,51.7930505697939,5.82198322161086,9.65972137451172,26,1,0,0,1,0.134963989257812,30.7917900085449,1,6,1,300.001434326172,0,2084573728,300.001510620117,,,,,,,,,,,,,,,,,,,,,,,,,,,,,,,,,
,3874239340.26258,300.00080871582,-2179.18115234375,-0.000378667143681927,6.90161151186807E-6,1,2,13.1008939743042,1.98955425872562,27.4000000208616,-0.0832932530381813,-0.0654537035738401,100,-0.000217071323763828,,,,,,,,,,,,,,,,,,,,,300.000640869141,300.0009765625,-2269.24340820313,-2089.11889648438,51.7094163182362,5.81865087416091,9.86150455474854,26,1,0,0,1,0.1300048828125,31.7693061828613,1,6,1,300.0009765625,0,2084573408,300.00080871582,,,,,,,,,,,,,,,,,,,,,,,,,,,,,,,,,
,3874239399.83323,300.000717163086,-8134.39233398438,-0.00148145626740432,9.5867510377055E-6,1,2,13.1008939743042,1.98958104389831,27.4000000208616,-0.353503099533375,-0.0675666431264112,100,-6.4245807042477E-5,,,,,,,,,,,,,,,,,,,,,300.000579833984,300.000854492188,-8219.12109375,-8049.66357421875,51.7363825021497,5.81954926538291,10.0585603713989,26,1,0,0,1,0.134429931640625,30.7917900085449,1,6,1,300.000579833984,0,2084573184,300.000717163086,,,,,,,,,,,,,,,,,,,,,,,,,,,,,,,,,
,3874239463.3061,300.000701904297,-14491.5947265625,-0.00259745778003927,2.28621148552359E-5,1,2,13.1008939743042,1.98958521820919,27.4000000208616,-0.62449277051551,-0.0864746806818695,10,2.05731503079018E-5,,,,,,,,,,,,,,,,,,,,,300.000579833984,300.000823974609,-14581.7060546875,-14401.4833984375,51.713715275092,5.81822313954612,10.170223236084,26,1,0,0,1,0.131759643554688,30.7917900085449,1,6,1,300.000579833984,0,2084573184,300.000701904297,,,,,,,,,,,,,,,,,,,,,,,,,,,,,,,,,
,3874239532.79687,300.000213623047,-21438.5341796875,-0.00378152021875492,6.73525191988729E-6,1,2,13.1008939743042,1.98986972377202,27.4000000208616,-0.909346784370373,-0.126408073709643,10,2.79557776980108E-5,,,,,,,,,,,,,,,,,,,,,300.000091552734,300.000335693359,-21523.6015625,-21353.466796875,51.7598313577266,5.81542262083087,10.1110181808472,25,1,68,0,0,0.134201049804688,31.2805480957031,1,6,1,300.000335693359,0,2084573952,300.000213623047,,,,,,,,,,,,,,,,,,,,,,,,,,,,,,,,,
,3874239611.38314,300,-29307.4912109375,-0.00510231214006988,5.94909810640982E-6,1,2,13.1008939743042,1.9900382739729,27.4000000208616,-1.22738516818878,-0.169024955847218,10,4.42205311692806E-5,,,,,,,,,,,,,,,,,,,,,300,300,-29312.484375,-29302.498046875,51.6531390648516,5.81239439727002,10.0464859008789,24,1,68,0,0,0.133209228515625,30.7917900085449,1,6,1,300,0,2084573920,300,,,,,,,,,,,,,,,,,,,,,,,,,,,,,,,,,
,3874239687.54887,299.999755859375,-36938.47265625,-0.00642292914668258,1.0829961649319E-5,1,2,13.1008939743042,1.98969056082317,27.4000000208616,-1.54476870167761,-0.211237506703282,10,6.17667505028087E-5,,,,,,,,,,,,,,,,,,,,,299.999420166016,300.000091552734,-37028.67578125,-36848.26953125,51.7926597555343,5.81612750883702,10.0001268386841,23,1,68,0,0,0.131912231445312,30.7917900085449,1,6,1,300.000091552734,0,2084573888,299.999755859375,,,,,,,,,,,,,,,,,,,,,,,,,,,,,,,,,
,3874239790.7793,299.999801635742,-47284.44140625,-0.00817953479095846,7.4988255578795E-6,1,2,13.1008939743042,1.98966539391812,27.4000000208616,-1.96650013689679,-0.273777945617938,100,5.87746575656491E-5,,,,,,,,,,,,,,,,,,,,,299.99951171875,300.000091552734,-47369.64453125,-47199.23828125,51.6265636951978,5.81527958987018,9.95185470581055,26,1,0,0,1,0.133743286132812,31.2805480957031,1,6,1,300.000091552734,0,2084574048,299.999801635742,,,,,,,,,,,,,,,,,,,,,,,,,,,,,,,,,
,3874239852.25987,300.000350952148,-47187.16015625,-0.00843641345534581,1.23488154857599E-5,1,2,13.1008939743042,1.98960434629306,27.4000000208616,-2.04941716927172,-0.137176647181711,100,0.000665170717514719,,,,,,,,,,,,,,,,,,,,,300.000152587891,300.000549316406,-47277.0859375,-47097.234375,51.7133244608324,5.81773653355396,9.92602062225342,23,1,68,0,0,0.134811401367188,30.7917900085449,1,6,1,300.000152587891,0,2084573952,300.000350952148,,,,,,,,,,,,,,,,,,,,,,,,,,,,,,,,,
,3874239911.78089,300.000366210937,-41236.96875,-0.00735087668792497,1.18080836050314E-5,1,2,13.1008939743042,1.98960698934946,27.4000000208616,-1.7829097241547,-0.138684562817436,100,0.00049980434524724,,,,,,,,,,,,,,,,,,,,,300.000213623047,300.000518798828,-41326.9375,-41147,51.7719465997747,5.81777234359833,9.90838527679443,24,1,68,0,0,0.131454467773438,30.7917900085449,1,6,1,300.000213623047,0,2084574016,300.000366210937,,,,,,,,,,,,,,,,,,,,,,,,,,,,,,,,,
,3874239971.39099,300.000473022461,-35291.369140625,-0.00631815456848713,1.90762110954705E-5,1,2,13.1008939743042,1.98961388394498,27.4000000208616,-1.53094024805175,-0.129431171919367,100,0.000386990840067398,,,,,,,,,,,,,,,,,,,,,300.000274658203,300.000671386719,-35375.92578125,-35206.8125,51.6543115076305,5.81548716819206,9.89188003540039,24,1,68,0,0,0.135498046875,33.2355842590332,1,6,1,300.000671386719,0,2084573920,300.000473022461,,,,,,,,,,,,,,,,,,,,,,,,,,,,,,,,,
,3874240040.84008,300.00065612793,-28352.2353515625,-0.00499726152222993,7.42596182742746E-5,1,2,13.1008939743042,1.9894524379444,27.4000000208616,-1.21060826045368,-0.102919491178261,100,0.00030373915673533,,,,,,,,,,,,,,,,,,,,,300.000457763672,300.000854492188,-28447.142578125,-28257.328125,51.8450288663228,5.81805029094292,9.87517642974854,24,1,68,0,0,0.132522583007812,30.7917900085449,1,6,1,300.000457763672,0,2084573952,300.00065612793,,,,,,,,,,,,,,,,,,,,,,,,,,,,,,,,,
,3874240108.30485,300.000579833984,-21623.26953125,-0.00389865519677344,2.52377674268471E-5,1,2,13.1008939743042,1.98949034631873,27.4000000208616,-0.944097891338315,-0.0830418162868003,100,0.000225531309083193,,,,,,,,,,,,,,,,,,,,,300.000366210937,300.000793457031,-21718.240234375,-21528.298828125,51.7203591175055,5.81765607478171,9.85778522491455,26,1,0,0,1,0.134506225585938,30.7917900085449,1,6,1,300.000793457031,0,2084573856,300.000579833984,,,,,,,,,,,,,,,,,,,,,,,,,,,,,,,,,
,3874240167.81573,299.999694824219,-15677.5581054687,-0.00290174555692132,1.31886082886293E-5,1,2,13.1008939743042,1.98946802047582,27.4000000208616,-0.704131392781012,-0.0518441114238884,100,0.000209349752681046,,,,,,,,,,,,,,,,,,,,,299.999633789063,299.999755859375,-15767.447265625,-15587.6689453125,51.7699925284766,5.81883063544145,9.84699726104736,26,1,0,0,1,0.1324462890625,31.7693061828613,1,6,1,299.999633789063,0,2084574016,299.999694824219,,,,,,,,,,,,,,,,,,,,,,,,,,,,,,,,,
,3874240235.37954,300.000610351562,-8929.2099609375,-0.00172493664892364,2.72426385404743E-5,1,2,13.1008939743042,1.98941586056404,27.4000000208616,-0.419811632586799,-0.0221991289310503,100,0.000160339694480887,,,,,,,,,,,,,,,,,,,,,300.000518798828,300.000701904297,-9004.2412109375,-8854.1787109375,51.8079015116593,5.81895611598944,9.83518218994141,25,1,68,0,0,0.132217407226562,30.7917900085449,1,6,1,300.000518798828,0,2084573664,300.000610351562,,,,,,,,,,,,,,,,,,,,,,,,,,,,,,,,,
,3874240294.79818,300.001037597656,-2987.12036132812,-0.000738948012813058,2.5559001079776E-5,1,2,13.1008939743042,1.98964576626119,27.4000000208616,-0.18736516066659,0.0415415859561514,100,0.000281269953118241,,,,,,,,,,,,,,,,,,,,,300.000946044922,300.001129150391,-3077.08374023438,-2897.15698242188,51.764521128842,5.81762362997172,9.82535934448242,26,1,0,0,1,0.13397216796875,30.7917900085449,1,6,1,300.000946044922,0,2084573472,300.001037597656,,,,,,,,,,,,,,,,,,,,,,,,,,,,,,,,,
,3874240364.28685,299.998764038086,3961.69799804687,0.000704330021851892,5.44979197090007E-5,1,2,13.1008939743042,1.98925874480604,27.4000000208616,0.162780462777169,0.0678287788000097,100,0.00017931441543558,,,,,,,,,,,,,,,,,,,,,299.998718261719,299.998809814453,3871.6357421875,4051.76025390625,51.7770271851497,5.82054113372462,9.81787490844727,26,1,0,0,1,0.13214111328125,31.7693061828613,1,6,1,299.998718261719,0,2084573344,299.998764038086,,,,,,,,,,,,,,,,,,,,,,,,,,,,,,,,,
,3874240431.7423,299.999145507812,10702.83984375,0.00191610450314506,8.11247750175254E-6,1,2,13.1008939743042,1.98966289513545,27.4000000208616,0.458615800799704,0.0781044147210282,100,4.44022819482169E-5,,,,,,,,,,,,,,,,,,,,,299.998962402344,299.999328613281,10612.7900390625,10792.8896484375,51.879420521169,5.8156233514868,9.80908393859863,26,1,0,0,1,0.13397216796875,30.7917900085449,1,6,1,299.999328613281,0,2084573184,299.999145507812,,,,,,,,,,,,,,,,,,,,,,,,,,,,,,,,,
,3874240495.3219,300.000991821289,17065.5546875,0.00303378019584728,4.90434798122969E-6,1,2,13.1008939743042,1.98937516705585,27.4000000208616,0.728790423338838,0.104112417617025,10,-1.0984816110311E-5,,,,,,,,,,,,,,,,,,,,,300.000946044922,300.001037597656,16965.423828125,17165.685546875,51.8012576692459,5.82018854262192,9.80173015594482,26,1,0,0,1,0.133438110351562,29.8142719268799,1,6,1,300.001037597656,0,2084573376,300.000991821289,,,,,,,,,,,,,,,,,,,,,,,,,,,,,,,,,
,3874240554.8737,299.999740600586,23022.97265625,0.00405420220758388,5.91847354025542E-6,1,2,13.1008939743042,1.9894350820286,27.4000000208616,0.974391018928383,0.136314644169401,10,-2.6441944111721E-5,,,,,,,,,,,,,,,,,,,,,299.99951171875,299.999969482422,22937.837890625,23108.107421875,51.7328651738132,5.81883456262141,9.79365062713623,25,1,68,0,0,0.134735107421875,32.2580642700195,1,6,1,299.999969482422,0,2084574080,299.999740600586,,,,,,,,,,,,,,,,,,,,,,,,,,,,,,,,,
,3874240614.41052,299.999969482422,28981.23046875,0.00507340667736604,8.57208867005016E-6,1,2,13.1008939743042,1.99000266958907,27.4000000208616,1.22014674931078,0.169724402574798,10,-3.70490467497524E-5,,,,,,,,,,,,,,,,,,,,,299.999572753906,300.000366210937,28895.970703125,29066.490234375,51.7352100593709,5.81371142108195,9.79189109802246,24,1,68,0,0,0.130996704101562,31.2805480957031,1,6,1,299.999572753906,0,2084573856,299.999969482422,,,,,,,,,,,,,,,,,,,,,,,,,,,,,,,,,
,3874240689.77031,300.000534057617,36538.591796875,0.00636628245386639,9.02523756729836E-6,1,2,13.1008939743042,1.98933923543645,27.4000000208616,1.53005170683689,0.213264749418493,10,-4.47267648811639E-5,,,,,,,,,,,,,,,,,,,,,300.000457763672,300.000610351562,36453.30859375,36623.875,51.5890455262747,5.81954986870821,9.78436374664307,24,1,68,0,0,0.134506225585938,31.7693061828613,1,6,1,300.000610351562,0,2084574048,300.000534057617,,,,,,,,,,,,,,,,,,,,,,,,,,,,,,,,,
,3874240775.09714,300.000350952148,45093.642578125,0.00781446038416443,8.09255154318905E-6,1,2,13.1008939743042,1.98940500876944,27.4000000208616,1.87821686196428,0.261814163661924,10,-5.48163207316331E-5,,,,,,,,,,,,,,,,,,,,,300.000061035156,300.000640869141,45003.34765625,45183.9375,51.5648150421785,5.81927569941145,9.77845764160156,23,1,68,0,0,0.134429931640625,31.2805480957031,1,6,1,300.000061035156,0,2084573984,300.000350952148,,,,,,,,,,,,,,,,,,,,,,,,,,,,,,,,,
,3874240832.82448,299.999664306641,50000.197265625,0.0086218690086741,3.32835874067101E-6,1,2,13.1008939743042,1.98935393586873,27.4000000208616,2.0702218869839,0.302197603876579,100,-4.89226412483759E-6,,,,,,,,,,,,,,,,,,,,,299.99951171875,299.999816894531,50000.19140625,50000.203125,51.581620055342,5.82123186607628,9.77412986755371,26,1,0,0,1,0.13427734375,31.7693061828613,1,4,1,299.999816894531,0,2084573952,299.999664306641,,,,,,,,,,,,,,,,,,,,,,,,,,,,,,,,,