File: LT data/Bridport/K1/177-FC-ZFC-RTSIRM-contsweepwithloop-MsT.dat
[Header]
; MPMS3 Data File (default extension .dat)
; Copyright (c) 2007, Quantum Design, Inc. All rights reserved.
TITLE,
FILEOPENTIME,3865926910.48806,07/02/2022,1:32 pm
BYAPP,MPMS3 w/ AC,1.0,1.1
INFO,MPMS3 Measurement Release 1.1.16 Build 424, MultiVu Release 2.3.4.19,APPNAME
INFO,Linear Motor Servo Controller,MOTOR_MODULE_NAME
INFO,3101-100 N2,MOTOR_HW_VERSION
INFO,,MOTOR_SERIAL_NUMBER
INFO,01.04.28,MOTOR_SOFTWARE_VERSION
INFO,Quantum Design Squid Module,SQUID_MODULE_NAME
INFO,3101-501 B0,SQUID_HW_VERSION
INFO,SQM327,SQUID_SERIAL_NUMBER
INFO,01.03.04,SQUID_SOFTWARE_VERSION
INFO,Quantum Design VSM Oven,OVEN_MODULE_NAME
INFO,3101-201 A3,OVEN_HW_VERSION
INFO,OVB365,OVEN_SERIAL_NUMBER
INFO,01.07.07,OVEN_SOFTWARE_VERSION
INFO,SQUID AC,AC_MODULE_NAME
INFO,3101-401 G0,AC_HW_VERSION
INFO,SAC220,AC_SERIAL_NUMBER
INFO,SQUID AC 00.95.07,AC_SOFTWARE_VERSION
INFO,TCI344,COIL_SERIAL_NUMBER
INFO,0,MOMENT_UNITS
INFO,sndst,SAMPLE_MATERIAL
INFO,,SAMPLE_COMMENT
INFO,102.1,SAMPLE_MASS
INFO,,SAMPLE_VOLUME
INFO,,SAMPLE_MOLECULAR_WEIGHT
INFO,,SAMPLE_SIZE
INFO,,SAMPLE_SHAPE
INFO,Straw,SAMPLE_HOLDER
INFO,Standard,SAMPLE_HOLDER_DETAIL
INFO,59.08,SAMPLE_OFFSET
DATATYPE,COMMENT,1
DATATYPE,TIME,2
STARTUPAXIS,X,2
STARTUPAXIS,Y1,5
FIELDGROUP, VSM,2,3,4,5,6,8,9,10,11,14,15
FIELDGROUP, DC, 2,3,4,14,56,57,58,59,60,61,62,63,64,65,66,67,68,69
FIELDGROUP, AC, 2,3,4,11,16,17,18,19,20,21,22,23,24,25,26,27,28,29,30
STARTUPGROUP, All
[Data]
Comment,Time Stamp (sec),Temperature (K),Magnetic Field (Oe),Moment (emu),M. Std. Err. (emu),Transport Action,Averaging Time (sec),Frequency (Hz),Peak Amplitude (mm),Center Position (mm),Lockin Signal' (V),Lockin Signal (V),Range,M. Quad. Signal (emu),AC Moment (emu),AC M. Std Err. (emu),AC Phase (deg),AC Phase Std. Err. (deg),AC Susceptibility (emu/Oe),AC Suscept. Std Err. (emu/Oe),AC X' (emu/Oe),AC X' Std Err. (emu/Oe),AC X'' (emu/Oe),AC X'' Std Err. (emu/Oe),AC Drive (Oe),AC Frequency (Hz),AC Averaging Time (sec),AC Cycles,AC Range,AC Measure Type,AC Signal' (V),AC Signal'' (V),AC Trim Coil Ratio,AC Trim Coil Phase,Min. Temperature (K),Max. Temperature (K),Min. Field (Oe),Max. Field (Oe),Mass (grams),Motor Lag (deg),Pressure (Torr),Measure Count,Measurement Number,SQUID Status (code),Motor Status (code),Measure Status (code),Motor Current (amps),Motor Temp. (C),Temp. Status (code),Field Status (code),Chamber Status (code),Chamber Temp (K),Redirection State,Average Temp (K),Rotation Angle (deg),Rotator state,DC Moment Fixed Ctr (emu),DC Moment Err Fixed Ctr (emu),DC Moment Free Ctr (emu),DC Moment Err Free Ctr (emu),DC Fixed Fit,DC Free Fit,DC Calculated Center (mm),DC Calculated Center Err (mm),DC Scan Length (mm),DC Scan Time (s),DC Number of Points,DC Squid Drift,DC Min V (V),DC Max V (V),DC Scans per Measure,Map 01,Map 02,Map 03,Map 04,Map 05,Map 06,Map 07,Map 08,Map 09,Map 10,Map 11,Map 12,Map 13,Map 14,Map 15,Map 16
,3865927991.45545,100.000778198242,49999.7265625,0.0450115482097413,1.87567207105404E-5,1,2,12.9061126708984,4.98368520033794,36.5599989891052,58.5268540214165,8.43427358044891,100,-0.000123484963261379,,,,,,,,,,,,,,,,,,,,,100.000778198242,100.000778198242,49999.7265625,49999.7265625,49.9366828366207,5.43003653843262,7.23303318023682,26,1,0,0,1,0.267791748046875,29.8142719268799,1,1,1,100.000778198242,0,100.000778198242,,,,,,,,,,,,,,,,,,,,,,,,,,,,,,,,,
,3865928085.477,87.4911918640137,49999.7265625,0.0517730884710787,1.3124163948265E-5,1,2,12.9061126708984,4.98274200121789,36.5200005471706,67.2823005936174,9.8241415247682,100,-4.5475039232012E-5,,,,,,,,,,,,,,,,,,,,,87.3989639282227,87.5834197998047,49999.7265625,49999.7265625,50.0887095836111,5.38622084699882,7.15865278244019,25,1,64,0,0,0.269699096679687,30.3030319213867,2,1,1,87.272834777832,0,87.4911918640137,,,,,,,,,,,,,,,,,,,,,,,,,,,,,,,,,
,3865928197.18226,69.0385055541992,49999.7265625,0.067015417469063,6.42233523776814E-5,1,2,12.9061126708984,4.98254728376673,36.4699997007847,87.0998719791798,12.6203443457217,100,-0.000132277649282363,,,,,,,,,,,,,,,,,,,,,69.0385055541992,69.0385055541992,49999.7265625,49999.7265625,50.0261793020726,5.38852485820942,7.07724571228027,26,1,0,0,1,0.270843505859375,31.2805480957031,2,1,1,69.0385055541992,0,69.0385055541992,,,,,,,,,,,,,,,,,,,,,,,,,,,,,,,,,
,3865928343.35251,44.0945091247559,49999.7265625,0.106505246152538,6.79822103197723E-5,1,2,12.9061126708984,4.98345998289989,36.4100001752377,138.455600227896,20.0948768610176,1000,-0.000185106483622831,,,,,,,,,,,,,,,,,,,,,43.9400978088379,44.2489204406738,49999.7265625,49999.7265625,50.0930085404668,5.38429717439284,6.81996583938599,26,1,0,0,1,0.26824951171875,30.7917900085449,2,1,1,43.9400978088379,0,44.0945091247559,,,,,,,,,,,,,,,,,,,,,,,,,,,,,,,,,
,3865928441.80372,27.5052919387817,49999.7265625,0.153643998549579,0.00322057474249995,1,2,12.9061126708984,4.98248288808299,36.3800004124641,199.320374747679,31.4314970657019,1000,0.0016191399086209,,,,,,,,,,,,,,,,,,,,,27.348876953125,27.6617069244385,49999.7265625,49999.7265625,49.9499705214476,5.38949108700341,6.41814804077148,26,1,0,0,1,0.271072387695313,31.2805480957031,2,1,1,27.348876953125,0,27.5052919387817,,,,,,,,,,,,,,,,,,,,,,,,,,,,,,,,,
,3865928510.42515,16.2853498458862,49999.7265625,0.209511289726026,0.00322032910496962,1,2,12.9061126708984,4.98235434786888,36.3500006496906,272.425869826715,38.5063840385577,1000,-0.00114214402380983,,,,,,,,,,,,,,,,,,,,,16.1896858215332,16.3810138702393,49999.7265625,49999.7265625,50.2571505295053,5.38841812746204,5.74668645858765,26,1,0,0,1,0.27008056640625,30.7917900085449,2,1,1,16.1896858215332,0,16.2853498458862,,,,,,,,,,,,,,,,,,,,,,,,,,,,,,,,,
,3865928580.77291,6.38866543769836,49999.7265625,0.279088629574588,0.00393389954260315,1,2,12.9061126708984,4.98203077410105,36.3500006496906,362.487777328179,53.8476627035595,1000,0.000447747778512385,,,,,,,,,,,,,,,,,,,,,6.24835109710693,6.52897977828979,49999.7265625,49999.7265625,50.56745705164,5.39147814029578,4.18689012527466,26,1,0,0,1,0.27191162109375,31.7693061828613,6,1,1,6.24835109710693,0,6.38866543769836,,,,,,,,,,,,,,,,,,,,,,,,,,,,,,,,,
,3865928649.70444,3.07904756069183,49999.7265625,0.303572105776428,0.00273612558046539,1,2,12.9061126708984,4.98222618722373,36.3500006496906,394.64020565571,56.3223847146447,1000,-0.00124663003513689,,,,,,,,,,,,,,,,,,,,,3.07135772705078,3.08673739433289,49999.7265625,49999.7265625,50.8808900878515,5.39217831401543,3.0864474773407,26,1,0,0,1,0.271453857421875,31.2805480957031,6,1,1,3.07135772705078,0,3.07904756069183,,,,,,,,,,,,,,,,,,,,,,,,,,,,,,,,,
,3865928717.73917,2.80975639820099,49999.7265625,0.307555514689611,6.57989456210299E-5,1,2,12.9061126708984,4.98278960125842,36.3500006496906,399.621692980898,58.8432772935308,1000,0.000101302013050467,,,,,,,,,,,,,,,,,,,,,2.80624389648438,2.8132688999176,49999.7265625,49999.7265625,50.9035573149092,5.39103086578415,2.93576836585999,26,1,0,0,1,0.270004272460938,31.2805480957031,6,1,1,2.80624389648438,0,2.80975639820099,,,,,,,,,,,,,,,,,,,,,,,,,,,,,,,,,
,3865928788.41528,2.80447328090668,49999.7265625,0.307625935040388,6.00868505784996E-5,1,2,12.9061126708984,4.98294091144772,36.3599993288517,399.747385213713,58.7426284683563,1000,1.15701909008854E-5,,,,,,,,,,,,,,,,,,,,,2.80145525932312,2.80749130249023,49999.7265625,49999.7265625,50.9387305982746,5.39114272818479,2.94015264511108,26,1,0,0,1,0.270767211914062,30.3030319213867,6,1,1,2.80145525932312,0,2.80447328090668,,,,,,,,,,,,,,,,,,,,,,,,,,,,,,,,,
,3865928855.10942,2.68407130241394,49999.7265625,0.307832344169804,5.56218401039554E-5,1,2,12.9061126708984,4.98282183517288,36.3500006496906,399.988301618709,58.8744874075179,1000,8.42395066775377E-5,,,,,,,,,,,,,,,,,,,,,2.67726874351501,2.69087386131287,49999.7265625,49999.7265625,51.1083439869477,5.3918653612743,2.87471008300781,26,1,0,0,1,0.270004272460938,30.7917900085449,6,1,1,2.67726874351501,0,2.68407130241394,,,,,,,,,,,,,,,,,,,,,,,,,,,,,,,,,
,3865928923.31284,2.0816912651062,49999.7265625,0.309667899073262,0.000121878562930575,1,2,12.9061126708984,4.98255855330749,36.3599993288517,402.307784470919,59.4641951020089,1000,0.000271797351703697,,,,,,,,,,,,,,,,,,,,,2.08084726333618,2.08253526687622,49999.7265625,49999.7265625,51.1482070414285,5.3938082319939,2.52212166786194,26,1,0,0,1,0.271148681640625,31.2805480957031,2,1,1,2.08084726333618,0,2.0816912651062,,,,,,,,,,,,,,,,,,,,,,,,,,,,,,,,,
,3865928993.72244,2.00241708755493,49999.7265625,0.310111118949749,8.88941784874918E-5,1,2,12.9061126708984,4.98262259249636,36.3500006496906,402.912532819098,59.4029551922035,1000,0.000158725693654599,,,,,,,,,,,,,,,,,,,,,2.00219464302063,2.00263953208923,49999.7265625,49999.7265625,51.0981828161977,5.39268262221462,2.46171522140503,26,1,0,0,1,0.269699096679687,32.2580642700195,5,1,1,2.00219464302063,0,2.00241708755493,,,,,,,,,,,,,,,,,,,,,,,,,,,,,,,,,
,3865929440.17364,8.16438579559326,26.500186920166,0.00115520892739177,5.02129012885037E-6,1,5,12.9061126708984,5.00231316933034,36.3500006496906,1.50956979842774,0.220226891184409,100,-1.15784713571299E-6,,,,,,,,,,,,,,,,,,,,,8.16438579559326,8.16438579559326,26.500186920166,26.500186920166,50.2989676552842,5.38793632722492,4.39731693267822,65,1,0,0,1,0.27374267578125,30.7917900085449,6,1,1,8.16438579559326,0,8.16438579559326,,,,,,,,,,,,,,,,,,,,,,,,,,,,,,,,,
,3865929639.72007,39.0045776367188,26.500186920166,0.000199252017046024,8.49494195405905E-8,1,5,12.9061126708984,5.00343781636726,36.3700017333031,0.260453945962908,0.038001541816784,1,-1.96225100972505E-7,,,,,,,,,,,,,,,,,,,,,39.0045776367188,39.0045776367188,26.500186920166,26.500186920166,50.1387338088418,5.38544307296619,6.28065872192383,65,1,0,0,1,0.272140502929687,31.7693061828613,2,1,1,39.0045776367188,0,39.0045776367188,,,,,,,,,,,,,,,,,,,,,,,,,,,,,,,,,
,3865929835.88162,70.0009155273437,26.500186920166,0.000136340840977388,3.49041537423228E-8,1,5,12.9061126708984,5.00189444729802,36.3899990916252,0.178148045078543,0.0259515022205572,1,-1.65140508666617E-7,,,,,,,,,,,,,,,,,,,,,70.0009155273437,70.0009155273437,26.500186920166,26.500186920166,50.1676540640534,5.3897832573004,6.69178009033203,65,1,0,0,1,0.27557373046875,31.2805480957031,2,1,1,70.0009155273437,0,70.0009155273437,,,,,,,,,,,,,,,,,,,,,,,,,,,,,,,,,
,3865930026.66614,101.001411437988,26.500186920166,8.29335659892387E-5,1.21813009707593E-7,1,5,12.9061126708984,5.00153075591687,36.4499986171722,0.108351770841975,0.0157930376631093,1,-9.36885828960307E-8,,,,,,,,,,,,,,,,,,,,,101.001411437988,101.001411437988,26.500186920166,26.500186920166,50.122319609938,5.39127506199968,6.88993644714355,65,1,0,0,1,0.279083251953125,31.2805480957031,2,1,1,101.001411437988,0,101.001411437988,,,,,,,,,,,,,,,,,,,,,,,,,,,,,,,,,
,3865930214.34618,132.012512207031,26.500186920166,5.01463172643036E-5,1.58519671961348E-8,1,5,12.9061126708984,5.00090337324297,36.5299992263317,0.0654822209671836,0.00969655495455591,1,5.73360688918897E-8,,,,,,,,,,,,,,,,,,,,,132.012512207031,132.012512207031,26.500186920166,26.500186920166,50.1789876775822,5.39267639327765,6.99646520614624,65,1,0,0,1,0.279693603515625,30.7917900085449,2,1,1,132.012512207031,0,132.012512207031,,,,,,,,,,,,,,,,,,,,,,,,,,,,,,,,,
,3865930401.90364,163.065582275391,26.500186920166,3.63304587250687E-5,1.36231859177636E-8,1,5,12.9061126708984,5.00074485833428,36.6300009191036,0.0474421407038486,0.0070036809501412,1,2.5417197742795E-8,,,,,,,,,,,,,,,,,,,,,163.065582275391,163.065582275391,26.500186920166,26.500186920166,49.9452807503322,5.39326009645172,7.06957387924194,65,1,0,0,1,0.27862548828125,31.2805480957031,2,1,1,163.065582275391,0,163.065582275391,,,,,,,,,,,,,,,,,,,,,,,,,,,,,,,,,
,3865930589.10196,194.148811340332,26.500186920166,2.60541965233482E-5,1.12624515052812E-8,1,5,12.9061126708984,4.9976419358768,36.7499999701977,0.033995914959372,0.00500056085714238,1,4.64259099532119E-9,,,,,,,,,,,,,,,,,,,,,194.122665405273,194.174957275391,26.500186920166,26.500186920166,50.0808932984188,5.40543181279891,7.15701293945313,63,1,64,0,0,0.26763916015625,31.7693061828613,2,1,1,194.174957275391,0,194.148811340332,,,,,,,,,,,,,,,,,,,,,,,,,,,,,,,,,
,3865930775.28077,225.028945922852,26.500186920166,1.88836014048117E-5,7.05082185781703E-9,1,5,12.9061126708984,4.99819736708464,36.8800014257431,0.0246411103643695,0.00364080235658592,1,1.55663621623149E-8,,,,,,,,,,,,,,,,,,,,,225.028945922852,225.028945922852,26.500186920166,26.500186920166,50.0914452834284,5.40372814494754,7.27716636657715,64,1,64,0,0,0.272979736328125,31.7693061828613,2,1,1,225.028945922852,0,225.028945922852,,,,,,,,,,,,,,,,,,,,,,,,,,,,,,,,,
,3865930962.63253,256.034729003906,26.500186920166,1.34942946897057E-5,8.2182173281702E-9,1,5,12.9061126708984,4.99963110620089,37.0399989187717,0.0176169575566099,0.00259428183301942,1,4.61691033479189E-9,,,,,,,,,,,,,,,,,,,,,256.034729003906,256.034729003906,26.500186920166,26.500186920166,50.1258369382745,5.39997868769772,7.51254320144653,64,1,64,0,0,0.281753540039062,32.2580642700195,2,1,1,256.034729003906,0,256.034729003906,,,,,,,,,,,,,,,,,,,,,,,,,,,,,,,,,
,3865931149.42948,287.18359375,26.500186920166,9.99506630129671E-6,1.03302490859811E-8,1,5,12.9061126708984,5.00051898955643,37.2200012207031,0.013051363824483,0.00192581990904676,1,6.32014680958061E-9,,,,,,,,,,,,,,,,,,,,,287.18359375,287.18359375,26.500186920166,26.500186920166,50.0871463265726,5.39688702924031,7.44922351837158,64,1,64,0,0,0.279998779296875,32.2580642700195,2,1,1,287.18359375,0,287.18359375,,,,,,,,,,,,,,,,,,,,,,,,,,,,,,,,,
,3865932797.65832,2.00012695789337,43312.2109375,0.297571051744851,7.25997265452474E-5,1,2,12.9061126708984,4.98198665358948,36.3500006496906,386.520419692753,57.1952247213196,1000,0.00030979185056627,,,,,,,,,,,,,,,,,,,,,2.00012135505676,2.00013256072998,43202.4375,43421.984375,50.9449836264285,5.39322189196012,2.55144858360291,26,1,0,0,1,0.272140502929687,30.7917900085449,1,6,1,2.00013256072998,0,2.00012695789337,,,,,,,,,,,,,,,,,,,,,,,,,,,,,,,,,
,3865932864.13254,1.99986743927002,36678.318359375,0.277849502591314,4.81853219520017E-5,1,2,12.9061126708984,4.98207459993296,36.3500006496906,360.908637559077,53.433564093091,1000,0.000310530604014856,,,,,,,,,,,,,,,,,,,,,1.99954771995544,2.00018715858459,36603.16796875,36753.46875,50.9008216150919,5.39168257183681,2.55030226707458,26,1,0,0,1,0.271377563476562,31.2805480957031,1,6,1,1.99954771995544,0,1.99986743927002,,,,,,,,,,,,,,,,,,,,,,,,,,,,,,,,,
,3865932931.86037,1.99987691640854,29918.9814453125,0.25440282766797,9.19687470033727E-5,1,2,12.9061126708984,4.98197023532013,36.3500006496906,330.421349002493,49.0717028654491,1000,0.000398740344355263,,,,,,,,,,,,,,,,,,,,,1.99974954128265,2.00000429153442,29764.083984375,30073.87890625,50.4244190326207,5.39104638155367,2.55114102363586,26,1,0,0,1,0.27374267578125,30.7917900085449,1,6,1,2.00000429153442,0,1.99987691640854,,,,,,,,,,,,,,,,,,,,,,,,,,,,,,,,,
,3865933001.09886,2.00068366527557,23005.7919921875,0.225250079180771,8.73082304105519E-5,1,2,12.9061126708984,4.98184367569235,36.3599993288517,292.575773413568,43.2508571097551,1000,0.000202148557490485,,,,,,,,,,,,,,,,,,,,,1.99995017051697,2.00141716003418,22916.09375,23095.490234375,50.3571989799669,5.38928092613734,2.55515074729919,26,1,0,0,1,0.273590087890625,31.2805480957031,1,6,1,1.99944269657135,0,2.00068366527557,,,,,,,,,,,,,,,,,,,,,,,,,,,,,,,,,
,3865933066.75498,2.00042325258255,16451.1264648438,0.188650623799145,7.10908635802632E-5,1,2,12.9061126708984,4.98243094383282,36.3500006496906,245.082432174799,36.1963493381557,1000,0.000143940931254305,,,,,,,,,,,,,,,,,,,,,1.99931299686432,2.00153350830078,16286.4716796875,16615.78125,50.3501643232938,5.38923108900699,2.54588341712952,26,1,0,0,1,0.27130126953125,29.3255138397217,1,6,1,2.00153350830078,0,2.00042325258255,,,,,,,,,,,,,,,,,,,,,,,,,,,,,,,,,
,3865933133.95149,1.99919801950455,9735.02685546875,0.138621397758746,9.57787608829294E-5,1,2,12.9061126708984,4.9821070204662,36.3500006496906,180.090694963584,26.4628812018486,1000,4.20868669100444E-6,,,,,,,,,,,,,,,,,,,,,1.99889862537384,1.99949741363525,9645.115234375,9824.9384765625,50.2360465594861,5.38763608847227,2.53993725776672,26,1,0,0,1,0.270309448242187,31.2805480957031,1,6,1,1.99889862537384,0,1.99919801950455,,,,,,,,,,,,,,,,,,,,,,,,,,,,,,,,,
,3865933204.82451,2.00054526329041,2654.5126953125,0.0566127689930196,0.000163890516661548,1,2,12.9061126708984,4.98179742684094,36.3500006496906,73.532961094654,10.8703219957101,100,5.08819755043633E-5,,,,,,,,,,,,,,,,,,,,,2.00021123886108,2.00087928771973,2599.55053710938,2709.47485351562,50.1492857938515,5.38994874310629,2.53442573547363,26,1,0,0,1,0.271530151367187,31.7693061828613,1,6,1,2.00021123886108,0,2.00054526329041,,,,,,,,,,,,,,,,,,,,,,,,,,,,,,,,,
,3865933301.15365,1.99930864572525,-6976.13037109375,-0.104804609278405,0.000128357808217323,1,2,12.9061126708984,4.98169939291553,36.3500006496906,-136.122159862388,-20.1385245814566,100,-0.000106016146263168,,,,,,,,,,,,,,,,,,,,,1.99919188022614,1.99942541122437,-7066.2734375,-6885.9873046875,50.3681417792361,5.38798183602274,2.5292329788208,26,1,0,0,1,0.272293090820313,31.2805480957031,1,6,1,1.99942541122437,0,1.99930864572525,,,,,,,,,,,,,,,,,,,,,,,,,,,,,,,,,
,3865933404.09303,1.9994695186615,-17267.2734375,-0.19252267842594,7.64280822272452E-5,1,2,12.9061126708984,4.98140190407199,36.3500006496906,-250.081426419104,-36.6475894630234,1000,6.94162502483894E-5,,,,,,,,,,,,,,,,,,,,,1.99898707866669,1.99995195865631,-17337.240234375,-17197.306640625,50.3786937642457,5.390719179945,2.5067400932312,26,1,0,0,1,0.272140502929687,31.2805480957031,1,6,1,1.99898707866669,0,1.9994695186615,,,,,,,,,,,,,,,,,,,,,,,,,,,,,,,,,
,3865933470.66236,2.00002932548523,-23927.7138671875,-0.228749494736676,8.60512901479414E-5,1,2,12.9061126708984,4.98136257299291,36.3500006496906,-297.131863121945,-43.569315919801,1000,6.22560767513141E-5,,,,,,,,,,,,,,,,,,,,,1.99990224838257,2.00015640258789,-23997.724609375,-23857.703125,50.5940324212938,5.3914711482809,2.4993851184845,26,1,0,0,1,0.271682739257813,31.2805480957031,1,6,1,2.00015640258789,0,2.00002932548523,,,,,,,,,,,,,,,,,,,,,,,,,,,,,,,,,
,3865933538.88839,1.99988329410553,-30756.9150390625,-0.257568203091201,5.46555498667848E-5,1,2,12.9061126708984,4.98131871603811,36.3500006496906,-334.557262352097,-49.0865433418398,1000,4.7917922819319E-5,,,,,,,,,,,,,,,,,,,,,1.99863505363464,2.00113153457642,-30847.18359375,-30666.646484375,50.7292541551207,5.3914963765619,2.48551726341248,26,1,0,0,1,0.272674560546875,31.2805480957031,1,6,1,1.99863505363464,0,1.99988329410553,,,,,,,,,,,,,,,,,,,,,,,,,,,,,,,,,
,3865933605.33326,1.99971783161163,-37414.392578125,-0.28088309997817,6.6846547330493E-5,1,2,12.9061126708984,4.98192625974756,36.3500006496906,-364.898414236981,-53.5749978217051,1000,2.4545827249541E-5,,,,,,,,,,,,,,,,,,,,,1.99936461448669,2.00007104873657,-37509.51171875,-37319.2734375,50.7956925792554,5.39088203831029,2.47516417503357,26,1,0,0,1,0.272293090820313,31.2805480957031,1,6,1,1.99936461448669,0,1.99971783161163,,,,,,,,,,,,,,,,,,,,,,,,,,,,,,,,,
,3865933673.82706,1.99934244155884,-44276.587890625,-0.300968696667186,0.000105862952787813,1,2,12.9061126708984,4.98193634537712,36.3500006496906,-390.994652514722,-57.3946716525657,1000,3.52073402807458E-5,,,,,,,,,,,,,,,,,,,,,1.9990907907486,1.99959409236908,-44371.6953125,-44181.48046875,51.0981828161977,5.39082702586113,2.46934676170349,26,1,0,0,1,0.273895263671875,31.7693061828613,1,6,1,1.9990907907486,0,1.99934244155884,,,,,,,,,,,,,,,,,,,,,,,,,,,,,,,,,
,3865933742.30972,2.00058674812317,-49337.904296875,-0.314227623774953,0.000113211578808088,1,2,12.9061126708984,4.98208124915752,36.3500006496906,-408.248563494803,-59.8420292123149,1000,0.000101082583254968,,,,,,,,,,,,,,,,,,,,,2.00023794174194,2.00093555450439,-49432.69140625,-49243.1171875,51.1806446249766,5.39080024409597,2.44797110557556,26,1,0,0,1,0.271453857421875,31.2805480957031,5,6,1,2.00093555450439,0,2.00058674812317,,,,,,,,,,,,,,,,,,,,,,,,,,,,,,,,,
,3865933810.93458,1.99964565038681,-42486.388671875,-0.296348010361919,7.74578507725371E-5,1,2,12.9061126708984,4.98206135429017,36.3500006496906,-385.061280670932,-56.1351366600551,1000,0.000327447321346689,,,,,,,,,,,,,,,,,,,,,1.99944067001343,1.99985063076019,-42566.22265625,-42406.5546875,50.9316959416015,5.39024347542362,2.44299268722534,26,1,0,0,1,0.271987915039062,31.7693061828613,1,6,1,1.99985063076019,0,1.99964565038681,,,,,,,,,,,,,,,,,,,,,,,,,,,,,,,,,
,3865933879.32871,1.99995124340057,-35659.08203125,-0.27557733089646,6.47880513477805E-5,1,2,12.9061126708984,4.98212215399833,36.3500006496906,-358.065496331783,-52.2930636696824,1000,0.000234085154733,,,,,,,,,,,,,,,,,,,,,1.99955081939697,2.00035166740417,-35748.89453125,-35569.26953125,50.684310515265,5.3899482251685,2.43852996826172,26,1,0,0,1,0.275192260742187,31.7693061828613,1,6,1,2.00035166740417,0,1.99995124340057,,,,,,,,,,,,,,,,,,,,,,,,,,,,,,,,,
,3865933945.83556,2.0001814365387,-29021.69140625,-0.251694700169054,6.31993605932028E-5,1,2,12.9061126708984,4.98208999581935,36.3500006496906,-327.035628329992,-47.7301901093439,1000,0.000237286594817749,,,,,,,,,,,,,,,,,,,,,1.99992084503174,2.00044202804565,-29121.63671875,-28921.74609375,50.6143547627938,5.38929769904867,2.43729782104492,26,1,0,0,1,0.27130126953125,31.7693061828613,1,6,1,1.99992084503174,0,2.0001814365387,,,,,,,,,,,,,,,,,,,,,,,,,,,,,,,,,
,3865934016.30689,1.99986606836319,-21989.0576171875,-0.220397717555484,7.39363975256117E-5,1,2,12.9061126708984,4.98210264333648,36.3500006496906,-286.367630563982,-41.820973539603,1000,0.000188040906792477,,,,,,,,,,,,,,,,,,,,,1.99986004829407,1.99987208843231,-22084.208984375,-21893.90625,50.5244674830823,5.3894382049646,2.43155479431152,26,1,0,0,1,0.271759033203125,30.7917900085449,5,6,1,1.99987208843231,0,1.99986606836319,,,,,,,,,,,,,,,,,,,,,,,,,,,,,,,,,
,3865934085.06971,1.99991381168365,-15121.4848632812,-0.18085414790811,8.35505055911351E-5,1,2,12.9061126708984,4.98183241941032,36.3500006496906,-234.972849628818,-34.2946753350523,1000,0.000169851618183332,,,,,,,,,,,,,,,,,,,,,1.9996874332428,2.00014019012451,-15186.5,-15056.4697265625,50.2723922856303,5.38901806203142,2.43201589584351,26,1,0,0,1,0.27435302734375,31.2805480957031,1,6,1,2.00014019012451,0,1.99991381168365,,,,,,,,,,,,,,,,,,,,,,,,,,,,,,,,,
,3865934151.61925,1.99983018636703,-8478.962890625,-0.127473130596418,0.000107590995813381,1,2,12.9061126708984,4.98213594699642,36.3500006496906,-165.644918818165,-24.08845960543,1000,0.000185797923496824,,,,,,,,,,,,,,,,,,,,,1.99964892864227,2.0000114440918,-8543.890625,-8414.03515625,50.3771305072072,5.38818478467493,2.43274879455566,26,1,0,0,1,0.274200439453125,31.7693061828613,1,6,1,2.0000114440918,0,1.99983018636703,,,,,,,,,,,,,,,,,,,,,,,,,,,,,,,,,
,3865934224.20536,1.99875861406326,-1224.57446289062,-0.0332711836947655,0.000193072073070518,1,2,12.9061126708984,4.98211195964156,36.3500006496906,-43.2280459330043,-6.32727297894928,100,1.76313732400129E-5,,,,,,,,,,,,,,,,,,,,,1.99811184406281,1.99940538406372,-1279.49279785156,-1169.65612792969,50.1418603229188,5.38823834444032,2.42193150520325,26,1,0,0,1,0.273895263671875,31.2805480957031,6,6,1,1.99940538406372,0,1.99875861406326,,,,,,,,,,,,,,,,,,,,,,,,,,,,,,,,,
,3865934308.41276,2.0005716085434,7192.71997070312,0.109546870413511,0.000125104986935726,1,2,12.9061126708984,4.98232227072986,36.3500006496906,142.333987491343,20.8663611204523,100,-3.31960395364508E-5,,,,,,,,,,,,,,,,,,,,,2.00003838539124,2.00110483169556,7097.7001953125,7287.73974609375,50.2102528183515,5.38801091468086,2.41790461540222,26,1,0,0,1,0.271759033203125,30.7917900085449,1,6,1,2.00110483169556,0,2.0005716085434,,,,,,,,,,,,,,,,,,,,,,,,,,,,,,,,,
,3865934391.06517,2.00332355499268,15464.294921875,0.183112943410431,8.09943404748494E-5,1,2,12.9061126708984,4.98221849966666,36.3500006496906,237.940889046794,34.6763482231553,1000,-0.000210793698134581,,,,,,,,,,,,,,,,,,,,,2.003093957901,2.00355315208435,15369.306640625,15559.283203125,50.3212440680823,5.38931526223795,2.41035771369934,26,1,0,0,1,0.271072387695313,31.7693061828613,6,6,1,2.003093957901,0,2.00332355499268,,,,,,,,,,,,,,,,,,,,,,,,,,,,,,,,,
,3865934457.58475,2.00037717819214,22121.0263671875,0.222074205817631,9.04846477017951E-5,1,2,12.9061126708984,4.98197741132846,36.3500006496906,288.53425104082,42.1477036138688,1000,-0.000181695754760544,,,,,,,,,,,,,,,,,,,,,1.99978089332581,2.00097346305847,22021.0546875,22220.998046875,50.6585167741304,5.39034489431344,2.40928649902344,26,1,0,0,1,0.272903442382813,31.7693061828613,5,6,1,1.99978089332581,0,2.00037717819214,,,,,,,,,,,,,,,,,,,,,,,,,,,,,,,,,
,3865934528.04506,2.00513225793838,29167.95703125,0.253998702622827,9.78789242007612E-5,1,2,12.9061126708984,4.98189388867496,36.3500006496906,329.999504320953,48.2429687794863,1000,-0.000179013517672819,,,,,,,,,,,,,,,,,,,,,1.99276745319366,2.01749706268311,29077.80078125,29258.11328125,50.6393668754092,5.39166493290357,2.39896488189697,26,1,0,0,1,0.2728271484375,31.7693061828613,6,6,1,1.99276745319366,0,2.00513225793838,,,,,,,,,,,,,,,,,,,,,,,,,,,,,,,,,
,3865934597.83599,2.00029557943344,36162.388671875,0.279533774124229,9.57633139858614E-5,1,2,12.9061126708984,4.98193256931721,36.3599993288517,363.19418710247,52.9906501716936,1000,-0.000276199145564309,,,,,,,,,,,,,,,,,,,,,1.9999772310257,2.00061392784119,36001.97265625,36322.8046875,50.6784483013707,5.39240960705682,2.39808583259583,26,1,0,0,1,0.272445678710938,31.2805480957031,1,6,1,1.9999772310257,0,2.00029557943344,,,,,,,,,,,,,,,,,,,,,,,,,,,,,,,,,
,3865934663.36414,2.00005626678467,42731.458984375,0.29919408482779,0.000107324888563635,1,2,12.9061126708984,4.98214724831948,36.3500006496906,388.748064414112,56.8165066122039,1000,-0.000222150501316601,,,,,,,,,,,,,,,,,,,,,1.99990439414978,2.00020813941956,42676.34765625,42786.5703125,50.9817201668323,5.39189736950347,2.3962070941925,26,1,0,0,1,0.270614624023438,31.2805480957031,1,6,1,1.99990439414978,0,2.00005626678467,,,,,,,,,,,,,,,,,,,,,,,,,,,,,,,,,
,3865934731.47386,2.00147724151611,49555.494140625,0.317331674379678,6.99599891721508E-5,1,2,12.9061126708984,4.98231207913312,36.3500006496906,412.328817550953,60.2969852141275,1000,-0.000209928924356315,,,,,,,,,,,,,,,,,,,,,2.00104999542236,2.00190448760986,49460.2421875,49650.74609375,51.1251490001112,5.39266444575382,2.39375448226929,26,1,0,0,1,0.272674560546875,32.2580642700195,1,6,1,2.00190448760986,0,2.00147724151611,,,,,,,,,,,,,,,,,,,,,,,,,,,,,,,,,
,3865935297.62618,28.0116901397705,26.4876518249512,0.000157396815137206,7.74744188225081E-8,1,5,12.9061126708984,4.9814881283865,36.3500006496906,0.204395706689949,0.0303921884982971,1,2.74475689924888E-7,,,,,,,,,,,,,,,,,,,,,28.0116901397705,28.0116901397705,26.4876518249512,26.4876518249512,50.3216348823419,5.39235502375661,5.94042873382568,63,1,64,0,0,0.27313232421875,31.7693061828613,2,1,1,28.0116901397705,0,28.0116901397705,,,,,,,,,,,,,,,,,,,,,,,,,,,,,,,,,
,3865935495.5898,59.0006561279297,26.4876518249512,0.000113376613019746,4.49024837500077E-8,1,5,12.9061126708984,4.98238834728055,36.3800004124641,0.14729264248375,0.0217328353294572,1,7.07696832571042E-8,,,,,,,,,,,,,,,,,,,,,59.0006561279297,59.0006561279297,26.4876518249512,26.4876518249512,50.1965743192649,5.39069418670867,6.57416915893555,65,1,0,0,1,0.269851684570313,31.2805480957031,2,1,1,59.0006561279297,0,59.0006561279297,,,,,,,,,,,,,,,,,,,,,,,,,,,,,,,,,
,3865935688.41934,90.0069046020508,26.4876518249512,8.14863470060833E-5,2.49557841452742E-8,1,5,12.9061126708984,4.981306433653,36.4300012588501,0.105817509942109,0.0157018982941858,1,1.17678118505987E-7,,,,,,,,,,,,,,,,,,,,,90.0069046020508,90.0069046020508,26.4876518249512,26.4876518249512,50.2485526157938,5.3954266422688,6.81246137619018,65,1,0,0,1,0.273971557617187,31.2805480957031,2,1,1,90.0069046020508,0,90.0069046020508,,,,,,,,,,,,,,,,,,,,,,,,,,,,,,,,,
,3865935876.84788,121.010032653809,26.4876518249512,5.70858261957847E-5,1.87351580836208E-8,1,5,12.9061126708984,4.98103939884615,36.4999994635582,0.0741145118041359,0.0110747557555462,1,1.40580475385116E-7,,,,,,,,,,,,,,,,,,,,,121.010032653809,121.010032653809,26.4876518249512,26.4876518249512,50.2000916476015,5.39877789808585,6.93610143661499,65,1,0,0,1,0.27587890625,32.7468223571777,2,1,1,121.010032653809,0,121.010032653809,,,,,,,,,,,,,,,,,,,,,,,,,,,,,,,,,
,3865936064.30141,152.032791137695,26.4876518249512,4.1381338853653E-5,2.91882724958303E-8,1,5,12.9061126708984,4.98060811923535,36.5899987518787,0.0537177942962199,0.00803420422781613,1,1.07393125834974E-7,,,,,,,,,,,,,,,,,,,,,152.032791137695,152.032791137695,26.4876518249512,26.4876518249512,50.229011902813,5.39898505755346,7.01630640029907,64,1,64,0,0,0.277328491210938,31.7693061828613,2,1,1,152.032791137695,0,152.032791137695,,,,,,,,,,,,,,,,,,,,,,,,,,,,,,,,,
,3865936251.32205,183.017440795898,26.4876518249512,2.9874763009758E-5,9.34939761300441E-9,1,5,12.9061126708984,4.97952550148284,36.6999991238117,0.0387778413691077,0.0057387062823878,1,3.1530408401288E-8,,,,,,,,,,,,,,,,,,,,,183.017440795898,183.017440795898,26.4876518249512,26.4876518249512,50.1563204505245,5.40228791710971,7.09205007553101,63,1,64,0,0,0.281219482421875,31.7693061828613,2,1,1,183.017440795898,0,183.017440795898,,,,,,,,,,,,,,,,,,,,,,,,,,,,,,,,,
,3865936437.60249,214.069778442383,26.4876518249512,2.14458297565175E-5,9.06790945259317E-9,1,5,12.9061126708984,4.98831569683567,36.8300005793571,0.0279102528871698,0.00410110451878811,1,5.88705716086374E-10,,,,,,,,,,,,,,,,,,,,,214.069778442383,214.069778442383,26.4876518249512,26.4876518249512,50.1539755649668,5.40609661657329,7.1907000541687,65,1,0,0,1,0.279464721679687,32.2580642700195,2,1,1,214.069778442383,0,214.069778442383,,,,,,,,,,,,,,,,,,,,,,,,,,,,,,,,,
,3865936624.74405,245.029052734375,26.4876518249512,1.54403933729427E-5,8.80961732036103E-9,1,5,12.9061126708984,4.98889383433263,36.9799993932247,0.0200962635759144,0.00296406200340277,1,8.79930408956113E-9,,,,,,,,,,,,,,,,,,,,,245.029052734375,245.029052734375,26.4876518249512,26.4876518249512,50.1946202479669,5.40482054989945,7.40686273574829,64,1,64,0,0,0.282363891601562,31.2805480957031,2,1,1,245.029052734375,0,245.029052734375,,,,,,,,,,,,,,,,,,,,,,,,,,,,,,,,,
,3865936812.01273,276.119903564453,26.4876518249512,1.15666912291082E-5,6.50720212521974E-9,1,5,12.9061126708984,4.98951029995995,37.1499992907047,0.0150574457173873,0.00221848621452815,1,4.79899924184496E-9,,,,,,,,,,,,,,,,,,,,,276.119903564453,276.119903564453,26.4876518249512,26.4876518249512,50.1723438351688,5.40435978757727,7.6020450592041,63,1,64,0,0,0.281906127929687,31.7693061828613,2,1,1,276.119903564453,0,276.119903564453,,,,,,,,,,,,,,,,,,,,,,,,,,,,,,,,,
,3865937590.50633,296.988067626953,26.2620124816895,1.5730778533813E-5,6.4412193698651E-9,1,5,12.9061126708984,4.98085737881059,37.2599996626377,0.0204341639376837,0.00297031644686203,1,-2.38827554771881E-8,,,,,,,,,,,,,,,,,,,,,296.988067626953,296.988067626953,26.2620124816895,26.2620124816895,50.0785484128611,5.39854292926827,8.12123394012451,65,1,0,0,1,0.274505615234375,30.7917900085449,2,1,1,296.988067626953,0,296.988067626953,,,,,,,,,,,,,,,,,,,,,,,,,,,,,,,,,
,3865937767.60634,265.861358642578,26.2620124816895,1.74834106989244E-5,7.34348372505561E-9,1,5,12.9061126708984,4.98110352317191,37.1100008487701,0.0227124463390943,0.00330115062306636,1,-2.67981811968217E-8,,,,,,,,,,,,,,,,,,,,,265.861358642578,265.861358642578,26.2620124816895,26.2620124816895,50.1852407057361,5.3972551092069,7.86270141601562,63,1,64,0,0,0.2734375,31.7693061828613,2,1,1,265.861358642578,0,265.861358642578,,,,,,,,,,,,,,,,,,,,,,,,,,,,,,,,,
,3865937953.78264,234.974426269531,26.2620124816895,1.91159519033154E-5,7.33713224981945E-9,1,5,12.9061126708984,4.97958233618189,36.9799993932247,0.0248205014133546,0.00362210443877565,1,-1.8321551952118E-8,,,,,,,,,,,,,,,,,,,,,234.974426269531,234.974426269531,26.2620124816895,26.2620124816895,50.1062962252938,5.40133569866456,7.73040628433228,63,1,64,0,0,0.280914306640625,32.2580642700195,2,1,1,234.974426269531,0,234.974426269531,,,,,,,,,,,,,,,,,,,,,,,,,,,,,,,,,
,3865938140.95878,203.782516479492,26.2620124816895,2.06262168835181E-5,6.5110580105028E-9,1,5,12.9061126708984,4.98007254615533,36.8600003421307,0.0267873529975356,0.00389391262313988,1,-3.12437406997089E-8,,,,,,,,,,,,,,,,,,,,,203.782516479492,203.782516479492,26.2620124816895,26.2620124816895,50.2630127433996,5.40095570176105,7.63625907897949,65,1,0,0,1,0.278778076171875,31.2805480957031,2,1,1,203.782516479492,0,203.782516479492,,,,,,,,,,,,,,,,,,,,,,,,,,,,,,,,,
,3865938324.93155,172.991470336914,26.2620124816895,2.22371087513196E-5,6.7579449347748E-9,1,5,12.9061126708984,4.98079361974083,36.7599986493588,0.0288865976695188,0.00419007203780115,1,-4.04651938895844E-8,,,,,,,,,,,,,,,,,,,,,172.991470336914,172.991470336914,26.2620124816895,26.2620124816895,50.2602770435822,5.39754474528174,7.5475869178772,63,1,64,0,0,0.276641845703125,31.7693061828613,2,1,1,172.991470336914,0,172.991470336914,,,,,,,,,,,,,,,,,,,,,,,,,,,,,,,,,
,3865938511.33365,141.950668334961,26.2620124816895,2.41784558338835E-5,1.68329229537309E-8,1,5,12.9061126708984,4.98002119430756,36.6600006818771,0.0314002423753358,0.00456420109059187,1,-3.6819731885633E-8,,,,,,,,,,,,,,,,,,,,,141.950668334961,141.950668334961,26.2620124816895,26.2620124816895,50.3376582669861,5.39674504101815,7.46872043609619,65,1,0,0,1,0.2783203125,31.2805480957031,2,1,1,141.950668334961,0,141.950668334961,,,,,,,,,,,,,,,,,,,,,,,,,,,,,,,,,
,3865938697.30175,110.989318847656,26.2620124816895,2.54822764481022E-5,1.48368765807228E-8,1,5,12.9061126708984,4.98070213865992,36.5800000727177,0.033102516715027,0.00479315968632671,1,-5.27352863987794E-8,,,,,,,,,,,,,,,,,,,,,110.989318847656,110.989318847656,26.2620124816895,26.2620124816895,50.2067354900149,5.3964950499989,7.37287712097168,63,1,64,0,0,0.277099609375,31.2805480957031,2,1,1,110.989318847656,0,110.989318847656,,,,,,,,,,,,,,,,,,,,,,,,,,,,,,,,,
,3865938883.03492,79.9820327758789,26.2620124816895,2.77957236434793E-5,1.26742727595346E-8,1,5,12.9061126708984,4.9813462389541,36.4999994635582,0.0361101306592927,0.00525793844521984,1,-3.54470353424559E-8,,,,,,,,,,,,,,,,,,,,,79.9820327758789,79.9820327758789,26.2620124816895,26.2620124816895,50.2731739141496,5.39461626958692,7.24368858337402,64,1,64,0,0,0.273284912109375,33.2355842590332,2,1,1,79.9820327758789,0,79.9820327758789,,,,,,,,,,,,,,,,,,,,,,,,,,,,,,,,,
,3865939064.43774,48.8041496276855,26.2620124816895,3.00454942107882E-5,7.30520844312015E-9,1,5,12.9061126708984,4.98239042507443,36.4300012588501,0.0390441335517487,0.00568676467217754,1,-3.71023218787614E-8,,,,,,,,,,,,,,,,,,,,,48.8041496276855,48.8041496276855,26.2620124816895,26.2620124816895,50.0609617711784,5.38902099835592,7.00191831588745,65,1,0,0,1,0.270614624023438,31.7693061828613,2,1,1,48.8041496276855,0,48.8041496276855,,,,,,,,,,,,,,,,,,,,,,,,,,,,,,,,,
,3865939246.6919,17.954122543335,26.2620124816895,3.25893275630692E-5,6.82542923897147E-9,1,5,12.9061126708984,4.98236825294157,36.3700017333031,0.0423481521377334,0.00617793011954734,1,-3.27561821334297E-8,,,,,,,,,,,,,,,,,,,,,17.954122543335,17.954122543335,26.2620124816895,26.2620124816895,50.1723438351688,5.39034662228905,6.19259166717529,65,1,0,0,1,0.271530151367187,30.3030319213867,2,1,1,17.954122543335,0,17.954122543335,,,,,,,,,,,,,,,,,,,,,,,,,,,,,,,,,
,3865939849.51438,15.0029497146606,26.2620124816895,3.31840177629615E-5,1.07897131163893E-8,1,5,12.9061126708984,4.98128804699944,36.3500006496906,0.0431119600732773,0.00626030807528126,1,-5.52501020888631E-8,,,,,,,,,,,,,,,,,,,,,15.0029497146606,15.0029497146606,26.2620124816895,26.2620124816895,50.0937901689861,5.39377047970515,5.3478479385376,65,1,0,0,1,0.273284912109375,31.2805480957031,6,1,1,15.0029497146606,0,15.0029497146606,,,,,,,,,,,,,,,,,,,,,,,,,,,,,,,,,
,3865940047.80489,46.0545921325684,26.2620124816895,3.00705620337423E-5,5.80733818291354E-9,1,5,12.9061126708984,4.98236987836616,36.3599993288517,0.0390768686117477,0.00568884965741371,1,-3.91549409740971E-8,,,,,,,,,,,,,,,,,,,,,46.0545921325684,46.0545921325684,26.2620124816895,26.2620124816895,50.2125977039092,5.39101165216779,6.40432071685791,65,1,0,0,1,0.271377563476562,31.2805480957031,2,1,1,46.0545921325684,0,46.0545921325684,,,,,,,,,,,,,,,,,,,,,,,,,,,,,,,,,
,3865940243.78104,77.0599670410156,26.2620124816895,2.76240818934753E-5,1.12484628135122E-8,1,5,12.9061126708984,4.98047479018507,36.4000014960766,0.0358774374591861,0.00523019999809997,1,-3.05961251478922E-8,,,,,,,,,,,,,,,,,,,,,77.0599670410156,77.0599670410156,26.2620124816895,26.2620124816895,50.2704382143322,5.39616425938448,6.78144407272339,65,1,0,0,1,0.277023315429687,31.7693061828613,2,1,1,77.0599670410156,0,77.0599670410156,,,,,,,,,,,,,,,,,,,,,,,,,,,,,,,,,
,3865940432.88801,108.022659301758,26.2620124816895,2.54645149821168E-5,1.32658695177358E-8,1,5,12.9061126708984,4.98012276796768,36.4699997007847,0.0330691252091353,0.00482245017480524,1,-2.69639171748297E-8,,,,,,,,,,,,,,,,,,,,,108.022659301758,108.022659301758,26.2620124816895,26.2620124816895,50.1078594823322,5.39954826657778,6.94001817703247,65,1,0,0,1,0.2777099609375,31.2805480957031,2,1,1,108.022659301758,0,108.022659301758,,,,,,,,,,,,,,,,,,,,,,,,,,,,,,,,,
,3865940621.10468,139.151184082031,26.2620124816895,2.30867863242692E-5,1.14034017102881E-8,1,5,12.9061126708984,4.97901237770452,36.5500003099442,0.0299709217767819,0.00437760194819435,1,-1.91960040814427E-8,,,,,,,,,,,,,,,,,,,,,139.134063720703,139.168304443359,26.2620124816895,26.2620124816895,50.1356072947649,5.40256074516935,7.04567432403564,63,1,64,0,0,0.271987915039062,31.2805480957031,2,1,1,139.168304443359,0,139.151184082031,,,,,,,,,,,,,,,,,,,,,,,,,,,,,,,,,
,3865940808.19215,170.109359741211,26.2620124816895,1.87706730518259E-5,8.68392931562804E-9,1,5,12.9061126708984,4.98702746160523,36.6600006818771,0.0244064603583249,0.00367948124418846,1,7.06560862264828E-8,,,,,,,,,,,,,,,,,,,,,170.109359741211,170.109359741211,26.2620124816895,26.2620124816895,50.2329200454092,5.40780542514481,7.11319351196289,65,1,0,0,1,0.2752685546875,31.2805480957031,2,1,1,170.109359741211,0,170.109359741211,,,,,,,,,,,,,,,,,,,,,,,,,,,,,,,,,
,3865940994.45042,201.020950317383,26.2620124816895,1.67664380870454E-5,3.33479637486377E-8,1,5,12.9061126708984,4.98881510844661,36.7700010538101,0.0218269285026923,0.00318281106425465,1,-1.79014677403975E-8,,,,,,,,,,,,,,,,,,,,,201.020950317383,201.020950317383,26.2620124816895,26.2620124816895,50.1434235799572,5.40520623515551,7.19325590133667,63,1,64,0,0,0.27008056640625,31.7693061828613,2,1,1,201.020950317383,0,201.020950317383,,,,,,,,,,,,,,,,,,,,,,,,,,,,,,,,,
,3865941181.21113,232.040740966797,26.2620124816895,1.52791971202167E-5,1.04517607250064E-8,1,5,12.9061126708984,4.98820895543249,36.9199998676777,0.0198883642773024,0.00289350875882155,1,-2.12937978266749E-8,,,,,,,,,,,,,,,,,,,,,232.023162841797,232.058319091797,26.2620124816895,26.2620124816895,50.1625734786784,5.40796488768471,7.31203985214233,63,1,64,0,0,0.27862548828125,30.3030319213867,2,1,1,232.058319091797,0,232.040740966797,,,,,,,,,,,,,,,,,,,,,,,,,,,,,,,,,
,3865941368.80078,263.128601074219,26.2620124816895,1.36706681921531E-5,9.35162592103132E-9,1,5,12.9061126708984,4.98861662133924,37.0800010859966,0.0177957028518846,0.00259559114364587,1,-1.41335607498071E-8,,,,,,,,,,,,,,,,,,,,,263.128601074219,263.128601074219,26.2620124816895,26.2620124816895,50.1750795349861,5.40471745584215,7.62821865081787,63,1,64,0,0,0.278244018554687,31.2805480957031,2,1,1,263.128601074219,0,263.128601074219,,,,,,,,,,,,,,,,,,,,,,,,,,,,,,,,,
,3865941555.29579,294.039215087891,26.2620124816895,1.24614721581019E-5,1.15905869980778E-8,1,5,12.9061126708984,4.98994606167196,37.2599996626377,0.0162249046815884,0.00238597040940849,1,1.76990991818471E-9,,,,,,,,,,,,,,,,,,,,,294.039215087891,294.039215087891,26.2620124816895,26.2620124816895,50.1453776512553,5.40196397948483,7.45741128921509,63,1,64,0,0,0.282516479492187,31.2805480957031,2,1,1,294.039215087891,0,294.039215087891,,,,,,,,,,,,,,,,,,,,,,,,,,,,,,,,,
,3865941835.99427,300.003555297852,42863.44140625,0.011786049252102,3.76336551193297E-6,1,2,12.9061126708984,4.98949962320166,37.2800007462502,15.3455740021505,2.24274908726893,100,-8.78502695080541E-6,,,,,,,,,,,,,,,,,,,,,300.003143310547,300.003967285156,42773.6484375,42953.234375,50.0515822289476,5.40434285472441,7.49721622467041,26,1,0,0,1,0.276336669921875,31.2805480957031,1,6,1,300.003143310547,0,300.003555297852,,,,,,,,,,,,,,,,,,,,,,,,,,,,,,,,,
,3865941902.62712,300.003082275391,36208.845703125,0.0100105522274404,2.75500729733547E-6,1,2,12.9061126708984,4.98962255933166,37.2800007462502,13.0316429351915,1.92309100021627,100,6.46604991078686E-6,,,,,,,,,,,,,,,,,,,,,300.003051757812,300.003112792969,36103.88671875,36313.8046875,50.0742494560053,5.40403296175089,7.5555534362793,26,1,0,0,1,0.277175903320313,30.7917900085449,1,6,1,300.003112792969,0,300.003082275391,,,,,,,,,,,,,,,,,,,,,,,,,,,,,,,,,
,3865941972.34128,300.002777099609,29250.2099609375,0.00809746705815998,3.09319600969049E-6,1,2,12.9061126708984,4.98978040124862,37.2800007462502,10.5407999413513,1.56159789712275,100,9.80318488552043E-6,,,,,,,,,,,,,,,,,,,,,300.002532958984,300.003021240234,29095.52734375,29404.892578125,50.0844106267553,5.40435545677227,7.64019727706909,26,1,0,0,1,0.281524658203125,31.2805480957031,1,6,1,300.002532958984,0,300.002777099609,,,,,,,,,,,,,,,,,,,,,,,,,,,,,,,,,
,3865942039.5054,300.00309753418,22546.7333984375,0.00629516611686684,3.7460515777068E-6,1,2,12.9061126708984,4.9898611284955,37.2800007462502,8.19425076597466,1.21818521963047,100,1.0796190818162E-5,,,,,,,,,,,,,,,,,,,,,300.003051757812,300.003143310547,22456.765625,22636.701171875,50.0887095836111,5.40427085709541,7.7678165435791,26,1,0,0,1,0.281906127929687,31.2805480957031,1,6,1,300.003051757812,0,300.00309753418,,,,,,,,,,,,,,,,,,,,,,,,,,,,,,,,,
,3865942103.92603,300.002593994141,16111.7001953125,0.00452359343432054,3.06704152847524E-6,1,2,12.9061126708984,4.99007020274335,37.2800007462502,5.8892968779839,0.870591106464935,100,4.0512513128542E-6,,,,,,,,,,,,,,,,,,,,,300.002593994141,300.002593994141,16016.6806640625,16206.7197265625,50.2274486457745,5.40302154206963,7.90872049331665,26,1,0,0,1,0.274581909179687,31.7693061828613,1,6,1,300.002593994141,0,300.002593994141,,,,,,,,,,,,,,,,,,,,,,,,,,,,,,,,,
,3865942170.42809,300.001480102539,9470.11279296875,0.00270395134031866,2.82561927215722E-6,1,2,12.9061126708984,4.99016341924558,37.2800007462502,3.52121654087784,0.514742922320566,100,-1.92626811534328E-6,,,,,,,,,,,,,,,,,,,,,300.001403808594,300.001556396484,9375.2119140625,9565.013671875,50.1778152348034,5.4028831924802,8.07419109344482,26,1,0,0,1,0.28076171875,31.7693061828613,1,6,1,300.001403808594,0,300.001480102539,,,,,,,,,,,,,,,,,,,,,,,,,,,,,,,,,
,3865942240.23538,300.001724243164,2489.75793457031,0.000760095102500875,3.39416282711297E-6,1,2,12.9061126708984,4.99045849591936,37.2800007462502,0.993023880382226,0.123546166178372,100,-1.67928160874819E-5,,,,,,,,,,,,,,,,,,,,,300.001617431641,300.001831054687,2329.88549804687,2649.63037109375,50.1758611635053,5.4027710553588,8.18616485595703,26,1,0,0,1,0.2783203125,31.2805480957031,1,6,1,300.001617431641,0,300.001724243164,,,,,,,,,,,,,,,,,,,,,,,,,,,,,,,,,
,3865942307.39149,300.001022338867,-4222.30493164063,-0.00124708435538491,4.82938750223891E-6,1,2,12.9061126708984,4.99005923728186,37.2800007462502,-1.62229752859332,-0.248754612247076,100,-7.8345527765451E-6,,,,,,,,,,,,,,,,,,,,,300.000579833984,300.00146484375,-4317.39990234375,-4127.2099609375,50.1973559477842,5.4036672646603,8.11986064910889,25,1,68,0,0,0.281982421875,31.7693061828613,1,6,1,300.000579833984,0,300.001022338867,,,,,,,,,,,,,,,,,,,,,,,,,,,,,,,,,
,3865942378.254,300.002182006836,-11307.2255859375,-0.00319022560773841,3.13395651817741E-6,1,2,12.9061126708984,4.99012159071877,37.2800007462502,-4.15260386665872,-0.619652132075994,10,-7.2088003922327E-6,,,,,,,,,,,,,,,,,,,,,300.002166748047,300.002197265625,-11367.2021484375,-11247.2490234375,50.1277910095726,5.40327095341927,8.06668567657471,26,1,0,0,1,0.28106689453125,30.7917900085449,1,6,1,300.002166748047,0,300.002182006836,,,,,,,,,,,,,,,,,,,,,,,,,,,,,,,,,
,3865942451.76619,300.001403808594,-18657.2666015625,-0.00524516648054599,2.41404582230236E-5,1,2,12.9061126708984,4.99006769967335,37.2800007462502,-6.82122764995865,-1.06041212905096,10,-4.38279753346383E-5,,,,,,,,,,,,,,,,,,,,,300.0009765625,300.001831054687,-18817.23828125,-18497.294921875,50.2567597152457,5.40271766544904,8.03471946716309,25,1,68,0,0,0.279541015625,32.2580642700195,1,6,1,300.0009765625,0,300.001403808594,,,,,,,,,,,,,,,,,,,,,,,,,,,,,,,,,
,3865942518.92832,299.999816894531,-25372.6953125,-0.00706574711870925,2.94635505337447E-6,1,2,12.9061126708984,4.98996366420603,37.2800007462502,-9.19423298603076,-1.389992936539,10,-2.95152346018297E-5,,,,,,,,,,,,,,,,,,,,,299.999786376953,299.999847412109,-25467.68359375,-25277.70703125,50.0937901689861,5.40305440542564,7.99981212615967,24,1,68,0,0,0.28167724609375,31.7693061828613,1,6,1,299.999847412109,0,299.999816894531,,,,,,,,,,,,,,,,,,,,,,,,,,,,,,,,,
,3865942612.64532,299.998840332031,-34764.0703125,-0.00960515557607676,4.37417582085523E-6,1,2,12.9061126708984,4.98995039126861,37.2800007462502,-12.4993228665503,-1.8843951388475,10,-3.61675240855293E-5,,,,,,,,,,,,,,,,,,,,,299.998840332031,299.998840332031,-34764.0703125,-34764.0703125,50.0750310845245,5.40312931545077,7.9777660369873,24,1,68,0,0,0.282135009765625,31.2805480957031,1,6,1,299.998840332031,0,299.998840332031,,,,,,,,,,,,,,,,,,,,,,,,,,,,,,,,,
,3865942714.41713,300.000823974609,-44957.51953125,-0.0124270255707769,3.48530886854669E-6,1,2,12.9061126708984,4.98986418660979,37.2800007462502,-16.1718118789388,-2.4328940906803,100,-4.2912308338831E-5,,,,,,,,,,,,,,,,,,,,,300.000732421875,300.000915527344,-45062.51953125,-44852.51953125,50.0222711594764,5.40283967800442,7.95645141601562,25,1,68,0,0,0.281906127929687,31.7693061828613,1,6,1,300.000732421875,0,300.000823974609,,,,,,,,,,,,,,,,,,,,,,,,,,,,,,,,,
,3865942791.27735,300.000747680664,-48359.419921875,-0.0133749916150739,5.18980597902404E-6,1,2,12.9061126708984,4.98988113193113,37.2800007462502,-17.4141596763196,-2.55970543424353,100,-1.0334929068581E-6,,,,,,,,,,,,,,,,,,,,,300.000640869141,300.000854492188,-48414.33984375,-48304.5,50.0152365028034,5.40297801620308,7.94180011749268,24,1,68,0,0,0.280990600585938,31.2805480957031,1,6,1,300.000823974609,0,300.000747680664,,,,,,,,,,,,,,,,,,,,,,,,,,,,,,,,,
,3865942856.7113,300.000427246094,-41832.119140625,-0.0115703707479046,4.41143551912799E-6,1,2,12.9061126708984,4.98991689157296,37.2800007462502,-15.0612560263145,-2.2378396456771,100,-1.89277087820848E-5,,,,,,,,,,,,,,,,,,,,,300.000427246094,300.000427246094,-41996.91796875,-41667.3203125,50.035949658563,5.40313269937828,7.93382883071899,26,1,0,0,1,0.281600952148438,31.2805480957031,1,6,1,300.000427246094,0,300.000427246094,,,,,,,,,,,,,,,,,,,,,,,,,,,,,,,,,
,3865942926.24616,300.000228881836,-34894.8046875,-0.00969715895097792,3.18719616547001E-6,1,2,12.9061126708984,4.98995623720146,37.2800007462502,-12.6219333915528,-1.8829497912886,100,-2.15387742777632E-5,,,,,,,,,,,,,,,,,,,,,300,300.000457763672,-35009.65625,-34779.953125,50.0343864015245,5.40343197465637,7.92020606994629,26,1,0,0,1,0.281448364257813,31.7693061828613,1,6,1,300,0,300.000228881836,,,,,,,,,,,,,,,,,,,,,,,,,,,,,,,,,
,3865942994.39108,300.000900268555,-28087.974609375,-0.00782183888222177,3.48961211121414E-6,1,2,12.9061126708984,4.99003781490823,37.2800007462502,-10.1810631744945,-1.51997127659107,100,-1.82394893376131E-5,,,,,,,,,,,,,,,,,,,,,300.000793457031,300.001007080078,-28182.923828125,-27993.025390625,50.1098135536303,5.40345061612678,7.91514205932617,26,1,0,0,1,0.280990600585938,31.2805480957031,1,6,1,300.001007080078,0,300.000900268555,,,,,,,,,,,,,,,,,,,,,,,,,,,,,,,,,
,3865943062.95851,299.997741699219,-21244.4580078125,-0.00594499221157702,3.25331905166564E-6,1,2,12.9061126708984,4.99006067912048,37.2800007462502,-7.737778313455,-1.15793843062618,100,-1.59182214925254E-5,,,,,,,,,,,,,,,,,,,,,299.997497558594,299.997985839844,-21344.259765625,-21144.65625,50.1469409082938,5.40250496684813,7.90676021575928,26,1,0,0,1,0.281143188476562,31.7693061828613,1,6,1,299.997985839844,0,299.997741699219,,,,,,,,,,,,,,,,,,,,,,,,,,,,,,,,,
,3865943129.50626,300.00016784668,-14601.7788085938,-0.00411880428768492,3.31638693554872E-6,1,2,12.9061126708984,4.99022819368962,37.2800007462502,-5.36142885406784,-0.800268066387745,100,-9.48359133141813E-6,,,,,,,,,,,,,,,,,,,,,299.999847412109,300.00048828125,-14716.580078125,-14486.9775390625,50.1950110622265,5.40196665154072,7.90262794494629,26,1,0,0,1,0.28076171875,31.7693061828613,1,6,1,300.00048828125,0,300.00016784668,,,,,,,,,,,,,,,,,,,,,,,,,,,,,,,,,
,3865943196.02888,300.000854492188,-7954.2685546875,-0.00229267029882257,3.28838801925666E-6,1,2,12.9061126708984,4.98997594287633,37.2800007462502,-2.9851636787284,-0.438504018042155,100,3.70032260341786E-8,,,,,,,,,,,,,,,,,,,,,300.000610351562,300.001098632812,-8024.20458984375,-7884.33251953125,50.1809417488803,5.40332395457707,7.90317249298096,24,1,68,0,0,0.282363891601562,32.2580642700195,1,6,1,300.001098632812,0,300.000854492188,,,,,,,,,,,,,,,,,,,,,,,,,,,,,,,,,
,3865943266.42972,299.999603271484,-924.335052490234,-0.00032683239061373,3.89725830755942E-6,1,2,12.9061126708984,4.98999251259591,37.2800007462502,-0.429803464843266,-0.0335791397060969,100,2.22258107684387E-5,,,,,,,,,,,,,,,,,,,,,299.999603271484,299.999603271484,-1029.11987304688,-819.550231933594,50.2122068896495,5.40300967096144,7.89401054382324,25,1,68,0,0,0.2813720703125,31.7693061828613,1,6,1,299.999603271484,0,299.999603271484,,,,,,,,,,,,,,,,,,,,,,,,,,,,,,,,,
,3865943332.93292,299.999710083008,5728.57861328125,0.00166348285289185,3.25930747386827E-6,1,2,12.9061126708984,4.99013018709907,37.2800007462502,2.16412371316154,0.331127383297377,100,9.91871772829983E-6,,,,,,,,,,,,,,,,,,,,,299.999572753906,299.999847412109,5648.65185546875,5808.50537109375,50.1817233773995,5.4028027620694,7.89560461044312,26,1,0,0,1,0.280685424804687,32.7468223571777,1,6,1,299.999847412109,0,299.999710083008,,,,,,,,,,,,,,,,,,,,,,,,,,,,,,,,,
,3865943405.55061,300.001220703125,12989.6293945313,0.00365712484961986,3.29299620550531E-6,1,2,12.9061126708984,4.98996200152158,37.2800007462502,4.75937657732133,0.715480614695,10,1.22363582465154E-5,,,,,,,,,,,,,,,,,,,,,300.001129150391,300.001312255859,12879.642578125,13099.6162109375,50.1445960227361,5.40302699460221,7.88906717300415,24,1,68,0,0,0.280609130859375,31.7693061828613,1,6,1,300.001312255859,0,300.001220703125,,,,,,,,,,,,,,,,,,,,,,,,,,,,,,,,,
,3865943472.17797,299.998733520508,19655.775390625,0.00548430991105864,3.37279788227313E-6,1,2,12.9061126708984,4.99004311389775,37.2800007462502,7.137503913204,1.07250807154894,10,1.79906093099582E-5,,,,,,,,,,,,,,,,,,,,,299.998657226562,299.998809814453,19540.62890625,19770.921875,50.1946202479669,5.40327987631607,7.88688659667969,25,1,68,0,0,0.281753540039062,31.2805480957031,1,6,1,299.998809814453,0,299.998733520508,,,,,,,,,,,,,,,,,,,,,,,,,,,,,,,,,
,3865943540.315,299.999954223633,26468.46875,0.0073532929886517,3.90743881670615E-6,1,2,12.9061126708984,4.98995586385487,37.2800007462502,9.56945425813089,1.43923194963249,10,2.50908697659387E-5,,,,,,,,,,,,,,,,,,,,,299.999847412109,300.000061035156,26373.3046875,26563.6328125,50.1801601203611,5.40303778480641,7.87829542160034,24,1,68,0,0,0.280380249023438,31.7693061828613,1,6,1,299.999847412109,0,299.999954223633,,,,,,,,,,,,,,,,,,,,,,,,,,,,,,,,,
,3865943619.03847,300.000350952148,34359.44921875,0.00950912964834924,4.02884808098293E-6,1,2,12.9061126708984,4.99001905387104,37.2800007462502,12.374864150942,1.8638074194799,10,3.44351780433067E-5,,,,,,,,,,,,,,,,,,,,,300.000183105469,300.000518798828,34279.1328125,34439.765625,50.0382945441207,5.40274299359397,7.8777027130127,24,1,68,0,0,0.282135009765625,31.7693061828613,1,6,1,300.000183105469,0,300.000350952148,,,,,,,,,,,,,,,,,,,,,,,,,,,,,,,,,
,3865943715.58901,300.000564575195,44034.26171875,0.0121553044443176,3.86597493688198E-6,1,2,12.9061126708984,4.98985671513825,37.2800007462502,15.818884440312,2.37487413770588,100,3.82728649721623E-5,,,,,,,,,,,,,,,,,,,,,300.000305175781,300.000823974609,43939.0546875,44129.46875,50.0269609305918,5.40390957719124,7.87158918380737,26,1,0,0,1,0.281829833984375,31.7693061828613,1,6,1,300.000823974609,0,300.000564575195,,,,,,,,,,,,,,,,,,,,,,,,,,,,,,,,,
,3865943776.92432,300.000579833984,50000.23828125,0.0137801052380224,9.71197947015034E-7,1,2,12.9061126708984,4.98995207171886,37.2800007462502,17.9333249335057,2.69615586243538,100,4.62764755182885E-5,,,,,,,,,,,,,,,,,,,,,300.000579833984,300.000579833984,50000.23828125,50000.23828125,50.0027304464957,5.40304259053205,7.86333227157593,26,1,0,0,1,0.281524658203125,31.7693061828613,1,4,1,300.000579833984,0,300.000579833984,,,,,,,,,,,,,,,,,,,,,,,,,,,,,,,,,