File: LT data/Bridport/K1/178-FC-ZFC-RTSIRM-contsweepwithloop.dat
[Header]
; MPMS3 Data File (default extension .dat)
; Copyright (c) 2007, Quantum Design, Inc. All rights reserved.
TITLE,
FILEOPENTIME,3865665655.29197,06/29/2022,12:58 pm
BYAPP,MPMS3 w/ AC,1.0,1.1
INFO,MPMS3 Measurement Release 1.1.16 Build 424, MultiVu Release 2.3.4.19,APPNAME
INFO,Linear Motor Servo Controller,MOTOR_MODULE_NAME
INFO,3101-100 N2,MOTOR_HW_VERSION
INFO,,MOTOR_SERIAL_NUMBER
INFO,01.04.28,MOTOR_SOFTWARE_VERSION
INFO,Quantum Design Squid Module,SQUID_MODULE_NAME
INFO,3101-501 B0,SQUID_HW_VERSION
INFO,SQM327,SQUID_SERIAL_NUMBER
INFO,01.03.04,SQUID_SOFTWARE_VERSION
INFO,Quantum Design VSM Oven,OVEN_MODULE_NAME
INFO,3101-201 A3,OVEN_HW_VERSION
INFO,OVB365,OVEN_SERIAL_NUMBER
INFO,01.07.07,OVEN_SOFTWARE_VERSION
INFO,SQUID AC,AC_MODULE_NAME
INFO,3101-401 G0,AC_HW_VERSION
INFO,SAC220,AC_SERIAL_NUMBER
INFO,SQUID AC 00.95.07,AC_SOFTWARE_VERSION
INFO,TCI344,COIL_SERIAL_NUMBER
INFO,0,MOMENT_UNITS
INFO,Sndst,SAMPLE_MATERIAL
INFO,,SAMPLE_COMMENT
INFO,253.08,SAMPLE_MASS
INFO,,SAMPLE_VOLUME
INFO,,SAMPLE_MOLECULAR_WEIGHT
INFO,,SAMPLE_SIZE
INFO,,SAMPLE_SHAPE
INFO,Straw,SAMPLE_HOLDER
INFO,Standard,SAMPLE_HOLDER_DETAIL
INFO,67.27,SAMPLE_OFFSET
DATATYPE,COMMENT,1
DATATYPE,TIME,2
STARTUPAXIS,X,2
STARTUPAXIS,Y1,5
FIELDGROUP, VSM,2,3,4,5,6,8,9,10,11,14,15
FIELDGROUP, DC, 2,3,4,14,56,57,58,59,60,61,62,63,64,65,66,67,68,69
FIELDGROUP, AC, 2,3,4,11,16,17,18,19,20,21,22,23,24,25,26,27,28,29,30
STARTUPGROUP, All
[Data]
Comment,Time Stamp (sec),Temperature (K),Magnetic Field (Oe),Moment (emu),M. Std. Err. (emu),Transport Action,Averaging Time (sec),Frequency (Hz),Peak Amplitude (mm),Center Position (mm),Lockin Signal' (V),Lockin Signal (V),Range,M. Quad. Signal (emu),AC Moment (emu),AC M. Std Err. (emu),AC Phase (deg),AC Phase Std. Err. (deg),AC Susceptibility (emu/Oe),AC Suscept. Std Err. (emu/Oe),AC X' (emu/Oe),AC X' Std Err. (emu/Oe),AC X'' (emu/Oe),AC X'' Std Err. (emu/Oe),AC Drive (Oe),AC Frequency (Hz),AC Averaging Time (sec),AC Cycles,AC Range,AC Measure Type,AC Signal' (V),AC Signal'' (V),AC Trim Coil Ratio,AC Trim Coil Phase,Min. Temperature (K),Max. Temperature (K),Min. Field (Oe),Max. Field (Oe),Mass (grams),Motor Lag (deg),Pressure (Torr),Measure Count,Measurement Number,SQUID Status (code),Motor Status (code),Measure Status (code),Motor Current (amps),Motor Temp. (C),Temp. Status (code),Field Status (code),Chamber Status (code),Chamber Temp (K),Redirection State,Average Temp (K),Rotation Angle (deg),Rotator state,DC Moment Fixed Ctr (emu),DC Moment Err Fixed Ctr (emu),DC Moment Free Ctr (emu),DC Moment Err Free Ctr (emu),DC Fixed Fit,DC Free Fit,DC Calculated Center (mm),DC Calculated Center Err (mm),DC Scan Length (mm),DC Scan Time (s),DC Number of Points,DC Squid Drift,DC Min V (V),DC Max V (V),DC Scans per Measure,Map 01,Map 02,Map 03,Map 04,Map 05,Map 06,Map 07,Map 08,Map 09,Map 10,Map 11,Map 12,Map 13,Map 14,Map 15,Map 16
,3865667763.98752,1.99989020824432,26.4625797271729,0.00972306623265237,7.13335579953172E-7,1,5,12.9061126708984,4.99635194708944,40.8900007605553,12.6821169344549,1.86614440588206,10,2.25325909883177E-6,,,,,,,,,,,,,,,,,,,,,1.99989020824432,1.99989020824432,26.4625797271729,26.4625797271729,50.2305751598515,5.40071218876708,2.59774327278137,65,1,0,0,1,0.290069580078125,31.2805480957031,1,1,1,1.99989020824432,0,1.99989020824432,,,,,,,,,,,,,,,,,,,,,,,,,,,,,,,,,
,3865667937.99574,28.0063533782959,26.4625797271729,0.000290480619237652,1.63411691810329E-7,1,5,12.9061126708984,4.99567295004093,40.8999994397163,0.378824554773914,0.0556510505074794,1,-1.82053074472922E-9,,,,,,,,,,,,,,,,,,,,,28.0063533782959,28.0063533782959,26.4625797271729,26.4625797271729,50.188367219813,5.40276646423882,6.00653696060181,65,1,0,0,1,0.268936157226562,30.7917900085449,2,1,1,28.0063533782959,0,28.0063533782959,,,,,,,,,,,,,,,,,,,,,,,,,,,,,,,,,
,3865668110.52464,55.0034675598145,26.4625797271729,0.000213930415598662,4.27262664696064E-8,1,5,12.9061126708984,4.99644231305627,40.9200005233288,0.279076368066743,0.0408375207867187,1,-1.21460715796015E-7,,,,,,,,,,,,,,,,,,,,,55.0034675598145,55.0034675598145,26.4625797271729,26.4625797271729,50.2110344468707,5.40080920189168,6.56956052780151,65,1,0,0,1,0.289077758789063,31.2805480957031,2,1,1,55.0034675598145,0,55.0034675598145,,,,,,,,,,,,,,,,,,,,,,,,,,,,,,,,,
,3865668280.02678,82.0010986328125,26.4625797271729,0.000178813441708254,3.66478540718865E-8,1,5,12.9061126708984,4.99540859067394,40.9700013697147,0.233195697798629,0.0341394127692548,1,-8.97697392658406E-8,,,,,,,,,,,,,,,,,,,,,82.0010986328125,82.0010986328125,26.4625797271729,26.4625797271729,50.1864131485149,5.40381546666311,6.8085150718689,65,1,0,0,1,0.279922485351562,31.7693061828613,2,1,1,82.0010986328125,0,82.0010986328125,,,,,,,,,,,,,,,,,,,,,,,,,,,,,,,,,
,3865668444.62593,109.002616882324,26.4625797271729,0.000137052053372319,5.53194567162621E-8,1,5,12.9061126708984,4.99479600145197,41.0199984908104,0.178701255276073,0.0261719568043681,1,-6.09743939928744E-8,,,,,,,,,,,,,,,,,,,,,109.002616882324,109.002616882324,26.4625797271729,26.4625797271729,50.2282302742938,5.40683586499493,6.93219041824341,63,1,64,0,0,0.27130126953125,32.7468223571777,2,1,1,109.002616882324,0,109.002616882324,,,,,,,,,,,,,,,,,,,,,,,,,,,,,,,,,
,3865668607.77191,136.093933105469,26.4625797271729,0.000100345681230803,2.304507582027E-8,1,5,12.9061126708984,4.99414154590476,41.0900004208088,0.130819838997264,0.0191328940608209,1,-6.45586898854087E-8,,,,,,,,,,,,,,,,,,,,,136.093933105469,136.093933105469,26.4625797271729,26.4625797271729,50.2251037602168,5.40901917925179,7.02144765853882,65,1,0,0,1,0.27191162109375,32.2580642700195,2,1,1,136.093933105469,0,136.093933105469,,,,,,,,,,,,,,,,,,,,,,,,,,,,,,,,,
,3865668770.68458,163.052505493164,26.4625797271729,8.67118090971634E-5,3.31469764420648E-8,1,5,12.9061126708984,4.99403142438541,41.1700010299683,0.113047776465722,0.0164933370841677,1,-8.60724139627577E-8,,,,,,,,,,,,,,,,,,,,,163.052505493164,163.052505493164,26.4625797271729,26.4625797271729,50.2000916476015,5.40966256402435,7.08861303329468,64,1,64,0,0,0.272674560546875,31.7693061828613,2,1,1,163.052505493164,0,163.052505493164,,,,,,,,,,,,,,,,,,,,,,,,,,,,,,,,,
,3865668934.36726,190.03337097168,26.4625797271729,7.41950327035859E-5,4.62533954721138E-8,1,5,12.9061126708984,4.99434701267461,41.2800014019012,0.0967199612132669,0.0142365535294764,1,2.05228755668347E-8,,,,,,,,,,,,,,,,,,,,,190.03337097168,190.03337097168,26.4625797271729,26.4625797271729,50.2098620040919,5.40861157027088,7.15668249130249,64,1,64,0,0,0.272064208984375,31.7693061828613,2,1,1,190.03337097168,0,190.03337097168,,,,,,,,,,,,,,,,,,,,,,,,,,,,,,,,,
,3865669096.56652,217.019760131836,26.4625797271729,6.42645387119917E-5,1.23768534550487E-8,1,5,12.9061126708984,4.99446082620273,41.3900017738342,0.0837912570296843,0.0122367354222668,1,-5.49006371768285E-8,,,,,,,,,,,,,,,,,,,,,217.019760131836,217.019760131836,26.4625797271729,26.4625797271729,50.1911029196303,5.40870567818437,7.24761247634888,64,1,64,0,0,0.271682739257813,31.7693061828613,2,1,1,217.019760131836,0,217.019760131836,,,,,,,,,,,,,,,,,,,,,,,,,,,,,,,,,
,3865669259.26312,244.010406494141,26.4625797271729,5.72141280969667E-5,1.97331550605039E-8,1,5,12.9061126708984,4.99420123164004,41.5299981832504,0.0745947514420188,0.0108825530198144,1,-5.7243718203067E-8,,,,,,,,,,,,,,,,,,,,,244.010406494141,244.010406494141,26.4625797271729,26.4625797271729,50.1711713923899,5.40963503228496,7.41631937026978,63,1,64,0,0,0.271987915039062,31.7693061828613,2,1,1,244.010406494141,0,244.010406494141,,,,,,,,,,,,,,,,,,,,,,,,,,,,,,,,,
,3865669421.17572,271.011932373047,26.4625797271729,5.1019605260654E-5,1.05018681014821E-8,1,5,12.9061126708984,4.99405950677278,41.6699983179569,0.0665098159608095,0.00974463480217934,1,-1.98138594201946E-8,,,,,,,,,,,,,,,,,,,,,271.011932373047,271.011932373047,26.4625797271729,26.4625797271729,50.2325292311495,5.41016336410991,7.62112951278686,63,1,64,0,0,0.273666381835938,31.7693061828613,2,1,1,271.011932373047,0,271.011932373047,,,,,,,,,,,,,,,,,,,,,,,,,,,,,,,,,
,3865669588.14513,298.088043212891,26.4625797271729,4.53485937828744E-5,1.64529459121669E-8,1,5,12.9061126708984,4.99390267512787,41.8299995362759,0.0591097896648316,0.00869254490389012,1,6.51047239410708E-9,,,,,,,,,,,,,,,,,,,,,298.088043212891,298.088043212891,26.4625797271729,26.4625797271729,50.1442052084765,5.41124050098606,7.50371646881103,65,1,0,0,1,0.273361206054687,31.7693061828613,6,1,1,298.088043212891,0,298.088043212891,,,,,,,,,,,,,,,,,,,,,,,,,,,,,,,,,
,3865671177.54513,1.99998474121094,42164.857421875,0.469325437679805,8.12520677824933E-5,1,2,12.9061126708984,4.99609110487522,40.8999994397163,612.113128523746,90.0624938355412,1000,0.000102347752798912,,,,,,,,,,,,,,,,,,,,,1.99990820884705,2.00006127357483,42064.9609375,42264.75390625,50.8336015624381,5.40642638030165,2.595707654953,26,1,0,0,1,0.290069580078125,31.7693061828613,1,6,1,1.99990820884705,0,1.99998474121094,,,,,,,,,,,,,,,,,,,,,,,,,,,,,,,,,
,3865671238.34524,2.00004857778549,36094.44140625,0.438254099785502,9.23070756919001E-5,1,2,12.9061126708984,4.99596353035363,40.8999994397163,571.558936730425,84.1598832413173,1000,0.000143814169057417,,,,,,,,,,,,,,,,,,,,,1.99987161159515,2.00022554397583,36044.4921875,36144.390625,50.8019456074092,5.4064058936587,2.60486936569214,26,1,0,0,1,0.289230346679687,31.2805480957031,1,6,1,1.99987161159515,0,2.00004857778549,,,,,,,,,,,,,,,,,,,,,,,,,,,,,,,,,
,3865671300.36863,2.0000097155571,29899.6142578125,0.399178924011917,9.7882671327748E-5,1,2,12.9061126708984,4.99591650541669,40.8999994397163,520.569032464703,76.8066570536127,1000,0.000247202896759219,,,,,,,,,,,,,,,,,,,,,1.99986207485199,2.00015735626221,29804.6875,29994.541015625,50.5838712505438,5.40564087265779,2.59654998779297,26,1,0,0,1,0.280075073242187,32.2580642700195,1,6,1,1.99986207485199,0,2.0000097155571,,,,,,,,,,,,,,,,,,,,,,,,,,,,,,,,,
,3865671360.89148,1.99994701147079,23859.876953125,0.353526499292375,9.91123624377941E-5,1,2,12.9061126708984,4.99587598348964,40.8999994397163,461.046466464166,67.8994422584138,1000,0.00012509233396263,,,,,,,,,,,,,,,,,,,,,1.99994349479675,1.99995052814484,23774.955078125,23944.798828125,50.4842136143419,5.4056058855892,2.60298252105713,26,1,0,0,1,0.290145874023438,31.2805480957031,1,6,1,1.99994349479675,0,1.99994701147079,,,,,,,,,,,,,,,,,,,,,,,,,,,,,,,,,
,3865671418.57245,1.9998254776001,18098.7763671875,0.300119540033573,0.000118910218608434,1,2,12.9061126708984,4.99602534535126,40.8999994397163,391.448459000797,57.4026836502,1000,-7.90914860757318E-5,,,,,,,,,,,,,,,,,,,,,1.99974572658539,1.99990522861481,17944.099609375,18253.453125,50.3525092088515,5.4043194655533,2.5987811088562,26,1,0,0,1,0.290145874023438,31.7693061828613,1,6,1,1.99990522861481,0,1.9998254776001,,,,,,,,,,,,,,,,,,,,,,,,,,,,,,,,,
,3865671479.946,1.99997711181641,11973.685546875,0.232145261545747,0.000138943749404019,1,2,12.9061126708984,4.99608730749331,40.8999994397163,302.787544989006,44.448232038987,1000,-2.59483871782076E-5,,,,,,,,,,,,,,,,,,,,,1.9999623298645,1.99999189376831,11903.875,12043.49609375,50.3157726684476,5.40358589041968,2.59400105476379,26,1,0,0,1,0.27923583984375,31.7693061828613,1,6,1,1.99999189376831,0,1.99997711181641,,,,,,,,,,,,,,,,,,,,,,,,,,,,,,,,,
,3865671538.11611,2.00007712841034,6158.06591796875,0.147188475277098,0.000181538768459635,1,2,12.9061126708984,4.99610157752502,40.8999994397163,191.978520171748,28.1851724567097,1000,-1.39404003376253E-5,,,,,,,,,,,,,,,,,,,,,2.00006198883057,2.00009226799011,6068.20458984375,6247.92724609375,50.2352649309669,5.40351582565437,2.59289646148682,26,1,0,0,1,0.290069580078125,31.7693061828613,1,6,1,2.00009226799011,0,2.00007712841034,,,,,,,,,,,,,,,,,,,,,,,,,,,,,,,,,
,3865671600.58551,2.00002616643906,-83.5620916485786,0.00939861979946225,0.000330013889315231,1,2,12.9061126708984,4.99609585687489,40.8999994397163,12.2601098643167,1.7897228178066,100,-8.57197721550425E-6,,,,,,,,,,,,,,,,,,,,,1.99989020824432,2.00016212463379,-168.553237915039,1.42905461788177,50.1797693061015,5.40299643623837,2.59139370918274,26,1,0,0,1,0.289993286132812,31.7693061828613,1,6,1,2.00016212463379,0,2.00002616643906,,,,,,,,,,,,,,,,,,,,,,,,,,,,,,,,,
,3865671659.24922,1.99941188097,-5946.03295898438,-0.131861001646378,0.000205066107248224,1,2,12.9061126708984,4.99584247214207,40.8999994397163,-171.954342594122,-25.384338720788,100,-9.18403982272892E-5,,,,,,,,,,,,,,,,,,,,,1.99924898147583,1.99957478046417,-6066.0986328125,-5825.96728515625,50.2763004282265,5.40409834315491,2.58102297782898,25,1,68,0,0,0.279541015625,31.7693061828613,1,6,1,1.99957478046417,0,1.99941188097,,,,,,,,,,,,,,,,,,,,,,,,,,,,,,,,,
,3865671731.70175,2.00010579824448,-13191.5590820312,-0.24278562634287,0.000137162114362272,1,2,12.9061126708984,4.99610853467812,40.8999994397163,-316.6765829101,-46.4251951843969,1000,7.35966830364817E-5,,,,,,,,,,,,,,,,,,,,,1.99983704090118,2.00037455558777,-13306.529296875,-13076.5888671875,50.2841167134188,5.40360440308654,2.55585622787476,26,1,0,0,1,0.289840698242188,31.2805480957031,1,6,1,2.00037455558777,0,2.00010579824448,,,,,,,,,,,,,,,,,,,,,,,,,,,,,,,,,
,3865671788.10809,2.00019919872284,-18836.9013671875,-0.305973958095206,0.000114186818039838,1,2,12.9061126708984,4.9961562851101,40.8999994397163,-399.085871537465,-58.6145426696967,1000,1.16646359164473E-5,,,,,,,,,,,,,,,,,,,,,2.00006628036499,2.00033211708069,-18907.0078125,-18766.794921875,50.3880733064765,5.40387702130877,2.54238247871399,26,1,0,0,1,0.289535522460937,31.7693061828613,1,6,1,2.00006628036499,0,2.00019919872284,,,,,,,,,,,,,,,,,,,,,,,,,,,,,,,,,
,3865671846.30208,1.99969267845154,-24652.3076171875,-0.358971806446429,9.72044285165969E-5,1,2,12.9061126708984,4.99629557032739,40.8999994397163,-468.202641154411,-68.9558332904965,1000,-0.000128882910006154,,,,,,,,,,,,,,,,,,,,,1.99958527088165,1.99980008602142,-24747.27734375,-24557.337890625,50.5315021397553,5.40386564374349,2.52647829055786,26,1,0,0,1,0.289306640625,31.7693061828613,1,6,1,1.99980008602142,0,1.99969267845154,,,,,,,,,,,,,,,,,,,,,,,,,,,,,,,,,
,3865671908.09286,2.00019454956055,-30846.4833984375,-0.405484416309166,9.85289497815E-5,1,2,12.9061126708984,4.99628886810407,40.8999994397163,-528.87289280017,-77.8536292555229,1000,-0.000117379671382012,,,,,,,,,,,,,,,,,,,,,2.0000901222229,2.00029897689819,-31006.8125,-30686.154296875,50.5451806388419,5.40479498879472,2.52611255645752,26,1,0,0,1,0.279617309570313,31.7693061828613,1,6,1,2.00029897689819,0,2.00019454956055,,,,,,,,,,,,,,,,,,,,,,,,,,,,,,,,,
,3865671969.34335,1.99992352724075,-36977.953125,-0.442368980449663,8.44539885667843E-5,1,2,12.9061126708984,4.99638521282106,40.8999994397163,-576.97282096094,-85.1023008902031,1000,-0.000254156720427112,,,,,,,,,,,,,,,,,,,,,1.9998984336853,1.9999486207962,-37058.03125,-36897.875,50.7968650220342,5.40532621839055,2.51064229011536,26,1,0,0,1,0.288543701171875,31.7693061828613,1,6,1,1.9998984336853,0,1.99992352724075,,,,,,,,,,,,,,,,,,,,,,,,,,,,,,,,,
,3865672029.66289,1.9925822019577,-43024.052734375,-0.472982591803792,6.74367692405558E-5,1,2,12.9061126708984,4.99641268335201,40.8999994397163,-616.914606825708,-90.9357424766853,1000,-0.000228306473963137,,,,,,,,,,,,,,,,,,,,,1.99253642559052,1.99262797832489,-43119.140625,-42928.96484375,50.8613493748708,5.40557893159183,2.50198483467102,26,1,0,0,1,0.279312133789062,31.2805480957031,1,6,1,1.99262797832489,0,1.9925822019577,,,,,,,,,,,,,,,,,,,,,,,,,,,,,,,,,
,3865672089.37975,1.99958389997482,-49004.2265625,-0.498564075228142,5.96159048896857E-5,1,2,12.9061126708984,4.99629603748427,40.8999994397163,-650.241744030213,-95.9713723727081,1000,-0.000333010026489968,,,,,,,,,,,,,,,,,,,,,1.99937772750854,1.9997900724411,-49169.6328125,-48838.8203125,50.9957894801785,5.40670860096791,2.47839856147766,26,1,0,0,1,0.27923583984375,32.2580642700195,1,6,1,1.99937772750854,0,1.99958389997482,,,,,,,,,,,,,,,,,,,,,,,,,,,,,,,,,
,3865672148.56383,1.99959713220596,-45724.8515625,-0.485249084835125,7.77042062792902E-5,1,2,12.9061126708984,4.99637419606783,40.8999994397163,-632.937996069003,-93.0824410196834,1000,-7.27315145315978E-5,,,,,,,,,,,,,,,,,,,,,1.99952614307404,1.99966812133789,-45829.59375,-45620.109375,50.8804992735919,5.40602268064083,2.46625399589539,26,1,0,0,1,0.289459228515625,29.8142719268799,1,6,1,1.99966812133789,0,1.99959713220596,,,,,,,,,,,,,,,,,,,,,,,,,,,,,,,,,
,3865672205.05307,2.00143182277679,-40085.6328125,-0.459359775750913,8.40699938517891E-5,1,2,12.9061126708984,4.99642225869035,40.8999994397163,-599.149028508637,-88.3090290119152,1000,-0.000215731947475172,,,,,,,,,,,,,,,,,,,,,2.00093817710876,2.00192546844482,-40160.49609375,-40010.76953125,50.8734646169188,5.40505602351531,2.45607614517212,26,1,0,0,1,0.289154052734375,31.2805480957031,5,6,1,2.00192546844482,0,2.00143182277679,,,,,,,,,,,,,,,,,,,,,,,,,,,,,,,,,
,3865672265.36567,2.00014877319336,-34067.0703125,-0.426229454620032,7.03414369794693E-5,1,2,12.9061126708984,4.99643240707524,40.8999994397163,-555.974056508597,-81.6967455319367,1000,-1.35585979366001E-5,,,,,,,,,,,,,,,,,,,,,1.99998617172241,2.00031137466431,-34161.7265625,-33972.4140625,50.60810173464,5.40460252518864,2.45317792892456,26,1,0,0,1,0.29022216796875,32.2580642700195,1,6,1,2.00031137466431,0,2.00014877319336,,,,,,,,,,,,,,,,,,,,,,,,,,,,,,,,,
,3865672325.77219,1.99985390901566,-28038.7021484375,-0.386092738747683,9.50867508212873E-5,1,2,12.9061126708984,4.99622802978512,40.8999994397163,-503.561366917522,-74.1998322324185,1000,-0.00016597015473595,,,,,,,,,,,,,,,,,,,,,1.99958407878876,2.00012373924255,-28133.634765625,-27943.76953125,50.5498704099573,5.4046196627485,2.46360945701599,26,1,0,0,1,0.279312133789062,30.7917900085449,1,6,1,1.99958407878876,0,1.99985390901566,,,,,,,,,,,,,,,,,,,,,,,,,,,,,,,,,
,3865672386.47157,1.99836266040802,-21978.833984375,-0.337593083238937,0.000106519142441143,1,2,12.9061126708984,4.99578393936226,40.8999994397163,-440.283351732255,-64.6497462792483,1000,2.45437350452741E-5,,,,,,,,,,,,,,,,,,,,,1.99647235870361,2.00025296211243,-22043.71875,-21913.94921875,50.4568566161688,5.4050153516681,2.46858477592468,26,1,0,0,1,0.2899169921875,31.2805480957031,1,6,1,1.99647235870361,0,1.99836266040802,,,,,,,,,,,,,,,,,,,,,,,,,,,,,,,,,
,3865672442.61175,1.99999874830246,-16374.0322265625,-0.2828310637883,0.000119405488383106,1,2,12.9061126708984,4.99560288246372,40.8999994397163,-368.831771900563,-54.2492254523693,1000,-4.78879777578581E-5,,,,,,,,,,,,,,,,,,,,,1.99995911121368,2.00003838539124,-16463.8359375,-16284.228515625,50.3583714227457,5.40495638773767,2.47830820083618,26,1,0,0,1,0.279998779296875,31.7693061828613,1,6,1,1.99995911121368,0,1.99999874830246,,,,,,,,,,,,,,,,,,,,,,,,,,,,,,,,,
,3865672501.17369,2.00015914440155,-10527.1372070312,-0.213002577757488,0.000150031539909896,1,2,12.9061126708984,4.99578777502549,40.8999994397163,-277.780446619396,-40.8878950047008,1000,-5.9223939204636E-5,,,,,,,,,,,,,,,,,,,,,2.00004720687866,2.00027108192444,-10632.2041015625,-10422.0703125,50.2962319554669,5.40426102716495,2.4690203666687,26,1,0,0,1,0.279693603515625,31.2805480957031,1,6,1,2.00027108192444,0,2.00015914440155,,,,,,,,,,,,,,,,,,,,,,,,,,,,,,,,,
,3865672561.48043,1.99997025728226,-4497.64208984375,-0.117485328242512,0.000203431897399811,1,2,12.9061126708984,4.99555640913083,40.8999994397163,-153.214072102281,-22.4875720470369,1000,1.59530252717607E-5,,,,,,,,,,,,,,,,,,,,,1.99989950656891,2.00004100799561,-4587.5283203125,-4407.755859375,50.2927146271303,5.40478055848427,2.47675442695618,26,1,0,0,1,0.280227661132813,31.7693061828613,1,6,1,2.00004100799561,0,1.99997025728226,,,,,,,,,,,,,,,,,,,,,,,,,,,,,,,,,
,3865672623.93122,2.00003385543823,1743.81011962891,0.0389683105729625,0.00028705717806468,1,2,12.9061126708984,4.99553757141881,40.8999994397163,50.8150937515313,7.48393308203117,100,1.39910928694689E-5,,,,,,,,,,,,,,,,,,,,,1.99998307228088,2.00008463859558,1648.89074707031,1838.7294921875,50.2219772461399,5.40493558976611,2.47383785247803,26,1,0,0,1,0.290298461914063,31.7693061828613,1,6,1,1.99998307228088,0,2.00003385543823,,,,,,,,,,,,,,,,,,,,,,,,,,,,,,,,,
,3865672696.45024,1.99985063076019,8993.35400390625,0.184527020606605,0.000170781804505623,1,2,12.9061126708984,4.99550084386239,40.8999994397163,240.644855483055,35.2877601301563,1000,-4.924493402086E-5,,,,,,,,,,,,,,,,,,,,,1.99964284896851,2.00005841255188,8898.3974609375,9088.310546875,50.2708290285919,5.40501218360304,2.46914291381836,26,1,0,0,1,0.279388427734375,31.7693061828613,1,6,1,1.99964284896851,0,1.99985063076019,,,,,,,,,,,,,,,,,,,,,,,,,,,,,,,,,
,3865672752.97019,2.00019240379334,14649.0317382812,0.260613662344085,0.000131280556855229,1,2,12.9061126708984,4.99546377913903,40.8999994397163,339.860952786861,49.8801950184937,1000,-3.68572041438456E-5,,,,,,,,,,,,,,,,,,,,,1.99990725517273,2.00047755241394,14548.9794921875,14749.083984375,50.3564173514476,5.40574459277731,2.46358919143677,26,1,0,0,1,0.2801513671875,31.7693061828613,1,6,1,1.99990725517273,0,2.00019240379334,,,,,,,,,,,,,,,,,,,,,,,,,,,,,,,,,
,3865672813.29551,2.00018131732941,20685.4140625,0.323966034542216,0.000105878570512749,1,2,12.9061126708984,4.99560788706741,40.8999994397163,422.475302597283,62.1392062180312,1000,5.47624429386396E-5,,,,,,,,,,,,,,,,,,,,,2.00010132789612,2.0002613067627,20590.21875,20780.609375,50.4298904322553,5.40579522134072,2.45601797103882,26,1,0,0,1,0.279617309570313,32.7468223571777,1,6,1,2.00010132789612,0,2.00018131732941,,,,,,,,,,,,,,,,,,,,,,,,,,,,,,,,,
,3865672875.00772,1.99976003170013,26858.2666015625,0.376859257444872,9.48078286564939E-5,1,2,12.9061126708984,4.99568841780175,40.8999994397163,491.447145391597,72.3942484753029,1000,0.000146576011136225,,,,,,,,,,,,,,,,,,,,,1.99954092502594,1.99997913837433,26692.97265625,27023.560546875,50.5514336669957,5.40644151926392,2.43990564346313,26,1,0,0,1,0.279922485351562,31.2805480957031,1,6,1,1.99997913837433,0,1.99976003170013,,,,,,,,,,,,,,,,,,,,,,,,,,,,,,,,,
,3865672932.15141,1.99993413686752,32584.568359375,0.416124139735891,9.84538494770961E-5,1,2,12.9061126708984,4.99561545289027,40.8999994397163,542.623038311237,80.0494728719985,1000,0.000249356124671921,,,,,,,,,,,,,,,,,,,,,1.99967730045319,2.00019097328186,32494.255859375,32674.880859375,50.6897819148996,5.40746661293255,2.44540023803711,26,1,0,0,1,0.289764404296875,31.2805480957031,1,6,1,1.99967730045319,0,1.99993413686752,,,,,,,,,,,,,,,,,,,,,,,,,,,,,,,,,
,3865672992.97604,1.99982756376266,38672.91796875,0.451010136147667,0.000103042640765703,1,2,12.9061126708984,4.9957140131435,40.8999994397163,588.103442475807,86.9463941075969,1000,0.000410989394718651,,,,,,,,,,,,,,,,,,,,,1.99964225292206,2.00001287460327,38617.79296875,38728.04296875,50.7484040538419,5.40832402697817,2.43524861335754,26,1,0,0,1,0.2911376953125,31.7693061828613,1,6,1,2.00001287460327,0,1.99982756376266,,,,,,,,,,,,,,,,,,,,,,,,,,,,,,,,,
,3865673053.28816,1.99993455410004,44720.271484375,0.480169009671821,0.000111020893252843,1,2,12.9061126708984,4.99571476609173,40.8999994397163,626.150563067653,92.3995216904202,1000,0.000308600958968262,,,,,,,,,,,,,,,,,,,,,1.99975538253784,2.00011372566223,44600.09375,44840.44921875,50.9168449997361,5.40789301605946,2.43118095397949,26,1,0,0,1,0.289382934570313,31.7693061828613,1,6,1,2.00011372566223,0,1.99993455410004,,,,,,,,,,,,,,,,,,,,,,,,,,,,,,,,,
,3865673451.35137,2.39076578617096,26.4751167297363,0.00928324559425117,3.86204553041905E-5,1,5,12.9061126708984,5.00591463816762,40.8999994397163,12.1431076263441,1.77154267607799,1000,-9.2903244363915E-6,,,,,,,,,,,,,,,,,,,,,2.06743741035461,2.7140941619873,26.4751167297363,26.4751167297363,50.1793784918418,5.40276399039375,2.77137279510498,65,1,0,0,1,0.269622802734375,30.3030319213867,6,1,1,2.7140941619873,0,2.39076578617096,,,,,,,,,,,,,,,,,,,,,,,,,,,,,,,,,
,3865673637.07465,30.1184787750244,26.4751167297363,0.00024924915636443,1.07284055739249E-7,1,5,12.9061126708984,5.00610395038656,40.8999994397163,0.325998403601284,0.0479311437976323,1,2.87447765428808E-8,,,,,,,,,,,,,,,,,,,,,30.1184787750244,30.1184787750244,26.4751167297363,26.4751167297363,50.2219772461399,5.40161927796901,6.00989437103271,65,1,0,0,1,0.26885986328125,31.2805480957031,2,1,1,30.1184787750244,0,30.1184787750244,,,,,,,,,,,,,,,,,,,,,,,,,,,,,,,,,
,3865673808.90703,57.028678894043,26.4751167297363,0.000198856640020976,6.4099516270374E-8,1,5,12.9061126708984,5.00540733552658,40.9299992024899,0.260049942042595,0.038153858231916,1,-3.7671842975608E-8,,,,,,,,,,,,,,,,,,,,,57.028678894043,57.028678894043,26.4751167297363,26.4751167297363,50.2129885181688,5.40408761370237,6.54618167877197,65,1,0,0,1,0.271835327148438,31.7693061828613,2,1,1,57.028678894043,0,57.028678894043,,,,,,,,,,,,,,,,,,,,,,,,,,,,,,,,,
,3865673977.90309,84.0135116577148,26.4751167297363,0.000170528551969824,8.41304316719862E-8,1,5,12.9061126708984,5.00538513742662,40.9700013697147,0.223009712700239,0.0326740484043576,1,-6.62627959036875E-8,,,,,,,,,,,,,,,,,,,,,84.0135116577148,84.0135116577148,26.4751167297363,26.4751167297363,50.2278394600342,5.40435734224513,6.78450965881348,65,1,0,0,1,0.266952514648438,30.7917900085449,2,1,1,84.0135116577148,0,84.0135116577148,,,,,,,,,,,,,,,,,,,,,,,,,,,,,,,,,
,3865674141.94099,111.11589050293,26.4751167297363,0.000128775285526517,8.66716606739819E-8,1,5,12.9061126708984,5.00467997044291,41.0199984908104,0.168398527616342,0.0244982768628002,1,-1.80670610293938E-7,,,,,,,,,,,,,,,,,,,,,111.11589050293,111.11589050293,26.4751167297363,26.4751167297363,50.1981375763034,5.4071811483837,6.9070029258728,65,1,0,0,1,0.272140502929687,32.2580642700195,2,1,1,111.11589050293,0,111.11589050293,,,,,,,,,,,,,,,,,,,,,,,,,,,,,,,,,
,3865674305.14481,138.016021728516,26.4751167297363,9.64689988644665E-5,4.12763296802906E-8,1,5,12.9061126708984,5.00435815805441,41.0999990999699,0.126116564272276,0.0185134102889822,1,-1.08528589262438E-8,,,,,,,,,,,,,,,,,,,,,138.016021728516,138.016021728516,26.4751167297363,26.4751167297363,50.2165058465053,5.40857799274195,6.99706363677978,65,1,0,0,1,0.2679443359375,31.7693061828613,2,1,1,138.016021728516,0,138.016021728516,,,,,,,,,,,,,,,,,,,,,,,,,,,,,,,,,
,3865674467.99366,165.001663208008,26.4751167297363,8.35619784261988E-5,2.97147709600138E-8,1,5,12.9061126708984,5.00470896140251,41.1799997091293,0.109262615312413,0.01597648670761,1,-5.64429281588858E-8,,,,,,,,,,,,,,,,,,,,,165.001663208008,165.001663208008,26.4751167297363,26.4751167297363,50.2536332011688,5.40738551936817,7.05452108383179,65,1,0,0,1,0.26763916015625,31.7693061828613,2,1,1,165.001663208008,0,165.001663208008,,,,,,,,,,,,,,,,,,,,,,,,,,,,,,,,,
,3865674631.33194,192.070541381836,26.4751167297363,7.39191858358169E-5,4.29372209823895E-8,1,5,12.9061126708984,5.00441474812925,41.2900000810623,0.0966308537765955,0.0142354504710769,1,2.94410425792098E-8,,,,,,,,,,,,,,,,,,,,,192.070541381836,192.070541381836,26.4751167297363,26.4751167297363,50.2301843455919,5.40731228380229,7.13140106201172,65,1,0,0,1,0.268096923828125,32.2580642700195,2,1,1,192.070541381836,0,192.070541381836,,,,,,,,,,,,,,,,,,,,,,,,,,,,,,,,,
,3865674793.72729,219.033767700195,26.4751167297363,6.58903467085796E-5,4.23696029714263E-8,1,5,12.9061126708984,5.00428837665989,41.4000004529953,0.0861427547107459,0.0126163418493481,1,-2.91818726088135E-8,,,,,,,,,,,,,,,,,,,,,219.033767700195,219.033767700195,26.4751167297363,26.4751167297363,50.2872432274957,5.40981210822608,7.24577379226685,65,1,0,0,1,0.270462036132813,31.7693061828613,2,1,1,219.033767700195,0,219.033767700195,,,,,,,,,,,,,,,,,,,,,,,,,,,,,,,,,
,3865674956.7037,246.031433105469,26.4751167297363,5.9335285024188E-5,2.70821891093874E-8,1,5,12.9061126708984,5.00398864545551,41.5400005877018,0.077576219127446,0.0112933682419305,1,-7.74518974975914E-8,,,,,,,,,,,,,,,,,,,,,246.031433105469,246.031433105469,26.4751167297363,26.4751167297363,50.2317476026303,5.41046171183815,7.47265386581421,64,1,64,0,0,0.268936157226562,31.7693061828613,2,1,1,246.031433105469,0,246.031433105469,,,,,,,,,,,,,,,,,,,,,,,,,,,,,,,,,
,3865675120.31445,273.243530273438,26.4751167297363,5.37307926580415E-5,2.24469301057827E-8,1,5,12.9061126708984,5.0040239107138,41.6899994015694,0.0702444376340065,0.0102610737960574,1,-4.38846539842788E-8,,,,,,,,,,,,,,,,,,,,,273.243530273438,273.243530273438,26.4751167297363,26.4751167297363,50.2637943719188,5.41003477664649,7.80769157409668,63,1,64,0,0,0.269317626953125,31.7693061828613,2,1,1,273.243530273438,0,273.243530273438,,,,,,,,,,,,,,,,,,,,,,,,,,,,,,,,,
,3865675365.00803,299.937377929687,26.4751167297363,4.84448922996149E-5,9.33425735423913E-9,1,5,12.9061126708984,5.00399946643825,41.8399982154369,0.0633353108979983,0.00923945263827106,1,-4.88234258900246E-8,,,,,,,,,,,,,,,,,,,,,299.937377929687,299.937377929687,26.4751167297363,26.4751167297363,50.2118160753899,5.41194339980541,7.54747486114502,65,1,0,0,1,0.2685546875,32.2580642700195,1,1,1,299.937377929687,0,299.937377929687,,,,,,,,,,,,,,,,,,,,,,,,,,,,,,,,,
,3865676040.57009,274.892150878906,26.1993350982666,0.000115293839815179,8.07891925453688E-9,1,5,12.9061126708984,4.98311100365714,41.7000018060207,0.149843195367105,0.0219056313919921,1,-8.13324834382793E-8,,,,,,,,,,,,,,,,,,,,,274.862701416016,274.921600341797,26.1993350982666,26.1993350982666,50.1911029196303,5.41386095432278,8.26358604431152,64,1,64,0,0,0.272064208984375,31.7693061828613,2,1,1,274.862701416016,0,274.892150878906,,,,,,,,,,,,,,,,,,,,,,,,,,,,,,,,,
,3865676193.68512,249.976463317871,26.1993350982666,0.000115777734708898,9.25407328571104E-9,1,5,12.9061126708984,4.98347870583268,41.5799990296364,0.15048894180271,0.0219913834596483,1,-8.81893521081212E-8,,,,,,,,,,,,,,,,,,,,,249.963668823242,249.9892578125,26.1993350982666,26.1993350982666,50.1692173210919,5.41361036483632,8.07784080505371,65,1,0,0,1,0.270538330078125,31.2805480957031,2,1,1,249.963668823242,0,249.976463317871,,,,,,,,,,,,,,,,,,,,,,,,,,,,,,,,,
,3865676355.05935,222.874572753906,26.1993350982666,0.000115210122555736,1.81488482863031E-8,1,5,12.9061126708984,4.98194941206846,41.4699986577034,0.149685634972156,0.0218805571355242,1,-8.28110591050926E-8,,,,,,,,,,,,,,,,,,,,,222.861221313477,222.887924194336,26.1993350982666,26.1993350982666,50.2227588746592,5.41861531063218,7.9457859992981,64,1,64,0,0,0.275802612304687,31.2805480957031,2,1,1,222.861221313477,0,222.874572753906,,,,,,,,,,,,,,,,,,,,,,,,,,,,,,,,,
,3865676516.96074,195.884918212891,26.1993350982666,0.000113600201750489,1.46064745265119E-8,1,5,12.9061126708984,4.98243717948113,41.3900017738342,0.147613608813216,0.021582275844069,1,-7.81873450437806E-8,,,,,,,,,,,,,,,,,,,,,195.884918212891,195.884918212891,26.1993350982666,26.1993350982666,50.1903212911111,5.41660297680403,7.83645057678223,65,1,0,0,1,0.274276733398438,31.7693061828613,2,1,1,195.884918212891,0,195.884918212891,,,,,,,,,,,,,,,,,,,,,,,,,,,,,,,,,
,3865676679.20275,168.867172241211,26.1993350982666,0.000107716449116433,1.49501269441137E-8,1,5,12.9061126708984,4.98269597492976,41.2999987602234,0.139976161970932,0.0204811797786241,1,-6.24153354789597E-8,,,,,,,,,,,,,,,,,,,,,168.867172241211,168.867172241211,26.1993350982666,26.1993350982666,50.1871947770342,5.41592390381918,7.75336265563965,64,1,64,0,0,0.272369384765625,32.2580642700195,2,1,1,168.867172241211,0,168.867172241211,,,,,,,,,,,,,,,,,,,,,,,,,,,,,,,,,
,3865676841.3088,141.900741577148,26.1993350982666,0.000101168975755991,1.30059567134663E-8,1,5,12.9061126708984,4.98399419192596,41.2199981510639,0.131522291374747,0.0192000264330566,1,-9.19029705845508E-8,,,,,,,,,,,,,,,,,,,,,141.900741577148,141.900741577148,26.1993350982666,26.1993350982666,50.2016549046399,5.410601591411,7.64556360244751,65,1,0,0,1,0.2691650390625,31.2805480957031,2,1,1,141.900741577148,0,141.900741577148,,,,,,,,,,,,,,,,,,,,,,,,,,,,,,,,,
,3865677003.39777,114.883865356445,26.1993350982666,8.6278107430295E-5,2.02541318387669E-8,1,5,12.9061126708984,4.9853506352207,41.1400012671947,0.112206974757622,0.0163781394057488,1,-8.00157302548088E-8,,,,,,,,,,,,,,,,,,,,,114.883865356445,114.883865356445,26.1993350982666,26.1993350982666,50.2168966607649,5.40449525733723,7.5471363067627,65,1,0,0,1,0.272750854492187,31.7693061828613,2,1,1,114.883865356445,0,114.883865356445,,,,,,,,,,,,,,,,,,,,,,,,,,,,,,,,,
,3865677165.14594,87.7955169677734,26.1993350982666,7.41619296447578E-5,8.84321703365323E-9,1,5,12.9061126708984,4.9856920769479,41.0600006580353,0.0964624142886955,0.0140551634113753,1,-8.74806049964673E-8,,,,,,,,,,,,,,,,,,,,,87.7955169677734,87.7955169677734,26.1993350982666,26.1993350982666,50.2512883156111,5.40384778574792,7.41207599639893,64,1,64,0,0,0.2691650390625,31.2805480957031,2,1,1,87.7955169677734,0,87.7955169677734,,,,,,,,,,,,,,,,,,,,,,,,,,,,,,,,,
,3865677323.06131,60.9465789794922,26.1993350982666,7.24612351320473E-5,8.20865745181972E-9,1,5,12.9061126708984,4.98603170235377,41.0000011324882,0.0942590969867339,0.0137358041982709,1,-8.4211659501764E-8,,,,,,,,,,,,,,,,,,,,,60.9465789794922,60.9465789794922,26.1993350982666,26.1993350982666,50.2208048033611,5.40187387174055,7.22579193115234,65,1,0,0,1,0.269317626953125,31.7693061828613,2,1,1,60.9465789794922,0,60.9465789794922,,,,,,,,,,,,,,,,,,,,,,,,,,,,,,,,,
,3865677481.60995,33.8963966369629,26.1993350982666,7.21065876111651E-5,6.04486040677448E-9,1,5,12.9061126708984,4.9864979654917,40.9400016069412,0.0938073393885764,0.0136890427258437,1,-6.94459233471175E-8,,,,,,,,,,,,,,,,,,,,,33.8963966369629,33.8963966369629,26.1993350982666,26.1993350982666,50.229011902813,5.40003923338266,6.85093259811401,65,1,0,0,1,0.26885986328125,31.2805480957031,2,1,1,33.8963966369629,0,33.8963966369629,,,,,,,,,,,,,,,,,,,,,,,,,,,,,,,,,
,3865677705.3328,6.90148735046387,26.1993350982666,6.55273802036344E-5,1.93169061676627E-8,1,5,12.9061126708984,4.98625171126653,40.8999994397163,0.0852421284604803,0.0124395212757077,1,-6.28265980819779E-8,,,,,,,,,,,,,,,,,,,,,6.90148735046387,6.90148735046387,26.1993350982666,26.1993350982666,50.2692657715534,5.40107894645177,4.50645351409912,65,1,0,0,1,0.269241333007813,31.2805480957031,6,1,1,6.90148735046387,0,6.90148735046387,,,,,,,,,,,,,,,,,,,,,,,,,,,,,,,,,
,3865678230.61327,22.1010208129883,26.1993350982666,7.01777136456793E-5,1.4326273330881E-8,1,5,12.9061126708984,4.9859138720139,40.8999994397163,0.091282402263986,0.0133243616262953,1,-6.47458501778618E-8,,,,,,,,,,,,,,,,,,,,,22.1010208129883,22.1010208129883,26.1993350982666,26.1993350982666,50.3341409386496,5.40280446938531,5.81157922744751,65,1,0,0,1,0.272445678710938,31.2805480957031,2,1,1,22.1010208129883,0,22.1010208129883,,,,,,,,,,,,,,,,,,,,,,,,,,,,,,,,,
,3865678403.66533,49.1020050048828,26.1993350982666,7.20877429419726E-5,6.2293287858204E-9,1,5,12.9061126708984,4.98648053897942,40.9200005233288,0.093784181285729,0.0136730218696816,1,-7.89422913180832E-8,,,,,,,,,,,,,,,,,,,,,49.1020050048828,49.1020050048828,26.1993350982666,26.1993350982666,50.2469893587553,5.40001688582911,6.47550582885742,65,1,0,0,1,0.269622802734375,31.7693061828613,2,1,1,49.1020050048828,0,49.1020050048828,,,,,,,,,,,,,,,,,,,,,,,,,,,,,,,,,
,3865678573.32122,76.0210723876953,26.1993350982666,7.18737176466423E-5,9.23137222069192E-9,1,5,12.9061126708984,4.9854704991179,40.9500002861023,0.0934800444884836,0.0136224024052069,1,-8.34349223895476E-8,,,,,,,,,,,,,,,,,,,,,76.0210723876953,76.0210723876953,26.1993350982666,26.1993350982666,50.2395638878226,5.40451011462595,6.79011535644531,65,1,0,0,1,0.269317626953125,31.7693061828613,2,1,1,76.0210723876953,0,76.0210723876953,,,,,,,,,,,,,,,,,,,,,,,,,,,,,,,,,
,3865678738.71844,103.027465820312,26.1993350982666,7.37477206963117E-5,7.60640046012977E-9,1,5,12.9061126708984,4.98461842624445,41.0000011324882,0.0958927487701123,0.0139852990631828,1,-7.70972150958004E-8,,,,,,,,,,,,,,,,,,,,,103.027465820312,103.027465820312,26.1993350982666,26.1993350982666,50.1633551071976,5.40817604871103,6.944176197052,65,1,0,0,1,0.270309448242187,31.7693061828613,2,1,1,103.027465820312,0,103.027465820312,,,,,,,,,,,,,,,,,,,,,,,,,,,,,,,,,
,3865678902.11325,130.039932250977,26.1993350982666,7.90916952337647E-5,6.80128156533839E-9,1,5,12.9061126708984,4.98445105444457,41.0699993371964,0.102834422595552,0.0150125935227858,1,-7.14637205514394E-8,,,,,,,,,,,,,,,,,,,,,130.039932250977,130.039932250977,26.1993350982666,26.1993350982666,50.254414829688,5.40879004399877,7.03619194030762,65,1,0,0,1,0.26947021484375,32.2580642700195,2,1,1,130.039932250977,0,130.039932250977,,,,,,,,,,,,,,,,,,,,,,,,,,,,,,,,,
,3865679065.46174,157.011184692383,26.1993350982666,8.08100621001414E-5,1.04274781809022E-8,1,5,12.9061126708984,4.98406351945309,41.1599986255169,0.105058523213962,0.0153277652856347,1,-8.01865579734089E-8,,,,,,,,,,,,,,,,,,,,,157.011184692383,157.011184692383,26.1993350982666,26.1993350982666,50.2067354900149,5.41047035648406,7.09971141815186,65,1,0,0,1,0.26947021484375,32.2580642700195,2,1,1,157.011184692383,0,157.011184692383,,,,,,,,,,,,,,,,,,,,,,,,,,,,,,,,,
,3865679227.85344,184.003295898438,26.1993350982666,8.07928724676801E-5,7.67286947068882E-9,1,5,12.9061126708984,4.98470819891475,41.2500016391277,0.105053779054171,0.0153373877913228,1,-7.24023196353638E-8,,,,,,,,,,,,,,,,,,,,,184.003295898438,184.003295898438,26.1993350982666,26.1993350982666,50.1946202479669,5.40953832966702,7.166015625,65,1,0,0,1,0.272140502929687,32.2580642700195,2,1,1,184.003295898438,0,184.003295898438,,,,,,,,,,,,,,,,,,,,,,,,,,,,,,,,,
,3865679391.33543,211.164077758789,26.1993350982666,7.97835268221807E-5,8.89265450951938E-9,1,5,12.9061126708984,4.98480438225775,41.3700006902218,0.103741921064838,0.0151613861106411,1,-5.98085059532652E-8,,,,,,,,,,,,,,,,,,,,,211.164077758789,211.164077758789,26.1993350982666,26.1993350982666,50.2254945744765,5.40824827527491,7.25359487533569,63,1,64,0,0,0.272750854492187,31.7693061828613,2,1,1,211.164077758789,0,211.164077758789,,,,,,,,,,,,,,,,,,,,,,,,,,,,,,,,,
,3865679553.45463,238.005722045898,26.1993350982666,7.83121904625397E-5,1.26396002468648E-8,1,5,12.9061126708984,4.98440580952055,41.4899997413158,0.101821743288527,0.0148499776015307,1,-8.18875266260923E-8,,,,,,,,,,,,,,,,,,,,,238.005722045898,238.005722045898,26.1993350982666,26.1993350982666,50.1911029196303,5.41149547906147,7.39687728881836,63,1,64,0,0,0.270233154296875,31.7693061828613,2,1,1,238.005722045898,0,238.005722045898,,,,,,,,,,,,,,,,,,,,,,,,,,,,,,,,,
,3865679716.10716,265.069091796875,26.1993350982666,7.63008763753186E-5,1.04710043928675E-8,1,5,12.9061126708984,4.98415634000236,41.6399985551834,0.0991981304906513,0.0144779152464817,1,-7.18214290060878E-8,,,,,,,,,,,,,,,,,,,,,265.069091796875,265.069091796875,26.1993350982666,26.1993350982666,50.2407363306015,5.4124925706132,7.7007532119751,63,1,64,0,0,0.271224975585938,32.2580642700195,2,1,1,265.069091796875,0,265.069091796875,,,,,,,,,,,,,,,,,,,,,,,,,,,,,,,,,
,3865679879.83917,292.125152587891,26.1993350982666,7.43529900204204E-5,9.37513956181434E-9,1,5,12.9061126708984,4.9842952203502,41.7999997735023,0.0966656380205168,0.0141350387472911,1,-4.98502823170199E-8,,,,,,,,,,,,,,,,,,,,,292.125152587891,292.125152587891,26.1993350982666,26.1993350982666,50.2055630472361,5.41196690683804,7.55323600769043,63,1,64,0,0,0.271453857421875,31.7693061828613,2,1,1,292.125152587891,0,292.125152587891,,,,,,,,,,,,,,,,,,,,,,,,,,,,,,,,,
,3865680172.64885,300.004028320313,43602.537109375,0.0198721074702867,5.63041935668446E-6,1,2,12.9061126708984,4.98432646180657,41.8299995362759,25.8386525834843,3.75825308905609,100,-2.84089373582267E-5,,,,,,,,,,,,,,,,,,,,,300.003845214844,300.004211425781,43442.671875,43762.40234375,50.0676056135918,5.41145696965449,7.54692888259888,26,1,0,0,1,0.270919799804687,31.2805480957031,1,6,1,300.004211425781,0,300.004028320313,,,,,,,,,,,,,,,,,,,,,,,,,,,,,,,,,
,3865680269.4639,300.004364013672,33938.4921875,0.0157748817890123,4.77132739673808E-6,1,2,12.9061126708984,4.98409811565374,41.8299995362759,20.5108921605593,2.97660985487246,1000,-2.76101901933488E-5,,,,,,,,,,,,,,,,,,,,,300.004364013672,300.004364013672,33938.4921875,33938.4921875,50.1660908070149,5.41245997501262,7.62130069732666,26,1,0,0,1,0.268478393554687,31.7693061828613,1,6,1,300.004364013672,0,300.004364013672,,,,,,,,,,,,,,,,,,,,,,,,,,,,,,,,,
,3865680377.19863,300.001953125,23180.9892578125,0.0110603543762031,5.40690859315682E-6,1,2,12.9061126708984,4.98466094096057,41.8299995362759,14.3824592520585,2.09257717670408,100,-1.53322314374083E-5,,,,,,,,,,,,,,,,,,,,,300.001922607422,300.001983642578,23056.25390625,23305.724609375,50.1903212911111,5.41060415537352,7.78150224685669,26,1,0,0,1,0.269317626953125,32.2580642700195,1,6,1,300.001922607422,0,300.001953125,,,,,,,,,,,,,,,,,,,,,,,,,,,,,,,,,
,3865680445.23244,300.001800537109,16387.0126953125,0.00808286743165917,4.76619553708104E-6,1,2,12.9061126708984,4.9848219179705,41.8299995362759,10.5113432753474,1.52784257251556,100,-1.23390055686223E-5,,,,,,,,,,,,,,,,,,,,,300.001647949219,300.001953125,16297.201171875,16476.82421875,50.1938386194476,5.41002805148497,7.92600202560425,26,1,0,0,1,0.269622802734375,30.7917900085449,1,6,1,300.001647949219,0,300.001800537109,,,,,,,,,,,,,,,,,,,,,,,,,,,,,,,,,
,3865680506.01764,300.002075195313,10319.8051757813,0.0054474532847874,4.92099802758675E-6,1,2,12.9061126708984,4.98476710149576,41.8299995362759,7.08449448396029,1.026421510114,100,-1.08179182348421E-5,,,,,,,,,,,,,,,,,,,,,300.001983642578,300.002166748047,10264.8994140625,10374.7109375,50.1590561503418,5.4101764960652,8.06290054321289,26,1,0,0,1,0.269088745117187,31.7693061828613,1,6,1,300.002166748047,0,300.002075195313,,,,,,,,,,,,,,,,,,,,,,,,,,,,,,,,,
,3865680561.46338,300.001098632812,4774.06420898438,0.00295778013532803,5.01718282010655E-6,1,2,12.9061126708984,4.9849196626077,41.8399982154369,3.84853016624214,0.545576923885428,100,-1.49175654475829E-5,,,,,,,,,,,,,,,,,,,,,300.000762939453,300.001434326172,4619.24365234375,4928.884765625,50.2266670172553,5.40921836557493,8.19253921508789,26,1,0,0,1,0.266952514648438,32.2580642700195,1,6,1,300.001434326172,0,300.001098632812,,,,,,,,,,,,,,,,,,,,,,,,,,,,,,,,,
,3865680618.49433,300.001205444336,-922.906036376953,-0.000949856464239494,9.2060996989435E-6,1,2,12.9061126708984,4.98488761844625,41.8399982154369,-1.23302568338249,-0.194763973220093,100,-1.02534047692663E-5,,,,,,,,,,,,,,,,,,,,,300.0009765625,300.001434326172,-1017.67486572266,-828.13720703125,50.1997008333418,5.40951473973933,8.32786178588867,26,1,0,0,1,0.269699096679687,31.2805480957031,1,6,1,300.001434326172,0,300.001205444336,,,,,,,,,,,,,,,,,,,,,,,,,,,,,,,,,
,3865680679.30493,300.000671386719,-7000.53125,-0.00396160889938974,4.96094931341102E-6,1,2,12.9061126708984,4.98485511094384,41.8299995362759,-5.15086959885095,-0.755934117373381,100,5.91041566951325E-7,,,,,,,,,,,,,,,,,,,,,300.00048828125,300.000854492188,-7055.5185546875,-6945.5439453125,50.2223680603995,5.40981299851784,8.50804233551025,26,1,0,0,1,0.271377563476562,32.2580642700195,1,6,1,300.00048828125,0,300.000671386719,,,,,,,,,,,,,,,,,,,,,,,,,,,,,,,,,
,3865680763.53374,300.000411987305,-15426.6196289062,-0.00767172820939822,4.94547003323765E-6,1,2,12.9061126708984,4.98482027063617,41.8299995362759,-9.97610249102167,-1.45401583520047,100,8.72062749243258E-6,,,,,,,,,,,,,,,,,,,,,300.000335693359,300.00048828125,-15516.5625,-15336.6767578125,50.2153334037265,5.4094211636664,8.5849552154541,26,1,0,0,1,0.267257690429687,31.7693061828613,1,6,1,300.000335693359,0,300.000411987305,,,,,,,,,,,,,,,,,,,,,,,,,,,,,,,,,
,3865680822.18488,300.000213623047,-21291.390625,-0.0102206302270554,5.02994305151138E-6,1,2,12.9061126708984,4.98469982874531,41.8299995362759,-13.2897047905104,-1.94022725119362,100,9.16744137787085E-6,,,,,,,,,,,,,,,,,,,,,300.000061035156,300.000366210937,-21406.310546875,-21176.470703125,50.1606194073803,5.40980137890803,8.53795146942139,26,1,0,0,1,0.268478393554687,32.2580642700195,1,6,1,300.000061035156,0,300.000213623047,,,,,,,,,,,,,,,,,,,,,,,,,,,,,,,,,
,3865680900.53662,300.000595092773,-29133.677734375,-0.013644810025129,5.20914263028138E-6,1,2,12.9061126708984,4.98464277960083,41.8299995362759,-17.7406230530826,-2.59836016406409,100,5.9719596268981E-6,,,,,,,,,,,,,,,,,,,,,300.000335693359,300.000854492188,-29223.7890625,-29043.56640625,50.213770146688,5.41014391555502,8.49336242675781,26,1,0,0,1,0.268173217773438,32.2580642700195,1,6,1,300.000854492188,0,300.000595092773,,,,,,,,,,,,,,,,,,,,,,,,,,,,,,,,,
,3865680977.21314,299.999130249023,-36817.44921875,-0.0169813599457317,5.16831016101278E-6,1,2,12.9061126708984,4.98469929490135,41.8399982154369,-22.0800986159407,-3.22677824436816,100,1.28221920521335E-5,,,,,,,,,,,,,,,,,,,,,299.998931884766,299.999328613281,-36897.7265625,-36737.171875,50.1055145967745,5.40973658284126,8.46816158294678,26,1,0,0,1,0.2691650390625,31.7693061828613,1,6,1,299.998931884766,0,299.999130249023,,,,,,,,,,,,,,,,,,,,,,,,,,,,,,,,,
,3865681065.82624,300.000503540039,-45693.224609375,-0.0208392211171229,5.24559958696029E-6,1,2,12.9061126708984,4.98454648192635,41.8299995362759,-27.093033682103,-3.97397790801293,100,4.73262268866581E-6,,,,,,,,,,,,,,,,,,,,,300.000366210937,300.000640869141,-45793.31640625,-45593.1328125,50.0636974709957,5.40979212513072,8.4340238571167,26,1,0,0,1,0.268707275390625,31.7693061828613,1,6,1,300.000640869141,0,300.000503540039,,,,,,,,,,,,,,,,,,,,,,,,,,,,,,,,,
,3865681138.35832,300.001159667969,-47521.109375,-0.021662691409004,6.16758726201458E-6,1,2,12.9061126708984,4.98460399493644,41.8299995362759,-28.174266647627,-4.06175577528255,1000,5.82414784931684E-5,,,,,,,,,,,,,,,,,,,,,300.000946044922,300.001373291016,-47625.875,-47416.34375,50.1055145967745,5.40956400951154,8.41610336303711,26,1,0,0,1,0.268707275390625,33.2355842590332,1,6,1,300.001373291016,0,300.001159667969,,,,,,,,,,,,,,,,,,,,,,,,,,,,,,,,,
,3865681213.005,300.001098632812,-40075.384765625,-0.0184287965232567,4.87092212276884E-6,1,2,12.9061126708984,4.98476166766789,41.8299995362759,-23.9650640059159,-3.48481177420749,100,2.70431774548076E-5,,,,,,,,,,,,,,,,,,,,,300.000671386719,300.001525878906,-40190.078125,-39960.69140625,50.0633066567361,5.40963324977862,8.40574550628662,26,1,0,0,1,0.269546508789062,31.7693061828613,1,6,1,300.001525878906,0,300.001098632812,,,,,,,,,,,,,,,,,,,,,,,,,,,,,,,,,
,3865681315.87482,300.000427246094,-29805.15234375,-0.0139636212912198,5.24394140510779E-6,1,2,12.9061126708984,4.98475090888586,41.8299995362759,-18.1572990458769,-2.64817432011466,100,1.45549690918823E-5,,,,,,,,,,,,,,,,,,,,,300.000427246094,300.000427246094,-29860.146484375,-29750.158203125,50.1946202479669,5.40937382015143,8.38924217224121,26,1,0,0,1,0.272064208984375,31.7693061828613,1,6,1,300.000427246094,0,300.000427246094,,,,,,,,,,,,,,,,,,,,,,,,,,,,,,,,,
,3865681394.28808,299.999786376953,-21978.9296875,-0.0105462156802139,5.27235339344056E-6,1,2,12.9061126708984,4.98462686431928,41.8299995362759,-13.7132323665152,-1.99888579110484,100,1.1849793932758E-5,,,,,,,,,,,,,,,,,,,,,299.999755859375,299.999816894531,-22093.94921875,-21863.91015625,50.2368281880053,5.41024692078331,8.37411594390869,26,1,0,0,1,0.2685546875,31.7693061828613,1,6,1,299.999755859375,0,299.999786376953,,,,,,,,,,,,,,,,,,,,,,,,,,,,,,,,,
,3865681452.52906,300.000762939453,-16159.1538085938,-0.00800197457641825,4.4490312376026E-6,1,2,12.9061126708984,4.98460321578356,41.8299995362759,-10.4054747925176,-1.51266464794223,100,1.20571780613362E-5,,,,,,,,,,,,,,,,,,,,,300.000610351562,300.000915527344,-16254.1044921875,-16064.203125,50.1899304768515,5.41028333228478,8.37007713317871,26,1,0,0,1,0.269241333007813,31.7693061828613,1,6,1,300.000610351562,0,300.000762939453,,,,,,,,,,,,,,,,,,,,,,,,,,,,,,,,,
,3865681510.99918,300.000518798828,-10327.025390625,-0.00544865026260771,4.7162998579024E-6,1,2,12.9061126708984,4.9843790579926,41.8299995362759,-7.08544205366571,-1.02540631989703,100,1.16883440214447E-5,,,,,,,,,,,,,,,,,,,,,300.00048828125,300.000549316406,-10421.8701171875,-10232.1806640625,50.1938386194476,5.41109722087202,8.36583042144775,26,1,0,0,1,0.270767211914062,31.7693061828613,1,6,1,300.000549316406,0,300.000518798828,,,,,,,,,,,,,,,,,,,,,,,,,,,,,,,,,
,3865681570.62921,300.000686645508,-4367.6171875,-0.00276928542533791,5.01344041432129E-6,1,2,12.9061126708984,4.98443597617454,41.8399982154369,-3.6028712674264,-0.510105143658609,100,1.44541104709354E-5,,,,,,,,,,,,,,,,,,,,,300.000579833984,300.000793457031,-4537.41162109375,-4197.82275390625,50.2766912424861,5.41114570528353,8.36039733886719,26,1,0,0,1,0.268325805664062,31.7693061828613,1,6,1,300.000793457031,0,300.000686645508,,,,,,,,,,,,,,,,,,,,,,,,,,,,,,,,,
,3865681625.76556,299.999847412109,1144.05853271484,0.00111961687357411,7.86912095583779E-6,1,2,12.9061126708984,4.98450325884406,41.8299995362759,1.45322785734806,0.229611950938843,100,1.21353011186322E-5,,,,,,,,,,,,,,,,,,,,,299.999755859375,299.999938964844,1049.12670898438,1238.99035644531,50.2946686984284,5.41105696099426,8.35743808746338,26,1,0,0,1,0.268783569335938,31.7693061828613,1,6,1,299.999755859375,0,299.999847412109,,,,,,,,,,,,,,,,,,,,,,,,,,,,,,,,,
,3865681686.48268,300.000198364258,7218.10473632813,0.00407222535003917,4.68358144924961E-6,1,2,12.9061126708984,4.98462942070437,41.8299995362759,5.2944294544376,0.776491756017219,100,-9.92297785225874E-7,,,,,,,,,,,,,,,,,,,,,299.999816894531,300.000579833984,7097.8134765625,7338.39599609375,50.2227588746592,5.41032465618051,8.347825050354,26,1,0,0,1,0.268707275390625,31.7693061828613,1,6,1,300.000579833984,0,300.000198364258,,,,,,,,,,,,,,,,,,,,,,,,,,,,,,,,,
,3865681782.94104,299.999298095703,16864.3681640625,0.00831382471304395,5.02516335268307E-6,1,2,12.9061126708984,4.98444806677379,41.8299995362759,10.8097343547049,1.57689867493456,100,-8.41042393780466E-6,,,,,,,,,,,,,,,,,,,,,299.999267578125,299.999328613281,16779.408203125,16949.328125,50.1942294337072,5.41063668040295,8.34262752532959,26,1,0,0,1,0.26885986328125,31.7693061828613,1,6,1,299.999328613281,0,299.999298095703,,,,,,,,,,,,,,,,,,,,,,,,,,,,,,,,,
,3865681852.67988,300.000274658203,23836.3046875,0.0113929093451126,5.20151302932197E-6,1,2,12.9061126708984,4.98470857896625,41.8299995362759,14.8139238878186,2.16352872153972,100,-9.63648986220968E-6,,,,,,,,,,,,,,,,,,,,,299.999877929687,300.000671386719,23671.19921875,24001.41015625,50.2450352874572,5.40993327504302,8.34195327758789,26,1,0,0,1,0.268936157226562,31.2805480957031,1,6,1,300.000671386719,0,300.000274658203,,,,,,,,,,,,,,,,,,,,,,,,,,,,,,,,,
,3865681911.92877,299.999847412109,29769.4326171875,0.013946025900648,5.88402759527668E-6,1,2,12.9061126708984,4.98468023933518,41.8299995362759,18.1331822253514,2.65074664697712,100,-9.95089300338136E-6,,,,,,,,,,,,,,,,,,,,,299.999816894531,299.999877929687,29669.080078125,29869.78515625,50.132480780688,5.40992352128916,8.33629131317139,26,1,0,0,1,0.269851684570313,32.2580642700195,1,6,1,299.999877929687,0,299.999847412109,,,,,,,,,,,,,,,,,,,,,,,,,,,,,,,,,
,3865681984.37752,300.000183105469,37029.763671875,0.0171094481429283,5.35504348252863E-6,1,2,12.9061126708984,4.98490835316829,41.8299995362759,22.247175662721,3.25662467125056,100,-8.83048437601026E-6,,,,,,,,,,,,,,,,,,,,,300.000061035156,300.000305175781,36934.56640625,37124.9609375,50.1911029196303,5.40854321157819,8.33764743804932,26,1,0,0,1,0.268936157226562,32.2580642700195,1,6,1,300.000305175781,0,300.000183105469,,,,,,,,,,,,,,,,,,,,,,,,,,,,,,,,,
,3865682064.93943,300.001159667969,45105.939453125,0.0206209068071663,5.27519202457801E-6,1,2,12.9061126708984,4.98481884973141,41.8299995362759,26.8124715921897,3.9244111979517,100,-1.10181863703995E-5,,,,,,,,,,,,,,,,,,,,,300.000915527344,300.001403808594,45010.7578125,45201.12109375,50.0855830695341,5.40965565368824,8.32746601104736,26,1,0,0,1,0.27099609375,31.7693061828613,1,6,1,300.001403808594,0,300.001159667969,,,,,,,,,,,,,,,,,,,,,,,,,,,,,,,,,
,3865682115.92734,300.000305175781,50000.44140625,0.0227553527938749,2.46219939991909E-6,1,2,12.9061126708984,4.98479806558695,41.8299995362759,29.5878620473069,4.32898980313297,100,-1.33948733397247E-5,,,,,,,,,,,,,,,,,,,,,300,300.000610351562,50000.4296875,50000.453125,50.1309175236495,5.40928395700857,8.33073139190674,26,1,0,0,1,0.267791748046875,31.7693061828613,1,4,1,300.000610351562,0,300.000305175781,,,,,,,,,,,,,,,,,,,,,,,,,,,,,,,,,