File: LT data/Bridport/K1/258-FC-ZFC-RTSIRM-contsweepwithloop-MsT-AC.dat
[Header]
; MPMS3 Data File (default extension .dat)
; Copyright (c) 2007, Quantum Design, Inc. All rights reserved.
TITLE,
FILEOPENTIME,3866295882.90021,07/06/2022,8:02 pm
BYAPP,MPMS3 w/ AC,1.0,1.1
INFO,MPMS3 Measurement Release 1.1.16 Build 424, MultiVu Release 2.3.4.19,APPNAME
INFO,Linear Motor Servo Controller,MOTOR_MODULE_NAME
INFO,3101-100 N2,MOTOR_HW_VERSION
INFO,,MOTOR_SERIAL_NUMBER
INFO,01.04.28,MOTOR_SOFTWARE_VERSION
INFO,Quantum Design Squid Module,SQUID_MODULE_NAME
INFO,3101-501 B0,SQUID_HW_VERSION
INFO,SQM327,SQUID_SERIAL_NUMBER
INFO,01.03.04,SQUID_SOFTWARE_VERSION
INFO,Quantum Design VSM Oven,OVEN_MODULE_NAME
INFO,3101-201 A3,OVEN_HW_VERSION
INFO,OVB365,OVEN_SERIAL_NUMBER
INFO,01.07.07,OVEN_SOFTWARE_VERSION
INFO,SQUID AC,AC_MODULE_NAME
INFO,3101-401 G0,AC_HW_VERSION
INFO,SAC220,AC_SERIAL_NUMBER
INFO,SQUID AC 00.95.07,AC_SOFTWARE_VERSION
INFO,TCI344,COIL_SERIAL_NUMBER
INFO,0,MOMENT_UNITS
INFO,sndst,SAMPLE_MATERIAL
INFO,,SAMPLE_COMMENT
INFO,109.85,SAMPLE_MASS
INFO,,SAMPLE_VOLUME
INFO,,SAMPLE_MOLECULAR_WEIGHT
INFO,,SAMPLE_SIZE
INFO,,SAMPLE_SHAPE
INFO,Straw,SAMPLE_HOLDER
INFO,Standard,SAMPLE_HOLDER_DETAIL
INFO,59.56,SAMPLE_OFFSET
DATATYPE,COMMENT,1
DATATYPE,TIME,2
STARTUPAXIS,X,2
STARTUPAXIS,Y1,5
FIELDGROUP, VSM,2,3,4,5,6,8,9,10,11,14,15
FIELDGROUP, DC, 2,3,4,14,56,57,58,59,60,61,62,63,64,65,66,67,68,69
FIELDGROUP, AC, 2,3,4,11,16,17,18,19,20,21,22,23,24,25,26,27,28,29,30
STARTUPGROUP, All
[Data]
Comment,Time Stamp (sec),Temperature (K),Magnetic Field (Oe),Moment (emu),M. Std. Err. (emu),Transport Action,Averaging Time (sec),Frequency (Hz),Peak Amplitude (mm),Center Position (mm),Lockin Signal' (V),Lockin Signal (V),Range,M. Quad. Signal (emu),AC Moment (emu),AC M. Std Err. (emu),AC Phase (deg),AC Phase Std. Err. (deg),AC Susceptibility (emu/Oe),AC Suscept. Std Err. (emu/Oe),AC X' (emu/Oe),AC X' Std Err. (emu/Oe),AC X'' (emu/Oe),AC X'' Std Err. (emu/Oe),AC Drive (Oe),AC Frequency (Hz),AC Averaging Time (sec),AC Cycles,AC Range,AC Measure Type,AC Signal' (V),AC Signal'' (V),AC Trim Coil Ratio,AC Trim Coil Phase,Min. Temperature (K),Max. Temperature (K),Min. Field (Oe),Max. Field (Oe),Mass (grams),Motor Lag (deg),Pressure (Torr),Measure Count,Measurement Number,SQUID Status (code),Motor Status (code),Measure Status (code),Motor Current (amps),Motor Temp. (C),Temp. Status (code),Field Status (code),Chamber Status (code),Chamber Temp (K),Redirection State,Average Temp (K),Rotation Angle (deg),Rotator state,DC Moment Fixed Ctr (emu),DC Moment Err Fixed Ctr (emu),DC Moment Free Ctr (emu),DC Moment Err Free Ctr (emu),DC Fixed Fit,DC Free Fit,DC Calculated Center (mm),DC Calculated Center Err (mm),DC Scan Length (mm),DC Scan Time (s),DC Number of Points,DC Squid Drift,DC Min V (V),DC Max V (V),DC Scans per Measure,Map 01,Map 02,Map 03,Map 04,Map 05,Map 06,Map 07,Map 08,Map 09,Map 10,Map 11,Map 12,Map 13,Map 14,Map 15,Map 16
,3866296855.07469,100.000503540039,49999.8515625,0.0910576927600614,4.19776999704588E-5,1,2,12.9061126708984,4.97604783746606,34.4999991357327,118.130630114791,17.116097948023,100,-0.000180073792318659,,,,,,,,,,,,,,,,,,,,,100.000503540039,100.000503540039,49999.8515625,49999.8515625,49.6400548135726,5.39389568253043,7.06150722503662,26,1,0,0,1,0.268707275390625,29.8142719268799,1,1,1,100.000503540039,0,100.000503540039,,,,,,,,,,,,,,,,,,,,,,,,,,,,,,,,,
,3866296980.85526,82.5712509155273,49999.8515625,0.112253138723618,3.15470154595132E-5,1,2,12.9061126708984,4.9744544837433,34.4399996101856,145.520511197829,21.3745324105665,100,-3.03882141441451E-6,,,,,,,,,,,,,,,,,,,,,82.4436264038086,82.6988754272461,49999.8515625,49999.8515625,49.6756189111976,5.35038534633458,6.97779893875122,26,1,0,0,1,0.268096923828125,31.2805480957031,2,1,1,82.4436264038086,0,82.5712509155273,,,,,,,,,,,,,,,,,,,,,,,,,,,,,,,,,
,3866297089.89735,64.0548076629639,49999.8515625,0.147556806096682,5.04383639735696E-5,1,2,12.9061126708984,4.97387366859473,34.3899987637997,191.290394537247,27.8536535048468,1000,-0.000188050260130254,,,,,,,,,,,,,,,,,,,,,63.884334564209,64.2252807617187,49999.8515625,49999.8515625,49.7299420932841,5.35334456741601,6.873619556427,25,1,64,0,0,0.270309448242187,30.7917900085449,2,1,1,63.884334564209,0,64.0548076629639,,,,,,,,,,,,,,,,,,,,,,,,,,,,,,,,,
,3866297159.906,52.2399291992188,49999.8515625,0.182630938938417,6.52737042915067E-5,1,2,12.9061126708984,4.97396112438379,34.3700014054775,236.759686577088,34.517085597221,1000,-0.000200510125741249,,,,,,,,,,,,,,,,,,,,,52.106861114502,52.3729972839355,49999.8515625,49999.8515625,49.7823112040726,5.35255608185394,6.77161169052124,26,1,0,0,1,0.27099609375,32.2580642700195,2,1,1,52.106861114502,0,52.2399291992188,,,,,,,,,,,,,,,,,,,,,,,,,,,,,,,,,
,3866297230.39781,40.2175121307373,49999.8515625,0.232411127408843,0.000278073531652081,1,2,12.9061126708984,4.98420633690102,34.3299992382526,302.186724100781,43.9183187787153,1000,-0.000358603473367506,,,,,,,,,,,,,,,,,,,,,40.019115447998,40.4159088134766,49999.8515625,49999.8515625,49.8127947163226,5.35308962399326,6.61097192764282,26,1,0,0,1,0.271759033203125,31.7693061828613,2,1,1,40.019115447998,0,40.2175121307373,,,,,,,,,,,,,,,,,,,,,,,,,,,,,,,,,
,3866297298.93427,28.6597843170166,49999.8515625,0.298152521941478,0.000112211124538552,1,2,12.9061126708984,4.98406789569561,34.3299992382526,387.60727613255,56.6312730859689,1000,-0.000235313426876521,,,,,,,,,,,,,,,,,,,,,28.51633644104,28.8032321929932,49999.8515625,49999.8515625,49.8104498307649,5.35384953086813,6.35310316085815,26,1,0,0,1,0.267562866210938,31.7693061828613,2,1,1,28.51633644104,0,28.6597843170166,,,,,,,,,,,,,,,,,,,,,,,,,,,,,,,,,
,3866297371.45601,16.692195892334,49999.8515625,0.369834505900759,0.00280154905054115,1,2,12.9061126708984,4.98279786568589,34.2999994754791,480.583560840894,70.495895817709,1000,-8.06748680614466E-5,,,,,,,,,,,,,,,,,,,,,16.4994659423828,16.8849258422852,49999.8515625,49999.8515625,50.0140640600245,5.35879358692155,5.74618864059448,25,1,68,0,0,0.269088745117187,31.2805480957031,2,1,1,16.4994659423828,0,16.692195892334,,,,,,,,,,,,,,,,,,,,,,,,,,,,,,,,,
,3866297444.02551,6.15054154396057,49999.8515625,0.442365323511935,0.00718657548263546,1,2,12.9061126708984,4.98280924061281,34.2799983918667,575.533321459833,79.5749806083151,1000,-0.00374938222354451,,,,,,,,,,,,,,,,,,,,,5.99101543426514,6.31006765365601,49999.8515625,49999.8515625,50.42520066114,5.36095076387607,4.15092086791992,24,1,68,0,0,0.269775390625,31.7693061828613,6,1,1,5.99101543426514,0,6.15054154396057,,,,,,,,,,,,,,,,,,,,,,,,,,,,,,,,,
,3866297514.48313,2.71423017978668,49999.8515625,0.472731708999217,0.0038485145953341,1,2,12.9061126708984,4.98280003408018,34.2799983918667,614.482689727599,88.8272956131111,1000,-0.00109000751577018,,,,,,,,,,,,,,,,,,,,,2.71375060081482,2.71470975875854,49999.8515625,49999.8515625,50.6991614571304,5.363460583217,2.87608432769775,26,1,0,0,1,0.266876220703125,31.7693061828613,6,1,1,2.71375060081482,0,2.71423017978668,,,,,,,,,,,,,,,,,,,,,,,,,,,,,,,,,
,3866297587.33078,2.65442049503326,49999.8515625,0.443451912286548,0.0105340050127511,1,2,12.9061126708984,4.98244348734986,34.2900007963181,575.712872567944,87.7577137350179,1000,0.00239518141510681,,,,,,,,,,,,,,,,,,,,,2.6509382724762,2.65790271759033,49999.8515625,49999.8515625,50.6800115584092,5.36378562662979,2.84489440917969,24,1,68,0,0,0.270156860351562,31.7693061828613,6,1,1,2.65790271759033,0,2.65442049503326,,,,,,,,,,,,,,,,,,,,,,,,,,,,,,,,,
,3866297655.49851,2.64580452442169,49999.8515625,0.475394540379383,0.00402548869275931,1,2,12.9061126708984,4.98296319952429,34.2799983918667,617.955806159566,89.4448448490423,1000,-0.0010091221830661,,,,,,,,,,,,,,,,,,,,,2.64376831054687,2.64784073829651,49999.8515625,49999.8515625,50.7417602114284,5.36250349098198,2.84271311759949,26,1,0,0,1,0.269699096679687,31.7693061828613,6,1,1,2.64376831054687,0,2.64580452442169,,,,,,,,,,,,,,,,,,,,,,,,,,,,,,,,,
,3866297725.29462,2.11139345169067,49999.8515625,0.481619876638407,0.000272698232548653,1,2,12.9061126708984,4.98300941057658,34.2900007963181,625.824915933661,92.191316754385,1000,0.000188908006268534,,,,,,,,,,,,,,,,,,,,,2.07405138015747,2.14873552322388,49999.8515625,49999.8515625,50.7448867255054,5.36253208798901,2.54191279411316,26,1,0,0,1,0.269088745117187,31.2805480957031,2,1,1,2.07405138015747,0,2.11139345169067,,,,,,,,,,,,,,,,,,,,,,,,,,,,,,,,,
,3866297796.73227,1.99935638904572,49999.8515625,0.482057192937061,3.46585186544954E-5,1,2,12.9061126708984,4.983016262927,34.2799983918667,626.451119718732,91.889004138481,1000,-0.000108114335089615,,,,,,,,,,,,,,,,,,,,,1.99897241592407,1.99974036216736,49999.8515625,49999.8515625,50.7542662677361,5.36243279614214,2.43255257606506,26,1,0,0,1,0.267257690429687,31.7693061828613,1,1,1,1.99974036216736,0,1.99935638904572,,,,,,,,,,,,,,,,,,,,,,,,,,,,,,,,,
,3866298354.48745,33.0174331665039,26.3372249603271,0.000120644311069704,2.39175626697062E-7,1,5,12.9061126708984,4.99243192284699,34.2900007963181,0.157174721813237,0.0232152333837282,1,9.35682934152061E-8,,,,,,,,,,,,,,,,,,,,,33.0174331665039,33.0174331665039,26.3372249603271,26.3372249603271,49.8233467013322,5.35965945505439,5.97195339202881,65,1,0,0,1,0.270233154296875,32.7468223571777,2,1,1,33.0174331665039,0,33.0174331665039,,,,,,,,,,,,,,,,,,,,,,,,,,,,,,,,,
,3866298557.93869,65.0252304077148,26.3372249603271,7.96315931169971E-5,2.37884828670783E-8,1,5,12.9061126708984,4.99266096205684,34.3200005590916,0.103764989048986,0.0152240186507707,1,-1.51708473210743E-8,,,,,,,,,,,,,,,,,,,,,65.0252304077148,65.0252304077148,26.3372249603271,26.3372249603271,49.6810903108322,5.35955576158031,6.48980808258057,64,1,64,0,0,0.269927978515625,31.2805480957031,2,1,1,65.0252304077148,0,65.0252304077148,,,,,,,,,,,,,,,,,,,,,,,,,,,,,,,,,
,3866298755.90712,97.0086822509766,26.3372249603271,6.36906916114335E-5,3.21719970090326E-8,1,5,12.9061126708984,4.99258442733973,34.3800000846386,0.0829944082870693,0.0121543563953365,1,-2.88712531645774E-8,,,,,,,,,,,,,,,,,,,,,97.0086822509766,97.0086822509766,26.3372249603271,26.3372249603271,49.8342895006014,5.36003595696474,6.70073699951172,63,1,64,0,0,0.269317626953125,31.7693061828613,2,1,1,97.0086822509766,0,97.0086822509766,,,,,,,,,,,,,,,,,,,,,,,,,,,,,,,,,
,3866298950.11919,129.009521484375,26.3372249603271,4.96890308410741E-5,2.72533430263743E-8,1,5,12.9061126708984,4.99292971203674,34.4499982893467,0.0647595636752404,0.0094544635875777,1,-4.46389134464923E-8,,,,,,,,,,,,,,,,,,,,,129.009521484375,129.009521484375,26.3372249603271,26.3372249603271,49.7291604647649,5.35891984728403,6.81627130508423,64,1,64,0,0,0.271835327148438,32.2580642700195,2,1,1,129.009521484375,0,129.009521484375,,,,,,,,,,,,,,,,,,,,,,,,,,,,,,,,,
,3866299143.45798,161.000106811523,26.3372249603271,4.0014416363778E-5,2.22258769678551E-8,1,5,12.9061126708984,4.99302409407791,34.5499999821186,0.0521536474632043,0.00760298077898218,1,-4.42889377061644E-8,,,,,,,,,,,,,,,,,,,,,161.000106811523,161.000106811523,26.3372249603271,26.3372249603271,49.9112799097457,5.35898243959794,6.89988660812378,63,1,64,0,0,0.268783569335938,31.7693061828613,2,1,1,161.000106811523,0,161.000106811523,,,,,,,,,,,,,,,,,,,,,,,,,,,,,,,,,
,3866299336.36231,193.075439453125,26.3372249603271,3.18588544495317E-5,1.62407802559457E-8,1,5,12.9061126708984,4.99319434416752,34.6699990332127,0.0415267670244559,0.00604780858651094,1,-3.97553795066344E-8,,,,,,,,,,,,,,,,,,,,,193.075439453125,193.075439453125,26.3372249603271,26.3372249603271,49.8585199846976,5.3597135169224,6.97646284103394,64,1,64,0,0,0.270462036132813,31.2805480957031,2,1,1,193.075439453125,0,193.075439453125,,,,,,,,,,,,,,,,,,,,,,,,,,,,,,,,,
,3866299528.51862,225.015350341797,26.3372249603271,2.53925676926956E-5,1.16642139558441E-8,1,5,12.9061126708984,4.99367141717421,34.8200015723705,0.0331040388909428,0.00481150306854897,1,-3.89348315254548E-8,,,,,,,,,,,,,,,,,,,,,225.015350341797,225.015350341797,26.3372249603271,26.3372249603271,49.8045876168706,5.35731859445157,7.09510946273804,64,1,64,0,0,0.27008056640625,31.7693061828613,2,1,1,225.015350341797,0,225.015350341797,,,,,,,,,,,,,,,,,,,,,,,,,,,,,,,,,
,3866299722.1431,257.056182861328,26.3372249603271,2.02052198839165E-5,7.13037113658205E-9,1,5,12.9061126708984,4.99362299441465,34.9799990653992,0.0263424194722214,0.0038187756608555,1,-3.84633119542307E-8,,,,,,,,,,,,,,,,,,,,,257.056182861328,257.056182861328,26.3372249603271,26.3372249603271,49.8624281272937,5.35836703308382,7.33343887329102,64,1,64,0,0,0.268936157226562,31.7693061828613,2,1,1,257.056182861328,0,257.056182861328,,,,,,,,,,,,,,,,,,,,,,,,,,,,,,,,,
,3866299914.09822,289.011474609375,26.3372249603271,1.58844555134946E-5,1.08689266214669E-8,1,5,12.9061126708984,4.99318173389525,35.1600013673306,0.0207071742221005,0.00299845581234872,1,-3.27900622923802E-8,,,,,,,,,,,,,,,,,,,,,289.011474609375,289.011474609375,26.3372249603271,26.3372249603271,49.8354619433803,5.36022135684904,7.22927474975586,64,1,64,0,0,0.267715454101562,31.7693061828613,2,1,1,289.011474609375,0,289.011474609375,,,,,,,,,,,,,,,,,,,,,,,,,,,,,,,,,
,3866301544.14619,1.99966835975647,43188.341796875,0.455921706485696,0.000108074846570813,1,2,12.9061126708984,4.98244231572565,34.2799983918667,592.390409203231,86.8983546888597,1000,-9.81554215374539E-5,,,,,,,,,,,,,,,,,,,,,1.99951124191284,1.9998254776001,43113.59765625,43263.0859375,50.5885610216592,5.36522573360243,2.49841618537903,26,1,0,0,1,0.2691650390625,30.3030319213867,1,6,1,1.99951124191284,0,1.99966835975647,,,,,,,,,,,,,,,,,,,,,,,,,,,,,,,,,
,3866301614.50073,2.0000296831131,36164.5078125,0.419964539339886,6.2345609077082E-5,1,2,12.9061126708984,4.98247113970427,34.2799983918667,545.712886203451,79.786377190382,1000,-0.000289920695926676,,,,,,,,,,,,,,,,,,,,,1.99974513053894,2.00031423568726,36064.53515625,36264.48046875,50.4037058768611,5.3640635018466,2.50455355644226,26,1,0,0,1,0.270309448242187,31.2805480957031,1,6,1,2.00031423568726,0,2.0000296831131,,,,,,,,,,,,,,,,,,,,,,,,,,,,,,,,,
,3866301686.98992,2.00014078617096,28926.2978515625,0.376772851617071,7.53067469413115E-5,1,2,12.9061126708984,4.98250845396727,34.2900007963181,489.600670931062,71.5335080745033,1000,-0.000296976935647914,,,,,,,,,,,,,,,,,,,,,1.99997329711914,2.00030827522278,28836.3046875,29016.291015625,50.2079079327938,5.36282637541112,2.49454379081726,26,1,0,0,1,0.269393920898438,31.2805480957031,1,6,1,1.99997329711914,0,2.00014078617096,,,,,,,,,,,,,,,,,,,,,,,,,,,,,,,,,
,3866301757.49211,1.99996155500412,21887.8779296875,0.326243795515007,8.78966657379938E-5,1,2,12.9061126708984,4.9824171806521,34.2799983918667,423.926099820006,61.9606502817369,1000,-0.000240136073495794,,,,,,,,,,,,,,,,,,,,,1.99986612796783,2.00005698204041,21798.060546875,21977.6953125,49.9847529905534,5.36285124200488,2.49706149101257,26,1,0,0,1,0.268936157226562,31.2805480957031,1,6,1,1.99986612796783,0,1.99996155500412,,,,,,,,,,,,,,,,,,,,,,,,,,,,,,,,,
,3866301826.05441,1.99973225593567,15039.376953125,0.265240952947768,0.000114778979054573,1,2,12.9061126708984,4.98224952032947,34.2799983918667,344.623319564558,50.4982415179576,1000,-9.84728137174721E-5,,,,,,,,,,,,,,,,,,,,,1.99913668632507,2.00032782554626,14939.4375,15139.31640625,49.8557842848803,5.36349247882774,2.4951753616333,26,1,0,0,1,0.270462036132813,30.7917900085449,1,6,1,2.00032782554626,0,1.99973225593567,,,,,,,,,,,,,,,,,,,,,,,,,,,,,,,,,
,3866301895.8511,1.99984627962112,8072.15283203125,0.18156085369182,0.000154390696601008,1,2,12.9061126708984,4.98206974029198,34.2799983918667,235.893957032397,34.5185715558538,1000,-0.00010310097855769,,,,,,,,,,,,,,,,,,,,,1.99981188774109,1.99988067150116,7917.326171875,8226.9794921875,49.839760900236,5.36358779146883,2.49874210357666,26,1,0,0,1,0.269775390625,32.2580642700195,1,6,1,1.99988067150116,0,1.99984627962112,,,,,,,,,,,,,,,,,,,,,,,,,,,,,,,,,
,3866301968.27503,1.99961471557617,831.239685058594,0.0433058510552871,0.000301025072500134,1,2,12.9061126708984,4.98191650560377,34.2799983918667,56.2672750401328,8.20348048000292,1000,-4.73190268853607E-5,,,,,,,,,,,,,,,,,,,,,1.99955940246582,1.99967002868652,661.414123535156,1001.06524658203,49.8335078720822,5.36359076025859,2.50162649154663,26,1,0,0,1,0.271530151367187,30.7917900085449,1,6,1,1.99955940246582,0,1.99961471557617,,,,,,,,,,,,,,,,,,,,,,,,,,,,,,,,,
,3866302081.86212,1.99908113479614,-10525.7890625,-0.208525715903393,0.000155022132152775,1,2,12.9061126708984,4.98190580855835,34.2799983918667,-270.916816883165,-39.6355650316962,1000,0.000124391007538071,,,,,,,,,,,,,,,,,,,,,1.99886608123779,1.99929618835449,-10615.9326171875,-10435.6455078125,49.761598048313,5.36380576660626,2.4758038520813,26,1,0,0,1,0.270309448242187,31.7693061828613,1,6,1,1.99886608123779,0,1.99908113479614,,,,,,,,,,,,,,,,,,,,,,,,,,,,,,,,,
,3866302150.45498,2.0006662607193,-17386.361328125,-0.287044729864874,0.000109095771189356,1,2,12.9061126708984,4.98182792206215,34.2799983918667,-372.924027734159,-54.5355716405245,1000,0.000189174166653628,,,,,,,,,,,,,,,,,,,,,2.0006275177002,2.0007050037384,-17466.255859375,-17306.466796875,49.8678995269284,5.36476636422927,2.46831107139587,26,1,0,0,1,0.271072387695313,31.2805480957031,1,6,1,2.0007050037384,0,2.0006662607193,,,,,,,,,,,,,,,,,,,,,,,,,,,,,,,,,
,3866302218.82836,2.0007883310318,-24221.8486328125,-0.34535999202013,9.53350532885113E-5,1,2,12.9061126708984,4.98160916983696,34.2799983918667,-448.638991868774,-65.7443873763965,1000,0.000124786916934778,,,,,,,,,,,,,,,,,,,,,2.00004816055298,2.00152850151062,-24316.818359375,-24126.87890625,50.086755512313,5.36577829231933,2.44682025909424,26,1,0,0,1,0.270309448242187,31.2805480957031,1,6,1,2.00152850151062,0,2.0007883310318,,,,,,,,,,,,,,,,,,,,,,,,,,,,,,,,,
,3866302289.62386,1.99982625246048,-31312.4169921875,-0.393801305302465,6.73584675393124E-5,1,2,12.9061126708984,4.98182316303502,34.2799983918667,-511.5617550768,-75.2133398228324,1000,-4.46957075618704E-5,,,,,,,,,,,,,,,,,,,,,1.99920451641083,2.00044798851013,-31377.5390625,-31247.294921875,50.4302812465149,5.36559119604488,2.44620490074158,26,1,0,0,1,0.272750854492187,30.7917900085449,1,6,1,2.00044798851013,0,1.99982625246048,,,,,,,,,,,,,,,,,,,,,,,,,,,,,,,,,
,3866302359.89907,2.00013142824173,-38350.115234375,-0.4347952864751,7.71249335830381E-5,1,2,12.9061126708984,4.98211235549831,34.2799983918667,-564.917152537275,-82.663799866268,1000,0.000247676437470928,,,,,,,,,,,,,,,,,,,,,1.99986755847931,2.00039529800415,-38450.26953125,-38249.9609375,50.4822595430438,5.3650530066345,2.43806481361389,26,1,0,0,1,0.269317626953125,31.2805480957031,1,6,1,1.99986755847931,0,2.00013142824173,,,,,,,,,,,,,,,,,,,,,,,,,,,,,,,,,
,3866302430.3416,1.99961030483246,-45407.521484375,-0.470059337378631,5.22529872474454E-5,1,2,12.9061126708984,4.98204268126968,34.2799983918667,-610.688529232518,-89.599266316382,1000,8.85841922926573E-5,,,,,,,,,,,,,,,,,,,,,1.99501347541809,2.00420713424683,-45502.81640625,-45312.2265625,50.6628157309861,5.36549419365616,2.41414475440979,26,1,0,0,1,0.270004272460938,31.7693061828613,5,6,1,1.99501347541809,0,1.99961030483246,,,,,,,,,,,,,,,,,,,,,,,,,,,,,,,,,
,3866302499.14411,1.99956601858139,-48315.01171875,-0.483718661915275,6.13216650413143E-5,1,2,12.9061126708984,4.98219028810945,34.2799983918667,-628.476661044772,-92.0969243326239,1000,0.000175689158178522,,,,,,,,,,,,,,,,,,,,,1.99841773509979,2.00071430206299,-48434.8828125,-48195.140625,50.9371673412362,5.36521255978439,2.39942765235901,26,1,0,0,1,0.272216796875,31.2805480957031,1,6,1,2.00071430206299,0,1.99956601858139,,,,,,,,,,,,,,,,,,,,,,,,,,,,,,,,,
,3866302571.54774,1.99966591596603,-41094.28125,-0.449925980687936,0.000115853632054835,1,2,12.9061126708984,4.9819899735757,34.2799983918667,-584.502151427633,-85.9030392114083,1000,-2.5069941901502E-5,,,,,,,,,,,,,,,,,,,,,1.99890100955963,2.00043082237244,-41199.06640625,-40989.49609375,50.4435689313419,5.36519792233701,2.39286375045776,26,1,0,0,1,0.271224975585938,31.2805480957031,5,6,1,2.00043082237244,0,1.99966591596603,,,,,,,,,,,,,,,,,,,,,,,,,,,,,,,,,
,3866302641.92486,2.00030356645584,-34066.96875,-0.412266663179599,7.99394321294438E-5,1,2,12.9061126708984,4.98222566777993,34.2799983918667,-535.639347506705,-78.5473678629502,1000,0.000108434075312349,,,,,,,,,,,,,,,,,,,,,1.99941575527191,2.00119137763977,-34161.625,-33972.3125,50.2766912424861,5.3650290811679,2.38715267181396,26,1,0,0,1,0.270233154296875,31.7693061828613,1,6,1,2.00119137763977,0,2.00030356645584,,,,,,,,,,,,,,,,,,,,,,,,,,,,,,,,,
,3866302710.7417,2.00070703029633,-27200.080078125,-0.369506041885874,8.77482674647337E-5,1,2,12.9061126708984,4.98194826298304,34.2799983918667,-480.040094491186,-70.4272112913884,1000,7.22876877415282E-5,,,,,,,,,,,,,,,,,,,,,2.0004677772522,2.00094628334045,-27315.013671875,-27085.146484375,50.1813325631399,5.36460610174371,2.38317441940308,26,1,0,0,1,0.270767211914062,32.2580642700195,6,6,1,2.0004677772522,0,2.00070703029633,,,,,,,,,,,,,,,,,,,,,,,,,,,,,,,,,
,3866302780.87988,2.00006937980652,-20197.1181640625,-0.316450427847465,9.61435124994157E-5,1,2,12.9061126708984,4.98197432668001,34.2799983918667,-411.134175975309,-60.1946533730732,1000,0.000154812697206761,,,,,,,,,,,,,,,,,,,,,1.99974465370178,2.00039410591126,-20286.998046875,-20107.23828125,50.1012156399188,5.3639854949404,2.37882518768311,26,1,0,0,1,0.269699096679687,31.7693061828613,1,6,1,1.99974465370178,0,2.00006937980652,,,,,,,,,,,,,,,,,,,,,,,,,,,,,,,,,
,3866302851.38917,1.99967139959335,-13154.9741210938,-0.249240866164688,0.000122922855004736,1,2,12.9061126708984,4.98231450487265,34.2799983918667,-323.837982212473,-47.4707292902992,1000,7.88206669129004E-5,,,,,,,,,,,,,,,,,,,,,1.99868905544281,2.0006537437439,-13249.755859375,-13060.1923828125,49.9085442099284,5.36224195813676,2.37820410728455,26,1,0,0,1,0.270538330078125,31.2805480957031,1,6,1,2.0006537437439,0,1.99967139959335,,,,,,,,,,,,,,,,,,,,,,,,,,,,,,,,,
,3866302922.31995,2.00063228607178,-6065.99194335938,-0.155688695369258,0.00017900390270923,1,2,12.9061126708984,4.98161970905656,34.2799983918667,-202.252863061274,-29.6018624799237,1000,8.38708768656917E-5,,,,,,,,,,,,,,,,,,,,,2.00045394897461,2.00081062316895,-6186.0263671875,-5945.95751953125,49.7440114066303,5.36349088865087,2.38313436508179,26,1,0,0,1,0.2703857421875,31.7693061828613,1,6,1,2.00045394897461,0,2.00063228607178,,,,,,,,,,,,,,,,,,,,,,,,,,,,,,,,,
,3866303010.53452,2.00027269124985,2743.4150390625,0.0642528671564498,0.000276743583715765,1,2,12.9061126708984,4.98231760531878,34.2799983918667,83.4781568789605,12.2750784012915,100,8.45557435470554E-6,,,,,,,,,,,,,,,,,,,,,1.99998676776886,2.00055861473083,2648.56469726562,2838.26538085938,49.8546118421014,5.36221107325905,2.38176584243774,25,1,68,0,0,0.269775390625,31.7693061828613,1,6,1,2.00055861473083,0,2.00027269124985,,,,,,,,,,,,,,,,,,,,,,,,,,,,,,,,,
,3866303103.33513,1.99996191263199,12028.6723632812,0.229802145943592,0.000137150273486032,1,2,12.9061126708984,4.98240330617821,34.2799983918667,298.612036151443,43.6112339226109,1000,-0.000194486817305773,,,,,,,,,,,,,,,,,,,,,1.99978482723236,2.00013899803162,11928.64453125,12128.7001953125,50.0042937035341,5.36250099988287,2.37400031089783,26,1,0,0,1,0.270004272460938,31.7693061828613,1,6,1,1.99978482723236,0,1.99996191263199,,,,,,,,,,,,,,,,,,,,,,,,,,,,,,,,,
,3866303172.0535,1.99960780143738,18900.4189453125,0.302641343298632,0.00010638635830809,1,2,12.9061126708984,4.98235782207373,34.2799983918667,393.240369723964,57.5435411879949,1000,-0.000171609157463704,,,,,,,,,,,,,,,,,,,,,1.9992264509201,1.99998915195465,18840.392578125,18960.4453125,50.041030243938,5.36256145720851,2.36451172828674,26,1,0,0,1,0.269546508789062,31.2805480957031,1,6,1,1.9992264509201,0,1.99960780143738,,,,,,,,,,,,,,,,,,,,,,,,,,,,,,,,,
,3866303242.53297,2.00042772293091,25946.787109375,0.359456863711137,9.66369182750499E-5,1,2,12.9061126708984,4.98207149305259,34.2799983918667,466.995209098264,68.553924030581,1000,-3.97733545185638E-5,,,,,,,,,,,,,,,,,,,,,1.99916815757751,2.0016872882843,25831.640625,26061.93359375,50.2759096139669,5.36421311488798,2.36093807220459,26,1,0,0,1,0.27130126953125,31.2805480957031,1,6,1,2.0016872882843,0,2.00042772293091,,,,,,,,,,,,,,,,,,,,,,,,,,,,,,,,,
,3866303314.83781,1.99957019090652,33191.578125,0.406985170976529,0.000102237918705297,1,2,12.9061126708984,4.98213050148926,34.2799983918667,528.746611244087,77.6515993456962,1000,-2.03951580365946E-5,,,,,,,,,,,,,,,,,,,,,1.9991626739502,1.99997770786285,33086.41015625,33296.74609375,50.3087380117746,5.36475319538832,2.34929609298706,26,1,0,0,1,0.269622802734375,31.7693061828613,1,6,1,1.9991626739502,0,1.99957019090652,,,,,,,,,,,,,,,,,,,,,,,,,,,,,,,,,
,3866303383.53674,1.99993145465851,40080.669921875,0.443692780282085,0.000305035034193243,1,2,12.9061126708984,4.98211807549591,34.2799983918667,576.351635286859,85.2180209299063,1000,0.000411129938806852,,,,,,,,,,,,,,,,,,,,,1.99942183494568,2.00044107437134,40020.5859375,40140.75390625,50.3986252914861,5.36516696983629,2.34894227981567,26,1,0,0,1,0.270156860351562,31.7693061828613,1,6,1,1.99942183494568,0,1.99993145465851,,,,,,,,,,,,,,,,,,,,,,,,,,,,,,,,,
,3866303451.73973,2.00058394670486,46909.357421875,0.463863401536596,0.00707547096353232,1,2,12.9061126708984,4.98237928600533,34.2799983918667,602.490488918699,89.8266072413209,1000,0.000990095396045019,,,,,,,,,,,,,,,,,,,,,1.99968039989471,2.00148749351501,46814.1640625,47004.55078125,50.6108374344573,5.36466249661992,2.34908890724182,25,1,68,0,0,0.269851684570313,32.2580642700195,1,6,1,2.00148749351501,0,2.00058394670486,,,,,,,,,,,,,,,,,,,,,,,,,,,,,,,,,
,3866303937.61839,17.2890739440918,26.550329208374,0.000640795573087472,2.36604418386966E-6,1,5,12.9061126708984,5.00268070615337,34.2799983918667,0.837268435442876,0.123381593110239,10,2.82936376474756E-7,,,,,,,,,,,,,,,,,,,,,17.0653858184814,17.5127620697021,26.550329208374,26.550329208374,49.7987254029764,5.36055318537413,5.33472108840942,65,1,0,0,1,0.276260375976562,31.7693061828613,2,1,1,17.5127620697021,0,17.2890739440918,,,,,,,,,,,,,,,,,,,,,,,,,,,,,,,,,
,3866304138.69199,49.0602264404297,26.550329208374,0.000100378728499934,1.04600381339134E-7,1,5,12.9061126708984,5.00290845913587,34.2999994754791,0.131175487130515,0.0192502605195888,1,-1.56220842113532E-8,,,,,,,,,,,,,,,,,,,,,49.0602264404297,49.0602264404297,26.550329208374,26.550329208374,49.7283788362456,5.35941575970427,6.27089786529541,65,1,0,0,1,0.271987915039062,31.2805480957031,2,1,1,49.0602264404297,0,49.0602264404297,,,,,,,,,,,,,,,,,,,,,,,,,,,,,,,,,
,3866304339.64829,81.012580871582,26.550329208374,7.94764855349958E-5,3.90750673206014E-8,1,5,12.9061126708984,5.0027825604416,34.3500003218651,0.10386979917348,0.0151517303248378,1,-8.08136273821824E-8,,,,,,,,,,,,,,,,,,,,,81.012580871582,81.012580871582,26.550329208374,26.550329208374,49.6658485547072,5.36065079006026,6.59606456756592,65,1,0,0,1,0.2734375,32.2580642700195,2,1,1,81.012580871582,0,81.012580871582,,,,,,,,,,,,,,,,,,,,,,,,,,,,,,,,,
,3866304534.90623,113.064994812012,26.550329208374,6.41913329522844E-5,1.80617275745472E-8,1,5,12.9061126708984,5.00270005108074,34.4099998474121,0.0838916469387388,0.012235166101622,1,-6.69978931830727E-8,,,,,,,,,,,,,,,,,,,,,113.064994812012,113.064994812012,26.550329208374,26.550329208374,49.7154819656783,5.36121907375843,6.74511194229126,65,1,0,0,1,0.273895263671875,32.2580642700195,2,1,1,113.064994812012,0,113.064994812012,,,,,,,,,,,,,,,,,,,,,,,,,,,,,,,,,
,3866304728.76528,145.098999023438,26.550329208374,5.05353201490638E-5,2.32260760072603E-8,1,5,12.9061126708984,5.00256057898131,34.510001540184,0.066047309693566,0.00959593532967812,1,-8.02620764561968E-8,,,,,,,,,,,,,,,,,,,,,145.098999023438,145.098999023438,26.550329208374,26.550329208374,49.8678995269284,5.36307664408338,6.84077405929565,65,1,0,0,1,0.276336669921875,32.2580642700195,2,1,1,145.098999023438,0,145.098999023438,,,,,,,,,,,,,,,,,,,,,,,,,,,,,,,,,
,3866304920.75952,177.001251220703,26.550329208374,4.12040755196322E-5,1.83672490691114E-8,1,5,12.9061126708984,5.00304502544908,34.6199981868267,0.0538555480659385,0.00784935853673973,1,-4.68987698156144E-8,,,,,,,,,,,,,,,,,,,,,177.001251220703,177.001251220703,26.550329208374,26.550329208374,49.7799663185149,5.36117809434304,6.91080045700073,63,1,64,0,0,0.272293090820313,31.7693061828613,2,1,1,177.001251220703,0,177.001251220703,,,,,,,,,,,,,,,,,,,,,,,,,,,,,,,,,
,3866305114.35677,209.029037475586,26.550329208374,3.35645868362533E-5,2.40958845753812E-8,1,5,12.9061126708984,5.00318131806154,34.7400009632111,0.0438737801549935,0.00638265316410059,1,-4.71024722045496E-8,,,,,,,,,,,,,,,,,,,,,209.029037475586,209.029037475586,26.550329208374,26.550329208374,49.8839229115726,5.36091952886814,7.00186586380005,63,1,64,0,0,0.2716064453125,31.2805480957031,2,1,1,209.029037475586,0,209.029037475586,,,,,,,,,,,,,,,,,,,,,,,,,,,,,,,,,
,3866305307.47707,241.14338684082,26.550329208374,2.72325369577756E-5,1.82039233148302E-8,1,5,12.9061126708984,5.00320725920166,34.9100008606911,0.0355924733706691,0.00521029310921868,1,-1.39548775293104E-8,,,,,,,,,,,,,,,,,,,,,241.12467956543,241.162094116211,26.550329208374,26.550329208374,49.8467955569091,5.36221482211769,7.18306350708008,63,1,64,0,0,0.271987915039062,31.2805480957031,2,1,1,241.162094116211,0,241.14338684082,,,,,,,,,,,,,,,,,,,,,,,,,,,,,,,,,
,3866305500.795,273.108947753906,26.550329208374,2.17982654422889E-5,1.56453494868621E-8,1,5,12.9061126708984,5.00296932752892,35.0699983537197,0.0284892635630263,0.00416220247101702,1,-1.73650315720545E-8,,,,,,,,,,,,,,,,,,,,,273.108947753906,273.108947753906,26.550329208374,26.550329208374,49.8272548439284,5.36263581908078,7.37943172454834,63,1,64,0,0,0.272064208984375,31.2805480957031,2,1,1,273.108947753906,0,273.108947753906,,,,,,,,,,,,,,,,,,,,,,,,,,,,,,,,,
,3866306296.3402,296.972045898438,26.4124393463135,2.7897762159421E-5,7.3580255270343E-9,1,5,12.9061126708984,4.99286008307178,35.1999998092651,0.0363590782980049,0.00530317381363232,1,-2.88253429198343E-8,,,,,,,,,,,,,,,,,,,,,296.972045898438,296.972045898438,26.4124393463135,26.4124393463135,49.768632704986,5.36405078615252,7.89889717102051,64,1,64,0,0,0.271072387695313,31.2805480957031,2,1,1,296.972045898438,0,296.972045898438,,,,,,,,,,,,,,,,,,,,,,,,,,,,,,,,,
,3866306479.32863,264.849609375,26.4124393463135,3.19146269493607E-5,7.7739043897651E-9,1,5,12.9061126708984,4.99277177384348,35.0299999117851,0.0415979031821864,0.00603469357973782,1,-5.74628075178654E-8,,,,,,,,,,,,,,,,,,,,,264.849609375,264.849609375,26.4124393463135,26.4124393463135,49.8432782285726,5.36677859315147,7.64183473587036,65,1,0,0,1,0.270004272460938,31.7693061828613,2,1,1,264.849609375,0,264.849609375,,,,,,,,,,,,,,,,,,,,,,,,,,,,,,,,,
,3866306673.13673,232.985336303711,26.4124393463135,3.56839474811E-5,8.57004534755875E-9,1,5,12.9061126708984,4.99238083297857,34.9100008606911,0.0465062091567122,0.00674371309258469,1,-6.65329687576552E-8,,,,,,,,,,,,,,,,,,,,,232.985336303711,232.985336303711,26.4124393463135,26.4124393463135,49.809277387986,5.36395367128199,7.5038914680481,63,1,64,0,0,0.270309448242187,31.7693061828613,2,1,1,232.985336303711,0,232.985336303711,,,,,,,,,,,,,,,,,,,,,,,,,,,,,,,,,
,3866306863.04405,200.993392944336,26.4124393463135,3.94829552416788E-5,7.52149280414578E-9,1,5,12.9061126708984,4.99255338321834,34.790001809597,0.0514587420859381,0.0074697625456209,1,-6.76805684321754E-8,,,,,,,,,,,,,,,,,,,,,200.993392944336,200.993392944336,26.4124393463135,26.4124393463135,49.8182661159572,5.36315043083483,7.41890287399292,65,1,0,0,1,0.269622802734375,31.7693061828613,2,1,1,200.993392944336,0,200.993392944336,,,,,,,,,,,,,,,,,,,,,,,,,,,,,,,,,
,3866307055.24783,168.86589050293,26.4124393463135,4.33197995850109E-5,7.00163943026982E-9,1,5,12.9061126708984,4.99234977896198,34.6900001168251,0.0564564059756226,0.00819331016674787,1,-7.56962148534479E-8,,,,,,,,,,,,,,,,,,,,,168.86589050293,168.86589050293,26.4124393463135,26.4124393463135,49.7662878194283,5.36355324733478,7.32902050018311,63,1,64,0,0,0.27130126953125,31.7693061828613,2,1,1,168.86589050293,0,168.86589050293,,,,,,,,,,,,,,,,,,,,,,,,,,,,,,,,,
,3866307248.68524,136.822708129883,26.4124393463135,4.72248096425187E-5,7.55123062125952E-9,1,5,12.9061126708984,4.99235675337789,34.5899984240532,0.0615460837519308,0.00892942662401973,1,-8.44208126822386E-8,,,,,,,,,,,,,,,,,,,,,136.822708129883,136.822708129883,26.4124393463135,26.4124393463135,49.9226135232745,5.36405451005456,7.24150848388672,64,1,64,0,0,0.2703857421875,32.2580642700195,2,1,1,136.822708129883,0,136.822708129883,,,,,,,,,,,,,,,,,,,,,,,,,,,,,,,,,
,3866307439.79833,104.809944152832,26.4124393463135,5.07971781229058E-5,9.67012780879799E-9,1,5,12.9061126708984,4.99200231724334,34.4800017774105,0.0661940211913454,0.00961201426361981,1,-8.46135123295664E-8,,,,,,,,,,,,,,,,,,,,,104.809944152832,104.809944152832,26.4124393463135,26.4124393463135,49.766678633688,5.36370022744456,7.15316152572632,63,1,64,0,0,0.271377563476562,31.2805480957031,2,1,1,104.809944152832,0,104.809944152832,,,,,,,,,,,,,,,,,,,,,,,,,,,,,,,,,
,3866307629.18895,72.8657531738281,26.4124393463135,5.42804163800602E-5,8.82504231253199E-9,1,5,12.9061126708984,4.99209770996057,34.400001168251,0.0707355597764734,0.0102671811788809,1,-9.36536134357437E-8,,,,,,,,,,,,,,,,,,,,,72.8657531738281,72.8657531738281,26.4124393463135,26.4124393463135,49.8768882548995,5.36453018402464,7.00343465805054,65,1,0,0,1,0.269851684570313,32.2580642700195,2,1,1,72.8657531738281,0,72.8657531738281,,,,,,,,,,,,,,,,,,,,,,,,,,,,,,,,,
,3866307817.16399,40.9655990600586,26.4124393463135,5.66510836178442E-5,1.22073666418106E-8,1,5,12.9061126708984,4.9921287023707,34.340001642704,0.0738217745035302,0.0107413140380102,1,-7.807437108661E-8,,,,,,,,,,,,,,,,,,,,,40.9655990600586,40.9655990600586,26.4124393463135,26.4124393463135,49.8678995269284,5.36322529491551,6.70724630355835,65,1,0,0,1,0.270233154296875,31.7693061828613,2,1,1,40.9655990600586,0,40.9655990600586,,,,,,,,,,,,,,,,,,,,,,,,,,,,,,,,,
,3866308015.76721,8.94685935974121,26.4124393463135,4.5806124184427E-5,7.8452788015408E-9,1,5,12.9061126708984,4.99097840348086,34.2999994754791,0.0596827734570557,0.00859844508857871,1,-1.27474921464373E-7,,,,,,,,,,,,,,,,,,,,,8.94685935974121,8.94685935974121,26.4124393463135,26.4124393463135,49.7713684048033,5.36686734665508,4.96411323547363,65,1,0,0,1,0.2764892578125,32.2580642700195,6,1,1,8.92848300933838,0,8.94685935974121,,,,,,,,,,,,,,,,,,,,,,,,,,,,,,,,,
,3866308680.81678,25.0067806243896,26.4124393463135,3.90827724252741E-5,3.33330127147838E-8,1,5,12.9061126708984,4.98985166080088,34.2900007963181,0.050882744179127,0.00749574155270621,1,1.54192814204511E-8,,,,,,,,,,,,,,,,,,,,,25.0067806243896,25.0067806243896,26.4124393463135,26.4124393463135,49.756517462938,5.36940778918207,5.76703691482544,65,1,0,0,1,0.275726318359375,31.2805480957031,2,1,1,25.0067806243896,0,25.0067806243896,,,,,,,,,,,,,,,,,,,,,,,,,,,,,,,,,
,3866308884.94117,57.0108871459961,26.4124393463135,4.128259624733E-5,6.96397054412578E-8,1,5,12.9061126708984,4.99089635120768,34.3099981546402,0.0537550320799693,0.00797104812949169,1,5.55022705190427E-8,,,,,,,,,,,,,,,,,,,,,57.0108871459961,57.0108871459961,26.4124393463135,26.4124393463135,49.8636005700726,5.36690704228669,6.43010759353638,65,1,0,0,1,0.273513793945313,31.7693061828613,2,1,1,57.0108871459961,0,57.0108871459961,,,,,,,,,,,,,,,,,,,,,,,,,,,,,,,,,
,3866309084.92209,89.0979309082031,26.4124393463135,3.81128980930871E-5,4.12597119219103E-8,1,5,12.9061126708984,4.99014140506749,34.3599990010262,0.0496198726880734,0.00733900529178998,1,3.70638191255656E-8,,,,,,,,,,,,,,,,,,,,,89.0979309082031,89.0979309082031,26.4124393463135,26.4124393463135,49.7854377181495,5.37051765077404,6.68677520751953,64,1,64,0,0,0.276031494140625,31.7693061828613,2,1,1,89.0979309082031,0,89.0979309082031,,,,,,,,,,,,,,,,,,,,,,,,,,,,,,,,,
,3866309278.91519,121.022270202637,26.4124393463135,3.52187568042098E-5,8.2621489239266E-9,1,5,12.9061126708984,4.99045546281662,34.4300009310246,0.0458665877807601,0.0067101527828505,1,-2.11612168467562E-8,,,,,,,,,,,,,,,,,,,,,121.022270202637,121.022270202637,26.4124393463135,26.4124393463135,49.7791846899956,5.36933222065306,6.81639385223389,63,1,64,0,0,0.276565551757813,31.2805480957031,2,1,1,121.022270202637,0,121.022270202637,,,,,,,,,,,,,,,,,,,,,,,,,,,,,,,,,
,3866309472.14361,153.002426147461,26.4124393463135,3.35119564764816E-5,2.97780858306137E-8,1,5,12.9061126708984,4.99152940940754,34.5299988985062,0.0436563306425995,0.00639104909533745,1,-1.69411209473512E-8,,,,,,,,,,,,,,,,,,,,,153.002426147461,153.002426147461,26.4124393463135,26.4124393463135,49.6408364420918,5.36572479212711,6.8996410369873,64,1,64,0,0,0.273208618164062,31.2805480957031,2,1,1,153.002426147461,0,153.002426147461,,,,,,,,,,,,,,,,,,,,,,,,,,,,,,,,,
,3866309665.74159,185.138748168945,26.4124393463135,2.92483784136704E-5,2.56948934802646E-8,1,5,12.9061126708984,4.99165230761157,34.6399992704391,0.0381097702911779,0.00553508035733381,1,-4.78385897224889E-8,,,,,,,,,,,,,,,,,,,,,185.116333007813,185.161163330078,26.4124393463135,26.4124393463135,49.8757158121207,5.36576031003695,6.97029733657837,64,1,64,0,0,0.271453857421875,31.2805480957031,2,1,1,185.161163330078,0,185.138748168945,,,,,,,,,,,,,,,,,,,,,,,,,,,,,,,,,
,3866309857.91638,217.024871826172,26.4124393463135,2.68221468241624E-5,1.7504388929731E-8,1,5,12.9061126708984,4.99180631264979,34.7799994051456,0.0349427026726491,0.00512565249008101,1,-5.87093971321902E-9,,,,,,,,,,,,,,,,,,,,,217.024871826172,217.024871826172,26.4124393463135,26.4124393463135,49.8096682022457,5.3642124233324,7.06793451309204,64,1,64,0,0,0.272293090820313,31.7693061828613,2,1,1,217.024871826172,0,217.024871826172,,,,,,,,,,,,,,,,,,,,,,,,,,,,,,,,,
,3866310050.60501,249.018615722656,26.4124393463135,2.37544600453466E-5,1.30837949451528E-8,1,5,12.9061126708984,4.99207633536815,34.9400006234646,0.0309542686174211,0.00450121602415484,1,-3.47914698772938E-8,,,,,,,,,,,,,,,,,,,,,249.018615722656,249.018615722656,26.4124393463135,26.4124393463135,49.8858769828707,5.3648445565191,7.24377298355103,64,1,64,0,0,0.27099609375,31.7693061828613,2,1,1,249.018615722656,0,249.018615722656,,,,,,,,,,,,,,,,,,,,,,,,,,,,,,,,,
,3866310244.11694,281.194946289062,26.4124393463135,2.06696586190452E-5,7.69831031914392E-9,1,5,12.9061126708984,4.99230040733647,35.1199992001057,0.0269332796949754,0.00393667879829658,1,-1.51124996903165E-8,,,,,,,,,,,,,,,,,,,,,281.194946289062,281.194946289062,26.4124393463135,26.4124393463135,49.814357973361,5.36577247168727,7.26732587814331,64,1,64,0,0,0.270233154296875,31.7693061828613,2,1,1,281.194946289062,0,281.194946289062,,,,,,,,,,,,,,,,,,,,,,,,,,,,,,,,,
,3866310579.50211,300.005920410156,45802.892578125,0.0253730903232859,6.59316233393358E-6,1,2,12.9061126708984,4.9924812833794,35.2200008928776,33.0616981235528,4.8463113673116,100,-8.1243477822014E-6,,,,,,,,,,,,,,,,,,,,,300.005889892578,300.005950927734,45708.05859375,45897.7265625,49.7029759093706,5.36346995430877,7.28774118423462,24,1,68,0,0,0.271377563476562,31.7693061828613,1,6,1,300.005889892578,0,300.005920410156,,,,,,,,,,,,,,,,,,,,,,,,,,,,,,,,,
,3866310648.30302,300.005432128906,38929.591796875,0.0216135094808655,6.53495608996768E-6,1,2,12.9061126708984,4.99257977061187,35.2200008928776,28.1623087952355,4.13753811446016,100,1.40123273097023E-7,,,,,,,,,,,,,,,,,,,,,300.005249023438,300.005615234375,38809.6875,39049.49609375,49.7772306186976,5.36327315096978,7.33651351928711,24,1,68,0,0,0.269393920898438,31.2805480957031,1,6,1,300.005584716797,0,300.005432128906,,,,,,,,,,,,,,,,,,,,,,,,,,,,,,,,,
,3866310718.49136,300.002288818359,31925.443359375,0.0177386673026265,6.3792248033313E-6,1,2,12.9061126708984,4.99250198091815,35.2200008928776,23.1113782552381,3.4060575622293,100,8.07081494762503E-6,,,,,,,,,,,,,,,,,,,,,300.002166748047,300.002410888672,31830.625,32020.26171875,49.6861708962072,5.36324840839182,7.42697143554687,26,1,0,0,1,0.272140502929687,32.7468223571777,1,6,1,300.002166748047,0,300.002288818359,,,,,,,,,,,,,,,,,,,,,,,,,,,,,,,,,
,3866310782.97599,300.001510620117,25486.3046875,0.0142063426691812,5.9954232542746E-6,1,2,12.9061126708984,4.99251183587957,35.2200008928776,18.5087787176867,2.73088223941897,100,8.81976805025674E-6,,,,,,,,,,,,,,,,,,,,,300.001434326172,300.001586914063,25391.50390625,25581.10546875,49.7627704910918,5.36380907390571,7.54125308990478,26,1,0,0,1,0.270538330078125,31.7693061828613,1,6,1,300.001586914063,0,300.001510620117,,,,,,,,,,,,,,,,,,,,,,,,,,,,,,,,,
,3866310852.77377,300.002288818359,18517.9716796875,0.0103286370382973,5.59366578004951E-6,1,2,12.9061126708984,4.99254967030768,35.2200008928776,13.4570995433842,1.98373055025895,100,5.05987956277139E-6,,,,,,,,,,,,,,,,,,,,,300.002166748047,300.002410888672,18353.310546875,18682.6328125,49.8596924274764,5.36392598405305,7.69572687149048,26,1,0,0,1,0.269393920898438,31.2805480957031,1,6,1,300.002410888672,0,300.002288818359,,,,,,,,,,,,,,,,,,,,,,,,,,,,,,,,,
,3866310922.19662,300.000823974609,11588.466796875,0.00654997501963702,5.84644297996538E-6,1,2,12.9061126708984,4.99248503660405,35.2200008928776,8.53457010093149,1.25242983401469,100,-1.04575220068558E-6,,,,,,,,,,,,,,,,,,,,,300.000671386719,300.0009765625,11473.6279296875,11703.3056640625,49.8847045400918,5.36463115696465,7.85542583465576,24,1,68,0,0,0.27099609375,31.2805480957031,1,6,1,300.000671386719,0,300.000823974609,,,,,,,,,,,,,,,,,,,,,,,,,,,,,,,,,
,3866310996.64789,300.000473022461,4143.90734863281,0.00243292219828662,5.73114006263836E-6,1,2,12.9061126708984,4.9924029864608,35.2200008928776,3.17205283343814,0.451265757313855,100,-1.10766006635964E-5,,,,,,,,,,,,,,,,,,,,,300.000366210937,300.000579833984,4068.80688476562,4219.0078125,49.926130851611,5.36549047382189,7.879319190979,26,1,0,0,1,0.269927978515625,31.7693061828613,1,6,1,300.000366210937,0,300.000473022461,,,,,,,,,,,,,,,,,,,,,,,,,,,,,,,,,
,3866311077.15718,300.000717163086,-3902.62915039063,-0.00229510555609599,6.24133301458513E-6,1,2,12.9061126708984,4.99254012792829,35.2200008928776,-2.98859527480558,-0.452177849661151,100,-9.85683218657037E-6,,,,,,,,,,,,,,,,,,,,,300.000549316406,300.000885009766,-3997.52978515625,-3807.728515625,49.8647730128514,5.36422310896531,7.81279420852661,26,1,0,0,1,0.271530151367187,31.2805480957031,1,6,1,300.000885009766,0,300.000717163086,,,,,,,,,,,,,,,,,,,,,,,,,,,,,,,,,
,3866311149.60747,300.000259399414,-11147.4467773438,-0.00630553795691585,6.08515101859623E-6,1,2,12.9061126708984,4.99251018460913,35.2200008928776,-8.21330960729748,-1.2248864618586,10,-1.37190458413666E-5,,,,,,,,,,,,,,,,,,,,,300.000152587891,300.000366210937,-11237.408203125,-11057.4853515625,49.8972105963995,5.36489502227881,7.77819490432739,26,1,0,0,1,0.270309448242187,31.7693061828613,1,6,1,300.000152587891,0,300.000259399414,,,,,,,,,,,,,,,,,,,,,,,,,,,,,,,,,
,3866311272.65033,300.000503540039,-23452.7607421875,-0.0131092140366778,6.59579539256661E-6,1,2,12.9061126708984,4.99243819621981,35.2200008928776,-17.0771075713788,-2.53300018093345,100,-1.81704332667111E-5,,,,,,,,,,,,,,,,,,,,,300.000335693359,300.000671386719,-23527.91796875,-23377.603515625,49.819438558736,5.36405744060696,7.72933101654053,26,1,0,0,1,0.270462036132813,32.2580642700195,1,6,1,300.000335693359,0,300.000503540039,,,,,,,,,,,,,,,,,,,,,,,,,,,,,,,,,
,3866311343.01302,299.998580932617,-30496.55859375,-0.0170087831300046,6.5251179950244E-6,1,2,12.9061126708984,4.99242051303497,35.2200008928776,-22.157509606861,-3.28223290060605,100,-2.0323710568171E-5,,,,,,,,,,,,,,,,,,,,,299.998107910156,299.999053955078,-30586.658203125,-30406.458984375,49.7987254029764,5.36453030223158,7.72189140319824,26,1,0,0,1,0.2703857421875,31.7693061828613,1,6,1,299.999053955078,0,299.998580932617,,,,,,,,,,,,,,,,,,,,,,,,,,,,,,,,,
,3866311413.51084,300.000595092773,-37559.720703125,-0.0209126357366968,6.74693343327468E-6,1,2,12.9061126708984,4.99242997225514,35.2200008928776,-27.2432112289355,-4.03529582019246,100,-2.4769465692228E-5,,,,,,,,,,,,,,,,,,,,,300.000091552734,300.001098632812,-37649.83203125,-37469.609375,49.768632704986,5.36404740841273,7.70830488204956,26,1,0,0,1,0.269546508789062,32.2580642700195,1,6,1,300.000091552734,0,300.000595092773,,,,,,,,,,,,,,,,,,,,,,,,,,,,,,,,,
,3866311484.24123,300.000396728516,-44647.482421875,-0.0248122565618166,6.65732912213193E-6,1,2,12.9061126708984,4.99244586797659,35.2200008928776,-32.3236520311184,-4.78642139102461,100,-2.83403012398353E-5,,,,,,,,,,,,,,,,,,,,,300.000213623047,300.000579833984,-44722.6015625,-44572.36328125,49.8069325024283,5.36417559290579,7.68647384643555,26,1,0,0,1,0.270309448242187,31.2805480957031,1,6,1,300.000579833984,0,300.000396728516,,,,,,,,,,,,,,,,,,,,,,,,,,,,,,,,,
,3866311567.93408,300.001068115234,-47476.435546875,-0.0263618163944347,6.23772402374929E-6,1,2,12.9061126708984,4.9924601896148,35.2200008928776,-34.3500155626522,-5.03384326310208,100,9.42863963969952E-6,,,,,,,,,,,,,,,,,,,,,300.000946044922,300.001190185547,-47646.09765625,-47306.7734375,49.7389308212553,5.36440406593536,7.68048906326294,26,1,0,0,1,0.270156860351562,31.7693061828613,1,6,1,300.000946044922,0,300.001068115234,,,,,,,,,,,,,,,,,,,,,,,,,,,,,,,,,
,3866311637.23525,300.000045776367,-40555.41015625,-0.0225796846551333,6.21095737972209E-6,1,2,12.9061126708984,4.99233648526004,35.2200008928776,-29.4194996837314,-4.32029577829895,100,1.3154683574311E-6,,,,,,,,,,,,,,,,,,,,,300,300.000091552734,-40660.1640625,-40450.65625,49.8358527576399,5.36508944591295,7.675856590271,25,1,68,0,0,0.270462036132813,31.7693061828613,1,6,1,300.000091552734,0,300.000045776367,,,,,,,,,,,,,,,,,,,,,,,,,,,,,,,,,
,3866311707.64507,299.999816894531,-33528.291015625,-0.0186865548981558,6.07251071028233E-6,1,2,12.9061126708984,4.99240284899802,35.2200008928776,-24.3462808811173,-3.58390985493637,100,-5.39013418478239E-6,,,,,,,,,,,,,,,,,,,,,299.999114990234,300.000518798828,-33623.22265625,-33433.359375,49.8893943112072,5.36488840656285,7.66678762435913,24,1,68,0,0,0.271148681640625,31.2805480957031,1,6,1,300.000518798828,0,299.999816894531,,,,,,,,,,,,,,,,,,,,,,,,,,,,,,,,,
,3866311779.50633,300.000381469727,-26357.0947265625,-0.0146895546266312,6.39800733114817E-6,1,2,12.9061126708984,4.99241167249779,35.2200008928776,-19.1379488964508,-2.82263868187639,100,-8.31248897389559E-6,,,,,,,,,,,,,,,,,,,,,300.000183105469,300.000579833984,-26516.759765625,-26197.4296875,49.9515337784861,5.36526434154715,7.6534686088562,26,1,0,0,1,0.271072387695313,31.7693061828613,1,6,1,300.000183105469,0,300.000381469727,,,,,,,,,,,,,,,,,,,,,,,,,,,,,,,,,
,3866311850.84075,300.000411987305,-19234.015625,-0.0108025022531918,6.26051408888018E-6,1,2,12.9061126708984,4.99244124418579,35.2200008928776,-14.0742173766385,-2.07364836004204,100,-4.50141546223269E-6,,,,,,,,,,,,,,,,,,,,,300.000335693359,300.00048828125,-19308.74609375,-19159.28515625,49.8819688402745,5.36536644562894,7.65468120574951,26,1,0,0,1,0.270156860351562,31.2805480957031,1,6,1,300.00048828125,0,300.000411987305,,,,,,,,,,,,,,,,,,,,,,,,,,,,,,,,,
,3866311919.17109,300.000030517578,-12411.1069335938,-0.00701455815562284,6.1199092209547E-6,1,2,12.9061126708984,4.99237452351644,35.2200008928776,-9.13976594346708,-1.34032894985714,100,1.80517552340346E-6,,,,,,,,,,,,,,,,,,,,,299.999908447266,300.000152587891,-12501.1689453125,-12321.044921875,50.0570536285822,5.36605054344333,7.64713430404663,26,1,0,0,1,0.272598266601562,31.2805480957031,1,6,1,300.000152587891,0,300.000030517578,,,,,,,,,,,,,,,,,,,,,,,,,,,,,,,,,
,3866311988.10315,299.998687744141,-5526.55541992188,-0.00322358279903252,5.95835589606803E-6,1,2,12.9061126708984,4.99234161744351,35.2200008928776,-4.20156278757788,-0.606647854224548,100,7.96956720781412E-6,,,,,,,,,,,,,,,,,,,,,299.998352050781,299.9990234375,-5646.49560546875,-5406.615234375,49.8288181009668,5.36577511389544,7.64315938949585,26,1,0,0,1,0.27130126953125,30.7917900085449,1,6,1,299.998352050781,0,299.998687744141,,,,,,,,,,,,,,,,,,,,,,,,,,,,,,,,,
,3866312058.19139,300.001342773438,1483.86639404297,0.000939089990688072,6.13049529898071E-6,1,2,12.9061126708984,4.99234545710287,35.2200008928776,1.22108718827272,0.196522325596854,100,1.28706517106757E-5,,,,,,,,,,,,,,,,,,,,,300.001312255859,300.001373291016,1388.95336914062,1578.77941894531,49.7995070314957,5.3664783210253,7.63919544219971,26,1,0,0,1,0.272445678710938,31.7693061828613,1,6,1,300.001312255859,0,300.001342773438,,,,,,,,,,,,,,,,,,,,,,,,,,,,,,,,,
,3866312131.7983,300.000244140625,8838.3017578125,0.00498283070610476,5.93975892390659E-6,1,2,12.9061126708984,4.99228307758277,35.2200008928776,6.48988906788233,0.968613335032662,10,1.14030500524897E-5,,,,,,,,,,,,,,,,,,,,,300.000244140625,300.000244140625,8838.3017578125,8838.3017578125,49.8366343861591,5.36658095791468,7.63213109970093,26,1,0,0,1,0.271759033203125,31.2805480957031,1,6,1,300.000244140625,0,300.000244140625,,,,,,,,,,,,,,,,,,,,,,,,,,,,,,,,,
,3866312231.44522,299.999908447266,18810.0947265625,0.0105715771794839,6.18852449233833E-6,1,2,12.9061126708984,4.99231173612246,35.2200008928776,13.771608674701,2.03770709491495,100,1.0899134285217E-5,,,,,,,,,,,,,,,,,,,,,299.999603271484,300.000213623047,18719.939453125,18900.25,49.858129170438,5.36651295801166,7.62722158432007,26,1,0,0,1,0.27099609375,31.2805480957031,1,6,1,299.999603271484,0,299.999908447266,,,,,,,,,,,,,,,,,,,,,,,,,,,,,,,,,
,3866312300.11898,299.999847412109,25676.275390625,0.0143685690582618,5.93850600518707E-6,1,2,12.9061126708984,4.99239854514334,35.2200008928776,18.7187174216095,2.7675784221702,100,1.32179913427403E-5,,,,,,,,,,,,,,,,,,,,,299.999694824219,300,25601.13671875,25751.4140625,49.858129170438,5.36623523514399,7.62436437606812,26,1,0,0,1,0.271148681640625,31.7693061828613,1,6,1,299.999694824219,0,299.999847412109,,,,,,,,,,,,,,,,,,,,,,,,,,,,,,,,,
,3866312368.42572,299.999969482422,32519.4091796875,0.0181658663101333,6.4591911608387E-6,1,2,12.9061126708984,4.9924101789797,35.2200008928776,23.6651243594786,3.50319544610425,100,1.99311692496643E-5,,,,,,,,,,,,,,,,,,,,,299.999938964844,300,32424.09375,32614.724609375,49.7131370801206,5.36572559961207,7.62263345718384,26,1,0,0,1,0.270919799804687,31.7693061828613,1,6,1,300,0,299.999969482422,,,,,,,,,,,,,,,,,,,,,,,,,,,,,,,,,
,3866312437.21274,300.000579833984,39414.26171875,0.0219597465359592,6.5992896364489E-6,1,2,12.9061126708984,4.99245395323918,35.2200008928776,28.6074053691309,4.2379592774509,100,2.64584615047345E-5,,,,,,,,,,,,,,,,,,,,,300.000457763672,300.000701904297,39299.19140625,39529.33203125,49.8409333430149,5.36504666137425,7.62211227416992,26,1,0,0,1,0.27099609375,31.7693061828613,1,6,1,300.000701904297,0,300.000579833984,,,,,,,,,,,,,,,,,,,,,,,,,,,,,,,,,
,3866312509.54143,299.999954223633,46659.0234375,0.0259714417652837,6.79234887939053E-6,1,2,12.9061126708984,4.99242628712681,35.2200008928776,33.8338749678304,5.00793357355099,100,2.8072921325949E-5,,,,,,,,,,,,,,,,,,,,,299.999786376953,300.000122070313,46553.875,46764.171875,49.7979437744572,5.36552856855656,7.61858177185059,26,1,0,0,1,0.270538330078125,32.2580642700195,1,6,1,300.000122070313,0,299.999954223633,,,,,,,,,,,,,,,,,,,,,,,,,,,,,,,,,
,3866316004.1419,51.6665668487549,24.7702808380127,,,5,,,,34.3200005590916,,,,,1.35983926081383E-5,3.92768737984945E-9,0.113917021899683,0.000212056371202348,4.5324221829976E-6,1.30912071163876E-9,4.53241322456154E-6,8.89172551504415E-10,9.01147870391438E-9,9.60816949940367E-10,3.00024844533454,100.057640075684,10,1000,1,3,0.0473802843468088,0.00569515348490181,0.0122765172272921,197.688903808594,51.6658897399902,51.6674690246582,24.7702808380127,24.7702808380127,,,6.40064716339111,,1,,,,,,1,1,1,51.666618347168,0,51.6666987948948,,,,,,,,,,,,,,,,,,,,,,,,,,,,,,,,,
,3866320435.77162,160.934127807617,24.7702808380127,,,5,,,,34.5599986612797,,,,,3.71537085598344E-6,1.16805011506148E-8,0.19838082297731,0.0012949638363146,1.23846086261043E-6,3.89351267785716E-9,1.23845343915735E-6,3.54962386879165E-9,4.28803650717953E-9,1.59987854624625E-9,2.99999052707422,10.005763053894,10,100,1,3,0.0130011372774596,0.00132063549338031,0.00379222701303661,254.76895904541,160.931030273438,160.93586730957,24.7702808380127,24.7702808380127,,,6.9197940826416,,1,,,,,,1,1,1,160.933822631836,0,160.933977762858,,,,,,,,,,,,,,,,,,,,,,,,,,,,,,,,,
,3866324911.87315,270.180267333984,24.7702808380127,,,5,,,,35.0500009953976,,,,,2.31409014742715E-6,6.13622236355543E-8,-0.48497736119341,0.0223644150590977,7.71363395447528E-7,2.04540748891554E-8,7.71335762697731E-7,1.09905731574928E-8,-6.52909027729032E-9,1.72504052486015E-8,2.99999994954981,1.00057637691498,19.98847910208,20,1,3,0.00814460320352759,2.99152122647828E-5,0.000352300034137443,274.873825073242,270.120910644531,270.199249267578,24.7702808380127,24.7702808380127,,,7.59972763061523,,1,,,,,,1,1,1,270.188354492187,0,270.177486101786,,,,,,,,,,,,,,,,,,,,,,,,,,,,,,,,,
,3866326335.97908,299.998291015625,24.7702808380127,,,5,,,,35.2299995720386,,,,,1.98480603600993E-6,2.34266728912521E-9,0.541241337398191,0.000851925205257451,6.61641720645943E-7,7.80935964500469E-10,6.61612199969187E-7,5.40728630695555E-10,6.25006810015364E-9,5.63447893417296E-10,2.99981995402621,100.057640075684,10,1000,1,3,0.00691041840708021,0.000878964213735388,0.0122923841699958,197.738220214844,299.991424560547,300.005767822266,24.7702808380127,24.7702808380127,,,7.72520780563354,,1,,,,,,1,1,1,299.997161865234,0,299.998730866805,,,,,,,,,,,,,,,,,,,,,,,,,,,,,,,,,