File: LT data/Bridport/K1/279-FC-ZFC-RTSIRM-contsweepwithloop-MsT.dat
[Header]
; MPMS3 Data File (default extension .dat)
; Copyright (c) 2007, Quantum Design, Inc. All rights reserved.
TITLE,
FILEOPENTIME,3865825737.05963,07/01/2022,9:26 am
BYAPP,MPMS3 w/ AC,1.0,1.1
INFO,MPMS3 Measurement Release 1.1.16 Build 424, MultiVu Release 2.3.4.19,APPNAME
INFO,Linear Motor Servo Controller,MOTOR_MODULE_NAME
INFO,3101-100 N2,MOTOR_HW_VERSION
INFO,,MOTOR_SERIAL_NUMBER
INFO,01.04.28,MOTOR_SOFTWARE_VERSION
INFO,Quantum Design Squid Module,SQUID_MODULE_NAME
INFO,3101-501 B0,SQUID_HW_VERSION
INFO,SQM327,SQUID_SERIAL_NUMBER
INFO,01.03.04,SQUID_SOFTWARE_VERSION
INFO,Quantum Design VSM Oven,OVEN_MODULE_NAME
INFO,3101-201 A3,OVEN_HW_VERSION
INFO,OVB365,OVEN_SERIAL_NUMBER
INFO,01.07.07,OVEN_SOFTWARE_VERSION
INFO,SQUID AC,AC_MODULE_NAME
INFO,3101-401 G0,AC_HW_VERSION
INFO,SAC220,AC_SERIAL_NUMBER
INFO,SQUID AC 00.95.07,AC_SOFTWARE_VERSION
INFO,TCI344,COIL_SERIAL_NUMBER
INFO,0,MOMENT_UNITS
INFO,sndst,SAMPLE_MATERIAL
INFO,,SAMPLE_COMMENT
INFO,123.08,SAMPLE_MASS
INFO,,SAMPLE_VOLUME
INFO,,SAMPLE_MOLECULAR_WEIGHT
INFO,,SAMPLE_SIZE
INFO,,SAMPLE_SHAPE
INFO,Straw,SAMPLE_HOLDER
INFO,Standard,SAMPLE_HOLDER_DETAIL
INFO,61.75,SAMPLE_OFFSET
DATATYPE,COMMENT,1
DATATYPE,TIME,2
STARTUPAXIS,X,2
STARTUPAXIS,Y1,5
FIELDGROUP, VSM,2,3,4,5,6,8,9,10,11,14,15
FIELDGROUP, DC, 2,3,4,14,56,57,58,59,60,61,62,63,64,65,66,67,68,69
FIELDGROUP, AC, 2,3,4,11,16,17,18,19,20,21,22,23,24,25,26,27,28,29,30
STARTUPGROUP, All
[Data]
Comment,Time Stamp (sec),Temperature (K),Magnetic Field (Oe),Moment (emu),M. Std. Err. (emu),Transport Action,Averaging Time (sec),Frequency (Hz),Peak Amplitude (mm),Center Position (mm),Lockin Signal' (V),Lockin Signal (V),Range,M. Quad. Signal (emu),AC Moment (emu),AC M. Std Err. (emu),AC Phase (deg),AC Phase Std. Err. (deg),AC Susceptibility (emu/Oe),AC Suscept. Std Err. (emu/Oe),AC X' (emu/Oe),AC X' Std Err. (emu/Oe),AC X'' (emu/Oe),AC X'' Std Err. (emu/Oe),AC Drive (Oe),AC Frequency (Hz),AC Averaging Time (sec),AC Cycles,AC Range,AC Measure Type,AC Signal' (V),AC Signal'' (V),AC Trim Coil Ratio,AC Trim Coil Phase,Min. Temperature (K),Max. Temperature (K),Min. Field (Oe),Max. Field (Oe),Mass (grams),Motor Lag (deg),Pressure (Torr),Measure Count,Measurement Number,SQUID Status (code),Motor Status (code),Measure Status (code),Motor Current (amps),Motor Temp. (C),Temp. Status (code),Field Status (code),Chamber Status (code),Chamber Temp (K),Redirection State,Average Temp (K),Rotation Angle (deg),Rotator state,DC Moment Fixed Ctr (emu),DC Moment Err Fixed Ctr (emu),DC Moment Free Ctr (emu),DC Moment Err Free Ctr (emu),DC Fixed Fit,DC Free Fit,DC Calculated Center (mm),DC Calculated Center Err (mm),DC Scan Length (mm),DC Scan Time (s),DC Number of Points,DC Squid Drift,DC Min V (V),DC Max V (V),DC Scans per Measure,Map 01,Map 02,Map 03,Map 04,Map 05,Map 06,Map 07,Map 08,Map 09,Map 10,Map 11,Map 12,Map 13,Map 14,Map 15,Map 16
,3865826831.59743,100.001815795898,49999.6875,0.0378520306769261,3.25791351741942E-6,1,2,12.9061126708984,4.98650146666163,37.4899990856647,49.2407223600719,7.20690218951387,100,-2.03930472535934E-5,,,,,,,,,,,,,,,,,,,,,100.001815795898,100.001815795898,49999.6875,49999.6875,49.6545149411783,5.34428749855997,7.15971851348877,26,1,0,0,1,0.266571044921875,28.8367557525635,1,1,1,100.001815795898,0,100.001815795898,,,,,,,,,,,,,,,,,,,,,,,,,,,,,,,,,
,3865826920.77643,88.359748840332,49999.6875,0.04314120677583,0.000103368514878058,1,2,12.9061126708984,4.98645505548928,37.4599993228912,56.1376530129967,8.09735426490537,100,-0.00011279246045981,,,,,,,,,,,,,,,,,,,,,88.1745834350586,88.5449142456055,49999.6875,49999.6875,49.7342410501399,5.34517520445588,7.08949756622314,26,1,0,0,1,0.26611328125,30.3030319213867,2,1,1,88.1745834350586,0,88.359748840332,,,,,,,,,,,,,,,,,,,,,,,,,,,,,,,,,
,3865827031.7825,70.1986045837402,49999.6875,0.0555019852273636,1.74123170496974E-5,1,2,12.9061126708984,4.98643010280313,37.3999997973442,72.2006996580718,10.5599579360749,100,-3.54567425164102E-5,,,,,,,,,,,,,,,,,,,,,70.0011138916016,70.3960952758789,49999.6875,49999.6875,49.7721500333226,5.34399275797255,7.00666952133179,26,1,0,0,1,0.275802612304687,31.7693061828613,2,1,1,70.0011138916016,0,70.1986045837402,,,,,,,,,,,,,,,,,,,,,,,,,,,,,,,,,
,3865827145.69615,50.7071380615234,49999.6875,0.077341555250664,8.94310922998732E-5,1,2,12.9061126708984,4.98629620158386,37.3600013554096,100.592168030061,14.8175304214287,100,2.96810604272105E-5,,,,,,,,,,,,,,,,,,,,,50.7071380615234,50.7071380615234,49999.6875,49999.6875,49.7647245623899,5.34478157590792,6.84543752670288,26,1,0,0,1,0.266647338867187,30.7917900085449,2,1,1,50.7071380615234,0,50.7071380615234,,,,,,,,,,,,,,,,,,,,,,,,,,,,,,,,,
,3865827259.40856,31.5203981399536,49999.6875,0.119633027687661,0.00010845204678329,1,2,12.9061126708984,4.98632940819272,37.3199991881847,155.627911378051,22.7224649503362,1000,-0.000106096987085643,,,,,,,,,,,,,,,,,,,,,31.3497562408447,31.6910400390625,49999.6875,49999.6875,49.8878310541687,5.34415430014271,6.52453565597534,26,1,0,0,1,0.26702880859375,31.7693061828613,2,1,1,31.3497562408447,0,31.5203981399536,,,,,,,,,,,,,,,,,,,,,,,,,,,,,,,,,
,3865827327.92826,20.1196699142456,49999.6875,0.163185034697068,7.91345562447702E-5,1,2,12.9061126708984,4.98632191138607,37.3000018298626,212.273497338679,31.0610825448683,1000,-9.34836395774646E-5,,,,,,,,,,,,,,,,,,,,,19.9689044952393,20.270435333252,49999.6875,49999.6875,49.8901759397264,5.34446881010063,6.07874202728271,26,1,0,0,1,0.275802612304687,31.7693061828613,2,1,1,19.9689044952393,0,20.1196699142456,,,,,,,,,,,,,,,,,,,,,,,,,,,,,,,,,
,3865827398.45318,9.39928150177002,49999.6875,0.231294944177635,0.000115481292699602,1,2,12.9061126708984,4.9863128162873,37.2800007462502,300.863298702282,44.0782995860175,1000,-9.16739474032309E-5,,,,,,,,,,,,,,,,,,,,,9.2752571105957,9.52330589294434,49999.6875,49999.6875,50.1262277525342,5.34664542596516,4.75346422195435,26,1,0,0,1,0.28472900390625,30.7917900085449,6,1,1,9.2752571105957,0,9.39928150177002,,,,,,,,,,,,,,,,,,,,,,,,,,,,,,,,,
,3865827467.14562,2.41070854663849,49999.6875,0.286006914979879,2.76824763784862E-5,1,2,12.9061126708984,4.98632071448832,37.2800007462502,372.019798081342,54.5896452200791,1000,-4.82680078219844E-5,,,,,,,,,,,,,,,,,,,,,2.41032195091248,2.4110951423645,49999.6875,49999.6875,50.7683355810823,5.34978986389264,2.76485276222229,26,1,0,0,1,0.27587890625,31.7693061828613,6,1,1,2.41032195091248,0,2.41070854663849,,,,,,,,,,,,,,,,,,,,,,,,,,,,,,,,,
,3865827537.46165,2.26319885253906,49999.6875,0.286945387861644,2.22866254379357E-5,1,2,12.9061126708984,4.98621086712644,37.2800007462502,373.234671979683,54.7281782594902,1000,-7.83320743377954E-5,,,,,,,,,,,,,,,,,,,,,2.26099944114685,2.26539826393127,49999.6875,49999.6875,50.8496249470823,5.35064997001973,2.62638425827026,26,1,0,0,1,0.26702880859375,31.2805480957031,6,1,1,2.26099944114685,0,2.26319885253906,,,,,,,,,,,,,,,,,,,,,,,,,,,,,,,,,
,3865827608.33749,2.11872243881226,49999.6875,0.287617720918254,3.25122180510546E-5,1,2,12.9061126708984,4.98610005415449,37.2800007462502,374.100593799456,54.8337120840574,1000,-9.46509590581596E-5,,,,,,,,,,,,,,,,,,,,,2.1164436340332,2.12100124359131,49999.6875,49999.6875,50.8031180501881,5.35145027360621,2.53087306022644,26,1,0,0,1,0.27618408203125,31.7693061828613,2,1,1,2.12100124359131,0,2.11872243881226,,,,,,,,,,,,,,,,,,,,,,,,,,,,,,,,,
,3865827676.46517,2.07251787185669,49999.6875,0.287776821626708,4.45988875119915E-5,1,2,12.9061126708984,4.985997554113,37.2800007462502,374.29674143811,54.8623661910436,1000,-9.47757167336631E-5,,,,,,,,,,,,,,,,,,,,,2.07011795043945,2.07491779327393,49999.6875,49999.6875,50.8160149207554,5.35191902209463,2.51656818389893,26,1,0,0,1,0.269088745117187,31.2805480957031,2,1,1,2.07011795043945,0,2.07251787185669,,,,,,,,,,,,,,,,,,,,,,,,,,,,,,,,,
,3865827745.17111,1.99955379962921,49999.6875,0.288047955270894,3.25624975762486E-5,1,2,12.9061126708984,4.98591668017514,37.2800007462502,374.641665168412,54.9073017855759,1000,-9.90962293463413E-5,,,,,,,,,,,,,,,,,,,,,1.99942147731781,1.99968612194061,49999.6875,49999.6875,50.8633034461688,5.35216190622418,2.44799184799194,26,1,0,0,1,0.26702880859375,30.7917900085449,5,1,1,1.99968612194061,0,1.99955379962921,,,,,,,,,,,,,,,,,,,,,,,,,,,,,,,,,
,3865828206.48272,20.7371368408203,26.1993350982666,0.000159228266957109,1.94272537452732E-7,1,5,12.9061126708984,5.00555485549457,37.2800007462502,0.208235415026035,0.0305522575790814,1,-2.97952247234144E-8,,,,,,,,,,,,,,,,,,,,,20.3673419952393,21.1069316864014,26.1993350982666,26.1993350982666,49.8901759397264,5.34968517952266,5.60212373733521,63,1,64,0,0,0.267181396484375,30.3030319213867,2,1,1,21.1069316864014,0,20.7371368408203,,,,,,,,,,,,,,,,,,,,,,,,,,,,,,,,,
,3865828400.59422,51.0000991821289,26.1993350982666,7.7017423439973E-5,2.75457436168995E-8,1,5,12.9061126708984,5.00523920788514,37.3000018298626,0.1007250126228,0.014694109612659,1,-7.7477158182815E-8,,,,,,,,,,,,,,,,,,,,,51.0000991821289,51.0000991821289,26.1993350982666,26.1993350982666,49.8241283298514,5.35055874417741,6.42606830596924,65,1,0,0,1,0.277481079101562,30.7917900085449,2,1,1,51.0000991821289,0,51.0000991821289,,,,,,,,,,,,,,,,,,,,,,,,,,,,,,,,,
,3865828595.85437,82.066764831543,26.1993350982666,5.5776862835171E-5,1.80921629308842E-8,1,5,12.9061126708984,5.00498196072355,37.3499989509583,0.0729451553389762,0.010611993523458,1,-7.81945463274587E-8,,,,,,,,,,,,,,,,,,,,,82.066764831543,82.066764831543,26.1993350982666,26.1993350982666,49.9413726077361,5.35207259733053,6.70775747299194,64,1,64,0,0,0.279083251953125,31.2805480957031,2,1,1,82.066764831543,0,82.066764831543,,,,,,,,,,,,,,,,,,,,,,,,,,,,,,,,,
,3865828784.1178,113.121788024902,26.1993350982666,4.04705645728035E-5,1.57318306421094E-8,1,5,12.9061126708984,5.0048083889637,37.4099984765053,0.0529254250088979,0.00769632444493651,1,-5.91455853457509E-8,,,,,,,,,,,,,,,,,,,,,113.121788024902,113.121788024902,26.1993350982666,26.1993350982666,49.9003371104764,5.35333544142269,6.85997009277344,64,1,64,0,0,0.269241333007813,31.7693061828613,2,1,1,113.121788024902,0,113.121788024902,,,,,,,,,,,,,,,,,,,,,,,,,,,,,,,,,
,3865828971.26606,144.019302368164,26.1993350982666,2.94397080438425E-5,9.75555915444785E-9,1,5,12.9061126708984,5.00474260067709,37.5000014901161,0.0384993280891547,0.00559693547143474,1,-4.42008134547619E-8,,,,,,,,,,,,,,,,,,,,,144.019302368164,144.019302368164,26.1993350982666,26.1993350982666,49.898773853438,5.353431033204,6.94543600082397,65,1,0,0,1,0.289459228515625,31.2805480957031,2,1,1,144.019302368164,0,144.019302368164,,,,,,,,,,,,,,,,,,,,,,,,,,,,,,,,,
,3865829158.78737,175.071380615234,26.1993350982666,2.3131781257709E-5,8.14081099843158E-9,1,5,12.9061126708984,5.00447220967735,37.5999994575977,0.0302476785259329,0.00439919260288478,1,-3.33362175049564E-8,,,,,,,,,,,,,,,,,,,,,175.071380615234,175.071380615234,26.1993350982666,26.1993350982666,49.8600832417361,5.35503537615036,7.03524446487427,65,1,0,0,1,0.278167724609375,30.7917900085449,2,1,1,175.071380615234,0,175.071380615234,,,,,,,,,,,,,,,,,,,,,,,,,,,,,,,,,
,3865829346.32684,206.093612670898,26.1993350982666,1.85280335836069E-5,6.92030864728918E-9,1,5,12.9061126708984,5.00424383518482,37.7300009131432,0.0242278153191267,0.00351215514734834,1,-3.53253657973356E-8,,,,,,,,,,,,,,,,,,,,,206.093612670898,206.093612670898,26.1993350982666,26.1993350982666,49.9996039324188,5.35598029953541,7.11206960678101,65,1,0,0,1,0.278549194335938,31.2805480957031,2,1,1,206.093612670898,0,206.093612670898,,,,,,,,,,,,,,,,,,,,,,,,,,,,,,,,,
,3865829532.16914,237.024795532227,26.1993350982666,1.52387121299758E-5,7.68390868241279E-9,1,5,12.9061126708984,5.00374299451095,37.8700010478497,0.0199227256396941,0.00289559966984164,1,-2.34158022865624E-8,,,,,,,,,,,,,,,,,,,,,237.024795532227,237.024795532227,26.1993350982666,26.1993350982666,49.8643821985918,5.35751536954313,7.25667142868042,64,1,64,0,0,0.270767211914062,31.7693061828613,2,1,1,237.024795532227,0,237.024795532227,,,,,,,,,,,,,,,,,,,,,,,,,,,,,,,,,
,3865829719.22692,268.026611328125,26.1993350982666,1.28719332700125E-5,6.78423744128905E-9,1,5,12.9061126708984,5.00270562590349,38.0499996244907,0.0168246757808125,0.0024376542314343,1,-2.55261098017183E-8,,,,,,,,,,,,,,,,,,,,,268.026611328125,268.026611328125,26.1993350982666,26.1993350982666,49.8612556845149,5.36254221381809,7.48738861083984,63,1,64,0,0,0.275192260742187,31.7693061828613,2,1,1,268.026611328125,0,268.026611328125,,,,,,,,,,,,,,,,,,,,,,,,,,,,,,,,,
,3865829916.97674,299.00634765625,26.1993350982666,1.13115419847436E-5,6.60822391947092E-9,1,5,12.9061126708984,5.00252149809327,38.2199995219708,0.0147839144908963,0.00214503385903573,1,-2.01411333596292E-8,,,,,,,,,,,,,,,,,,,,,299.00634765625,299.00634765625,26.1993350982666,26.1993350982666,49.8714168552649,5.36210660712199,7.3678731918335,64,1,64,0,0,0.273361206054687,30.7917900085449,6,1,1,299.00634765625,0,299.00634765625,,,,,,,,,,,,,,,,,,,,,,,,,,,,,,,,,
,3865831502.68841,1.99999445676804,40891.921875,0.269554848935567,4.61187574112367E-5,1,2,12.9061126708984,4.99394020658369,37.2800007462502,351.378473851074,51.5162671786354,1000,-7.89101045770499E-5,,,,,,,,,,,,,,,,,,,,,1.99987018108368,2.00011873245239,40777.0078125,41006.8359375,50.5967681211111,5.359616764381,2.51084423065186,26,1,0,0,1,0.269622802734375,30.3030319213867,1,6,1,2.00011873245239,0,1.99999445676804,,,,,,,,,,,,,,,,,,,,,,,,,,,,,,,,,
,3865831572.80765,2.00001889467239,33888.107421875,0.250707146009022,4.37158639486137E-5,1,2,12.9061126708984,4.99384676793504,37.2800007462502,326.792725615739,47.9689511511064,1000,-3.03991174578233E-5,,,,,,,,,,,,,,,,,,,,,1.99999821186066,2.00003957748413,33798.37109375,33977.84375,50.4173843759476,5.35978671362167,2.50906085968018,26,1,0,0,1,0.269012451171875,30.7917900085449,1,6,1,2.00003957748413,0,2.00001889467239,,,,,,,,,,,,,,,,,,,,,,,,,,,,,,,,,
,3865831642.60362,1.99980968236923,26919.37109375,0.226689001421944,4.57073486280685E-5,1,2,12.9061126708984,4.99375512425686,37.2800007462502,295.484326474144,43.3282961358175,1000,-6.12722089282758E-5,,,,,,,,,,,,,,,,,,,,,1.99968326091766,1.9999361038208,26759.587890625,27079.154296875,50.2215864318803,5.35976618948032,2.50319337844849,26,1,0,0,1,0.269317626953125,29.3255138397217,1,6,1,1.9999361038208,0,1.99980968236923,,,,,,,,,,,,,,,,,,,,,,,,,,,,,,,,,
,3865831709.77206,1.99983900785446,20215.5009765625,0.197210212063456,6.0949925992022E-5,1,2,12.9061126708984,4.99367477298005,37.2800007462502,257.048053012252,37.7303997865831,1000,-2.46140941597325E-5,,,,,,,,,,,,,,,,,,,,,1.99976444244385,1.99991357326508,20120.61328125,20310.388671875,50.1465500940341,5.35872515927367,2.49952459335327,26,1,0,0,1,0.269088745117187,31.2805480957031,1,6,1,1.99976444244385,0,1.99983900785446,,,,,,,,,,,,,,,,,,,,,,,,,,,,,,,,,
,3865831776.45311,1.99986386299133,13556.7700195313,0.157819773637369,7.31820090953236E-5,1,2,12.9061126708984,4.9935710521886,37.2800007462502,205.707308609853,30.1416072658189,1000,-5.93690262481278E-5,,,,,,,,,,,,,,,,,,,,,1.99966382980347,2.0000638961792,13442,13671.5400390625,49.980063219438,5.35857473784427,2.5005898475647,26,1,0,0,1,0.270004272460938,31.7693061828613,1,6,1,2.0000638961792,0,1.99986386299133,,,,,,,,,,,,,,,,,,,,,,,,,,,,,,,,,
,3865831844.76792,2.00008702278137,6731.91259765625,0.0998796002063948,0.000113263625938935,1,2,12.9061126708984,4.9935628012746,37.2800007462502,130.185327405405,19.0799067068434,1000,-3.43553295743049E-5,,,,,,,,,,,,,,,,,,,,,1.99998593330383,2.00018811225891,6637.01806640625,6826.80712890625,49.8792331404572,5.35803409695211,2.51033711433411,26,1,0,0,1,0.271530151367187,31.7693061828613,1,6,1,2.00018811225891,0,2.00008702278137,,,,,,,,,,,,,,,,,,,,,,,,,,,,,,,,,
,3865831939.44989,2.00005066394806,-2732.50280761719,-0.0435230364525097,0.000163517993544327,1,2,12.9061126708984,4.99339146511299,37.2800007462502,-56.7200523312224,-8.35547022928771,100,-1.70294124448207E-5,,,,,,,,,,,,,,,,,,,,,2.00002837181091,2.00007295608521,-2827.296875,-2637.70874023438,49.9835805477745,5.35904485350872,2.50121402740479,26,1,0,0,1,0.269546508789062,30.3030319213867,1,6,1,2.00002837181091,0,2.00005066394806,,,,,,,,,,,,,,,,,,,,,,,,,,,,,,,,,
,3865832006.05596,2.00003433227539,-9391.30810546875,-0.121940120026067,9.93384957318118E-5,1,2,12.9061126708984,4.99332571662762,37.2800007462502,-158.909926767237,-23.4218715466438,100,-5.72803343710489E-5,,,,,,,,,,,,,,,,,,,,,2.00002837181091,2.00004029273987,-9496.23046875,-9286.3857421875,49.9718561199861,5.35914550567297,2.48012709617615,26,1,0,0,1,0.269927978515625,31.2805480957031,1,6,1,2.00002837181091,0,2.00003433227539,,,,,,,,,,,,,,,,,,,,,,,,,,,,,,,,,
,3865832088.69283,2.00005495548248,-17656.6025390625,-0.182255270205317,6.65151526538111E-5,1,2,12.9061126708984,4.99342286383329,37.2800007462502,-237.543431083889,-34.8342191693247,1000,4.7702245083892E-5,,,,,,,,,,,,,,,,,,,,,2.00001931190491,2.00009059906006,-17756.54296875,-17556.662109375,50.1098135536303,5.35972202086207,2.47244882583618,26,1,0,0,1,0.272140502929687,30.7917900085449,1,6,1,2.00001931190491,0,2.00005495548248,,,,,,,,,,,,,,,,,,,,,,,,,,,,,,,,,
,3865832155.27849,1.99990820884705,-24317.4765625,-0.215662472013315,5.07243684169967E-5,1,2,12.9061126708984,4.99337857159267,37.2800007462502,-281.090444091464,-41.1572125606599,1000,0.000103688070304653,,,,,,,,,,,,,,,,,,,,,1.999880194664,1.99993622303009,-24397.634765625,-24237.318359375,50.1434235799572,5.36057237771833,2.45047402381897,26,1,0,0,1,0.269699096679687,31.2805480957031,1,6,1,1.999880194664,0,1.99990820884705,,,,,,,,,,,,,,,,,,,,,,,,,,,,,,,,,
,3865832223.51174,2.00009644031525,-31147.4482421875,-0.241761937599853,4.54695045357908E-5,1,2,12.9061126708984,4.99341475835897,37.2800007462502,-315.096400553996,-46.2392864130176,1000,3.89248282637051E-5,,,,,,,,,,,,,,,,,,,,,1.99986243247986,2.00033044815063,-31237.716796875,-31057.1796875,50.3783029499861,5.36089782968853,2.4493043422699,26,1,0,0,1,0.268783569335938,31.2805480957031,1,6,1,2.00033044815063,0,2.00009644031525,,,,,,,,,,,,,,,,,,,,,,,,,,,,,,,,,
,3865832290.02286,2.00005304813385,-37814.46484375,-0.261542658253599,5.9352328424611E-5,1,2,12.9061126708984,4.99339731297213,37.2800007462502,-340.87243196255,-50.0438829356969,1000,2.55444591848149E-5,,,,,,,,,,,,,,,,,,,,,1.99992036819458,2.00018572807312,-37909.609375,-37719.3203125,50.5475255243996,5.36198547278202,2.4326024055481,26,1,0,0,1,0.269775390625,31.2805480957031,1,6,1,2.00018572807312,0,2.00005304813385,,,,,,,,,,,,,,,,,,,,,,,,,,,,,,,,,
,3865832358.84166,1.99997788667679,-44707.236328125,-0.277924345382955,4.11975732621377E-5,1,2,12.9061126708984,4.99330395016704,37.2800007462502,-362.198802331338,-53.2765486794427,1000,-4.92551677878484E-5,,,,,,,,,,,,,,,,,,,,,1.99980390071869,2.00015187263489,-44762.3671875,-44652.10546875,50.6925176147169,5.36280868500927,2.4136962890625,26,1,0,0,1,0.268936157226562,31.2805480957031,1,6,1,1.99980390071869,0,1.99997788667679,,,,,,,,,,,,,,,,,,,,,,,,,,,,,,,,,
,3865832424.94346,1.99990803003311,-49337.345703125,-0.287488662576147,3.05822712301575E-5,1,2,12.9061126708984,4.99323561594239,37.2800007462502,-374.673272954803,-54.9920092951328,1000,3.87556506091192E-5,,,,,,,,,,,,,,,,,,,,,1.999844789505,1.99997127056122,-49432.12890625,-49242.5625,50.918017442515,5.36306158634018,2.39712810516357,26,1,0,0,1,0.270462036132813,31.2805480957031,1,6,1,1.99997127056122,0,1.99990803003311,,,,,,,,,,,,,,,,,,,,,,,,,,,,,,,,,
,3865832493.74126,2.00350964069366,-42470.951171875,-0.273262940699499,3.24495297997171E-5,1,2,12.9061126708984,4.99326201687358,37.2800007462502,-356.135294149436,-52.276455529366,1000,3.28379086572407E-5,,,,,,,,,,,,,,,,,,,,,1.99827313423157,2.00874614715576,-42585.67578125,-42356.2265625,50.635458732813,5.36306886834101,2.3837468624115,26,1,0,0,1,0.270462036132813,31.7693061828613,6,6,1,1.99827313423157,0,2.00350964069366,,,,,,,,,,,,,,,,,,,,,,,,,,,,,,,,,
,3865832561.22871,2.00425797700882,-35733.265625,-0.255962228497273,4.31840911085825E-5,1,2,12.9061126708984,4.9932086911252,37.2800007462502,-333.573171511166,-49.0315887930247,1000,-1.95564960244469E-5,,,,,,,,,,,,,,,,,,,,,1.99865162372589,2.00986433029175,-35897.71484375,-35568.81640625,50.4943747850919,5.36234627484343,2.38384485244751,26,1,0,0,1,0.269241333007813,31.7693061828613,6,6,1,1.99865162372589,0,2.00425797700882,,,,,,,,,,,,,,,,,,,,,,,,,,,,,,,,,
,3865832628.41896,2.000168800354,-29026.1923828125,-0.234859868376459,5.17231816206146E-5,1,2,12.9061126708984,4.99317219845644,37.2800007462502,-306.073722470322,-44.9578506805456,1000,5.80711459527118E-6,,,,,,,,,,,,,,,,,,,,,2.00007700920105,2.00026059150696,-29121.125,-28931.259765625,50.3083471975149,5.36180784791492,2.38636708259583,26,1,0,0,1,0.27099609375,29.3255138397217,5,6,1,2.00007700920105,0,2.000168800354,,,,,,,,,,,,,,,,,,,,,,,,,,,,,,,,,
,3865832695.23966,1.99982339143753,-22353.109375,-0.207881745842744,5.74417197579888E-5,1,2,12.9061126708984,4.99316673948486,37.2800007462502,-270.920653428157,-39.7544922765844,1000,3.50916070170491E-5,,,,,,,,,,,,,,,,,,,,,1.99968230724335,1.99996447563171,-22472.82421875,-22233.39453125,50.1907121053707,5.36178453131348,2.37685465812683,26,1,0,0,1,0.269317626953125,31.7693061828613,1,6,1,1.99996447563171,0,1.99982339143753,,,,,,,,,,,,,,,,,,,,,,,,,,,,,,,,,
,3865832765.4609,1.99963390827179,-15350.5786132812,-0.169850881777414,7.02270748647672E-5,1,2,12.9061126708984,4.99298642962061,37.2800007462502,-221.338564949282,-32.5302033499619,1000,-9.87332488924221E-6,,,,,,,,,,,,,,,,,,,,,1.99944317340851,1.99982464313507,-15435.39453125,-15265.7626953125,49.9644306490534,5.3608778350955,2.37343287467957,26,1,0,0,1,0.26824951171875,31.7693061828613,5,6,1,1.99982464313507,0,1.99963390827179,,,,,,,,,,,,,,,,,,,,,,,,,,,,,,,,,
,3865832836.26071,2.00000774860382,-8273.83740234375,-0.115553677053388,0.000102373778834676,1,2,12.9061126708984,4.99290924840044,37.2800007462502,-150.588173924369,-22.0663427923402,1000,4.25986926361126E-5,,,,,,,,,,,,,,,,,,,,,1.99984407424927,2.00017142295837,-8333.6201171875,-8214.0546875,49.9374644651399,5.36098602239338,2.38864517211914,26,1,0,0,1,0.269699096679687,31.7693061828613,5,6,1,2.00017142295837,0,2.00000774860382,,,,,,,,,,,,,,,,,,,,,,,,,,,,,,,,,
,3865832924.68803,1.99187397956848,559.944976806641,0.00554995951034003,0.000231724312796048,1,2,12.9061126708984,4.99267606507382,37.2800007462502,7.23103503647434,1.06746805282751,100,3.86867883635858E-6,,,,,,,,,,,,,,,,,,,,,1.98511910438538,1.99862885475159,480.024475097656,639.865478515625,49.9437174932937,5.36169573121581,2.36150574684143,24,1,68,0,0,0.272445678710938,30.3030319213867,6,6,1,1.99862885475159,0,1.99187397956848,,,,,,,,,,,,,,,,,,,,,,,,,,,,,,,,,
,3865833003.18188,1.99990576505661,8413.69677734375,0.112837736887112,0.000106561898585579,1,2,12.9061126708984,4.99257246564765,37.2899994254112,147.014675425382,21.6832005890111,100,6.39573422292536E-5,,,,,,,,,,,,,,,,,,,,,1.99964272975922,2.000168800354,8328.7431640625,8498.650390625,49.9996039324188,5.36284852799143,2.3798189163208,26,1,0,0,1,0.269241333007813,31.2805480957031,1,6,1,1.99964272975922,0,1.99990576505661,,,,,,,,,,,,,,,,,,,,,,,,,,,,,,,,,
,3865833085.80384,2.0001757144928,16674.705078125,0.176600477173502,6.88601604131882E-5,1,2,12.9061126708984,4.99254268484692,37.2800007462502,230.112003155606,33.7744846362416,1000,-2.36561271257013E-5,,,,,,,,,,,,,,,,,,,,,2.00013279914856,2.00021862983704,16589.7578125,16759.65234375,50.2118160753899,5.36342337843442,2.35967636108398,26,1,0,0,1,0.27099609375,31.2805480957031,1,6,1,2.00021862983704,0,2.0001757144928,,,,,,,,,,,,,,,,,,,,,,,,,,,,,,,,,
,3865833152.43194,1.99992501735687,23336.5244140625,0.211454783098228,5.76929782515977E-5,1,2,12.9061126708984,4.9925333416742,37.2899994254112,275.526714423627,40.4404541840866,1000,-2.81253559122898E-5,,,,,,,,,,,,,,,,,,,,,1.99972176551819,2.00012826919556,23221.373046875,23451.67578125,50.2090803755726,5.3638034208178,2.35134410858154,26,1,0,0,1,0.270614624023438,31.2805480957031,1,6,1,1.99972176551819,0,1.99992501735687,,,,,,,,,,,,,,,,,,,,,,,,,,,,,,,,,
,3865833219.95824,2.00000870227814,30100.396484375,0.238539685920063,4.30581074115566E-5,1,2,12.9061126708984,4.99259578615499,37.2800007462502,310.827854673682,45.5945657515145,1000,-5.21741030013936E-5,,,,,,,,,,,,,,,,,,,,,1.99980115890503,2.00021624565125,29930.169921875,30270.623046875,50.2962319554669,5.3644111541727,2.35454177856445,26,1,0,0,1,0.270156860351562,31.7693061828613,1,6,1,2.00021624565125,0,2.00000870227814,,,,,,,,,,,,,,,,,,,,,,,,,,,,,,,,,
,3865833287.17186,1.99613571166992,36834.833984375,0.258983299582962,4.39224775283114E-5,1,2,12.9061126708984,4.99265807078765,37.2800007462502,337.453994495527,49.6303619237641,1000,4.10730721834395E-5,,,,,,,,,,,,,,,,,,,,,1.99318611621857,1.99908530712128,36744.703125,36924.96484375,50.5752733368323,5.36447251065205,2.34164524078369,26,1,0,0,1,0.271148681640625,31.7693061828613,5,6,1,1.99318611621857,0,1.99613571166992,,,,,,,,,,,,,,,,,,,,,,,,,,,,,,,,,
,3865833355.92335,2.00123715400696,43723.736328125,0.275807495074241,4.08843697900013E-5,1,2,12.9061126708984,4.99265523856473,37.2800007462502,359.391431473908,52.7463581437801,1000,-3.91986395060641E-5,,,,,,,,,,,,,,,,,,,,,2.00077986717224,2.00169444084167,43658.54296875,43788.9296875,50.6917359861977,5.36465316073593,2.34261655807495,26,1,0,0,1,0.269851684570313,31.2805480957031,5,6,1,2.00077986717224,0,2.00123715400696,,,,,,,,,,,,,,,,,,,,,,,,,,,,,,,,,
,3865833765.58851,2.24613130092621,26.1993350982666,0.00439325666947768,3.91788950705451E-6,1,5,12.9061126708984,4.99306530897176,37.2800007462502,5.7260885668827,0.834911484276138,1000,-4.74245777354784E-6,,,,,,,,,,,,,,,,,,,,,2.00026798248291,2.49199461936951,26.1993350982666,26.1993350982666,49.8761066263803,5.35986445481219,2.57423496246338,65,1,0,0,1,0.271377563476562,29.8142719268799,6,1,1,2.49199461936951,0,2.24613130092621,,,,,,,,,,,,,,,,,,,,,,,,,,,,,,,,,
,3865833979.46211,34.1652793884277,26.1993350982666,8.48284003339194E-5,2.55261935290852E-8,1,5,12.9061126708984,4.99314433632553,37.2800007462502,0.110562010893893,0.0161500208616187,1,-6.96667093889943E-8,,,,,,,,,,,,,,,,,,,,,34.1652793884277,34.1652793884277,26.1993350982666,26.1993350982666,49.8964289678803,5.35840030384634,6.05346822738647,65,1,0,0,1,0.26947021484375,30.7917900085449,2,1,1,34.1652793884277,0,34.1652793884277,,,,,,,,,,,,,,,,,,,,,,,,,,,,,,,,,
,3865834175.63722,65.0261306762695,26.1993350982666,6.4577207155786E-5,1.6028715949801E-8,1,5,12.9061126708984,4.99317998645905,37.3199991881847,0.0841737338596034,0.0122572503172452,1,-8.17167282197807E-8,,,,,,,,,,,,,,,,,,,,,65.0261306762695,65.0261306762695,26.1993350982666,26.1993350982666,49.9222227090149,5.35901179279373,6.5534873008728,65,1,0,0,1,0.268783569335938,31.2805480957031,2,1,1,65.0261306762695,0,65.0261306762695,,,,,,,,,,,,,,,,,,,,,,,,,,,,,,,,,
,3865834367.25489,96.0465774536133,26.1993350982666,4.88835480314199E-5,1.30021063173078E-8,1,5,12.9061126708984,4.99314901530219,37.3799987137318,0.0637166973817187,0.0092814072183624,1,-5.95444566627747E-8,,,,,,,,,,,,,,,,,,,,,96.0465774536133,96.0465774536133,26.1993350982666,26.1993350982666,49.8909575682457,5.36002713894262,6.75324630737305,65,1,0,0,1,0.27069091796875,31.2805480957031,2,1,1,96.0465774536133,0,96.0465774536133,,,,,,,,,,,,,,,,,,,,,,,,,,,,,,,,,
,3865834555.45696,127.006904602051,26.1993350982666,3.51764952939988E-5,1.06426780118536E-8,1,5,12.9061126708984,4.99347512346736,37.4500006437302,0.0458576957896147,0.0066584006510722,1,-5.90310192444188E-8,,,,,,,,,,,,,,,,,,,,,127.006904602051,127.006904602051,26.1993350982666,26.1993350982666,49.9515337784861,5.35849869723205,6.87477684020996,65,1,0,0,1,0.27923583984375,31.2805480957031,2,1,1,127.006904602051,0,127.006904602051,,,,,,,,,,,,,,,,,,,,,,,,,,,,,,,,,
,3865834742.8113,158.136581420898,26.1993350982666,2.72919896029595E-5,8.79681699390912E-9,1,5,12.9061126708984,4.9931827972139,37.5399999320507,0.0355719439520023,0.00519432522062705,1,-2.37225761889565E-8,,,,,,,,,,,,,,,,,,,,,158.136581420898,158.136581420898,26.1993350982666,26.1993350982666,49.9667755346111,5.3605856724387,6.95203638076782,65,1,0,0,1,0.2703857421875,30.7917900085449,2,1,1,158.136581420898,0,158.136581420898,,,,,,,,,,,,,,,,,,,,,,,,,,,,,,,,,
,3865834929.25206,189.005706787109,26.1993350982666,2.15585870285479E-5,7.57788433691316E-9,1,5,12.9061126708984,4.99288670296929,37.6599989831448,0.0280969423389485,0.00410168424735402,1,-1.95790502864936E-8,,,,,,,,,,,,,,,,,,,,,189.005706787109,189.005706787109,26.1993350982666,26.1993350982666,49.8491404424668,5.36174298370387,7.02199745178223,65,1,0,0,1,0.2703857421875,31.7693061828613,2,1,1,189.005706787109,0,189.005706787109,,,,,,,,,,,,,,,,,,,,,,,,,,,,,,,,,
,3865835115.87056,220.003646850586,26.1993350982666,1.7487241075371E-5,6.07273793946868E-9,1,5,12.9061126708984,4.99251368146104,37.7900004386902,0.0227905394981426,0.00331242465621813,1,-2.68615005439078E-8,,,,,,,,,,,,,,,,,,,,,220.003646850586,220.003646850586,26.1993350982666,26.1993350982666,49.9347287653226,5.36368341598594,7.14006328582764,64,1,64,0,0,0.270919799804687,31.7693061828613,2,1,1,220.003646850586,0,220.003646850586,,,,,,,,,,,,,,,,,,,,,,,,,,,,,,,,,
,3865835303.01586,251.020294189453,26.1993350982666,1.46562178636828E-5,6.47910758886376E-9,1,5,12.9061126708984,4.99165680387516,37.9500016570091,0.0190953271238802,0.00278255281302844,1,-1.71027320023897E-8,,,,,,,,,,,,,,,,,,,,,251.020294189453,251.020294189453,26.1993350982666,26.1993350982666,49.8432782285726,5.36525623258403,7.39692306518555,65,1,0,0,1,0.272064208984375,31.2805480957031,2,1,1,251.020294189453,0,251.020294189453,,,,,,,,,,,,,,,,,,,,,,,,,,,,,,,,,
,3865835490.90823,282.162750244141,26.1993350982666,1.26759719482413E-5,7.30543365716814E-9,1,5,12.9061126708984,4.9915895432963,38.1300002336502,0.016514230700524,0.00241169984820754,1,-1.08371341347126E-8,,,,,,,,,,,,,,,,,,,,,282.162750244141,282.162750244141,26.1993350982666,26.1993350982666,49.9347287653226,5.3665182508655,7.49314785003662,64,1,64,0,0,0.272064208984375,31.7693061828613,2,1,1,282.162750244141,0,282.162750244141,,,,,,,,,,,,,,,,,,,,,,,,,,,,,,,,,
,3865836281.43282,288.995544433594,26.4751167297363,1.59104728037902E-5,7.0007035041236E-9,1,5,12.9061126708984,4.98160279665255,38.1500013172626,0.0206723231497398,0.00300222592011239,1,-2.6197774543607E-8,,,,,,,,,,,,,,,,,,,,,288.995544433594,288.995544433594,26.4751167297363,26.4751167297363,49.6885157817649,5.36687447781332,8.0229377746582,65,1,0,0,1,0.27191162109375,30.7917900085449,2,1,1,288.995544433594,0,288.995544433594,,,,,,,,,,,,,,,,,,,,,,,,,,,,,,,,,
,3865836461.31164,257.986297607422,26.4751167297363,1.64842503837951E-5,7.94554633415314E-9,1,5,12.9061126708984,4.98153849650823,38.0100011825562,0.0214170185974851,0.00311329474278341,1,-2.49435994255213E-8,,,,,,,,,,,,,,,,,,,,,257.986297607422,257.986297607422,26.4751167297363,26.4751167297363,49.8237375155918,5.36656627520749,7.80352783203125,63,1,64,0,0,0.272674560546875,31.7693061828613,2,1,1,257.986297607422,0,257.986297607422,,,,,,,,,,,,,,,,,,,,,,,,,,,,,,,,,
,3865836646.0702,226.977264404297,26.4751167297363,1.69458335009424E-5,8.16528905688175E-9,1,5,12.9061126708984,4.98197440974573,37.8899984061718,0.0220207038364566,0.00319222431904234,1,-3.22934241055805E-8,,,,,,,,,,,,,,,,,,,,,226.977264404297,226.977264404297,26.4751167297363,26.4751167297363,49.8366343861591,5.36540338336691,7.68693161010742,65,1,0,0,1,0.26947021484375,31.7693061828613,2,1,1,226.977264404297,0,226.977264404297,,,,,,,,,,,,,,,,,,,,,,,,,,,,,,,,,
,3865836831.60549,195.987396240234,26.4751167297363,1.74066485802748E-5,8.15946478791849E-9,1,5,12.9061126708984,4.98260347932962,37.7699993550777,0.0226220521599911,0.00328971475662563,1,-2.53976255399056E-8,,,,,,,,,,,,,,,,,,,,,195.987396240234,195.987396240234,26.4751167297363,26.4751167297363,49.804196802611,5.36396501579821,7.5825366973877,64,1,64,0,0,0.268630981445313,31.7693061828613,2,1,1,195.987396240234,0,195.987396240234,,,,,,,,,,,,,,,,,,,,,,,,,,,,,,,,,
,3865837017.66393,164.99658203125,26.4751167297363,1.7789955524042E-5,6.14519470014392E-9,1,5,12.9061126708984,4.982765494655,37.6599989831448,0.0231217656674046,0.0033588855216131,1,-2.85925415270325E-8,,,,,,,,,,,,,,,,,,,,,164.99658203125,164.99658203125,26.4751167297363,26.4751167297363,49.9081533956687,5.36392295479068,7.48885631561279,64,1,64,0,0,0.269088745117187,31.2805480957031,2,1,1,164.99658203125,0,164.99658203125,,,,,,,,,,,,,,,,,,,,,,,,,,,,,,,,,
,3865837204.83296,133.857696533203,26.4751167297363,1.80385718128759E-5,5.80648618477186E-9,1,5,12.9061126708984,4.98267855993458,37.5699996948242,0.0234440306335153,0.00340771022450555,1,-2.74779541585553E-8,,,,,,,,,,,,,,,,,,,,,133.857696533203,133.857696533203,26.4751167297363,26.4751167297363,49.8241283298514,5.36289540009594,7.40662240982056,65,1,0,0,1,0.2691650390625,31.7693061828613,2,1,1,133.857696533203,0,133.857696533203,,,,,,,,,,,,,,,,,,,,,,,,,,,,,,,,,
,3865837389.89366,102.852279663086,26.4751167297363,1.78569125344519E-5,5.9361611197004E-9,1,5,12.9061126708984,4.98270546919309,37.4899990856647,0.0232076670246074,0.00337644200597373,1,-2.48740689247078E-8,,,,,,,,,,,,,,,,,,,,,102.852279663086,102.852279663086,26.4751167297363,26.4751167297363,49.8217834442937,5.36126340861784,7.29873847961426,63,1,64,0,0,0.269851684570313,31.2805480957031,2,1,1,102.852279663086,0,102.852279663086,,,,,,,,,,,,,,,,,,,,,,,,,,,,,,,,,
,3865837573.31094,71.998908996582,26.4751167297363,1.83151102371026E-5,5.82118375417038E-9,1,5,12.9061126708984,4.98287512409409,37.4099984765053,0.0238059883533857,0.00345175844240977,1,-3.43520750934536E-8,,,,,,,,,,,,,,,,,,,,,71.998908996582,71.998908996582,26.4751167297363,26.4751167297363,49.8698535982264,5.36045563367422,7.14184236526489,64,1,64,0,0,0.268020629882813,31.2805480957031,2,1,1,71.998908996582,0,71.998908996582,,,,,,,,,,,,,,,,,,,,,,,,,,,,,,,,,
,3865837755.23516,40.9973297119141,26.4751167297363,1.84747489753037E-5,6.34715206395445E-9,1,5,12.9061126708984,4.9831212543733,37.3499989509583,0.024013938450615,0.00349035826465617,1,-2.82862712921322E-8,,,,,,,,,,,,,,,,,,,,,40.9973297119141,40.9973297119141,26.4751167297363,26.4751167297363,49.9245675945726,5.35945287629039,6.83217620849609,65,1,0,0,1,0.267562866210938,31.7693061828613,2,1,1,40.9973297119141,0,40.9973297119141,,,,,,,,,,,,,,,,,,,,,,,,,,,,,,,,,
,3865837939.91948,9.98263549804687,26.4751167297363,1.95731326747472E-5,7.02408905097667E-9,1,5,12.9061126708984,4.98326026782094,37.3100005090237,0.0254410650573665,0.00370875186883971,1,-2.17072293995421E-8,,,,,,,,,,,,,,,,,,,,,9.98263549804687,9.98263549804687,26.4751167297363,26.4751167297363,49.9710744914668,5.35929191782092,5.41441106796265,65,1,0,0,1,0.266799926757813,31.7693061828613,6,1,1,9.98263549804687,0,9.98263549804687,,,,,,,,,,,,,,,,,,,,,,,,,,,,,,,,,
,3865838553.30646,23.0386924743652,26.4751167297363,1.89249352055931E-5,5.75559911838166E-9,1,5,12.9061126708984,4.98330301222892,37.2899994254112,0.0245988111542761,0.00358615308711263,1,-2.08501587637476E-8,,,,,,,,,,,,,,,,,,,,,23.0386924743652,23.0386924743652,26.4751167297363,26.4751167297363,49.8401517144957,5.3598935198068,5.76043462753296,65,1,0,0,1,0.268096923828125,31.7693061828613,2,1,1,23.0386924743652,0,23.0386924743652,,,,,,,,,,,,,,,,,,,,,,,,,,,,,,,,,
,3865838752.01437,54.0492935180664,26.4751167297363,1.836704958861E-5,6.13705382820571E-9,1,5,12.9061126708984,4.98332402450448,37.3100005090237,0.0238760079614259,0.0034654801841259,1,-3.17603893108418E-8,,,,,,,,,,,,,,,,,,,,,54.0492935180664,54.0492935180664,26.4751167297363,26.4751167297363,49.8995554819572,5.36041427778866,6.47899293899536,65,1,0,0,1,0.269851684570313,31.7693061828613,2,1,1,54.0492935180664,0,54.0492935180664,,,,,,,,,,,,,,,,,,,,,,,,,,,,,,,,,
,3865838946.08686,85.0481491088867,26.4751167297363,1.77865700586533E-5,6.2978721085562E-9,1,5,12.9061126708984,4.98319430015106,37.3499989509583,0.0231215658150628,0.00334909131228757,1,-3.59443068302359E-8,,,,,,,,,,,,,,,,,,,,,85.0481491088867,85.0481491088867,26.4751167297363,26.4751167297363,49.9323838797649,5.36100921880212,6.75866317749023,65,1,0,0,1,0.268325805664062,32.7468223571777,2,1,1,85.0481491088867,0,85.0481491088867,,,,,,,,,,,,,,,,,,,,,,,,,,,,,,,,,
,3865839134.54806,116.004333496094,26.4751167297363,1.72466789272869E-5,6.5595342897813E-9,1,5,12.9061126708984,4.98315574387682,37.4200008809567,0.0224189171045297,0.00325131951345138,1,-3.18357638007521E-8,,,,,,,,,,,,,,,,,,,,,116.004333496094,116.004333496094,26.4751167297363,26.4751167297363,49.9816264764764,5.36156638601393,6.89915037155151,65,1,0,0,1,0.268630981445313,31.2805480957031,2,1,1,116.040725708008,0,116.004333496094,,,,,,,,,,,,,,,,,,,,,,,,,,,,,,,,,
,3865839322.50561,147.227798461914,26.4751167297363,1.6766431464475E-5,6.75817843083028E-9,1,5,12.9061126708984,4.98329536513571,37.5100001692772,0.0217954065834791,0.00316156219965117,1,-3.04461800577842E-8,,,,,,,,,,,,,,,,,,,,,147.227798461914,147.227798461914,26.4751167297363,26.4751167297363,49.8976014106591,5.36083444061778,6.98799228668213,65,1,0,0,1,0.268783569335938,31.7693061828613,2,1,1,147.227798461914,0,147.227798461914,,,,,,,,,,,,,,,,,,,,,,,,,,,,,,,,,
,3865839508.70708,178.020233154297,26.4751167297363,1.61059306166668E-5,6.32695011439959E-9,1,5,12.9061126708984,4.98307322250531,37.6100018620491,0.0209351118826724,0.00303934146243979,1,-2.73100224209926E-8,,,,,,,,,,,,,,,,,,,,,178.020233154297,178.020233154297,26.4751167297363,26.4751167297363,49.9742010055438,5.3619593423787,7.05640602111816,64,1,64,0,0,0.268707275390625,31.7693061828613,2,1,1,178.020233154297,0,178.020233154297,,,,,,,,,,,,,,,,,,,,,,,,,,,,,,,,,
,3865839696.06539,209.137756347656,26.4751167297363,1.53957625406059E-5,6.60379758979788E-9,1,5,12.9061126708984,4.98294104191997,37.7499982714653,0.0200118764102177,0.00290103554290685,1,-2.93242169578417E-8,,,,,,,,,,,,,,,,,,,,,209.137756347656,209.137756347656,26.4751167297363,26.4751167297363,49.8323354293033,5.36295729347267,7.14971542358398,64,1,64,0,0,0.269012451171875,30.7917900085449,2,1,1,209.137756347656,0,209.137756347656,,,,,,,,,,,,,,,,,,,,,,,,,,,,,,,,,
,3865839882.67271,240.031768798828,26.4751167297363,1.468641596283E-5,6.81578011494611E-9,1,5,12.9061126708984,4.98262880581802,37.8899984061718,0.0190871685383314,0.00277391453603812,1,-2.27509861332912E-8,,,,,,,,,,,,,,,,,,,,,240.031768798828,240.031768798828,26.4751167297363,26.4751167297363,49.9355103938418,5.36530692949311,7.28666639328003,63,1,64,0,0,0.269393920898438,30.3030319213867,2,1,1,240.031768798828,0,240.031768798828,,,,,,,,,,,,,,,,,,,,,,,,,,,,,,,,,
,3865840070.11866,271.212127685547,26.4751167297363,1.39854802620741E-5,7.72819152880552E-9,1,5,12.9061126708984,4.9818773070354,38.0599983036518,0.0181734678544644,0.00263333025895735,1,-2.75418623433621E-8,,,,,,,,,,,,,,,,,,,,,271.212127685547,271.212127685547,26.4751167297363,26.4751167297363,49.9644306490534,5.36729463688442,7.51201152801514,64,1,64,0,0,0.270462036132813,31.2805480957031,2,1,1,271.212127685547,0,271.212127685547,,,,,,,,,,,,,,,,,,,,,,,,,,,,,,,,,
,3865840413.61413,300.005142211914,50000.328125,0.0105746029082574,9.79819147515056E-7,1,2,12.9061126708984,4.98199739229482,38.2199995219708,13.7386505053096,2.01164877174758,10,-5.05549837304614E-6,,,,,,,,,,,,,,,,,,,,,300.005096435547,300.005187988281,50000.328125,50000.328125,49.8014611027937,5.36663404713055,7.40910577774048,26,1,0,0,1,0.27008056640625,31.7693061828613,1,6,1,300.005187988281,0,300.005142211914,,,,,,,,,,,,,,,,,,,,,,,,,,,,,,,,,
,3865840503.05851,300.003845214844,41097.216796875,0.00873420653155086,3.38925589813934E-6,1,2,12.9061126708984,4.98198874472463,38.2199995219708,11.351871668063,1.63217530345282,100,-2.67782874982877E-5,,,,,,,,,,,,,,,,,,,,,300.003479003906,300.004211425781,41007.3984375,41187.03515625,49.8893943112072,5.36674804264819,7.4556565284729,26,1,0,0,1,0.271759033203125,31.7693061828613,1,6,1,300.003479003906,0,300.003845214844,,,,,,,,,,,,,,,,,,,,,,,,,,,,,,,,,
,3865840571.71246,300.003677368164,34237.923828125,0.00730445515060058,2.86495461670335E-6,1,2,12.9061126708984,4.9819719814636,38.2199995219708,9.49378063128207,1.36358963519855,100,-2.3471888814543E-5,,,,,,,,,,,,,,,,,,,,,300.003570556641,300.003784179687,34158.06640625,34317.78125,49.7447930351495,5.36727565023245,7.52311420440674,26,1,0,0,1,0.272293090820313,32.2580642700195,1,6,1,300.003753662109,0,300.003677368164,,,,,,,,,,,,,,,,,,,,,,,,,,,,,,,,,
,3865840640.0611,300.002319335937,27419.0712890625,0.00587486158521924,2.61418462306882E-6,1,2,12.9061126708984,4.9820116427319,38.2199995219708,7.63543939341133,1.09909966779004,100,-1.70513886894984E-5,,,,,,,,,,,,,,,,,,,,,300.002288818359,300.002349853516,27329.2421875,27508.900390625,49.829599729486,5.36720594484979,7.62586069107056,26,1,0,0,1,0.270767211914062,31.2805480957031,1,6,1,300.002349853516,0,300.002319335937,,,,,,,,,,,,,,,,,,,,,,,,,,,,,,,,,
,3865840708.82818,300.003067016602,20550.5693359375,0.00444502988133847,2.62459373754455E-6,1,2,12.9061126708984,4.98207022696909,38.2199995219708,5.77752147477272,0.829502272072325,100,-1.45261460966398E-5,,,,,,,,,,,,,,,,,,,,,300.002899169922,300.003234863281,20430.642578125,20670.49609375,49.888612682688,5.36710753327056,7.75741004943848,26,1,0,0,1,0.2703857421875,32.2580642700195,1,6,1,300.002899169922,0,300.003067016602,,,,,,,,,,,,,,,,,,,,,,,,,,,,,,,,,
,3865840779.04091,300.002777099609,13542.3544921875,0.00296714107896975,2.80136894399779E-6,1,2,12.9061126708984,4.9820189426245,38.2199995219708,3.85674170571679,0.552385192061105,100,-1.07088242601783E-5,,,,,,,,,,,,,,,,,,,,,300.002716064453,300.002838134766,13452.5673828125,13632.1416015625,49.6928147386206,5.36739600203104,7.92718362808228,26,1,0,0,1,0.272674560546875,31.7693061828613,1,6,1,300.002716064453,0,300.002777099609,,,,,,,,,,,,,,,,,,,,,,,,,,,,,,,,,
,3865840847.69407,300.000503540039,6682.5224609375,0.00153039763685037,2.319977490267E-6,1,2,12.9061126708984,4.98205258354728,38.2199995219708,1.99067387901692,0.27526448579121,100,-1.29502462511622E-5,,,,,,,,,,,,,,,,,,,,,300.000213623047,300.000793457031,6607.62255859375,6757.42236328125,49.9472348216303,5.36729286839231,8.10555648803711,26,1,0,0,1,0.270843505859375,31.7693061828613,1,6,1,300.000793457031,0,300.000503540039,,,,,,,,,,,,,,,,,,,,,,,,,,,,,,,,,
,3865840916.02968,300.000640869141,-148.302024841309,-3.60777348069459E-5,4.14180571209333E-6,1,2,12.9061126708984,4.98188768558953,38.2199995219708,-0.0424337353024065,-0.0370679510998371,100,-2.32337764311965E-5,,,,,,,,,,,,,,,,,,,,,300.000366210937,300.000915527344,-238.288589477539,-58.3154602050781,49.9222227090149,5.3678029118585,8.24015522003174,26,1,0,0,1,0.270309448242187,32.2580642700195,1,6,1,300.000366210937,0,300.000640869141,,,,,,,,,,,,,,,,,,,,,,,,,,,,,,,,,
,3865840998.63546,300.000564575195,-8405.74267578125,-0.00188917675563517,2.25045169215863E-6,1,2,12.9061126708984,4.98186758826659,38.2199995219708,-2.4541409345398,-0.3608033060367,10,-1.98269179677638E-7,,,,,,,,,,,,,,,,,,,,,300.000457763672,300.000671386719,-8495.69140625,-8315.7939453125,49.8999462962168,5.3681568427252,8.16932487487793,26,1,0,0,1,0.270233154296875,31.7693061828613,1,6,1,300.000671386719,0,300.000564575195,,,,,,,,,,,,,,,,,,,,,,,,,,,,,,,,,
,3865841069.44441,300.000442504883,-15486.4204101562,-0.00337140581656392,2.57678715083053E-6,1,2,12.9061126708984,4.98191371777032,38.2199995219708,-4.38072962533238,-0.636832732367499,10,5.08197147110994E-6,,,,,,,,,,,,,,,,,,,,,300.000244140625,300.000640869141,-15546.4345703125,-15426.40625,49.812403902063,5.36782366569773,8.11526870727539,26,1,0,0,1,0.269851684570313,32.2580642700195,1,6,1,300.000244140625,0,300.000442504883,,,,,,,,,,,,,,,,,,,,,,,,,,,,,,,,,
,3865841167.34032,300.000671386719,-25276.9921875,-0.00539452658290842,2.97339640788405E-6,1,2,12.9061126708984,4.981671219075,38.2199995219708,-7.00884523229736,-1.02029613170781,10,7.06837208935158E-6,,,,,,,,,,,,,,,,,,,,,300.000671386719,300.000671386719,-25276.9921875,-25276.9921875,49.865163827111,5.36862520934227,8.0737361907959,25,1,68,0,0,0.2728271484375,32.2580642700195,1,6,1,300.000671386719,0,300.000671386719,,,,,,,,,,,,,,,,,,,,,,,,,,,,,,,,,
,3865841260.74415,300.000595092773,-34638.16015625,-0.00738095272002669,2.57553921830547E-6,1,2,12.9061126708984,4.98170967285606,38.2199995219708,-9.59005386233775,-1.39439476973915,100,1.09183179788807E-5,,,,,,,,,,,,,,,,,,,,,300.000457763672,300.000732421875,-34713.2421875,-34563.078125,49.8401517144957,5.36840772352871,8.03299617767334,26,1,0,0,1,0.270538330078125,32.2580642700195,1,6,1,300.000457763672,0,300.000595092773,,,,,,,,,,,,,,,,,,,,,,,,,,,,,,,,,
,3865841329.01083,300.000518798828,-41475.939453125,-0.00881184849527721,2.74356800462019E-6,1,2,12.9061126708984,4.98171228441487,38.2199995219708,-11.4486757843711,-1.66843383766538,100,1.01744418790794E-5,,,,,,,,,,,,,,,,,,,,,300.000305175781,300.000732421875,-41566.08203125,-41385.796875,49.6947688099187,5.36773081441147,8.0153636932373,26,1,0,0,1,0.272369384765625,31.7693061828613,1,6,1,300.000305175781,0,300.000518798828,,,,,,,,,,,,,,,,,,,,,,,,,,,,,,,,,
,3865841397.86672,300.000930786133,-48373.166015625,-0.0102409815695653,3.02432176232493E-6,1,2,12.9061126708984,4.98172132609986,38.2199995219708,-13.3054890152118,-1.93904869917134,100,1.18106224737958E-5,,,,,,,,,,,,,,,,,,,,,300.000854492188,300.001007080078,-48498.30078125,-48248.03125,49.6220773576303,5.36778232398258,8.00246906280518,26,1,0,0,1,0.27313232421875,31.7693061828613,1,6,1,300.001007080078,0,300.000930786133,,,,,,,,,,,,,,,,,,,,,,,,,,,,,,,,,
,3865841468.06247,300.001129150391,-45180.734375,-0.00960058608607789,2.8464435554262E-6,1,2,12.9061126708984,4.98173428722534,38.2199995219708,-12.478386248893,-1.78459226964734,100,3.66368512473663E-5,,,,,,,,,,,,,,,,,,,,,300.001037597656,300.001220703125,-45270.51953125,-45090.94921875,49.7096197517841,5.36772734917525,7.98536109924316,25,1,68,0,0,0.271072387695313,31.7693061828613,1,6,1,300.001037597656,0,300.001129150391,,,,,,,,,,,,,,,,,,,,,,,,,,,,,,,,,
,3865841534.73323,299.999969482422,-38528.68359375,-0.0082094223963479,3.33930650963054E-6,1,2,12.9061126708984,4.98180492090401,38.2199995219708,-10.6692201522069,-1.53426559984322,100,2.49868173338706E-5,,,,,,,,,,,,,,,,,,,,,299.99951171875,300.000427246094,-38643.46484375,-38413.90234375,49.847967999688,5.3674623623776,7.98282766342163,26,1,0,0,1,0.27069091796875,31.7693061828613,1,6,1,300.000427246094,0,299.999969482422,,,,,,,,,,,,,,,,,,,,,,,,,,,,,,,,,
,3865841604.99902,300.000076293945,-31516.890625,-0.00673982089978114,3.10000697338247E-6,1,2,12.9061126708984,4.98181260043754,38.2199995219708,-8.75904376343881,-1.26135347348041,100,1.91742681989831E-5,,,,,,,,,,,,,,,,,,,,,299.999877929687,300.000274658203,-31606.67578125,-31427.10546875,49.8604740559957,5.36787475695332,7.9654278755188,26,1,0,0,1,0.270614624023438,32.2580642700195,1,6,1,299.999877929687,0,300.000076293945,,,,,,,,,,,,,,,,,,,,,,,,,,,,,,,,,
,3865841673.70517,300.000610351562,-24659.421875,-0.0053060702790724,2.82653756570873E-6,1,2,12.9061126708984,4.98161393798714,38.2199995219708,-6.89547700692415,-0.992181217575536,100,1.57043141026629E-5,,,,,,,,,,,,,,,,,,,,,300.000549316406,300.000671386719,-24729.30078125,-24589.54296875,49.7846560896303,5.36882448958247,7.96292209625244,24,1,68,0,0,0.272445678710938,31.7693061828613,1,6,1,300.000549316406,0,300.000610351562,,,,,,,,,,,,,,,,,,,,,,,,,,,,,,,,,
,3865841739.97949,300.001754760742,-18041,-0.00391527670045482,2.81119463973586E-6,1,2,12.9061126708984,4.98171324088408,38.2199995219708,-5.08820762615144,-0.73222680590338,100,1.15192233193072E-5,,,,,,,,,,,,,,,,,,,,,300.001190185547,300.002319335937,-18130.85546875,-17951.14453125,49.9163604951207,5.36825823972586,7.95481395721436,26,1,0,0,1,0.270462036132813,31.7693061828613,1,6,1,300.001190185547,0,300.001754760742,,,,,,,,,,,,,,,,,,,,,,,,,,,,,,,,,
,3865841808.5246,300.002090454102,-11197.2006835938,-0.00248139316919465,2.29364088714907E-6,1,2,12.9061126708984,4.98165702646448,38.2199995219708,-3.22561243303409,-0.457934777364645,100,1.20140404190417E-5,,,,,,,,,,,,,,,,,,,,,300.002014160156,300.002166748047,-11292.0888671875,-11102.3125,49.7850469038899,5.36823636807853,7.95012760162354,26,1,0,0,1,0.2734375,31.7693061828613,1,6,1,300.002014160156,0,300.002090454102,,,,,,,,,,,,,,,,,,,,,,,,,,,,,,,,,
,3865841875.34207,299.999801635742,-4522.38745117188,-0.00108125862974651,2.87689882571261E-6,1,2,12.9061126708984,4.9816365139076,38.2199995219708,-1.40714081586226,-0.188656117634829,100,1.3615635566811E-5,,,,,,,,,,,,,,,,,,,,,299.999542236328,300.000061035156,-4637.14404296875,-4407.630859375,49.7846560896303,5.36853946863276,7.93821907043457,25,1,68,0,0,0.272140502929687,31.7693061828613,1,6,1,299.999542236328,0,299.999801635742,,,,,,,,,,,,,,,,,,,,,,,,,,,,,,,,,
,3865841945.47262,299.999176025391,2488.62963867187,0.000631348137246514,2.50730971633163E-6,1,2,12.9061126708984,4.98156773191572,38.2199995219708,0.818734001382762,0.129766042534753,100,7.14774790768339E-6,,,,,,,,,,,,,,,,,,,,,299.999145507812,299.999206542969,2398.6806640625,2578.57861328125,49.8690719697072,5.3681517833129,7.93632650375366,26,1,0,0,1,0.272216796875,31.7693061828613,1,6,1,299.999145507812,0,299.999176025391,,,,,,,,,,,,,,,,,,,,,,,,,,,,,,,,,
,3865842025.19844,299.999816894531,10458.3349609375,0.00229843011085992,2.61553859212454E-6,1,2,12.9061126708984,4.9816422924255,38.2199995219708,2.98614244703602,0.435196365700214,10,-2.63797589295463E-6,,,,,,,,,,,,,,,,,,,,,299.999816894531,299.999816894531,10458.3349609375,10458.3349609375,50.0050753320534,5.36783984729756,7.92429113388062,26,1,0,0,1,0.272216796875,31.7693061828613,1,6,1,299.999816894531,0,299.999816894531,,,,,,,,,,,,,,,,,,,,,,,,,,,,,,,,,
,3865842128.4412,299.998962402344,20790.587890625,0.00445485608567864,2.90758864273118E-6,1,2,12.9061126708984,4.98163621926223,38.2199995219708,5.78800321143358,0.841996669652784,10,-6.27297681755706E-6,,,,,,,,,,,,,,,,,,,,,299.998962402344,299.998962402344,20790.587890625,20790.587890625,49.8698535982264,5.36821031261589,7.91719150543213,25,1,68,0,0,0.272445678710938,31.2805480957031,1,6,1,299.998962402344,0,299.998962402344,,,,,,,,,,,,,,,,,,,,,,,,,,,,,,,,,
,3865842211.41444,300.000411987305,29092.8505859375,0.00623015334223702,3.02859810086238E-6,1,2,12.9061126708984,4.98153806100855,38.2299982011318,8.09528766367478,1.17110050595782,100,-1.37046595127016E-5,,,,,,,,,,,,,,,,,,,,,300.000213623047,300.000610351562,28997.736328125,29187.96484375,50.0179722026207,5.36879943296542,7.91325092315674,26,1,0,0,1,0.27435302734375,31.7693061828613,1,6,1,300.000610351562,0,300.000411987305,,,,,,,,,,,,,,,,,,,,,,,,,,,,,,,,,
,3865842278.27572,299.999267578125,35791.7265625,0.00762075434683577,3.05004480428824E-6,1,2,12.9061126708984,4.98142465614518,38.2199995219708,9.90101375049697,1.43833973564581,100,-1.22293086347492E-5,,,,,,,,,,,,,,,,,,,,,299.999176025391,299.999359130859,35671.63671875,35911.81640625,49.8917391967649,5.3688707159092,7.91576957702637,26,1,0,0,1,0.27374267578125,31.7693061828613,1,6,1,299.999176025391,0,299.999267578125,,,,,,,,,,,,,,,,,,,,,,,,,,,,,,,,,
,3865842350.54735,299.999862670898,43036.818359375,0.00913642237766065,3.20906826081847E-6,1,2,12.9061126708984,4.98130656378477,38.2199995219708,11.8690739596109,1.72929055138556,100,-1.08571817341727E-5,,,,,,,,,,,,,,,,,,,,,299.999603271484,300.000122070313,42926.78125,43146.85546875,49.837806828938,5.3688372370281,7.91523361206055,26,1,0,0,1,0.27191162109375,32.2580642700195,1,6,1,300.000122070313,0,299.999862670898,,,,,,,,,,,,,,,,,,,,,,,,,,,,,,,,,
,3865842417.03678,300.000305175781,49695.90625,0.0105269733618627,2.66712382197287E-6,1,2,12.9061126708984,4.98123689545321,38.2199995219708,13.6757296604541,1.98926319346585,100,-1.49609227482701E-5,,,,,,,,,,,,,,,,,,,,,300,300.000610351562,49620.73828125,49771.07421875,49.9132339810437,5.36898588420589,7.90462207794189,26,1,0,0,1,0.273208618164062,31.7693061828613,1,6,1,300,0,300.000305175781,,,,,,,,,,,,,,,,,,,,,,,,,,,,,,,,,
,3865842423.00541,300.000411987305,50000.208984375,0.0105944949005969,9.72172269283199E-7,1,2,12.9061126708984,4.98133381393467,38.2199995219708,13.7630816632594,2.00713176172176,100,-1.11655321855212E-5,,,,,,,,,,,,,,,,,,,,,300.000335693359,300.00048828125,50000.1640625,50000.25390625,49.6650669261879,5.36859672518035,7.91162014007568,26,1,0,0,1,0.2734375,32.2580642700195,1,4,1,300.000671386719,0,300.000411987305,,,,,,,,,,,,,,,,,,,,,,,,,,,,,,,,,