File: LT data/Bridport/K1/280_FULL_SEQUENCE.dat
[Header]
; MPMS3 Data File (default extension .dat)
; Copyright (c) 2007, Quantum Design, Inc. All rights reserved.
TITLE,
FILEOPENTIME,3872832730.18004,09/20/2022,1:03 pm
BYAPP,MPMS3 w/ AC,1.0,1.1
INFO,MPMS3 Measurement Release 1.1.16 Build 424, MultiVu Release 2.3.4.19,APPNAME
INFO,Linear Motor Servo Controller,MOTOR_MODULE_NAME
INFO,3101-100 N0,MOTOR_HW_VERSION
INFO,MMC1047,MOTOR_SERIAL_NUMBER
INFO,01.04.28,MOTOR_SOFTWARE_VERSION
INFO,Quantum Design Squid Module,SQUID_MODULE_NAME
INFO,3101-501 B0,SQUID_HW_VERSION
INFO,SQM278,SQUID_SERIAL_NUMBER
INFO,01.03.04,SQUID_SOFTWARE_VERSION
INFO,Quantum Design VSM Oven,OVEN_MODULE_NAME
INFO,3101-201 A3,OVEN_HW_VERSION
INFO,OVB323,OVEN_SERIAL_NUMBER
INFO,01.07.07,OVEN_SOFTWARE_VERSION
INFO,SQUID AC,AC_MODULE_NAME
INFO,3101-401 G0,AC_HW_VERSION
INFO,SAC258,AC_SERIAL_NUMBER
INFO,SQUID AC 00.95.07,AC_SOFTWARE_VERSION
INFO,TCI127,COIL_SERIAL_NUMBER
INFO,0,MOMENT_UNITS
INFO,sndst,SAMPLE_MATERIAL
INFO,,SAMPLE_COMMENT
INFO,,SAMPLE_MASS
INFO,,SAMPLE_VOLUME
INFO,,SAMPLE_MOLECULAR_WEIGHT
INFO,,SAMPLE_SIZE
INFO,,SAMPLE_SHAPE
INFO,Straw,SAMPLE_HOLDER
INFO,Standard,SAMPLE_HOLDER_DETAIL
INFO,66,SAMPLE_OFFSET
DATATYPE,COMMENT,1
DATATYPE,TIME,2
STARTUPAXIS,X,2
STARTUPAXIS,Y1,5
FIELDGROUP, VSM,2,3,4,5,6,8,9,10,11,14,15
FIELDGROUP, DC, 2,3,4,14,56,57,58,59,60,61,62,63,64,65,66,67,68,69
FIELDGROUP, AC, 2,3,4,11,16,17,18,19,20,21,22,23,24,25,26,27,28,29,30
STARTUPGROUP, All
[Data]
Comment,Time Stamp (sec),Temperature (K),Magnetic Field (Oe),Moment (emu),M. Std. Err. (emu),Transport Action,Averaging Time (sec),Frequency (Hz),Peak Amplitude (mm),Center Position (mm),Lockin Signal' (V),Lockin Signal (V),Range,M. Quad. Signal (emu),AC Moment (emu),AC M. Std Err. (emu),AC Phase (deg),AC Phase Std. Err. (deg),AC Susceptibility (emu/Oe),AC Suscept. Std Err. (emu/Oe),AC X' (emu/Oe),AC X' Std Err. (emu/Oe),AC X'' (emu/Oe),AC X'' Std Err. (emu/Oe),AC Drive (Oe),AC Frequency (Hz),AC Averaging Time (sec),AC Cycles,AC Range,AC Measure Type,AC Signal' (V),AC Signal'' (V),AC Trim Coil Ratio,AC Trim Coil Phase,Min. Temperature (K),Max. Temperature (K),Min. Field (Oe),Max. Field (Oe),Mass (grams),Motor Lag (deg),Pressure (Torr),Measure Count,Measurement Number,SQUID Status (code),Motor Status (code),Measure Status (code),Motor Current (amps),Motor Temp. (C),Temp. Status (code),Field Status (code),Chamber Status (code),Chamber Temp (K),Redirection State,Evercool Status,Average Temp (K),Rotation Angle (deg),Rotator state,DC Moment Fixed Ctr (emu),DC Moment Err Fixed Ctr (emu),DC Moment Free Ctr (emu),DC Moment Err Free Ctr (emu),DC Fixed Fit,DC Free Fit,DC Calculated Center (mm),DC Calculated Center Err (mm),DC Scan Length (mm),DC Scan Time (s),DC Number of Points,DC Squid Drift,DC Min V (V),DC Max V (V),DC Scans per Measure,Map 01,Map 02,Map 03,Map 04,Map 05,Map 06,Map 07,Map 08,Map 09,Map 10,Map 11,Map 12,Map 13,Map 14,Map 15,Map 16
"FC",3872833173.81996
,3872834035.26714,86.4524040222168,49999.70703125,0.0303933511261209,8.22579339910228E-6,1,2,13.1008939743042,4.99716420187683,41.4399988949299,35.2918587514659,5.18575899259271,100,1.14888418601261E-5,,,,,,,,,,,,,,,,,,,,,86.3192520141602,86.5855560302734,49999.70703125,49999.70703125,52.5793688601402,5.72856402758678,7.65086889266968,26,1,0,0,1,0.3021240234375,32.7468223571777,2,1,1,86.3192520141602,0,2084573184,86.4524040222168,,,,,,,,,,,,,,,,,,,,,,,,,,,,,,,,,
,3872834180.21527,62.0982456207275,49999.70703125,0.0434655381666578,0.000128648843333168,1,2,13.1008939743042,4.99631033085044,41.3599982857704,50.4712311317892,7.32971430064801,1000,-5.64983664682997E-5,,,,,,,,,,,,,,,,,,,,,61.9365539550781,62.2599372863769,49999.70703125,49999.70703125,52.6950498809863,5.73224674440103,7.44586133956909,26,1,0,0,1,0.298233032226562,32.7468223571777,2,1,1,61.9365539550781,0,2084573184,62.0982456207275,,,,,,,,,,,,,,,,,,,,,,,,,,,,,,,,,
,3872834309.13317,40.1205425262451,49999.70703125,0.0663100667862554,2.67482415025766E-5,1,2,13.1008939743042,4.99579612463991,41.3199998438358,76.9729105304302,11.2745569676526,1000,-5.11206315720681E-6,,,,,,,,,,,,,,,,,,,,,39.9601783752441,40.2809066772461,49999.70703125,49999.70703125,52.6755091680056,5.7333430087227,7.10553503036499,26,1,0,0,1,0.300445556640625,33.2355842590332,2,1,1,39.9601783752441,0,2084573184,40.1205425262451,,,,,,,,,,,,,,,,,,,,,,,,,,,,,,,,,
,3872834424.28835,20.6809453964233,49999.70703125,0.109574477276399,0.000140272272424315,1,2,13.1008939743042,4.99514436550345,41.2800014019012,127.143896401548,18.813112845042,1000,0.000151649402808241,,,,,,,,,,,,,,,,,,,,,20.5465354919434,20.8153553009033,49999.70703125,49999.70703125,52.7282690930537,5.73640816616827,6.37007522583008,26,1,0,0,1,0.299758911132812,33.2355842590332,2,1,1,20.5465354919434,0,2084573184,20.6809453964233,,,,,,,,,,,,,,,,,,,,,,,,,,,,,,,,,
,3872834487.74835,10.508768081665,49999.70703125,0.154342458936952,0.000191608804786892,1,2,13.1008939743042,4.99437025469802,41.2600003182888,179.045506400936,26.5326567778387,1000,0.000247191710436788,,,,,,,,,,,,,,,,,,,,,10.3801174163818,10.6374187469482,49999.70703125,49999.70703125,52.9287568082364,5.74137007259619,5.22564077377319,26,1,0,0,1,0.3021240234375,33.7243423461914,2,1,1,10.3445711135864,0,2084573184,10.508768081665,,,,,,,,,,,,,,,,,,,,,,,,,,,,,,,,,
,3872834551.27704,1.99801200628281,49999.70703125,0.201186020567003,3.49042475283999E-5,1,2,13.1008939743042,4.99473764376388,41.2600003182888,233.433164872584,34.4348990030869,1000,0.000189431006263538,,,,,,,,,,,,,,,,,,,,,1.99596130847931,2.0000627040863,49999.70703125,49999.70703125,53.5411627530537,5.74304329533775,2.77679538726807,26,1,0,0,1,0.300674438476562,33.2355842590332,6,1,1,2.0000627040863,0,2084573184,1.99801200628281,,,,,,,,,,,,,,,,,,,,,,,,,,,,,,,,,
,3872834922.91479,2.29502654075623,26.1682205200195,0.00267113088915091,6.30443562634906E-6,1,5,13.1008939743042,4.98302638196856,41.2699989974499,3.0896504347584,0.451905730256044,1000,-7.55081049884818E-7,,,,,,,,,,,,,,,,,,,,,2.0180070400238,2.57204604148865,26.1682205200195,26.1682205200195,52.6035993442363,5.74046645625985,2.8248496055603,66,1,0,0,1,0.301055908203125,32.2580642700195,6,1,1,2.57204604148865,0,2084573184,2.29502654075623,,,,,,,,,,,,,,,,,,,,,,,,,,,,,,,,,
,3872835133.58948,34.0325164794922,26.1682205200195,0.000108325802855903,1.23383907951257E-7,1,5,13.1008939743042,4.98284193832895,41.2800014019012,0.125279349049809,0.0184124990213485,1,4.43725330691251E-8,,,,,,,,,,,,,,,,,,,,,34.0325164794922,34.0325164794922,26.1682205200195,26.1682205200195,52.7083375658133,5.74151520370426,6.36970710754394,66,1,0,0,1,0.299758911132812,32.7468223571777,2,1,1,34.0325164794922,0,2084573184,34.0325164794922,,,,,,,,,,,,,,,,,,,,,,,,,,,,,,,,,
,3872835337.3327,66.0215682983398,26.1682205200195,7.35725325590753E-5,1.82823912941358E-8,1,5,13.1008939743042,4.98216394545331,41.2999987602234,0.0850726597528681,0.0124901477013785,1,1.90366665868867E-8,,,,,,,,,,,,,,,,,,,,,66.0215682983398,66.0215682983398,26.1682205200195,26.1682205200195,52.6712102111498,5.74410620153133,6.8974175453186,66,1,0,0,1,0.30181884765625,33.2355842590332,2,1,1,66.0215682983398,0,2084573184,66.0215682983398,,,,,,,,,,,,,,,,,,,,,,,,,,,,,,,,,
,3872835534.63394,98.0118103027344,26.1682205200195,5.58670343843352E-5,7.65247289755151E-8,1,5,13.1008939743042,4.98147970555342,41.3599982857704,0.0646027309239093,0.00937635830866579,1,-7.73708001067354E-8,,,,,,,,,,,,,,,,,,,,,98.0118103027344,98.0118103027344,26.1682205200195,26.1682205200195,52.6176686575825,5.74674958920409,7.10687446594238,66,1,0,0,1,0.295257568359375,34.2131004333496,2,1,1,98.0118103027344,0,2084574112,98.0118103027344,,,,,,,,,,,,,,,,,,,,,,,,,,,,,,,,,
,3872835728.27925,130.017852783203,26.1682205200195,4.00225705712064E-5,2.69259388870963E-8,1,5,13.1008939743042,4.98174984441294,41.4399988949299,0.0462760346060832,0.00677372098402602,1,-6.921979539688E-9,,,,,,,,,,,,,,,,,,,,,130.017852783203,130.017852783203,26.1682205200195,26.1682205200195,52.6782448678229,5.74601973928995,7.23811483383179,64,1,64,0,0,0.294113159179687,33.2355842590332,2,1,1,130.017852783203,0,2084574080,130.017852783203,,,,,,,,,,,,,,,,,,,,,,,,,,,,,,,,,
,3872835921.73217,162.006408691406,26.1682205200195,2.88823432619513E-5,8.01119663878548E-9,1,5,13.1008939743042,4.98169012751349,41.5400005877018,0.0333923797348625,0.0049033519780957,1,8.12450338188025E-9,,,,,,,,,,,,,,,,,,,,,162.006408691406,162.006408691406,26.1682205200195,26.1682205200195,52.6884060385729,5.74598653508326,7.33261823654175,66,1,0,0,1,0.295333862304687,32.7468223571777,2,1,1,162.006408691406,0,2084574144,162.006408691406,,,,,,,,,,,,,,,,,,,,,,,,,,,,,,,,,
,3872836115.0705,194.034408569336,26.1682205200195,2.12739122415959E-5,7.91122168702854E-9,1,5,13.1008939743042,4.98038990460235,41.6599996387959,0.0245899913431947,0.0035890742239552,1,-1.24217940922181E-8,,,,,,,,,,,,,,,,,,,,,194.034408569336,194.034408569336,26.1682205200195,26.1682205200195,52.7567985340056,5.74800994065552,7.42724227905273,65,1,64,0,0,0.296783447265625,35.6793746948242,2,1,1,194.034408569336,0,2084574208,194.034408569336,,,,,,,,,,,,,,,,,,,,,,,,,,,,,,,,,
,3872836306.74864,226.006393432617,26.1682205200195,1.59981832882402E-5,9.95551260606377E-9,1,5,13.1008939743042,4.99092933853788,41.7999997735023,0.0185462845866553,0.00271042628896503,1,-6.40920365829764E-9,,,,,,,,,,,,,,,,,,,,,226.006393432617,226.006393432617,26.1682205200195,26.1682205200195,52.6915325526498,5.75143383890982,7.60839033126831,65,1,64,0,0,0.296554565429687,33.7243423461914,2,1,1,226.006393432617,0,2084574144,226.006393432617,,,,,,,,,,,,,,,,,,,,,,,,,,,,,,,,,
,3872836500.68746,258.040374755859,26.1682205200195,1.22723594752403E-5,7.77901344305407E-9,1,5,13.1008939743042,4.98861452184227,41.9699996709824,0.0142173825137971,0.00208061247956247,1,-2.5258828581607E-9,,,,,,,,,,,,,,,,,,,,,258.040374755859,258.040374755859,26.1682205200195,26.1682205200195,52.6286114568517,5.76049396303309,8.00689315795898,65,1,64,0,0,0.293655395507812,33.7243423461914,2,1,1,258.040374755859,0,2084574240,258.040374755859,,,,,,,,,,,,,,,,,,,,,,,,,,,,,,,,,
,3872836686.33589,288.864517211914,26.1682205200195,9.86933231335403E-6,7.12712178907612E-9,1,5,13.1008939743042,4.98686417488235,42.1499982476234,0.011427124271472,0.00167756392332001,1,2.43793029851005E-9,,,,,,,,,,,,,,,,,,,,,288.516296386719,289.212738037109,26.1682205200195,26.1682205200195,52.5418506912171,5.76866439228661,8.05466556549072,64,1,64,0,0,0.298995971679687,33.2355842590332,2,1,1,289.212738037109,0,2084574272,288.864517211914,,,,,,,,,,,,,,,,,,,,,,,,,,,,,,,,,
,3872838331.29539,1.99985474348068,44879.828125,0.194800986553083,4.81901939014198E-5,1,2,13.1008939743042,4.98982799473297,41.2600003182888,225.72958401737,33.1869791420237,1000,8.92169467449433E-5,,,,,,,,,,,,,,,,,,,,,1.99903571605682,2.00067377090454,44789.8828125,44969.7734375,53.386400306246,5.76043865133492,2.61489915847778,26,1,0,0,1,0.291748046875,33.7243423461914,1,6,1,2.00067377090454,0,2084573184,1.99985474348068,,,,,,,,,,,,,,,,,,,,,,,,,,,,,,,,,
,3872838394.78165,2.00005865097046,38538.32421875,0.185035855565435,4.77273557543521E-5,1,2,13.1008939743042,4.98983866865274,41.2600003182888,214.412592575753,31.5377192250147,1000,9.70564267970862E-5,,,,,,,,,,,,,,,,,,,,,1.99990010261536,2.00021719932556,38448.359375,38628.2890625,53.2734549852172,5.75930778993301,2.61297464370728,26,1,0,0,1,0.294113159179687,31.7693061828613,1,6,1,1.99990010261536,0,2084573184,2.00005865097046,,,,,,,,,,,,,,,,,,,,,,,,,,,,,,,,,
,3872838458.33774,1.99898409843445,32192.140625,0.172796343785274,3.2067224511095E-5,1,2,13.1008939743042,4.99039121021644,41.2600003182888,200.259370003742,29.4670887344936,1000,0.000100055173721805,,,,,,,,,,,,,,,,,,,,,1.99819684028626,1.99977135658264,32107.171875,32277.109375,53.1151752100729,5.75679300327074,2.60708832740784,26,1,0,0,1,0.292129516601562,31.2805480957031,1,6,1,1.99977135658264,0,2084573184,1.99898409843445,,,,,,,,,,,,,,,,,,,,,,,,,,,,,,,,,
,3872838521.78537,1.99989134073257,25856.1494140625,0.157128930808815,3.22190349933723E-5,1,2,13.1008939743042,4.99018905961785,41.2600003182888,182.089772834255,26.805955329701,1000,0.000101477692673455,,,,,,,,,,,,,,,,,,,,,1.99988496303558,1.99989771842957,25766.1171875,25946.181640625,53.015517573871,5.7558212301618,2.59297394752502,26,1,0,0,1,0.2923583984375,33.7243423461914,1,6,1,1.99989771842957,0,2084573184,1.99989134073257,,,,,,,,,,,,,,,,,,,,,,,,,,,,,,,,,
,3872838585.31611,1.9972767829895,19515.275390625,0.136913701743745,3.9976004418573E-5,1,2,13.1008939743042,4.98997847231475,41.2600003182888,158.657981419726,23.3277443524273,1000,6.41379964720215E-5,,,,,,,,,,,,,,,,,,,,,1.99693655967712,1.99761700630188,19425.23828125,19605.3125,52.9213313373037,5.75574441593269,2.5930609703064,26,1,0,0,1,0.293045043945313,33.7243423461914,1,6,1,1.99693655967712,0,2084573184,1.9972767829895,,,,,,,,,,,,,,,,,,,,,,,,,,,,,,,,,
,3872838648.82967,2.00015914440155,13168.9008789062,0.109946668191959,5.58401746803161E-5,1,2,13.1008939743042,4.99053306507472,41.2600003182888,127.428417177745,18.7327661465501,1000,4.87654516941969E-5,,,,,,,,,,,,,,,,,,,,,2.00001454353333,2.00030374526978,13083.8876953125,13253.9140625,52.741165963621,5.75318922172956,2.58583736419678,26,1,0,0,1,0.2972412109375,33.2355842590332,1,6,1,2.00030374526978,0,2084573184,2.00015914440155,,,,,,,,,,,,,,,,,,,,,,,,,,,,,,,,,
,3872838712.3175,1.99986451864243,6822.90966796875,0.0714698442559745,8.11214037703406E-5,1,2,13.1008939743042,4.99065320677193,41.2600003182888,82.8376893616602,12.1693053715011,1000,2.46496031633194E-5,,,,,,,,,,,,,,,,,,,,,1.99985468387604,1.99987435340881,6727.84130859375,6917.97802734375,52.6583133405825,5.75235286540832,2.57869124412537,25,1,68,0,0,0.291824340820313,33.2355842590332,1,6,1,1.99998617172241,0,2084573184,1.99986451864243,,,,,,,,,,,,,,,,,,,,,,,,,,,,,,,,,
,3872838775.93333,1.99977707862854,466.021774291992,0.00963299255778727,0.000138832781293156,1,2,13.1008939743042,4.99054267462851,41.2600003182888,11.1771907238296,1.55597005842279,1000,-6.93273567450333E-5,,,,,,,,,,,,,,,,,,,,,1.99924874305725,2.00030541419983,390.928741455078,541.114807128906,52.6528419409479,5.75209967196701,2.56884050369263,26,1,0,0,1,0.296630859375,33.2355842590332,1,6,1,1.99924874305725,0,2084573184,1.99977707862854,,,,,,,,,,,,,,,,,,,,,,,,,,,,,,,,,
,3872838851.37748,1.99997353553772,-7078.77563476563,-0.0707159285084465,8.1237673475897E-5,1,2,13.1008939743042,4.99050514039023,41.2600003182888,-81.9432040669058,-12.1581160768833,100,-0.000125920969512061,,,,,,,,,,,,,,,,,,,,,1.99964785575867,2.00029921531677,-7148.8193359375,-7008.73193359375,52.664957182996,5.75306539600573,2.57221245765686,26,1,0,0,1,0.291671752929687,32.7468223571777,1,6,1,2.00029921531677,0,2084573184,1.99997353553772,,,,,,,,,,,,,,,,,,,,,,,,,,,,,,,,,
,3872838914.73222,1.99989169836044,-13420.947265625,-0.110050760487753,5.78515280660179E-5,1,2,13.1008939743042,4.99038200944273,41.2600003182888,-127.517453782207,-18.9284679618322,100,-0.000203045653711786,,,,,,,,,,,,,,,,,,,,,1.99975216388702,2.00003123283386,-13510.9970703125,-13330.8974609375,52.829489986294,5.75334263291771,2.5659773349762,26,1,0,0,1,0.291519165039063,33.2355842590332,1,6,1,2.00003123283386,0,2084573184,1.99989169836044,,,,,,,,,,,,,,,,,,,,,,,,,,,,,,,,,
,3872839000.04832,2.00032234191895,-21953.4130859375,-0.144842087015787,4.17095714071382E-5,1,2,13.1008939743042,4.99007841849294,41.2600003182888,-167.847621933869,-24.6971772576502,1000,-8.32798250460261E-5,,,,,,,,,,,,,,,,,,,,,2.0001163482666,2.00052833557129,-22043.53125,-21863.294921875,52.8888937537556,5.7551190522844,2.55531573295593,26,1,0,0,1,0.292282104492188,33.2355842590332,1,6,1,2.0001163482666,0,2084573856,2.00032234191895,,,,,,,,,,,,,,,,,,,,,,,,,,,,,,,,,
,3872839063.59638,1.9996612071991,-28309.4921875,-0.163334458002047,3.41625330348745E-5,1,2,13.1008939743042,4.98997814018248,41.2600003182888,-189.273828288505,-27.8359891570089,1000,-8.22135609355505E-5,,,,,,,,,,,,,,,,,,,,,1.99950325489044,1.99981915950775,-28399.763671875,-28219.220703125,53.0385756151883,5.75608872970799,2.55165338516235,26,1,0,0,1,0.292816162109375,33.2355842590332,1,6,1,1.99950325489044,0,2084574144,1.9996612071991,,,,,,,,,,,,,,,,,,,,,,,,,,,,,,,,,
,3872839127.15824,1.99996334314346,-34677.953125,-0.177691762844697,3.39470377020302E-5,1,2,13.1008939743042,4.98989270118393,41.2600003182888,-205.907070796242,-30.2768017234642,1000,-8.4884453431683E-5,,,,,,,,,,,,,,,,,,,,,1.99995672702789,1.99996995925903,-34763.1875,-34592.71875,53.1878666623614,5.75661960382511,2.55632495880127,26,1,0,0,1,0.293350219726562,33.2355842590332,1,6,1,1.99995672702789,0,2084573824,1.99996334314346,,,,,,,,,,,,,,,,,,,,,,,,,,,,,,,,,
,3872839190.59081,2.00028169155121,-41036.166015625,-0.188868004874699,0.000145531170573373,1,2,13.1008939743042,4.98978312356586,41.2600003182888,-218.872686567683,-32.0337292870348,1000,3.61071479304302E-5,,,,,,,,,,,,,,,,,,,,,2.00018191337585,2.00038146972656,-41126.39453125,-40945.9375,53.3293414243422,5.75854940235785,2.54669117927551,26,1,0,0,1,0.293807983398438,33.2355842590332,1,6,1,2.00038146972656,0,2084573184,2.00028169155121,,,,,,,,,,,,,,,,,,,,,,,,,,,,,,,,,
,3872839254.07722,2.00016218423843,-47399.4375,-0.19795828794778,0.000114918187753731,1,2,13.1008939743042,4.98924298359613,41.2600003182888,-229.336360899899,-33.8157496224617,1000,-0.000173880957027278,,,,,,,,,,,,,,,,,,,,,1.99996912479401,2.00035524368286,-47489.6953125,-47309.1796875,53.5071619124672,5.76051165189307,2.5550274848938,26,1,0,0,1,0.293807983398438,33.2355842590332,1,6,1,1.99996912479401,0,2084574048,2.00016218423843,,,,,,,,,,,,,,,,,,,,,,,,,,,,,,,,,
,3872839319.58032,2.00011569261551,-46578.232421875,-0.197170130693298,2.16911938803652E-5,1,2,13.1008939743042,4.98907671755107,41.2600003182888,-228.430683794677,-33.5562047195716,1000,-6.67353608221455E-5,,,,,,,,,,,,,,,,,,,,,1.99987304210663,2.00035834312439,-46668.1953125,-46488.26953125,53.4411143025922,5.76106134261317,2.55369114875793,26,1,0,0,1,0.296096801757812,32.2580642700195,1,6,1,2.00035834312439,0,2084574016,2.00011569261551,,,,,,,,,,,,,,,,,,,,,,,,,,,,,,,,,
,3872839383.07118,2.00018298625946,-40238.76953125,-0.187944181734498,2.85588961944987E-5,1,2,13.1008939743042,4.98891501796649,41.2600003182888,-217.729561146406,-32.0019780015919,1000,-7.86156487224435E-5,,,,,,,,,,,,,,,,,,,,,1.99989581108093,2.00047016143799,-40328.73828125,-40148.80078125,53.3703769216018,5.7609851922386,2.55332398414612,26,1,0,0,1,0.294876098632812,33.2355842590332,1,6,1,1.99989581108093,0,2084573952,2.00018298625946,,,,,,,,,,,,,,,,,,,,,,,,,,,,,,,,,
,3872839446.63675,2.00006818771362,-33893.953125,-0.176439761183469,3.8140402846994E-5,1,2,13.1008939743042,4.988591290888,41.2600003182888,-204.386164016635,-30.0210492237649,1000,-5.71472365444734E-5,,,,,,,,,,,,,,,,,,,,,1.99989938735962,2.00023698806763,-33978.921875,-33808.984375,53.1585555928902,5.76150479965709,2.54841184616089,26,1,0,0,1,0.294723510742188,36.1681327819824,1,6,1,1.99989938735962,0,2084573824,2.00006818771362,,,,,,,,,,,,,,,,,,,,,,,,,,,,,,,,,
,3872839510.09784,2.00020051002502,-27553.734375,-0.161807552029772,3.33344089898942E-5,1,2,13.1008939743042,4.9883036770995,41.2600003182888,-187.421851161949,-27.5247781987173,1000,-4.86172283280538E-5,,,,,,,,,,,,,,,,,,,,,2.00017595291138,2.00022506713867,-27648.671875,-27458.796875,52.9897238327364,5.76171632560312,2.54563140869141,26,1,0,0,1,0.294342041015625,32.7468223571777,1,6,1,2.00022506713867,0,2084574112,2.00020051002502,,,,,,,,,,,,,,,,,,,,,,,,,,,,,,,,,
,3872839573.59263,2.00032877922058,-21218.6875,-0.14293899199083,4.22210283593514E-5,1,2,13.1008939743042,4.98874819487975,41.2600003182888,-165.585612983633,-24.3279471174236,1000,-5.14312678850755E-5,,,,,,,,,,,,,,,,,,,,,2.00010848045349,2.00054907798767,-21308.669921875,-21128.705078125,52.8959284104287,5.75934350508221,2.53715181350708,26,1,0,0,1,0.293731689453125,33.7243423461914,1,6,1,2.00010848045349,0,2084574304,2.00032877922058,,,,,,,,,,,,,,,,,,,,,,,,,,,,,,,,,
,3872839637.10741,2.00023198127747,-14874.1118164062,-0.11811711159377,5.29703199835009E-5,1,2,13.1008939743042,4.98852801857579,41.2600003182888,-136.823606005874,-20.0952147409733,1000,-3.65852237673679E-5,,,,,,,,,,,,,,,,,,,,,2.00012850761414,2.0003354549408,-14969.1005859375,-14779.123046875,52.8181563727652,5.75904811191703,2.53726148605347,26,1,0,0,1,0.29510498046875,32.7468223571777,1,6,1,2.0003354549408,0,2084573632,2.00023198127747,,,,,,,,,,,,,,,,,,,,,,,,,,,,,,,,,
,3872839700.6538,2.00013554096222,-8524.1220703125,-0.0834680902902508,6.94660358893355E-5,1,2,13.1008939743042,4.98809705992959,41.2600003182888,-96.6763222238471,-14.1925871845755,1000,-2.05996483898831E-5,,,,,,,,,,,,,,,,,,,,,2.00000739097595,2.00026369094849,-8604.12890625,-8444.115234375,52.7779025040248,5.76012744902662,2.54371738433838,26,1,0,0,1,0.294189453125,33.2355842590332,1,6,1,2.00000739097595,0,2084573856,2.00013554096222,,,,,,,,,,,,,,,,,,,,,,,,,,,,,,,,,
,3872839764.15231,2.00021433830261,-2177.66076660156,-0.0298878455896015,0.000114373459932295,1,2,13.1008939743042,4.98793214712369,41.2600003182888,-34.6233430062956,-5.0301768549624,1000,3.71743955275035E-5,,,,,,,,,,,,,,,,,,,,,1.99999952316284,2.00042915344238,-2277.72290039062,-2077.5986328125,52.7907993745921,5.76006736334377,2.53654956817627,26,1,0,0,1,0.29541015625,32.2580642700195,1,6,1,1.99999952316284,0,2084573792,2.00021433830261,,,,,,,,,,,,,,,,,,,,,,,,,,,,,,,,,
,3872839827.62112,1.99990969896317,4171.8349609375,0.0459044383840313,0.000101510512561573,1,2,13.1008939743042,4.98758010179433,41.2600003182888,53.1518997845651,7.86478700584677,1000,6.35774101364625E-5,,,,,,,,,,,,,,,,,,,,,1.99969494342804,2.00012445449829,4081.78515625,4261.884765625,52.7399935208421,5.76238298938204,2.53293514251709,26,1,0,0,1,0.294113159179687,33.7243423461914,1,6,1,1.99969494342804,0,2084573184,1.99990969896317,,,,,,,,,,,,,,,,,,,,,,,,,,,,,,,,,
,3872839891.16642,1.99988704919815,10522.59765625,0.0942737789237296,6.36760363589882E-5,1,2,13.1008939743042,4.98713885463041,41.2600003182888,109.154185195207,16.0826388172022,1000,7.24989206190416E-5,,,,,,,,,,,,,,,,,,,,,1.99963772296906,2.00013637542725,10432.5048828125,10612.6904296875,52.720843622121,5.76480034591522,2.53287506103516,26,1,0,0,1,0.295639038085937,33.7243423461914,1,6,1,1.99963772296906,0,2084573408,1.99988704919815,,,,,,,,,,,,,,,,,,,,,,,,,,,,,,,,,
,3872839954.64159,2.00022459030151,16875.21484375,0.126086778078766,4.41379673169647E-5,1,2,13.1008939743042,4.98694415335785,41.2600003182888,145.987659769747,21.4606956085908,1000,5.55910277131341E-5,,,,,,,,,,,,,,,,,,,,,2.00019240379334,2.00025677680969,16785.126953125,16965.302734375,52.786891231996,5.7664770925797,2.5361635684967,26,1,0,0,1,0.298690795898438,33.2355842590332,1,6,1,2.00025677680969,0,2084573728,2.00022459030151,,,,,,,,,,,,,,,,,,,,,,,,,,,,,,,,,
,3872840018.1524,1.99999403953552,23228.1220703125,0.14908210874681,3.51272670601803E-5,1,2,13.1008939743042,4.98811331595105,41.2600003182888,172.665101695474,25.410725292783,1000,8.969129976365E-5,,,,,,,,,,,,,,,,,,,,,1.99995422363281,2.00003385543823,23138.060546875,23318.18359375,52.7943167029287,5.76317832960286,2.53893446922302,26,1,0,0,1,0.296554565429687,33.2355842590332,1,6,1,1.99995422363281,0,2084573856,1.99999403953552,,,,,,,,,,,,,,,,,,,,,,,,,,,,,,,,,
,3872840081.64722,2.00008076429367,29588.0380859375,0.166638005912601,3.34542401613039E-5,1,2,13.1008939743042,4.98782437329831,41.2600003182888,192.978987983066,28.4245023261815,1000,0.000120731428305277,,,,,,,,,,,,,,,,,,,,,1.99979484081268,2.00036668777466,29497.7421875,29678.333984375,52.9639300916018,5.76476578047596,2.52868676185608,26,1,0,0,1,0.29571533203125,33.2355842590332,1,6,1,1.99979484081268,0,2084574144,2.00008076429367,,,,,,,,,,,,,,,,,,,,,,,,,,,,,,,,,
,3872840145.14379,1.99988025426865,35952.216796875,0.180311761048752,3.24251950885741E-5,1,2,13.1008939743042,4.98789863202397,41.2600003182888,208.818290031403,30.7593524232932,1000,0.000132183026230717,,,,,,,,,,,,,,,,,,,,,1.99981296062469,1.9999475479126,35861.96875,36042.46484375,53.1839585197652,5.76438100545595,2.53782415390015,26,1,0,0,1,0.295639038085937,33.7243423461914,1,6,1,1.99981296062469,0,2084573664,1.99988025426865,,,,,,,,,,,,,,,,,,,,,,,,,,,,,,,,,
,3872840208.70339,2.00007522106171,42321.55859375,0.191080637839263,2.27770223225038E-5,1,2,13.1008939743042,4.98805565162559,41.2600003182888,221.299789331466,32.5954876691142,1000,0.000138036869338807,,,,,,,,,,,,,,,,,,,,,1.99994325637817,2.00020718574524,42236.34765625,42406.76953125,53.3594341223326,5.76545133821863,2.5342321395874,26,1,0,0,1,0.295333862304687,33.7243423461914,1,6,1,2.00020718574524,0,2084574112,2.00007522106171,,,,,,,,,,,,,,,,,,,,,,,,,,,,,,,,,
,3872840272.19512,2.00009661912918,48687.025390625,0.19983991592206,2.83777509401962E-5,1,2,13.1008939743042,4.98858793934887,41.2600003182888,231.477279667823,34.106152224211,1000,0.000154175626890171,,,,,,,,,,,,,,,,,,,,,1.9999166727066,2.00027656555176,48591.69140625,48782.359375,53.4723794433614,5.76330520382152,2.52801299095154,26,1,0,0,1,0.295867919921875,32.7468223571777,1,6,1,2.00027656555176,0,2084574144,2.00009661912918,,,,,,,,,,,,,,,,,,,,,,,,,,,,,,,,,
,3872840747.74064,24.2445507049561,26.2176666259766,9.58353262799447E-5,4.11304109793818E-8,1,5,13.1008939743042,4.97576581435198,41.2600003182888,0.110605942844815,0.0163072992793048,1,8.28249422690722E-8,,,,,,,,,,,,,,,,,,,,,24.0067348480225,24.4823665618896,26.2176666259766,26.2176666259766,52.6180594718421,5.76560001539611,5.95494318008423,66,1,0,0,1,0.299148559570313,33.7243423461914,2,1,1,24.4823665618896,0,2084574176,24.2445507049561,,,,,,,,,,,,,,,,,,,,,,,,,,,,,,,,,
,3872840951.27564,56.002368927002,26.2176666259766,7.04645871982416E-5,1.67975724570364E-8,1,5,13.1008939743042,4.98372584671734,41.2999987602234,0.0815172438303369,0.0119506332493831,1,3.40919873979507E-9,,,,,,,,,,,,,,,,,,,,,56.002368927002,56.002368927002,26.2176666259766,26.2176666259766,52.634473670746,5.77666427426555,6.70708227157593,66,1,0,0,1,0.300979614257812,32.7468223571777,2,1,1,56.002368927002,0,2084574272,56.002368927002,,,,,,,,,,,,,,,,,,,,,,,,,,,,,,,,,
,3872841151.77667,88.0071029663086,26.2176666259766,5.50380647601174E-5,1.30235716370561E-8,1,5,13.1008939743042,4.98052801911731,41.3400009274483,0.06361764807905,0.00929915476808568,1,-2.05045399322933E-8,,,,,,,,,,,,,,,,,,,,,88.0071029663086,88.0071029663086,26.2176666259766,26.2176666259766,52.5844494455152,5.78955156529984,6.97156000137329,66,1,0,0,1,0.290985107421875,31.7693061828613,2,1,1,88.0071029663086,0,2084574272,88.0071029663086,,,,,,,,,,,,,,,,,,,,,,,,,,,,,,,,,
,3872841345.42104,120.010520935059,26.2176666259766,4.14943522797543E-5,1.57451701379655E-8,1,5,13.1008939743042,4.98889667783064,41.4099991321564,0.0480761055604465,0.00702456792198261,1,-1.78585052090045E-8,,,,,,,,,,,,,,,,,,,,,120.010520935059,120.010520935059,26.2176666259766,26.2176666259766,52.5750699032844,5.79643270411317,7.11596775054932,66,1,0,0,1,0.296783447265625,33.2355842590332,2,1,1,120.010520935059,0,2084574400,120.010520935059,,,,,,,,,,,,,,,,,,,,,,,,,,,,,,,,,
,3872841538.80703,152.032012939453,26.2176666259766,2.93897108687311E-5,9.11412718343838E-9,1,5,13.1008939743042,4.98938492876605,41.5100008249283,0.0340576705114985,0.00496547174080063,1,-2.17857148360029E-8,,,,,,,,,,,,,,,,,,,,,152.032012939453,152.032012939453,26.2176666259766,26.2176666259766,52.5781964173613,5.79419309937261,7.21068477630615,66,1,0,0,1,0.294265747070313,33.2355842590332,2,1,1,152.032012939453,0,2084574400,152.032012939453,,,,,,,,,,,,,,,,,,,,,,,,,,,,,,,,,
,3872841732.23858,184.032928466797,26.2176666259766,2.18693876648488E-5,8.86170955428733E-9,1,5,13.1008939743042,4.98736525921944,41.6299998760223,0.0253283936546066,0.00369367595144449,1,-1.54521056228199E-8,,,,,,,,,,,,,,,,,,,,,184.032928466797,184.032928466797,26.2176666259766,26.2176666259766,52.4414114264959,5.8023854597975,7.30563449859619,66,1,0,0,1,0.29815673828125,33.2355842590332,2,1,1,184.032928466797,0,2084574272,184.032928466797,,,,,,,,,,,,,,,,,,,,,,,,,,,,,,,,,
,3872841924.51955,216.016998291016,26.2176666259766,1.6645761026649E-5,7.39565654587574E-9,1,5,13.1008939743042,4.98573580765524,41.7700000107288,0.0192695470178508,0.00281142596968266,1,-1.06445121547673E-8,,,,,,,,,,,,,,,,,,,,,216.016998291016,216.016998291016,26.2176666259766,26.2176666259766,52.5735066462459,5.80809024953959,7.45446252822876,64,1,64,0,0,0.300521850585937,33.2355842590332,2,1,1,216.016998291016,0,2084574336,216.016998291016,,,,,,,,,,,,,,,,,,,,,,,,,,,,,,,,,
,3872842118.02875,248.028549194336,26.2176666259766,1.28532043439133E-5,6.54892797801492E-9,1,5,13.1008939743042,4.98524717796146,41.9199988245964,0.0148735668996484,0.00219498971577077,1,1.2876185809834E-8,,,,,,,,,,,,,,,,,,,,,248.028549194336,248.028549194336,26.2176666259766,26.2176666259766,52.4386757266786,5.81131319995041,7.85839223861694,65,1,64,0,0,0.301895141601562,33.2355842590332,2,1,1,248.028549194336,0,2084574336,248.028549194336,,,,,,,,,,,,,,,,,,,,,,,,,,,,,,,,,
,3872842310.42536,280.01025390625,26.2176666259766,1.03653559244987E-5,9.81856749845818E-9,1,5,13.1008939743042,4.98471662782741,42.1000011265278,0.0119928904214842,0.00176973019614804,1,1.02661283874778E-8,,,,,,,,,,,,,,,,,,,,,280.01025390625,280.01025390625,26.2176666259766,26.2176666259766,52.5555291903036,5.81272443351728,8.33197975158691,65,1,64,0,0,0.302963256835937,33.7243423461914,2,1,1,280.01025390625,0,2084574464,280.01025390625,,,,,,,,,,,,,,,,,,,,,,,,,,,,,,,,,
,3872843107.39639,290.928497314453,26.192943572998,1.16881403006489E-5,9.55624877242836E-8,1,5,13.1008939743042,4.9843843578121,42.1600006520748,0.013534853038159,0.0019084402912467,1,-6.35693037558718E-8,,,,,,,,,,,,,,,,,,,,,290.928497314453,290.928497314453,26.192943572998,26.192943572998,52.5930473592267,5.81357744175656,8.92047786712647,64,1,64,0,0,0.300674438476562,33.2355842590332,2,1,1,290.928497314453,0,2084573184,290.928497314453,,,,,,,,,,,,,,,,,,,,,,,,,,,,,,,,,
,3872843281.54766,258.976013183594,26.192943572998,1.22185405027836E-5,2.38511028702539E-8,1,5,13.1008939743042,4.98254382032855,41.9900007545948,0.0141241398270856,0.00211404266413554,1,3.73365125183518E-8,,,,,,,,,,,,,,,,,,,,,258.976013183594,258.976013183594,26.192943572998,26.192943572998,52.6555776407652,5.81790465380106,9.00662422180176,66,1,0,0,1,0.296630859375,29.8142719268799,2,1,1,258.976013183594,0,2084574112,258.976013183594,,,,,,,,,,,,,,,,,,,,,,,,,,,,,,,,,
,3872843473.62006,226.969757080078,26.192943572998,1.28141761379911E-5,5.48032326924472E-9,1,5,13.1008939743042,4.9828713385988,41.8599992990494,0.014817730106789,0.00219209647543071,1,1.73622805247713E-8,,,,,,,,,,,,,,,,,,,,,226.969757080078,226.969757080078,26.192943572998,26.192943572998,52.5559200045633,5.82111225490357,8.67163562774658,66,1,0,0,1,0.296478271484375,34.7018585205078,2,1,1,226.969757080078,0,2084574208,226.969757080078,,,,,,,,,,,,,,,,,,,,,,,,,,,,,,,,,
,3872843663.2854,194.986419677734,26.192943572998,1.37796364058703E-5,5.79384507428772E-9,1,5,13.1008939743042,4.98665346249916,41.7600013315678,0.0159543902303315,0.0023373277032432,1,-7.08221286838908E-10,,,,,,,,,,,,,,,,,,,,,194.986419677734,194.986419677734,26.192943572998,26.192943572998,52.6024269014575,5.80617242756051,8.41443538665772,66,1,0,0,1,0.298309326171875,34.7018585205078,2,1,1,194.986419677734,0,2084573792,194.986419677734,,,,,,,,,,,,,,,,,,,,,,,,,,,,,,,,,
,3872843856.23081,162.968627929687,26.192943572998,1.47105410426495E-5,6.15391707039782E-9,1,5,13.1008939743042,4.98450764531591,41.6599996387959,0.0170234612416773,0.00248335091109245,1,-9.72111839589442E-9,,,,,,,,,,,,,,,,,,,,,162.968627929687,162.968627929687,26.192943572998,26.192943572998,52.5785872316209,5.81256127952265,8.2065544128418,66,1,0,0,1,0.301589965820313,32.7468223571777,2,1,1,162.968627929687,0,2084574048,162.968627929687,,,,,,,,,,,,,,,,,,,,,,,,,,,,,,,,,
,3872844047.83731,130.99626159668,26.192943572998,1.57915469904572E-5,6.00623952041285E-9,1,5,13.1008939743042,4.98169124925776,41.5499992668629,0.018258228810213,0.00267551229373037,1,-2.4359184346207E-10,,,,,,,,,,,,,,,,,,,,,130.99626159668,130.99626159668,26.192943572998,26.192943572998,52.6184502861017,5.82170351035461,8.02462291717529,66,1,0,0,1,0.299453735351562,34.7018585205078,2,1,1,130.99626159668,0,2084573984,130.99626159668,,,,,,,,,,,,,,,,,,,,,,,,,,,,,,,,,
,3872844240.0423,98.9738693237305,26.192943572998,1.68226332166256E-5,6.17072330274759E-9,1,5,13.1008939743042,4.98021229369013,41.4699986577034,0.0194430348246651,0.0028438353595127,1,-4.74495628698799E-9,,,,,,,,,,,,,,,,,,,,,98.965217590332,98.9825210571289,26.192943572998,26.192943572998,52.5590465186402,5.82626650134011,7.83475637435913,65,1,64,0,0,0.299530029296875,33.2355842590332,2,1,1,98.965217590332,0,2084573984,98.9738693237305,,,,,,,,,,,,,,,,,,,,,,,,,,,,,,,,,
,3872844429.88328,66.9481658935547,26.192943572998,1.83822196699329E-5,6.55287850427134E-9,1,5,13.1008939743042,4.97907020497367,41.3900017738342,0.0212388490528225,0.00310558892671923,1,-5.95697039233002E-9,,,,,,,,,,,,,,,,,,,,,66.9481658935547,66.9481658935547,26.192943572998,26.192943572998,52.5633454754959,5.83038604847019,7.60008573532104,66,1,0,0,1,0.301437377929687,32.7468223571777,2,1,1,66.9481658935547,0,2084573888,66.9481658935547,,,,,,,,,,,,,,,,,,,,,,,,,,,,,,,,,
,3872844615.62815,34.97900390625,26.192943572998,2.07940070404598E-5,7.45753286415245E-9,1,5,13.1008939743042,4.99872874366549,41.3299985229969,0.0241558761659611,0.00355007505296974,1,8.39017592847663E-9,,,,,,,,,,,,,,,,,,,,,34.97900390625,34.97900390625,26.192943572998,26.192943572998,52.6168870290633,5.83488634102646,7.14505624771118,66,1,0,0,1,0.309906005859375,33.7243423461914,2,1,1,34.97900390625,0,2084573696,34.97900390625,,,,,,,,,,,,,,,,,,,,,,,,,,,,,,,,,
,3872844876.74324,2.98780655860901,26.192943572998,4.09430017657226E-5,8.71891898695888E-8,1,5,13.1008939743042,4.9981059059633,41.2699989974499,0.0475514803154073,0.00700712024429318,1,3.22830994129226E-8,,,,,,,,,,,,,,,,,,,,,2.98780655860901,2.98780655860901,26.192943572998,26.192943572998,52.6352552992652,5.83685297355678,3.51489758491516,66,1,0,0,1,0.310745239257812,33.7243423461914,6,1,1,2.98780655860901,0,2084574720,2.98780655860901,,,,,,,,,,,,,,,,,,,,,,,,,,,,,,,,,
,3872845183.33884,31.0178623199463,26.192943572998,2.16099723299894E-5,7.36489614783219E-9,1,5,13.1008939743042,4.99599693111076,41.2800014019012,0.0250846065256949,0.00368624857883431,1,8.45159566055905E-9,,,,,,,,,,,,,,,,,,,,,31.0178623199463,31.0178623199463,26.192943572998,26.192943572998,52.600863644419,5.84448859686815,6.30574798583984,66,1,0,0,1,0.2996826171875,33.2355842590332,2,1,1,31.0178623199463,0,2084574272,31.0178623199463,,,,,,,,,,,,,,,,,,,,,,,,,,,,,,,,,
,3872845386.79183,63.0226364135742,26.192943572998,1.87309930680006E-5,2.53062152295291E-8,1,5,13.1008939743042,4.99683440251591,41.3100011646748,0.0217536015842959,0.00315647010631686,1,-2.66322333385223E-8,,,,,,,,,,,,,,,,,,,,,63.0226364135742,63.0226364135742,26.192943572998,26.192943572998,52.5387241771402,5.84186641639731,6.89819002151489,66,1,0,0,1,0.30426025390625,33.7243423461914,2,1,1,63.0226364135742,0,2084574304,63.0226364135742,,,,,,,,,,,,,,,,,,,,,,,,,,,,,,,,,
,3872845585.46667,95.0241165161133,26.192943572998,1.71014918579496E-5,9.81390898060204E-9,1,5,13.1008939743042,4.99652946217607,41.3599982857704,0.0198539424857101,0.00291922157046396,1,8.06500081158823E-9,,,,,,,,,,,,,,,,,,,,,95.0241165161133,95.0241165161133,26.192943572998,26.192943572998,52.6430715844575,5.84405864720033,7.11406898498535,66,1,0,0,1,0.302276611328125,32.7468223571777,2,1,1,95.0241165161133,0,2084574400,95.0241165161133,,,,,,,,,,,,,,,,,,,,,,,,,,,,,,,,,
,3872845779.73942,127.101409912109,26.192943572998,1.57450905385586E-5,6.16647829751676E-9,1,5,13.1008939743042,4.99800420040737,41.4399988949299,0.0182891322048339,0.00267276890999146,1,-6.37197749075141E-9,,,,,,,,,,,,,,,,,,,,,127.101409912109,127.101409912109,26.192943572998,26.192943572998,52.5910932879286,5.83931502141874,7.23612260818481,66,1,0,0,1,0.303726196289063,33.7243423461914,2,1,1,127.101409912109,0,2084574464,127.101409912109,,,,,,,,,,,,,,,,,,,,,,,,,,,,,,,,,
,3872845972.61007,159.034545898438,26.192943572998,1.43469579129423E-5,6.43634120046104E-9,1,5,13.1008939743042,4.9979401762672,41.5400005877018,0.0166653330196663,0.00243171724804547,1,-8.96714863963302E-9,,,,,,,,,,,,,,,,,,,,,159.034545898438,159.034545898438,26.192943572998,26.192943572998,52.5441955767748,5.83928430659699,7.3232102394104,66,1,0,0,1,0.314102172851562,32.7468223571777,2,1,1,159.034545898438,0,2084574400,159.034545898438,,,,,,,,,,,,,,,,,,,,,,,,,,,,,,,,,
,3872846165.55613,191.021560668945,26.192943572998,1.30981315579872E-5,6.13892393566209E-9,1,5,13.1008939743042,4.99862281464972,41.6599996387959,0.0152175747658234,0.00222073474233299,1,-7.96181916264513E-9,,,,,,,,,,,,,,,,,,,,,191.021560668945,191.021560668945,26.192943572998,26.192943572998,52.5996912016402,5.83698281474761,7.4042181968689,66,1,0,0,1,0.303115844726562,33.2355842590332,2,1,1,191.021560668945,0,2084574368,191.021560668945,,,,,,,,,,,,,,,,,,,,,,,,,,,,,,,,,
,3872846358.92728,223.09098815918,26.192943572998,1.19414699618233E-5,6.75479236138105E-9,1,5,13.1008939743042,4.99771939909249,41.7999997735023,0.0138690007413818,0.00203258055256449,1,2.99548377500954E-11,,,,,,,,,,,,,,,,,,,,,223.09098815918,223.09098815918,26.192943572998,26.192943572998,52.5441955767748,5.84097121396778,7.54752588272095,65,1,64,0,0,0.313186645507812,33.2355842590332,2,1,1,223.09098815918,0,2084573184,223.09098815918,,,,,,,,,,,,,,,,,,,,,,,,,,,,,,,,,
,3872846551.2175,255.048492431641,26.192943572998,1.08085982899727E-5,8.09937610407858E-9,1,5,13.1008939743042,4.99807031367545,41.9600009918213,0.0125514988244178,0.0018604147149533,1,1.76604302349428E-8,,,,,,,,,,,,,,,,,,,,,255.033538818359,255.063446044922,26.192943572998,26.192943572998,52.6825438246787,5.84097660982383,7.87050724029541,64,1,64,0,0,0.299835205078125,33.7243423461914,2,1,1,255.063446044922,0,2084574464,255.048492431641,,,,,,,,,,,,,,,,,,,,,,,,,,,,,,,,,
,3872846744.21318,287.102416992187,26.192943572998,9.85476064858625E-6,6.1601141167135E-9,1,5,13.1008939743042,4.99969048959006,42.1499982476234,0.0114484114744825,0.00170133360583583,1,1.98257376366437E-8,,,,,,,,,,,,,,,,,,,,,287.102416992187,287.102416992187,26.192943572998,26.192943572998,52.6180594718421,5.8342132082705,7.9901237487793,65,1,64,0,0,0.308914184570313,34.2131004333496,2,1,1,287.102416992187,0,2084574368,287.102416992187,,,,,,,,,,,,,,,,,,,,,,,,,,,,,,,,,
,3872847117.34887,300.002700805664,44564.783203125,0.00603336718040404,4.54294076556963E-6,1,2,13.1008939743042,5.01030842787958,42.1999990940094,7.04607181109135,0.93416076739813,100,-8.27042599357052E-5,,,,,,,,,,,,,,,,,,,,,300.002410888672,300.002990722656,44479.859375,44649.70703125,52.6055534155344,5.79298167445939,7.92770051956177,25,1,68,0,0,0.295639038085937,33.7243423461914,1,6,1,300.002410888672,0,2084573184,300.002700805664,,,,,,,,,,,,,,,,,,,,,,,,,,,,,,,,,
,3872847188.73118,300.002349853516,37434.634765625,0.00509438218557305,3.15420802799544E-6,1,2,13.1008939743042,5.01081616097703,42.1999990940094,5.95023328602648,0.789480340518532,100,-6.93239718435582E-5,,,,,,,,,,,,,,,,,,,,,300.002105712891,300.002593994141,37349.703125,37519.56640625,52.5441955767748,5.79132606857851,8.02157115936279,25,1,68,0,0,0.299835205078125,33.2355842590332,1,6,1,300.002593994141,0,2084574016,300.002349853516,,,,,,,,,,,,,,,,,,,,,,,,,,,,,,,,,
,3872847252.25736,300.002883911133,31093.384765625,0.00426356406506424,5.5750302780532E-6,1,2,13.1008939743042,5.01168181378806,42.1999990940094,4.98025024492973,0.666282126947958,100,-5.3391337239229E-5,,,,,,,,,,,,,,,,,,,,,300.002532958984,300.003234863281,31008.44140625,31178.328125,52.6137605149863,5.78906413103443,8.15999507904053,24,1,68,0,0,0.297470092773438,33.2355842590332,1,6,1,300.002532958984,0,2084573856,300.002883911133,,,,,,,,,,,,,,,,,,,,,,,,,,,,,,,,,
,3872847323.70718,300.001937866211,23953.5146484375,0.00332125913564372,2.61768117657616E-6,1,2,13.1008939743042,5.01231623621366,42.1999990940094,3.87981636526029,0.521968570006897,100,-3.91455660934686E-5,,,,,,,,,,,,,,,,,,,,,300.001800537109,300.002075195313,23868.5078125,24038.521484375,52.6825438246787,5.78737218031735,8.35227012634277,26,1,0,0,1,0.304641723632812,33.7243423461914,1,6,1,300.002075195313,0,2084573888,300.001937866211,,,,,,,,,,,,,,,,,,,,,,,,,,,,,,,,,
,3872847387.22066,300.001327514648,17617.4306640625,0.00247394667555016,1.06907334543631E-5,1,2,13.1008939743042,5.01259219417446,42.1999990940094,2.88896284036892,0.397469956799368,100,-2.17547973201581E-5,,,,,,,,,,,,,,,,,,,,,300.001251220703,300.001403808594,17527.455078125,17707.40625,52.5746790890248,5.78665735501471,8.57478809356689,26,1,0,0,1,0.30487060546875,33.7243423461914,1,6,1,300.001251220703,0,2084573824,300.001327514648,,,,,,,,,,,,,,,,,,,,,,,,,,,,,,,,,
,3872847458.65181,300.000839233398,10480.607421875,0.0015222903300691,6.32773692745803E-6,1,2,13.1008939743042,5.01232264309818,42.1999990940094,1.78073426032785,0.222679193269068,100,-3.2146224757486E-5,,,,,,,,,,,,,,,,,,,,,300.000732421875,300.000946044922,10395.5703125,10565.64453125,52.6270481998133,5.78728394750833,8.84099769592285,26,1,0,0,1,0.306472778320313,32.7468223571777,1,6,1,300.000946044922,0,2084573664,300.000839233398,,,,,,,,,,,,,,,,,,,,,,,,,,,,,,,,,
,3872847522.16857,300.000930786133,4134.60986328125,0.000687436673959658,1.15378400055752E-5,1,2,13.1008939743042,5.01223431027139,42.1999990940094,0.812496957845635,0.0434301555379705,100,-6.35031658606014E-5,,,,,,,,,,,,,,,,,,,,,300.000701904297,300.001159667969,4049.52294921875,4219.69677734375,52.6153237720248,5.78775404816989,9.06805610656738,25,1,68,0,0,0.306472778320313,33.7243423461914,1,6,1,300.001159667969,0,2084573792,300.000930786133,,,,,,,,,,,,,,,,,,,,,,,,,,,,,,,,,
,3872847593.59567,300.000885009766,-3008.93127441406,-0.000484231088448713,4.14325385231545E-6,1,2,13.1008939743042,5.0121566763896,42.1999990940094,-0.557726496230794,-0.130110433236378,100,-4.0610888179508E-5,,,,,,,,,,,,,,,,,,,,,300.000701904297,300.001068115234,-3098.93774414063,-2918.9248046875,52.6614398546594,5.78791728088951,9.32733058929443,25,1,68,0,0,0.304946899414063,33.7243423461914,1,6,1,300.001068115234,0,2084573536,300.000885009766,,,,,,,,,,,,,,,,,,,,,,,,,,,,,,,,,
,3872847657.07612,300.001205444336,-9359.35400390625,-0.00135170521102409,1.87593420115595E-6,1,2,13.1008939743042,5.01214925770559,42.1999990940094,-1.57398347804951,-0.246357487503262,100,-1.31681921528542E-5,,,,,,,,,,,,,,,,,,,,,300.000885009766,300.001525878906,-9449.421875,-9269.2861328125,52.7368670067652,5.78897233603969,9.61581039428711,26,1,0,0,1,0.303268432617188,33.7243423461914,1,6,1,300.001525878906,0,2084573280,300.001205444336,,,,,,,,,,,,,,,,,,,,,,,,,,,,,,,,,
,3872847724.5333,300.000900268555,-16107.4970703125,-0.00225981010079877,1.89839100285458E-6,1,2,13.1008939743042,5.01231111134007,42.1999990940094,-2.63454025159424,-0.39140182515488,10,-4.45077277850694E-6,,,,,,,,,,,,,,,,,,,,,300.000701904297,300.001098632812,-16202.5654296875,-16012.4287109375,52.6528419409479,5.78782120429575,9.73490428924561,26,1,0,0,1,0.305404663085937,34.7018585205078,1,6,1,300.000701904297,0,2084573728,300.000900268555,,,,,,,,,,,,,,,,,,,,,,,,,,,,,,,,,
,3872847798.00531,299.999618530273,-23454.322265625,-0.00324496588982033,2.05124673946745E-6,1,2,13.1008939743042,5.01230910596995,42.1999990940094,-3.78407279619158,-0.555094545020289,10,-4.42371980753619E-7,,,,,,,,,,,,,,,,,,,,,299.999603271484,299.999633789063,-23544.328125,-23364.31640625,52.6235308714767,5.78786530264739,9.65514850616455,25,1,68,0,0,0.303268432617188,34.2131004333496,1,6,1,299.999603271484,0,2084573920,299.999618530273,,,,,,,,,,,,,,,,,,,,,,,,,,,,,,,,,
,3872847869.457,300.001190185547,-30610.4716796875,-0.00419184030085917,2.21558674545572E-6,1,2,13.1008939743042,5.01209942444819,42.1999990940094,-4.888339153118,-0.714521157439925,10,1.57839677859837E-6,,,,,,,,,,,,,,,,,,,,,300.001129150391,300.001251220703,-30695.6953125,-30525.248046875,52.5977371303421,5.78810895030183,9.58320713043213,22,1,68,0,0,0.304641723632812,32.7468223571777,1,6,1,300.001129150391,0,2084574272,300.001190185547,,,,,,,,,,,,,,,,,,,,,,,,,,,,,,,,,
,3872847968.66554,300.000259399414,-40555.859375,-0.00551746218636848,2.16967874931742E-6,1,2,13.1008939743042,5.01199623637827,42.1999990940094,-6.43449364685065,-0.937329101344998,100,4.75683077030168E-6,,,,,,,,,,,,,,,,,,,,,300.000030517578,300.00048828125,-40646.10546875,-40465.61328125,52.5406782484383,5.7886873912982,9.50210475921631,26,1,0,0,1,0.30364990234375,32.7468223571777,1,6,1,300.000030517578,0,2084573952,300.000259399414,,,,,,,,,,,,,,,,,,,,,,,,,,,,,,,,,
,3872848042.13834,299.999877929687,-47915.767578125,-0.00651829066548289,6.79727021266595E-5,1,2,13.1008939743042,5.01192591616736,42.1999990940094,-7.61318433441482,-1.02771435387119,100,7.39005486572615E-5,,,,,,,,,,,,,,,,,,,,,299.999877929687,299.999877929687,-48000.61328125,-47830.921875,52.634473670746,5.78810797256148,9.45265769958496,24,1,68,0,0,0.302886962890625,33.7243423461914,1,6,1,299.999877929687,0,2084573920,299.999877929687,,,,,,,,,,,,,,,,,,,,,,,,,,,,,,,,,
,3872848113.5732,300.00016784668,-45379.34765625,-0.00622342432555884,5.48367198543838E-6,1,2,13.1008939743042,5.01171827796619,42.1999990940094,-7.27546036708362,-0.932770821138749,100,0.000112064908113507,,,,,,,,,,,,,,,,,,,,,299.999969482422,300.000366210937,-45469.29296875,-45289.40234375,52.534816034544,5.7891225496429,9.41261959075928,22,1,68,0,0,0.299835205078125,33.2355842590332,1,6,1,299.999969482422,0,2084573984,300.00016784668,,,,,,,,,,,,,,,,,,,,,,,,,,,,,,,,,
,3872848184.96405,299.999923706055,-38250.701171875,-0.00526762544243422,3.73193813165336E-6,1,2,13.1008939743042,5.01161703420389,42.1999990940094,-6.15564131364895,-0.805007457220899,100,8.1547243320084E-5,,,,,,,,,,,,,,,,,,,,,299.999816894531,300.000030517578,-38340.64453125,-38160.7578125,52.6168870290633,5.7900282539154,9.37729263305664,25,1,68,0,0,0.299224853515625,32.7468223571777,1,6,1,300.000030517578,0,2084574048,299.999923706055,,,,,,,,,,,,,,,,,,,,,,,,,,,,,,,,,
,3872848264.37746,300.000289916992,-30324.1533203125,-0.00420449765329783,1.05166049984004E-5,1,2,13.1008939743042,5.01159982811434,42.1999990940094,-4.9137722105403,-0.639094611583288,100,6.80402343327509E-5,,,,,,,,,,,,,,,,,,,,,300.000244140625,300.000335693359,-30414.1484375,-30234.158203125,52.6258757570344,5.78992559761298,9.34206199645996,24,1,68,0,0,0.30059814453125,31.7693061828613,1,6,1,300.000335693359,0,2084573856,300.000289916992,,,,,,,,,,,,,,,,,,,,,,,,,,,,,,,,,
,3872848355.63942,300.001068115234,-21207.853515625,-0.00299306986551375,5.19120919152895E-6,1,2,13.1008939743042,5.01152520956918,42.1999990940094,-3.49625367386498,-0.466251927528755,100,3.87380121078976E-5,,,,,,,,,,,,,,,,,,,,,300.000915527344,300.001220703125,-21297.8046875,-21117.90234375,52.6477613555729,5.79010456796787,9.31405830383301,24,1,68,0,0,0.298690795898438,33.7243423461914,1,6,1,300.000915527344,0,2084573824,300.001068115234,,,,,,,,,,,,,,,,,,,,,,,,,,,,,,,,,
,3872848429.1246,299.99934387207,-13874.0522460938,-0.00199906045199612,3.13656690188302E-5,1,2,13.1008939743042,5.01257417943394,42.1999990940094,-2.3322971631216,-0.335524088872898,100,5.27265547753417E-6,,,,,,,,,,,,,,,,,,,,,299.999237060547,299.999450683594,-13958.9599609375,-13789.14453125,52.568426060871,5.78678778997399,9.29000186920166,26,1,0,0,1,0.302200317382812,31.7693061828613,1,6,1,299.999450683594,0,2084574048,299.99934387207,,,,,,,,,,,,,,,,,,,,,,,,,,,,,,,,,
,3872848492.58068,300.000061035156,-7533.98168945313,-0.00113723646917374,9.15984991212254E-6,1,2,13.1008939743042,5.01333535042549,42.1999990940094,-1.3319882880887,-0.15750233811719,100,3.16434601130015E-5,,,,,,,,,,,,,,,,,,,,,299.999908447266,300.000213623047,-7623.951171875,-7444.01220703125,52.6176686575825,5.78420131115338,9.27468109130859,24,1,68,0,0,0.302734375,33.7243423461914,1,6,1,300.000213623047,0,2084573952,300.000061035156,,,,,,,,,,,,,,,,,,,,,,,,,,,,,,,,,
,3872848564.12172,299.999694824219,-382.603607177734,-0.000135094013634434,1.05601020014288E-5,1,2,13.1008939743042,5.01300136635087,42.1999990940094,-0.174149683965023,0.0900274078987245,100,9.69834477771436E-5,,,,,,,,,,,,,,,,,,,,,299.999603271484,299.999786376953,-467.665771484375,-297.541442871094,52.6348644850056,5.78458798997357,9.25535011291504,25,1,68,0,0,0.302505493164063,31.7693061828613,1,6,1,299.999603271484,0,2084573696,299.999694824219,,,,,,,,,,,,,,,,,,,,,,,,,,,,,,,,,
,3872848637.52301,300.00048828125,6957.26733398438,0.00103208471256326,3.3447997223621E-6,1,2,13.1008939743042,5.01312606278321,42.1999990940094,1.19925506282255,0.20777921816292,100,2.68781183458038E-5,,,,,,,,,,,,,,,,,,,,,300.000457763672,300.000518798828,6862.1435546875,7052.39111328125,52.5973463160825,5.78405674835247,9.23797035217285,26,1,0,0,1,0.302200317382812,33.7243423461914,1,6,1,300.000457763672,0,2084573184,300.00048828125,,,,,,,,,,,,,,,,,,,,,,,,,,,,,,,,,
,3872848700.94761,300.000152587891,13304.3896484375,0.00189788731037507,2.08161702288471E-6,1,2,13.1008939743042,5.01264315140051,42.1999990940094,2.21197877267847,0.334397374770831,100,8.58296570695364E-6,,,,,,,,,,,,,,,,,,,,,300.000122070313,300.000183105469,13214.296875,13394.482421875,52.5305170776882,5.78494457367967,9.21992206573486,26,1,0,0,1,0.302886962890625,31.7693061828613,1,6,1,300.000122070313,0,2084573952,300.000152587891,,,,,,,,,,,,,,,,,,,,,,,,,,,,,,,,,
,3872848768.50753,300.000717163086,20062.0888671875,0.00280639907819475,1.77590345880894E-6,1,2,13.1008939743042,5.01181458935187,42.1999990940094,3.27149475829152,0.484769451660855,10,4.46815636499247E-6,,,,,,,,,,,,,,,,,,,,,300.00048828125,300.000946044922,19977.0078125,20147.169921875,52.6254849427748,5.78911982010258,9.21716594696045,24,1,68,0,0,0.305938720703125,32.7468223571777,1,6,1,300.00048828125,0,2084574112,300.000717163086,,,,,,,,,,,,,,,,,,,,,,,,,,,,,,,,,
,3872848831.9439,300.000030517578,26410.8486328125,0.0036608822236621,2.22190914061804E-6,1,2,13.1008939743042,5.01126690869343,42.1999990940094,4.26722968627178,0.630276826828256,10,4.11559610372121E-6,,,,,,,,,,,,,,,,,,,,,299.999938964844,300.000122070313,26320.595703125,26501.1015625,52.5516210477075,5.79156712780799,9.19953155517578,24,1,68,0,0,0.300140380859375,33.7243423461914,1,6,1,299.999938964844,0,2084574016,300.000030517578,,,,,,,,,,,,,,,,,,,,,,,,,,,,,,,,,
,3872848904.61049,299.999588012695,33692.7578125,0.00463426041147651,4.28690568078451E-5,1,2,13.1008939743042,5.01085220515891,42.1999990940094,5.40979050388193,0.739167202460709,10,-4.50603356959342E-5,,,,,,,,,,,,,,,,,,,,,299.999389648438,299.999786376953,33527.28515625,33858.23046875,52.5969555018229,5.79182339145236,9.18680381774902,24,1,68,0,0,0.299606323242188,33.2355842590332,1,6,1,299.999786376953,0,2084574048,299.999588012695,,,,,,,,,,,,,,,,,,,,,,,,,,,,,,,,,
,3872849006.63201,299.999664306641,43916.443359375,0.00603284823391359,4.18564097194818E-5,1,2,13.1008939743042,5.00997589933615,42.1999990940094,7.02430775809385,1.07390521591562,100,3.73571781827677E-5,,,,,,,,,,,,,,,,,,,,,299.999481201172,299.999847412109,43831.15234375,44001.734375,52.5445863910344,5.79488306177834,9.17557048797607,26,1,0,0,1,0.300140380859375,32.7468223571777,1,6,1,299.999481201172,0,2084573760,299.999664306641,,,,,,,,,,,,,,,,,,,,,,,,,,,,,,,,,
,3872849070.12548,300.000839233398,50000.478515625,0.00682060360649169,7.42839996150446E-7,1,2,13.1008939743042,5.01026658057141,42.1999990940094,7.94696937086686,1.18148095053458,100,1.41348846890995E-5,,,,,,,,,,,,,,,,,,,,,300.000762939453,300.000915527344,50000.47265625,50000.484375,52.4621245822556,5.79420725916129,9.17484188079834,26,1,0,0,1,0.300445556640625,32.2580642700195,1,4,1,300.000915527344,0,2084573952,300.000839233398,,,,,,,,,,,,,,,,,,,,,,,,,,,,,,,,,