File: LT data/Frome/M1/295M1-FC-ZFC-RTSIRM-contsweepwithloop-MsT.dat
[Header]
; MPMS3 Data File (default extension .dat)
; Copyright (c) 2007, Quantum Design, Inc. All rights reserved.
TITLE,
FILEOPENTIME,3866187276.69308,07/05/2022,1:52 pm
BYAPP,MPMS3 w/ AC,1.0,1.1
INFO,MPMS3 Measurement Release 1.1.16 Build 424, MultiVu Release 2.3.4.19,APPNAME
INFO,Linear Motor Servo Controller,MOTOR_MODULE_NAME
INFO,3101-100 N2,MOTOR_HW_VERSION
INFO,,MOTOR_SERIAL_NUMBER
INFO,01.04.28,MOTOR_SOFTWARE_VERSION
INFO,Quantum Design Squid Module,SQUID_MODULE_NAME
INFO,3101-501 B0,SQUID_HW_VERSION
INFO,SQM327,SQUID_SERIAL_NUMBER
INFO,01.03.04,SQUID_SOFTWARE_VERSION
INFO,Quantum Design VSM Oven,OVEN_MODULE_NAME
INFO,3101-201 A3,OVEN_HW_VERSION
INFO,OVB365,OVEN_SERIAL_NUMBER
INFO,01.07.07,OVEN_SOFTWARE_VERSION
INFO,SQUID AC,AC_MODULE_NAME
INFO,3101-401 G0,AC_HW_VERSION
INFO,SAC220,AC_SERIAL_NUMBER
INFO,SQUID AC 00.95.07,AC_SOFTWARE_VERSION
INFO,TCI344,COIL_SERIAL_NUMBER
INFO,0,MOMENT_UNITS
INFO,lmst,SAMPLE_MATERIAL
INFO,,SAMPLE_COMMENT
INFO,115.71,SAMPLE_MASS
INFO,,SAMPLE_VOLUME
INFO,,SAMPLE_MOLECULAR_WEIGHT
INFO,,SAMPLE_SIZE
INFO,,SAMPLE_SHAPE
INFO,Straw,SAMPLE_HOLDER
INFO,Standard,SAMPLE_HOLDER_DETAIL
INFO,63.67,SAMPLE_OFFSET
DATATYPE,COMMENT,1
DATATYPE,TIME,2
STARTUPAXIS,X,2
STARTUPAXIS,Y1,5
FIELDGROUP, VSM,2,3,4,5,6,8,9,10,11,14,15
FIELDGROUP, DC, 2,3,4,14,56,57,58,59,60,61,62,63,64,65,66,67,68,69
FIELDGROUP, AC, 2,3,4,11,16,17,18,19,20,21,22,23,24,25,26,27,28,29,30
STARTUPGROUP, All
[Data]
Comment,Time Stamp (sec),Temperature (K),Magnetic Field (Oe),Moment (emu),M. Std. Err. (emu),Transport Action,Averaging Time (sec),Frequency (Hz),Peak Amplitude (mm),Center Position (mm),Lockin Signal' (V),Lockin Signal (V),Range,M. Quad. Signal (emu),AC Moment (emu),AC M. Std Err. (emu),AC Phase (deg),AC Phase Std. Err. (deg),AC Susceptibility (emu/Oe),AC Suscept. Std Err. (emu/Oe),AC X' (emu/Oe),AC X' Std Err. (emu/Oe),AC X'' (emu/Oe),AC X'' Std Err. (emu/Oe),AC Drive (Oe),AC Frequency (Hz),AC Averaging Time (sec),AC Cycles,AC Range,AC Measure Type,AC Signal' (V),AC Signal'' (V),AC Trim Coil Ratio,AC Trim Coil Phase,Min. Temperature (K),Max. Temperature (K),Min. Field (Oe),Max. Field (Oe),Mass (grams),Motor Lag (deg),Pressure (Torr),Measure Count,Measurement Number,SQUID Status (code),Motor Status (code),Measure Status (code),Motor Current (amps),Motor Temp. (C),Temp. Status (code),Field Status (code),Chamber Status (code),Chamber Temp (K),Redirection State,Average Temp (K),Rotation Angle (deg),Rotator state,DC Moment Fixed Ctr (emu),DC Moment Err Fixed Ctr (emu),DC Moment Free Ctr (emu),DC Moment Err Free Ctr (emu),DC Fixed Fit,DC Free Fit,DC Calculated Center (mm),DC Calculated Center Err (mm),DC Scan Length (mm),DC Scan Time (s),DC Number of Points,DC Squid Drift,DC Min V (V),DC Max V (V),DC Scans per Measure,Map 01,Map 02,Map 03,Map 04,Map 05,Map 06,Map 07,Map 08,Map 09,Map 10,Map 11,Map 12,Map 13,Map 14,Map 15,Map 16
,3866188537.10556,100.001892089844,49999.73828125,0.00407791363640142,2.22735944903569E-7,1,2,12.9061126708984,4.98469410802428,41.6299998760223,5.30303279216004,0.770027064473932,100,-6.81128049360541E-6,,,,,,,,,,,,,,,,,,,,,100.001892089844,100.001892089844,49999.73828125,49999.73828125,49.6431813276495,5.3983398589541,7.16436147689819,26,1,0,0,1,0.267715454101562,30.7917900085449,1,1,1,100.001892089844,0,100.001892089844,,,,,,,,,,,,,,,,,,,,,,,,,,,,,,,,,
,3866188609.07212,91.0259170532227,49999.73828125,0.00464723914726578,9.57161913515543E-6,1,2,12.9061126708984,4.98280317053993,41.6000001132488,6.04092970949332,0.871952769987643,10,-1.16959844286204E-5,,,,,,,,,,,,,,,,,,,,,90.7745590209961,91.2772750854492,49999.73828125,49999.73828125,49.6255946859668,5.40468903015046,7.11946105957031,26,1,0,0,1,0.273590087890625,31.2805480957031,2,1,1,90.7745590209961,0,91.0259170532227,,,,,,,,,,,,,,,,,,,,,,,,,,,,,,,,,
,3866188716.49848,73.5566673278809,49999.73828125,0.00629012696194711,1.43430153017751E-5,1,2,12.9061126708984,4.98199457346091,41.5400005877018,8.17180504848309,1.19929446464192,10,-9.29198855526985E-7,,,,,,,,,,,,,,,,,,,,,73.4265899658203,73.6867446899414,49999.73828125,49999.73828125,49.726033950688,5.40549172637733,7.04400444030762,26,1,0,0,1,0.275192260742187,31.2805480957031,2,1,1,73.4265899658203,0,73.5566673278809,,,,,,,,,,,,,,,,,,,,,,,,,,,,,,,,,
,3866188829.63325,54.467924118042,49999.73828125,0.00918326503144469,3.44665457910591E-5,1,2,12.9061126708984,4.98191336837061,41.4899997413158,11.9296558704024,1.75420425946339,10,1.21100556872979E-6,,,,,,,,,,,,,,,,,,,,,54.3144760131836,54.6213722229004,49999.73828125,49999.73828125,49.7662878194283,5.40569302211469,6.91946363449097,24,1,64,0,0,0.275802612304687,31.2805480957031,2,1,1,54.3144760131836,0,54.467924118042,,,,,,,,,,,,,,,,,,,,,,,,,,,,,,,,,
,3866188947.17737,34.5555191040039,49999.73828125,0.0150918202207097,5.38865748174537E-5,1,2,12.9061126708984,4.9814862638843,41.4599999785423,19.6030478704908,2.88144017552682,100,1.15884640162531E-6,,,,,,,,,,,,,,,,,,,,,34.5555191040039,34.5555191040039,49999.73828125,49999.73828125,49.9120615382649,5.40751377286898,6.64620780944824,26,1,0,0,1,0.2764892578125,31.2805480957031,2,1,1,34.5555191040039,0,34.5555191040039,,,,,,,,,,,,,,,,,,,,,,,,,,,,,,,,,
,3866189084.22344,11.8141431808472,49999.73828125,0.0333792162324761,0.000226167837939906,1,2,12.9061126708984,5.00063397470389,41.4099991321564,43.5246949207104,6.85801196855778,1000,0.000347610520445634,,,,,,,,,,,,,,,,,,,,,11.8141431808472,11.8141431808472,49999.73828125,49999.73828125,49.8991646676976,5.41515823991249,5.32766199111938,26,1,0,0,1,0.276947021484375,31.7693061828613,2,1,1,11.8141431808472,0,11.8141431808472,,,,,,,,,,,,,,,,,,,,,,,,,,,,,,,,,
,3866189229.7031,4.14169073104858,49999.73828125,0.0471104199417449,0.000128121569004556,1,2,12.9061126708984,5.00078524036505,41.4099991321564,61.4841307586879,9.32506296775003,1000,0.000219137876960056,,,,,,,,,,,,,,,,,,,,,4.14169073104858,4.14169073104858,49999.73828125,49999.73828125,50.2102528183515,5.4146262693008,3.7976450920105,26,1,0,0,1,0.287017822265625,32.2580642700195,6,1,1,4.14169073104858,0,4.14169073104858,,,,,,,,,,,,,,,,,,,,,,,,,,,,,,,,,
,3866189376.3721,3.85142922401428,49999.73828125,0.0478175729601418,0.00010416060219825,1,2,12.9061126708984,5.00140419237134,41.4099991321564,62.4718364249301,9.09925360292189,1000,-5.88596466132629E-5,,,,,,,,,,,,,,,,,,,,,3.85142922401428,3.85142922401428,49999.73828125,49999.73828125,50.2723922856303,5.41209268299306,3.68785834312439,26,1,0,0,1,0.28350830078125,31.2805480957031,6,1,1,3.85142922401428,0,3.85142922401428,,,,,,,,,,,,,,,,,,,,,,,,,,,,,,,,,
,3866189509.62584,2.71855688095093,49999.73828125,0.0492524011742822,0.000125887306928601,1,2,12.9061126708984,5.00101294439434,41.4099991321564,64.3384173843091,9.37751597189141,1000,-5.58373385756039E-5,,,,,,,,,,,,,,,,,,,,,2.71797585487366,2.7191379070282,49999.73828125,49999.73828125,50.2688749572938,5.4177747568821,3.13540244102478,26,1,0,0,1,0.28411865234375,30.7917900085449,6,1,1,2.71797585487366,0,2.71855688095093,,,,,,,,,,,,,,,,,,,,,,,,,,,,,,,,,
,3866189656.29913,2.75847840309143,49999.73828125,0.0490550070962792,0.000200662119971242,1,2,12.9061126708984,5.00067694756349,41.4099991321564,64.0500725164403,9.50554823880457,1000,7.18745279379694E-5,,,,,,,,,,,,,,,,,,,,,2.75847840309143,2.75847840309143,49999.73828125,49999.73828125,50.076594341563,5.41971353384701,3.16054654121399,26,1,0,0,1,0.283737182617187,33.2355842590332,6,1,1,2.75847840309143,0,2.75847840309143,,,,,,,,,,,,,,,,,,,,,,,,,,,,,,,,,
,3866189790.27216,2.67893803119659,49999.73828125,0.0489947138667334,0.00020461994268396,1,2,12.9061126708984,5.00098059020457,41.4099991321564,63.9388167883963,9.75314146918413,1000,0.000269684452208233,,,,,,,,,,,,,,,,,,,,,2.6744704246521,2.68340563774109,49999.73828125,49999.73828125,50.2149425894668,5.41866872159766,3.11866354942322,26,1,0,0,1,0.284576416015625,31.7693061828613,6,1,1,2.6744704246521,0,2.67893803119659,,,,,,,,,,,,,,,,,,,,,,,,,,,,,,,,,
,3866189934.70596,2.75546479225159,49999.73828125,0.0497569349919788,0.000199434341959351,1,2,12.9061126708984,5.00064610217965,41.4099991321564,64.9280788777802,9.89962704631672,1000,0.000270573302168758,,,,,,,,,,,,,,,,,,,,,2.74991083145142,2.76101875305176,49999.73828125,49999.73828125,50.2829442706399,5.4198640267971,3.15038824081421,26,1,0,0,1,0.28289794921875,31.7693061828613,6,1,1,2.74991083145142,0,2.75546479225159,,,,,,,,,,,,,,,,,,,,,,,,,,,,,,,,,
,3866190060.40254,2.57964766025543,49999.73828125,0.0477665479865838,0.000993066711072457,1,2,12.9061126708984,5.00133262529856,41.4099991321564,62.1399764480963,10.886010655922,1000,0.00131668123754526,,,,,,,,,,,,,,,,,,,,,2.57817959785461,2.58111572265625,49999.73828125,49999.73828125,50.3341409386496,5.41727858121439,3.0381236076355,25,1,68,0,0,0.282211303710938,31.7693061828613,6,1,1,2.57817959785461,0,2.57964766025543,,,,,,,,,,,,,,,,,,,,,,,,,,,,,,,,,
,3866190158.93577,2.44868910312653,49999.73828125,0.049596796512102,0.000128725677000937,1,2,12.9061126708984,5.00143440798407,41.4099991321564,64.7333232097399,9.87047261860633,1000,0.000270106902147214,,,,,,,,,,,,,,,,,,,,,2.44501996040344,2.45235824584961,49999.73828125,49999.73828125,50.2219772461399,5.41748111334156,2.96679091453552,26,1,0,0,1,0.283889770507813,31.7693061828613,6,1,1,2.44501996040344,0,2.44868910312653,,,,,,,,,,,,,,,,,,,,,,,,,,,,,,,,,
,3866190307.32753,2.38192403316498,49999.73828125,0.0497390249195998,0.000137276295722559,1,2,12.9061126708984,5.00165922077129,41.4099991321564,64.9746602308546,9.54806119476828,1000,1.92730149044003E-6,,,,,,,,,,,,,,,,,,,,,2.37839460372925,2.38545346260071,49999.73828125,49999.73828125,50.020707902438,5.41547663619953,2.91280293464661,26,1,0,0,1,0.282135009765625,32.2580642700195,6,1,1,2.38545346260071,0,2.38192403316498,,,,,,,,,,,,,,,,,,,,,,,,,,,,,,,,,
,3866190452.09193,2.30937576293945,49999.73828125,0.0495866969967658,0.000133693834621016,1,2,12.9061126708984,5.0021627404951,41.4099991321564,64.7627856297343,9.67002980044903,1000,0.000116630842792412,,,,,,,,,,,,,,,,,,,,,2.30937576293945,2.30937576293945,49999.73828125,49999.73828125,50.3267154677169,5.41363855338948,2.8618471622467,26,1,0,0,1,0.280380249023438,31.7693061828613,6,1,1,2.30937576293945,0,2.30937576293945,,,,,,,,,,,,,,,,,,,,,,,,,,,,,,,,,
,3866190583.67138,2.29841947555542,49999.73828125,0.0497437141847966,0.000117369256822391,1,2,12.9061126708984,5.00140052262677,41.4099991321564,65.0087801437005,9.3256836422428,1000,-0.000168476752837935,,,,,,,,,,,,,,,,,,,,,2.29841947555542,2.29841947555542,49999.73828125,49999.73828125,50.2942778841688,5.4161070504655,2.86016178131104,26,1,0,0,1,0.283050537109375,32.2580642700195,6,1,1,2.29841947555542,0,2.29841947555542,,,,,,,,,,,,,,,,,,,,,,,,,,,,,,,,,
,3866190733.07411,1.99737942218781,49999.73828125,0.0501680301574325,7.89039960360696E-5,1,2,12.9061126708984,5.00094125154935,41.4099991321564,65.4774275463058,9.93121012892193,1000,0.000233734415723449,,,,,,,,,,,,,,,,,,,,,1.99725329875946,1.99750554561615,49999.73828125,49999.73828125,50.3556357229284,5.41779332263031,2.65301990509033,26,1,0,0,1,0.2838134765625,31.7693061828613,6,1,1,1.99725329875946,0,1.99737942218781,,,,,,,,,,,,,,,,,,,,,,,,,,,,,,,,,
,3866190866.03441,1.99937057495117,49999.73828125,0.0501933858142375,9.14873838981162E-5,1,2,12.9061126708984,5.00081990810273,41.4099991321564,65.5627947074425,9.56491939484684,1000,-5.01972838371281E-5,,,,,,,,,,,,,,,,,,,,,1.99862861633301,2.00011253356934,49999.73828125,49999.73828125,50.2039997901976,5.41725292532318,2.62859869003296,26,1,0,0,1,0.285110473632813,32.2580642700195,5,1,1,2.00011253356934,0,1.99937057495117,,,,,,,,,,,,,,,,,,,,,,,,,,,,,,,,,
,3866191000.64998,2.00215291976929,49999.73828125,0.050170163756501,8.8161189531145E-5,1,2,12.9061126708984,5.00122153091054,41.4099991321564,65.5204156569002,9.69373493420914,1000,5.10123476812912E-5,,,,,,,,,,,,,,,,,,,,,1.99818754196167,2.0061182975769,49999.73828125,49999.73828125,50.3700958505342,5.41618246406681,2.61462259292603,26,1,0,0,1,0.283432006835938,32.2580642700195,6,1,1,1.99818754196167,0,2.00215291976929,,,,,,,,,,,,,,,,,,,,,,,,,,,,,,,,,
,3866191134.18942,2.00007772445679,49999.73828125,0.0502538897315711,0.000136926253389086,1,2,12.9061126708984,5.00094227764034,41.4099991321564,65.6100689544861,9.8082481870598,1000,0.000126971045957988,,,,,,,,,,,,,,,,,,,,,1.99897575378418,2.00117969512939,49999.73828125,49999.73828125,50.3091288260342,5.41745437514273,2.61423325538635,26,1,0,0,1,0.2850341796875,31.7693061828613,5,1,1,2.00117969512939,0,2.00007772445679,,,,,,,,,,,,,,,,,,,,,,,,,,,,,,,,,
,3866191267.20692,1.99931013584137,49999.73828125,0.050010941572398,0.000111211282941626,1,2,12.9061126708984,5.00131483095954,41.4099991321564,65.3169871091738,9.64413872687906,1000,3.62399140756385E-5,,,,,,,,,,,,,,,,,,,,,1.99890649318695,1.99971377849579,49999.73828125,49999.73828125,50.3880733064765,5.41790630937393,2.61624503135681,26,1,0,0,1,0.28167724609375,32.7468223571777,5,1,1,1.99971377849579,0,1.99931013584137,,,,,,,,,,,,,,,,,,,,,,,,,,,,,,,,,
,3866191936.30637,26.0246410369873,26.4876518249512,3.39115801597157E-5,2.21759775281931E-8,1,5,12.9061126708984,5.01207481660636,41.4099991321564,0.0444332146518196,0.00649445482530608,1,-2.48587797820016E-8,,,,,,,,,,,,,,,,,,,,,26.0246410369873,26.0246410369873,26.4876518249512,26.4876518249512,49.6123070011399,5.40984763556255,5.9144344329834,65,1,0,0,1,0.280303955078125,32.2580642700195,2,1,1,26.0246410369873,0,26.0246410369873,,,,,,,,,,,,,,,,,,,,,,,,,,,,,,,,,
,3866192127.85915,56.0275802612305,26.4876518249512,2.17004305688628E-5,9.71237429999227E-9,1,5,12.9061126708984,5.00696506617034,41.4300002157688,0.0283949849072737,0.00413531822419153,1,-2.70977813006071E-8,,,,,,,,,,,,,,,,,,,,,56.0275802612305,56.0275802612305,26.4876518249512,26.4876518249512,49.7772306186976,5.43017093082951,6.57168197631836,65,1,0,0,1,0.2838134765625,31.7693061828613,2,1,1,56.0275802612305,0,56.0275802612305,,,,,,,,,,,,,,,,,,,,,,,,,,,,,,,,,
,3866192316.05002,86.0127182006836,26.4876518249512,1.66115187829536E-5,7.40768231880123E-9,1,5,12.9061126708984,5.01079314341672,41.4800010621548,0.0217579667049108,0.0031786300849659,1,-1.33441971720426E-8,,,,,,,,,,,,,,,,,,,,,86.0127182006836,86.0127182006836,26.4876518249512,26.4876518249512,49.7307237218033,5.4132071555394,6.82554244995117,63,1,64,0,0,0.27923583984375,32.2580642700195,2,1,1,86.0127182006836,0,86.0127182006836,,,,,,,,,,,,,,,,,,,,,,,,,,,,,,,,,
,3866192497.91658,116.015266418457,26.4876518249512,1.36123068343731E-5,7.97254206257761E-9,1,5,12.9061126708984,5.01308793690092,41.5499992668629,0.0178430444008941,0.00259230320761626,1,-2.16879800002848E-8,,,,,,,,,,,,,,,,,,,,,116.015266418457,116.015266418457,26.4876518249512,26.4876518249512,49.692423924361,5.40500155850469,6.95819997787476,65,1,0,0,1,0.278854370117187,31.7693061828613,2,1,1,116.015266418457,0,116.015266418457,,,,,,,,,,,,,,,,,,,,,,,,,,,,,,,,,
,3866192679.06727,146.063652038574,26.4876518249512,1.1830006528092E-5,9.12017620742578E-9,1,5,12.9061126708984,5.01460535880884,41.6299998760223,0.0155139539863691,0.00224978012417816,1,-2.1943265800188E-8,,,,,,,,,,,,,,,,,,,,,146.04719543457,146.080108642578,26.4876518249512,26.4876518249512,49.7471379207072,5.40153672572439,7.0346531867981,64,1,64,0,0,0.273818969726562,31.7693061828613,2,1,1,146.080108642578,0,146.063652038574,,,,,,,,,,,,,,,,,,,,,,,,,,,,,,,,,
,3866192860.79049,176.086151123047,26.4876518249512,1.07350233270934E-5,6.19551838550156E-8,1,5,12.9061126708984,5.0047108296904,41.7300015687943,0.0140266916776337,0.00212082762181465,1,4.503639931261E-8,,,,,,,,,,,,,,,,,,,,,176.086151123047,176.086151123047,26.4876518249512,26.4876518249512,49.7354134929187,5.39885753739121,7.10581541061401,63,1,64,0,0,0.2764892578125,31.7693061828613,2,1,1,176.126663208008,0,176.086151123047,,,,,,,,,,,,,,,,,,,,,,,,,,,,,,,,,
,3866193041.41976,206.024078369141,26.4876518249512,9.70517238062897E-6,6.17187456237125E-8,1,5,12.9061126708984,5.00587410047783,41.8599992990494,0.0126817460626111,0.00194138735536303,1,5.86039338808294E-8,,,,,,,,,,,,,,,,,,,,,206.024078369141,206.024078369141,26.4876518249512,26.4876518249512,49.7252523221687,5.39576684803327,7.18031454086304,64,1,64,0,0,0.274124145507813,31.7693061828613,2,1,1,206.024078369141,0,206.024078369141,,,,,,,,,,,,,,,,,,,,,,,,,,,,,,,,,
,3866193222.20489,236.063507080078,26.4876518249512,8.95561376777788E-6,1.22637625264188E-8,1,5,12.9061126708984,5.00753586717271,41.9900007545948,0.011722138008981,0.00169422377199928,1,-2.08622133345134E-8,,,,,,,,,,,,,,,,,,,,,236.063507080078,236.063507080078,26.4876518249512,26.4876518249512,49.6224681718899,5.39254779944732,7.35356998443603,64,1,64,0,0,0.286178588867187,32.2580642700195,2,1,1,236.063507080078,0,236.063507080078,,,,,,,,,,,,,,,,,,,,,,,,,,,,,,,,,
,3866193402.77465,266.023773193359,26.4876518249512,8.29509526904304E-6,9.45382032854473E-9,1,5,12.9061126708984,5.00894596027983,42.1600006520748,0.0108592039229972,0.00158790391121706,1,-5.55779592007841E-9,,,,,,,,,,,,,,,,,,,,,266.023773193359,266.023773193359,26.4876518249512,26.4876518249512,49.731114536063,5.38622322347249,7.63424301147461,64,1,64,0,0,0.2838134765625,34.2131004333496,2,1,1,266.023773193359,0,266.023773193359,,,,,,,,,,,,,,,,,,,,,,,,,,,,,,,,,
,3866193583.84236,296.0126953125,26.4876518249512,7.55140674922477E-6,9.48152185584312E-9,1,5,12.9061126708984,5.00964946850962,42.3300005495548,0.00988888760905419,0.00143688455304326,1,-1.18888809326131E-8,,,,,,,,,,,,,,,,,,,,,296.0126953125,296.0126953125,26.4876518249512,26.4876518249512,49.6697566973033,5.38435499998286,7.42006731033325,63,1,64,0,0,0.282211303710938,31.7693061828613,2,1,1,296.0126953125,0,296.0126953125,,,,,,,,,,,,,,,,,,,,,,,,,,,,,,,,,
,3866196216.15122,2.00011748075485,41904.984375,0.0476222686511177,0.000333909764193237,1,2,12.9061126708984,5.00119210417639,41.4099991321564,62.1055033734546,9.79315727549696,1000,0.000501505926882731,,,,,,,,,,,,,,,,,,,,,1.99985730648041,2.0003776550293,41745.26953125,42064.69921875,50.0840198124957,5.41517320440775,2.63444685935974,25,1,64,0,0,0.284652709960938,31.7693061828613,5,6,1,1.99985730648041,0,2.00011748075485,,,,,,,,,,,,,,,,,,,,,,,,,,,,,,,,,
,3866196281.599,2.00070071220398,35370.556640625,0.0457912372285012,0.000319411978015519,1,2,12.9061126708984,5.00147224109068,41.4099991321564,59.6891652483207,9.64282800761823,1000,0.00065483188926985,,,,,,,,,,,,,,,,,,,,,2.00012731552124,2.00127410888672,35305.53515625,35435.578125,49.9976498611207,5.41319716270654,2.62670564651489,26,1,0,0,1,0.284881591796875,30.7917900085449,1,6,1,2.00012731552124,0,2.00070071220398,,,,,,,,,,,,,,,,,,,,,,,,,,,,,,,,,
,3866196362.03313,1.98831737041473,27338.6611328125,0.0425495279839464,0.000136472019600526,1,2,12.9061126708984,5.00138367935998,41.4099991321564,55.5676492462179,8.24219396703877,1000,5.89756646882283E-5,,,,,,,,,,,,,,,,,,,,,1.97659850120544,2.00003623962402,27248.837890625,27428.484375,49.8772790691591,5.41268183314557,2.60722041130066,26,1,0,0,1,0.28106689453125,31.7693061828613,1,6,1,1.97659850120544,0,1.98831737041473,,,,,,,,,,,,,,,,,,,,,,,,,,,,,,,,,
,3866196495.11549,2.00276106595993,14055.5229492187,0.0317034722838652,3.48858868092369E-5,1,2,12.9061126708984,5.00148886637301,41.4099991321564,41.4176418714747,6.0515303058561,100,-2.48603577443664E-5,,,,,,,,,,,,,,,,,,,,,1.9983617067337,2.00716042518616,13940.7783203125,14170.267578125,49.6978953239956,5.41265922258243,2.61589813232422,26,1,0,0,1,0.283584594726562,31.7693061828613,6,6,1,2.00716042518616,0,2.00276106595993,,,,,,,,,,,,,,,,,,,,,,,,,,,,,,,,,
,3866196579.60365,2.00169384479523,5613.14453125,0.0175926172907299,2.71869157776755E-5,1,2,12.9061126708984,5.00132928141842,41.4099991321564,22.9839968095882,3.34495815606034,100,-2.37132329117579E-5,,,,,,,,,,,,,,,,,,,,,2.00166249275208,2.00172519683838,5508.265625,5718.0234375,49.5743980179572,5.4123012219718,2.60938453674316,26,1,0,0,1,0.281753540039062,31.2805480957031,1,6,1,2.00172519683838,0,2.00169384479523,,,,,,,,,,,,,,,,,,,,,,,,,,,,,,,,,
,3866196664.19923,1.99939942359924,-2842.35205078125,-0.00951118846193075,3.54118472716228E-5,1,2,12.9061126708984,5.00149367800239,41.4099991321564,-12.4242378389345,-1.82408803422259,100,8.75696132983985E-7,,,,,,,,,,,,,,,,,,,,,1.9987199306488,2.00007891654968,-2947.13696289063,-2737.56713867187,49.5861224457456,5.41167731729172,2.61015176773071,26,1,0,0,1,0.280609130859375,32.2580642700195,1,6,1,1.9987199306488,0,1.99939942359924,,,,,,,,,,,,,,,,,,,,,,,,,,,,,,,,,
,3866196728.51964,2.00043225288391,-9271.18603515625,-0.0246476430448481,1.86895340353698E-5,1,2,12.9061126708984,5.00161778166021,41.4099991321564,-32.2026660529357,-4.69367489552383,100,2.79127002540748E-5,,,,,,,,,,,,,,,,,,,,,2.00017261505127,2.00069189071655,-9366.224609375,-9176.1474609375,49.5407879916302,5.41058278511698,2.60464096069336,26,1,0,0,1,0.284423828125,31.2805480957031,1,6,1,2.00069189071655,0,2.00043225288391,,,,,,,,,,,,,,,,,,,,,,,,,,,,,,,,,
,3866196801.06464,1.99951988458633,-16526.666015625,-0.0345789518183509,7.08382398995678E-5,1,2,12.9061126708984,5.00167970713505,41.4099991321564,-45.1740329479376,-6.61824158754867,100,1.37267231018519E-5,,,,,,,,,,,,,,,,,,,,,1.99884879589081,2.00019097328186,-16616.783203125,-16436.548828125,49.7182176654956,5.41030984368268,2.58891582489014,26,1,0,0,1,0.283203125,31.7693061828613,1,6,1,1.99884879589081,0,1.99951988458633,,,,,,,,,,,,,,,,,,,,,,,,,,,,,,,,,
,3866196910.98962,1.99879395961761,-27525.9736328125,-0.0427504055377637,0.000257217379568268,1,2,12.9061126708984,5.00166033400829,41.4099991321564,-55.9570490108972,-7.44628211664563,100,0.00058030231536036,,,,,,,,,,,,,,,,,,,,,1.99879395961761,1.99879395961761,-27530.9765625,-27520.970703125,49.8401517144957,5.41039978984888,2.57818818092346,26,1,0,0,1,0.283279418945313,31.2805480957031,1,6,1,1.99879395961761,0,1.99879395961761,,,,,,,,,,,,,,,,,,,,,,,,,,,,,,,,,
,3866197051.90652,1.99895894527435,-41646.5,-0.0478403442904736,0.00019427302868343,1,2,12.9061126708984,5.00152904680245,41.4099991321564,-62.5039921132458,-9.10240052712381,1000,6.00394106328594E-5,,,,,,,,,,,,,,,,,,,,,1.99895894527435,1.99895894527435,-41646.5,-41646.5,50.0980891258418,5.41189990638213,2.56880331039429,26,1,0,0,1,0.28167724609375,31.7693061828613,1,6,1,1.99895894527435,0,1.99895894527435,,,,,,,,,,,,,,,,,,,,,,,,,,,,,,,,,
,3866197181.79113,1.99993711709976,-46743.1484375,-0.0490655226019176,0.000207097664296565,1,2,12.9061126708984,5.00134261731209,41.4099991321564,-64.1216482533187,-9.19690149796919,1000,0.000167319972572811,,,,,,,,,,,,,,,,,,,,,1.99974119663239,2.00013303756714,-46837.765625,-46648.53125,50.0730770132265,5.41258168144299,2.57192254066467,26,1,0,0,1,0.282135009765625,30.7917900085449,1,6,1,1.99974119663239,0,1.99993711709976,,,,,,,,,,,,,,,,,,,,,,,,,,,,,,,,,
,3866197246.3025,1.99901920557022,-40305.3515625,-0.0475988953798571,0.00014103339999465,1,2,12.9061126708984,5.00151149536462,41.4099991321564,-62.1361858564157,-9.41067690960162,1000,-0.0002114646828344,,,,,,,,,,,,,,,,,,,,,1.99808478355408,1.99995362758636,-40400.15234375,-40210.55078125,50.0887095836111,5.41221010647415,2.56719756126404,26,1,0,0,1,0.281906127929687,31.2805480957031,1,6,1,1.99995362758636,0,1.99901920557022,,,,,,,,,,,,,,,,,,,,,,,,,,,,,,,,,
,3866197350.68691,1.99905967712402,-29880.478515625,-0.0439909639700995,0.000106836973621927,1,2,12.9061126708984,5.00153788210009,41.4099991321564,-57.474227718426,-8.37440003788062,1000,5.18509887732569E-5,,,,,,,,,,,,,,,,,,,,,1.99905967712402,1.99905967712402,-29880.478515625,-29880.478515625,49.8573475419187,5.41209950687,2.56742763519287,26,1,0,0,1,0.283432006835938,31.7693061828613,1,6,1,1.99905967712402,0,1.99905967712402,,,,,,,,,,,,,,,,,,,,,,,,,,,,,,,,,
,3866197465.91228,1.99958884716034,-18380.576171875,-0.0365977059456381,6.77036840679347E-5,1,2,12.9061126708984,5.00143141062356,41.4099991321564,-47.8053086282519,-7.02255784727022,100,4.23815070312799E-7,,,,,,,,,,,,,,,,,,,,,1.99837875366211,2.00079894065857,-18480.59765625,-18280.5546875,49.6892974102841,5.41144550644244,2.57544851303101,26,1,0,0,1,0.281600952148438,31.7693061828613,1,6,1,1.99837875366211,0,1.99958884716034,,,,,,,,,,,,,,,,,,,,,,,,,,,,,,,,,
,3866197550.50091,1.99839824438095,-9933.07666015625,-0.0265159802412019,1.42857513938376E-5,1,2,12.9061126708984,5.00158469050554,41.4099991321564,-34.6395568367721,-5.07535336295848,100,1.01738909603304E-5,,,,,,,,,,,,,,,,,,,,,1.99706494808197,1.99973154067993,-10032.9287109375,-9833.224609375,49.6631128548899,5.41005628546251,2.58207559585571,26,1,0,0,1,0.283584594726562,31.2805480957031,1,6,1,1.99973154067993,0,1.99839824438095,,,,,,,,,,,,,,,,,,,,,,,,,,,,,,,,,
,3866197646.38851,1.99702435731888,-350.394165039063,-0.00213962647866616,4.16595336197964E-5,1,2,12.9061126708984,5.00167192705512,41.4099991321564,-2.80093924662707,-0.370498211791589,100,3.07155446632553E-5,,,,,,,,,,,,,,,,,,,,,1.99698090553284,1.99706780910492,-350.394165039063,-350.394165039063,49.6384915565341,5.40942668529786,2.57536363601685,26,1,0,0,1,0.282211303710938,31.7693061828613,6,6,1,1.99698090553284,0,1.99702435731888,,,,,,,,,,,,,,,,,,,,,,,,,,,,,,,,,
,3866197717.68354,1.99888271093369,6772.52758789063,0.0204204369414004,2.48192099323613E-5,1,2,12.9061126708984,5.00173726836964,41.4099991321564,26.6758714122683,3.92116724941153,100,1.64070250888825E-6,,,,,,,,,,,,,,,,,,,,,1.99795997142792,1.99980545043945,6677.39501953125,6867.66015625,49.6603771550726,5.40881365421472,2.57997417449951,26,1,0,0,1,0.2825927734375,31.7693061828613,1,6,1,1.99980545043945,0,1.99888271093369,,,,,,,,,,,,,,,,,,,,,,,,,,,,,,,,,
,3866197784.13326,1.99954980611801,13424.0815429688,0.031433205203332,1.90352795765326E-5,1,2,12.9061126708984,5.00160259030314,41.4099991321564,41.0626096127421,6.02232912032853,100,-7.65680715622708E-6,,,,,,,,,,,,,,,,,,,,,1.99768483638763,2.00141477584839,13329.130859375,13519.0322265625,49.7631613053514,5.4111784732536,2.58119225502014,26,1,0,0,1,0.283126831054687,31.7693061828613,1,6,1,2.00141477584839,0,1.99954980611801,,,,,,,,,,,,,,,,,,,,,,,,,,,,,,,,,
,3866197858.83584,1.9972962141037,20895.3857421875,0.038750747357951,0.000126720265699757,1,2,12.9061126708984,5.00165365395347,41.4099991321564,50.5882552501882,7.65797214724859,100,0.000169352988996183,,,,,,,,,,,,,,,,,,,,,1.99679088592529,1.9978015422821,20820.373046875,20970.3984375,49.8976014106591,5.41028701386495,2.56951427459717,26,1,0,0,1,0.282058715820313,32.2580642700195,1,6,1,1.9978015422821,0,1.9972962141037,,,,,,,,,,,,,,,,,,,,,,,,,,,,,,,,,
,3866197999.68345,1.99753546714783,34995.06640625,0.0459051662842348,0.00015798454704372,1,2,12.9061126708984,5.00160962504914,41.4099991321564,59.9597370714923,8.85198267016674,1000,3.24022471789686E-5,,,,,,,,,,,,,,,,,,,,,1.99520134925842,1.99986958503723,34899.93359375,35090.19921875,50.0128916172457,5.411971233704,2.56585836410522,26,1,0,0,1,0.28228759765625,32.2580642700195,1,6,1,1.99986958503723,0,1.99753546714783,,,,,,,,,,,,,,,,,,,,,,,,,,,,,,,,,
,3866198126.91461,1.99972212314606,47746.412109375,0.049462170887244,0.000150103439198187,1,2,12.9061126708984,5.00182490995455,41.4099991321564,64.5821618487782,9.72568416889085,1000,0.000178227010995168,,,,,,,,,,,,,,,,,,,,,1.99935007095337,2.00009417533874,47625.75,47867.07421875,50.2536332011688,5.41333043493636,2.56340980529785,26,1,0,0,1,0.282516479492187,31.7693061828613,1,6,1,1.99935007095337,0,1.99972212314606,,,,,,,,,,,,,,,,,,,,,,,,,,,,,,,,,
,3866198680.80962,20.2051525115967,26.424976348877,1.82384549270759E-5,8.66385223160354E-9,1,5,12.9061126708984,5.01268446612834,41.4099991321564,0.0239006045841198,0.00349821325077598,1,-9.74677623721269E-9,,,,,,,,,,,,,,,,,,,,,20.0130214691162,20.3972835540771,26.424976348877,26.424976348877,49.6103529298418,5.4083346939181,5.64331483840942,65,1,0,0,1,0.277252197265625,31.2805480957031,2,1,1,20.3972835540771,0,20.2051525115967,,,,,,,,,,,,,,,,,,,,,,,,,,,,,,,,,
,3866198870.99008,50.0840950012207,26.424976348877,1.49899314092898E-5,7.3700649453084E-9,1,5,12.9061126708984,5.00211380236048,41.4300002157688,0.0195863052855381,0.00286226841161333,1,-1.13692500647742E-8,,,,,,,,,,,,,,,,,,,,,50.0840950012207,50.0840950012207,26.424976348877,26.424976348877,49.812403902063,5.410675239209,6.47995281219482,65,1,0,0,1,0.278549194335938,30.7917900085449,2,1,1,50.0840950012207,0,50.0840950012207,,,,,,,,,,,,,,,,,,,,,,,,,,,,,,,,,
,3866199058.90401,80.0065155029297,26.424976348877,1.33706476196477E-5,6.53851454448129E-9,1,5,12.9061126708984,4.9987354249235,41.4699986577034,0.0174550781005316,0.00254315700459608,1,-1.58878126439037E-8,,,,,,,,,,,,,,,,,,,,,80.0065155029297,80.0065155029297,26.424976348877,26.424976348877,49.6349742281976,5.42431394757851,6.76944780349731,63,1,64,0,0,0.282440185546875,31.7693061828613,2,1,1,80.0065155029297,0,80.0065155029297,,,,,,,,,,,,,,,,,,,,,,,,,,,,,,,,,
,3866199242.86106,110.109275817871,26.424976348877,1.19206552853467E-5,7.02706403255244E-9,1,5,12.9061126708984,5.00194016362925,41.5400005877018,0.0155743257368298,0.00228161864129419,1,-4.81064891181668E-9,,,,,,,,,,,,,,,,,,,,,110.109275817871,110.109275817871,26.424976348877,26.424976348877,49.7018034665918,5.41191908957973,6.9181981086731,64,1,64,0,0,0.280838012695313,32.2580642700195,2,1,1,110.109275817871,0,110.109275817871,,,,,,,,,,,,,,,,,,,,,,,,,,,,,,,,,
,3866199423.25925,140.000091552734,26.424976348877,1.08145755644991E-5,6.32915473940947E-9,1,5,12.9061126708984,5.00422486873397,41.6099987924099,0.014138807623291,0.00206756721643471,1,-7.17235201387219E-9,,,,,,,,,,,,,,,,,,,,,140.000091552734,140.000091552734,26.424976348877,26.424976348877,49.8155304161399,5.40380990628783,7.00692272186279,64,1,64,0,0,0.276260375976562,31.7693061828613,2,1,1,140.000091552734,0,140.000091552734,,,,,,,,,,,,,,,,,,,,,,,,,,,,,,,,,
,3866199604.50654,170.006118774414,26.424976348877,1.0004471282315E-5,7.45046768101933E-9,1,5,12.9061126708984,5.0044245317209,41.7100004851818,0.0130817822642276,0.00190352447375914,1,-1.37266800641707E-8,,,,,,,,,,,,,,,,,,,,,170.006118774414,170.006118774414,26.424976348877,26.424976348877,49.7404940782937,5.40217853442457,7.07293272018433,64,1,64,0,0,0.276031494140625,31.7693061828613,2,1,1,170.006118774414,0,170.006118774414,,,,,,,,,,,,,,,,,,,,,,,,,,,,,,,,,
,3866199785.89456,200.004333496094,26.424976348877,9.2757679518183E-6,8.53677585211531E-9,1,5,12.9061126708984,5.00567695128112,41.8299995362759,0.0121339334397616,0.00176037954532822,1,-1.66376797064613E-8,,,,,,,,,,,,,,,,,,,,,200.004333496094,200.004333496094,26.424976348877,26.424976348877,49.7955988888995,5.39729778843401,7.15453004837036,64,1,64,0,0,0.27191162109375,31.7693061828613,2,1,1,200.004333496094,0,200.004333496094,,,,,,,,,,,,,,,,,,,,,,,,,,,,,,,,,
,3866199966.5955,230.027038574219,26.424976348877,8.63381632113415E-6,9.80586393637483E-9,1,5,12.9061126708984,5.00687786337644,41.9600009918213,0.0112969506805771,0.00164601189087625,1,-1.02014774965288E-8,,,,,,,,,,,,,,,,,,,,,230.027038574219,230.027038574219,26.424976348877,26.424976348877,49.7932540033418,5.3947637849316,7.29613971710205,63,1,64,0,0,0.278396606445313,31.7693061828613,2,1,1,230.027038574219,0,230.027038574219,,,,,,,,,,,,,,,,,,,,,,,,,,,,,,,,,
,3866200147.10057,260.036376953125,26.424976348877,8.10526154276536E-6,3.03075216257416E-8,1,5,12.9061126708984,5.00825471744213,42.1199984848499,0.0106072261522483,0.00156090922723921,1,1.93835619429375E-9,,,,,,,,,,,,,,,,,,,,,260.036376953125,260.036376953125,26.424976348877,26.424976348877,49.7592531627553,5.39172731977477,7.56034421920776,64,1,64,0,0,0.27618408203125,31.7693061828613,2,1,1,260.036376953125,0,260.036376953125,,,,,,,,,,,,,,,,,,,,,,,,,,,,,,,,,
,3866200327.81496,290.034057617188,26.424976348877,7.39138348910061E-6,5.71692047176919E-8,1,5,12.9061126708984,5.00904864599685,42.2899983823299,0.00966290387753945,0.0015069646338272,1,6.53406319318826E-8,,,,,,,,,,,,,,,,,,,,,290.034057617188,290.034057617188,26.424976348877,26.424976348877,49.8065416881687,5.38711777921496,7.45303106307983,63,1,64,0,0,0.284576416015625,31.7693061828613,2,1,1,290.034057617188,0,290.034057617188,,,,,,,,,,,,,,,,,,,,,,,,,,,,,,,,,
,3866201106.00052,281.998962402344,26.2620124816895,9.19593915933004E-6,7.34913629903319E-9,1,5,12.9061126708984,5.0096788756299,42.2499999403954,0.0120423265380042,0.00175148802475985,1,-1.32048814192202E-8,,,,,,,,,,,,,,,,,,,,,281.998962402344,281.998962402344,26.2620124816895,26.2620124816895,49.776839804438,5.38397135388055,7.83666181564331,63,1,64,0,0,0.281448364257813,31.7693061828613,2,1,1,281.998962402344,0,281.998962402344,,,,,,,,,,,,,,,,,,,,,,,,,,,,,,,,,
,3866201284.89745,251.992477416992,26.2620124816895,9.48363478993435E-6,7.52550019666937E-9,1,5,12.9061126708984,5.00882127424129,42.1000011265278,0.0124165684994636,0.00180265729860333,1,-1.60580308852618E-8,,,,,,,,,,,,,,,,,,,,,251.992477416992,251.992477416992,26.2620124816895,26.2620124816895,49.7334594216207,5.38602966238782,7.68544483184814,63,1,64,0,0,0.285263061523438,31.7693061828613,2,1,1,251.992477416992,0,251.992477416992,,,,,,,,,,,,,,,,,,,,,,,,,,,,,,,,,
,3866201463.16329,221.976181030273,26.2620124816895,9.67126819304199E-6,6.92991280003231E-9,1,5,12.9061126708984,5.00669440490804,41.9900007545948,0.0126527523147423,0.00185056407861381,1,-6.1836638473302E-9,,,,,,,,,,,,,,,,,,,,,221.976181030273,221.976181030273,26.2620124816895,26.2620124816895,49.6595955265533,5.39203308026572,7.59546184539795,65,1,0,0,1,0.271759033203125,31.2805480957031,2,1,1,221.976181030273,0,221.976181030273,,,,,,,,,,,,,,,,,,,,,,,,,,,,,,,,,
,3866201642.5954,191.975799560547,26.2620124816895,9.75198824129391E-6,6.56375464430662E-9,1,5,12.9061126708984,5.00650050065501,41.8800003826618,0.0127584744058926,0.00186040417456577,1,-1.04431824443887E-8,,,,,,,,,,,,,,,,,,,,,191.975799560547,191.975799560547,26.2620124816895,26.2620124816895,49.6791362395341,5.3944223887438,7.52446794509888,65,1,0,0,1,0.279998779296875,31.7693061828613,2,1,1,191.975799560547,0,191.975799560547,,,,,,,,,,,,,,,,,,,,,,,,,,,,,,,,,
,3866201823.68941,161.987457275391,26.2620124816895,9.66660102137292E-6,6.71980026561353E-9,1,5,12.9061126708984,5.00146188897466,41.7799986898899,0.0126288141091999,0.00184246238891853,1,-9.62854878934014E-9,,,,,,,,,,,,,,,,,,,,,161.987457275391,161.987457275391,26.2620124816895,26.2620124816895,49.1781123587071,5.40800569435314,7.44662618637085,64,1,64,0,0,0.27984619140625,31.7693061828613,2,1,1,161.987457275391,0,161.987457275391,,,,,,,,,,,,,,,,,,,,,,,,,,,,,,,,,
,3866201997.31431,132.898391723633,26.2620124816895,9.42496479413057E-6,6.88075802658741E-9,1,5,12.9061126708984,5.00047780677063,41.6899994015694,0.012309275062867,0.0017990678468303,1,-6.97074299052067E-9,,,,,,,,,,,,,,,,,,,,,132.898391723633,132.898391723633,26.2620124816895,26.2620124816895,49.184365386861,5.41052200139824,7.37871599197388,63,1,64,0,0,0.28106689453125,32.2580642700195,2,1,1,132.898391723633,0,132.898391723633,,,,,,,,,,,,,,,,,,,,,,,,,,,,,,,,,
,3866202176.54539,102.943519592285,26.2620124816895,8.96216794483546E-6,6.91931218898695E-9,1,5,12.9061126708984,5.00052295682376,41.6099987924099,0.0117047438918282,0.00171247273787551,1,-5.30874042822769E-9,,,,,,,,,,,,,,,,,,,,,102.943519592285,102.943519592285,26.2620124816895,26.2620124816895,49.4673149108225,5.41013171691155,7.29406070709229,65,1,0,0,1,0.280838012695313,31.7693061828613,2,1,1,102.943519592285,0,102.943519592285,,,,,,,,,,,,,,,,,,,,,,,,,,,,,,,,,
,3866202354.95482,72.9804458618164,26.2620124816895,8.8097614927522E-6,5.99761251895778E-9,1,5,12.9061126708984,5.00272760212661,41.5299981832504,0.011515272949732,0.00166757015820363,1,-1.80907435567318E-8,,,,,,,,,,,,,,,,,,,,,72.9804458618164,72.9804458618164,26.2620124816895,26.2620124816895,49.6806994965726,5.4071699260027,7.16166496276855,65,1,0,0,1,0.27679443359375,32.2580642700195,2,1,1,72.9804458618164,0,72.9804458618164,,,,,,,,,,,,,,,,,,,,,,,,,,,,,,,,,
,3866202530.40203,42.9456405639648,26.2620124816895,8.85152439612638E-6,6.42108483463317E-9,1,5,12.9061126708984,5.00463923961485,41.4800010621548,0.0115743514332138,0.0016879318942146,1,-9.33426855554415E-9,,,,,,,,,,,,,,,,,,,,,42.9456405639648,42.9456405639648,26.2620124816895,26.2620124816895,49.7018034665918,5.39952651941867,6.90901184082031,65,1,0,0,1,0.27587890625,32.2580642700195,2,1,1,42.9456405639648,0,42.9456405639648,,,,,,,,,,,,,,,,,,,,,,,,,,,,,,,,,
,3866202708.51906,12.992787361145,26.2620124816895,8.70353279473745E-6,6.60177960023675E-9,1,5,12.9061126708984,5.0020564241828,41.4300002157688,0.0113708723265686,0.00167037765845807,1,-9.59189517570313E-11,,,,,,,,,,,,,,,,,,,,,12.992787361145,12.992787361145,26.2620124816895,26.2620124816895,49.6506067985822,5.41080298309037,5.87411260604858,65,1,0,0,1,0.278091430664062,32.2580642700195,2,1,1,12.992787361145,0,12.992787361145,,,,,,,,,,,,,,,,,,,,,,,,,,,,,,,,,
,3866204840.93719,19.0287284851074,26.2620124816895,8.70854323345238E-6,6.12594549888608E-9,1,5,12.9061126708984,5.00174970566762,41.4099991321564,0.0113788123399032,0.00165505793201402,1,-1.24493354020756E-8,,,,,,,,,,,,,,,,,,,,,19.0287284851074,19.0287284851074,26.2620124816895,26.2620124816895,49.677182168236,5.4108974475863,5.6091046333313,65,1,0,0,1,0.282440185546875,31.2805480957031,2,1,1,19.0287284851074,0,19.0287284851074,,,,,,,,,,,,,,,,,,,,,,,,,,,,,,,,,
,3866205032.4147,49.0103988647461,26.2620124816895,8.7455885514028E-6,6.03739618518912E-9,1,5,12.9061126708984,5.00538291385671,41.4200015366077,0.0114373263489987,0.00167406812208505,1,-4.64133661662003E-9,,,,,,,,,,,,,,,,,,,,,49.0103988647461,49.0103988647461,26.2620124816895,26.2620124816895,49.6451353989476,5.398231553059,6.46943044662476,65,1,0,0,1,0.274505615234375,31.7693061828613,2,1,1,49.0103988647461,0,49.0103988647461,,,,,,,,,,,,,,,,,,,,,,,,,,,,,,,,,
,3866205221.1234,79.044792175293,26.2620124816895,8.76315893403203E-6,6.09014687488145E-9,1,5,12.9061126708984,5.00160797983848,41.4699986577034,0.0114476961454079,0.00167915018694261,1,-1.979590384847E-9,,,,,,,,,,,,,,,,,,,,,79.044792175293,79.044792175293,26.2620124816895,26.2620124816895,49.7373675642168,5.41211979256093,6.78239917755127,65,1,0,0,1,0.280227661132813,31.7693061828613,2,1,1,79.044792175293,0,79.044792175293,,,,,,,,,,,,,,,,,,,,,,,,,,,,,,,,,
,3866205404.51215,109.011703491211,26.2620124816895,8.70094845098624E-6,6.28433168107606E-9,1,5,12.9061126708984,5.00223235095592,41.5299981832504,0.0113696584118695,0.00165905465362946,1,-8.44568658911667E-9,,,,,,,,,,,,,,,,,,,,,109.011703491211,109.011703491211,26.2620124816895,26.2620124816895,49.5677541755437,5.40745998785471,6.92960643768311,65,1,0,0,1,0.28076171875,31.2805480957031,2,1,1,109.011703491211,0,109.011703491211,,,,,,,,,,,,,,,,,,,,,,,,,,,,,,,,,
,3866205586.06924,139.023788452148,26.2620124816895,8.59867525883183E-6,6.47069996755958E-9,1,5,12.9061126708984,5.00105222758039,41.6099987924099,0.011233488081778,0.00163095943415732,1,-1.45118739802411E-8,,,,,,,,,,,,,,,,,,,,,139.023788452148,139.023788452148,26.2620124816895,26.2620124816895,49.5239829784668,5.41308690900196,7.02668714523315,63,1,64,0,0,0.282745361328125,32.2580642700195,2,1,1,139.023788452148,0,139.023788452148,,,,,,,,,,,,,,,,,,,,,,,,,,,,,,,,,
,3866205766.99968,169.090103149414,26.2620124816895,8.48343311838166E-6,6.13108465906045E-9,1,5,12.9061126708984,5.00421834301357,41.7000018060207,0.0110914319730669,0.00161954759589347,1,-7.41704535907473E-9,,,,,,,,,,,,,,,,,,,,,169.090103149414,169.090103149414,26.2620124816895,26.2620124816895,49.7049299806687,5.40215020817937,7.09961175918579,64,1,64,0,0,0.276641845703125,31.2805480957031,2,1,1,169.090103149414,0,169.090103149414,,,,,,,,,,,,,,,,,,,,,,,,,,,,,,,,,
,3866205947.90092,199.025207519531,26.2620124816895,8.41845580958167E-6,6.12518324282047E-9,1,5,12.9061126708984,5.00462002302998,41.8200008571148,0.0110068483219722,0.00161322665340847,1,-2.84505649693483E-9,,,,,,,,,,,,,,,,,,,,,199.025207519531,199.025207519531,26.2620124816895,26.2620124816895,49.7049299806687,5.40044762671193,7.17655897140503,64,1,64,0,0,0.275650024414062,30.7917900085449,2,1,1,199.025207519531,0,199.025207519531,,,,,,,,,,,,,,,,,,,,,,,,,,,,,,,,,
,3866206129.0533,229.01692199707,26.2620124816895,8.24946091592177E-6,5.690987573028E-9,1,5,12.9061126708984,5.00603430341367,41.9600009918213,0.0107916197776692,0.00157151867675508,1,-1.03944078497156E-8,,,,,,,,,,,,,,,,,,,,,229.01692199707,229.01692199707,26.2620124816895,26.2620124816895,49.731114536063,5.39550458051005,7.31105279922485,64,1,64,0,0,0.2734375,31.7693061828613,2,1,1,229.01692199707,0,229.01692199707,,,,,,,,,,,,,,,,,,,,,,,,,,,,,,,,,
,3866206310.41735,259.219757080078,26.2620124816895,8.09730062511382E-6,6.8872267159966E-9,1,5,12.9061126708984,5.00824839376696,42.1199984848499,0.0105983317061447,0.00154887319122454,1,-6.08673789096133E-9,,,,,,,,,,,,,,,,,,,,,259.219757080078,259.219757080078,26.2620124816895,26.2620124816895,49.6599863408129,5.38956705076336,7.58252096176147,64,1,64,0,0,0.285263061523438,31.7693061828613,2,1,1,259.219757080078,0,259.219757080078,,,,,,,,,,,,,,,,,,,,,,,,,,,,,,,,,
,3866206490.52454,289.077392578125,26.2620124816895,7.82171685629472E-6,7.48917197721851E-9,1,5,12.9061126708984,5.00879136415945,42.2899983823299,0.0102394831503003,0.00149432092511121,1,-7.45697554113793E-9,,,,,,,,,,,,,,,,,,,,,289.077392578125,289.077392578125,26.2620124816895,26.2620124816895,49.6795270537937,5.38530619557255,7.48718643188477,63,1,64,0,0,0.282821655273438,31.7693061828613,2,1,1,289.077392578125,0,289.077392578125,,,,,,,,,,,,,,,,,,,,,,,,,,,,,,,,,
,3866206823.32996,300.004638671875,40477.46875,-2.89151615792755E-5,2.08993364668937E-6,1,2,12.9061126708984,5.00883116517221,42.3399992287159,-0.0337931730825947,-0.0331624591694935,100,-2.10873886584154E-5,,,,,,,,,,,,,,,,,,,,,300.00439453125,300.0048828125,40397.62890625,40557.30859375,49.4813842241687,5.38746195118347,7.48868942260742,25,1,68,0,0,0.283966064453125,32.2580642700195,1,6,1,300.0048828125,0,300.004638671875,,,,,,,,,,,,,,,,,,,,,,,,,,,,,,,,,
,3866206905.87617,300.002502441406,32235.0087890625,-6.98067083554552E-6,1.77895482215606E-6,1,2,12.9061126708984,5.00933852757092,42.3399992287159,-0.00647629429974997,-0.0194643065434838,100,-1.38426318464282E-5,,,,,,,,,,,,,,,,,,,,,300.002410888672,300.002593994141,32130.236328125,32339.78125,49.4833382954668,5.38498191747841,7.55878496170044,26,1,0,0,1,0.283432006835938,32.2580642700195,1,6,1,300.002593994141,0,300.002502441406,,,,,,,,,,,,,,,,,,,,,,,,,,,,,,,,,
,3866206970.25368,300.001831054687,25806.431640625,1.56942017035151E-5,1.36435668672446E-6,1,2,12.9061126708984,5.00989350494015,42.3399992287159,0.022979058801738,-0.0135230636130586,100,-1.2633891455427E-5,,,,,,,,,,,,,,,,,,,,,300.001647949219,300.002014160156,25711.587890625,25901.275390625,49.5904214026014,5.38188587831438,7.65405464172363,26,1,0,0,1,0.281600952148438,32.2580642700195,1,6,1,300.001647949219,0,300.001831054687,,,,,,,,,,,,,,,,,,,,,,,,,,,,,,,,,
,3866207034.71519,300.002090454102,19371.80078125,3.40711769110633E-5,1.52074137861167E-6,1,2,12.9061126708984,5.0099689263424,42.3399992287159,0.0462813572157797,-0.00481385290017968,100,-8.68193234996967E-6,,,,,,,,,,,,,,,,,,,,,300.001861572266,300.002319335937,19281.970703125,19461.630859375,49.6420088848706,5.38214593094646,7.77260541915894,25,1,68,0,0,0.28167724609375,32.2580642700195,1,6,1,300.001861572266,0,300.002090454102,,,,,,,,,,,,,,,,,,,,,,,,,,,,,,,,,
,3866207101.18841,300.002151489258,12732.7006835938,5.28165668707629E-5,1.02417113409273E-6,1,2,12.9061126708984,5.01027973737017,42.3399992287159,0.0709023660910096,-0.00168780609589183,100,-9.04825530245956E-6,,,,,,,,,,,,,,,,,,,,,300.001922607422,300.002380371094,12642.7451171875,12822.65625,49.7647245623899,5.38132874032157,7.91811656951904,25,1,68,0,0,0.280990600585938,31.2805480957031,1,6,1,300.002380371094,0,300.002151489258,,,,,,,,,,,,,,,,,,,,,,,,,,,,,,,,,
,3866207169.80853,300.00178527832,5877.87084960937,7.01475695989339E-5,7.85958788190802E-7,1,2,12.9061126708984,5.01032795875973,42.3399992287159,0.0942295234661161,-0.00265205604529924,100,-1.23307088119774E-5,,,,,,,,,,,,,,,,,,,,,300.001678466797,300.001892089844,5777.78076171875,5977.9609375,49.7264247649476,5.38119395541671,8.07851791381836,26,1,0,0,1,0.280914306640625,31.7693061828613,1,6,1,300.001892089844,0,300.00178527832,,,,,,,,,,,,,,,,,,,,,,,,,,,,,,,,,
,3866207236.37844,300.000518798828,-773.695159912109,-3.18966043242551E-5,2.26393840543946E-6,1,2,12.9061126708984,5.01025500640299,42.3399992287159,-0.0399784359087287,-0.0183129731761663,100,-9.29916411898339E-6,,,,,,,,,,,,,,,,,,,,,300.000244140625,300.000793457031,-888.571044921875,-658.819274902344,49.7936448176014,5.38134990421006,8.03244209289551,25,1,68,0,0,0.281753540039062,31.7693061828613,1,6,1,300.000244140625,0,300.000518798828,,,,,,,,,,,,,,,,,,,,,,,,,,,,,,,,,
,3866207315.09792,299.999420166016,-8641.16748046875,-5.98866440890105E-5,9.71076824647579E-7,1,2,12.9061126708984,5.01000612449309,42.3399992287159,-0.0783564097239233,-0.0119102879937799,10,-2.98194046532653E-7,,,,,,,,,,,,,,,,,,,,,299.999389648438,299.999450683594,-8696.1611328125,-8586.173828125,49.606053972986,5.3828822717912,7.96300554275513,24,1,68,0,0,0.28167724609375,31.2805480957031,1,6,1,299.999389648438,0,299.999420166016,,,,,,,,,,,,,,,,,,,,,,,,,,,,,,,,,
,3866207427.53166,300.00080871582,-19892.0703125,-3.40584615489876E-5,1.86484351914495E-6,1,2,12.9061126708984,5.01010146779845,42.3399992287159,-0.0458583549711304,0.00203884674537636,100,6.56064008148491E-6,,,,,,,,,,,,,,,,,,,,,300.000762939453,300.000854492188,-19987.0078125,-19797.1328125,49.6541241269187,5.38213047364638,7.91215753555298,26,1,0,0,1,0.281600952148438,31.7693061828613,1,6,1,300.000762939453,0,300.00080871582,,,,,,,,,,,,,,,,,,,,,,,,,,,,,,,,,
,3866207494.0476,300.000885009766,-26544.4443359375,-1.30146288764998E-5,1.84603192409052E-6,1,2,12.9061126708984,5.01022844554925,42.3399992287159,-0.0181319333720776,0.0049152065496765,100,5.66563025638394E-6,,,,,,,,,,,,,,,,,,,,,300.000732421875,300.001037597656,-26639.58203125,-26449.306640625,49.726033950688,5.38126520842897,7.89676475524902,26,1,0,0,1,0.280609130859375,31.7693061828613,1,6,1,300.001037597656,0,300.000885009766,,,,,,,,,,,,,,,,,,,,,,,,,,,,,,,,,
,3866207570.56573,300.000457763672,-34207.857421875,6.61954953700197E-6,1.62871466808495E-6,1,2,12.9061126708984,5.01017529039493,42.3399992287159,0.00707039328946593,0.0121470288071042,100,8.3040808912209E-6,,,,,,,,,,,,,,,,,,,,,300.000366210937,300.000549316406,-34303,-34112.71484375,49.6877341532456,5.38149876632601,7.87603616714478,26,1,0,0,1,0.2801513671875,31.7693061828613,1,6,1,300.000366210937,0,300.000457763672,,,,,,,,,,,,,,,,,,,,,,,,,,,,,,,,,
,3866207657.2227,300.000549316406,-42889.16796875,3.08176448149971E-5,1.98884211023966E-6,1,2,12.9061126708984,5.01022635536493,42.3399992287159,0.0398151288835465,0.00959768582541957,100,2.80210334545227E-6,,,,,,,,,,,,,,,,,,,,,300.000427246094,300.000671386719,-42989.3203125,-42789.015625,49.6044907159476,5.38106959845178,7.86247110366821,25,1,68,0,0,0.281753540039062,31.2805480957031,1,6,1,300.000671386719,0,300.000549316406,,,,,,,,,,,,,,,,,,,,,,,,,,,,,,,,,
,3866207750.94754,299.998840332031,-48419.37890625,2.75911233443911E-5,1.50351180554772E-6,1,2,12.9061126708984,5.01017124409886,42.3399992287159,0.0269647461977216,0.0676849726295727,100,4.76369612836878E-5,,,,,,,,,,,,,,,,,,,,,299.998840332031,299.998840332031,-48424.3671875,-48414.390625,49.6588138980341,5.3811238293322,7.8610782623291,25,1,68,0,0,0.28076171875,31.2805480957031,1,6,1,299.998840332031,0,299.998840332031,,,,,,,,,,,,,,,,,,,,,,,,,,,,,,,,,
,3866207880.81941,300.00178527832,-35453.892578125,1.00077028829496E-6,1.64729198749451E-6,1,2,12.9061126708984,5.01004022885257,42.3399992287159,-0.00216716633433762,0.0238637025771297,100,1.80781352324134E-5,,,,,,,,,,,,,,,,,,,,,300.001708984375,300.001861572266,-35548.75,-35359.03515625,49.6963320669572,5.38173156504337,7.85128307342529,26,1,0,0,1,0.281829833984375,32.2580642700195,1,6,1,300.001861572266,0,300.00178527832,,,,,,,,,,,,,,,,,,,,,,,,,,,,,,,,,
,3866207949.30186,299.999450683594,-28621.7646484375,-1.2081842958389E-5,2.14009464826046E-6,1,2,12.9061126708984,5.01000391975251,42.3399992287159,-0.0181229796547674,0.0133547298193276,100,1.1974317200961E-5,,,,,,,,,,,,,,,,,,,,,299.999206542969,299.999694824219,-28711.525390625,-28532.00390625,49.621295729111,5.38209145276739,7.84180927276611,25,1,68,0,0,0.281600952148438,31.7693061828613,1,6,1,299.999206542969,0,299.999450683594,,,,,,,,,,,,,,,,,,,,,,,,,,,,,,,,,
,3866208013.7716,299.999816894531,-22183.3525390625,-3.06005637320362E-5,1.47563242625912E-6,1,2,12.9061126708984,5.01004486719279,42.3399992287159,-0.042148819657414,0.00827814629606699,100,1.08177260858916E-5,,,,,,,,,,,,,,,,,,,,,299.999694824219,299.999938964844,-22273.18359375,-22093.521484375,49.6521700556206,5.38171321687054,7.84072065353394,26,1,0,0,1,0.281600952148438,31.7693061828613,1,6,1,299.999694824219,0,299.999816894531,,,,,,,,,,,,,,,,,,,,,,,,,,,,,,,,,
,3866208080.27429,300.001693725586,-15549.9448242187,-4.801508347297E-5,1.22384036748413E-6,1,2,12.9061126708984,5.0098135361134,42.3399992287159,-0.0645064706601464,0.00192983673068634,100,8.52788752863631E-6,,,,,,,,,,,,,,,,,,,,,300.001556396484,300.001831054687,-15644.6005859375,-15455.2890625,49.5845591887072,5.38217847680391,7.83633041381836,26,1,0,0,1,0.281600952148438,31.7693061828613,1,6,1,300.001831054687,0,300.001693725586,,,,,,,,,,,,,,,,,,,,,,,,,,,,,,,,,
,3866208146.73245,299.999740600586,-8908.16845703125,-6.38482388061654E-5,7.79990615645454E-7,1,2,12.9061126708984,5.01000779357287,42.3399992287159,-0.0856314972951758,0.00153935962007116,100,1.05556541315944E-5,,,,,,,,,,,,,,,,,,,,,299.999664306641,299.999816894531,-9003.0693359375,-8813.267578125,49.7080564947457,5.38180587840893,7.82990837097168,26,1,0,0,1,0.28167724609375,30.3030319213867,1,6,1,299.999816894531,0,299.999740600586,,,,,,,,,,,,,,,,,,,,,,,,,,,,,,,,,
,3866208213.21301,299.999206542969,-2263.64758300781,-6.97672179766538E-5,1.25824573125634E-6,1,2,12.9061126708984,5.01026608581783,42.3399992287159,-0.0947265704743333,0.00950977110050142,100,1.75119021411341E-5,,,,,,,,,,,,,,,,,,,,,299.999145507812,299.999267578125,-2358.71728515625,-2168.57788085938,49.692423924361,5.38112504704855,7.82877254486084,26,1,0,0,1,0.28106689453125,31.7693061828613,1,6,1,299.999267578125,0,299.999206542969,,,,,,,,,,,,,,,,,,,,,,,,,,,,,,,,,
,3866208277.69394,299.999771118164,4184.19067382812,6.15034217156332E-5,2.13361970812145E-6,1,2,12.9061126708984,5.01006686336238,42.3399992287159,0.0795373547037869,0.0186020917372019,100,5.1711361902074E-6,,,,,,,,,,,,,,,,,,,,,299.99951171875,300.000030517578,4089.064453125,4279.31689453125,49.6869525247264,5.38194147588964,7.82318115234375,25,1,68,0,0,0.280532836914062,30.7917900085449,1,6,1,299.99951171875,0,299.999771118164,,,,,,,,,,,,,,,,,,,,,,,,,,,,,,,,,
,3866208365.84365,300.001495361328,12999.658203125,5.25937424174812E-5,9.72133465754545E-7,1,2,12.9061126708984,5.0100934038018,42.3399992287159,0.0692446764542245,0.00754195275202549,10,-1.96675078429447E-6,,,,,,,,,,,,,,,,,,,,,300.001495361328,300.001495361328,12999.658203125,12999.658203125,49.727988021986,5.38190740418713,7.81506633758545,26,1,0,0,1,0.281600952148438,31.7693061828613,1,6,1,300.001495361328,0,300.001495361328,,,,,,,,,,,,,,,,,,,,,,,,,,,,,,,,,
,3866208469.21311,300.0009765625,23331.5537109375,2.69164674261559E-5,1.58383175524097E-6,1,2,12.9061126708984,5.0100232511567,42.3399992287159,0.0366231816764364,-0.00421166632984645,100,-7.17086803056805E-6,,,,,,,,,,,,,,,,,,,,,300.000610351562,300.001342773438,23221.423828125,23441.68359375,49.6853892676879,5.38222878342337,7.80506706237793,26,1,0,0,1,0.280532836914062,31.7693061828613,1,6,1,300.000610351562,0,300.0009765625,,,,,,,,,,,,,,,,,,,,,,,,,,,,,,,,,
,3866208533.51397,299.999923706055,29774.748046875,8.23662689797905E-6,1.53095554101835E-6,1,2,12.9061126708984,5.00984351757827,42.3399992287159,0.0118012362069694,-0.00533777949772908,100,-5.28683724981371E-6,,,,,,,,,,,,,,,,,,,,,299.999572753906,300.000274658203,29679.4453125,29870.05078125,49.819438558736,5.38221327218895,7.80230522155762,26,1,0,0,1,0.279769897460938,31.7693061828613,1,6,1,299.999572753906,0,299.999923706055,,,,,,,,,,,,,,,,,,,,,,,,,,,,,,,,,
,3866208606.04759,299.999801635742,37040.19921875,-1.04574738968987E-5,1.90875632453199E-6,1,2,12.9061126708984,5.01015720379784,42.3399992287159,-0.0129426836923568,-0.00712087817505357,100,-3.90185391143788E-6,,,,,,,,,,,,,,,,,,,,,299.999694824219,299.999908447266,36944.99609375,37135.40234375,49.651779241361,5.38162882209619,7.7967677116394,26,1,0,0,1,0.282745361328125,31.7693061828613,1,6,1,299.999694824219,0,299.999801635742,,,,,,,,,,,,,,,,,,,,,,,,,,,,,,,,,
,3866208671.84486,299.999649047852,43638.46484375,-3.01407770895561E-5,1.52206645789859E-6,1,2,12.9061126708984,5.01015833172074,42.3399992287159,-0.038471946088997,-0.0125720282954695,100,-5.17316827638014E-6,,,,,,,,,,,,,,,,,,,,,299.999450683594,299.999847412109,43478.0078125,43798.921875,49.6877341532456,5.3815913204175,7.78359937667847,26,1,0,0,1,0.281448364257813,32.2580642700195,1,6,1,299.999450683594,0,299.999649047852,,,,,,,,,,,,,,,,,,,,,,,,,,,,,,,,,
,3866208739.00305,300.000213623047,50000.1953125,-4.85658384888321E-5,1.71517263850479E-7,1,2,12.9061126708984,5.01029523994703,42.3399992287159,-0.0634650852682416,-0.0102325213958241,100,-6.79359848827746E-7,,,,,,,,,,,,,,,,,,,,,300.000122070313,300.000305175781,50000.17578125,50000.21484375,49.6037090874283,5.38105941109826,7.78219985961914,26,1,0,0,1,0.281219482421875,31.7693061828613,1,4,1,300.000305175781,0,300.000213623047,,,,,,,,,,,,,,,,,,,,,,,,,,,,,,,,,