File: LT data/Frome/M1/300-FC-ZFC-RTSIRM-contsweepwithloop-MsT-AC.dat
[Header]
; MPMS3 Data File (default extension .dat)
; Copyright (c) 2007, Quantum Design, Inc. All rights reserved.
TITLE,
FILEOPENTIME,3866116436.74352,07/04/2022,6:11 pm
BYAPP,MPMS3 w/ AC,1.0,1.1
INFO,MPMS3 Measurement Release 1.1.16 Build 424, MultiVu Release 2.3.4.19,APPNAME
INFO,Linear Motor Servo Controller,MOTOR_MODULE_NAME
INFO,3101-100 N2,MOTOR_HW_VERSION
INFO,,MOTOR_SERIAL_NUMBER
INFO,01.04.28,MOTOR_SOFTWARE_VERSION
INFO,Quantum Design Squid Module,SQUID_MODULE_NAME
INFO,3101-501 B0,SQUID_HW_VERSION
INFO,SQM327,SQUID_SERIAL_NUMBER
INFO,01.03.04,SQUID_SOFTWARE_VERSION
INFO,Quantum Design VSM Oven,OVEN_MODULE_NAME
INFO,3101-201 A3,OVEN_HW_VERSION
INFO,OVB365,OVEN_SERIAL_NUMBER
INFO,01.07.07,OVEN_SOFTWARE_VERSION
INFO,SQUID AC,AC_MODULE_NAME
INFO,3101-401 G0,AC_HW_VERSION
INFO,SAC220,AC_SERIAL_NUMBER
INFO,SQUID AC 00.95.07,AC_SOFTWARE_VERSION
INFO,TCI344,COIL_SERIAL_NUMBER
INFO,0,MOMENT_UNITS
INFO,sndst,SAMPLE_MATERIAL
INFO,,SAMPLE_COMMENT
INFO,153.48,SAMPLE_MASS
INFO,,SAMPLE_VOLUME
INFO,,SAMPLE_MOLECULAR_WEIGHT
INFO,,SAMPLE_SIZE
INFO,,SAMPLE_SHAPE
INFO,Straw,SAMPLE_HOLDER
INFO,Standard,SAMPLE_HOLDER_DETAIL
INFO,57.25,SAMPLE_OFFSET
DATATYPE,COMMENT,1
DATATYPE,TIME,2
STARTUPAXIS,X,2
STARTUPAXIS,Y1,5
FIELDGROUP, VSM,2,3,4,5,6,8,9,10,11,14,15
FIELDGROUP, DC, 2,3,4,14,56,57,58,59,60,61,62,63,64,65,66,67,68,69
FIELDGROUP, AC, 2,3,4,11,16,17,18,19,20,21,22,23,24,25,26,27,28,29,30
STARTUPGROUP, All
[Data]
Comment,Time Stamp (sec),Temperature (K),Magnetic Field (Oe),Moment (emu),M. Std. Err. (emu),Transport Action,Averaging Time (sec),Frequency (Hz),Peak Amplitude (mm),Center Position (mm),Lockin Signal' (V),Lockin Signal (V),Range,M. Quad. Signal (emu),AC Moment (emu),AC M. Std Err. (emu),AC Phase (deg),AC Phase Std. Err. (deg),AC Susceptibility (emu/Oe),AC Suscept. Std Err. (emu/Oe),AC X' (emu/Oe),AC X' Std Err. (emu/Oe),AC X'' (emu/Oe),AC X'' Std Err. (emu/Oe),AC Drive (Oe),AC Frequency (Hz),AC Averaging Time (sec),AC Cycles,AC Range,AC Measure Type,AC Signal' (V),AC Signal'' (V),AC Trim Coil Ratio,AC Trim Coil Phase,Min. Temperature (K),Max. Temperature (K),Min. Field (Oe),Max. Field (Oe),Mass (grams),Motor Lag (deg),Pressure (Torr),Measure Count,Measurement Number,SQUID Status (code),Motor Status (code),Measure Status (code),Motor Current (amps),Motor Temp. (C),Temp. Status (code),Field Status (code),Chamber Status (code),Chamber Temp (K),Redirection State,Average Temp (K),Rotation Angle (deg),Rotator state,DC Moment Fixed Ctr (emu),DC Moment Err Fixed Ctr (emu),DC Moment Free Ctr (emu),DC Moment Err Free Ctr (emu),DC Fixed Fit,DC Free Fit,DC Calculated Center (mm),DC Calculated Center Err (mm),DC Scan Length (mm),DC Scan Time (s),DC Number of Points,DC Squid Drift,DC Min V (V),DC Max V (V),DC Scans per Measure,Map 01,Map 02,Map 03,Map 04,Map 05,Map 06,Map 07,Map 08,Map 09,Map 10,Map 11,Map 12,Map 13,Map 14,Map 15,Map 16
,3866117474.02082,100.001121520996,49999.48828125,0.0034062989232093,3.97847981605147E-7,1,2,12.9061126708984,4.97795503452497,37.3300015926361,4.42082766877288,0.644727108174736,100,-3.57628992698534E-6,,,,,,,,,,,,,,,,,,,,,100.001121520996,100.001121520996,49999.48828125,49999.48828125,49.7291604647649,5.38056574577763,7.34225702285767,26,1,0,0,1,0.266342163085938,29.8142719268799,1,1,1,100.001121520996,0,100.001121520996,,,,,,,,,,,,,,,,,,,,,,,,,,,,,,,,,
,3866117598.10838,82.9602699279785,49999.48828125,0.00460300123435537,3.07617128979276E-5,1,2,12.9061126708984,4.98710968392844,37.3300015926361,5.99549654309946,0.831986502398636,10,-3.67305659964815E-5,,,,,,,,,,,,,,,,,,,,,82.7783355712891,83.142204284668,49999.48828125,49999.48828125,49.7186084797553,5.38366698361417,7.25451898574829,26,1,0,0,1,0.266799926757813,30.3030319213867,2,1,1,82.7783355712891,0,82.9602699279785,,,,,,,,,,,,,,,,,,,,,,,,,,,,,,,,,
,3866117722.39207,61.9542198181152,49999.48828125,0.00707171292813498,5.95667032102128E-6,1,2,12.9061126708984,4.9877304774393,37.3300015926361,9.20138702252769,1.3550937563961,10,2.48944313481497E-6,,,,,,,,,,,,,,,,,,,,,61.717945098877,62.1904945373535,49999.48828125,49999.48828125,49.7627704910918,5.37941254559183,7.11511516571045,26,1,0,0,1,0.284576416015625,30.7917900085449,2,1,1,61.717945098877,0,61.9542198181152,,,,,,,,,,,,,,,,,,,,,,,,,,,,,,,,,
,3866117847.2546,40.6389083862305,49999.48828125,0.0117117332158041,8.80247098212473E-5,1,2,12.9061126708984,4.98765907989315,37.3300015926361,15.2557196705433,2.12670272742795,100,-8.6159197329468E-5,,,,,,,,,,,,,,,,,,,,,40.6389083862305,40.6389083862305,49999.48828125,49999.48828125,49.8253007726303,5.38250414115918,6.86941576004028,26,1,0,0,1,0.275421142578125,31.2805480957031,2,1,1,40.6389083862305,0,40.6389083862305,,,,,,,,,,,,,,,,,,,,,,,,,,,,,,,,,
,3866118005.04049,14.4569244384766,49999.48828125,0.0289655081809677,0.000302411745990259,1,2,12.9061126708984,4.98168276449822,37.3300015926361,37.6593720986408,5.30295684520718,1000,-0.000173029509873053,,,,,,,,,,,,,,,,,,,,,14.2750549316406,14.6387939453125,49999.48828125,49999.48828125,50.0148456885438,5.40554977935549,5.69560623168945,26,1,0,0,1,0.276107788085938,30.3030319213867,2,1,1,14.2750549316406,0,14.4569244384766,,,,,,,,,,,,,,,,,,,,,,,,,,,,,,,,,
,3866118149.3411,4.2090220451355,49999.48828125,0.0459190071868739,0.000355970304299753,1,2,12.9061126708984,4.98225989016465,37.3300015926361,59.584798070446,9.26790851306239,1000,0.0003874523481225,,,,,,,,,,,,,,,,,,,,,4.19785833358765,4.22018575668335,49999.48828125,49999.48828125,50.4138670476111,5.40409072376445,3.82124757766724,26,1,0,0,1,0.272064208984375,31.2805480957031,6,1,1,4.19785833358765,0,4.2090220451355,,,,,,,,,,,,,,,,,,,,,,,,,,,,,,,,,
,3866118234.78232,3.95051252841949,49999.48828125,0.0468836045231147,0.000456372968421355,1,2,12.9061126708984,4.98324898934602,37.3300015926361,60.7772729872835,9.98368313246377,1000,0.000794526866297787,,,,,,,,,,,,,,,,,,,,,3.94734740257263,3.95367765426636,49999.48828125,49999.48828125,50.5049267701015,5.40176585069166,3.70683717727661,26,1,0,0,1,0.279769897460938,31.2805480957031,6,1,1,3.94734740257263,0,3.95051252841949,,,,,,,,,,,,,,,,,,,,,,,,,,,,,,,,,
,3866118301.68089,3.68112409114838,49999.48828125,0.046868729371224,0.00052670837472149,1,2,12.9061126708984,4.98376269349617,37.3300015926361,60.6326614566755,10.894955424574,1000,0.00149670360509153,,,,,,,,,,,,,,,,,,,,,3.64086008071899,3.72138810157776,49999.48828125,49999.48828125,50.3939355203707,5.39970002957905,3.60261082649231,24,1,68,0,0,0.27008056640625,31.2805480957031,6,1,1,3.64086008071899,0,3.68112409114838,,,,,,,,,,,,,,,,,,,,,,,,,,,,,,,,,
,3866118365.87011,2.7185879945755,49999.48828125,0.0479292629080033,0.000598393168314214,1,2,12.9061126708984,4.98232989123148,37.3300015926361,62.1002925262252,10.3154072785364,1000,0.000898220939374291,,,,,,,,,,,,,,,,,,,,,2.71497201919556,2.72220396995544,49999.48828125,49999.48828125,50.5901242786977,5.40473990774117,3.16208457946777,26,1,0,0,1,0.273361206054687,32.2580642700195,6,1,1,2.71497201919556,0,2.7185879945755,,,,,,,,,,,,,,,,,,,,,,,,,,,,,,,,,
,3866118432.47192,2.61965882778168,49999.48828125,0.0481988390691445,0.000617951943120247,1,2,12.9061126708984,4.98336167203551,37.3300015926361,62.5897446979447,9.54602798157382,1000,0.000264304354653193,,,,,,,,,,,,,,,,,,,,,2.61964583396912,2.61967182159424,49999.48828125,49999.48828125,50.5717560084957,5.40137350841077,3.09410977363586,26,1,0,0,1,0.271530151367187,31.2805480957031,6,1,1,2.61967182159424,0,2.61965882778168,,,,,,,,,,,,,,,,,,,,,,,,,,,,,,,,,
,3866118496.88778,2.67241156101227,49999.48828125,0.048103668109846,0.000513824956373957,1,2,12.9061126708984,4.98328913688784,37.3300015926361,62.3404493659516,10.3739682304301,1000,0.00091551227059533,,,,,,,,,,,,,,,,,,,,,2.66928172111511,2.67554140090942,49999.48828125,49999.48828125,50.5854345075823,5.40158074306822,3.10898160934448,26,1,0,0,1,0.2734375,31.7693061828613,6,1,1,2.66928172111511,0,2.67241156101227,,,,,,,,,,,,,,,,,,,,,,,,,,,,,,,,,
,3866118573.20015,2.63415479660034,49999.48828125,0.0490677867735187,0.000458902609175681,1,2,12.9061126708984,4.98310086171522,37.3300015926361,63.6253850584673,10.3168676062717,1000,0.000730356871211817,,,,,,,,,,,,,,,,,,,,,2.63378977775574,2.63451981544495,49999.48828125,49999.48828125,50.4838228000823,5.40204151838861,3.09194493293762,26,1,0,0,1,0.274200439453125,30.7917900085449,6,1,1,2.63378977775574,0,2.63415479660034,,,,,,,,,,,,,,,,,,,,,,,,,,,,,,,,,
,3866118639.61334,2.60633146762848,49999.48828125,0.0488119231983382,0.000616674853556586,1,2,12.9061126708984,4.98324011037354,37.3300015926361,63.2907397330098,10.2999348729238,1000,0.000754604881990657,,,,,,,,,,,,,,,,,,,,,2.60594177246094,2.60672116279602,49999.48828125,49999.48828125,50.483041171563,5.40121034993493,3.07937359809876,26,1,0,0,1,0.273818969726562,30.7917900085449,6,1,1,2.60594177246094,0,2.60633146762848,,,,,,,,,,,,,,,,,,,,,,,,,,,,,,,,,
,3866118706.3394,2.55803394317627,49999.48828125,0.0481345905266918,0.00038507609062798,1,2,12.9061126708984,4.98337873857484,37.3300015926361,62.4950285461432,9.61220960667526,1000,0.000324631379414925,,,,,,,,,,,,,,,,,,,,,2.55557465553284,2.5604932308197,49999.48828125,49999.48828125,50.5838712505438,5.40117736020085,3.04172325134277,26,1,0,0,1,0.279922485351562,30.7917900085449,6,1,1,2.5604932308197,0,2.55803394317627,,,,,,,,,,,,,,,,,,,,,,,,,,,,,,,,,
,3866118786.67794,2.5377471446991,49999.48828125,0.0480162472431967,0.000436480478410117,1,2,12.9061126708984,4.98278884440825,37.3300015926361,62.2176719424726,10.3584530325052,1000,0.000917541429521814,,,,,,,,,,,,,,,,,,,,,2.53701543807983,2.53847885131836,49999.48828125,49999.48828125,50.5905150929573,5.40242347793375,3.04534769058228,26,1,0,0,1,0.271072387695313,31.2805480957031,6,1,1,2.53701543807983,0,2.5377471446991,,,,,,,,,,,,,,,,,,,,,,,,,,,,,,,,,
,3866118859.21015,2.11086452007294,49999.48828125,0.0490458490651754,0.000430776204325495,1,2,12.9061126708984,4.98423699895394,37.3300015926361,63.7169798492353,9.63714013289168,1000,0.000208146400698838,,,,,,,,,,,,,,,,,,,,,2.09550786018372,2.12622117996216,49999.48828125,49999.48828125,50.544008196063,5.39860929965504,2.81062340736389,26,1,0,0,1,0.278778076171875,30.7917900085449,2,1,1,2.12622117996216,0,2.11086452007294,,,,,,,,,,,,,,,,,,,,,,,,,,,,,,,,,
,3866118927.92177,2.09479129314423,49999.48828125,0.0485807777623703,0.000500514686238252,1,2,12.9061126708984,4.98459532874613,37.3300015926361,63.0022683572783,10.3424229432345,1000,0.000818216682016023,,,,,,,,,,,,,,,,,,,,,2.08589863777161,2.10368394851685,49999.48828125,49999.48828125,50.6428842037457,5.39628661096298,2.77055668830872,26,1,0,0,1,0.2679443359375,31.2805480957031,2,1,1,2.08589863777161,0,2.09479129314423,,,,,,,,,,,,,,,,,,,,,,,,,,,,,,,,,
,3866118992.476,1.99907648563385,49999.48828125,0.0489715854567423,0.00051916170615634,1,2,12.9061126708984,4.98583940031878,37.3300015926361,63.5564104293712,10.2587302370012,1000,0.000693661864780001,,,,,,,,,,,,,,,,,,,,,1.9986230134964,1.9995299577713,49999.48828125,49999.48828125,50.7175297273323,5.39223227077499,2.70218968391418,26,1,0,0,1,0.2655029296875,31.2805480957031,6,1,1,1.9995299577713,0,1.99907648563385,,,,,,,,,,,,,,,,,,,,,,,,,,,,,,,,,
,3866119060.83514,1.999751329422,49999.48828125,0.0490543171618706,0.000559305186426267,1,2,12.9061126708984,4.98635909259136,37.3300015926361,63.6536854623857,10.4097243629329,1000,0.000796438251121432,,,,,,,,,,,,,,,,,,,,,1.99839162826538,2.00111103057861,49999.48828125,49999.48828125,50.589733464438,5.38955254013227,2.68957114219666,26,1,0,0,1,0.2667236328125,30.7917900085449,6,1,1,2.00111103057861,0,1.999751329422,,,,,,,,,,,,,,,,,,,,,,,,,,,,,,,,,
,3866124379.56456,8.78084087371826,26.4500465393066,0.000119218774996048,1.10695818568595E-7,1,5,12.9061126708984,4.99907228291865,37.3300015926361,0.155641342846224,0.022751363732898,10,-8.55269115715542E-8,,,,,,,,,,,,,,,,,,,,,8.41060733795166,9.15107440948486,26.4500465393066,26.4500465393066,49.8077141309476,5.37933862578789,4.54020166397095,65,1,0,0,1,0.279617309570313,31.2805480957031,6,1,1,9.15107440948486,0,8.78084087371826,,,,,,,,,,,,,,,,,,,,,,,,,,,,,,,,,
,3866124569.90919,38.1384124755859,26.4500465393066,7.83795675966085E-5,1.2504631710228E-8,1,5,12.9061126708984,4.99077645823346,37.3300015926361,0.102093674889323,0.0148798457387619,1,-8.93184192291521E-8,,,,,,,,,,,,,,,,,,,,,38.1384124755859,38.1384124755859,26.4500465393066,26.4500465393066,49.9620857634957,5.40781832692196,6.26354694366455,65,1,0,0,1,0.281524658203125,31.7693061828613,2,1,1,38.1384124755859,0,38.1384124755859,,,,,,,,,,,,,,,,,,,,,,,,,,,,,,,,,
,3866124760.30691,68.0708923339844,26.4500465393066,6.85282772085811E-5,1.12631285108941E-8,1,5,12.9061126708984,4.9862630046739,37.3300015926361,0.0891484271104818,0.012993860801246,1,-7.75307728141667E-8,,,,,,,,,,,,,,,,,,,,,68.0708923339844,68.0708923339844,26.4500465393066,26.4500465393066,49.842887414313,5.42782355813629,6.70756530761719,65,1,0,0,1,0.278091430664062,31.7693061828613,2,1,1,68.0708923339844,0,68.0708923339844,,,,,,,,,,,,,,,,,,,,,,,,,,,,,,,,,
,3866124945.45322,98.1091995239258,26.4500465393066,6.26582913548142E-5,8.63631745649176E-9,1,5,12.9061126708984,4.98791045566422,37.3300015926361,0.0815525514228504,0.011868849140929,1,-8.43358900575316E-8,,,,,,,,,,,,,,,,,,,,,98.1091995239258,98.1091995239258,26.4500465393066,26.4500465393066,49.8475771854284,5.41938965041053,6.9084587097168,65,1,0,0,1,0.286788940429687,31.2805480957031,2,1,1,98.1091995239258,0,98.1091995239258,,,,,,,,,,,,,,,,,,,,,,,,,,,,,,,,,
,3866125126.79318,128.025421142578,26.4500465393066,5.75013445502198E-5,5.5513553721113E-9,1,5,12.9061126708984,4.99200352359301,37.3300015926361,0.074927608942324,0.0108987483513456,1,-8.1852654780062E-8,,,,,,,,,,,,,,,,,,,,,128.025421142578,128.025421142578,26.4500465393066,26.4500465393066,49.7002402095533,5.40519802374322,7.02925682067871,65,1,0,0,1,0.279006958007813,31.2805480957031,2,1,1,128.025421142578,0,128.025421142578,,,,,,,,,,,,,,,,,,,,,,,,,,,,,,,,,
,3866125308.34222,158.115325927734,26.4500465393066,5.36261678721223E-5,7.47196555693996E-9,1,5,12.9061126708984,4.99493368722237,37.3300015926361,0.0699362542066886,0.0101678670989387,1,-7.9980950691102E-8,,,,,,,,,,,,,,,,,,,,,158.115325927734,158.115325927734,26.4500465393066,26.4500465393066,49.7780122472168,5.39366987996747,7.11118412017822,65,1,0,0,1,0.26763916015625,31.2805480957031,2,1,1,158.115325927734,0,158.115325927734,,,,,,,,,,,,,,,,,,,,,,,,,,,,,,,,,
,3866125488.86998,188.080261230469,26.4500465393066,4.99890716203601E-5,6.08440870870358E-9,1,5,12.9061126708984,4.99655827688439,37.3300015926361,0.0652205890372086,0.00949681650174846,1,-6.36364161898027E-8,,,,,,,,,,,,,,,,,,,,,188.080261230469,188.080261230469,26.4500465393066,26.4500465393066,49.7662878194283,5.38504952007186,7.1934289932251,65,1,0,0,1,0.268478393554687,31.7693061828613,2,1,1,188.080261230469,0,188.080261230469,,,,,,,,,,,,,,,,,,,,,,,,,,,,,,,,,
,3866125669.57315,218.000274658203,26.4500465393066,4.63875498444809E-5,7.48248103263847E-9,1,5,12.9061126708984,4.99898572865501,37.3300015926361,0.0605636877106049,0.00881324098604186,1,-6.31624602176816E-8,,,,,,,,,,,,,,,,,,,,,218.000274658203,218.000274658203,26.4500465393066,26.4500465393066,49.812403902063,5.37813070194927,7.30810737609863,65,1,0,0,1,0.280227661132813,32.7468223571777,2,1,1,218.000274658203,0,218.000274658203,,,,,,,,,,,,,,,,,,,,,,,,,,,,,,,,,
,3866125851.35592,248.152740478516,26.4500465393066,4.33055592897587E-5,7.85844183367421E-9,1,5,12.9061126708984,5.00063897863338,37.3300015926361,0.0565662745730082,0.00822981474521708,1,-6.02567890718081E-8,,,,,,,,,,,,,,,,,,,,,248.152740478516,248.152740478516,26.4500465393066,26.4500465393066,49.9022911817745,5.37158968649572,7.63862228393555,65,1,0,0,1,0.277328491210938,32.2580642700195,2,1,1,248.152740478516,0,248.152740478516,,,,,,,,,,,,,,,,,,,,,,,,,,,,,,,,,
,3866126031.5778,278.027160644531,26.4500465393066,4.04066404172197E-5,6.36293778571741E-9,1,5,12.9061126708984,5.00272239489338,37.3300015926361,0.0528112983216003,0.00767768862238595,1,-6.05804713290167E-8,,,,,,,,,,,,,,,,,,,,,278.027160644531,278.027160644531,26.4500465393066,26.4500465393066,49.8655546413707,5.36528872546056,7.84922599792481,65,1,0,0,1,0.274810791015625,32.2580642700195,2,1,1,278.027160644531,0,278.027160644531,,,,,,,,,,,,,,,,,,,,,,,,,,,,,,,,,
,3866128741.0896,2.00031000375748,45768.25,0.0486638252532453,0.000135792609148538,1,2,12.9061126708984,4.98119994313307,37.3300015926361,63.2645949886877,8.88652815249186,1000,-0.000307292003258679,,,,,,,,,,,,,,,,,,,,,1.99971163272858,2.00090837478638,45688.37890625,45848.12109375,50.5873885788804,5.41165690731007,2.63189792633057,26,1,0,0,1,0.27862548828125,31.2805480957031,5,6,1,2.00090837478638,0,2.00031000375748,,,,,,,,,,,,,,,,,,,,,,,,,,,,,,,,,
,3866128809.44941,2.00037854909897,38949.8671875,0.0473424517207042,0.000130630453581025,1,2,12.9061126708984,4.98062878464385,37.3300015926361,61.4574257071588,9.18443188165586,1000,0.000117335638858192,,,,,,,,,,,,,,,,,,,,,1.99841272830963,2.00234436988831,38859.90625,39039.828125,50.3638428223803,5.41325805555164,2.6198525428772,26,1,0,0,1,0.275115966796875,31.2805480957031,1,6,1,1.99841272830963,0,2.00037854909897,,,,,,,,,,,,,,,,,,,,,,,,,,,,,,,,,
,3866128959.88855,1.99999612569809,23924.34765625,0.042479534950345,6.83256250170337E-5,1,2,12.9061126708984,4.98061344814196,37.3300015926361,55.1792053126377,8.00414355711218,1000,-7.71014961305391E-5,,,,,,,,,,,,,,,,,,,,,1.99911105632782,2.00088119506836,23764.67578125,24084.01953125,50.0406394296784,5.41203571544804,2.631831407547,26,1,0,0,1,0.273361206054687,31.2805480957031,1,6,1,1.99911105632782,0,1.99999612569809,,,,,,,,,,,,,,,,,,,,,,,,,,,,,,,,,
,3866129081.59859,1.99836659431458,11773.6865234375,0.0320905548540146,2.25475036381022E-5,1,2,12.9061126708984,4.98539727339727,37.3300015926361,41.7306015168455,6.12290751530743,100,-5.8526725449328E-6,,,,,,,,,,,,,,,,,,,,,1.99332880973816,2.00340437889099,11663.78125,11883.591796875,49.9429358647745,5.39339239130311,2.61884164810181,26,1,0,0,1,0.268630981445313,31.7693061828613,6,6,1,2.00340437889099,0,1.99836659431458,,,,,,,,,,,,,,,,,,,,,,,,,,,,,,,,,
,3866129195.97737,2.00135922431946,340.829498291016,0.00255719358513802,4.61158642314552E-5,1,2,12.9061126708984,4.98029968725441,37.3300015926361,3.3257990835772,0.451830537101073,100,-2.77158800444556E-5,,,,,,,,,,,,,,,,,,,,,2.00135922431946,2.00135922431946,340.829498291016,340.829498291016,49.8671178984091,5.41150809488661,2.62434911727905,26,1,0,0,1,0.267791748046875,31.7693061828613,5,6,1,2.00135922431946,0,2.00135922431946,,,,,,,,,,,,,,,,,,,,,,,,,,,,,,,,,
,3866129268.75537,2.00198459625244,-6930.84619140625,-0.0229586531498173,2.71366088187047E-5,1,2,12.9061126708984,4.98043956173407,37.3300015926361,-29.8115538899441,-4.38937027753977,100,-7.33204605969313E-6,,,,,,,,,,,,,,,,,,,,,2.00196075439453,2.00200843811035,-7025.99755859375,-6835.69482421875,49.9046360673322,5.41139354284257,2.62116074562073,26,1,0,0,1,0.279083251953125,31.7693061828613,5,6,1,2.00196075439453,0,2.00198459625244,,,,,,,,,,,,,,,,,,,,,,,,,,,,,,,,,
,3866129331.27979,1.99749511480331,-13181.8125,-0.0337103654971415,1.81421457200486E-5,1,2,12.9061126708984,4.98055544540434,37.3300015926361,-43.7736325648375,-6.44741129763626,100,-1.25019029130555E-5,,,,,,,,,,,,,,,,,,,,,1.99600732326508,1.99898290634155,-13276.744140625,-13086.880859375,50.0242252307745,5.41139020184097,2.61510324478149,26,1,0,0,1,0.274200439453125,31.2805480957031,1,6,1,1.99898290634155,0,1.99749511480331,,,,,,,,,,,,,,,,,,,,,,,,,,,,,,,,,
,3866129431.5326,1.99888998270035,-23207.251953125,-0.0420524437792454,6.85375000267419E-5,1,2,12.9061126708984,4.9838817759225,37.3300015926361,-54.671620010446,-7.9527260284077,1000,5.95947020174213E-5,,,,,,,,,,,,,,,,,,,,,1.99640381336212,2.00137615203857,-23377.21484375,-23037.2890625,50.1762519777649,5.39996948802352,2.61483383178711,26,1,0,0,1,0.270309448242187,32.2580642700195,5,6,1,2.00137615203857,0,1.99888998270035,,,,,,,,,,,,,,,,,,,,,,,,,,,,,,,,,
,3866129578.43584,1.99828034639359,-37924.595703125,-0.0474690784467007,0.000143538037933142,1,2,12.9061126708984,4.98473055806477,37.3300015926361,-61.723880902071,-9.01036958301351,1000,4.33257582370909E-5,,,,,,,,,,,,,,,,,,,,,1.99826276302338,1.99829792976379,-38079.81640625,-37769.375,50.4416148600438,5.39846232972851,2.60325574874878,26,1,0,0,1,0.26885986328125,32.7468223571777,5,6,1,1.99829792976379,0,1.99828034639359,,,,,,,,,,,,,,,,,,,,,,,,,,,,,,,,,
,3866129710.16715,1.99977505207062,-49920.64453125,-0.0491040405933945,0.000144191179285415,1,2,12.9061126708984,4.9850533599038,37.3300015926361,-63.8681633855503,-9.2362110110388,1000,0.000110457949821662,,,,,,,,,,,,,,,,,,,,,1.99953389167786,2.00001621246338,-49999.65234375,-49841.63671875,50.7870946655438,5.39816883383803,2.59565210342407,26,1,0,0,1,0.267181396484375,31.7693061828613,1,6,1,1.99953389167786,0,1.99977505207062,,,,,,,,,,,,,,,,,,,,,,,,,,,,,,,,,
,3866129780.48721,1.99986237287521,-42905.572265625,-0.0481134560826366,0.000101235445818777,1,2,12.9061126708984,4.98162394809848,37.3300015926361,-62.5420948839993,-8.88567963897528,1000,0.000227908509808564,,,,,,,,,,,,,,,,,,,,,1.99820148944855,2.00152325630188,-42995.3515625,-42815.79296875,50.4642820871015,5.40928611016249,2.6033992767334,26,1,0,0,1,0.278091430664062,30.7917900085449,6,6,1,1.99820148944855,0,1.99986237287521,,,,,,,,,,,,,,,,,,,,,,,,,,,,,,,,,
,3866129876.51205,1.99972462654114,-33318.33203125,-0.0458986014365946,0.000103612694418649,1,2,12.9061126708984,4.98458159589532,37.3300015926361,-59.7107443856192,-8.49779493141944,1000,0.000206582204960901,,,,,,,,,,,,,,,,,,,,,1.99825048446655,2.00119876861572,-33472.97265625,-33163.69140625,50.3493826947746,5.39828692948456,2.59930801391602,26,1,0,0,1,0.2685546875,31.2805480957031,5,6,1,1.99825048446655,0,1.99972462654114,,,,,,,,,,,,,,,,,,,,,,,,,,,,,,,,,
,3866130013.67831,1.99953269958496,-19627.677734375,-0.039870233735474,4.39834742652409E-5,1,2,12.9061126708984,4.98503135071059,37.3300015926361,-51.852902997689,-7.53201492378978,1000,6.45522309977518E-5,,,,,,,,,,,,,,,,,,,,,1.99953269958496,1.99953269958496,-19627.677734375,-19627.677734375,50.0711229419284,5.39549117806213,2.60481667518616,26,1,0,0,1,0.26824951171875,31.7693061828613,1,6,1,1.99953269958496,0,1.99953269958496,,,,,,,,,,,,,,,,,,,,,,,,,,,,,,,,,
,3866130107.02024,2.00283682346344,-10306.9750976562,-0.0298503514696711,1.68171922564319E-5,1,2,12.9061126708984,4.98492234417528,37.3300015926361,-38.81209161516,-5.69574872202642,100,4.6471547657344E-6,,,,,,,,,,,,,,,,,,,,,1.99991965293884,2.00575399398804,-10421.857421875,-10192.0927734375,50.0023396322361,5.39516532240236,2.6060619354248,26,1,0,0,1,0.268020629882813,31.2805480957031,6,6,1,1.99991965293884,0,2.00283682346344,,,,,,,,,,,,,,,,,,,,,,,,,,,,,,,,,
,3866130209.53663,1.99941939115524,-65.2100143432617,-0.000543703735112998,5.38362323741682E-5,1,2,12.9061126708984,4.98539678707092,37.3300015926361,-0.712540420742472,-0.0662509056155663,100,2.8928155746335E-5,,,,,,,,,,,,,,,,,,,,,1.99926710128784,1.99957168102264,-160.217071533203,29.7970428466797,49.9890519474091,5.39304166149341,2.62235116958618,24,1,68,0,0,0.27099609375,31.7693061828613,1,6,1,1.99957168102264,0,1.99941939115524,,,,,,,,,,,,,,,,,,,,,,,,,,,,,,,,,
,3866130284.08248,2.00001889467239,7388.28149414062,0.0241105523316362,2.50378188279655E-5,1,2,12.9061126708984,4.98510882379311,37.3300015926361,31.3482032943222,4.61793884413692,100,9.44382196964331E-6,,,,,,,,,,,,,,,,,,,,,1.99955666065216,2.00048112869263,7298.0068359375,7478.55615234375,49.9667755346111,5.39442755781058,2.6210446357727,26,1,0,0,1,0.271453857421875,31.7693061828613,1,6,1,1.99955666065216,0,2.00001889467239,,,,,,,,,,,,,,,,,,,,,,,,,,,,,,,,,
,3866130346.59436,2.00364702939987,13644.4692382812,0.0343465486988711,4.54348686318006E-5,1,2,12.9061126708984,4.98515088387089,37.3300015926361,44.6749082699747,6.45957796384628,100,-7.80337454424727E-5,,,,,,,,,,,,,,,,,,,,,1.99957621097565,2.0077178478241,13559.4970703125,13729.44140625,50.0203170881784,5.39517460240297,2.60951280593872,26,1,0,0,1,0.267715454101562,30.3030319213867,6,6,1,1.99957621097565,0,2.00364702939987,,,,,,,,,,,,,,,,,,,,,,,,,,,,,,,,,
,3866130453.84177,1.99974870681763,24371.66796875,0.0426554081940342,0.000112899407779764,1,2,12.9061126708984,4.98521725723692,37.3300015926361,55.4858188215165,8.00567562110282,1000,-0.000109758138067391,,,,,,,,,,,,,,,,,,,,,1.99931955337524,2.00017786026001,24331.673828125,24411.662109375,50.1059054110341,5.3960242584379,2.600172996521,26,1,0,0,1,0.272598266601562,31.2805480957031,5,6,1,1.99931955337524,0,1.99974870681763,,,,,,,,,,,,,,,,,,,,,,,,,,,,,,,,,
,3866130597.8346,2.00120902061462,38798.41796875,0.0475294209240131,0.000199868418011271,1,2,12.9061126708984,4.98511297040051,37.3300015926361,61.8090557858977,9.02244464785879,1000,-4.36508720861607E-5,,,,,,,,,,,,,,,,,,,,,2.00120902061462,2.00120902061462,38798.41796875,38798.41796875,50.4490403309765,5.39720507699085,2.60404562950134,26,1,0,0,1,0.2667236328125,31.2805480957031,1,6,1,2.00120902061462,0,2.00120902061462,,,,,,,,,,,,,,,,,,,,,,,,,,,,,,,,,
,3866131142.39313,4.69550395011902,26.2118682861328,0.000121916829278906,5.45158687599269E-7,1,5,12.9061126708984,4.99509471424147,37.3300015926361,0.158976527399402,0.0233063630808994,10,-3.6807581742183E-8,,,,,,,,,,,,,,,,,,,,,4.33687543869019,5.05413246154785,26.2118682861328,26.2118682861328,49.8413241572745,5.39327436160938,3.71709823608398,65,1,0,0,1,0.266876220703125,31.2805480957031,6,1,1,5.05413246154785,0,4.69550395011902,,,,,,,,,,,,,,,,,,,,,,,,,,,,,,,,,
,3866131335.44468,34.0723152160645,26.2118682861328,6.96582250231036E-5,1.0408336992661E-8,1,5,12.9061126708984,4.99698075031483,37.3300015926361,0.0908810932188704,0.0133205155520772,1,-2.31941657732788E-8,,,,,,,,,,,,,,,,,,,,,34.0723152160645,34.0723152160645,26.2118682861328,26.2118682861328,49.8159212303995,5.38528724740655,6.1429295539856,65,1,0,0,1,0.2703857421875,31.2805480957031,2,1,1,34.0723152160645,0,34.0723152160645,,,,,,,,,,,,,,,,,,,,,,,,,,,,,,,,,
,3866131525.83741,64.1084823608398,26.2118682861328,6.31227350309253E-5,6.81098876919138E-9,1,5,12.9061126708984,4.98988216489507,37.3300015926361,0.082199123590382,0.0119873572494341,1,-6.66066923947357E-8,,,,,,,,,,,,,,,,,,,,,64.1084823608398,64.1084823608398,26.2118682861328,26.2118682861328,49.8608648702553,5.41425612583414,6.65350818634033,65,1,0,0,1,0.279312133789062,30.7917900085449,2,1,1,64.1084823608398,0,64.1084823608398,,,,,,,,,,,,,,,,,,,,,,,,,,,,,,,,,
,3866131711.49291,94.07373046875,26.2118682861328,5.88499352469328E-5,6.81331944912702E-9,1,5,12.9061126708984,4.99037864830372,37.3300015926361,0.0766463690232256,0.0111731869035848,1,-6.54020854476408E-8,,,,,,,,,,,,,,,,,,,,,94.07373046875,94.07373046875,26.2118682861328,26.2118682861328,49.9073717671495,5.41127043520802,6.86914300918579,65,1,0,0,1,0.281143188476562,31.2805480957031,2,1,1,94.07373046875,0,94.07373046875,,,,,,,,,,,,,,,,,,,,,,,,,,,,,,,,,
,3866131893.29638,124.031188964844,26.2118682861328,5.47379984526055E-5,7.09226866695307E-9,1,5,12.9061126708984,4.99442878612858,37.3300015926361,0.0713737346517823,0.010393473636339,1,-6.91612307081143E-8,,,,,,,,,,,,,,,,,,,,,124.031188964844,124.031188964844,26.2118682861328,26.2118682861328,49.8718076695245,5.39592935229623,6.99320268630982,65,1,0,0,1,0.268478393554687,31.2805480957031,2,1,1,124.031188964844,0,124.031188964844,,,,,,,,,,,,,,,,,,,,,,,,,,,,,,,,,
,3866132074.36195,154.030075073242,26.2118682861328,5.16741502408184E-5,7.2916964191313E-9,1,5,12.9061126708984,4.99552790284043,37.3300015926361,0.0673977998579371,0.00982648784306056,1,-5.62872518553267E-8,,,,,,,,,,,,,,,,,,,,,154.030075073242,154.030075073242,26.2118682861328,26.2118682861328,49.9585684351591,5.39201974663074,7.07071208953857,65,1,0,0,1,0.266799926757813,29.8142719268799,2,1,1,154.030075073242,0,154.030075073242,,,,,,,,,,,,,,,,,,,,,,,,,,,,,,,,,
,3866132255.32522,184.07307434082,26.2118682861328,4.87737304589763E-5,8.14017137403384E-9,1,5,12.9061126708984,4.99736538399805,37.3300015926361,0.0636479242764602,0.00927768636426189,1,-5.46855104676577E-8,,,,,,,,,,,,,,,,,,,,,184.07307434082,184.07307434082,26.2118682861328,26.2118682861328,49.7877826037072,5.38389340065324,7.12674760818481,65,1,0,0,1,0.266494750976562,31.2805480957031,2,1,1,184.07307434082,0,184.07307434082,,,,,,,,,,,,,,,,,,,,,,,,,,,,,,,,,
,3866132437.25962,214.201446533203,26.2118682861328,4.58035774576248E-5,5.86515874873913E-9,1,5,12.9061126708984,4.99882100481515,37.3300015926361,0.0597955154158712,0.00872214707395608,1,-4.68475761325812E-8,,,,,,,,,,,,,,,,,,,,,214.201446533203,214.201446533203,26.2118682861328,26.2118682861328,49.8815780260149,5.37965065799502,7.22764825820923,65,1,0,0,1,0.271835327148438,31.7693061828613,2,1,1,214.201446533203,0,214.201446533203,,,,,,,,,,,,,,,,,,,,,,,,,,,,,,,,,
,3866132617.34232,244.078155517578,26.2118682861328,4.31848254328669E-5,7.43719057906254E-9,1,5,12.9061126708984,5.00072256185653,37.3300015926361,0.0564086394159596,0.00821558105711247,1,-5.35660591145155E-8,,,,,,,,,,,,,,,,,,,,,244.078155517578,244.078155517578,26.2118682861328,26.2118682861328,49.8475771854284,5.37261188094031,7.4408073425293,65,1,0,0,1,0.276260375976562,29.3255138397217,2,1,1,244.078155517578,0,244.078155517578,,,,,,,,,,,,,,,,,,,,,,,,,,,,,,,,,
,3866132797.95822,274.067321777344,26.2118682861328,4.07968922557452E-5,6.78283411497351E-9,1,5,12.9061126708984,5.0028280310022,37.3300015926361,0.0533228322170961,0.00775274825685411,1,-6.06463214369073E-8,,,,,,,,,,,,,,,,,,,,,274.067321777344,274.067321777344,26.2118682861328,26.2118682861328,49.8964289678803,5.3649128476554,7.66381120681763,65,1,0,0,1,0.273971557617187,31.2805480957031,2,1,1,274.067321777344,0,274.067321777344,,,,,,,,,,,,,,,,,,,,,,,,,,,,,,,,,
,3866133576.92767,297.996826171875,26.424976348877,4.52770858313683E-5,7.83967489586226E-9,1,5,12.9061126708984,4.98389579471255,37.3300015926361,0.058860589707775,0.008586829764533,1,-4.5513111624331E-8,,,,,,,,,,,,,,,,,,,,,297.996826171875,297.996826171875,26.424976348877,26.424976348877,49.8944748965822,5.3608746006202,8.15850162506104,65,1,0,0,1,0.26947021484375,30.7917900085449,2,1,1,297.996826171875,0,297.996826171875,,,,,,,,,,,,,,,,,,,,,,,,,,,,,,,,,
,3866133748.2541,267.918731689453,26.424976348877,4.61172713350181E-5,7.82254085522849E-9,1,5,12.9061126708984,4.98391448266344,37.3300015926361,0.0599556719608296,0.00872907632668742,1,-5.95450544835362E-8,,,,,,,,,,,,,,,,,,,,,267.918731689453,267.918731689453,26.424976348877,26.424976348877,49.934337951063,5.361227807213,7.96807622909546,65,1,0,0,1,0.267715454101562,31.2805480957031,2,1,1,267.918731689453,0,267.918731689453,,,,,,,,,,,,,,,,,,,,,,,,,,,,,,,,,
,3866133930.82652,237.844581604004,26.424976348877,4.66735766578477E-5,5.91349884651898E-9,1,5,12.9061126708984,4.98264781176945,37.3300015926361,0.0606559697541571,0.00883986026633444,1,-5.36129530404403E-8,,,,,,,,,,,,,,,,,,,,,237.836502075195,237.852661132813,26.424976348877,26.424976348877,49.8831412830534,5.36616791816941,7.80830383300781,65,1,0,0,1,0.272064208984375,31.2805480957031,2,1,1,237.836502075195,0,237.844581604004,,,,,,,,,,,,,,,,,,,,,,,,,,,,,,,,,
,3866134108.78892,207.939575195313,26.424976348877,4.67673382742031E-5,6.61014219975102E-9,1,5,12.9061126708984,4.98100360311929,37.3300015926361,0.0607513535778961,0.00884179954091393,1,-6.27377454598976E-8,,,,,,,,,,,,,,,,,,,,,207.939575195313,207.939575195313,26.424976348877,26.424976348877,49.9757642625822,5.37120692708868,7.71192312240601,65,1,0,0,1,0.274658203125,31.7693061828613,2,1,1,207.939575195313,0,207.939575195313,,,,,,,,,,,,,,,,,,,,,,,,,,,,,,,,,
,3866134288.83772,177.921463012695,26.424976348877,4.62604431520743E-5,6.24017127534677E-9,1,5,12.9061126708984,4.97977078924898,37.3300015926361,0.0600712303840629,0.00874803391830792,1,-5.81212623092009E-8,,,,,,,,,,,,,,,,,,,,,177.921463012695,177.921463012695,26.424976348877,26.424976348877,49.8667270841495,5.37589098456096,7.60820579528809,65,1,0,0,1,0.27923583984375,31.7693061828613,2,1,1,177.921463012695,0,177.921463012695,,,,,,,,,,,,,,,,,,,,,,,,,,,,,,,,,
,3866134468.94748,147.965560913086,26.424976348877,4.55106506670799E-5,6.11148389595229E-9,1,5,12.9061126708984,4.98648919478721,37.3300015926361,0.0592104297699903,0.00861731576359868,1,-6.12148876681734E-8,,,,,,,,,,,,,,,,,,,,,147.965560913086,147.965560913086,26.424976348877,26.424976348877,49.865163827111,5.38778115958366,7.52021360397339,65,1,0,0,1,0.273818969726562,31.2805480957031,2,1,1,147.965560913086,0,147.965560913086,,,,,,,,,,,,,,,,,,,,,,,,,,,,,,,,,
,3866134649.24557,117.913208007813,26.424976348877,4.44637647682079E-5,6.10066806270972E-9,1,5,12.9061126708984,4.98748556538323,37.3300015926361,0.0578629314591,0.00843306679011133,1,-5.08808753410461E-8,,,,,,,,,,,,,,,,,,,,,117.913208007813,117.913208007813,26.424976348877,26.424976348877,49.8823596545341,5.38248768486749,7.42952013015747,65,1,0,0,1,0.267410278320313,31.7693061828613,2,1,1,117.913208007813,0,117.913208007813,,,,,,,,,,,,,,,,,,,,,,,,,,,,,,,,,
,3866134828.99204,87.9100036621094,26.424976348877,4.33570304721855E-5,6.16957209194298E-9,1,5,12.9061126708984,4.98430235220778,37.3300015926361,0.0563740547310648,0.00820257714424975,1,-5.97797949133596E-8,,,,,,,,,,,,,,,,,,,,,87.9100036621094,87.9100036621094,26.424976348877,26.424976348877,49.8202201872553,5.39787795450967,7.31347513198852,65,1,0,0,1,0.267105102539062,31.7693061828613,2,1,1,87.9100036621094,0,87.9100036621094,,,,,,,,,,,,,,,,,,,,,,,,,,,,,,,,,
,3866135005.51015,57.9780578613281,26.424976348877,4.26368732024783E-5,6.21110928707678E-9,1,5,12.9061126708984,4.98676194673731,37.3300015926361,0.0554759912169916,0.00807275333629664,1,-5.81494859903168E-8,,,,,,,,,,,,,,,,,,,,,57.9780578613281,57.9780578613281,26.424976348877,26.424976348877,49.8358527576399,5.38675852325423,7.12775135040283,65,1,0,0,1,0.267715454101562,30.7917900085449,2,1,1,57.9780578613281,0,57.9780578613281,,,,,,,,,,,,,,,,,,,,,,,,,,,,,,,,,
,3866135180.64613,27.9762935638428,26.424976348877,4.21850920906687E-5,5.80932613483055E-9,1,5,12.9061126708984,4.98875936058398,37.3300015926361,0.0549116347120296,0.00804207789285198,1,-1.88334354451587E-8,,,,,,,,,,,,,,,,,,,,,27.9762935638428,27.9762935638428,26.424976348877,26.424976348877,49.8960381536207,5.37954229083975,6.64996910095215,65,1,0,0,1,0.28228759765625,31.7693061828613,2,1,1,27.9762935638428,0,27.9762935638428,,,,,,,,,,,,,,,,,,,,,,,,,,,,,,,,,
,3866136759.53223,4.13864302635193,26.424976348877,4.30374767955272E-5,9.74816942022619E-9,1,5,12.9061126708984,4.98359384620937,37.3300015926361,0.055942398872331,0.00817444653512664,1,-3.32173234863627E-8,,,,,,,,,,,,,,,,,,,,,4.01737117767334,4.25991487503052,26.424976348877,26.424976348877,49.7862193466687,5.40065960205114,3.65467810630798,65,1,0,0,1,0.2703857421875,31.2805480957031,6,1,1,4.25991487503052,0,4.13864302635193,,,,,,,,,,,,,,,,,,,,,,,,,,,,,,,,,
,3866136956.06435,34.0745277404785,26.424976348877,4.22214707278664E-5,6.38585324270093E-9,1,5,12.9061126708984,4.98886651300078,37.3300015926361,0.0549631295964819,0.00803234441133916,1,-3.18420049188694E-8,,,,,,,,,,,,,,,,,,,,,34.0745277404785,34.0745277404785,26.424976348877,26.424976348877,49.9366828366207,5.37812414769541,6.19080495834351,65,1,0,0,1,0.2789306640625,30.7917900085449,2,1,1,34.0745277404785,0,34.0745277404785,,,,,,,,,,,,,,,,,,,,,,,,,,,,,,,,,
,3866137147.02374,64.1375579833984,26.424976348877,4.2584335297313E-5,6.48325673785288E-9,1,5,12.9061126708984,4.98464361866133,37.3300015926361,0.0553730193150369,0.00806860929823465,1,-4.99143010203285E-8,,,,,,,,,,,,,,,,,,,,,64.1375579833984,64.1375579833984,26.424976348877,26.424976348877,49.8460139283899,5.39592656478193,6.67769432067871,65,1,0,0,1,0.27008056640625,30.7917900085449,2,1,1,64.1375579833984,0,64.1375579833984,,,,,,,,,,,,,,,,,,,,,,,,,,,,,,,,,
,3866137332.59363,94.0656967163086,26.424976348877,4.30718100190839E-5,6.58701353187329E-9,1,5,12.9061126708984,4.98332960195051,37.3300015926361,0.0559843483696243,0.00817019936847758,1,-4.10606775693569E-8,,,,,,,,,,,,,,,,,,,,,94.0656967163086,94.0656967163086,26.424976348877,26.424976348877,49.8362435718995,5.39951194239418,6.89903974533081,65,1,0,0,1,0.273208618164062,30.7917900085449,2,1,1,94.0656967163086,0,94.0656967163086,,,,,,,,,,,,,,,,,,,,,,,,,,,,,,,,,
,3866137514.26326,124.017356872559,26.424976348877,4.37139629636374E-5,5.97180002287601E-9,1,5,12.9061126708984,4.98531407999598,37.3300015926361,0.0568550626310419,0.00826765162363466,1,-6.39714596031738E-8,,,,,,,,,,,,,,,,,,,,,124.017356872559,124.017356872559,26.424976348877,26.424976348877,49.883532097313,5.39341006922654,7.00685501098633,65,1,0,0,1,0.268020629882813,31.7693061828613,2,1,1,124.017356872559,0,124.017356872559,,,,,,,,,,,,,,,,,,,,,,,,,,,,,,,,,
,3866137695.85538,154.119400024414,26.424976348877,4.42111785155815E-5,6.63367055198193E-9,1,5,12.9061126708984,4.98395898253598,37.3300015926361,0.0574795790176153,0.00835995731952805,1,-6.35761329216421E-8,,,,,,,,,,,,,,,,,,,,,154.119400024414,154.119400024414,26.424976348877,26.424976348877,49.712746265861,5.39683448775603,7.08211421966553,65,1,0,0,1,0.270462036132813,30.3030319213867,2,1,1,154.119400024414,0,154.119400024414,,,,,,,,,,,,,,,,,,,,,,,,,,,,,,,,,
,3866137876.35911,184.143493652344,26.424976348877,4.4468779206645E-5,6.77930961566417E-9,1,5,12.9061126708984,4.98785573694486,37.3300015926361,0.0578775356121627,0.00842095370709955,1,-6.16015454591506E-8,,,,,,,,,,,,,,,,,,,,,184.143493652344,184.143493652344,26.424976348877,26.424976348877,49.824519144111,5.38113765857487,7.14830827713013,65,1,0,0,1,0.273361206054687,31.2805480957031,2,1,1,184.143493652344,0,184.143493652344,,,,,,,,,,,,,,,,,,,,,,,,,,,,,,,,,
,3866138057.67292,214.013534545898,26.424976348877,4.44948798698381E-5,5.77308954668794E-9,1,5,12.9061126708984,4.98907350513981,37.3300015926361,0.0579286880802287,0.00844693736194728,1,-4.76921182341235E-8,,,,,,,,,,,,,,,,,,,,,214.013534545898,214.013534545898,26.424976348877,26.424976348877,49.939418536438,5.3782516902524,7.23808288574219,65,1,0,0,1,0.278778076171875,30.7917900085449,2,1,1,214.013534545898,0,214.013534545898,,,,,,,,,,,,,,,,,,,,,,,,,,,,,,,,,
,3866138237.83579,244.007873535156,26.424976348877,4.41642589397152E-5,6.18137983976983E-9,1,5,12.9061126708984,4.99059501288869,37.3300015926361,0.0575256505165265,0.00836874418316003,1,-6.19402618499283E-8,,,,,,,,,,,,,,,,,,,,,244.007873535156,244.007873535156,26.424976348877,26.424976348877,49.9788907766591,5.37221995247091,7.4023118019104,65,1,0,0,1,0.274887084960938,31.2805480957031,2,1,1,244.007873535156,0,244.007873535156,,,,,,,,,,,,,,,,,,,,,,,,,,,,,,,,,
,3866138418.85428,274.030853271484,26.424976348877,4.35006726307044E-5,6.6239634924098E-9,1,5,12.9061126708984,4.99209699752337,37.3300015926361,0.0566851895800764,0.00824675746483023,1,-6.0797463403666E-8,,,,,,,,,,,,,,,,,,,,,274.030853271484,274.030853271484,26.424976348877,26.424976348877,49.792081560563,5.36707669870031,7.57723760604858,65,1,0,0,1,0.272903442382813,30.3030319213867,2,1,1,274.030853271484,0,274.030853271484,,,,,,,,,,,,,,,,,,,,,,,,,,,,,,,,,
,3866138786.66992,300.005645751953,45913.58203125,-0.000493353004571961,1.54648368105221E-6,1,2,12.9061126708984,4.99331431110505,37.3300015926361,-0.635485823070529,-0.145403554642481,1000,-3.90896534080514E-5,,,,,,,,,,,,,,,,,,,,,300.005645751953,300.005645751953,45908.62890625,45918.53515625,49.7987254029764,5.36278722067108,7.48377275466919,26,1,0,0,1,0.272140502929687,31.2805480957031,1,6,1,300.005645751953,0,300.005645751953,,,,,,,,,,,,,,,,,,,,,,,,,,,,,,,,,
,3866138907.78408,300.003311157227,33823.654296875,-0.000239403245019824,1.54950592124351E-6,1,2,12.9061126708984,4.99330473254413,37.3300015926361,-0.308775379485577,-0.0678219773449833,100,-1.68692017126745E-5,,,,,,,,,,,,,,,,,,,,,300.003112792969,300.003509521484,33728.84765625,33918.4609375,49.8256915868899,5.36278723402649,7.57798480987549,26,1,0,0,1,0.2703857421875,31.7693061828613,1,6,1,300.003112792969,0,300.003311157227,,,,,,,,,,,,,,,,,,,,,,,,,,,,,,,,,
,3866138982.10328,300.003555297852,26400.8994140625,-8.1481880221002E-5,1.95916839158165E-6,1,2,12.9061126708984,4.99332587346525,37.3300015926361,-0.10410125280545,-0.0298383511158284,100,-1.09244073915027E-5,,,,,,,,,,,,,,,,,,,,,300.003509521484,300.003601074219,26331.0703125,26470.728515625,49.890566753986,5.36273698478519,7.68848466873169,26,1,0,0,1,0.269699096679687,31.2805480957031,1,6,1,300.003601074219,0,300.003555297852,,,,,,,,,,,,,,,,,,,,,,,,,,,,,,,,,
,3866139046.67873,300.002014160156,19951.326171875,5.46717962124675E-5,1.5037312402978E-6,1,2,12.9061126708984,4.99333135908858,37.3300015926361,0.0731839164515316,-0.00268101232311529,100,-1.00890251134263E-5,,,,,,,,,,,,,,,,,,,,,300.001983642578,300.002044677734,19891.462890625,20011.189453125,49.9144064238226,5.36282209534326,7.80936288833618,26,1,0,0,1,0.26885986328125,31.7693061828613,1,6,1,300.002044677734,0,300.002014160156,,,,,,,,,,,,,,,,,,,,,,,,,,,,,,,,,
,3866139115.04792,300.002410888672,13127.728515625,0.000191767630145622,1.0923138473959E-6,1,2,12.9061126708984,4.99325856604656,37.3300015926361,0.251545825551912,0.0256511611101356,100,-8.49023889119702E-6,,,,,,,,,,,,,,,,,,,,,300.002380371094,300.00244140625,13022.9248046875,13232.5322265625,49.895647339361,5.36276414592257,7.97047710418701,26,1,0,0,1,0.268936157226562,31.2805480957031,1,6,1,300.00244140625,0,300.002410888672,,,,,,,,,,,,,,,,,,,,,,,,,,,,,,,,,
,3866139179.71012,300.001846313477,6667.36083984375,0.000301472829238795,9.21742994710251E-7,1,2,12.9061126708984,4.99321985010354,37.3300015926361,0.395113746119743,0.0425747772892952,100,-1.16210306874633E-5,,,,,,,,,,,,,,,,,,,,,300.001495361328,300.002197265625,6547.48974609375,6787.23193359375,49.939418536438,5.36341758124837,8.14034271240234,25,1,68,0,0,0.269775390625,31.7693061828613,1,6,1,300.001495361328,0,300.001846313477,,,,,,,,,,,,,,,,,,,,,,,,,,,,,,,,,
,3866139245.16484,300.000396728516,121.394439697266,7.543326186008E-5,4.79470498428869E-6,1,2,12.9061126708984,4.99322854919844,37.3300015926361,0.103624145723347,-0.0217490770182493,100,-2.77705107155219E-5,,,,,,,,,,,,,,,,,,,,,299.999908447266,300.000885009766,-38.5343322753906,281.323211669922,49.9257400373514,5.36313445921971,8.26426887512207,25,1,68,0,0,0.269699096679687,31.7693061828613,1,6,1,299.999908447266,0,300.000396728516,,,,,,,,,,,,,,,,,,,,,,,,,,,,,,,,,
,3866139322.47469,300.000305175781,-7606.00537109375,-0.000281613442316385,1.28533907493229E-6,1,2,12.9061126708984,4.99320599087652,37.3300015926361,-0.366854416702149,-0.0549489679863636,10,-7.91702928933572E-7,,,,,,,,,,,,,,,,,,,,,300.000244140625,300.000366210937,-7705.98876953125,-7506.02197265625,49.9030728102937,5.36353830289174,8.19058322906494,26,1,0,0,1,0.270919799804687,33.2355842590332,1,6,1,300.000366210937,0,300.000305175781,,,,,,,,,,,,,,,,,,,,,,,,,,,,,,,,,
,3866139428.74017,300.001403808594,-18236.353515625,-9.34137947373245E-5,1.00937200329477E-6,1,2,12.9061126708984,4.99315943156324,37.3300015926361,-0.122762714850144,-0.0109075232301596,100,5.35376792638448E-6,,,,,,,,,,,,,,,,,,,,,300.001403808594,300.001403808594,-18236.353515625,-18236.353515625,49.8620373130341,5.36346721359004,8.10232543945313,26,1,0,0,1,0.2703857421875,31.2805480957031,1,6,1,300.001403808594,0,300.001403808594,,,,,,,,,,,,,,,,,,,,,,,,,,,,,,,,,
,3866139503.80639,300.000259399414,-25737.361328125,6.26688015931442E-5,1.61648837229409E-6,1,2,12.9061126708984,4.99317221117936,37.3300015926361,0.0806484321498346,0.0189577430523867,100,5.34018422050724E-6,,,,,,,,,,,,,,,,,,,,,300,300.000518798828,-25847.724609375,-25626.998046875,49.8636005700726,5.36315599214979,8.06408882141113,26,1,0,0,1,0.268936157226562,31.7693061828613,1,6,1,300.000518798828,0,300.000259399414,,,,,,,,,,,,,,,,,,,,,,,,,,,,,,,,,
,3866139571.42497,300.00048828125,-32514.3896484375,0.000205009439179387,1.98430224948167E-6,1,2,12.9061126708984,4.99305590706739,37.3300015926361,0.265797025379397,0.0485429322028257,100,7.13171892748103E-6,,,,,,,,,,,,,,,,,,,,,300.000183105469,300.000793457031,-32679.759765625,-32349.01953125,49.8436690428322,5.36322392069727,8.03623390197754,26,1,0,0,1,0.269927978515625,31.2805480957031,1,6,1,300.000183105469,0,300.00048828125,,,,,,,,,,,,,,,,,,,,,,,,,,,,,,,,,
,3866139642.92714,300.000518798828,-39677.255859375,0.000352575808138816,1.47695174412554E-6,1,2,12.9061126708984,4.99303974848292,37.3300015926361,0.458411979050536,0.0746650492584029,100,5.49790211160059E-6,,,,,,,,,,,,,,,,,,,,,300.000396728516,300.000640869141,-39742.34765625,-39612.1640625,49.7928631890822,5.36312213738691,8.01389026641846,26,1,0,0,1,0.270843505859375,31.2805480957031,1,6,1,300.000396728516,0,300.000518798828,,,,,,,,,,,,,,,,,,,,,,,,,,,,,,,,,
,3866139731.45385,299.999130249023,-48543.54296875,0.000543666476162816,1.79836219241451E-6,1,2,12.9061126708984,4.99299124601723,37.3300015926361,0.707479564336347,0.110876715661161,100,5.21321978746058E-6,,,,,,,,,,,,,,,,,,,,,299.999053955078,299.999206542969,-48648.75390625,-48438.33203125,49.7834836468514,5.36316477024649,7.98816823959351,26,1,0,0,1,0.269699096679687,31.2805480957031,1,6,1,299.999206542969,0,299.999130249023,,,,,,,,,,,,,,,,,,,,,,,,,,,,,,,,,
,3866139855.20673,300.000915527344,-39601.234375,0.0003466871808502,1.70348470820086E-6,1,2,12.9061126708984,4.99292935641991,37.3300015926361,0.44774620488138,0.0938057885225615,100,2.1053121323071E-5,,,,,,,,,,,,,,,,,,,,,300.000915527344,300.000915527344,-39601.234375,-39601.234375,49.8456231141303,5.36373707150809,7.95959186553955,26,1,0,0,1,0.269546508789062,31.7693061828613,1,6,1,300.000915527344,0,300.000915527344,,,,,,,,,,,,,,,,,,,,,,,,,,,,,,,,,
,3866139951.203,300.000473022461,-30014.8232421875,0.00014569568048196,1.37299542494757E-6,1,2,12.9061126708984,4.99305753271166,37.3300015926361,0.187361449763246,0.0449449507404467,100,1.30846008540164E-5,,,,,,,,,,,,,,,,,,,,,300.000183105469,300.000762939453,-30079.681640625,-29949.96484375,49.8878310541687,5.36348115944905,7.93802165985107,26,1,0,0,1,0.270233154296875,31.7693061828613,1,6,1,300.000183105469,0,300.000473022461,,,,,,,,,,,,,,,,,,,,,,,,,,,,,,,,,
,3866140013.6043,299.99919128418,-23785.7548828125,1.71255605442781E-5,1.43091218043788E-6,1,2,12.9061126708984,4.99302636569477,37.3300015926361,0.0202276371387779,0.0175030263461138,100,1.09152819982892E-5,,,,,,,,,,,,,,,,,,,,,299.999114990234,299.999267578125,-23850.62109375,-23720.888671875,49.8491404424668,5.36371087004026,7.93455362319946,25,1,68,0,0,0.268783569335938,31.2805480957031,1,6,1,299.999267578125,0,299.99919128418,,,,,,,,,,,,,,,,,,,,,,,,,,,,,,,,,
,3866140073.9161,300.00080871582,-17766.1259765625,-0.000102883593943613,1.59461251475352E-6,1,2,12.9061126708984,4.9929598785145,37.3300015926361,-0.135702856307472,-0.00859092101293547,100,8.52222924677411E-6,,,,,,,,,,,,,,,,,,,,,300.000793457031,300.000823974609,-17870.880859375,-17661.37109375,49.8897851254668,5.36377975563288,7.92530632019043,25,1,68,0,0,0.270767211914062,31.7693061828613,1,6,1,300.000823974609,0,300.00080871582,,,,,,,,,,,,,,,,,,,,,,,,,,,,,,,,,
,3866140138.35984,300.001235961914,-11331.9458007813,-0.000227158598199363,9.62549825461919E-7,1,2,12.9061126708984,4.99292028931795,37.3300015926361,-0.297450347338773,-0.0337194856550685,100,7.49615293294627E-6,,,,,,,,,,,,,,,,,,,,,300.001190185547,300.001281738281,-11411.7783203125,-11252.11328125,49.9273032943899,5.36385813385304,7.91560935974121,25,1,68,0,0,0.26947021484375,32.7468223571777,1,6,1,300.001190185547,0,300.001235961914,,,,,,,,,,,,,,,,,,,,,,,,,,,,,,,,,
,3866140205.06483,299.999984741211,-4667.12329101562,-0.000325248469238616,1.05766736855215E-6,1,2,12.9061126708984,4.99289830538897,37.3300015926361,-0.42669967990277,-0.0427712260356689,100,1.49602284637713E-5,,,,,,,,,,,,,,,,,,,,,299.999816894531,300.000152587891,-4726.91162109375,-4607.3349609375,49.9319930655053,5.36433214819831,7.90279245376587,26,1,0,0,1,0.268630981445313,31.7693061828613,1,6,1,299.999816894531,0,299.999984741211,,,,,,,,,,,,,,,,,,,,,,,,,,,,,,,,,
,3866140265.43221,299.999740600586,1369.00299072266,0.000259000250493074,1.08363375995132E-6,1,2,12.9061126708984,4.99286117299522,37.3300015926361,0.33505760924539,0.0662296782493334,100,1.27747394615265E-5,,,,,,,,,,,,,,,,,,,,,299.999694824219,299.999786376953,1248.90600585938,1489.09997558594,49.8929116395437,5.36430105528918,7.89414358139038,26,1,0,0,1,0.269622802734375,31.2805480957031,1,6,1,299.999786376953,0,299.999740600586,,,,,,,,,,,,,,,,,,,,,,,,,,,,,,,,,
,3866140346.04523,300.001098632812,9423.57470703125,0.000255956571152388,8.64107979345058E-7,1,2,12.9061126708984,4.99281052856941,37.3300015926361,0.333541233021919,0.0489383068867369,10,-4.69898619223434E-8,,,,,,,,,,,,,,,,,,,,,300.000915527344,300.001281738281,9308.5859375,9538.5634765625,49.8686811554476,5.36495985423145,7.88323926925659,26,1,0,0,1,0.270156860351562,31.7693061828613,1,6,1,300.001281738281,0,300.001098632812,,,,,,,,,,,,,,,,,,,,,,,,,,,,,,,,,
,3866140466.93917,300.000564575195,21520.421875,2.75490588266873E-5,1.56467910203991E-6,1,2,12.9061126708984,4.99281960317129,37.3300015926361,0.0371037733850794,-0.00292844118534547,100,-6.29457301831116E-6,,,,,,,,,,,,,,,,,,,,,300.000427246094,300.000701904297,21460.2890625,21580.5546875,49.773713290361,5.36519087197123,7.87784671783447,26,1,0,0,1,0.27099609375,31.2805480957031,1,6,1,300.000701904297,0,300.000564575195,,,,,,,,,,,,,,,,,,,,,,,,,,,,,,,,,
,3866140529.40696,299.999740600586,27770.41015625,-0.000102926114368583,1.77684608757234E-6,1,2,12.9061126708984,4.99284658474022,37.3300015926361,-0.133356265978504,-0.0249194206293516,100,-4.00229003788114E-6,,,,,,,,,,,,,,,,,,,,,299.999572753906,299.999908447266,27715.3359375,27825.484375,49.8768882548995,5.36474237539651,7.86924457550049,25,1,68,0,0,0.26947021484375,31.2805480957031,1,6,1,299.999908447266,0,299.999740600586,,,,,,,,,,,,,,,,,,,,,,,,,,,,,,,,,
,3866140610.76644,300.001220703125,35921.984375,-0.00027078027996379,2.02009267709084E-6,1,2,12.9061126708984,4.99272567397178,37.3300015926361,-0.351698035457503,-0.0596114955631407,100,-5.96706629955499E-6,,,,,,,,,,,,,,,,,,,,,300.001220703125,300.001220703125,35921.984375,35921.984375,49.8381976431976,5.36430588225993,7.87302207946777,26,1,0,0,1,0.271148681640625,30.7917900085449,1,6,1,300.001220703125,0,300.001220703125,,,,,,,,,,,,,,,,,,,,,,,,,,,,,,,,,
,3866140680.37592,300.000244140625,42901.861328125,-0.000416809726764437,1.63062140346266E-6,1,2,12.9061126708984,4.9927175559352,37.3300015926361,-0.541868940553899,-0.0883255197190252,100,-6.54990179212527E-6,,,,,,,,,,,,,,,,,,,,,300.000213623047,300.000274658203,42786.671875,43017.05078125,49.7854377181495,5.36506966999452,7.86837291717529,26,1,0,0,1,0.269699096679687,31.7693061828613,1,6,1,300.000213623047,0,300.000244140625,,,,,,,,,,,,,,,,,,,,,,,,,,,,,,,,,
,3866142600.8942,11.9331192970276,24.9833850860596,,,5,,,,37.3400002717972,,,,,3.50843169594416E-6,1.52347513978316E-8,-0.000571094950979401,0.00314455608514456,1.16947871830976E-6,5.07825692006504E-9,1.16947871825167E-6,3.50276209167721E-9,-1.16567641974573E-11,3.67686701898472E-9,2.99999618720286,10.005763053894,10,100,1,3,0.0122810475930799,0.00120653219540602,0.00376743380911648,254.757629394531,11.9321737289429,11.9350023269653,24.9833850860596,24.9833850860596,,,5.28180837631226,,1,,,,,,1,1,1,11.933385848999,0,11.9332709312439,,,,,,,,,,,,,,,,,,,,,,,,,,,,,,,,,
,3866146624.49133,111.266166687012,24.9833850860596,,,5,,,,37.3400002717972,,,,,9.95747844493333E-7,1.23229254660219E-8,1.26364196020505,0.00451896510939543,3.31914843085845E-7,4.1076281460538E-9,3.31834122949448E-7,3.83356122947558E-9,7.3196930995702E-9,1.47526854711781E-9,3.00000998821194,10.005763053894,10,100,1,3,0.00347721795598442,0.000418689602634489,0.0037651474121958,254.842720031738,111.265365600586,111.268409729004,24.9833850860596,24.9833850860596,,,6.98439216613769,,1,,,,,,1,1,1,111.266067504883,0,111.266736117276,,,,,,,,,,,,,,,,,,,,,,,,,,,,,,,,,
,3866150720.50874,210.600570678711,24.9833850860596,,,5,,,,37.3400002717972,,,,,9.64717861271102E-7,1.22694943783528E-8,1.46397637514083,0.00568157411529441,3.21571960476403E-7,4.08982306609576E-9,3.21466994772738E-7,3.66874715196156E-9,8.21565800298034E-9,1.80746979143299E-9,3.00000615676158,10.005763053894,10,100,1,3,0.00336742757839088,0.000417366435449374,0.00377430696971714,254.816429138184,210.596496582031,210.60481262207,24.9833850860596,24.9833850860596,,,7.24792623519897,,1,,,,,,1,1,1,210.599746704102,0,210.600936889648,,,,,,,,,,,,,,,,,,,,,,,,,,,,,,,,,
,3866154556.0289,299.997177124023,24.9833850860596,,,5,,,,37.3400002717972,,,,,9.28127577760728E-7,3.45547493934352E-9,2.17688982786247,0.00337479785444725,3.09377859741962E-7,1.15183242772007E-9,3.09154587555021E-7,4.7747352344088E-10,1.17516421066246E-8,1.04820655214536E-9,2.99998060150405,100.057640075684,10,1000,1,3,0.00321837541403338,0.000503087378296786,0.0122965173795819,197.728363037109,299.992065429687,300.005096435547,24.9833850860596,24.9833850860596,,,7.94536399841309,,1,,,,,,1,1,1,299.996643066406,0,299.998264478601,,,,,,,,,,,,,,,,,,,,,,,,,,,,,,,,,