File: LT data/Frome/M1/301-FC-ZFC-RTSIRM-contsweepwithloop-MsT.dat
[Header]
; MPMS3 Data File (default extension .dat)
; Copyright (c) 2007, Quantum Design, Inc. All rights reserved.
TITLE,
FILEOPENTIME,3865742957.32839,06/30/2022,10:27 am
BYAPP,MPMS3 w/ AC,1.0,1.1
INFO,MPMS3 Measurement Release 1.1.16 Build 424, MultiVu Release 2.3.4.19,APPNAME
INFO,Linear Motor Servo Controller,MOTOR_MODULE_NAME
INFO,3101-100 N2,MOTOR_HW_VERSION
INFO,,MOTOR_SERIAL_NUMBER
INFO,01.04.28,MOTOR_SOFTWARE_VERSION
INFO,Quantum Design Squid Module,SQUID_MODULE_NAME
INFO,3101-501 B0,SQUID_HW_VERSION
INFO,SQM327,SQUID_SERIAL_NUMBER
INFO,01.03.04,SQUID_SOFTWARE_VERSION
INFO,Quantum Design VSM Oven,OVEN_MODULE_NAME
INFO,3101-201 A3,OVEN_HW_VERSION
INFO,OVB365,OVEN_SERIAL_NUMBER
INFO,01.07.07,OVEN_SOFTWARE_VERSION
INFO,SQUID AC,AC_MODULE_NAME
INFO,3101-401 G0,AC_HW_VERSION
INFO,SAC220,AC_SERIAL_NUMBER
INFO,SQUID AC 00.95.07,AC_SOFTWARE_VERSION
INFO,TCI344,COIL_SERIAL_NUMBER
INFO,0,MOMENT_UNITS
INFO,Lmst,SAMPLE_MATERIAL
INFO,,SAMPLE_COMMENT
INFO,111.94,SAMPLE_MASS
INFO,,SAMPLE_VOLUME
INFO,,SAMPLE_MOLECULAR_WEIGHT
INFO,,SAMPLE_SIZE
INFO,,SAMPLE_SHAPE
INFO,Straw,SAMPLE_HOLDER
INFO,Standard,SAMPLE_HOLDER_DETAIL
INFO,61.28,SAMPLE_OFFSET
DATATYPE,COMMENT,1
DATATYPE,TIME,2
STARTUPAXIS,X,2
STARTUPAXIS,Y1,5
FIELDGROUP, VSM,2,3,4,5,6,8,9,10,11,14,15
FIELDGROUP, DC, 2,3,4,14,56,57,58,59,60,61,62,63,64,65,66,67,68,69
FIELDGROUP, AC, 2,3,4,11,16,17,18,19,20,21,22,23,24,25,26,27,28,29,30
STARTUPGROUP, All
[Data]
Comment,Time Stamp (sec),Temperature (K),Magnetic Field (Oe),Moment (emu),M. Std. Err. (emu),Transport Action,Averaging Time (sec),Frequency (Hz),Peak Amplitude (mm),Center Position (mm),Lockin Signal' (V),Lockin Signal (V),Range,M. Quad. Signal (emu),AC Moment (emu),AC M. Std Err. (emu),AC Phase (deg),AC Phase Std. Err. (deg),AC Susceptibility (emu/Oe),AC Suscept. Std Err. (emu/Oe),AC X' (emu/Oe),AC X' Std Err. (emu/Oe),AC X'' (emu/Oe),AC X'' Std Err. (emu/Oe),AC Drive (Oe),AC Frequency (Hz),AC Averaging Time (sec),AC Cycles,AC Range,AC Measure Type,AC Signal' (V),AC Signal'' (V),AC Trim Coil Ratio,AC Trim Coil Phase,Min. Temperature (K),Max. Temperature (K),Min. Field (Oe),Max. Field (Oe),Mass (grams),Motor Lag (deg),Pressure (Torr),Measure Count,Measurement Number,SQUID Status (code),Motor Status (code),Measure Status (code),Motor Current (amps),Motor Temp. (C),Temp. Status (code),Field Status (code),Chamber Status (code),Chamber Temp (K),Redirection State,Average Temp (K),Rotation Angle (deg),Rotator state,DC Moment Fixed Ctr (emu),DC Moment Err Fixed Ctr (emu),DC Moment Free Ctr (emu),DC Moment Err Free Ctr (emu),DC Fixed Fit,DC Free Fit,DC Calculated Center (mm),DC Calculated Center Err (mm),DC Scan Length (mm),DC Scan Time (s),DC Number of Points,DC Squid Drift,DC Min V (V),DC Max V (V),DC Scans per Measure,Map 01,Map 02,Map 03,Map 04,Map 05,Map 06,Map 07,Map 08,Map 09,Map 10,Map 11,Map 12,Map 13,Map 14,Map 15,Map 16
,3865744005.75706,100.00048828125,49999.75,0.0241382877418729,2.76847963667254E-6,1,2,12.9061126708984,4.98086357589644,45.7400009036064,31.3506301188738,4.59106683694441,100,-1.10678310693961E-5,,,,,,,,,,,,,,,,,,,,,100.00048828125,100.00048828125,49999.75,49999.75,49.6463078417264,5.40634607683171,7.42642784118652,26,1,0,0,1,0.27496337890625,30.7917900085449,1,1,1,100.00048828125,0,100.00048828125,,,,,,,,,,,,,,,,,,,,,,,,,,,,,,,,,
,3865744088.97947,89.4096488952637,49999.75,0.0269904189769333,6.42962448202433E-6,1,2,12.9061126708984,4.98134964728069,45.6999987363815,35.0599326770988,5.13310840470214,100,-1.32485160083236E-5,,,,,,,,,,,,,,,,,,,,,89.2486267089844,89.570671081543,49999.75,49999.75,49.5669725470245,5.40394903373731,7.3778133392334,26,1,0,0,1,0.27435302734375,30.3030319213867,2,1,1,89.2486267089844,0,89.4096488952637,,,,,,,,,,,,,,,,,,,,,,,,,,,,,,,,,
,3865744173.62204,75.6212768554687,49999.75,0.0322412853355468,8.40393178894686E-6,1,2,12.9061126708984,4.98165747081895,45.669998973608,41.8841724339343,6.13330273368842,100,-1.50266966829377E-5,,,,,,,,,,,,,,,,,,,,,75.4342422485352,75.8083114624023,49999.75,49999.75,49.6877341532456,5.40154249144605,7.29711008071899,26,1,0,0,1,0.27496337890625,31.2805480957031,2,1,1,75.4342422485352,0,75.6212768554687,,,,,,,,,,,,,,,,,,,,,,,,,,,,,,,,,
,3865744274.3583,58.6889533996582,49999.75,0.0420222390480563,6.6541153108391E-5,1,2,12.9061126708984,4.98280894729892,45.6200018525124,54.604205319912,8.02372177482278,100,1.33035084624866E-6,,,,,,,,,,,,,,,,,,,,,58.5535354614258,58.8243713378906,49999.75,49999.75,49.6334109711591,5.3999170662963,7.17454528808594,26,1,0,0,1,0.27008056640625,31.2805480957031,2,1,1,58.5535354614258,0,58.6889533996582,,,,,,,,,,,,,,,,,,,,,,,,,,,,,,,,,
,3865744412.58552,35.0310020446777,49999.75,0.0679372908644765,4.824262311024E-5,1,2,12.9061126708984,4.98439581817371,45.5700010061264,88.3328977061285,12.876617246078,1000,-7.5638938276411E-5,,,,,,,,,,,,,,,,,,,,,35.0310020446777,35.0310020446777,49999.75,49999.75,49.6599863408129,5.39333956756504,6.81677722930908,26,1,0,0,1,0.2685546875,31.2805480957031,2,1,1,35.0310020446777,0,35.0310020446777,,,,,,,,,,,,,,,,,,,,,,,,,,,,,,,,,
,3865744530.15363,15.6326699256897,49999.75,0.125355484203102,0.000170710566822719,1,2,12.9061126708984,4.98348953725757,45.549999922514,162.904525011365,24.0432180128603,1000,8.3420701362931E-5,,,,,,,,,,,,,,,,,,,,,15.5061597824097,15.7591800689697,49999.75,49999.75,49.7823112040726,5.3975260993457,5.87680912017822,26,1,0,0,1,0.269317626953125,30.7917900085449,2,1,1,15.5061597824097,0,15.6326699256897,,,,,,,,,,,,,,,,,,,,,,,,,,,,,,,,,
,3865744596.81708,5.9769492149353,49999.75,0.190797784270337,0.000159709496908818,1,2,12.9061126708984,4.98365396250731,45.5400012433529,248.004940209332,36.2972445743676,1000,-0.000103478978571384,,,,,,,,,,,,,,,,,,,,,5.79004144668579,6.16385698318481,49999.75,49999.75,49.9988223038995,5.39940795285274,4.27292060852051,26,1,0,0,1,0.26885986328125,31.2805480957031,6,1,1,5.79004144668579,0,5.9769492149353,,,,,,,,,,,,,,,,,,,,,,,,,,,,,,,,,
,3865744663.36,2.61747252941132,49999.75,0.215495229342104,3.57414121270863E-5,1,2,12.9061126708984,4.9837419906717,45.5400012433529,280.091905108825,41.1498410242578,1000,9.58430953065058E-7,,,,,,,,,,,,,,,,,,,,,2.61287784576416,2.62206721305847,49999.75,49999.75,50.3099104545534,5.40143433511676,3.01358318328857,26,1,0,0,1,0.269317626953125,31.2805480957031,6,1,1,2.61287784576416,0,2.61747252941132,,,,,,,,,,,,,,,,,,,,,,,,,,,,,,,,,
,3865744729.61362,2.48017728328705,49999.75,0.216238658238858,4.69840548893941E-5,1,2,12.9061126708984,4.98381188056327,45.5299988389015,281.05864440549,41.3271743605588,1000,2.75495529574848E-5,,,,,,,,,,,,,,,,,,,,,2.47386336326599,2.48649120330811,49999.75,49999.75,50.3032666121399,5.40090546649272,2.92227411270142,26,1,0,0,1,0.270156860351562,31.7693061828613,6,1,1,2.47386336326599,0,2.48017728328705,,,,,,,,,,,,,,,,,,,,,,,,,,,,,,,,,
,3865744792.41684,2.45345139503479,49999.75,0.216468251074121,1.30808648069925E-5,1,2,12.9061126708984,4.98382949528885,45.5299988389015,281.377422429444,41.2421675859058,1000,-7.17383233033819E-5,,,,,,,,,,,,,,,,,,,,,2.45139169692993,2.45551109313965,49999.75,49999.75,50.3396123382842,5.40118366257788,2.90157389640808,26,1,0,0,1,0.269317626953125,31.7693061828613,6,1,1,2.45551109313965,0,2.45345139503479,,,,,,,,,,,,,,,,,,,,,,,,,,,,,,,,,
,3865744858.54572,2.36467933654785,49999.75,0.216909444465092,2.86588012869294E-5,1,2,12.9061126708984,4.98383107156538,45.5299988389015,281.951209177129,41.3250600337474,1000,-7.27949723869327E-5,,,,,,,,,,,,,,,,,,,,,2.36291217803955,2.36644649505615,49999.75,49999.75,50.4357526461496,5.40114237250304,2.85628294944763,26,1,0,0,1,0.269241333007813,31.7693061828613,6,1,1,2.36291217803955,0,2.36467933654785,,,,,,,,,,,,,,,,,,,,,,,,,,,,,,,,,
,3865744921.00179,1.99966925382614,49999.75,0.218562158911112,1.73466409991617E-5,1,2,12.9061126708984,4.98386001377167,45.5299988389015,284.104903289086,41.6192781902374,1000,-8.95003192049921E-5,,,,,,,,,,,,,,,,,,,,,1.99957168102264,1.99976682662964,49999.75,49999.75,50.416993561688,5.40075954354337,2.6083288192749,26,1,0,0,1,0.2679443359375,31.2805480957031,5,1,1,1.99957168102264,0,1.99966925382614,,,,,,,,,,,,,,,,,,,,,,,,,,,,,,,,,
,3865745380.15569,20.6814603805542,26.500186920166,0.000131286437697053,5.93313698047978E-8,1,5,12.9061126708984,4.9831361502705,45.5299988389015,0.170615411555243,0.0250395986229917,1,-1.93387905747659E-8,,,,,,,,,,,,,,,,,,,,,20.269645690918,21.0932750701904,26.500186920166,26.500186920166,49.7416665210726,5.39823595939601,5.7154221534729,65,1,0,0,1,0.270004272460938,31.2805480957031,2,1,1,21.0932750701904,0,20.6814603805542,,,,,,,,,,,,,,,,,,,,,,,,,,,,,,,,,
,3865745568.63993,50.0886116027832,26.500186920166,0.000101759072980818,1.72833644824994E-8,1,5,12.9061126708984,4.98458432197073,45.5400012433529,0.132312833556032,0.0193057369419254,1,-9.9739938053914E-8,,,,,,,,,,,,,,,,,,,,,50.0886116027832,50.0886116027832,26.500186920166,26.500186920166,49.7721500333226,5.39238144711658,6.55081796646118,65,1,0,0,1,0.271530151367187,31.2805480957031,2,1,1,50.0886116027832,0,50.0886116027832,,,,,,,,,,,,,,,,,,,,,,,,,,,,,,,,,
,3865745757.2135,80.0249481201172,26.500186920166,8.95239190677587E-5,1.16279316614727E-8,1,5,12.9061126708984,4.98272908321893,45.5899983644486,0.116335980102155,0.017024296171965,1,-5.02725117682208E-8,,,,,,,,,,,,,,,,,,,,,80.0249481201172,80.0249481201172,26.500186920166,26.500186920166,49.7526093203418,5.39946585736945,6.85372543334961,64,1,64,0,0,0.269775390625,31.7693061828613,2,1,1,80.0249481201172,0,80.0249481201172,,,,,,,,,,,,,,,,,,,,,,,,,,,,,,,,,
,3865745939.96207,110.128227233887,26.500186920166,7.96834209672733E-5,1.46987342170676E-8,1,5,12.9061126708984,4.98101900482012,45.6500016152859,0.103502674205093,0.0151162099313921,1,-6.74306078711388E-8,,,,,,,,,,,,,,,,,,,,,110.128227233887,110.128227233887,26.500186920166,26.500186920166,49.6435721419091,5.40433774276026,7.02310800552368,63,1,64,0,0,0.274658203125,33.2355842590332,2,1,1,110.128227233887,0,110.128227233887,,,,,,,,,,,,,,,,,,,,,,,,,,,,,,,,,
,3865746120.7487,140.073715209961,26.500186920166,7.25533425799661E-5,9.83954075581779E-9,1,5,12.9061126708984,4.98025132075786,45.729998499155,0.0942234780999236,0.0137425930904184,1,-7.52863547277421E-8,,,,,,,,,,,,,,,,,,,,,140.073715209961,140.073715209961,26.500186920166,26.500186920166,49.7049299806687,5.40778517549272,7.11690807342529,65,1,0,0,1,0.278549194335938,32.2580642700195,2,1,1,140.073715209961,0,140.073715209961,,,,,,,,,,,,,,,,,,,,,,,,,,,,,,,,,
,3865746302.00745,170.017517089844,26.500186920166,6.67618572188552E-5,9.52136496840814E-9,1,5,12.9061126708984,4.97988130065464,45.830000191927,0.0866913045892711,0.0126567973616432,1,-5.96401429466089E-8,,,,,,,,,,,,,,,,,,,,,170.017517089844,170.017517089844,26.500186920166,26.500186920166,49.6228589861495,5.40984933896734,7.19034910202026,63,1,64,0,0,0.28045654296875,31.2805480957031,2,1,1,170.017517089844,0,170.017517089844,,,,,,,,,,,,,,,,,,,,,,,,,,,,,,,,,
,3865746483.11803,200.070251464844,26.500186920166,6.11053954620787E-5,9.24346655466844E-9,1,5,12.9061126708984,4.97843148110071,45.9400005638599,0.0793167672149645,0.0115596249111016,1,-7.00521797851052E-8,,,,,,,,,,,,,,,,,,,,,200.070251464844,200.070251464844,26.500186920166,26.500186920166,49.7244706936495,5.41369268234892,7.27913808822632,64,1,64,0,0,0.27069091796875,31.7693061828613,2,1,1,200.070251464844,0,200.070251464844,,,,,,,,,,,,,,,,,,,,,,,,,,,,,,,,,
,3865746663.74947,230.040328979492,26.500186920166,5.66181292220742E-5,8.21246338236567E-9,1,5,12.9061126708984,4.98827159274495,46.0800006985664,0.0736990547291089,0.010722039382467,1,-7.90961216762814E-8,,,,,,,,,,,,,,,,,,,,,230.040328979492,230.040328979492,26.500186920166,26.500186920166,49.7901274892649,5.41381812488313,7.41916179656982,64,1,64,0,0,0.275039672851562,30.7917900085449,2,1,1,230.040328979492,0,230.040328979492,,,,,,,,,,,,,,,,,,,,,,,,,,,,,,,,,
,3865746845.63895,260.160934448242,26.500186920166,5.28024408430236E-5,7.61507555577278E-9,1,5,12.9061126708984,4.98857195156209,46.2399981915951,0.0687367731847242,0.0100088742201588,1,-6.71699843974739E-8,,,,,,,,,,,,,,,,,,,,,260.141479492187,260.180389404297,26.500186920166,26.500186920166,49.7721500333226,5.41260412005708,7.71872091293335,63,1,64,0,0,0.270462036132813,31.7693061828613,2,1,1,260.180389404297,0,260.160934448242,,,,,,,,,,,,,,,,,,,,,,,,,,,,,,,,,
,3865747026.08839,290.095672607422,26.500186920166,4.9464742705002E-5,8.73691975399238E-9,1,5,12.9061126708984,4.98928999716958,46.4100018143654,0.0644041988379607,0.00938258985950856,1,-5.94728702467916E-8,,,,,,,,,,,,,,,,,,,,,290.095672607422,290.095672607422,26.500186920166,26.500186920166,49.7553450201591,5.40994100624425,7.642333984375,64,1,64,0,0,0.282745361328125,31.7693061828613,2,1,1,290.095672607422,0,290.095672607422,,,,,,,,,,,,,,,,,,,,,,,,,,,,,,,,,
,3865748669.89497,1.99993604421616,42958.51171875,0.210391894931242,1.25366517493146E-5,1,2,12.9061126708984,5.00357693080416,45.5200001597404,274.995475277732,40.3370788108933,1000,-4.70093311035932E-5,,,,,,,,,,,,,,,,,,,,,1.99992156028748,1.99995052814484,42843.76171875,43073.26171875,50.213770146688,5.40080655818232,2.66637587547302,26,1,0,0,1,0.270004272460938,31.2805480957031,1,6,1,1.99995052814484,0,1.99993604421616,,,,,,,,,,,,,,,,,,,,,,,,,,,,,,,,,
,3865748737.34748,1.99988222122192,36224.095703125,0.199818372753382,2.67303254468371E-5,1,2,12.9061126708984,5.00346124553071,45.5299988389015,261.164760881547,38.3222739083158,1000,-3.42197406339115E-5,,,,,,,,,,,,,,,,,,,,,1.99977385997772,1.99999058246613,36054.2578125,36393.93359375,50.0629158424764,5.39996340636124,2.66039276123047,26,1,0,0,1,0.27069091796875,31.2805480957031,1,6,1,1.99999058246613,0,1.99988222122192,,,,,,,,,,,,,,,,,,,,,,,,,,,,,,,,,
,3865748804.61063,1.9998767375946,29509.9833984375,0.186555284839942,2.83465560502674E-5,1,2,12.9061126708984,5.0031426406105,45.5200001597404,243.80979699051,35.7633873675237,1000,-4.11529853486035E-5,,,,,,,,,,,,,,,,,,,,,1.999596118927,2.00015735626221,29415.18359375,29604.783203125,49.9816264764764,5.40006798874144,2.6642735004425,26,1,0,0,1,0.27069091796875,31.7693061828613,1,6,1,2.00015735626221,0,1.9998767375946,,,,,,,,,,,,,,,,,,,,,,,,,,,,,,,,,
,3865748869.0439,1.99979680776596,23075.814453125,0.169291274576543,5.67811474497523E-5,1,2,12.9061126708984,5.00325719943589,45.5299988389015,221.259201232761,32.4227723139999,1000,-6.18882091564098E-5,,,,,,,,,,,,,,,,,,,,,1.99973165988922,1.9998619556427,22985.978515625,23165.650390625,49.9468440073707,5.3991500328456,2.65258359909058,26,1,0,0,1,0.27099609375,31.7693061828613,1,6,1,1.99973165988922,0,1.99979680776596,,,,,,,,,,,,,,,,,,,,,,,,,,,,,,,,,
,3865748933.53083,2.00002908706665,16636.14453125,0.144867074628656,9.68600814092564E-5,1,2,12.9061126708984,5.00339164994568,45.5200001597404,189.342454864963,27.7602862366869,1000,-4.20878712297051E-5,,,,,,,,,,,,,,,,,,,,,1.9999520778656,2.0001060962677,16546.345703125,16725.943359375,49.9011187389957,5.39878512544639,2.65249586105347,26,1,0,0,1,0.271377563476562,31.7693061828613,1,6,1,2.0001060962677,0,2.00002908706665,,,,,,,,,,,,,,,,,,,,,,,,,,,,,,,,,
,3865749000.01265,1.99997174739838,9999.884765625,0.107040123573765,7.65670097482462E-5,1,2,12.9061126708984,5.00309784202852,45.5200001597404,139.89529915469,20.4794884896919,1000,-5.44272182491045E-5,,,,,,,,,,,,,,,,,,,,,1.99991655349731,2.00002694129944,9905.0908203125,10094.6787109375,49.7795755042553,5.39852820482781,2.65704989433289,26,1,0,0,1,0.273056030273438,33.2355842590332,1,6,1,1.99991655349731,0,1.99997174739838,,,,,,,,,,,,,,,,,,,,,,,,,,,,,,,,,
,3865749087.93012,2.00010722875595,1215.65539550781,0.0191038289629798,0.000152478951751396,1,2,12.9061126708984,5.00303900087043,45.5200001597404,24.9685123319437,3.64603433246784,100,-1.65641285868829E-5,,,,,,,,,,,,,,,,,,,,,1.99997913837433,2.00023531913757,1050.61840820312,1380.6923828125,49.7236890651303,5.39865290837212,2.65287709236145,26,1,0,0,1,0.271453857421875,31.2805480957031,1,6,1,1.99997913837433,0,2.00010722875595,,,,,,,,,,,,,,,,,,,,,,,,,,,,,,,,,
,3865749163.16196,2.00010251998901,-6311.0498046875,-0.0762264344480388,0.000100176018538202,1,2,12.9061126708984,5.00293126171523,45.5200001597404,-99.6059587987882,-14.6716788291329,100,-2.88186851144081E-5,,,,,,,,,,,,,,,,,,,,,1.99995565414429,2.00024938583374,-6405.962890625,-6216.13671875,49.751436877563,5.39894641516636,2.64187788963318,26,1,0,0,1,0.274734497070313,31.7693061828613,1,6,1,2.00024938583374,0,2.00010251998901,,,,,,,,,,,,,,,,,,,,,,,,,,,,,,,,,
,3865749229.6952,2.00007992982864,-12961.7885742187,-0.125448891194726,6.3539309049228E-5,1,2,12.9061126708984,5.00283828636163,45.5200001597404,-163.917104918502,-24.1733194511424,100,-6.89923156011558E-5,,,,,,,,,,,,,,,,,,,,,1.99997842311859,2.0001814365387,-13056.720703125,-12866.8564453125,49.7651153766495,5.39946188257668,2.6289427280426,26,1,0,0,1,0.270233154296875,31.7693061828613,1,6,1,1.99997842311859,0,2.00007992982864,,,,,,,,,,,,,,,,,,,,,,,,,,,,,,,,,
,3865749320.30905,2.00037574768066,-22022.1640625,-0.165654136029931,3.99576650931006E-5,1,2,12.9061126708984,5.0028807617334,45.5200001597404,-216.481023467037,-31.7346354027883,1000,5.15351392504623E-5,,,,,,,,,,,,,,,,,,,,,2.00036215782166,2.00038933753967,-22117.453125,-21926.875,49.9124523525245,5.40002374894025,2.6170916557312,26,1,0,0,1,0.273056030273438,32.2580642700195,1,6,1,2.00038933753967,0,2.00037574768066,,,,,,,,,,,,,,,,,,,,,,,,,,,,,,,,,
,3865749386.97497,2.00011646747589,-28693.0234375,-0.184490672329929,2.87085248790254E-5,1,2,12.9061126708984,5.00281522776561,45.5200001597404,-241.091528269963,-35.3502743088088,1000,5.1471498891962E-5,,,,,,,,,,,,,,,,,,,,,2.00004076957703,2.00019216537476,-28803.16015625,-28582.88671875,49.9808448479572,5.40055615759456,2.5983030796051,26,1,0,0,1,0.273513793945313,31.7693061828613,1,6,1,2.00004076957703,0,2.00011646747589,,,,,,,,,,,,,,,,,,,,,,,,,,,,,,,,,
,3865749453.51631,2.0002543926239,-35359.931640625,-0.198298171422844,3.01482294087351E-5,1,2,12.9061126708984,5.00296410439533,45.5200001597404,-259.13295312482,-38.0856210014358,1000,-1.20990081028905E-5,,,,,,,,,,,,,,,,,,,,,2.0002167224884,2.0002920627594,-35425.171875,-35294.69140625,50.1395154373611,5.40089447375039,2.59870004653931,26,1,0,0,1,0.271835327148438,32.7468223571777,1,6,1,2.0002167224884,0,2.0002543926239,,,,,,,,,,,,,,,,,,,,,,,,,,,,,,,,,
,3865749519.74198,1.99944961071014,-41997.46484375,-0.208934640871997,5.66987115326733E-5,1,2,12.9061126708984,5.00279362439072,45.5200001597404,-273.02342779331,-40.0998456738592,1000,7.70523584550681E-6,,,,,,,,,,,,,,,,,,,,,1.9989972114563,1.99990200996399,-42087.578125,-41907.3515625,50.229011902813,5.40240654834437,2.59821128845215,26,1,0,0,1,0.273513793945313,31.7693061828613,1,6,1,1.9989972114563,0,1.99944961071014,,,,,,,,,,,,,,,,,,,,,,,,,,,,,,,,,
,3865749586.25379,1.9984547495842,-48658.876953125,-0.217552987423123,3.20325935664262E-5,1,2,12.9061126708984,5.00286539417802,45.5200001597404,-284.291272672299,-41.75346772593,1000,9.01430432424791E-6,,,,,,,,,,,,,,,,,,,,,1.99831521511078,1.99859428405762,-48748.8515625,-48568.90234375,50.3446929236592,5.4026294842063,2.56600618362427,26,1,0,0,1,0.2716064453125,31.7693061828613,1,6,1,1.99831521511078,0,1.9984547495842,,,,,,,,,,,,,,,,,,,,,,,,,,,,,,,,,
,3865749652.80092,2.00015932321548,-45185.328125,-0.213403702162089,0.000221562607591365,1,2,12.9061126708984,5.00295207693463,45.5200001597404,-278.834262142733,-41.2414275954538,1000,-0.000207956220225232,,,,,,,,,,,,,,,,,,,,,1.99737846851349,2.00294017791748,-45290.08984375,-45080.56640625,50.2505066870919,5.40251228559753,2.54756236076355,26,1,0,0,1,0.275039672851562,31.7693061828613,1,6,1,2.00294017791748,0,2.00015932321548,,,,,,,,,,,,,,,,,,,,,,,,,,,,,,,,,
,3865749719.33451,2.00491225719452,-38543.20703125,-0.203712559711246,7.72537593289E-5,1,2,12.9061126708984,5.00273848735654,45.5200001597404,-266.178437724067,-39.2125478579399,1000,-8.09190799483841E-5,,,,,,,,,,,,,,,,,,,,,2.00260066986084,2.0072238445282,-38623.12109375,-38463.29296875,50.2376098165245,5.40239975533793,2.55068421363831,26,1,0,0,1,0.272598266601562,31.7693061828613,5,6,1,2.0072238445282,0,2.00491225719452,,,,,,,,,,,,,,,,,,,,,,,,,,,,,,,,,
,3865749787.6642,1.99983078241348,-31721.1767578125,-0.191417494035872,3.82155477146246E-5,1,2,12.9061126708984,5.00274384044519,45.5200001597404,-250.127927293101,-36.7485462881783,1000,-1.50899518617274E-6,,,,,,,,,,,,,,,,,,,,,1.99972653388977,1.99993503093719,-31816.109375,-31626.244140625,50.112158439188,5.40188791831756,2.53523826599121,26,1,0,0,1,0.27496337890625,31.7693061828613,1,6,1,1.99993503093719,0,1.99983078241348,,,,,,,,,,,,,,,,,,,,,,,,,,,,,,,,,
,3865749854.19425,2.00001275539398,-25082.8857421875,-0.175276108208406,3.84294261596556E-5,1,2,12.9061126708984,5.00288324404246,45.5200001597404,-229.049651534374,-33.6172186055151,1000,2.44827485237089E-5,,,,,,,,,,,,,,,,,,,,,1.99969530105591,2.00033020973206,-25177.685546875,-24988.0859375,49.9609133207168,5.40078866779509,2.53752899169922,26,1,0,0,1,0.272293090820313,33.7243423461914,1,6,1,1.99969530105591,0,2.00001275539398,,,,,,,,,,,,,,,,,,,,,,,,,,,,,,,,,
,3865749920.76404,1.9997119307518,-18434.9296875,-0.152725218780772,4.57967104690852E-5,1,2,12.9061126708984,5.00271199048422,45.5200001597404,-199.58020837904,-29.2261699260377,1000,7.0677975868118E-5,,,,,,,,,,,,,,,,,,,,,1.99942481517792,1.99999904632568,-18509.94140625,-18359.91796875,49.9136247953034,5.40075673331967,2.5397834777832,26,1,0,0,1,0.271987915039062,32.2580642700195,1,6,1,1.99942481517792,0,1.9997119307518,,,,,,,,,,,,,,,,,,,,,,,,,,,,,,,,,
,3865749987.46086,1.99911165237427,-11776.4379882812,-0.119713333057316,6.96242697877341E-5,1,2,12.9061126708984,5.00268711347941,45.5200001597404,-156.436271863184,-22.9301836792923,1000,3.89677535634713E-5,,,,,,,,,,,,,,,,,,,,,1.99904239177704,1.9991809129715,-11831.369140625,-11721.5068359375,49.8034151740918,5.40035408120628,2.51338624954224,26,1,0,0,1,0.275039672851562,32.2580642700195,5,6,1,1.9991809129715,0,1.99911165237427,,,,,,,,,,,,,,,,,,,,,,,,,,,,,,,,,
,3865750054.6093,1.99992191791534,-5066.24951171875,-0.0664048534738958,0.000112522750670969,1,2,12.9061126708984,5.00238861043695,45.5200001597404,-86.7597638661849,-12.7728394857155,100,-2.01380576569061E-5,,,,,,,,,,,,,,,,,,,,,1.99992191791534,1.99992191791534,-5066.24951171875,-5066.24951171875,49.7733224761014,5.40086312416426,2.55177807807922,24,1,68,0,0,0.275344848632813,31.7693061828613,5,6,1,1.99992191791534,0,1.99992191791534,,,,,,,,,,,,,,,,,,,,,,,,,,,,,,,,,
,3865750146.28287,1.99977171421051,4099.05505371094,0.053924407642439,0.000117567832515368,1,2,12.9061126708984,5.00272271626004,45.5200001597404,70.4583666383408,10.3864245926003,100,2.64578667046669E-5,,,,,,,,,,,,,,,,,,,,,1.99955475330353,1.99998867511749,4008.93676757812,4189.17333984375,49.7342410501399,5.39996720364057,2.53449583053589,26,1,0,0,1,0.273590087890625,31.7693061828613,1,6,1,1.99998867511749,0,1.99977171421051,,,,,,,,,,,,,,,,,,,,,,,,,,,,,,,,,
,3865750212.94186,2.00009417533874,10758.8950195312,0.111648855946366,7.42105201138833E-5,1,2,12.9061126708984,5.00261222753589,45.5200001597404,145.876224216254,21.512170094986,100,6.09461533830611E-5,,,,,,,,,,,,,,,,,,,,,1.99995970726013,2.00022864341736,10648.9267578125,10868.86328125,49.773713290361,5.40027573473165,2.53489565849304,26,1,0,0,1,0.2728271484375,31.2805480957031,1,6,1,1.99995970726013,0,2.00009417533874,,,,,,,,,,,,,,,,,,,,,,,,,,,,,,,,,
,3865750299.64682,1.99983841180801,19435.5,0.156256708756219,4.77071511231773E-5,1,2,12.9061126708984,5.0028264342665,45.5200001597404,204.197152996788,29.9336968178021,1000,-4.87668887060566E-5,,,,,,,,,,,,,,,,,,,,,1.99974846839905,1.99992835521698,19370.53515625,19500.46484375,49.9659939060918,5.40115941936556,2.50827550888062,26,1,0,0,1,0.271835327148438,33.2355842590332,1,6,1,1.99974846839905,0,1.99983841180801,,,,,,,,,,,,,,,,,,,,,,,,,,,,,,,,,
,3865750362.02555,1.99976944923401,25671.8564453125,0.17669864426169,5.71096191226069E-5,1,2,12.9061126708984,5.0027240269568,45.5200001597404,230.909347604125,33.8135157312707,1000,-8.21001203648595E-5,,,,,,,,,,,,,,,,,,,,,1.99970722198486,1.99983167648315,25601.7265625,25741.986328125,49.9280849229091,5.40151853185141,2.50217843055725,26,1,0,0,1,0.273513793945313,31.2805480957031,1,6,1,1.99983167648315,0,1.99976944923401,,,,,,,,,,,,,,,,,,,,,,,,,,,,,,,,,
,3865750426.49729,2.00023758411407,32134.1669921875,0.192108630769216,2.65852715250586E-5,1,2,12.9061126708984,5.00264584444231,45.5200001597404,251.031982142237,36.8269868852528,1000,-3.92248853053789E-5,,,,,,,,,,,,,,,,,,,,,2.00002527236938,2.00044989585876,32064.125,32204.208984375,50.1727346494284,5.40312923220532,2.51330947875977,26,1,0,0,1,0.276641845703125,31.7693061828613,1,6,1,2.00044989585876,0,2.00023758411407,,,,,,,,,,,,,,,,,,,,,,,,,,,,,,,,,
,3865750492.02323,2.0001021027565,38703.48046875,0.20408294962923,2.35238188095123E-5,1,2,12.9061126708984,5.00280927951593,45.5200001597404,266.695445853238,39.0956615797247,1000,-6.35384960554938E-5,,,,,,,,,,,,,,,,,,,,,1.99988996982574,2.00031423568726,38538.19140625,38868.76953125,50.1645275499765,5.40296830765544,2.49675703048706,26,1,0,0,1,0.272216796875,32.2580642700195,1,6,1,2.00031423568726,0,2.0001021027565,,,,,,,,,,,,,,,,,,,,,,,,,,,,,,,,,
,3865750559.29212,1.99997764825821,45441.97265625,0.213526193907921,3.18973432772248E-5,1,2,12.9061126708984,5.0028117347941,45.5200001597404,279.026115562606,40.9724130808273,1000,-1.46666653017323E-5,,,,,,,,,,,,,,,,,,,,,1.99997508525848,1.99998021125793,45351.609375,45532.3359375,50.3188991825246,5.40367155757372,2.49668884277344,26,1,0,0,1,0.271224975585938,31.7693061828613,1,6,1,1.99997508525848,0,1.99997764825821,,,,,,,,,,,,,,,,,,,,,,,,,,,,,,,,,
,3865751063.47693,9.18172359466553,26.4500465393066,0.000133891391610579,1.84660065296486E-7,1,5,12.9061126708984,5.00236543415696,45.5200001597404,0.174960957912555,0.0255540350413303,10,-1.12113002262029E-7,,,,,,,,,,,,,,,,,,,,,8.81800651550293,9.54544067382813,26.4500465393066,26.4500465393066,49.7385400069956,5.40107268525109,4.58951282501221,65,1,0,0,1,0.274429321289062,31.2805480957031,6,1,1,9.54544067382813,0,9.18172359466553,,,,,,,,,,,,,,,,,,,,,,,,,,,,,,,,,
,3865751257.5878,39.0320739746094,26.4500465393066,9.52167840294008E-5,1.36773727457519E-8,1,5,12.9061126708984,5.00370625870052,45.5299988389015,0.124469269176268,0.018184997334412,1,-7.55659212424873E-8,,,,,,,,,,,,,,,,,,,,,39.0320739746094,39.0320739746094,26.4500465393066,26.4500465393066,49.7830928325918,5.39610659134428,6.29356241226196,65,1,0,0,1,0.269851684570313,31.7693061828613,2,1,1,39.0320739746094,0,39.0320739746094,,,,,,,,,,,,,,,,,,,,,,,,,,,,,,,,,
,3865751447.7966,69.1140670776367,26.4500465393066,8.50106039953173E-5,1.01947230550963E-8,1,5,12.9061126708984,5.00178614321422,45.5700010061264,0.111069718294866,0.0162143675184547,1,-7.71718733765377E-8,,,,,,,,,,,,,,,,,,,,,69.1140670776367,69.1140670776367,26.4500465393066,26.4500465393066,49.8522669565437,5.40417829798045,6.72396659851074,65,1,0,0,1,0.2777099609375,30.7917900085449,2,1,1,69.1140670776367,0,69.1140670776367,,,,,,,,,,,,,,,,,,,,,,,,,,,,,,,,,
,3865751631.87631,99.0406341552734,26.4500465393066,7.677409094589E-5,1.05969907538747E-8,1,5,12.9061126708984,5.00008652218083,45.6200018525124,0.100264572148676,0.0146097842924981,1,-9.009457904075E-8,,,,,,,,,,,,,,,,,,,,,99.0406341552734,99.0406341552734,26.4500465393066,26.4500465393066,49.6994585810341,5.40983078561027,6.92327737808228,65,1,0,0,1,0.281600952148438,31.2805480957031,2,1,1,99.0406341552734,0,99.0406341552734,,,,,,,,,,,,,,,,,,,,,,,,,,,,,,,,,
,3865751814.20224,129.108535766602,26.4500465393066,7.00273215133903E-5,1.15044026832304E-8,1,5,12.9061126708984,4.99971143811331,45.6999987363815,0.0914436590703219,0.0133260899709896,1,-8.09613332403573E-8,,,,,,,,,,,,,,,,,,,,,129.108535766602,129.108535766602,26.4500465393066,26.4500465393066,49.6947688099187,5.41185296441504,7.03219127655029,65,1,0,0,1,0.281295776367187,31.7693061828613,2,1,1,129.108535766602,0,129.108535766602,,,,,,,,,,,,,,,,,,,,,,,,,,,,,,,,,
,3865751994.99016,159.107421875,26.4500465393066,6.53207250395676E-5,8.65971584998473E-9,1,5,12.9061126708984,4.99969326547197,45.7900017499924,0.0852985396265108,0.01242137171228,1,-8.24109452630416E-8,,,,,,,,,,,,,,,,,,,,,159.107421875,159.107421875,26.4500465393066,26.4500465393066,49.7193901082745,5.41156668476073,7.12537670135498,65,1,0,0,1,0.281600952148438,32.2580642700195,2,1,1,159.107421875,0,159.107421875,,,,,,,,,,,,,,,,,,,,,,,,,,,,,,,,,
,3865752175.43434,189.062240600586,26.4500465393066,6.07439262475432E-5,7.73020757952831E-9,1,5,12.9061126708984,4.99895190679451,45.8999983966351,0.0793064782507529,0.0115419095258428,1,-8.18002047909049E-8,,,,,,,,,,,,,,,,,,,,,189.062240600586,189.062240600586,26.4500465393066,26.4500465393066,49.7236890651303,5.41360545852127,7.19950246810913,64,1,64,0,0,0.282974243164062,31.2805480957031,2,1,1,189.062240600586,0,189.062240600586,,,,,,,,,,,,,,,,,,,,,,,,,,,,,,,,,
,3865752356.36291,219.005874633789,26.4500465393066,5.67811260511002E-5,9.80874589017824E-9,1,5,12.9061126708984,4.99823546477421,46.0299998521805,0.0741143174498158,0.0108105687527992,1,-5.82314847632417E-8,,,,,,,,,,,,,,,,,,,,,219.005874633789,219.005874633789,26.4500465393066,26.4500465393066,49.817484487438,5.41460269403503,7.3165225982666,63,1,64,0,0,0.270156860351562,31.7693061828613,2,1,1,219.005874633789,0,219.005874633789,,,,,,,,,,,,,,,,,,,,,,,,,,,,,,,,,
,3865752537.26821,249.023620605469,26.4500465393066,5.36078073261339E-5,1.08652942547777E-8,1,5,12.9061126708984,4.99774252587605,46.1799986660481,0.0699624893701282,0.0102059599546685,1,-5.4233516666987E-8,,,,,,,,,,,,,,,,,,,,,249.023620605469,249.023620605469,26.4500465393066,26.4500465393066,49.7420573353322,5.41685260792602,7.59101152420044,63,1,64,0,0,0.267791748046875,30.7917900085449,2,1,1,249.023620605469,0,249.023620605469,,,,,,,,,,,,,,,,,,,,,,,,,,,,,,,,,
,3865752718.58185,279.058258056641,26.4500465393066,5.0822924845337E-5,1.14593315957146E-8,1,5,12.9061126708984,4.99823072628925,46.3499985635281,0.0663378842141647,0.00967157158457093,1,-5.56468346695477E-8,,,,,,,,,,,,,,,,,,,,,279.058258056641,279.058258056641,26.4500465393066,26.4500465393066,49.6990677667745,5.41518812905621,7.8689136505127,64,1,64,0,0,0.269088745117187,31.7693061828613,2,1,1,279.058258056641,0,279.058258056641,,,,,,,,,,,,,,,,,,,,,,,,,,,,,,,,,
,3865753505.2237,292.997741699219,26.500186920166,6.07544850292333E-5,7.32879053125465E-9,1,5,12.9061126708984,4.98023416403715,46.4200004935265,0.0788976515813838,0.0115248245860756,1,-4.98338135991309E-8,,,,,,,,,,,,,,,,,,,,,292.997741699219,292.997741699219,26.500186920166,26.500186920166,49.7619888625726,5.4092506772109,8.38045024871826,64,1,64,0,0,0.279006958007813,31.2805480957031,2,1,1,292.997741699219,0,292.997741699219,,,,,,,,,,,,,,,,,,,,,,,,,,,,,,,,,
,3865753677.32449,262.966888427734,26.500186920166,6.13068830889902E-5,7.92601308244482E-9,1,5,12.9061126708984,4.97931468333682,46.2700016796589,0.0795967684870341,0.011610101136508,1,-6.2991055232428E-8,,,,,,,,,,,,,,,,,,,,,262.966888427734,262.966888427734,26.500186920166,26.500186920166,49.8065416881687,5.41299170279996,8.30758953094482,64,1,64,0,0,0.275726318359375,31.7693061828613,2,1,1,262.966888427734,0,262.966888427734,,,,,,,,,,,,,,,,,,,,,,,,,,,,,,,,,
,3865753857.48421,232.9609375,26.500186920166,6.13290466482805E-5,8.21083309479886E-9,1,5,12.9061126708984,4.98766577888664,46.1400002241135,0.0798137076354162,0.0116385569834263,1,-6.54118877580413E-8,,,,,,,,,,,,,,,,,,,,,232.9609375,232.9609375,26.500186920166,26.500186920166,49.773713290361,5.41533807389537,8.11975955963135,64,1,64,0,0,0.27862548828125,32.2580642700195,2,1,1,232.9609375,0,232.9609375,,,,,,,,,,,,,,,,,,,,,,,,,,,,,,,,,
,3865754037.64483,202.964645385742,26.500186920166,6.10794864460642E-5,7.93556727397023E-9,1,5,12.9061126708984,4.98833902433189,46.0399985313416,0.0795045717742776,0.0115894547835247,1,-6.81724652928378E-8,,,,,,,,,,,,,,,,,,,,,202.964645385742,202.964645385742,26.500186920166,26.500186920166,49.7213441795726,5.41305085133291,7.98051500320435,63,1,64,0,0,0.274276733398438,31.7693061828613,2,1,1,202.964645385742,0,202.964645385742,,,,,,,,,,,,,,,,,,,,,,,,,,,,,,,,,
,3865754217.24061,172.936111450195,26.500186920166,6.02422611000397E-5,6.6909234615139E-9,1,5,12.9061126708984,4.98793152285607,45.9199994802475,0.0784091944616656,0.0114061703640405,1,-8.50012741888814E-8,,,,,,,,,,,,,,,,,,,,,172.936111450195,172.936111450195,26.500186920166,26.500186920166,49.6513884271014,5.41938870025405,7.85272264480591,65,1,0,0,1,0.276718139648438,30.7917900085449,2,1,1,172.936111450195,0,172.936111450195,,,,,,,,,,,,,,,,,,,,,,,,,,,,,,,,,
,3865754396.44094,142.990219116211,26.500186920166,5.89248770302918E-5,6.48870990984743E-9,1,5,12.9061126708984,4.98739134381894,45.8500012755394,0.076683272452287,0.0111523247667372,1,-8.52314409063661E-8,,,,,,,,,,,,,,,,,,,,,142.990219116211,142.990219116211,26.500186920166,26.500186920166,49.7494828062649,5.41911180356969,7.74331426620483,65,1,0,0,1,0.268783569335938,31.2805480957031,2,1,1,142.990219116211,0,142.990219116211,,,,,,,,,,,,,,,,,,,,,,,,,,,,,,,,,
,3865754576.98293,112.874496459961,26.500186920166,5.67019639954749E-5,7.05027460770144E-9,1,5,12.9061126708984,4.99104327866547,45.7700006663799,0.0738608325607683,0.0107797197487705,1,-5.3546099580878E-8,,,,,,,,,,,,,,,,,,,,,112.874496459961,112.874496459961,26.500186920166,26.500186920166,49.6384915565341,5.4055568376434,7.64203977584839,65,1,0,0,1,0.2789306640625,31.7693061828613,2,1,1,112.874496459961,0,112.874496459961,,,,,,,,,,,,,,,,,,,,,,,,,,,,,,,,,
,3865754756.64341,82.9920806884766,26.500186920166,5.50134464309123E-5,5.78985397179674E-9,1,5,12.9061126708984,4.99090049961935,45.6800013780594,0.0716599654805776,0.0104480982457144,1,-5.97790494576159E-8,,,,,,,,,,,,,,,,,,,,,82.9920806884766,82.9920806884766,26.500186920166,26.500186920166,49.7670694479476,5.40619031521878,7.474365234375,65,1,0,0,1,0.278091430664062,31.7693061828613,2,1,1,82.9920806884766,0,82.9920806884766,,,,,,,,,,,,,,,,,,,,,,,,,,,,,,,,,
,3865754932.20518,52.9758491516113,26.500186920166,5.43392845554993E-5,6.21792481981056E-9,1,5,12.9061126708984,4.99283048215542,45.609999448061,0.0708192961792742,0.010331878434241,1,-5.42751477445713E-8,,,,,,,,,,,,,,,,,,,,,52.9758491516113,52.9758491516113,26.500186920166,26.500186920166,49.8608648702553,5.39895244128237,7.22640562057495,65,1,0,0,1,0.27313232421875,32.2580642700195,2,1,1,52.9758491516113,0,52.9758491516113,,,,,,,,,,,,,,,,,,,,,,,,,,,,,,,,,
,3865755107.46789,22.9919395446777,26.500186920166,5.39520728180141E-5,6.37459778883995E-9,1,5,12.9061126708984,4.99401625983954,45.5700010061264,0.0703366210274906,0.0102715468086361,1,-4.63131041258755E-8,,,,,,,,,,,,,,,,,,,,,22.9919395446777,22.9919395446777,26.500186920166,26.500186920166,49.7807479470341,5.39503938727732,6.61004400253296,65,1,0,0,1,0.270004272460938,30.3030319213867,2,1,1,22.9919395446777,0,22.9919395446777,,,,,,,,,,,,,,,,,,,,,,,,,,,,,,,,,
,3865755712.90414,9.02128505706787,26.500186920166,5.41732794913264E-5,6.16562428337377E-9,1,5,12.9061126708984,4.99455878571933,45.5299988389015,0.0706373534310221,0.0103044104147347,1,-5.48034027562526E-8,,,,,,,,,,,,,,,,,,,,,9.02128505706787,9.02128505706787,26.500186920166,26.500186920166,49.7729316618418,5.39502304387196,4.71112680435181,65,1,0,0,1,0.27069091796875,31.7693061828613,6,1,1,9.02128505706787,0,9.02128505706787,,,,,,,,,,,,,,,,,,,,,,,,,,,,,,,,,
,3865755906.32528,39.0144500732422,26.500186920166,5.4259814989665E-5,6.1717173602029E-9,1,5,12.9061126708984,4.9953532745211,45.5299988389015,0.0707691422428515,0.0103015622641855,1,-7.14629280257212E-8,,,,,,,,,,,,,,,,,,,,,39.0144500732422,39.0144500732422,26.500186920166,26.500186920166,49.7709775905437,5.39116983444549,6.37754249572754,65,1,0,0,1,0.279617309570313,31.2805480957031,2,1,1,39.0144500732422,0,39.0144500732422,,,,,,,,,,,,,,,,,,,,,,,,,,,,,,,,,
,3865756097.24486,69.0820846557617,26.500186920166,5.46309756098948E-5,6.73315148738337E-9,1,5,12.9061126708984,4.99331874549991,45.5700010061264,0.0712088760117771,0.0103910845531081,1,-5.27861201427212E-8,,,,,,,,,,,,,,,,,,,,,69.0820846557617,69.0820846557617,26.500186920166,26.500186920166,49.7854377181495,5.3977555452701,6.81958627700806,65,1,0,0,1,0.272445678710938,31.2805480957031,2,1,1,69.0820846557617,0,69.0820846557617,,,,,,,,,,,,,,,,,,,,,,,,,,,,,,,,,
,3865756281.89425,99.066780090332,26.500186920166,5.51314497125939E-5,6.40409679516288E-9,1,5,12.9061126708984,4.99196855422499,45.6200018525124,0.0718364343582249,0.0104655039246628,1,-6.6162482650871E-8,,,,,,,,,,,,,,,,,,,,,99.066780090332,99.066780090332,26.500186920166,26.500186920166,49.792081560563,5.40345416250687,7.02197694778442,64,1,64,0,0,0.277175903320313,31.2805480957031,2,1,1,99.066780090332,0,99.066780090332,,,,,,,,,,,,,,,,,,,,,,,,,,,,,,,,,
,3865756463.8369,129.118041992188,26.500186920166,5.63284595282144E-5,7.84238833451663E-9,1,5,12.9061126708984,4.99269850568452,45.6900000572205,0.0734110085204661,0.0106962023776498,1,-6.66174788303946E-8,,,,,,,,,,,,,,,,,,,,,129.118041992188,129.118041992188,26.500186920166,26.500186920166,49.7545633916399,5.4009558145716,7.11803531646729,65,1,0,0,1,0.273666381835938,33.2355842590332,2,1,1,129.118041992188,0,129.118041992188,,,,,,,,,,,,,,,,,,,,,,,,,,,,,,,,,
,3865756644.37734,159.090209960938,26.500186920166,5.68136054347583E-5,6.1572732302654E-9,1,5,12.9061126708984,4.9916281959352,45.7900017499924,0.074024305342517,0.010762705777336,1,-8.43691595162978E-8,,,,,,,,,,,,,,,,,,,,,159.090209960938,159.090209960938,26.500186920166,26.500186920166,49.682262753611,5.40463908330808,7.19006061553955,64,1,64,0,0,0.277099609375,31.7693061828613,2,1,1,159.090209960938,0,159.090209960938,,,,,,,,,,,,,,,,,,,,,,,,,,,,,,,,,
,3865756825.46518,189.048324584961,26.500186920166,5.70009906957576E-5,4.99023036286371E-9,1,5,12.9061126708984,4.99046035174006,45.8999983966351,0.0742448449118557,0.0107894352403629,1,-8.86591355130402E-8,,,,,,,,,,,,,,,,,,,,,189.048324584961,189.048324584961,26.500186920166,26.500186920166,49.5747888322168,5.40874926094074,7.26871824264526,65,1,0,0,1,0.2813720703125,31.7693061828613,2,1,1,189.048324584961,0,189.048324584961,,,,,,,,,,,,,,,,,,,,,,,,,,,,,,,,,
,3865757005.82965,219.007705688477,26.500186920166,5.67732703587356E-5,8.31603570649837E-9,1,5,12.9061126708984,4.98957018013117,46.0299998521805,0.073929071411731,0.0107480894950024,1,-8.48882021467112E-8,,,,,,,,,,,,,,,,,,,,,219.007705688477,219.007705688477,26.500186920166,26.500186920166,49.9366828366207,5.41092642344614,7.36957168579102,65,1,0,0,1,0.281753540039062,32.2580642700195,2,1,1,219.007705688477,0,219.007705688477,,,,,,,,,,,,,,,,,,,,,,,,,,,,,,,,,
,3865757187.19161,249.020431518555,26.500186920166,5.62732185385683E-5,2.5330165561357E-8,1,5,12.9061126708984,4.98871683922119,46.1799986660481,0.0732632646724819,0.0106308477779943,1,-9.95192403806952E-8,,,,,,,,,,,,,,,,,,,,,249.020431518555,249.020431518555,26.500186920166,26.500186920166,49.8018519170534,5.4145485392394,7.55106830596924,65,1,0,0,1,0.27679443359375,33.2355842590332,2,1,1,249.020431518555,0,249.020431518555,,,,,,,,,,,,,,,,,,,,,,,,,,,,,,,,,
,3865757367.99586,279.034149169922,26.500186920166,5.56734046695154E-5,1.97084958188403E-8,1,5,12.9061126708984,4.98845535784122,46.339999884367,0.0724740917193576,0.01053670446473,1,-8.31342478941662E-8,,,,,,,,,,,,,,,,,,,,,279.034149169922,279.034149169922,26.500186920166,26.500186920166,49.7326777931014,5.41530769455154,7.72272634506226,64,1,64,0,0,0.278854370117187,32.7468223571777,2,1,1,279.034149169922,0,279.034149169922,,,,,,,,,,,,,,,,,,,,,,,,,,,,,,,,,
,3865757703.07338,300.006896972656,46308.013671875,0.00601721743007833,1.76177921468074E-6,1,2,12.9061126708984,4.99032030237711,46.459998935461,7.8422100158669,1.10501524867931,100,-3.53996878492984E-5,,,,,,,,,,,,,,,,,,,,,300.006713867188,300.007080078125,46208.0546875,46407.97265625,49.6029274589091,5.41023610311227,7.63121938705444,25,1,68,0,0,0.28228759765625,32.2580642700195,1,6,1,300.007080078125,0,300.006896972656,,,,,,,,,,,,,,,,,,,,,,,,,,,,,,,,,
,3865757770.70749,300.005233764648,39559.2578125,0.00521355793487723,2.11793692395859E-6,1,2,12.9061126708984,4.99046405183152,46.459998935461,6.79347122997456,0.968413231586238,100,-2.2266760726445E-5,,,,,,,,,,,,,,,,,,,,,300.004699707031,300.005767822266,39389.74609375,39728.76953125,49.6783546110149,5.40937213381804,7.66788864135742,25,1,68,0,0,0.279998779296875,32.2580642700195,1,6,1,300.004699707031,0,300.005233764648,,,,,,,,,,,,,,,,,,,,,,,,,,,,,,,,,
,3865757837.98727,300.004272460937,32834.6162109375,0.00443840660459238,2.49207679477612E-6,1,2,12.9061126708984,4.99052216066054,46.459998935461,5.78339182671774,0.825268097276331,100,-1.83226274861631E-5,,,,,,,,,,,,,,,,,,,,,300.00390625,300.004638671875,32739.802734375,32929.4296875,49.6994585810341,5.40927459130069,7.72952508926392,26,1,0,0,1,0.279617309570313,31.7693061828613,1,6,1,300.00390625,0,300.004272460937,,,,,,,,,,,,,,,,,,,,,,,,,,,,,,,,,
,3865757904.58495,300.003768920898,26191.26171875,0.00366378142271621,2.26346431329231E-6,1,2,12.9061126708984,4.99066600687822,46.459998935461,4.77405871786831,0.68237807954968,100,-1.42689279176029E-5,,,,,,,,,,,,,,,,,,,,,300.003387451172,300.004150390625,26081.2734375,26301.25,49.6990677667745,5.40830610268398,7.82787418365479,26,1,0,0,1,0.279541015625,32.2580642700195,1,6,1,300.003387451172,0,300.003768920898,,,,,,,,,,,,,,,,,,,,,,,,,,,,,,,,,
,3865757969.11287,300.002593994141,19746.6259765625,0.00290963752125029,1.88622501829691E-6,1,2,12.9061126708984,4.99068212472215,46.459998935461,3.79121372210661,0.543156816209448,100,-1.03832697017691E-5,,,,,,,,,,,,,,,,,,,,,300.002563476562,300.002624511719,19631.712890625,19861.5390625,49.7092289375245,5.40851816031102,7.95168828964233,26,1,0,0,1,0.279617309570313,31.7693061828613,1,6,1,300.002563476562,0,300.002593994141,,,,,,,,,,,,,,,,,,,,,,,,,,,,,,,,,
,3865758033.56066,300.00276184082,13312.5336914062,0.00214974907442013,1.73010110274208E-6,1,2,12.9061126708984,4.990852724323,46.459998935461,2.80156414748234,0.399014704592021,100,-9.44457214391398E-6,,,,,,,,,,,,,,,,,,,,,300.002685546875,300.002838134766,13202.62109375,13422.4462890625,49.7776214329572,5.40783166903944,8.09804534912109,25,1,68,0,0,0.277633666992187,31.7693061828613,1,6,1,300.002685546875,0,300.00276184082,,,,,,,,,,,,,,,,,,,,,,,,,,,,,,,,,
,3865758100.0838,300.001937866211,6667.4296875,0.00134573416716767,1.53100305430245E-6,1,2,12.9061126708984,4.99103828535947,46.459998935461,1.75497070507187,0.24222903120189,100,-1.17210709782088E-5,,,,,,,,,,,,,,,,,,,,,300.001892089844,300.001983642578,6597.50634765625,6737.35302734375,49.7596439770149,5.40704271180081,8.28640174865723,26,1,0,0,1,0.280075073242187,31.7693061828613,1,6,1,300.001892089844,0,300.001937866211,,,,,,,,,,,,,,,,,,,,,,,,,,,,,,,,,
,3865758166.33329,300.001190185547,46.4693489074707,9.22968571528948E-5,7.86189435010015E-6,1,2,12.9061126708984,4.99108794907262,46.459998935461,0.125901959755772,-0.0210694546885064,100,-2.97361959103658E-5,,,,,,,,,,,,,,,,,,,,,300.001098632812,300.001281738281,-48.5126419067383,141.45133972168,49.717826851236,5.40650179936884,8.48948097229004,26,1,0,0,1,0.2783203125,31.7693061828613,1,6,1,300.001098632812,0,300.001190185547,,,,,,,,,,,,,,,,,,,,,,,,,,,,,,,,,
,3865758242.87161,300.000396728516,-7605.9990234375,-0.00145333000417951,1.64271811634436E-6,1,2,12.9061126708984,4.99119050753359,46.459998935461,-1.89262319096299,-0.280286910699089,10,-1.68332830510997E-6,,,,,,,,,,,,,,,,,,,,,300.000152587891,300.000640869141,-7695.935546875,-7516.0625,49.7014126523322,5.40633470641571,8.74440097808838,26,1,0,0,1,0.27923583984375,31.7693061828613,1,6,1,300.000152587891,0,300.000396728516,,,,,,,,,,,,,,,,,,,,,,,,,,,,,,,,,
,3865758331.87386,300.000747680664,-16506.4267578125,-0.00251988395835159,2.01320890232084E-6,1,2,12.9061126708984,4.9912522239662,46.459998935461,-3.28274158190945,-0.478339573065861,10,2.95434426965622E-6,,,,,,,,,,,,,,,,,,,,,300.000457763672,300.001037597656,-16566.529296875,-16446.32421875,49.6967228812168,5.40481545186271,8.75572967529297,25,1,68,0,0,0.278701782226562,31.2805480957031,1,6,1,300.001037597656,0,300.000747680664,,,,,,,,,,,,,,,,,,,,,,,,,,,,,,,,,
,3865758412.51193,299.999893188477,-24577.212890625,-0.00346639985957624,2.02842699098723E-6,1,2,12.9061126708984,4.99111496343236,46.459998935461,-4.51639770997855,-0.652741085746353,100,8.09216333718186E-6,,,,,,,,,,,,,,,,,,,,,299.999481201172,300.000305175781,-24697.16015625,-24457.265625,49.761598048313,5.40553738905568,8.68361282348633,26,1,0,0,1,0.279617309570313,31.7693061828613,1,6,1,299.999481201172,0,299.999893188477,,,,,,,,,,,,,,,,,,,,,,,,,,,,,,,,,
,3865758478.9423,300.000732421875,-31227.2236328125,-0.00423950765457655,1.76970876955277E-6,1,2,12.9061126708984,4.99123306875001,46.459998935461,-5.52352922832837,-0.800659846811676,100,8.12187255063185E-6,,,,,,,,,,,,,,,,,,,,,300.000701904297,300.000762939453,-31287.39453125,-31167.052734375,49.580651046111,5.40499020550572,8.65216636657715,26,1,0,0,1,0.277862548828125,31.7693061828613,1,6,1,300.000701904297,0,300.000732421875,,,,,,,,,,,,,,,,,,,,,,,,,,,,,,,,,
,3865758545.06199,300.001373291016,-37849.201171875,-0.00501276276026908,3.14261991375708E-6,1,2,12.9061126708984,4.99099317161872,46.459998935461,-6.52955081009379,-0.953364006814051,100,4.43322343891959E-6,,,,,,,,,,,,,,,,,,,,,300.000915527344,300.001831054687,-37939.34375,-37759.05859375,49.8350711291207,5.40575354109423,8.62127017974854,26,1,0,0,1,0.281524658203125,31.7693061828613,1,6,1,300.001831054687,0,300.001373291016,,,,,,,,,,,,,,,,,,,,,,,,,,,,,,,,,
,3865758627.65106,299.999862670898,-46124.111328125,-0.00596640904993388,2.17361234803186E-6,1,2,12.9061126708984,4.99117591021671,46.459998935461,-7.77213196334168,-1.1349549193737,100,5.15287523183606E-6,,,,,,,,,,,,,,,,,,,,,299.999847412109,299.999877929687,-46214.19921875,-46034.0234375,49.6455262132072,5.40479627465714,8.59840488433838,26,1,0,0,1,0.276031494140625,31.7693061828613,1,6,1,299.999847412109,0,299.999862670898,,,,,,,,,,,,,,,,,,,,,,,,,,,,,,,,,
,3865758704.3317,300.000396728516,-46747.583984375,-0.00605682983301296,2.36933858539204E-6,1,2,12.9061126708984,4.99123522741059,46.459998935461,-7.89653424919093,-1.10803700197887,100,3.91174812596598E-5,,,,,,,,,,,,,,,,,,,,,299.999969482422,300.000823974609,-46847.203125,-46647.96484375,49.6470894702456,5.40472910229765,8.56568145751953,24,1,68,0,0,0.276870727539062,32.2580642700195,1,6,1,300.000823974609,0,300.000396728516,,,,,,,,,,,,,,,,,,,,,,,,,,,,,,,,,
,3865758770.822,300.000045776367,-40110.31640625,-0.00528199032944125,2.09457972115683E-6,1,2,12.9061126708984,4.99121881768341,46.459998935461,-6.88462242410693,-0.977789844416948,100,2.52790699971048E-5,,,,,,,,,,,,,,,,,,,,,300,300.000091552734,-40190.1171875,-40030.515625,49.7021942808514,5.40523695247197,8.54446506500244,25,1,68,0,0,0.279083251953125,31.7693061828613,1,6,1,300,0,300.000045776367,,,,,,,,,,,,,,,,,,,,,,,,,,,,,,,,,
,3865758837.50545,300.000106811523,-33453.005859375,-0.00450940613173823,2.3606474509754E-6,1,2,12.9061126708984,4.99096513421127,46.459998935461,-5.87645885140527,-0.839796318972577,100,1.7677244138096E-5,,,,,,,,,,,,,,,,,,,,,299.999938964844,300.000274658203,-33512.89453125,-33393.1171875,49.7803571327745,5.40607095196986,8.52904510498047,26,1,0,0,1,0.27862548828125,31.7693061828613,1,6,1,300.000274658203,0,300.000106811523,,,,,,,,,,,,,,,,,,,,,,,,,,,,,,,,,
,3865758903.64069,300.000457763672,-26855.4892578125,-0.00373616206487143,1.74884299317608E-6,1,2,12.9061126708984,4.99105314970041,46.459998935461,-4.86901680772904,-0.695164036741827,100,1.51425226089271E-5,,,,,,,,,,,,,,,,,,,,,300.000427246094,300.00048828125,-26945.275390625,-26765.703125,49.7522185060822,5.40547601041662,8.51301288604736,26,1,0,0,1,0.276565551757813,31.7693061828613,1,6,1,300.000427246094,0,300.000457763672,,,,,,,,,,,,,,,,,,,,,,,,,,,,,,,,,
,3865758970.15731,299.999206542969,-20211.8837890625,-0.00295935926994152,1.85960946510114E-6,1,2,12.9061126708984,4.99105830370754,46.459998935461,-3.85651497133951,-0.551770485356812,100,1.11185584013288E-5,,,,,,,,,,,,,,,,,,,,,299.998962402344,299.999450683594,-20306.765625,-20117.001953125,49.809277387986,5.40557831779594,8.49265956878662,26,1,0,0,1,0.278701782226562,31.7693061828613,1,6,1,299.999450683594,0,299.999206542969,,,,,,,,,,,,,,,,,,,,,,,,,,,,,,,,,
,3865759034.63855,300.000137329102,-13778.6879882812,-0.00220327891101782,1.79299719907344E-6,1,2,12.9061126708984,4.99099706464152,46.459998935461,-2.87149646996286,-0.408589554660754,100,9.96952498679464E-6,,,,,,,,,,,,,,,,,,,,,300,300.000274658203,-13878.4150390625,-13678.9609375,49.5712715038802,5.40669058071132,8.48757648468018,26,1,0,0,1,0.27923583984375,33.7243423461914,1,6,1,300,0,300.000137329102,,,,,,,,,,,,,,,,,,,,,,,,,,,,,,,,,
,3865759103.41843,300.001037597656,-6904.83447265625,-0.00137553135146401,1.77065991879436E-6,1,2,12.9061126708984,4.99130164024747,46.459998935461,-1.79364693713383,-0.249755283434636,100,1.03341872032466E-5,,,,,,,,,,,,,,,,,,,,,300.000854492188,300.001220703125,-6974.8896484375,-6834.779296875,49.863209755813,5.40581329821425,8.46728134155273,24,1,68,0,0,0.276870727539062,31.7693061828613,1,6,1,300.000854492188,0,300.001037597656,,,,,,,,,,,,,,,,,,,,,,,,,,,,,,,,,
,3865759169.59322,300.000564575195,-295.09349822998,-0.000242719603506785,5.42328896119309E-6,1,2,12.9061126708984,4.9911192443043,46.459998935461,-0.322059970126106,-0.00610017060049274,100,3.09745997115552E-5,,,,,,,,,,,,,,,,,,,,,300.000427246094,300.000701904297,-390.019073486328,-200.167922973633,49.8213926300341,5.40553376986936,8.46067237854004,26,1,0,0,1,0.279769897460938,32.2580642700195,1,6,1,300.000701904297,0,300.000564575195,,,,,,,,,,,,,,,,,,,,,,,,,,,,,,,,,
,3865759234.0761,300.000259399414,6153.2021484375,0.00127295473304937,2.35528852692739E-6,1,2,12.9061126708984,4.99114712960801,46.459998935461,1.65735208147319,0.247907989684008,100,3.32547181699213E-6,,,,,,,,,,,,,,,,,,,,,300.000213623047,300.000305175781,6058.2890625,6248.115234375,49.6506067985822,5.40606946044233,8.44710636138916,26,1,0,0,1,0.279464721679687,32.7468223571777,1,6,1,300.000305175781,0,300.000259399414,,,,,,,,,,,,,,,,,,,,,,,,,,,,,,,,,
,3865759333.93125,299.999725341797,16139.455078125,0.0024648063928854,1.77108894101441E-6,1,2,12.9061126708984,4.99106516882988,46.459998935461,3.21093633429394,0.467076538779014,10,-3.49116153667335E-6,,,,,,,,,,,,,,,,,,,,,299.999725341797,299.999725341797,16139.455078125,16139.455078125,49.7326777931014,5.40635300621218,8.43024253845215,25,1,68,0,0,0.276412963867187,33.7243423461914,1,6,1,299.999725341797,0,299.999725341797,,,,,,,,,,,,,,,,,,,,,,,,,,,,,,,,,
,3865759429.49867,300.000686645508,25696.6396484375,0.00359943132499885,2.36124709437685E-6,1,2,12.9061126708984,4.99101910525905,46.459998935461,4.68949510730574,0.678480559831667,100,-7.85971518682929E-6,,,,,,,,,,,,,,,,,,,,,300.000640869141,300.000732421875,25601.501953125,25791.77734375,49.8253007726303,5.40616868051941,8.42179393768311,26,1,0,0,1,0.278244018554687,32.2580642700195,1,6,1,300.000640869141,0,300.000686645508,,,,,,,,,,,,,,,,,,,,,,,,,,,,,,,,,
,3865759498.34041,300.000183105469,32594.830078125,0.00439590459286604,2.38238899558386E-6,1,2,12.9061126708984,4.99060220162037,46.459998935461,5.72672599028155,0.827003245354435,100,-1.07604786255585E-5,,,,,,,,,,,,,,,,,,,,,300.000152587891,300.000213623047,32544.5625,32645.09765625,49.6849984534283,5.40771283480523,8.42250728607178,26,1,0,0,1,0.280838012695313,31.7693061828613,1,6,1,300.000152587891,0,300.000183105469,,,,,,,,,,,,,,,,,,,,,,,,,,,,,,,,,
,3865759562.41669,300.001174926758,39018.931640625,0.00514225411469656,1.95957283193431E-6,1,2,12.9061126708984,4.99070371277167,46.459998935461,6.6985361531303,0.972079394211303,100,-9.02643560200494E-6,,,,,,,,,,,,,,,,,,,,,300.001037597656,300.001312255859,38928.625,39109.23828125,49.5982376877937,5.40707016135734,8.40646839141846,26,1,0,0,1,0.280227661132813,31.7693061828613,1,6,1,300.001037597656,0,300.001174926758,,,,,,,,,,,,,,,,,,,,,,,,,,,,,,,,,
,3865759638.97833,300.001266479492,46689.48828125,0.00602975620094924,2.07680369537965E-6,1,2,12.9061126708984,4.99094637620563,46.459998935461,7.85474445253943,1.14284529777529,100,-8.3446954407654E-6,,,,,,,,,,,,,,,,,,,,,300.0009765625,300.001556396484,46594.32421875,46784.65234375,49.6220773576303,5.40600335436329,8.39585494995117,26,1,0,0,1,0.279617309570313,31.7693061828613,1,6,1,300.001556396484,0,300.001266479492,,,,,,,,,,,,,,,,,,,,,,,,,,,,,,,,,
,3865759675.2844,300.000213623047,50000.494140625,0.0064120833190193,6.91566357470024E-7,1,2,12.9061126708984,4.99110527588819,46.459998935461,8.35247520811559,1.22003331231097,100,-5.28854794139451E-6,,,,,,,,,,,,,,,,,,,,,300,300.000427246094,50000.48828125,50000.5,49.5661909185052,5.40540804820301,8.39809894561768,26,1,0,0,1,0.27862548828125,31.7693061828613,1,4,1,300.000427246094,0,300.000213623047,,,,,,,,,,,,,,,,,,,,,,,,,,,,,,,,,