File: LT data/Frome/M1/304-FC-ZFC-RTSIRM-contsweepwithloop-MsT.dat
[Header]
; MPMS3 Data File (default extension .dat)
; Copyright (c) 2007, Quantum Design, Inc. All rights reserved.
TITLE,
FILEOPENTIME,3866254327.33062,07/06/2022,8:29 am
BYAPP,MPMS3 w/ AC,1.0,1.1
INFO,MPMS3 Measurement Release 1.1.16 Build 424, MultiVu Release 2.3.4.19,APPNAME
INFO,Linear Motor Servo Controller,MOTOR_MODULE_NAME
INFO,3101-100 N2,MOTOR_HW_VERSION
INFO,,MOTOR_SERIAL_NUMBER
INFO,01.04.28,MOTOR_SOFTWARE_VERSION
INFO,Quantum Design Squid Module,SQUID_MODULE_NAME
INFO,3101-501 B0,SQUID_HW_VERSION
INFO,SQM327,SQUID_SERIAL_NUMBER
INFO,01.03.04,SQUID_SOFTWARE_VERSION
INFO,Quantum Design VSM Oven,OVEN_MODULE_NAME
INFO,3101-201 A3,OVEN_HW_VERSION
INFO,OVB365,OVEN_SERIAL_NUMBER
INFO,01.07.07,OVEN_SOFTWARE_VERSION
INFO,SQUID AC,AC_MODULE_NAME
INFO,3101-401 G0,AC_HW_VERSION
INFO,SAC220,AC_SERIAL_NUMBER
INFO,SQUID AC 00.95.07,AC_SOFTWARE_VERSION
INFO,TCI344,COIL_SERIAL_NUMBER
INFO,0,MOMENT_UNITS
INFO,lmst,SAMPLE_MATERIAL
INFO,,SAMPLE_COMMENT
INFO,130.62,SAMPLE_MASS
INFO,,SAMPLE_VOLUME
INFO,,SAMPLE_MOLECULAR_WEIGHT
INFO,,SAMPLE_SIZE
INFO,,SAMPLE_SHAPE
INFO,Straw,SAMPLE_HOLDER
INFO,Standard,SAMPLE_HOLDER_DETAIL
INFO,61.24,SAMPLE_OFFSET
DATATYPE,COMMENT,1
DATATYPE,TIME,2
STARTUPAXIS,X,2
STARTUPAXIS,Y1,5
FIELDGROUP, VSM,2,3,4,5,6,8,9,10,11,14,15
FIELDGROUP, DC, 2,3,4,14,56,57,58,59,60,61,62,63,64,65,66,67,68,69
FIELDGROUP, AC, 2,3,4,11,16,17,18,19,20,21,22,23,24,25,26,27,28,29,30
STARTUPGROUP, All
[Data]
Comment,Time Stamp (sec),Temperature (K),Magnetic Field (Oe),Moment (emu),M. Std. Err. (emu),Transport Action,Averaging Time (sec),Frequency (Hz),Peak Amplitude (mm),Center Position (mm),Lockin Signal' (V),Lockin Signal (V),Range,M. Quad. Signal (emu),AC Moment (emu),AC M. Std Err. (emu),AC Phase (deg),AC Phase Std. Err. (deg),AC Susceptibility (emu/Oe),AC Suscept. Std Err. (emu/Oe),AC X' (emu/Oe),AC X' Std Err. (emu/Oe),AC X'' (emu/Oe),AC X'' Std Err. (emu/Oe),AC Drive (Oe),AC Frequency (Hz),AC Averaging Time (sec),AC Cycles,AC Range,AC Measure Type,AC Signal' (V),AC Signal'' (V),AC Trim Coil Ratio,AC Trim Coil Phase,Min. Temperature (K),Max. Temperature (K),Min. Field (Oe),Max. Field (Oe),Mass (grams),Motor Lag (deg),Pressure (Torr),Measure Count,Measurement Number,SQUID Status (code),Motor Status (code),Measure Status (code),Motor Current (amps),Motor Temp. (C),Temp. Status (code),Field Status (code),Chamber Status (code),Chamber Temp (K),Redirection State,Average Temp (K),Rotation Angle (deg),Rotator state,DC Moment Fixed Ctr (emu),DC Moment Err Fixed Ctr (emu),DC Moment Free Ctr (emu),DC Moment Err Free Ctr (emu),DC Fixed Fit,DC Free Fit,DC Calculated Center (mm),DC Calculated Center Err (mm),DC Scan Length (mm),DC Scan Time (s),DC Number of Points,DC Squid Drift,DC Min V (V),DC Max V (V),DC Scans per Measure,Map 01,Map 02,Map 03,Map 04,Map 05,Map 06,Map 07,Map 08,Map 09,Map 10,Map 11,Map 12,Map 13,Map 14,Map 15,Map 16
,3866255328.14406,100.002426147461,49999.76171875,0.0445566925700302,0.00345641204502353,1,2,12.9061126708984,4.97758242322982,34.0799987316132,58.5719037920793,3.32351194417055,1000,-0.00398439700077436,,,,,,,,,,,,,,,,,,,,,100.002426147461,100.002426147461,49999.76171875,49999.76171875,49.5872948885245,5.37090019950702,7.40469026565552,26,1,0,0,1,0.26611328125,29.8142719268799,1,1,1,100.002426147461,0,100.002426147461,,,,,,,,,,,,,,,,,,,,,,,,,,,,,,,,,
,3866255427.7356,86.713264465332,49999.76171875,0.0345951145148485,0.00417170028409219,1,2,12.9061126708984,4.98536900639555,34.0400002896786,44.4975781467168,9.93334406745211,1000,0.00255653978046147,,,,,,,,,,,,,,,,,,,,,86.5401000976563,86.8864288330078,49999.76171875,49999.76171875,49.7647245623899,5.37908798786644,7.33523273468018,24,1,68,0,0,0.264968872070313,29.8142719268799,2,1,1,86.5401000976563,0,86.713264465332,,,,,,,,,,,,,,,,,,,,,,,,,,,,,,,,,
,3866255510.78927,72.9243392944336,49999.76171875,0.0441051346650545,0.00367829653156552,1,2,12.9061126708984,4.98601696984639,33.9899994432926,60.0144245325352,-9.62159750173163,1000,-0.013877378449693,,,,,,,,,,,,,,,,,,,,,72.8513870239258,72.9972915649414,49999.76171875,49999.76171875,49.7049299806687,5.38235403473375,7.26841354370117,24,1,64,0,0,0.277862548828125,30.7917900085449,2,1,1,72.8513870239258,0,72.9243392944336,,,,,,,,,,,,,,,,,,,,,,,,,,,,,,,,,
,3866255590.92111,59.3054428100586,49999.76171875,0.0583030930594557,0.00269271781110129,1,2,12.9061126708984,4.9867263089746,33.9699983596802,77.0153004414093,3.1679035307468,1000,-0.00613011268497549,,,,,,,,,,,,,,,,,,,,,59.1650085449219,59.4458770751953,49999.76171875,49999.76171875,49.6509976128418,5.37487465896623,7.18128967285156,26,1,0,0,1,0.285797119140625,30.7917900085449,2,1,1,59.1650085449219,0,59.3054428100586,,,,,,,,,,,,,,,,,,,,,,,,,,,,,,,,,
,3866255667.46117,46.334888458252,49999.76171875,0.0674454764862186,0.00326259615981201,1,2,12.9061126708984,4.98694809238185,33.9399985969067,90.0317120850199,-2.69436246846561,1000,-0.0119795766400937,,,,,,,,,,,,,,,,,,,,,46.1921539306641,46.4776229858398,49999.76171875,49999.76171875,49.741275706813,5.37517108392404,7.02895593643188,25,1,68,0,0,0.273895263671875,30.7917900085449,2,1,1,46.1921539306641,0,46.334888458252,,,,,,,,,,,,,,,,,,,,,,,,,,,,,,,,,
,3866255748.05442,32.603063583374,49999.76171875,0.0601639117482522,0.0075015320150447,1,2,12.9061126708984,4.98708470213084,33.9000001549721,80.3993677593858,-2.97936911853323,1000,-0.0111288253227025,,,,,,,,,,,,,,,,,,,,,32.4221076965332,32.7840194702148,49999.76171875,49999.76171875,49.7744949188803,5.3744243258828,6.77614688873291,26,1,0,0,1,0.2825927734375,30.7917900085449,2,1,1,32.4221076965332,0,32.603063583374,,,,,,,,,,,,,,,,,,,,,,,,,,,,,,,,,
,3866255828.82048,19.1324167251587,49999.76171875,0.0802743961804761,0.00664259391118226,1,2,12.9061126708984,4.98262640311129,33.890001475811,106.976537799903,-2.86372890813574,1000,-0.0139971562428687,,,,,,,,,,,,,,,,,,,,,18.8944778442383,19.3703556060791,49999.76171875,49999.76171875,49.9515337784861,5.39192153814102,6.21197509765625,26,1,0,0,1,0.273284912109375,31.2805480957031,2,1,1,18.8944778442383,0,19.1324167251587,,,,,,,,,,,,,,,,,,,,,,,,,,,,,,,,,
,3866255908.56201,7.30437040328979,49999.76171875,0.117785510364093,0.00848461524234706,1,2,12.9061126708984,4.97970890754427,33.8600017130375,154.597425518642,11.039262387826,1000,-0.00880100336838635,,,,,,,,,,,,,,,,,,,,,7.06154108047485,7.54719972610474,49999.76171875,49999.76171875,50.4005793627842,5.40286608073277,4.52909851074219,24,1,68,0,0,0.270919799804687,30.7917900085449,6,1,1,7.06154108047485,0,7.30437040328979,,,,,,,,,,,,,,,,,,,,,,,,,,,,,,,,,
,3866255987.77791,4.33232164382935,49999.76171875,0.103106057251695,0.0100176708135321,1,2,12.9061126708984,4.98021040497765,33.8600017130375,138.159159011992,-9.4613507595442,1000,-0.022433970855666,,,,,,,,,,,,,,,,,,,,,4.32134199142456,4.34330129623413,49999.76171875,49999.76171875,50.4920298995342,5.4006542178122,3.8952476978302,24,1,68,0,0,0.272369384765625,31.2805480957031,6,1,1,4.32134199142456,0,4.33232164382935,,,,,,,,,,,,,,,,,,,,,,,,,,,,,,,,,
,3866256070.39592,4.0210382938385,49999.76171875,0.125423302768269,0.0131032847684957,1,2,12.9061126708984,4.98232918651178,33.8600017130375,164.30456094654,14.7554416024747,1000,-0.00706909783399638,,,,,,,,,,,,,,,,,,,,,4.01675319671631,4.02532339096069,49999.76171875,49999.76171875,50.5678478658996,5.39171435020672,3.72212791442871,22,1,68,0,0,0.276031494140625,31.2805480957031,6,1,1,4.01675319671631,0,4.0210382938385,,,,,,,,,,,,,,,,,,,,,,,,,,,,,,,,,
,3866256149.18973,4.04757356643677,49999.76171875,0.125900683779878,0.00729360114388958,1,2,12.9061126708984,4.98205878027017,33.8600017130375,166.91235030205,1.2308165265693,1000,-0.0175487829518112,,,,,,,,,,,,,,,,,,,,,4.04752588272095,4.04762125015259,49999.76171875,49999.76171875,50.5760549653515,5.39418979831128,3.72385239601135,24,1,68,0,0,0.272216796875,31.2805480957031,6,1,1,4.04762125015259,0,4.04757356643677,,,,,,,,,,,,,,,,,,,,,,,,,,,,,,,,,
,3866256229.5306,2.82303333282471,49999.76171875,0.115416409459355,0.0106418053710179,1,2,12.9061126708984,4.98374392760527,33.8600017130375,153.639684749044,-2.64272659396463,1000,-0.0189891753862143,,,,,,,,,,,,,,,,,,,,,2.81337475776672,2.83269190788269,49999.76171875,49999.76171875,50.6620341024669,5.38895996091639,3.18909072875977,24,1,68,0,0,0.272750854492187,31.2805480957031,6,1,1,2.81337475776672,0,2.82303333282471,,,,,,,,,,,,,,,,,,,,,,,,,,,,,,,,,
,3866256310.2518,2.74001622200012,49999.76171875,0.130522980837761,0.00886775596073957,1,2,12.9061126708984,4.98269294866521,33.8600017130375,172.21923577879,7.07609609839102,1000,-0.0137294889600328,,,,,,,,,,,,,,,,,,,,,2.73895168304443,2.74108076095581,49999.76171875,49999.76171875,50.7734161664573,5.39255978172227,3.1264796257019,24,1,68,0,0,0.272140502929687,30.7917900085449,6,1,1,2.73895168304443,0,2.74001622200012,,,,,,,,,,,,,,,,,,,,,,,,,,,,,,,,,
,3866256390.75355,2.79783248901367,49999.76171875,0.141617262774724,0.00766924732987828,1,2,12.9061126708984,4.98171648617355,33.8600017130375,184.539914098544,23.1015724798254,1000,-0.00302124952271994,,,,,,,,,,,,,,,,,,,,,2.79451417922974,2.80115079879761,49999.76171875,49999.76171875,50.6143547627938,5.3955510162714,3.15235018730164,24,1,68,0,0,0.27740478515625,29.8142719268799,6,1,1,2.80115079879761,0,2.79783248901367,,,,,,,,,,,,,,,,,,,,,,,,,,,,,,,,,
,3866256469.48975,2.80215179920197,49999.76171875,0.150073151705605,0.0102178670463882,1,2,12.9061126708984,4.9816588018567,33.8600017130375,196.071097206771,20.9710219156194,1000,-0.00590337374725417,,,,,,,,,,,,,,,,,,,,,2.79178619384766,2.81251740455627,49999.76171875,49999.76171875,50.686264586563,5.39756650766263,3.16527605056763,22,1,68,0,0,0.275726318359375,31.2805480957031,6,1,1,2.79178619384766,0,2.80215179920197,,,,,,,,,,,,,,,,,,,,,,,,,,,,,,,,,
,3866256551.86299,2.79894912242889,49999.76171875,0.127411760793974,0.00807542113380835,1,2,12.9061126708984,4.98160503241977,33.8600017130375,169.421548461443,-2.34529063569403,1000,-0.0205236736953044,,,,,,,,,,,,,,,,,,,,,2.79437780380249,2.8035204410553,49999.76171875,49999.76171875,50.5025818845438,5.39848396182549,3.17502856254578,24,1,68,0,0,0.275421142578125,31.2805480957031,6,1,1,2.79437780380249,0,2.79894912242889,,,,,,,,,,,,,,,,,,,,,,,,,,,,,,,,,
,3866256633.73921,2.71976780891418,49999.76171875,0.128779716483054,0.00973501145961133,1,2,12.9061126708984,4.98214222709354,33.8600017130375,169.030812243682,12.8471254907424,1000,-0.00903046180503971,,,,,,,,,,,,,,,,,,,,,2.71903824806213,2.72049736976624,49999.76171875,49999.76171875,50.7128399562169,5.39536949566332,3.12217116355896,22,1,68,0,0,0.273208618164062,31.2805480957031,6,1,1,2.72049736976624,0,2.71976780891418,,,,,,,,,,,,,,,,,,,,,,,,,,,,,,,,,
,3866256713.01214,2.85929775238037,49999.76171875,0.13573498619731,0.00994928467353834,1,2,12.9061126708984,4.98035347250103,33.8600017130375,178.002446084793,13.9946415433299,1000,-0.00916356228082187,,,,,,,,,,,,,,,,,,,,,2.85904359817505,2.85955190658569,49999.76171875,49999.76171875,50.6163088340919,5.40273471351515,3.21325159072876,24,1,68,0,0,0.272369384765625,31.2805480957031,6,1,1,2.85955190658569,0,2.85929775238037,,,,,,,,,,,,,,,,,,,,,,,,,,,,,,,,,
,3866256793.58008,2.78757476806641,49999.76171875,0.137456810782125,0.00893948695435154,1,2,12.9061126708984,4.98058223748615,33.8600017130375,180.313151103397,13.8935334773042,1000,-0.00949507226980671,,,,,,,,,,,,,,,,,,,,,2.78746318817139,2.78768634796143,49999.76171875,49999.76171875,50.7917844366592,5.40073159893745,3.16841959953308,24,1,68,0,0,0.276718139648438,31.2805480957031,6,1,1,2.78768634796143,0,2.78757476806641,,,,,,,,,,,,,,,,,,,,,,,,,,,,,,,,,
,3866256876.32831,2.71532583236694,49999.76171875,0.124465333933324,0.0107872850909808,1,2,12.9061126708984,4.98058374921269,33.8600017130375,165.274170835244,-1.05311264159941,1000,-0.0190962790723425,,,,,,,,,,,,,,,,,,,,,2.71377921104431,2.71687245368958,49999.76171875,49999.76171875,50.6655514308034,5.40231405673212,3.12679886817932,25,1,68,0,0,0.277252197265625,31.2805480957031,6,1,1,2.71377921104431,0,2.71532583236694,,,,,,,,,,,,,,,,,,,,,,,,,,,,,,,,,
,3866256956.82107,2.63284146785736,49999.76171875,0.120697760612334,0.0104941152203376,1,2,12.9061126708984,4.98028468654915,33.8600017130375,158.71417658835,9.48593241317559,1000,-0.0104264829599926,,,,,,,,,,,,,,,,,,,,,2.62795162200928,2.63773131370544,49999.76171875,49999.76171875,50.6968165715727,5.40345632354197,3.08167099952698,24,1,68,0,0,0.269775390625,31.2805480957031,6,1,1,2.63773131370544,0,2.63284146785736,,,,,,,,,,,,,,,,,,,,,,,,,,,,,,,,,
,3866257035.5311,2.62866747379303,49999.76171875,0.125648052474575,0.0117147152097102,1,2,12.9061126708984,4.98051682333433,33.8600017130375,165.647117201362,7.06700839540993,1000,-0.0130169620322547,,,,,,,,,,,,,,,,,,,,,2.62801265716553,2.62932229042053,49999.76171875,49999.76171875,50.7245643840054,5.40291238305686,3.08129143714905,24,1,68,0,0,0.274887084960938,31.7693061828613,6,1,1,2.62801265716553,0,2.62866747379303,,,,,,,,,,,,,,,,,,,,,,,,,,,,,,,,,
,3866257115.92722,2.58614134788513,49999.76171875,0.128676089620921,0.0123229768995279,1,2,12.9061126708984,4.98046300250791,33.8600017130375,167.804341616444,19.7086222269392,1000,-0.00372661669591245,,,,,,,,,,,,,,,,,,,,,2.58511400222778,2.58716869354248,49999.76171875,49999.76171875,50.7753702377554,5.40341519198974,3.04834461212158,22,1,68,0,0,0.273056030273438,31.2805480957031,6,1,1,2.58716869354248,0,2.58614134788513,,,,,,,,,,,,,,,,,,,,,,,,,,,,,,,,,
,3866257194.71772,2.53810000419617,49999.76171875,0.127638522216476,0.0104085325780429,1,2,12.9061126708984,4.98050756051562,33.8600017130375,168.180967695554,7.79039859228223,1000,-0.0127523048295436,,,,,,,,,,,,,,,,,,,,,2.5375292301178,2.53867077827454,49999.76171875,49999.76171875,50.8433719189285,5.40277610155876,3.02158379554749,25,1,68,0,0,0.277481079101562,30.7917900085449,6,1,1,2.53867077827454,0,2.53810000419617,,,,,,,,,,,,,,,,,,,,,,,,,,,,,,,,,
,3866257275.06359,2.45889115333557,49999.76171875,0.112528641916015,0.0117276337388447,1,2,12.9061126708984,4.98084381343423,33.8600017130375,148.50881937792,5.3503248760629,1000,-0.0124119289660963,,,,,,,,,,,,,,,,,,,,,2.45808124542236,2.45970106124878,49999.76171875,49999.76171875,50.7214378699284,5.40207935684608,2.96531701087952,23,1,68,0,0,0.277938842773438,31.2805480957031,6,1,1,2.45970106124878,0,2.45889115333557,,,,,,,,,,,,,,,,,,,,,,,,,,,,,,,,,
,3866257355.7508,2.44215953350067,49999.76171875,0.114911587228243,0.0122413153411911,1,2,12.9061126708984,4.9809700532225,33.8600017130375,151.440261697519,6.95339559926188,1000,-0.0115278328012086,,,,,,,,,,,,,,,,,,,,,2.43867373466492,2.44564533233643,49999.76171875,49999.76171875,50.7999915361111,5.40129673776144,2.94903469085693,25,1,68,0,0,0.276565551757813,31.2805480957031,6,1,1,2.44564533233643,0,2.44215953350067,,,,,,,,,,,,,,,,,,,,,,,,,,,,,,,,,
,3866257436.21117,2.0874410867691,49999.76171875,0.119191220840688,0.0113313015427481,1,2,12.9061126708984,4.98075680579672,33.8600017130375,157.189781513411,6.40253402756863,1000,-0.0125804105425526,,,,,,,,,,,,,,,,,,,,,2.06253743171692,2.11234474182129,49999.76171875,49999.76171875,50.7671631383034,5.40239060656184,2.74803733825684,26,1,0,0,1,0.273590087890625,31.2805480957031,2,1,1,2.06253743171692,0,2.0874410867691,,,,,,,,,,,,,,,,,,,,,,,,,,,,,,,,,
,3866257970.92385,8.29337501525879,26.5127239227295,0.000131252086988384,4.58688154957672E-7,1,5,12.9061126708984,5.01160804591997,33.8600017130375,0.171843485286683,0.0258774994700842,10,4.72124050306798E-7,,,,,,,,,,,,,,,,,,,,,7.92502689361572,8.66172313690186,26.5127239227295,26.5127239227295,49.9257400373514,5.39789239750502,4.58814096450806,65,1,0,0,1,0.281143188476562,30.7917900085449,6,1,1,8.66172313690186,0,8.29337501525879,,,,,,,,,,,,,,,,,,,,,,,,,,,,,,,,,
,3866258202.91205,44.0344924926758,26.5127239227295,1.72652332875439E-5,9.69538679762147E-9,1,5,12.9061126708984,5.01074444188216,33.8799990713596,0.0226101371294402,0.00332930508876511,1,5.70168855516706E-9,,,,,,,,,,,,,,,,,,,,,44.0344924926758,44.0344924926758,26.5127239227295,26.5127239227295,49.7944264461207,5.4010168701954,6.51284885406494,65,1,0,0,1,0.277786254882813,31.2805480957031,2,1,1,44.0344924926758,0,44.0344924926758,,,,,,,,,,,,,,,,,,,,,,,,,,,,,,,,,
,3866258436.24913,81.0258407592773,26.5127239227295,1.26427807615914E-5,6.31485175089175E-9,1,5,12.9061126708984,5.0114023501234,33.9299999177456,0.0165602377234917,0.00243488149701392,1,1.49550312582397E-9,,,,,,,,,,,,,,,,,,,,,81.0258407592773,81.0258407592773,26.5127239227295,26.5127239227295,50.0058569605726,5.39832920584456,6.94025707244873,65,1,0,0,1,0.276947021484375,31.2805480957031,2,1,1,81.0258407592773,0,81.0258407592773,,,,,,,,,,,,,,,,,,,,,,,,,,,,,,,,,
,3866258661.38025,118.03929901123,26.5127239227295,1.05531457443849E-5,7.14587120575068E-9,1,5,12.9061126708984,5.01180424010138,34.0100005269051,0.0138227664897025,0.00204557701215127,1,1.11045499111901E-8,,,,,,,,,,,,,,,,,,,,,118.029838562012,118.048759460449,26.5127239227295,26.5127239227295,49.9949141613034,5.39740702620067,7.11111259460449,63,1,64,0,0,0.279388427734375,31.2805480957031,2,1,1,118.048759460449,0,118.03929901123,,,,,,,,,,,,,,,,,,,,,,,,,,,,,,,,,
,3866258884.78445,155.058059692383,26.5127239227295,8.95045146759692E-6,6.55990125393369E-9,1,5,12.9061126708984,5.00508232766386,34.120000898838,0.011701221492706,0.00173381397309618,1,1.10618939471568E-8,,,,,,,,,,,,,,,,,,,,,155.058059692383,155.058059692383,26.5127239227295,26.5127239227295,50.0031212607553,5.38530154818573,7.21689224243164,64,1,64,0,0,0.274658203125,31.2805480957031,2,1,1,155.058059692383,0,155.058059692383,,,,,,,,,,,,,,,,,,,,,,,,,,,,,,,,,
,3866259108.15056,192.033294677734,26.5127239227295,7.8613083669845E-6,6.36260963912721E-9,1,5,12.9061126708984,5.00647382054493,34.2600010335445,0.0102824174687552,0.0015161351977288,1,4.14234295806953E-9,,,,,,,,,,,,,,,,,,,,,192.033294677734,192.033294677734,26.5127239227295,26.5127239227295,50.0277425591111,5.38043211422629,7.30409097671509,64,1,64,0,0,0.287094116210938,30.7917900085449,2,1,1,192.033294677734,0,192.033294677734,,,,,,,,,,,,,,,,,,,,,,,,,,,,,,,,,
,3866259331.05267,229.031829833984,26.5127239227295,6.98105012579731E-6,7.55944281841345E-9,1,5,12.9061126708984,5.00703095891856,34.4199985265732,0.00913150983325861,0.00135318546054938,1,8.72913632338331E-9,,,,,,,,,,,,,,,,,,,,,229.031829833984,229.031829833984,26.5127239227295,26.5127239227295,49.9366828366207,5.37957407219765,7.47986364364624,64,1,64,0,0,0.279083251953125,31.7693061828613,2,1,1,229.031829833984,0,229.031829833984,,,,,,,,,,,,,,,,,,,,,,,,,,,,,,,,,
,3866259554.14907,266.026428222656,26.5127239227295,6.24641738425276E-6,6.70383868770676E-9,1,5,12.9061126708984,5.00781019503717,34.6099995076656,0.00817235598476303,0.00121106062360177,1,7.8186319105032E-9,,,,,,,,,,,,,,,,,,,,,266.026428222656,266.026428222656,26.5127239227295,26.5127239227295,49.8585199846976,5.37479903934704,7.86231470108032,64,1,64,0,0,0.277328491210938,30.7917900085449,2,1,1,266.026428222656,0,266.026428222656,,,,,,,,,,,,,,,,,,,,,,,,,,,,,,,,,
,3866262202.74195,1.9994255900383,49841.25,0.159318662367026,0.00898945432703183,1,2,12.9061126708984,5.0018600695943,33.8700003921986,210.695642861663,13.131331530226,1000,-0.0133540580084047,,,,,,,,,,,,,,,,,,,,,1.99927055835724,1.99958062171936,49682.48828125,50000.01171875,50.6065384776015,5.40234216557236,2.66276693344116,24,1,68,0,0,0.284423828125,31.2805480957031,1,6,1,1.99927055835724,0,1.9994255900383,,,,,,,,,,,,,,,,,,,,,,,,,,,,,,,,,
,3866262292.14869,1.99929738044739,40926.927734375,0.142563993939332,0.00969324847494813,1,2,12.9061126708984,5.00208454561319,33.8700003921986,189.676604954914,4.0810419479113,1000,-0.017820506214883,,,,,,,,,,,,,,,,,,,,,1.99851059913635,2.00008416175842,40837.10546875,41016.75,50.3775213214669,5.4022649652473,2.65168857574463,26,1,0,0,1,0.281753540039062,31.2805480957031,1,6,1,1.99851059913635,0,1.99929738044739,,,,,,,,,,,,,,,,,,,,,,,,,,,,,,,,,
,3866262374.7217,2.00099384784698,32684.4599609375,0.133010189754242,0.00960893202259742,1,2,12.9061126708984,5.00198724485016,33.8700003921986,176.53071572673,6.73476218819171,1000,-0.0143856002403775,,,,,,,,,,,,,,,,,,,,,2.00085592269897,2.001131772995,32589.603515625,32779.31640625,50.1868039627745,5.40028349795079,2.64046263694763,24,1,68,0,0,0.279006958007813,30.7917900085449,1,6,1,2.001131772995,0,2.00099384784698,,,,,,,,,,,,,,,,,,,,,,,,,,,,,,,,,
,3866262455.44321,2.00005602836609,24623.4443359375,0.0966517441018855,0.0106748938548258,1,2,12.9061126708984,5.00206748107115,33.8700003921986,127.387312879885,10.9619914245968,1000,-0.00580864636713931,,,,,,,,,,,,,,,,,,,,,1.99961876869202,2.00049328804016,24543.548828125,24703.33984375,50.0961350545438,5.40019764535349,2.63950395584106,26,1,0,0,1,0.2801513671875,31.2805480957031,1,6,1,1.99961876869202,0,2.00005602836609,,,,,,,,,,,,,,,,,,,,,,,,,,,,,,,,,
,3866262540.03691,2.00023180246353,16176.9609375,0.0944661119619339,0.00710177645314326,1,2,12.9061126708984,5.00204733123674,33.8700003921986,125.870164041854,1.42798411292916,1000,-0.0127850892968256,,,,,,,,,,,,,,,,,,,,,1.99923646450043,2.00122714042664,16097.0849609375,16256.8369140625,49.8847045400918,5.39984536912386,2.63212752342224,25,1,68,0,0,0.282211303710938,31.2805480957031,1,6,1,2.00122714042664,0,2.00023180246353,,,,,,,,,,,,,,,,,,,,,,,,,,,,,,,,,
,3866262620.52092,1.99980300664902,8136.71752929688,0.0748836311633083,0.00652031890156646,1,2,12.9061126708984,5.00199821152374,33.8700003921986,98.7878050925702,7.86093198105269,1000,-0.00498417575386991,,,,,,,,,,,,,,,,,,,,,1.99958336353302,2.00002264976501,8046.78076171875,8226.654296875,49.7315053503226,5.39917470286964,2.634920835495,25,1,68,0,0,0.283355712890625,30.7917900085449,1,6,1,2.00002264976501,0,1.99980300664902,,,,,,,,,,,,,,,,,,,,,,,,,,,,,,,,,
,3866262705.1295,2.00077450275421,-318.572624206543,-0.00531544246840696,0.000190712548126378,1,2,12.9061126708984,5.00270504313095,33.8700003921986,-6.94459053534247,-1.02792318099392,100,-5.758299116861E-6,,,,,,,,,,,,,,,,,,,,,2.00024175643921,2.00130724906921,-408.496520996094,-228.648727416992,49.849922070986,5.3988703730083,2.62904191017151,26,1,0,0,1,0.281524658203125,31.2805480957031,1,6,1,2.00024175643921,0,2.00077450275421,,,,,,,,,,,,,,,,,,,,,,,,,,,,,,,,,
,3866262807.8636,2.00012964010239,-10586.0483398438,-0.0740917401574663,0.00949707970566008,1,2,12.9061126708984,5.00221880464459,33.8700003921986,-98.7228683906494,-1.15042676560969,1000,0.0100043629997266,,,,,,,,,,,,,,,,,,,,,1.99957692623138,2.00068235397339,-10676.1787109375,-10495.91796875,49.7639429338706,5.39769810489542,2.6195695400238,26,1,0,0,1,0.283889770507813,31.2805480957031,1,6,1,1.99957692623138,0,2.00012964010239,,,,,,,,,,,,,,,,,,,,,,,,,,,,,,,,,
,3866262888.69556,2.00011789798737,-18671.876953125,-0.0903311079787477,0.00969389276952388,1,2,12.9061126708984,5.00207456165269,33.8700003921986,-121.121928680961,3.8109841774094,1000,0.0161876357903093,,,,,,,,,,,,,,,,,,,,,1.99993324279785,2.00030255317688,-18736.84765625,-18606.90625,49.8526577708034,5.39960466609292,2.62042474746704,24,1,68,0,0,0.282745361328125,31.2805480957031,1,6,1,1.99993324279785,0,2.00011789798737,,,,,,,,,,,,,,,,,,,,,,,,,,,,,,,,,
,3866262969.01875,2.00000667572021,-26704.455078125,-0.124598143088529,0.00899992443123862,1,2,12.9061126708984,5.00232627430802,33.8700003921986,-166.562384637696,1.72549759649932,1000,0.0196254705943314,,,,,,,,,,,,,,,,,,,,,1.99968862533569,2.00032472610474,-26799.48828125,-26609.421875,49.9964774183418,5.39812661900769,2.60709166526794,23,1,68,0,0,0.282669067382813,31.7693061828613,1,6,1,2.00032472610474,0,2.00000667572021,,,,,,,,,,,,,,,,,,,,,,,,,,,,,,,,,
,3866263049.95095,2.00100100040436,-34813.7578125,-0.145472126804981,0.00941171892963482,1,2,12.9061126708984,5.00240058100143,33.8700003921986,-194.015000249632,-1.08727163293052,1000,0.0205393041907185,,,,,,,,,,,,,,,,,,,,,2.00089621543884,2.00110578536987,-34873.859375,-34753.65625,50.1430327656976,5.39859923933612,2.59695839881897,24,1,68,0,0,0.278244018554687,31.2805480957031,1,6,1,2.00110578536987,0,2.00100100040436,,,,,,,,,,,,,,,,,,,,,,,,,,,,,,,,,
,3866263130.27419,2.00058567523956,-42863.84765625,-0.13992978547526,0.011544175619758,1,2,12.9061126708984,5.0023438653284,33.8700003921986,-186.394980863935,-2.57928592541546,1000,0.0185831275767739,,,,,,,,,,,,,,,,,,,,,2.00048494338989,2.00068640708923,-42968.9765625,-42758.71875,50.4318445035534,5.39898155620806,2.59908986091614,24,1,68,0,0,0.281906127929687,31.2805480957031,1,6,1,2.00068640708923,0,2.00058567523956,,,,,,,,,,,,,,,,,,,,,,,,,,,,,,,,,
,3866263210.05243,2.00034862756729,-49596.99609375,-0.103427617856519,0.0142633226974716,1,2,12.9061126708984,5.00212221276512,33.8700003921986,-141.543986376187,23.8280205517078,1000,0.0334328701609127,,,,,,,,,,,,,,,,,,,,,1.99958407878876,2.00111317634583,-49761.73828125,-49432.25390625,50.6057568490823,5.40050355656929,2.59292554855347,24,1,68,0,0,0.281906127929687,31.2805480957031,1,6,1,1.99958407878876,0,2.00034862756729,,,,,,,,,,,,,,,,,,,,,,,,,,,,,,,,,
,3866263289.33833,1.99991494417191,-41687.591796875,-0.122143592974838,0.0149644605343037,1,2,12.9061126708984,5.00230906220844,33.8700003921986,-164.545677628568,10.3042932238551,1000,0.0258308346958679,,,,,,,,,,,,,,,,,,,,,1.99959528446198,2.00023460388184,-41777.39453125,-41597.7890625,50.3286695390149,5.3998136678575,2.58700585365295,22,1,68,0,0,0.280380249023438,31.2805480957031,1,6,1,2.00023460388184,0,1.99991494417191,,,,,,,,,,,,,,,,,,,,,,,,,,,,,,,,,
,3866263370.276,1.99942809343338,-33607.810546875,-0.100050112540612,0.0113599043768445,1,2,12.9061126708984,5.00219504237351,33.8700003921986,-134.819307458008,8.72028330721284,1000,0.0213729188107801,,,,,,,,,,,,,,,,,,,,,1.99911820888519,1.99973797798157,-33662.7109375,-33552.91015625,50.2364373737457,5.39795286598196,2.59334063529968,18,1,68,0,0,0.279464721679687,31.7693061828613,1,6,1,1.99911820888519,0,1.99942809343338,,,,,,,,,,,,,,,,,,,,,,,,,,,,,,,,,
,3866263448.52548,2.00006061792374,-25797.125,-0.103139135626065,0.0101335040919665,1,2,12.9061126708984,5.00212292380153,33.8700003921986,-138.479305151609,5.5878866240133,1000,0.0194292955998596,,,,,,,,,,,,,,,,,,,,,1.99973475933075,2.00038647651672,-25887.38671875,-25706.86328125,50.0117191744668,5.40024150713097,2.59513425827026,23,1,68,0,0,0.283660888671875,31.2805480957031,1,6,1,1.99973475933075,0,2.00006061792374,,,,,,,,,,,,,,,,,,,,,,,,,,,,,,,,,
,3866263529.27375,1.99960517883301,-17735.9404296875,-0.0786060009820175,0.0103831571082786,1,2,12.9061126708984,5.00198989354253,33.8700003921986,-105.416568834426,3.44513940548338,1000,0.0141851264401365,,,,,,,,,,,,,,,,,,,,,1.99926555156708,1.99994480609894,-17810.759765625,-17661.12109375,49.8370252004187,5.39984995320807,2.59694600105286,21,1,68,0,0,0.281829833984375,31.2805480957031,1,6,1,1.99926555156708,0,1.99960517883301,,,,,,,,,,,,,,,,,,,,,,,,,,,,,,,,,
,3866263609.67112,1.99916583299637,-9702.62255859375,-0.0833616955823479,0.00794816119042001,1,2,12.9061126708984,5.00221613541596,33.8700003921986,-109.546016167214,-11.6981967543398,1000,0.0032930572118691,,,,,,,,,,,,,,,,,,,,,1.99914908409119,1.99918258190155,-9792.6845703125,-9612.560546875,49.7912999320437,5.39865179673393,2.59997749328613,26,1,0,0,1,0.284042358398438,31.7693061828613,1,6,1,1.99914908409119,0,1.99916583299637,,,,,,,,,,,,,,,,,,,,,,,,,,,,,,,,,
,3866263692.34902,2.00090169906616,-1444.11608886719,-0.0269158482707709,0.000178329336964657,1,2,12.9061126708984,5.00290789848592,33.8700003921986,-35.1827302680686,-5.10087342996605,100,5.08284715642472E-5,,,,,,,,,,,,,,,,,,,,,2.00027561187744,2.00152778625488,-1529.20129394531,-1359.03088378906,49.934337951063,5.39826272684367,2.59670639038086,26,1,0,0,1,0.2783203125,31.2805480957031,5,6,1,2.00027561187744,0,2.00090169906616,,,,,,,,,,,,,,,,,,,,,,,,,,,,,,,,,
,3866263804.32275,2.00093221664429,9748.8349609375,0.0793798149868593,0.01032202957186,1,2,12.9061126708984,5.00210313506347,33.8700003921986,104.045564322193,12.9397727753696,1000,-0.00175747158730851,,,,,,,,,,,,,,,,,,,,,1.99906539916992,2.00279903411865,9578.77734375,9918.892578125,49.758471534236,5.39894624683011,2.60397362709045,24,1,68,0,0,0.2813720703125,31.2805480957031,1,6,1,2.00279903411865,0,2.00093221664429,,,,,,,,,,,,,,,,,,,,,,,,,,,,,,,,,
,3866263885.84823,2.00024592876434,17899.6669921875,0.0917819574097836,0.0067684262340641,1,2,12.9061126708984,5.00204459282714,33.8700003921986,122.697161654982,-1.35955353542228,1000,-0.0145244140778099,,,,,,,,,,,,,,,,,,,,,2.0001585483551,2.00033330917358,17789.498046875,18009.8359375,49.9616949492361,5.3993974318818,2.59647631645203,26,1,0,0,1,0.281295776367187,31.7693061828613,1,6,1,2.00033330917358,0,2.00024592876434,,,,,,,,,,,,,,,,,,,,,,,,,,,,,,,,,
,3866263968.24468,2.00002616643906,26147.587890625,0.109352333740756,0.0105384939681348,1,2,12.9061126708984,5.00254472145235,33.8700003921986,144.453180087369,10.3130749255007,1000,-0.00817225157194169,,,,,,,,,,,,,,,,,,,,,1.99931204319,2.00074028968811,26052.279296875,26242.896484375,50.0164089455822,5.39888619596603,2.57867479324341,25,1,68,0,0,0.280075073242187,30.7917900085449,1,6,1,2.00074028968811,0,2.00002616643906,,,,,,,,,,,,,,,,,,,,,,,,,,,,,,,,,
,3866264049.09201,1.9992504119873,34248.810546875,0.136094632379856,0.00753482475297958,1,2,12.9061126708984,5.00236923868181,33.8700003921986,180.132496077156,10.3713001036844,1000,-0.0120560374053818,,,,,,,,,,,,,,,,,,,,,1.99919438362122,1.99930644035339,34178.66015625,34318.9609375,50.0879279550918,5.40002486995529,2.56773900985718,24,1,68,0,0,0.281906127929687,30.7917900085449,1,6,1,1.99930644035339,0,1.9992504119873,,,,,,,,,,,,,,,,,,,,,,,,,,,,,,,,,
,3866264131.56852,2.00001728534698,42516.185546875,0.146411217276053,0.00944016598978941,1,2,12.9061126708984,5.00206862600309,33.8700003921986,194.405266592572,6.83950519542817,1000,-0.0162743027618186,,,,,,,,,,,,,,,,,,,,,1.99966406822205,2.00037050247192,42405.9921875,42626.37890625,50.3333593101303,5.40126485209735,2.56893372535706,24,1,68,0,0,0.279769897460938,31.7693061828613,1,6,1,2.00037050247192,0,2.00001728534698,,,,,,,,,,,,,,,,,,,,,,,,,,,,,,,,,
,3866264650.82719,4.01385021209717,26.2118682861328,0.000360071128025588,5.22426795988249E-6,1,5,12.9061126708984,4.98111568571726,33.8700003921986,0.467350591441767,0.0708069900262114,100,1.61894962116361E-6,,,,,,,,,,,,,,,,,,,,,4.01385021209717,4.01385021209717,26.2118682861328,26.2118682861328,49.8030243598322,5.40287310309914,3.40118861198425,65,1,0,0,1,0.2716064453125,31.2805480957031,6,1,1,4.01385021209717,0,4.01385021209717,,,,,,,,,,,,,,,,,,,,,,,,,,,,,,,,,
,3866264893.68646,41.0928535461426,26.2118682861328,1.39670593775514E-5,7.17308863671823E-9,1,5,12.9061126708984,4.98096950794817,33.8799990713596,0.0181391941883934,0.00266790581024259,1,2.30598694750403E-9,,,,,,,,,,,,,,,,,,,,,41.0928535461426,41.0928535461426,26.2118682861328,26.2118682861328,49.8038059883514,5.39989000184717,6.44315195083618,65,1,0,0,1,0.271835327148438,31.2805480957031,2,1,1,41.0928535461426,0,41.0928535461426,,,,,,,,,,,,,,,,,,,,,,,,,,,,,,,,,
,3866265126.8952,78.0464019775391,26.2118682861328,1.20170506096796E-5,7.61722353302833E-9,1,5,12.9061126708984,4.98844311648016,33.9299999177456,0.0156348282542978,0.00233273601636658,1,2.69323640585889E-8,,,,,,,,,,,,,,,,,,,,,78.0464019775391,78.0464019775391,26.2118682861328,26.2118682861328,49.9210502662361,5.40917843737175,6.89450407028198,65,1,0,0,1,0.282669067382813,31.2805480957031,2,1,1,78.0464019775391,0,78.0464019775391,,,,,,,,,,,,,,,,,,,,,,,,,,,,,,,,,
,3866265352.39162,115.047348022461,26.2118682861328,1.04678681261339E-5,6.61952398434593E-9,1,5,12.9061126708984,4.99161702819881,34.000001847744,0.0136312946299968,0.00203468186171394,1,2.41181063276646E-8,,,,,,,,,,,,,,,,,,,,,115.047348022461,115.047348022461,26.2118682861328,26.2118682861328,50.0039028892745,5.39799207474345,7.09463500976563,65,1,0,0,1,0.278854370117187,31.2805480957031,2,1,1,115.047348022461,0,115.047348022461,,,,,,,,,,,,,,,,,,,,,,,,,,,,,,,,,
,3866265576.24486,152.029907226562,26.2118682861328,9.21794668125829E-6,6.37431909446257E-9,1,5,12.9061126708984,4.9930539084962,34.1099984943867,0.0120090163195032,0.00178886840485091,1,1.8487530423774E-8,,,,,,,,,,,,,,,,,,,,,152.029907226562,152.029907226562,26.2118682861328,26.2118682861328,49.7784030614764,5.39036671818082,7.19254159927368,65,1,0,0,1,0.275497436523438,31.2805480957031,2,1,1,152.029907226562,0,152.029907226562,,,,,,,,,,,,,,,,,,,,,,,,,,,,,,,,,
,3866265799.31415,189.010009765625,26.2118682861328,8.16055481106275E-6,6.21307537752691E-9,1,5,12.9061126708984,4.99538994946897,34.2399999499321,0.0106389115519789,0.00158146732354631,1,1.38831378394905E-8,,,,,,,,,,,,,,,,,,,,,189.010009765625,189.010009765625,26.2118682861328,26.2118682861328,49.9093258384476,5.38001518245362,7.28567600250244,63,1,64,0,0,0.268707275390625,30.7917900085449,2,1,1,189.010009765625,0,189.010009765625,,,,,,,,,,,,,,,,,,,,,,,,,,,,,,,,,
,3866266022.29604,226.096038818359,26.2118682861328,7.36131528898186E-6,6.78525961638091E-9,1,5,12.9061126708984,4.99594324067265,34.4099998474121,0.0095979243665942,0.00143026627741136,1,1.51804438894906E-8,,,,,,,,,,,,,,,,,,,,,226.096038818359,226.096038818359,26.2118682861328,26.2118682861328,50.025788487813,5.38090305450271,7.43644285202026,65,1,0,0,1,0.26641845703125,31.7693061828613,2,1,1,226.096038818359,0,226.096038818359,,,,,,,,,,,,,,,,,,,,,,,,,,,,,,,,,
,3866266245.49456,263.023406982422,26.2118682861328,6.64902081019742E-6,6.8965567988243E-9,1,5,12.9061126708984,4.99673833438184,34.6000008285046,0.00867157259747537,0.00128925094790599,1,1.14821494024322E-8,,,,,,,,,,,,,,,,,,,,,263.023406982422,263.023406982422,26.2118682861328,26.2118682861328,49.761598048313,5.37863357275443,7.83523845672607,64,1,64,0,0,0.265960693359375,31.2805480957031,2,1,1,263.023406982422,0,263.023406982422,,,,,,,,,,,,,,,,,,,,,,,,,,,,,,,,,
,3866266547.76268,299.946105957031,26.2118682861328,5.95428336175886E-6,7.23417291566219E-9,1,5,12.9061126708984,4.99781689437024,34.8000004887581,0.00776879047801275,0.0011485122582953,1,5.39492665227103E-9,,,,,,,,,,,,,,,,,,,,,299.946105957031,299.946105957031,26.2118682861328,26.2118682861328,49.8440598570918,5.37623880689546,7.63472318649292,65,1,0,0,1,0.265274047851562,31.7693061828613,1,1,1,299.946105957031,0,299.946105957031,,,,,,,,,,,,,,,,,,,,,,,,,,,,,,,,,
,3866267283.69542,264.994476318359,26.4625797271729,1.01513890803704E-5,8.1560445064331E-9,1,5,12.9061126708984,5.00756449231422,34.6199981868267,0.0132798462022711,0.00197195923795897,1,1.57133999392129E-8,,,,,,,,,,,,,,,,,,,,,264.994476318359,264.994476318359,26.4625797271729,26.4625797271729,49.837806828938,5.37858307333808,8.06739616394043,63,1,64,0,0,0.27679443359375,31.2805480957031,2,1,1,264.994476318359,0,264.994476318359,,,,,,,,,,,,,,,,,,,,,,,,,,,,,,,,,
,3866267508.01502,227.9658203125,26.4625797271729,1.00366667035581E-5,6.78391955547867E-9,1,5,12.9061126708984,5.00564614430087,34.4600006937981,0.0131211676630198,0.00195928523353274,1,2.36840952122662E-8,,,,,,,,,,,,,,,,,,,,,227.9658203125,227.9658203125,26.4625797271729,26.4625797271729,49.8147487876207,5.38141484125785,7.90885019302368,64,1,64,0,0,0.275115966796875,31.2805480957031,2,1,1,227.9658203125,0,227.9658203125,,,,,,,,,,,,,,,,,,,,,,,,,,,,,,,,,
,3866267726.78104,190.996612548828,26.4625797271729,9.73963626454675E-6,7.33860317493688E-9,1,5,12.9061126708984,5.00568151995124,34.340001642704,0.0127281099209626,0.00193446136839766,1,4.83247621231481E-8,,,,,,,,,,,,,,,,,,,,,190.996612548828,190.996612548828,26.4625797271729,26.4625797271729,49.9179237521591,5.39007104697182,7.79035806655884,64,1,64,0,0,0.274887084960938,31.7693061828613,2,1,1,190.996612548828,0,190.996612548828,,,,,,,,,,,,,,,,,,,,,,,,,,,,,,,,,
,3866267950.40065,153.869445800781,26.4625797271729,8.50164635101001E-6,6.15550634687089E-9,1,5,12.9061126708984,5.00292203643129,34.2199988663197,0.0111017816117401,0.0016866441193357,1,4.17014615594038E-8,,,,,,,,,,,,,,,,,,,,,153.869445800781,153.869445800781,26.4625797271729,26.4625797271729,50.5041451415823,5.39387943869784,7.68332290649414,63,1,64,0,0,0.27679443359375,31.2805480957031,2,1,1,153.869445800781,0,153.869445800781,,,,,,,,,,,,,,,,,,,,,,,,,,,,,,,,,
,3866268172.12217,116.965217590332,26.4625797271729,6.860382272735E-6,6.47451877324886E-9,1,5,12.9061126708984,5.00301177665244,34.1099984943867,0.00895975482836445,0.0013544310380484,1,2.85725883961045E-8,,,,,,,,,,,,,,,,,,,,,116.965217590332,116.965217590332,26.4625797271729,26.4625797271729,50.2247129459572,5.39390067410294,7.58138132095337,65,1,0,0,1,0.281143188476562,31.7693061828613,2,1,1,116.965217590332,0,116.965217590332,,,,,,,,,,,,,,,,,,,,,,,,,,,,,,,,,
,3866268394.63425,79.7347183227539,26.4625797271729,6.065418320623E-6,6.34374232964538E-9,1,5,12.9061126708984,5.00267958303186,34.000001847744,0.00792202699938734,0.00118891441219838,1,1.87894179809536E-8,,,,,,,,,,,,,,,,,,,,,79.7347183227539,79.7347183227539,26.4625797271729,26.4625797271729,49.8436690428322,5.3972358087216,7.41825819015503,65,1,0,0,1,0.278396606445313,31.2805480957031,2,1,1,79.7347183227539,0,79.7347183227539,,,,,,,,,,,,,,,,,,,,,,,,,,,,,,,,,
,3866268609.99933,42.9214057922363,26.4625797271729,5.61175331787997E-6,5.7378288706501E-9,1,5,12.9061126708984,5.00472961401888,33.9399985969067,0.00733665800997754,0.00108048894928317,1,1.98668622157695E-9,,,,,,,,,,,,,,,,,,,,,42.9214057922363,42.9214057922363,26.4625797271729,26.4625797271729,49.7760581759187,5.38597452759157,7.09395408630371,65,1,0,0,1,0.275497436523438,33.2355842590332,2,1,1,42.9214057922363,0,42.9214057922363,,,,,,,,,,,,,,,,,,,,,,,,,,,,,,,,,
,3866268889.20913,5.98750352859497,26.4625797271729,3.57640156958666E-6,8.05454861260784E-9,1,5,12.9061126708984,5.00043022700749,33.8799990713596,0.00467183764390177,0.000675746273127014,1,-7.94408910152115E-9,,,,,,,,,,,,,,,,,,,,,5.98750352859497,5.98750352859497,26.4625797271729,26.4625797271729,49.8253007726303,5.40998091872625,4.52095508575439,65,1,0,0,1,0.269012451171875,31.2805480957031,6,1,1,5.98750352859497,0,5.98750352859497,,,,,,,,,,,,,,,,,,,,,,,,,,,,,,,,,
,3866270647.34019,33.0037651062012,26.4625797271729,5.39940284555906E-6,6.51218637497049E-9,1,5,12.9061126708984,5.00619428430065,33.8799990713596,0.00706242289395835,0.001036655012761,1,-6.67754062382395E-10,,,,,,,,,,,,,,,,,,,,,33.0037651062012,33.0037651062012,26.4625797271729,26.4625797271729,49.6939871813995,5.38283835024856,6.27110624313354,65,1,0,0,1,0.278701782226562,31.2805480957031,2,1,1,33.0037651062012,0,33.0037651062012,,,,,,,,,,,,,,,,,,,,,,,,,,,,,,,,,
,3866270881.86563,70.0080108642578,26.4625797271729,5.84782883441187E-6,5.998308098299E-9,1,5,12.9061126708984,4.99930835737812,33.9099988341331,0.00763175131429756,0.00113753009885184,1,1.22539173861802E-8,,,,,,,,,,,,,,,,,,,,,70.0080108642578,70.0080108642578,26.4625797271729,26.4625797271729,49.926130851611,5.40747335483858,6.87158155441284,65,1,0,0,1,0.28594970703125,31.2805480957031,2,1,1,70.0080108642578,0,70.0080108642578,,,,,,,,,,,,,,,,,,,,,,,,,,,,,,,,,
,3866271103.45622,106.031494140625,26.4625797271729,6.20995082655438E-6,6.25614865404076E-9,1,5,12.9061126708984,5.00278158524552,33.9800007641315,0.00811220623617096,0.00120928714182259,1,1.31206667076376E-8,,,,,,,,,,,,,,,,,,,,,106.031494140625,106.031494140625,26.4625797271729,26.4625797271729,49.9128431667841,5.39595635575449,7.08963012695313,64,1,64,0,0,0.280609130859375,34.2131004333496,2,1,1,106.031494140625,0,106.031494140625,,,,,,,,,,,,,,,,,,,,,,,,,,,,,,,,,
,3866271326.78187,143.023025512695,26.4625797271729,6.72408276288061E-6,6.06912045961976E-9,1,5,12.9061126708984,5.00068121585149,34.0799987316132,0.00877505329000368,0.00133322651864149,1,3.30361398017484E-8,,,,,,,,,,,,,,,,,,,,,143.023025512695,143.023025512695,26.4625797271729,26.4625797271729,50.2274486457745,5.40586606530884,7.2062611579895,64,1,64,0,0,0.280380249023438,31.7693061828613,2,1,1,143.023025512695,0,143.023025512695,,,,,,,,,,,,,,,,,,,,,,,,,,,,,,,,,
,3866271550.46196,180.036819458008,26.4625797271729,6.79464071492806E-6,6.55192605174848E-9,1,5,12.9061126708984,5.00462179325028,34.2100001871586,0.00887972368225394,0.00132959186954614,1,1.87652311869296E-8,,,,,,,,,,,,,,,,,,,,,180.036819458008,180.036819458008,26.4625797271729,26.4625797271729,49.8464047426495,5.38660736729691,7.2791223526001,65,1,0,0,1,0.27557373046875,31.2805480957031,2,1,1,180.036819458008,0,180.036819458008,,,,,,,,,,,,,,,,,,,,,,,,,,,,,,,,,
,3866271773.67282,217.034729003906,26.4625797271729,6.75054738998213E-6,7.51605408394008E-9,1,5,12.9061126708984,5.00574702504753,34.3599990010262,0.0088255371232997,0.00131687176849585,1,1.51969337732746E-8,,,,,,,,,,,,,,,,,,,,,217.034729003906,217.034729003906,26.4625797271729,26.4625797271729,49.7963805174187,5.38197522146932,7.40219259262085,64,1,64,0,0,0.275192260742187,31.7693061828613,2,1,1,217.034729003906,0,217.034729003906,,,,,,,,,,,,,,,,,,,,,,,,,,,,,,,,,
,3866271996.35431,254.029922485352,26.4625797271729,6.56632584235325E-6,6.95226516349461E-9,1,5,12.9061126708984,5.00671824381289,34.5499999821186,0.00858980906739034,0.00126229451834081,1,2.67502762333103E-10,,,,,,,,,,,,,,,,,,,,,254.029922485352,254.029922485352,26.4625797271729,26.4625797271729,49.7928631890822,5.3791711368632,7.69082498550415,64,1,64,0,0,0.276947021484375,31.2805480957031,2,1,1,254.029922485352,0,254.029922485352,,,,,,,,,,,,,,,,,,,,,,,,,,,,,,,,,
,3866272219.14721,291.004791259766,26.4625797271729,6.26435600352427E-6,6.90189205675827E-9,1,5,12.9061126708984,5.00781501775819,34.7599983215332,0.00819425797422117,0.00122528568444944,1,1.60527031176685E-8,,,,,,,,,,,,,,,,,,,,,291.004791259766,291.004791259766,26.4625797271729,26.4625797271729,49.7987254029764,5.37858753637492,7.67622709274292,63,1,64,0,0,0.277938842773438,31.7693061828613,2,1,1,291.004791259766,0,291.004791259766,,,,,,,,,,,,,,,,,,,,,,,,,,,,,,,,,
,3866272534.64804,300.003921508789,41176.580078125,0.00917580603540188,4.24888292512571E-6,1,2,12.9061126708984,5.00888422882134,34.8000004887581,12.0103013583016,1.7676564047274,100,2.40171448408072E-6,,,,,,,,,,,,,,,,,,,,,300.003601074219,300.004241943359,41086.7265625,41266.43359375,49.819438558736,5.3757602683337,7.69217205047607,26,1,0,0,1,0.283660888671875,31.2805480957031,1,6,1,300.004241943359,0,300.003921508789,,,,,,,,,,,,,,,,,,,,,,,,,,,,,,,,,
,3866272615.55776,300.003112792969,33094.5546875,0.00742812326569925,3.37670476360413E-6,1,2,12.9061126708984,5.00903583219227,34.8000004887581,9.72074811822637,1.44741373748914,100,1.44543822307986E-5,,,,,,,,,,,,,,,,,,,,,300.003021240234,300.003204345703,33039.64453125,33149.46484375,49.8139671591014,5.37608260898878,7.76374292373657,26,1,0,0,1,0.274658203125,32.2580642700195,1,6,1,300.003021240234,0,300.003112792969,,,,,,,,,,,,,,,,,,,,,,,,,,,,,,,,,
,3866272693.77289,300.001907348633,25287.0341796875,0.00570235961224841,2.77154398233006E-6,1,2,12.9061126708984,5.00783465455519,34.8000004887581,7.4575577314816,1.12630439134574,100,2.29705591137277E-5,,,,,,,,,,,,,,,,,,,,,300.001556396484,300.002258300781,25192.064453125,25382.00390625,49.7545633916399,5.38167134324748,7.89417409896851,26,1,0,0,1,0.286407470703125,31.7693061828613,1,6,1,300.001556396484,0,300.001907348633,,,,,,,,,,,,,,,,,,,,,,,,,,,,,,,,,
,3866272778.39712,300.002151489258,16840.6689453125,0.00381476160759337,2.93436203499864E-6,1,2,12.9061126708984,5.00802278619506,34.8000004887581,4.99078138499543,0.742853709863983,100,7.2206908129231E-6,,,,,,,,,,,,,,,,,,,,,300.001922607422,300.002380371094,16745.861328125,16935.4765625,49.8823596545341,5.37944902528482,8.07879257202148,26,1,0,0,1,0.284805297851562,32.2580642700195,1,6,1,300.001922607422,0,300.002151489258,,,,,,,,,,,,,,,,,,,,,,,,,,,,,,,,,
,3866272859.34616,300.001708984375,8755.84912109375,0.00202758315991669,2.52391959084793E-6,1,2,12.9061126708984,5.00810924911836,34.8000004887581,2.65344931781463,0.389833165159454,100,9.27502241101542E-9,,,,,,,,,,,,,,,,,,,,,300.001617431641,300.001800537109,8635.83984375,8875.8583984375,50.0926177262072,5.37918875469712,8.27104663848877,26,1,0,0,1,0.276641845703125,32.2580642700195,1,6,1,300.001617431641,0,300.001708984375,,,,,,,,,,,,,,,,,,,,,,,,,,,,,,,,,
,3866272939.54705,300.000534057617,736.050872802734,0.000216023530793892,3.00065584055136E-6,1,2,12.9061126708984,5.00822987708245,34.8000004887581,0.287888023156901,0.00631857065685725,100,-2.6908172037798E-5,,,,,,,,,,,,,,,,,,,,,300.000305175781,300.000762939453,641.131591796875,830.970153808594,50.0007763751976,5.37906428913621,8.44713020324707,26,1,0,0,1,0.284347534179687,31.7693061828613,1,6,1,300.000762939453,0,300.000534057617,,,,,,,,,,,,,,,,,,,,,,,,,,,,,,,,,
,3866273030.38979,300.001831054687,-8341.2724609375,-0.00192003036457665,2.5223340899934E-6,1,2,12.9061126708984,5.00861640853016,34.8000004887581,-2.51148992778955,-0.379849050544966,10,-8.13969346792723E-6,,,,,,,,,,,,,,,,,,,,,300.001678466797,300.001983642578,-8416.1533203125,-8266.3916015625,49.8636005700726,5.37732103164498,8.38472175598145,26,1,0,0,1,0.283966064453125,31.7693061828613,1,6,1,300.001983642578,0,300.001831054687,,,,,,,,,,,,,,,,,,,,,,,,,,,,,,,,,
,3866273130.28183,300.001190185547,-18336.857421875,-0.00416193018617545,2.65074920836411E-6,1,2,12.9061126708984,5.00856762769512,34.8000004887581,-5.44522170161685,-0.814544868917359,100,-1.09058730025975E-5,,,,,,,,,,,,,,,,,,,,,300.001098632812,300.001281738281,-18507.05859375,-18166.65625,49.8495312567264,5.37732972692709,8.31738471984863,26,1,0,0,1,0.275802612304687,32.2580642700195,1,6,1,300.001281738281,0,300.001190185547,,,,,,,,,,,,,,,,,,,,,,,,,,,,,,,,,
,3866273211.51617,300.001312255859,-26464.2978515625,-0.00595662350883149,2.71315852116608E-6,1,2,12.9061126708984,5.00885946185399,34.8000004887581,-7.79480738138749,-1.15988948938851,100,-1.10281907735093E-5,,,,,,,,,,,,,,,,,,,,,300.000915527344,300.001708984375,-26559.455078125,-26369.140625,49.7694143335053,5.3754859481685,8.2705078125,26,1,0,0,1,0.283050537109375,31.7693061828613,1,6,1,300.001708984375,0,300.001312255859,,,,,,,,,,,,,,,,,,,,,,,,,,,,,,,,,
,3866273292.1868,300.00146484375,-34543.416015625,-0.00774193537268482,3.4088671031904E-6,1,2,12.9061126708984,5.00888739002222,34.8000004887581,-10.1301094356411,-1.51453252173221,100,-1.96741402129807E-5,,,,,,,,,,,,,,,,,,,,,300.000915527344,300.002014160156,-34643.6328125,-34443.19921875,49.7502644347841,5.3745724721839,8.24318981170654,26,1,0,0,1,0.274276733398438,32.2580642700195,1,6,1,300.000915527344,0,300.00146484375,,,,,,,,,,,,,,,,,,,,,,,,,,,,,,,,,
,3866273372.67111,299.999572753906,-42603.345703125,-0.00954605603503327,2.83025579343597E-6,1,2,12.9061126708984,5.00899675608246,34.8000004887581,-12.4899831847972,-1.87535120402869,100,-3.02380195773074E-5,,,,,,,,,,,,,,,,,,,,,299.99951171875,299.999633789063,-42698.546875,-42508.14453125,49.7045391664091,5.37453455829094,8.22195911407471,26,1,0,0,1,0.283279418945313,31.7693061828613,1,6,1,299.99951171875,0,299.999572753906,,,,,,,,,,,,,,,,,,,,,,,,,,,,,,,,,
,3866273456.61683,300.00065612793,-49601.921875,-0.0110986561093952,3.68481316336157E-6,1,2,12.9061126708984,5.00903526238653,34.8000004887581,-14.5328102447766,-2.10373236788504,100,2.34034107165547E-5,,,,,,,,,,,,,,,,,,,,,300,300.001312255859,-49761.6484375,-49442.1953125,49.6967228812168,5.3747324573986,8.20608043670654,25,1,68,0,0,0.283432006835938,31.7693061828613,1,6,1,300,0,300.00065612793,,,,,,,,,,,,,,,,,,,,,,,,,,,,,,,,,
,3866273538.12264,300.001129150391,-41467.931640625,-0.00931805328681705,3.17168530258094E-6,1,2,12.9061126708984,5.00893523680693,34.8000004887581,-12.1959469011107,-1.79996492174688,100,-6.1670409008935E-6,,,,,,,,,,,,,,,,,,,,,300.000732421875,300.001525878906,-41577.62890625,-41358.234375,49.7416665210726,5.3750325357463,8.17872524261475,24,1,68,0,0,0.282974243164062,32.2580642700195,1,6,1,300.001525878906,0,300.001129150391,,,,,,,,,,,,,,,,,,,,,,,,,,,,,,,,,
,3866273620.50109,300.00032043457,-33243.2265625,-0.00749383110774808,3.54313865507359E-6,1,2,12.9061126708984,5.00892930310107,34.8000004887581,-9.80586460771284,-1.46412108476667,100,-1.75977339061603E-5,,,,,,,,,,,,,,,,,,,,,300.000183105469,300.000457763672,-33343.015625,-33143.4375,49.8241283298514,5.37483519020037,8.17348670959473,26,1,0,0,1,0.283584594726562,30.7917900085449,1,6,1,300.000183105469,0,300.00032043457,,,,,,,,,,,,,,,,,,,,,,,,,,,,,,,,,
,3866273705.07249,300.000411987305,-24803.5673828125,-0.00562501903324639,2.68476702625299E-6,1,2,12.9061126708984,5.00899836237487,34.8000004887581,-7.35985613697746,-1.10421482865422,100,-1.7178010338057E-5,,,,,,,,,,,,,,,,,,,,,300.000335693359,300.00048828125,-24898.279296875,-24708.85546875,49.7037575378899,5.37537034375648,8.15671634674072,26,1,0,0,1,0.282974243164062,31.7693061828613,1,6,1,300.000335693359,0,300.000411987305,,,,,,,,,,,,,,,,,,,,,,,,,,,,,,,,,
,3866273784.03358,300.001312255859,-16917.6943359375,-0.00387076358991215,2.72606308850827E-6,1,2,12.9061126708984,5.00862177864816,34.8000004887581,-5.06373944055591,-0.761749073960663,100,-1.33349171089998E-5,,,,,,,,,,,,,,,,,,,,,300.001190185547,300.001434326172,-17032.58984375,-16802.798828125,49.9296481799476,5.37611092915257,8.15153503417969,26,1,0,0,1,0.283203125,31.7693061828613,1,6,1,300.001190185547,0,300.001312255859,,,,,,,,,,,,,,,,,,,,,,,,,,,,,,,,,
,3866273864.2657,299.999984741211,-8903.29248046875,-0.00206529902624237,2.646117646415E-6,1,2,12.9061126708984,5.00885177882903,34.8000004887581,-2.70355531410151,-0.395888783125036,100,9.67022638080628E-7,,,,,,,,,,,,,,,,,,,,,299.999816894531,300.000152587891,-8993.1787109375,-8813.40625,49.8522669565437,5.37589107327457,8.1355562210083,26,1,0,0,1,0.282516479492187,31.7693061828613,1,6,1,300.000152587891,0,299.999984741211,,,,,,,,,,,,,,,,,,,,,,,,,,,,,,,,,
,3866273946.82167,300.000686645508,-654.895599365234,-0.000198042960432147,3.6712611692593E-6,1,2,12.9061126708984,5.00921185409899,34.8000004887581,-0.263859140155941,-0.00674094807659191,100,2.39453005129795E-5,,,,,,,,,,,,,,,,,,,,,300.000518798828,300.000854492188,-749.81494140625,-559.976257324219,49.8167028589187,5.37634577538827,8.13491153717041,25,1,68,0,0,0.274429321289062,32.2580642700195,1,6,1,300.000854492188,0,300.000686645508,,,,,,,,,,,,,,,,,,,,,,,,,,,,,,,,,
,3866274041.51285,300.000549316406,8813.8134765625,0.00204659570519244,2.73907356614615E-6,1,2,12.9061126708984,5.00923604492951,34.8000004887581,2.67667420457538,0.410622909063616,10,1.30035162977051E-5,,,,,,,,,,,,,,,,,,,,,300.000366210937,300.000732421875,8718.7998046875,8908.8271484375,49.7186084797553,5.37526929583277,8.12037086486816,24,1,68,0,0,0.281906127929687,31.7693061828613,1,6,1,300.000732421875,0,300.000549316406,,,,,,,,,,,,,,,,,,,,,,,,,,,,,,,,,
,3866274132.71509,300.000671386719,17934.7099609375,0.00408089376250826,2.7904294141832E-6,1,2,12.9061126708984,5.00900931075815,34.8000004887581,5.33732622671253,0.816008888588473,10,2.38527026787689E-5,,,,,,,,,,,,,,,,,,,,,300.000518798828,300.000823974609,17849.59375,18019.826171875,49.9413726077361,5.37652649085102,8.12114143371582,26,1,0,0,1,0.283584594726562,31.7693061828613,1,6,1,300.000823974609,0,300.000671386719,,,,,,,,,,,,,,,,,,,,,,,,,,,,,,,,,
,3866274253.06845,299.998489379883,29980.1806640625,0.00678194771523312,2.15910443008743E-6,1,2,12.9061126708984,5.00929270276941,34.8000004887581,8.87350090779344,1.33705985543645,100,2.50084505588198E-5,,,,,,,,,,,,,,,,,,,,,299.998352050781,299.998626708984,29880.00390625,30080.357421875,49.822565072813,5.37575236407724,8.10701274871826,26,1,0,0,1,0.2813720703125,31.2805480957031,1,6,1,299.998352050781,0,299.998489379883,,,,,,,,,,,,,,,,,,,,,,,,,,,,,,,,,
,3866274335.62953,299.999938964844,38252.494140625,0.00864619323426513,3.02859600326376E-6,1,2,12.9061126708984,5.00928346821602,34.8000004887581,11.3125735982705,1.70511617583241,100,3.22839149755796E-5,,,,,,,,,,,,,,,,,,,,,299.998931884766,300.000946044922,38157.3359375,38347.65234375,49.7139187086399,5.37544491493584,8.1019344329834,26,1,0,0,1,0.282211303710938,31.7693061828613,1,6,1,300.000946044922,0,299.999938964844,,,,,,,,,,,,,,,,,,,,,,,,,,,,,,,,,
,3866274414.24703,299.99951171875,46133.234375,0.0104039134190513,2.79455088872343E-6,1,2,12.9061126708984,5.00926172991982,34.8000004887581,13.6113429489045,2.05805835092658,100,4.36706281612995E-5,,,,,,,,,,,,,,,,,,,,,299.999389648438,299.999633789063,46033.08203125,46233.38671875,49.6967228812168,5.37390841250388,8.09540939331055,26,1,0,0,1,0.281906127929687,30.7917900085449,1,6,1,299.999694824219,0,299.99951171875,,,,,,,,,,,,,,,,,,,,,,,,,,,,,,,,,
,3866274454.72506,299.998794555664,50000.453125,0.0112476794565948,1.3263669788418E-6,1,2,12.9061126708984,5.00895538464408,34.8000004887581,14.7163055036114,2.20892157941049,100,3.50985701748563E-5,,,,,,,,,,,,,,,,,,,,,299.998748779297,299.998840332031,50000.4296875,50000.4765625,49.7033667236303,5.37433768496134,8.09284210205078,26,1,0,0,1,0.282745361328125,32.2580642700195,1,4,1,299.998840332031,0,299.998794555664,,,,,,,,,,,,,,,,,,,,,,,,,,,,,,,,,