File: LT data/Frome/M1/306_FULL_SEQUENCE.dat
[Header]
; MPMS3 Data File (default extension .dat)
; Copyright (c) 2007, Quantum Design, Inc. All rights reserved.
TITLE,
FILEOPENTIME,3873624057.04835,09/29/2022,4:52 pm
BYAPP,MPMS3 w/ AC,1.0,1.1
INFO,MPMS3 Measurement Release 1.1.16 Build 424, MultiVu Release 2.3.4.19,APPNAME
INFO,Linear Motor Servo Controller,MOTOR_MODULE_NAME
INFO,3101-100 N0,MOTOR_HW_VERSION
INFO,MMC1047,MOTOR_SERIAL_NUMBER
INFO,01.04.28,MOTOR_SOFTWARE_VERSION
INFO,Quantum Design Squid Module,SQUID_MODULE_NAME
INFO,3101-501 B0,SQUID_HW_VERSION
INFO,SQM278,SQUID_SERIAL_NUMBER
INFO,01.03.04,SQUID_SOFTWARE_VERSION
INFO,Quantum Design VSM Oven,OVEN_MODULE_NAME
INFO,3101-201 A3,OVEN_HW_VERSION
INFO,OVB323,OVEN_SERIAL_NUMBER
INFO,01.07.07,OVEN_SOFTWARE_VERSION
INFO,SQUID AC,AC_MODULE_NAME
INFO,3101-401 G0,AC_HW_VERSION
INFO,SAC258,AC_SERIAL_NUMBER
INFO,SQUID AC 00.95.07,AC_SOFTWARE_VERSION
INFO,TCI127,COIL_SERIAL_NUMBER
INFO,0,MOMENT_UNITS
INFO,,SAMPLE_MATERIAL
INFO,,SAMPLE_COMMENT
INFO,,SAMPLE_MASS
INFO,,SAMPLE_VOLUME
INFO,,SAMPLE_MOLECULAR_WEIGHT
INFO,,SAMPLE_SIZE
INFO,,SAMPLE_SHAPE
INFO,Straw,SAMPLE_HOLDER
INFO,Standard,SAMPLE_HOLDER_DETAIL
INFO,69.78,SAMPLE_OFFSET
DATATYPE,COMMENT,1
DATATYPE,TIME,2
STARTUPAXIS,X,2
STARTUPAXIS,Y1,5
FIELDGROUP, VSM,2,3,4,5,6,8,9,10,11,14,15
FIELDGROUP, DC, 2,3,4,14,56,57,58,59,60,61,62,63,64,65,66,67,68,69
FIELDGROUP, AC, 2,3,4,11,16,17,18,19,20,21,22,23,24,25,26,27,28,29,30
STARTUPGROUP, All
[Data]
Comment,Time Stamp (sec),Temperature (K),Magnetic Field (Oe),Moment (emu),M. Std. Err. (emu),Transport Action,Averaging Time (sec),Frequency (Hz),Peak Amplitude (mm),Center Position (mm),Lockin Signal' (V),Lockin Signal (V),Range,M. Quad. Signal (emu),AC Moment (emu),AC M. Std Err. (emu),AC Phase (deg),AC Phase Std. Err. (deg),AC Susceptibility (emu/Oe),AC Suscept. Std Err. (emu/Oe),AC X' (emu/Oe),AC X' Std Err. (emu/Oe),AC X'' (emu/Oe),AC X'' Std Err. (emu/Oe),AC Drive (Oe),AC Frequency (Hz),AC Averaging Time (sec),AC Cycles,AC Range,AC Measure Type,AC Signal' (V),AC Signal'' (V),AC Trim Coil Ratio,AC Trim Coil Phase,Min. Temperature (K),Max. Temperature (K),Min. Field (Oe),Max. Field (Oe),Mass (grams),Motor Lag (deg),Pressure (Torr),Measure Count,Measurement Number,SQUID Status (code),Motor Status (code),Measure Status (code),Motor Current (amps),Motor Temp. (C),Temp. Status (code),Field Status (code),Chamber Status (code),Chamber Temp (K),Redirection State,Evercool Status,Average Temp (K),Rotation Angle (deg),Rotator state,DC Moment Fixed Ctr (emu),DC Moment Err Fixed Ctr (emu),DC Moment Free Ctr (emu),DC Moment Err Free Ctr (emu),DC Fixed Fit,DC Free Fit,DC Calculated Center (mm),DC Calculated Center Err (mm),DC Scan Length (mm),DC Scan Time (s),DC Number of Points,DC Squid Drift,DC Min V (V),DC Max V (V),DC Scans per Measure,Map 01,Map 02,Map 03,Map 04,Map 05,Map 06,Map 07,Map 08,Map 09,Map 10,Map 11,Map 12,Map 13,Map 14,Map 15,Map 16
"FC",3873624199.41678
,3873625047.20338,90.0891342163086,49999.609375,0.0386298398739694,5.05170219742647E-5,1,2,13.1008939743042,1.98092286939144,27.9699992388487,9.20032461621377,1.3484024255166,10,2.72756470293995E-7,,,,,,,,,,,,,,,,,,,,,90.065071105957,90.1131973266602,49999.609375,49999.609375,51.8059474403612,5.81551114012961,7.50613880157471,26,1,0,0,1,0.130615234375,31.7693061828613,2,1,1,90.065071105957,0,2084573184,90.0891342163086,,,,,,,,,,,,,,,,,,,,,,,,,,,,,,,,,
,3873625193.93598,65.9248275756836,49999.609375,0.0533844786598709,1.80723531721796E-5,1,2,13.1008939743042,1.97996658859645,27.8900004923344,12.7016540452397,1.86910480721113,100,3.14247418620483E-5,,,,,,,,,,,,,,,,,,,,,65.9144592285156,65.9351959228516,49999.609375,49999.609375,51.7817169562651,5.82685150723013,7.32622623443603,26,1,0,0,1,0.131378173828125,31.7693061828613,2,1,1,65.9144592285156,0,2084573184,65.9248275756836,,,,,,,,,,,,,,,,,,,,,,,,,,,,,,,,,
,3873625313.82566,45.5062141418457,49999.609375,0.0763739670878209,5.46007382729468E-5,1,2,13.1008939743042,1.97947051537206,27.8500001877546,18.1641263669264,2.66406355907218,1000,8.45703043275331E-6,,,,,,,,,,,,,,,,,,,,,45.382381439209,45.6300468444824,49999.609375,49999.609375,51.8723858644959,5.83035584052733,7.06614208221436,26,1,0,0,1,0.134353637695312,31.2805480957031,2,1,1,45.3396606445313,0,2084573184,45.5062141418457,,,,,,,,,,,,,,,,,,,,,,,,,,,,,,,,,
,3873625432.92727,25.3091154098511,49999.609375,0.126625880883351,0.00117342045257032,1,2,13.1008939743042,1.97881386487727,27.8099998831749,30.0753629129387,4.55941826623275,100,0.000625150836144208,,,,,,,,,,,,,,,,,,,,,25.1920547485352,25.426176071167,49999.609375,49999.609375,51.6996459617459,5.83837306609147,6.51632118225098,25,1,64,0,0,0.129852294921875,30.7917900085449,2,1,1,25.1920547485352,0,2084573184,25.3091154098511,,,,,,,,,,,,,,,,,,,,,,,,,,,,,,,,,
,3873625555.16868,6.62080049514771,49999.609375,0.250372424592093,0.000171216092077201,1,2,13.1008939743042,1.97821056590117,27.7900006622076,59.4706563277086,8.74915672760429,1000,0.000138256094567273,,,,,,,,,,,,,,,,,,,,,6.62080049514771,6.62080049514771,49999.609375,49999.609375,52.4468828261306,5.84120361963732,4.47444677352905,26,1,0,0,1,0.132980346679688,31.2805480957031,6,1,1,6.62080049514771,0,2084573184,6.62080049514771,,,,,,,,,,,,,,,,,,,,,,,,,,,,,,,,,
,3873626335.4768,6.0145525932312,26.4896049499512,0.00039725002544599,1.86936240397312E-6,1,2,13.1008939743042,1.99665577623308,27.7900006622076,0.0959816799729662,0.0144841405131619,10,1.69148897241167E-6,,,,,,,,,,,,,,,,,,,,,6.0145525932312,6.0145525932312,26.4896049499512,26.4896049499512,51.935306960294,5.85544641404887,4.09299373626709,26,1,0,0,1,0.146484375,31.7693061828613,6,1,1,6.0145525932312,0,2084574016,6.0145525932312,,,,,,,,,,,,,,,,,,,,,,,,,,,,,,,,,
,3873626530.95389,36.0380401611328,26.4896049499512,4.65220539345879E-5,4.82514910223051E-8,1,2,13.1008939743042,1.99880335311046,27.7900006622076,0.0112694386124913,0.00165822206969504,1,2.68765586154757E-8,,,,,,,,,,,,,,,,,,,,,36.0380401611328,36.0380401611328,26.4896049499512,26.4896049499512,51.9603190729093,5.83337137020077,6.32459545135498,26,1,0,0,1,0.13763427734375,31.2805480957031,2,1,1,36.0380401611328,0,2084574080,36.0380401611328,,,,,,,,,,,,,,,,,,,,,,,,,,,,,,,,,
,3873626721.549,66.0208511352539,26.4896049499512,2.82743726388238E-5,4.56927684122209E-8,1,2,13.1008939743042,1.99700986930409,27.8299991041422,0.00683660336096303,0.00101224473610526,1,4.1771634709652E-8,,,,,,,,,,,,,,,,,,,,,66.0208511352539,66.0208511352539,26.4896049499512,26.4896049499512,51.8852827350632,5.85071242586213,6.77001333236694,26,1,0,0,1,0.14312744140625,31.7693061828613,2,1,1,66.0208511352539,0,2084574080,66.0208511352539,,,,,,,,,,,,,,,,,,,,,,,,,,,,,,,,,
,3873626907.36592,96.0355453491211,26.4896049499512,2.18385135154013E-5,4.41446565107107E-8,1,2,13.1008939743042,1.99613464562797,27.8799999505281,0.00527730185815139,0.000772710982421599,1,-2.81137517133964E-9,,,,,,,,,,,,,,,,,,,,,96.0355453491211,96.0355453491211,26.4896049499512,26.4896049499512,51.9138121760151,5.86024899099722,6.96183586120605,26,1,0,0,1,0.146026611328125,30.7917900085449,2,1,1,96.0355453491211,0,2084574112,96.0355453491211,,,,,,,,,,,,,,,,,,,,,,,,,,,,,,,,,
,3873627088.74452,126.009506225586,26.4896049499512,1.73980976613313E-5,3.95854726444574E-8,1,2,13.1008939743042,1.99513292459876,27.9500000178814,0.00420102196044148,0.000609897585165022,1,-2.34190997545495E-8,,,,,,,,,,,,,,,,,,,,,126.009506225586,126.009506225586,26.4896049499512,26.4896049499512,51.9114672904574,5.87240322645485,7.07206058502197,26,1,0,0,1,0.142745971679688,30.7917900085449,2,1,1,126.009506225586,0,2084574144,126.009506225586,,,,,,,,,,,,,,,,,,,,,,,,,,,,,,,,,
,3873627270.25256,156.034217834473,26.4896049499512,1.55906132718612E-5,6.89501323588699E-7,1,2,13.1008939743042,1.99421688669443,28.0399993062019,0.00374867840720318,0.000632206275073236,1,3.36161077477383E-7,,,,,,,,,,,,,,,,,,,,,156.010070800781,156.058364868164,26.4896049499512,26.4896049499512,51.9231917182459,5.88380877794692,7.16687393188477,26,1,0,0,1,0.144195556640625,31.2805480957031,2,1,1,156.058364868164,0,2084574240,156.034217834473,,,,,,,,,,,,,,,,,,,,,,,,,,,,,,,,,
,3873627450.9211,186.008209228516,26.4896049499512,1.30736285962369E-5,4.35207112790666E-8,1,2,13.1008939743042,1.99058932524086,28.1499996781349,0.00314315008710728,0.000456682987058379,1,-1.61090602033398E-8,,,,,,,,,,,,,,,,,,,,,186.008209228516,186.008209228516,26.4896049499512,26.4896049499512,51.9798597858901,5.90909679428578,7.26748418807983,24,1,64,0,0,0.140304565429688,29.8142719268799,2,1,1,186.008209228516,0,2084574240,186.008209228516,,,,,,,,,,,,,,,,,,,,,,,,,,,,,,,,,
,3873627631.51335,216.030639648438,26.4896049499512,1.1744919365736E-5,5.81173873269749E-8,1,2,13.1008939743042,1.98904393643347,28.2799992710352,0.00282218461056688,0.000391674195617245,1,-8.94279978086085E-8,,,,,,,,,,,,,,,,,,,,,216.030639648438,216.030639648438,26.4896049499512,26.4896049499512,51.749279372717,5.9216656785125,7.40849447250366,26,1,0,0,1,0.139999389648438,32.7468223571777,2,1,1,216.030639648438,0,2084574176,216.030639648438,,,,,,,,,,,,,,,,,,,,,,,,,,,,,,,,,
,3873627812.6097,246.028396606445,26.4896049499512,1.07224788210849E-5,4.07197130170684E-8,1,2,13.1008939743042,1.98879615768005,28.4199994057417,0.00257364700085738,0.000372825202375505,1,-1.77494728020715E-8,,,,,,,,,,,,,,,,,,,,,246.028396606445,246.028396606445,26.4896049499512,26.4896049499512,52.0087800411017,5.92381481038565,7.66930913925171,24,1,64,0,0,0.139541625976562,31.7693061828613,2,1,1,246.028396606445,0,2084574368,246.028396606445,,,,,,,,,,,,,,,,,,,,,,,,,,,,,,,,,
,3873627993.46747,276.034759521484,26.4896049499512,9.72012575287708E-6,4.35434379653139E-8,1,2,13.1008939743042,1.9891217271199,28.5899993032217,0.00233198598072196,0.00035033946595577,1,3.49912783328054E-8,,,,,,,,,,,,,,,,,,,,,276.034759521484,276.034759521484,26.4896049499512,26.4896049499512,52.0498155383613,5.91634044399086,7.88331842422485,25,1,64,0,0,0.137405395507812,31.2805480957031,2,1,1,276.034759521484,0,2084574272,276.034759521484,,,,,,,,,,,,,,,,,,,,,,,,,,,,,,,,,
,3873629677.75151,1.99971663951874,48105.125,0.292596035649668,0.00194725705241126,1,2,13.1008939743042,1.99651527584775,27.7800001204014,70.7266435862044,10.3912949568546,100,0.000105644176836872,,,,,,,,,,,,,,,,,,,,,1.99946558475494,1.99996769428253,48015.16015625,48195.08984375,52.9150783091498,5.85402263572043,2.60047912597656,23,1,68,0,0,0.139617919921875,30.7917900085449,1,6,1,1.99996769428253,0,2084573184,1.99971663951874,,,,,,,,,,,,,,,,,,,,,,,,,,,,,,,,,
,3873629737.29632,2.00036382675171,42157.955078125,0.283609652165376,5.94899865369166E-5,1,2,13.1008939743042,1.99621443203715,27.7800001204014,68.5293616919557,10.10685929385,100,0.000257920627745585,,,,,,,,,,,,,,,,,,,,,2.00019574165344,2.00053191184998,42063.03515625,42252.875,52.8060411307171,5.85776190592454,2.58965277671814,24,1,68,0,0,0.13885498046875,29.8142719268799,1,6,1,2.00053191184998,0,2084573184,2.00036382675171,,,,,,,,,,,,,,,,,,,,,,,,,,,,,,,,,
,3873629806.04064,2.00061416625977,35292.30078125,0.268127720194796,0.00011481751314993,1,2,13.1008939743042,1.99604552073156,27.7800001204014,64.773931958763,9.58158153405126,100,0.0003596252779172,,,,,,,,,,,,,,,,,,,,,2.00061416625977,2.00061416625977,35292.30078125,35292.30078125,52.5488853478902,5.85935320718097,2.58188009262085,25,1,68,0,0,0.143203735351562,30.7917900085449,1,6,1,2.00061416625977,0,2084573184,2.00061416625977,,,,,,,,,,,,,,,,,,,,,,,,,,,,,,,,,
,3873629891.43356,2.00030732154846,26764.6875,0.240697236223538,6.34983488062244E-5,1,2,13.1008939743042,1.9958454293333,27.7800001204014,58.1370421124295,8.59442354183176,100,0.000300929188349911,,,,,,,,,,,,,,,,,,,,,2.00030732154846,2.00030732154846,26764.6875,26764.6875,52.3659842743902,5.86164170886764,2.57832288742065,24,1,68,0,0,0.148696899414062,30.7917900085449,1,6,1,2.00030732154846,0,2084573184,2.00030732154846,,,,,,,,,,,,,,,,,,,,,,,,,,,,,,,,,
,3873629955.70328,1.9972710609436,20348.74609375,0.215608782522382,6.15350066957562E-5,1,2,13.1008939743042,1.99630569480971,27.7800001204014,52.1037277486633,7.67680846617532,1000,0.000165450123343576,,,,,,,,,,,,,,,,,,,,,1.99663913249969,1.99790298938751,20263.771484375,20433.720703125,52.2061412422074,5.85362260662821,2.56752157211304,25,1,68,0,0,0.138702392578125,30.7917900085449,1,6,1,1.99663913249969,0,2084573184,1.9972710609436,,,,,,,,,,,,,,,,,,,,,,,,,,,,,,,,,
,3873630029.04691,2.00008237361908,13023.7885742187,0.170230058290552,0.000100706699905819,1,2,13.1008939743042,1.99649103618428,27.7800001204014,41.1430659126759,6.07401723549209,100,0.000179707862700742,,,,,,,,,,,,,,,,,,,,,1.99996757507324,2.00019717216492,12933.7890625,13113.7880859375,51.950548716419,5.85478477450481,2.5633008480072,26,1,0,0,1,0.142974853515625,31.2805480957031,1,6,1,2.00019717216492,0,2084573184,2.00008237361908,,,,,,,,,,,,,,,,,,,,,,,,,,,,,,,,,
,3873630088.59567,2.00010520219803,7077.7314453125,0.113083324108259,0.000132253899201029,1,2,13.1008939743042,1.99643112207087,27.7800001204014,27.3322383324428,4.0171471010654,100,4.66692250918647E-5,,,,,,,,,,,,,,,,,,,,,1.99996411800385,2.00024628639221,6987.74365234375,7167.71923828125,52.0361370392747,5.85512101436887,2.55763816833496,26,1,0,0,1,0.144805908203125,31.2805480957031,1,6,1,1.99996411800385,0,2084573184,2.00010520219803,,,,,,,,,,,,,,,,,,,,,,,,,,,,,,,,,
,3873630163.99067,2.00001209974289,-459.865997314453,-0.00774116021640507,0.000346484954727643,1,2,13.1008939743042,1.9966819345208,27.7800001204014,-1.85996940350623,-0.353629001550195,100,-0.000328162932513695,,,,,,,,,,,,,,,,,,,,,1.99984896183014,2.00017523765564,-550.014709472656,-369.71728515625,52.0294931968613,5.84911531385897,2.55094599723816,24,1,68,0,0,0.143966674804688,31.2805480957031,1,6,1,2.00017523765564,0,2084573184,2.00001209974289,,,,,,,,,,,,,,,,,,,,,,,,,,,,,,,,,
,3873630223.53629,1.9998237490654,-6418.68041992188,-0.099191566874016,0.000126052583873057,1,2,13.1008939743042,1.99700628329835,27.7800001204014,-23.978882086646,-3.58569308713636,100,-0.000289480971197726,,,,,,,,,,,,,,,,,,,,,1.99927031993866,2.00037717819214,-6508.396484375,-6328.96435546875,52.0212860974094,5.84578068741165,2.54485630989075,26,1,0,0,1,0.14404296875,31.2805480957031,1,6,1,1.99927031993866,0,2084573184,1.9998237490654,,,,,,,,,,,,,,,,,,,,,,,,,,,,,,,,,
,3873630283.08269,2.00021123886108,-12375.9868164062,-0.157779001420858,9.17013223427334E-5,1,2,13.1008939743042,1.99693222475038,27.7800001204014,-38.1440802254552,-5.67064927038551,100,-0.000325945295836275,,,,,,,,,,,,,,,,,,,,,2.00001883506775,2.00040364265442,-12461.1044921875,-12290.869140625,52.0122973694382,5.84410077470492,2.54258823394775,26,1,0,0,1,0.142059326171875,31.2805480957031,1,6,1,2.00001883506775,0,2084573184,2.00021123886108,,,,,,,,,,,,,,,,,,,,,,,,,,,,,,,,,
,3873630342.64121,1.99997133016586,-18332.7294921875,-0.200045291528451,7.57899545540201E-5,1,2,13.1008939743042,1.99704990770563,27.7800001204014,-48.3667230603023,-7.19668681172933,100,-0.000438750190422407,,,,,,,,,,,,,,,,,,,,,1.99964225292206,2.00030040740967,-18422.78515625,-18242.673828125,52.2346706831594,5.84514414813639,2.5377950668335,26,1,0,0,1,0.142822265625,30.7917900085449,1,6,1,1.99964225292206,0,2084573184,1.99997133016586,,,,,,,,,,,,,,,,,,,,,,,,,,,,,,,,,
,3873630420.0452,2.00022566318512,-26075.8779296875,-0.237424049279928,5.914195110166E-5,1,2,13.1008939743042,1.99696636331543,27.7800001204014,-57.3998649557743,-8.53868116815847,100,-0.000512295551630521,,,,,,,,,,,,,,,,,,,,,1.99998617172241,2.00046515464783,-26166.107421875,-25985.6484375,52.3706740455055,5.84631354169332,2.53360462188721,26,1,0,0,1,0.139617919921875,30.7917900085449,1,6,1,1.99998617172241,0,2084573184,2.00022566318512,,,,,,,,,,,,,,,,,,,,,,,,,,,,,,,,,
,3873630531.34025,2.0001979470253,-37228.5703125,-0.271474747463798,5.5135187385735E-5,1,2,13.1008939743042,1.99695744124641,27.7800001204014,-65.6319073986974,-9.75999365773503,100,-0.000572540361282327,,,,,,,,,,,,,,,,,,,,,1.99969303607941,2.00070285797119,-37298.76171875,-37158.37890625,52.675118353746,5.84814480100058,2.53263306617737,26,1,0,0,1,0.142745971679688,30.7917900085449,1,6,1,1.99969303607941,0,2084573184,2.0001979470253,,,,,,,,,,,,,,,,,,,,,,,,,,,,,,,,,
,3873630639.59626,2.00007915496826,-48081.09765625,-0.290327491760337,0.00343173848401712,1,2,13.1008939743042,1.99709101713948,27.7800001204014,-70.1138757454001,-11.0176013000503,100,-0.0030041013226439,,,,,,,,,,,,,,,,,,,,,2.00007915496826,2.00007915496826,-48081.09765625,-48081.09765625,53.0487367859383,5.8496444528456,2.52955079078674,26,1,0,0,1,0.138626098632812,30.7917900085449,1,6,1,2.00007915496826,0,2084573184,2.00007915496826,,,,,,,,,,,,,,,,,,,,,,,,,,,,,,,,,
,3873630723.64248,2.00027894973755,-44202.828125,-0.288305228630963,5.32250682807982E-5,1,2,13.1008939743042,1.99729535617237,27.7800001204014,-69.7384285826869,-10.2645391985299,100,-0.000178692570216193,,,,,,,,,,,,,,,,,,,,,2.0002121925354,2.0003457069397,-44292.7109375,-44112.9453125,53.0202073449864,5.84683179896552,2.52589178085327,23,1,68,0,0,0.137710571289062,30.7917900085449,1,6,1,2.0002121925354,0,2084573248,2.00027894973755,,,,,,,,,,,,,,,,,,,,,,,,,,,,,,,,,
,3873630799.07301,2.0002002120018,-36674.478515625,-0.27278557305311,5.2248740076379E-5,1,2,13.1008939743042,1.997317724864,27.7800001204014,-65.984477037093,-9.72098387504117,100,-0.000205388618292251,,,,,,,,,,,,,,,,,,,,,1.99999988079071,2.00040054321289,-36764.4609375,-36584.49609375,52.656750083544,5.84940485576028,2.5229001045227,25,1,68,0,0,0.140914916992188,30.7917900085449,1,6,1,1.99999988079071,0,2084573536,2.0002002120018,,,,,,,,,,,,,,,,,,,,,,,,,,,,,,,,,
,3873630878.47958,2.000168800354,-28742.0068359375,-0.250226997005419,0.000171026895112696,1,2,13.1008939743042,1.99756308978822,27.7800001204014,-60.5502257925634,-8.86196226546041,1000,4.79863952968971E-5,,,,,,,,,,,,,,,,,,,,,1.99990463256836,2.00043296813965,-28826.93359375,-28657.080078125,52.3280752912075,5.84794701554397,2.52136898040771,26,1,0,0,1,0.14312744140625,29.8142719268799,1,6,1,1.99990463256836,0,2084573952,2.000168800354,,,,,,,,,,,,,,,,,,,,,,,,,,,,,,,,,
,3873630938.00982,2.00015830993652,-22801.0869140625,-0.227628962092791,6.64475557005929E-5,1,2,13.1008939743042,1.9977883554967,27.7800001204014,-55.091266245095,-8.07994883800622,1000,-2.48888761784638E-5,,,,,,,,,,,,,,,,,,,,,2.0001277923584,2.00018882751465,-22885.96875,-22716.205078125,52.2686715237459,5.84132730065521,2.52346134185791,26,1,0,0,1,0.142135620117188,31.2805480957031,1,6,1,2.00018882751465,0,2084574016,2.00015830993652,,,,,,,,,,,,,,,,,,,,,,,,,,,,,,,,,
,3873630997.56227,1.99992692470551,-16855.80078125,-0.1968489526936,0.000112436769429713,1,2,13.1008939743042,1.99767391816386,27.7800001204014,-47.637164650018,-6.98310089613881,1000,-6.9857890799809E-6,,,,,,,,,,,,,,,,,,,,,1.99976062774658,2.00009322166443,-16945.6953125,-16765.90625,52.1084376773036,5.8424699044281,2.5192699432373,26,1,0,0,1,0.142745971679688,30.7917900085449,1,6,1,2.00009322166443,0,2084573824,1.99992692470551,,,,,,,,,,,,,,,,,,,,,,,,,,,,,,,,,
,3873631070.96931,2.00015771389008,-9523.3720703125,-0.13996929174229,0.000116100122428105,1,2,13.1008939743042,1.99787881140739,27.7800001204014,-33.8764771789648,-4.98317718638371,100,-7.47213994392026E-5,,,,,,,,,,,,,,,,,,,,,2.00015187263489,2.00016355514526,-9613.4775390625,-9433.2666015625,51.8665236506016,5.84118820251282,2.51847124099731,25,1,68,0,0,0.141372680664062,30.7917900085449,1,6,1,2.00015187263489,0,2084573792,2.00015771389008,,,,,,,,,,,,,,,,,,,,,,,,,,,,,,,,,
,3873631130.49322,2.00002193450928,-3572.0673828125,-0.0671986479823341,0.000165895964388331,1,2,13.1008939743042,1.9979009475264,27.7800001204014,-16.2705304218948,-2.34987580470836,100,0.000140023163471028,,,,,,,,,,,,,,,,,,,,,1.99999260902405,2.00005125999451,-3666.88842773438,-3477.24633789063,52.0248034257459,5.83886074105238,2.52000379562378,26,1,0,0,1,0.142059326171875,30.3030319213867,1,6,1,1.99999260902405,0,2084573184,2.00002193450928,,,,,,,,,,,,,,,,,,,,,,,,,,,,,,,,,
,3873631199.96889,2.00015044212341,3376.68933105469,0.0598951293549485,0.000161424222658911,1,2,13.1008939743042,1.99810278643788,27.7800001204014,14.4899618904272,2.19705420372296,100,0.000297234115405816,,,,,,,,,,,,,,,,,,,,,2.00011992454529,2.00018095970154,3281.62084960937,3471.7578125,51.8473737518805,5.83796563584203,2.5169038772583,26,1,0,0,1,0.141983032226562,31.2805480957031,1,6,1,2.00020146369934,0,2084573184,2.00015044212341,,,,,,,,,,,,,,,,,,,,,,,,,,,,,,,,,
,3873631267.39767,1.99990493059158,10122.21875,0.141525305050436,0.000114266070587103,1,2,13.1008939743042,1.9983101891588,27.7800001204014,34.2573855084263,5.10686159905611,100,0.000349047146459289,,,,,,,,,,,,,,,,,,,,,1.99978291988373,2.00002694129944,10032.15625,10212.28125,52.0220677259286,5.83664812172032,2.51612901687622,25,1,68,0,0,0.135726928710938,31.2805480957031,1,6,1,1.99978291988373,0,2084573184,1.99990493059158,,,,,,,,,,,,,,,,,,,,,,,,,,,,,,,,,
,3873631334.89674,2.00001609325409,16875.412109375,0.193887990224039,0.000100574340875435,1,2,13.1008939743042,1.99822233908944,27.7800001204014,46.9353706687122,6.9475288974938,100,0.000279003969439159,,,,,,,,,,,,,,,,,,,,,1.99998092651367,2.00005125999451,16785.337890625,16965.486328125,52.0529420524382,5.83741714293608,2.51402711868286,26,1,0,0,1,0.139846801757812,29.8142719268799,1,6,1,2.00005125999451,0,2084573984,2.00001609325409,,,,,,,,,,,,,,,,,,,,,,,,,,,,,,,,,
,3873631404.35141,1.99972116947174,23818.0439453125,0.229126386718344,5.51706627247751E-5,1,2,13.1008939743042,1.99789667351553,27.7800001204014,55.4479395255031,8.21195724130122,100,0.000347381487844669,,,,,,,,,,,,,,,,,,,,,1.99953556060791,1.99990677833557,23727.98828125,23908.099609375,52.3394089047363,5.84041756306873,2.51289129257202,26,1,0,0,1,0.140914916992188,31.2805480957031,1,6,1,1.99953556060791,0,2084574080,1.99972116947174,,,,,,,,,,,,,,,,,,,,,,,,,,,,,,,,,
,3873631491.68287,2.00022673606873,32574.7138671875,0.259299311639799,5.29323587905297E-5,1,2,13.1008939743042,1.99794968737781,27.7800001204014,62.7514669886235,9.30331813844913,100,0.000432319721226609,,,,,,,,,,,,,,,,,,,,,2.00008058547974,2.00037288665771,32484.58984375,32664.837890625,52.6590949691017,5.83985999079913,2.51439499855042,26,1,0,0,1,0.142135620117188,31.2805480957031,1,6,1,2.00008058547974,0,2084573792,2.00022673606873,,,,,,,,,,,,,,,,,,,,,,,,,,,,,,,,,
,3873631614.76609,1.99995011091232,44908.228515625,0.289409681156583,7.26583446824691E-5,1,2,13.1008939743042,1.99789107591469,27.7800001204014,70.0350801574304,10.3784425655385,100,0.000463439438618304,,,,,,,,,,,,,,,,,,,,,1.99962747097015,2.00027275085449,44822.9609375,44993.49609375,52.8064319449767,5.84207321444474,2.51620697975159,26,1,0,0,1,0.140914916992188,32.7468223571777,1,6,1,1.99962747097015,0,2084573984,1.99995011091232,,,,,,,,,,,,,,,,,,,,,,,,,,,,,,,,,
,3873632109.48008,15.0696048736572,26.2053050994873,4.73496028668643E-5,5.68061684461133E-8,1,2,13.1008939743042,1.97820469013659,27.7800001204014,0.011249422796491,0.00163690999408308,1,-4.83322695811094E-8,,,,,,,,,,,,,,,,,,,,,15.0696048736572,15.0696048736572,26.2053050994873,26.2053050994873,51.7703833427362,5.84065963758156,5.33603572845459,26,1,0,0,1,0.132675170898438,30.7917900085449,6,1,1,15.0696048736572,0,2084574272,15.0696048736572,,,,,,,,,,,,,,,,,,,,,,,,,,,,,,,,,
,3873632301.49728,45.0326309204102,26.2053050994873,2.70078499526005E-5,2.05296775332393E-7,1,2,13.1008939743042,1.97888774353253,27.7999993413687,0.00642316620017322,0.000918080947403225,1,-9.57710741849918E-8,,,,,,,,,,,,,,,,,,,,,45.0326309204102,45.0326309204102,26.2053050994873,26.2053050994873,51.7641303145824,5.83278961456306,6.45427322387695,26,1,0,0,1,0.133514404296875,30.7917900085449,2,1,1,45.0326309204102,0,2084574176,45.0326309204102,,,,,,,,,,,,,,,,,,,,,,,,,,,,,,,,,
,3873632491.01959,75.0060806274414,26.2053050994873,2.18049600848761E-5,6.91859629898658E-8,1,2,13.1008939743042,1.98643817289028,27.8399996459484,0.00521797858888741,0.000783506478980765,1,7.68519405467137E-8,,,,,,,,,,,,,,,,,,,,,75.0060806274414,75.0060806274414,26.2053050994873,26.2053050994873,51.789924055717,5.84508132464845,6.78291368484497,25,1,64,0,0,0.13519287109375,30.7917900085449,2,1,1,75.0060806274414,0,2084574336,75.0060806274414,,,,,,,,,,,,,,,,,,,,,,,,,,,,,,,,,
,3873632674.85713,105.014793395996,26.2053050994873,1.77393170139452E-5,3.8654136509103E-8,1,2,13.1008939743042,1.9848203619926,27.8999991714954,0.00423957173062997,0.000629158134315517,1,3.20887112878403E-8,,,,,,,,,,,,,,,,,,,,,105.014793395996,105.014793395996,26.2053050994873,26.2053050994873,51.7903148699766,5.86395269435598,6.93955183029175,26,1,0,0,1,0.13763427734375,30.7917900085449,2,1,1,105.014793395996,0,2084574432,105.014793395996,,,,,,,,,,,,,,,,,,,,,,,,,,,,,,,,,
,3873632856.53636,135.033264160156,26.2053050994873,1.47877382260686E-5,3.59449641296107E-8,1,2,13.1008939743042,1.9839906297422,27.9699992388487,0.00353192490756399,0.0005202259890315,1,1.07028077395467E-8,,,,,,,,,,,,,,,,,,,,,135.033264160156,135.033264160156,26.2053050994873,26.2053050994873,51.7563140293901,5.87237490341732,7.03116941452026,26,1,0,0,1,0.1397705078125,31.2805480957031,2,1,1,135.033264160156,0,2084574272,135.033264160156,,,,,,,,,,,,,,,,,,,,,,,,,,,,,,,,,
,3873633037.41377,165.017791748047,26.2053050994873,1.30821233993352E-5,3.9557835479779E-8,1,2,13.1008939743042,1.98424517171325,28.0699990689754,0.00312398679497505,0.000469390549210135,1,4.73685714605984E-8,,,,,,,,,,,,,,,,,,,,,165.017791748047,165.017791748047,26.2053050994873,26.2053050994873,51.7914873127555,5.87116519774664,7.10929918289185,26,1,0,0,1,0.139923095703125,30.3030319213867,2,1,1,165.017791748047,0,2084574144,165.017791748047,,,,,,,,,,,,,,,,,,,,,,,,,,,,,,,,,
,3873633217.87929,195.024765014648,26.2053050994873,1.17142271932295E-5,4.08155207471648E-8,1,2,13.1008939743042,1.98122134500535,28.1899999827147,0.00278991787294158,0.000414561926398841,1,2.33852018822316E-8,,,,,,,,,,,,,,,,,,,,,195.024765014648,195.024765014648,26.2053050994873,26.2053050994873,51.9951015420151,5.8957287673109,7.21709394454956,26,1,0,0,1,0.140228271484375,31.2805480957031,2,1,1,195.024765014648,0,2084574272,195.024765014648,,,,,,,,,,,,,,,,,,,,,,,,,,,,,,,,,
,3873633399.68497,225.111557006836,26.2053050994873,1.07382358847782E-5,4.55770049297722E-8,1,2,13.1008939743042,1.97960517526976,28.3199995756149,0.00255354353564317,0.000379228355315199,1,2.05726734053607E-8,,,,,,,,,,,,,,,,,,,,,225.111557006836,225.111557006836,26.2053050994873,26.2053050994873,51.815326982592,5.90728234525411,7.42616987228394,26,1,0,0,1,0.140609741210938,30.3030319213867,2,1,1,225.111557006836,0,2084574304,225.111557006836,,,,,,,,,,,,,,,,,,,,,,,,,,,,,,,,,
,3873633579.78597,255.020706176758,26.2053050994873,9.88952972240558E-6,4.18720796549922E-8,1,2,13.1008939743042,1.99119102949155,28.4700002521276,0.00237951146559905,0.000342128780183985,1,-2.68480029530267E-8,,,,,,,,,,,,,,,,,,,,,255.020706176758,255.020706176758,26.2053050994873,26.2053050994873,52.0181595833324,5.90378474909295,7.77582931518555,24,1,64,0,0,0.138473510742188,33.2355842590332,2,1,1,255.020706176758,0,2084574272,255.020706176758,,,,,,,,,,,,,,,,,,,,,,,,,,,,,,,,,
,3873633760.40951,285.039184570313,26.2053050994873,9.16238602009636E-6,4.30110293645321E-8,1,2,13.1008939743042,1.99259545051155,28.6400001496077,0.00220630894506874,0.000325542580456843,1,8.94756638769398E-9,,,,,,,,,,,,,,,,,,,,,285.039184570313,285.039184570313,26.2053050994873,26.2053050994873,51.9216284612074,5.89029431016133,7.83641195297241,26,1,0,0,1,0.138015747070312,32.2580642700195,2,1,1,285.039184570313,0,2084574048,285.039184570313,,,,,,,,,,,,,,,,,,,,,,,,,,,,,,,,,
,3873634532.30266,287.932159423828,26.5143280029297,1.14427597861198E-5,9.12913917724253E-7,1,2,13.1008939743042,2.00451093990392,28.6400001496077,0.00275309073842304,0.000640708631756694,1,9.53505474900274E-7,,,,,,,,,,,,,,,,,,,,,287.932159423828,287.932159423828,26.5143280029297,26.5143280029297,51.9732159434767,5.88519986564912,8.65563488006592,26,1,0,0,1,0.139541625976562,30.7917900085449,2,1,1,287.932159423828,0,2084573184,287.932159423828,,,,,,,,,,,,,,,,,,,,,,,,,,,,,,,,,
,3873634697.24784,257.982635498047,26.5143280029297,1.19794634058877E-5,5.0967099303963E-8,1,2,13.1008939743042,2.0039036269243,28.5100005567074,0.00291861843919655,0.000410727452533279,1,-6.83870685768327E-8,,,,,,,,,,,,,,,,,,,,,257.982635498047,257.982635498047,26.5143280029297,26.5143280029297,52.0150330692555,5.8849120177901,8.37512111663818,25,1,64,0,0,0.14129638671875,30.3030319213867,2,1,1,257.982635498047,0,2084573184,257.982635498047,,,,,,,,,,,,,,,,,,,,,,,,,,,,,,,,,
,3873634878.23243,227.964309692383,26.5143280029297,1.24429168495291E-5,2.73144184553509E-7,1,2,13.1008939743042,2.00289110682072,28.3899996429682,0.00302908263611017,0.0004231304547799,1,-8.36922311142255E-8,,,,,,,,,,,,,,,,,,,,,227.964309692383,227.964309692383,26.5143280029297,26.5143280029297,52.3933412725632,5.87619574498015,8.13984394073486,26,1,0,0,1,0.142974853515625,30.3030319213867,2,1,1,227.964309692383,0,2084574080,227.964309692383,,,,,,,,,,,,,,,,,,,,,,,,,,,,,,,,,
,3873635055.4059,197.977127075195,26.5143280029297,1.23333740026357E-5,4.65097770997628E-8,1,2,13.1008939743042,2.00625844021753,28.2700005918741,0.00300898108204799,0.00044122339312568,1,9.94712354992026E-10,,,,,,,,,,,,,,,,,,,,,197.977127075195,197.977127075195,26.5143280029297,26.5143280029297,51.7766363708901,5.86397292311181,7.96482133865356,26,1,0,0,1,0.145339965820313,31.7693061828613,2,1,1,197.977127075195,0,2084573888,197.977127075195,,,,,,,,,,,,,,,,,,,,,,,,,,,,,,,,,
,3873635236.06631,167.998260498047,26.5143280029297,1.20642567158511E-5,4.87073277028273E-8,1,2,13.1008939743042,2.00671900712408,28.1700007617474,0.00294280299221509,0.000444072314127821,1,5.13208901837591E-8,,,,,,,,,,,,,,,,,,,,,167.998260498047,167.998260498047,26.5143280029297,26.5143280029297,51.7641303145824,5.85801652844754,7.81461000442505,25,1,64,0,0,0.14739990234375,30.7917900085449,2,1,1,167.998260498047,0,2084574080,167.998260498047,,,,,,,,,,,,,,,,,,,,,,,,,,,,,,,,,
,3873635416.0655,137.974151611328,26.5143280029297,1.20195811433099E-5,4.20474088936744E-8,1,2,13.1008939743042,2.00730502160155,28.0900001525879,0.00293486383151499,0.000433549468902918,1,1.3774101943987E-8,,,,,,,,,,,,,,,,,,,,,137.974151611328,137.974151611328,26.5143280029297,26.5143280029297,51.7770271851497,5.85488767997745,7.69324588775635,26,1,0,0,1,0.143203735351562,30.7917900085449,2,1,1,137.974151611328,0,2084573984,137.974151611328,,,,,,,,,,,,,,,,,,,,,,,,,,,,,,,,,
,3873635596.47012,107.976974487305,26.5143280029297,1.1246799778226E-5,6.50211954769293E-7,1,2,13.1008939743042,2.00856252209422,28.0099995434284,0.00274696281356624,0.000422986227564138,1,8.17211222223148E-8,,,,,,,,,,,,,,,,,,,,,107.976974487305,107.976974487305,26.5143280029297,26.5143280029297,51.8098555829574,5.84032369517697,7.56551027297974,26,1,0,0,1,0.1434326171875,30.7917900085449,2,1,1,107.976974487305,0,2084573856,107.976974487305,,,,,,,,,,,,,,,,,,,,,,,,,,,,,,,,,
,3873635773.93702,77.998893737793,26.5143280029297,1.2157959688322E-5,4.87818022861216E-8,1,2,13.1008939743042,2.00885621059627,27.9300007969141,0.00297201047463317,0.000445915841042768,1,4.14630469103894E-8,,,,,,,,,,,,,,,,,,,,,77.998893737793,77.998893737793,26.5143280029297,26.5143280029297,51.7500610012362,5.83640798968115,7.40824699401855,26,1,0,0,1,0.142669677734375,31.2805480957031,2,1,1,77.998893737793,0,2084573184,77.998893737793,,,,,,,,,,,,,,,,,,,,,,,,,,,,,,,,,
,3873635950.17703,47.9252319335937,26.5143280029297,1.31049682892705E-5,4.08280793071342E-8,1,2,13.1008939743042,2.01055103127485,27.8699994087219,0.00321124944668623,0.000463509246875467,1,-2.84117612348417E-8,,,,,,,,,,,,,,,,,,,,,47.9252319335937,47.9252319335937,26.5143280029297,26.5143280029297,51.8039933690632,5.82013216977264,7.14749336242676,26,1,0,0,1,0.138473510742188,31.2805480957031,2,1,1,47.9252319335937,0,2084573472,47.9252319335937,,,,,,,,,,,,,,,,,,,,,,,,,,,,,,,,,
,3873636126.45856,17.9836750030518,26.5143280029297,1.72435213056996E-5,4.21352412597445E-8,1,2,13.1008939743042,2.01074625215296,27.8099998831749,0.0042226865624082,0.000633559971878361,1,5.87852115818442E-8,,,,,,,,,,,,,,,,,,,,,17.9836750030518,17.9836750030518,26.5143280029297,26.5143280029297,51.8606614367074,5.81655319373957,6.31911039352417,26,1,0,0,1,0.141525268554688,30.3030319213867,2,1,1,17.9836750030518,0,2084573600,17.9836750030518,,,,,,,,,,,,,,,,,,,,,,,,,,,,,,,,,
,3873636482.81268,14.0349149703979,26.5143280029297,1.97541957020769E-5,4.30400956614579E-8,1,2,13.1008939743042,2.01024543648637,27.7900006622076,0.00483734841800395,0.000711033585772927,1,8.41565077790708E-9,,,,,,,,,,,,,,,,,,,,,14.0349149703979,14.0349149703979,26.5143280029297,26.5143280029297,51.764521128842,5.82062467405563,5.37882852554321,26,1,0,0,1,0.140609741210938,31.7693061828613,6,1,1,14.0349149703979,0,2084574240,14.0349149703979,,,,,,,,,,,,,,,,,,,,,,,,,,,,,,,,,
,3873636675.55207,44.026985168457,26.5143280029297,1.34475082209415E-5,4.38563017831906E-8,1,2,13.1008939743042,2.01071321614934,27.7999993413687,0.0032939622606546,0.000487478391500073,1,1.8932218759213E-8,,,,,,,,,,,,,,,,,,,,,44.026985168457,44.026985168457,26.5143280029297,26.5143280029297,51.8993520484093,5.81663030969816,6.52227449417114,26,1,0,0,1,0.137939453125,30.3030319213867,2,1,1,44.026985168457,0,2084574240,44.026985168457,,,,,,,,,,,,,,,,,,,,,,,,,,,,,,,,,
,3873636865.00347,74.0056457519531,26.5143280029297,1.2045203694295E-5,3.73587586043919E-8,1,2,13.1008939743042,2.00934979310798,27.8299991041422,0.00294638737693602,0.000438094602066294,1,2.51755553734973E-8,,,,,,,,,,,,,,,,,,,,,74.0056457519531,74.0056457519531,26.5143280029297,26.5143280029297,51.7371641306689,5.83229518928565,6.88917970657349,25,1,64,0,0,0.140457153320312,31.2805480957031,2,1,1,74.0056457519531,0,2084574304,74.0056457519531,,,,,,,,,,,,,,,,,,,,,,,,,,,,,,,,,
,3873637049.43085,104.039306640625,26.5143280029297,1.1320258167054E-5,3.6598622020709E-8,1,2,13.1008939743042,2.00898588289211,27.8999991714954,0.00276905954992551,0.000405096973514399,1,-2.87078105646808E-9,,,,,,,,,,,,,,,,,,,,,104.039306640625,104.039306640625,26.5143280029297,26.5143280029297,51.7770271851497,5.8345732423731,7.04251098632813,26,1,0,0,1,0.140533447265625,30.7917900085449,2,1,1,104.039306640625,0,2084574304,104.039306640625,,,,,,,,,,,,,,,,,,,,,,,,,,,,,,,,,
,3873637230.09323,134.016952514648,26.5143280029297,1.09761096501451E-5,3.94112137653291E-8,1,2,13.1008939743042,2.00848892768025,27.9699992388487,0.00268302461318852,0.000396658719137559,1,1.38270756590069E-8,,,,,,,,,,,,,,,,,,,,,134.016952514648,134.016952514648,26.5143280029297,26.5143280029297,51.7250488886209,5.84152165857079,7.13083505630493,26,1,0,0,1,0.1446533203125,31.2805480957031,2,1,1,134.016952514648,0,2084574272,134.016952514648,,,,,,,,,,,,,,,,,,,,,,,,,,,,,,,,,
,3873637411.27498,164.007736206055,26.5143280029297,1.06941153179194E-5,4.15126586675865E-8,1,2,13.1008939743042,2.00718236695025,28.0699990689754,0.00261012827219008,0.000391083778588686,1,3.43237180916158E-8,,,,,,,,,,,,,,,,,,,,,164.007736206055,164.007736206055,26.5143280029297,26.5143280029297,51.830568738717,5.85293473550834,7.21065378189087,26,1,0,0,1,0.146255493164062,30.7917900085449,2,1,1,164.007736206055,0,2084574272,164.007736206055,,,,,,,,,,,,,,,,,,,,,,,,,,,,,,,,,
,3873637592.55351,194.001281738281,26.5143280029297,1.04802235183109E-5,4.75989154683461E-8,1,2,13.1008939743042,2.00495398042858,28.1799994409084,0.0025528018725468,0.000380727001844221,1,2.65399794559138E-8,,,,,,,,,,,,,,,,,,,,,194.001281738281,194.001281738281,26.5143280029297,26.5143280029297,51.8364309526113,5.87319058334658,7.29247617721558,26,1,0,0,1,0.149154663085938,31.2805480957031,2,1,1,194.001281738281,0,2084574240,194.001281738281,,,,,,,,,,,,,,,,,,,,,,,,,,,,,,,,,
,3873637773.52143,224.066665649414,26.5143280029297,1.02302805412012E-5,4.11688462903731E-8,1,2,13.1008939743042,2.00341177517817,28.3199995756149,0.00248855576623546,0.00036929968993949,1,1.84841688070615E-8,,,,,,,,,,,,,,,,,,,,,224.066665649414,224.066665649414,26.5143280029297,26.5143280029297,52.0408268103901,5.88327558896527,7.43355846405029,26,1,0,0,1,0.135345458984375,30.7917900085449,2,1,1,224.066665649414,0,2084574240,224.066665649414,,,,,,,,,,,,,,,,,,,,,,,,,,,,,,,,,
,3873637953.85794,254.011123657227,26.5143280029297,1.00245156663829E-5,4.86308489721644E-8,1,2,13.1008939743042,2.00349642123277,28.4599997103214,0.00244000786224309,0.000352961643160841,1,-1.86232247509849E-8,,,,,,,,,,,,,,,,,,,,,254.011123657227,254.011123657227,26.5143280029297,26.5143280029297,51.960709887169,5.8766640442339,7.66441917419434,26,1,0,0,1,0.135879516601562,31.2805480957031,2,1,1,254.011123657227,0,2084574272,254.011123657227,,,,,,,,,,,,,,,,,,,,,,,,,,,,,,,,,
,3873638134.55307,284.061004638672,26.5143280029297,9.67264272047174E-6,5.1298072272523E-8,1,2,13.1008939743042,2.00414016777204,28.6400001496077,0.00235465283955984,0.000348562999137425,1,1.39972494302634E-8,,,,,,,,,,,,,,,,,,,,,284.061004638672,284.061004638672,26.5143280029297,26.5143280029297,52.0353554107555,5.86862863594132,7.69620990753174,26,1,0,0,1,0.142822265625,31.2805480957031,2,1,1,284.061004638672,0,2084574336,284.061004638672,,,,,,,,,,,,,,,,,,,,,,,,,,,,,,,,,
,3873638517.1323,300.003173828125,45452.802734375,0.00931935092566232,1.4708462610058E-5,1,2,13.1008939743042,2.00477621524985,28.7200007587671,2.2864785724522,0.223683366929978,100,-0.00044766101974935,,,,,,,,,,,,,,,,,,,,,300.003051757812,300.003295898438,45367.8828125,45537.72265625,51.7867975416401,5.86351467496534,7.69030714035034,25,1,68,0,0,0.138015747070312,30.3030319213867,1,6,1,300.003051757812,0,2084573184,300.003173828125,,,,,,,,,,,,,,,,,,,,,,,,,,,,,,,,,
,3873638592.45401,300.001724243164,37928.33984375,0.00779351131230225,2.57215132985104E-5,1,2,13.1008939743042,2.00476192739682,28.7200007587671,1.91024157760786,0.199683702497154,100,-0.000322541168282673,,,,,,,,,,,,,,,,,,,,,300.001708984375,300.001739501953,37838.86328125,38017.81640625,51.960709887169,5.87073953199428,7.78969430923462,25,1,68,0,0,0.137481689453125,31.2805480957031,1,6,1,300.001708984375,0,2084573184,300.001724243164,,,,,,,,,,,,,,,,,,,,,,,,,,,,,,,,,
,3873638661.26414,300.001983642578,31057.78515625,0.00632114704651637,0.000135449722047535,1,2,13.1008939743042,2.00534307759482,28.7200007587671,1.5522838074652,0.147869919096329,100,-0.000319769630097122,,,,,,,,,,,,,,,,,,,,,300.001983642578,300.001983642578,31057.78515625,31057.78515625,51.9380426601113,5.86729113772659,7.92264175415039,25,1,68,0,0,0.148849487304687,31.2805480957031,1,6,1,300.001983642578,0,2084573696,300.001983642578,,,,,,,,,,,,,,,,,,,,,,,,,,,,,,,,,
,3873638729.46498,300.000915527344,24247.6875,0.00504223942843336,6.68375870690162E-6,1,2,13.1008939743042,2.00541472813552,28.7200007587671,1.23571522978756,0.135640646810725,100,-0.000182548152248638,,,,,,,,,,,,,,,,,,,,,300.000885009766,300.000946044922,24167.755859375,24327.619140625,51.891535763217,5.86605491448257,8.10795783996582,26,1,0,0,1,0.144119262695313,30.7917900085449,1,6,1,300.000885009766,0,2084573920,300.000915527344,,,,,,,,,,,,,,,,,,,,,,,,,,,,,,,,,
,3873638788.93285,300.000854492188,18306.0419921875,0.00385291251803978,7.32087857534682E-6,1,2,13.1008939743042,2.00568671938069,28.7200007587671,0.945156197581974,0.0991017011628886,100,-0.000158238375339031,,,,,,,,,,,,,,,,,,,,,300.000793457031,300.000915527344,18216.109375,18395.974609375,51.9185019471305,5.86301135392241,8.29567813873291,26,1,0,0,1,0.144577026367187,30.7917900085449,1,6,1,300.000793457031,0,2084574016,300.000854492188,,,,,,,,,,,,,,,,,,,,,,,,,,,,,,,,,
,3873638848.5176,300.001068115234,12359.0268554687,0.00266545817172501,5.62194796747006E-6,1,2,13.1008939743042,2.00564031982289,28.7200007587671,0.655136910242332,0.059663302602995,100,-0.000145940136735053,,,,,,,,,,,,,,,,,,,,,300.001037597656,300.001098632812,12274.0693359375,12443.984375,52.0154238835151,5.8643050054938,8.49496364593506,26,1,0,0,1,0.149688720703125,30.7917900085449,1,6,1,300.001037597656,0,2084573696,300.001068115234,,,,,,,,,,,,,,,,,,,,,,,,,,,,,,,,,
,3873638916.03132,300.000640869141,5612.50244140625,0.00132640953354762,4.69434406280717E-5,1,2,13.1008939743042,2.00572999641266,28.7200007587671,0.331893018379198,-0.0102261114862509,100,-0.000236325182028681,,,,,,,,,,,,,,,,,,,,,300.000518798828,300.000762939453,5527.48974609375,5697.51513671875,52.0345737822363,5.86494905432903,8.70742321014404,26,1,0,0,1,0.143356323242188,31.2805480957031,1,6,1,300.000762939453,0,2084573600,300.000640869141,,,,,,,,,,,,,,,,,,,,,,,,,,,,,,,,,
,3873638983.52523,300.000442504883,-1135.07281494141,-0.000260420466680716,2.75854162260741E-5,1,2,13.1008939743042,2.00506205897843,28.7200007587671,-0.0550685195650077,-0.0665868926249499,100,-0.000235069769314861,,,,,,,,,,,,,,,,,,,,,300.000427246094,300.000457763672,-1220.11645507812,-1050.02917480469,51.9442956882651,5.86849047026671,8.88347625732422,25,1,68,0,0,0.139083862304688,29.8142719268799,1,6,1,300.000427246094,0,2084573280,300.000442504883,,,,,,,,,,,,,,,,,,,,,,,,,,,,,,,,,
,3873639052.88728,300.000823974609,-8070.36181640625,-0.00170362696756892,6.31387897697775E-6,1,2,13.1008939743042,2.00541483723569,28.7200007587671,-0.411854564580319,-0.0844358091874935,100,-9.66898956130099E-5,,,,,,,,,,,,,,,,,,,,,300.000610351562,300.001037597656,-8160.43017578125,-7980.29345703125,51.9263182323228,5.86341870085651,8.83331871032715,26,1,0,0,1,0.143356323242188,30.7917900085449,1,6,1,300.001037597656,0,2084573184,300.000823974609,,,,,,,,,,,,,,,,,,,,,,,,,,,,,,,,,
,3873639116.45044,300.000198364258,-14427.212890625,-0.00300163525053486,9.47601811739108E-6,1,2,13.1008939743042,2.00532200372696,28.7200007587671,-0.730987429099239,-0.111902409939086,10,-1.91729578951001E-5,,,,,,,,,,,,,,,,,,,,,300.000061035156,300.000335693359,-14512.3125,-14342.11328125,51.9313988176978,5.86416316779719,8.77012729644775,26,1,0,0,1,0.1409912109375,31.2805480957031,1,6,1,300.000061035156,0,2084574080,300.000198364258,,,,,,,,,,,,,,,,,,,,,,,,,,,,,,,,,
,3873639175.96762,300.000228881836,-20383.9189453125,-0.00420465892143637,5.28159787491512E-6,1,2,13.1008939743042,2.00546631373392,28.7200007587671,-1.02427345046698,-0.15558280302021,10,-2.19749310505495E-5,,,,,,,,,,,,,,,,,,,,,299.999938964844,300.000518798828,-20474.068359375,-20293.76953125,51.9579741873517,5.86447067334857,8.71847534179688,26,1,0,0,1,0.144119262695313,31.2805480957031,1,6,1,299.999938964844,0,2084573760,300.000228881836,,,,,,,,,,,,,,,,,,,,,,,,,,,,,,,,,
,3873639245.42914,300.000244140625,-27333.4609375,-0.00557782114363982,1.23133678733941E-5,1,2,13.1008939743042,2.00515460162457,28.7200007587671,-1.35857330980324,-0.205026329187544,10,-2.37923637212503E-5,,,,,,,,,,,,,,,,,,,,,300.000152587891,300.000335693359,-27418.671875,-27248.25,51.8438564235439,5.86589917136161,8.66942119598389,24,1,68,0,0,0.149307250976562,31.2805480957031,1,6,1,300.000152587891,0,2084574016,300.000244140625,,,,,,,,,,,,,,,,,,,,,,,,,,,,,,,,,
,3873639322.80415,299.999282836914,-35090.1875,-0.00710431837178246,5.57818222833369E-6,1,2,13.1008939743042,2.00516801544609,28.7200007587671,-1.73118427273093,-0.255785706521756,10,-8.33593166032569E-6,,,,,,,,,,,,,,,,,,,,,299.999267578125,299.999298095703,-35185.4296875,-34994.9453125,51.886455177842,5.86586364527128,8.62386703491211,24,1,68,0,0,0.1434326171875,30.7917900085449,1,6,1,299.999298095703,0,2084573920,299.999282836914,,,,,,,,,,,,,,,,,,,,,,,,,,,,,,,,,
,3873639402.21557,300.000595092773,-43046.216796875,-0.00881032271437983,0.000133115914421419,1,2,13.1008939743042,2.00550113957114,28.7200007587671,-2.1495568636862,-0.303818946047551,100,4.49946835303107E-5,,,,,,,,,,,,,,,,,,,,,300.000549316406,300.000640869141,-43131.49609375,-42960.9375,51.8946622772939,5.86735690037426,8.58617973327637,26,1,0,0,1,0.140533447265625,31.2805480957031,1,6,1,300.000549316406,0,2084573920,300.000595092773,,,,,,,,,,,,,,,,,,,,,,,,,,,,,,,,,
,3873639481.66188,300.000732421875,-49572.9140625,-0.0102812354919874,1.16081042199274E-5,1,2,13.1008939743042,2.00566463435835,28.7200007587671,-2.53304233600362,-0.189315815628227,100,0.000730343095843625,,,,,,,,,,,,,,,,,,,,,300.000579833984,300.000885009766,-49662.8203125,-49483.0078125,51.8043841833228,5.86706736076008,8.55243015289307,22,1,68,0,0,0.142135620117188,31.7693061828613,1,6,1,300.000885009766,0,2084574208,300.000732421875,,,,,,,,,,,,,,,,,,,,,,,,,,,,,,,,,
,3873639541.13965,300.000503540039,-43637.623046875,-0.00899486109902183,1.6645552223388E-5,1,2,13.1008939743042,2.00548912058217,28.7200007587671,-2.21093720056574,-0.198402107711472,100,0.000504422260887363,,,,,,,,,,,,,,,,,,,,,300.000457763672,300.000549316406,-43722.5,-43552.74609375,51.8395574666882,5.86658077476365,8.53183937072754,23,1,68,0,0,0.143051147460938,31.2805480957031,1,6,1,300.000549316406,0,2084574336,300.000503540039,,,,,,,,,,,,,,,,,,,,,,,,,,,,,,,,,
,3873639600.69358,300.000122070313,-37687.20703125,-0.00780200083380607,4.45718183011608E-5,1,2,13.1008939743042,2.00546272290648,28.7200007587671,-1.9171798859517,-0.175528421424071,100,0.000423409856418884,,,,,,,,,,,,,,,,,,,,,299.999969482422,300.000274658203,-37772.1171875,-37602.296875,51.8911449489574,5.86587166686014,8.51555252075195,25,1,68,0,0,0.143508911132812,30.7917900085449,1,6,1,300.000274658203,0,2084573984,300.000122070313,,,,,,,,,,,,,,,,,,,,,,,,,,,,,,,,,
,3873639660.22725,300.000259399414,-31741.7177734375,-0.00656545378806497,3.29169141513703E-5,1,2,13.1008939743042,2.00597251239431,28.7200007587671,-1.61246766297759,-0.158923556024345,100,0.000310615007460516,,,,,,,,,,,,,,,,,,,,,300,300.000518798828,-31831.248046875,-31652.1875,51.8962255343324,5.85950588623732,8.49795627593994,25,1,68,0,0,0.146942138671875,32.7468223571777,1,6,1,300,0,2084573920,300.000259399414,,,,,,,,,,,,,,,,,,,,,,,,,,,,,,,,,
,3873639727.65958,299.999755859375,-25012.0791015625,-0.00521278794217939,4.26777506229093E-5,1,2,13.1008939743042,2.00630405937451,28.7200007587671,-1.28057403900929,-0.126774595681523,100,0.00024434818109171,,,,,,,,,,,,,,,,,,,,,299.999603271484,299.999908447266,-25102.048828125,-24922.109375,51.9700894293997,5.85332300926124,8.48313522338867,24,1,68,0,0,0.141067504882812,31.2805480957031,1,6,1,299.999908447266,0,2084574080,299.999755859375,,,,,,,,,,,,,,,,,,,,,,,,,,,,,,,,,
,3873639795.13351,300.000183105469,-18272.69921875,-0.00391549082532085,4.049975840477E-5,1,2,13.1008939743042,2.00606212874803,28.7200007587671,-0.961647823866196,-0.0952875705404932,100,0.000183189710546572,,,,,,,,,,,,,,,,,,,,,300.000061035156,300.000305175781,-18362.587890625,-18182.810546875,51.9368702173324,5.85656456019294,8.46653366088867,26,1,0,0,1,0.143966674804688,31.2805480957031,1,6,1,300.000305175781,0,2084573856,300.000183105469,,,,,,,,,,,,,,,,,,,,,,,,,,,,,,,,,
,3873639854.64233,300.000549316406,-12331.4370117188,-0.00267980581348541,1.49045731481795E-5,1,2,13.1008939743042,2.0060592506661,28.7200007587671,-0.65929493389103,-0.0574767257694852,100,0.000157103623728338,,,,,,,,,,,,,,,,,,,,,300.000213623047,300.000885009766,-12421.44921875,-12241.4248046875,52.0189412118517,5.85633041211369,8.45234107971191,26,1,0,0,1,0.147323608398438,30.7917900085449,1,6,1,300.000885009766,0,2084573856,300.000549316406,,,,,,,,,,,,,,,,,,,,,,,,,,,,,,,,,
,3873639914.21645,299.999374389648,-6374.59497070312,-0.00148557399464936,1.28003225754907E-5,1,2,13.1008939743042,2.00605715712096,28.7200007587671,-0.36968710378161,-0.00319139995903729,100,0.000204632056957853,,,,,,,,,,,,,,,,,,,,,299.999328613281,299.999420166016,-6464.2060546875,-6284.98388671875,51.8606614367074,5.85614787188365,8.44533920288086,26,1,0,0,1,0.14373779296875,30.7917900085449,1,6,1,299.999420166016,0,2084573184,299.999374389648,,,,,,,,,,,,,,,,,,,,,,,,,,,,,,,,,
,3873639973.77831,299.999221801758,-422.727401733398,-0.000268893804344582,4.19061337773046E-5,1,2,13.1008939743042,2.00599978808184,28.7200007587671,-0.080988796384737,0.0954819786728052,100,0.000430864842091482,,,,,,,,,,,,,,,,,,,,,299.998992919922,299.999450683594,-507.839019775391,-337.615783691406,51.9548476732747,5.85809191501447,8.43373966217041,24,1,68,0,0,0.14068603515625,31.2805480957031,1,6,1,299.998992919922,0,2084573216,299.999221801758,,,,,,,,,,,,,,,,,,,,,,,,,,,,,,,,,
,3873640033.31075,299.999282836914,5526.8408203125,0.00117626145750432,1.95389834939799E-5,1,2,13.1008939743042,2.00603172875085,28.7200007587671,0.281925223696125,0.0760975248208256,100,0.000139590948688568,,,,,,,,,,,,,,,,,,,,,299.998992919922,299.999572753906,5441.80322265625,5611.87841796875,51.904823448044,5.85780963796201,8.42612075805664,26,1,0,0,1,0.143508911132812,31.2805480957031,1,6,1,299.999572753906,0,2084573184,299.999282836914,,,,,,,,,,,,,,,,,,,,,,,,,,,,,,,,,
,3873640102.76331,300.000930786133,12474.32421875,0.00262170781020888,1.12175286407297E-5,1,2,13.1008939743042,2.00606399152453,28.7200007587671,0.637433740183228,0.107888695683394,100,5.80765525368061E-5,,,,,,,,,,,,,,,,,,,,,300.000915527344,300.000946044922,12384.255859375,12564.392578125,51.8669144648613,5.85721667723495,8.41663455963135,26,1,0,0,1,0.142822265625,31.2805480957031,1,6,1,300.000915527344,0,2084573664,300.000930786133,,,,,,,,,,,,,,,,,,,,,,,,,,,,,,,,,
,3873640166.22994,300.000473022461,18827.3740234375,0.00389950833161554,5.5817457613746E-6,1,2,13.1008939743042,2.00600827186209,28.7200007587671,0.950056918914475,0.146867462689866,10,3.06383095145978E-5,,,,,,,,,,,,,,,,,,,,,300.000366210937,300.000579833984,18737.275390625,18917.47265625,52.011515740919,5.856350123953,8.40626049041748,26,1,0,0,1,0.148544311523438,30.7917900085449,1,6,1,300.000579833984,0,2084574208,300.000473022461,,,,,,,,,,,,,,,,,,,,,,,,,,,,,,,,,
,3873640235.72256,300.00016784668,25774.9248046875,0.00528275895612425,7.53143015770726E-6,1,2,13.1008939743042,2.00590248317849,28.7200007587671,1.28817903373994,0.19046823928994,10,6.74994286933285E-6,,,,,,,,,,,,,,,,,,,,,299.999908447266,300.000427246094,25679.640625,25870.208984375,51.967744543842,5.85929314174455,8.3995885848999,25,1,68,0,0,0.140914916992188,31.2805480957031,1,6,1,299.999908447266,0,2084573824,300.00016784668,,,,,,,,,,,,,,,,,,,,,,,,,,,,,,,,,
,3873640295.24846,300.000076293945,31743.3115234375,0.00647375158444378,5.20142117785175E-6,1,2,13.1008939743042,2.00609566968909,28.7200007587671,1.57860196682802,0.235387022598233,10,1.62055217847505E-5,,,,,,,,,,,,,,,,,,,,,300.000061035156,300.000091552734,31653.373046875,31833.25,51.8852827350632,5.85866274469683,8.39022445678711,24,1,68,0,0,0.141525268554688,31.2805480957031,1,6,1,300.000091552734,0,2084573920,300.000076293945,,,,,,,,,,,,,,,,,,,,,,,,,,,,,,,,,
,3873640386.62205,299.999359130859,40904.0390625,0.00828635614752595,7.45027298019028E-6,1,2,13.1008939743042,2.00618158237382,28.7200007587671,2.02100510726966,0.299667487719785,100,1.39766976475025E-5,,,,,,,,,,,,,,,,,,,,,299.999359130859,299.999359130859,40813.80859375,40994.26953125,51.7590497292074,5.85819322227491,8.38178157806397,26,1,0,0,1,0.141525268554688,30.7917900085449,1,6,1,299.999359130859,0,2084573920,299.999359130859,,,,,,,,,,,,,,,,,,,,,,,,,,,,,,,,,
,3873640446.09866,300.000152587891,46863.3046875,0.00780340398507018,0.00153662231086467,1,2,13.1008939743042,2.00609682595431,28.7200007587671,1.89684957078554,0.32457644774652,100,0.000186965668990729,,,,,,,,,,,,,,,,,,,,,300.000061035156,300.000244140625,46778.05078125,46948.55859375,51.774682299592,5.85911798370462,8.37707138061523,26,1,0,0,1,0.143890380859375,30.7917900085449,1,6,1,300.000061035156,0,2084573856,300.000152587891,,,,,,,,,,,,,,,,,,,,,,,,,,,,,,,,,
,3873640479.85739,300,50000.4296875,0.0100572481393473,4.74307560765665E-6,1,2,13.1008939743042,2.00616525998026,28.7200007587671,2.45132110227607,0.374340978951773,100,6.05649541544938E-5,,,,,,,,,,,,,,,,,,,,,299.999969482422,300.000030517578,50000.421875,50000.4375,51.8090739544382,5.85601773212754,8.37431240081787,26,1,0,0,1,0.142898559570312,30.7917900085449,1,4,1,300.000030517578,0,2084573984,300,,,,,,,,,,,,,,,,,,,,,,,,,,,,,,,,,