File: LT data/Frome/M1/310_FR_FULL_SEQUENCE.dat
[Header]
; MPMS3 Data File (default extension .dat)
; Copyright (c) 2007, Quantum Design, Inc. All rights reserved.
TITLE,
FILEOPENTIME,3873604014.51394,09/29/2022,11:18 am
BYAPP,MPMS3 w/ AC,1.0,1.1
INFO,MPMS3 Measurement Release 1.1.16 Build 424, MultiVu Release 2.3.4.19,APPNAME
INFO,Linear Motor Servo Controller,MOTOR_MODULE_NAME
INFO,3101-100 N0,MOTOR_HW_VERSION
INFO,MMC1047,MOTOR_SERIAL_NUMBER
INFO,01.04.28,MOTOR_SOFTWARE_VERSION
INFO,Quantum Design Squid Module,SQUID_MODULE_NAME
INFO,3101-501 B0,SQUID_HW_VERSION
INFO,SQM278,SQUID_SERIAL_NUMBER
INFO,01.03.04,SQUID_SOFTWARE_VERSION
INFO,Quantum Design VSM Oven,OVEN_MODULE_NAME
INFO,3101-201 A3,OVEN_HW_VERSION
INFO,OVB323,OVEN_SERIAL_NUMBER
INFO,01.07.07,OVEN_SOFTWARE_VERSION
INFO,SQUID AC,AC_MODULE_NAME
INFO,3101-401 G0,AC_HW_VERSION
INFO,SAC258,AC_SERIAL_NUMBER
INFO,SQUID AC 00.95.07,AC_SOFTWARE_VERSION
INFO,TCI127,COIL_SERIAL_NUMBER
INFO,0,MOMENT_UNITS
INFO,lmst,SAMPLE_MATERIAL
INFO,,SAMPLE_COMMENT
INFO,,SAMPLE_MASS
INFO,,SAMPLE_VOLUME
INFO,,SAMPLE_MOLECULAR_WEIGHT
INFO,,SAMPLE_SIZE
INFO,,SAMPLE_SHAPE
INFO,Straw,SAMPLE_HOLDER
INFO,Standard,SAMPLE_HOLDER_DETAIL
INFO,64.94,SAMPLE_OFFSET
DATATYPE,COMMENT,1
DATATYPE,TIME,2
STARTUPAXIS,X,2
STARTUPAXIS,Y1,5
FIELDGROUP, VSM,2,3,4,5,6,8,9,10,11,14,15
FIELDGROUP, DC, 2,3,4,14,56,57,58,59,60,61,62,63,64,65,66,67,68,69
FIELDGROUP, AC, 2,3,4,11,16,17,18,19,20,21,22,23,24,25,26,27,28,29,30
STARTUPGROUP, All
[Data]
Comment,Time Stamp (sec),Temperature (K),Magnetic Field (Oe),Moment (emu),M. Std. Err. (emu),Transport Action,Averaging Time (sec),Frequency (Hz),Peak Amplitude (mm),Center Position (mm),Lockin Signal' (V),Lockin Signal (V),Range,M. Quad. Signal (emu),AC Moment (emu),AC M. Std Err. (emu),AC Phase (deg),AC Phase Std. Err. (deg),AC Susceptibility (emu/Oe),AC Suscept. Std Err. (emu/Oe),AC X' (emu/Oe),AC X' Std Err. (emu/Oe),AC X'' (emu/Oe),AC X'' Std Err. (emu/Oe),AC Drive (Oe),AC Frequency (Hz),AC Averaging Time (sec),AC Cycles,AC Range,AC Measure Type,AC Signal' (V),AC Signal'' (V),AC Trim Coil Ratio,AC Trim Coil Phase,Min. Temperature (K),Max. Temperature (K),Min. Field (Oe),Max. Field (Oe),Mass (grams),Motor Lag (deg),Pressure (Torr),Measure Count,Measurement Number,SQUID Status (code),Motor Status (code),Measure Status (code),Motor Current (amps),Motor Temp. (C),Temp. Status (code),Field Status (code),Chamber Status (code),Chamber Temp (K),Redirection State,Evercool Status,Average Temp (K),Rotation Angle (deg),Rotator state,DC Moment Fixed Ctr (emu),DC Moment Err Fixed Ctr (emu),DC Moment Free Ctr (emu),DC Moment Err Free Ctr (emu),DC Fixed Fit,DC Free Fit,DC Calculated Center (mm),DC Calculated Center Err (mm),DC Scan Length (mm),DC Scan Time (s),DC Number of Points,DC Squid Drift,DC Min V (V),DC Max V (V),DC Scans per Measure,Map 01,Map 02,Map 03,Map 04,Map 05,Map 06,Map 07,Map 08,Map 09,Map 10,Map 11,Map 12,Map 13,Map 14,Map 15,Map 16
"FC",3873604208.04454
,3873605113.83931,89.9965858459473,49999.55859375,0.00580563246665346,1.70394560615589E-5,1,2,13.1008939743042,4.99930105672814,31.2200002372265,6.74753682548372,0.976328292393065,10,-1.05689462602495E-5,,,,,,,,,,,,,,,,,,,,,89.8498153686523,90.1433563232422,49999.55859375,49999.55859375,50.6038027777842,5.84283727666442,7.40176153182983,26,1,0,0,1,0.311126708984375,32.2580642700195,2,1,1,89.8498153686523,0,2084573184,89.9965858459473,,,,,,,,,,,,,,,,,,,,,,,,,,,,,,,,,
,3873605226.94439,71.4029388427734,49999.55859375,0.00789035020391324,5.33816116866031E-5,1,2,13.1008939743042,5.00046921818323,31.1600007116795,9.16373633225282,1.3938147842554,100,4.2821505773169E-5,,,,,,,,,,,,,,,,,,,,,71.2284851074219,71.577392578125,49999.55859375,49999.55859375,51.2935899460054,5.83403330710453,7.26008129119873,26,1,0,0,1,0.309982299804687,32.7468223571777,2,1,1,71.2284851074219,0,2084573184,71.4029388427734,,,,,,,,,,,,,,,,,,,,,,,,,,,,,,,,,
,3873605371.9846,46.6969871520996,49999.55859375,0.0130974448901824,0.000232922482951463,1,2,13.1008939743042,5.00026158936908,31.1099998652935,15.1866276222102,2.47500046439587,1000,0.000210033849276744,,,,,,,,,,,,,,,,,,,,,46.5746040344238,46.8193702697754,49999.55859375,49999.55859375,51.6461044081785,5.83708709724337,6.95262765884399,26,1,0,0,1,0.308761596679687,33.2355842590332,2,1,1,46.5746040344238,0,2084573184,46.6969871520996,,,,,,,,,,,,,,,,,,,,,,,,,,,,,,,,,
,3873605499.93153,25.0326156616211,49999.55859375,0.0232632382413455,6.63506173899184E-5,1,2,13.1008939743042,4.99832472458634,31.08000010252,27.0243490292909,3.95013114076574,1000,-8.74031069693863E-6,,,,,,,,,,,,,,,,,,,,,25.0326156616211,25.0326156616211,49999.55859375,49999.55859375,51.4030179386978,5.84874701510234,6.3779935836792,26,1,0,0,1,0.310897827148438,31.7693061828613,2,1,1,25.0326156616211,0,2084573184,25.0326156616211,,,,,,,,,,,,,,,,,,,,,,,,,,,,,,,,,
,3873605631.86209,5.41377830505371,49999.55859375,0.0514371630807549,9.89916925566864E-5,1,2,13.1008939743042,4.99053416702402,31.0500003397465,59.6301911451055,8.66567649734431,1000,-6.19209695071457E-5,,,,,,,,,,,,,,,,,,,,,5.27283668518066,5.55471992492676,49999.55859375,49999.55859375,50.8031180501881,5.89130602591997,4.01885271072388,26,1,0,0,1,0.32012939453125,33.2355842590332,6,1,1,5.27283668518066,0,2084573184,5.41377830505371,,,,,,,,,,,,,,,,,,,,,,,,,,,,,,,,,
,3873605774.78403,4.22558403015137,49999.55859375,0.053681770918222,6.40600104722584E-5,1,2,13.1008939743042,4.99715154881832,31.0500003397465,62.3523910537582,9.03006178617751,1000,-9.09432307884096E-5,,,,,,,,,,,,,,,,,,,,,4.22200298309326,4.22916507720947,49999.55859375,49999.55859375,50.4283271752169,5.90196866747197,3.51289248466492,26,1,0,0,1,0.321197509765625,33.2355842590332,6,1,1,4.22200298309326,0,2084573184,4.22558403015137,,,,,,,,,,,,,,,,,,,,,,,,,,,,,,,,,
,3873605917.62911,4.06942582130432,49999.55859375,0.0537069119591228,0.00200972504546789,1,2,13.1008939743042,5.006822497929,31.0500003397465,62.9395113742509,6.40472931043846,1000,-0.00237034541740477,,,,,,,,,,,,,,,,,,,,,4.06110429763794,4.0777473449707,49999.55859375,49999.55859375,51.3256367152939,5.89830294198878,3.50955700874329,26,1,0,0,1,0.322265625,33.2355842590332,6,1,1,4.07498359680176,0,2084573184,4.06942582130432,,,,,,,,,,,,,,,,,,,,,,,,,,,,,,,,,
,3873605989.07074,3.99472761154175,49999.55859375,0.0535283483339937,0.00226409588041691,1,2,13.1008939743042,5.00938409742078,31.0500003397465,60.9222622591364,19.0309380155926,1000,0.00848789788169728,,,,,,,,,,,,,,,,,,,,,3.98544311523438,4.00401210784912,49999.55859375,49999.55859375,52.1178172195344,5.89307950537731,3.49513292312622,25,1,68,0,0,0.313491821289063,31.7693061828613,6,1,1,3.98544311523438,0,2084573184,3.99472761154175,,,,,,,,,,,,,,,,,,,,,,,,,,,,,,,,,
,3873606052.5163,3.99571585655212,49999.55859375,0.0516291636249471,0.00221794795081777,1,2,13.1008939743042,5.0087633384687,31.0500003397465,59.4160628149512,13.8115283950069,1000,0.00428890536388922,,,,,,,,,,,,,,,,,,,,,3.99405097961426,3.99738073348999,49999.55859375,49999.55859375,52.2686715237459,5.89876414151478,3.48583793640137,24,1,68,0,0,0.320053100585937,33.2355842590332,6,1,1,3.99405097961426,0,2084573184,3.99571585655212,,,,,,,,,,,,,,,,,,,,,,,,,,,,,,,,,
,3873606116.09702,3.96853232383728,49999.55859375,0.0540294510370074,0.00428919407355561,1,2,13.1008939743042,5.01005967777358,31.0500003397465,62.8107912538069,10.2970625730665,1000,0.000917248200973163,,,,,,,,,,,,,,,,,,,,,3.96812200546265,3.96894264221191,49999.55859375,49999.55859375,52.072482765419,5.90020859240611,3.47312593460083,26,1,0,0,1,0.322418212890625,32.7468223571777,6,1,1,3.96812200546265,0,2084573184,3.96853232383728,,,,,,,,,,,,,,,,,,,,,,,,,,,,,,,,,
,3873606179.55008,4.01459884643555,49999.55859375,0.0537995929232239,0.000653593276531253,1,2,13.1008939743042,5.00744178080156,31.0500003397465,62.6495673003156,9.21083500649417,1000,2.46697429271261E-5,,,,,,,,,,,,,,,,,,,,,4.00833702087402,4.02086067199707,49999.55859375,49999.55859375,51.8419023522459,5.91351345964381,3.49691319465637,26,1,0,0,1,0.32318115234375,31.7693061828613,6,1,1,4.00833702087402,0,2084573184,4.01459884643555,,,,,,,,,,,,,,,,,,,,,,,,,,,,,,,,,
,3873606268.11924,4.12654161453247,49999.55859375,0.053694505575681,0.000214485109016673,1,2,13.1008939743042,5.00687601837454,31.0500003397465,62.4668125735631,9.53599960572773,1000,0.000320576895002264,,,,,,,,,,,,,,,,,,,,,4.12654161453247,4.12654161453247,49999.55859375,49999.55859375,51.8618338794863,5.9114911942836,3.54296088218689,26,1,0,0,1,0.320587158203125,32.2580642700195,6,1,1,4.12654161453247,0,2084574080,4.12654161453247,,,,,,,,,,,,,,,,,,,,,,,,,,,,,,,,,
,3873606399.85839,3.86748385429382,49999.55859375,0.0538326617926325,0.000750649122184459,1,2,13.1008939743042,5.00707017534315,31.0500003397465,62.5676404703878,9.99294634385049,1000,0.000692297741019373,,,,,,,,,,,,,,,,,,,,,3.8650643825531,3.86990332603455,49999.55859375,49999.55859375,52.1764393584767,5.92165509777669,3.46422266960144,26,1,0,0,1,0.317840576171875,33.2355842590332,6,1,1,3.8650643825531,0,2084573984,3.86748385429382,,,,,,,,,,,,,,,,,,,,,,,,,,,,,,,,,
,3873606542.69039,3.32871747016907,49999.55859375,0.055022163010031,0.00116385362836318,1,2,13.1008939743042,5.008636939296,31.0500003397465,64.0855926010427,9.48495254728656,1000,7.81609229570251E-5,,,,,,,,,,,,,,,,,,,,,3.3208224773407,3.33661246299744,49999.55859375,49999.55859375,52.2291992835248,5.90774452355855,3.23269057273865,24,1,68,0,0,0.32867431640625,32.7468223571777,6,1,1,3.3208224773407,0,2084574016,3.32871747016907,,,,,,,,,,,,,,,,,,,,,,,,,,,,,,,,,
,3873606675.72642,3.20753383636475,49999.55859375,0.0554388394932932,0.00021995147437416,1,2,13.1008939743042,5.01304402145123,31.0500003397465,64.6244833052265,9.74485189814289,1000,0.000229916186134402,,,,,,,,,,,,,,,,,,,,,3.20413970947266,3.21092796325684,49999.55859375,49999.55859375,52.1924627431209,5.89243475889232,3.16308641433716,26,1,0,0,1,0.325469970703125,33.2355842590332,6,1,1,3.20413970947266,0,2084574048,3.20753383636475,,,,,,,,,,,,,,,,,,,,,,,,,,,,,,,,,
,3873606829.87528,3.07547354698181,49999.55859375,0.0550413204814388,0.000356265137047772,1,2,13.1008939743042,5.01413329225763,31.0500003397465,64.0775157911798,10.3811578549495,1000,0.000831003078988981,,,,,,,,,,,,,,,,,,,,,3.07547354698181,3.07547354698181,49999.55859375,49999.55859375,52.5148845073036,5.88490905979393,3.10289692878723,26,1,0,0,1,0.32440185546875,31.2805480957031,6,1,1,3.07547354698181,0,2084574016,3.07547354698181,,,,,,,,,,,,,,,,,,,,,,,,,,,,,,,,,
,3873606961.55716,3.07143926620483,49999.55859375,0.0549193352846407,0.000367644611669737,1,2,13.1008939743042,5.01290643582175,31.0500003397465,63.9495985744683,10.10930736295,1000,0.000618845703206559,,,,,,,,,,,,,,,,,,,,,3.07089161872864,3.07198691368103,49999.55859375,49999.55859375,52.1338406041786,5.88813234717331,3.09195137023926,26,1,0,0,1,0.317306518554687,34.7018585205078,6,1,1,3.07089161872864,0,2084573888,3.07143926620483,,,,,,,,,,,,,,,,,,,,,,,,,,,,,,,,,
,3873607755.23462,24.0240459442139,26.4772434234619,3.30253956923404E-5,4.44233250174622E-8,1,2,13.1008939743042,2.01770719260676,31.0500003397465,0.00814420178308739,0.00119614039325339,1,1.02511781258886E-8,,,,,,,,,,,,,,,,,,,,,24.0240459442139,24.0240459442139,26.4772434234619,26.4772434234619,52.0044810842459,6.0501700488053,5.78780269622803,26,1,0,0,1,0.156631469726562,31.2805480957031,2,1,1,24.0240459442139,0,2084574112,24.0240459442139,,,,,,,,,,,,,,,,,,,,,,,,,,,,,,,,,
,3873607960.66587,56.0316715240479,26.4772434234619,2.1565718123838E-5,3.63731093972417E-7,1,2,13.1008939743042,2.00347224226081,31.08000010252,0.00523547222847321,0.000852047603091444,1,3.4105827699792E-7,,,,,,,,,,,,,,,,,,,,,56.0133018493652,56.0500411987305,26.4772434234619,26.4772434234619,51.6824501343228,6.11217347578396,6.50412845611572,26,1,0,0,1,0.163955688476562,31.2805480957031,2,1,1,56.0500411987305,0,2084574304,56.0316715240479,,,,,,,,,,,,,,,,,,,,,,,,,,,,,,,,,
,3873608160.65232,88.0247421264648,26.4772434234619,1.79760040277679E-5,5.27244751514991E-8,1,2,13.1008939743042,2.00822529940276,31.1299990862608,0.00439278350184691,0.000650955856466858,1,2.87565417636427E-8,,,,,,,,,,,,,,,,,,,,,88.0247421264648,88.0247421264648,26.4772434234619,26.4772434234619,51.6367248659478,6.04032502717928,6.75203800201416,26,1,0,0,1,0.157470703125,30.7917900085449,2,1,1,88.0247421264648,0,2084574336,88.0247421264648,,,,,,,,,,,,,,,,,,,,,,,,,,,,,,,,,
,3873608354.72564,120.014724731445,26.4772434234619,1.52267773433753E-5,4.40367655262799E-8,1,2,13.1008939743042,2.01089511129052,31.199999153614,0.00373126846642146,0.000546366765535807,1,-1.84648702035702E-9,,,,,,,,,,,,,,,,,,,,,120.014724731445,120.014724731445,26.4772434234619,26.4772434234619,51.830568738717,6.01268554415443,6.88259267807007,26,1,0,0,1,0.149993896484375,31.2805480957031,2,1,1,120.014724731445,0,2084574304,120.014724731445,,,,,,,,,,,,,,,,,,,,,,,,,,,,,,,,,
,3873608547.72209,152.005950927734,26.4772434234619,1.36541925716544E-5,1.18305114710045E-7,1,2,13.1008939743042,2.0126652956776,31.300000846386,0.00334574564929489,0.000529947860101139,1,1.58017318801289E-7,,,,,,,,,,,,,,,,,,,,,152.005950927734,152.005950927734,26.4772434234619,26.4772434234619,52.0025270129478,5.98657141363911,6.97890949249268,25,1,64,0,0,0.149765014648438,29.8142719268799,2,1,1,152.005950927734,0,2084574272,152.005950927734,,,,,,,,,,,,,,,,,,,,,,,,,,,,,,,,,
,3873608741.45408,184.07080078125,26.4772434234619,1.24566788765657E-5,4.4826343455005E-8,1,2,13.1008939743042,2.01316276488208,31.4100012183189,0.00305838342109004,0.00045202373546061,1,1.51817003469874E-8,,,,,,,,,,,,,,,,,,,,,184.07080078125,184.07080078125,26.4772434234619,26.4772434234619,52.1662781877267,5.97987670161439,7.09555625915527,26,1,0,0,1,0.146408081054687,29.8142719268799,2,1,1,184.07080078125,0,2084574304,184.07080078125,,,,,,,,,,,,,,,,,,,,,,,,,,,,,,,,,
,3873608933.2926,216.02424621582,26.4772434234619,1.14394055798513E-5,3.75942609199238E-8,1,2,13.1008939743042,2.01079132746166,31.5399989485741,0.00280115639954624,0.00042241047424612,1,4.75159682237998E-8,,,,,,,,,,,,,,,,,,,,,216.02424621582,216.02424621582,26.4772434234619,26.4772434234619,52.4265604846305,6.00016150576576,7.27977466583252,26,1,0,0,1,0.149688720703125,32.2580642700195,2,1,1,216.02424621582,0,2084574240,216.02424621582,,,,,,,,,,,,,,,,,,,,,,,,,,,,,,,,,
,3873609126.62721,248.014739990234,26.4772434234619,1.05940652225537E-5,3.84202556465998E-8,1,2,13.1008939743042,2.00992567717981,31.7099988460541,0.00259232915462567,0.000388937898411791,1,3.60850506456611E-8,,,,,,,,,,,,,,,,,,,,,248.014739990234,248.014739990234,26.4772434234619,26.4772434234619,53.0209889735056,6.011859349431,7.66235780715942,25,1,64,0,0,0.149688720703125,30.7917900085449,2,1,1,248.014739990234,0,2084574208,248.014739990234,,,,,,,,,,,,,,,,,,,,,,,,,,,,,,,,,
,3873609319.50532,280.013031005859,26.4772434234619,9.82595194059645E-6,5.95324398770148E-8,1,2,13.1008939743042,2.00800926445671,31.8900011479855,0.00239902879320235,0.000366961728333,1,6.1598787403467E-8,,,,,,,,,,,,,,,,,,,,,280.013031005859,280.013031005859,26.4772434234619,26.4772434234619,53.2484428726018,6.03598643787067,7.94062805175781,25,1,64,0,0,0.150833129882813,31.2805480957031,2,1,1,280.013031005859,0,2084574464,280.013031005859,,,,,,,,,,,,,,,,,,,,,,,,,,,,,,,,,
,3873611539.90354,2.00568270683289,44868.869140625,0.0534470299927458,1.93506758792897E-5,1,2,13.1008939743042,2.00900193961079,31.0500003397465,13.0894547639245,1.80669666113961,1000,-0.000446665482228866,,,,,,,,,,,,,,,,,,,,,2.00542187690735,2.00594353675842,44778.87890625,44958.859375,52.2163024129574,6.03744110977814,2.4711422920227,26,1,0,0,1,0.154266357421875,29.3255138397217,1,6,1,2.00594353675842,0,2084573184,2.00568270683289,,,,,,,,,,,,,,,,,,,,,,,,,,,,,,,,,
,3873611603.38967,1.99970352649689,38532.359375,0.0514613834349754,8.30499811751779E-6,1,2,13.1008939743042,2.00937041540851,31.0500003397465,12.6031250931238,1.77027825526663,1000,-0.000307061427168205,,,,,,,,,,,,,,,,,,,,,1.99919986724854,2.00020718574524,38447.43359375,38617.28515625,52.2815683943132,6.03035458709631,2.46813368797302,26,1,0,0,1,0.154953002929687,30.7917900085449,5,6,1,1.99919986724854,0,2084573184,1.99970352649689,,,,,,,,,,,,,,,,,,,,,,,,,,,,,,,,,
,3873611666.89214,2.00000524520874,32191.169921875,0.0489301850888365,1.87359417609788E-5,1,2,13.1008939743042,2.00987909943784,31.0500003397465,11.9866203606215,1.7000228548665,1000,-0.000226554347532183,,,,,,,,,,,,,,,,,,,,,1.99990653991699,2.00010395050049,32096.169921875,32286.169921875,52.1135182626786,6.02522652215929,2.4635591506958,24,1,68,0,0,0.152359008789062,30.7917900085449,1,6,1,1.99980008602142,0,2084573184,2.00000524520874,,,,,,,,,,,,,,,,,,,,,,,,,,,,,,,,,
,3873611730.41527,1.99977934360504,25845.197265625,0.0454488735785608,9.56263572938931E-6,1,2,13.1008939743042,2.01032875892214,31.0500003397465,11.1370080322024,1.5899564480577,1000,-0.000168710438549425,,,,,,,,,,,,,,,,,,,,,1.99938726425171,2.00017142295837,25755.19140625,25935.203125,52.104920348967,6.0234194610296,2.4582371711731,26,1,0,0,1,0.151748657226562,30.3030319213867,1,6,1,2.00017142295837,0,2084573184,1.99977934360504,,,,,,,,,,,,,,,,,,,,,,,,,,,,,,,,,
,3873611857.64113,1.99957454204559,13142.8930664062,0.0335603569321137,1.7283875218233E-5,1,2,13.1008939743042,2.01120738124445,31.0500003397465,8.23048444127271,1.17577794869176,1000,-0.000121516084706514,,,,,,,,,,,,,,,,,,,,,1.99892282485962,2.00022625923157,13072.8623046875,13212.923828125,52.0341829679767,6.02036767881304,2.45324802398682,26,1,0,0,1,0.151443481445313,31.2805480957031,1,6,1,2.00022625923157,0,2084573184,1.99957454204559,,,,,,,,,,,,,,,,,,,,,,,,,,,,,,,,,
,3873611972.52847,1.99995392560959,1659.908203125,0.00698032624384076,5.15941592699917E-5,1,2,13.1008939743042,2.01131033523753,31.0500003397465,1.72274210545687,0.171625284834983,100,-0.000322871215333789,,,,,,,,,,,,,,,,,,,,,1.99966037273407,2.00024747848511,1569.87072753906,1749.94567871094,51.8821562209863,6.01637987560413,2.44803667068481,24,1,68,0,0,0.150604248046875,30.7917900085449,1,6,1,1.99966037273407,0,2084573184,1.99995392560959,,,,,,,,,,,,,,,,,,,,,,,,,,,,,,,,,
,3873612069.76148,1.99958693981171,-8060.455078125,-0.0245381303399662,2.35863315924135E-5,1,2,13.1008939743042,2.01151768720465,31.0500003397465,-6.01204210635627,-0.911460358618493,100,-0.00012128866351594,,,,,,,,,,,,,,,,,,,,,1.99929797649384,1.99987590312958,-8150.5419921875,-7970.3681640625,51.8962255343324,6.00878834847228,2.44659423828125,26,1,0,0,1,0.150680541992187,30.7917900085449,1,6,1,1.99929797649384,0,2084573184,1.99958693981171,,,,,,,,,,,,,,,,,,,,,,,,,,,,,,,,,
,3873612133.22452,1.9999617934227,-14412.2802734375,-0.0349957769575957,1.61993154289169E-5,1,2,13.1008939743042,2.01197208026243,31.0500003397465,-8.58198073942769,-1.27273564688644,100,-5.99451354064932E-5,,,,,,,,,,,,,,,,,,,,,1.99985682964325,2.00006675720215,-14502.3984375,-14322.162109375,52.0791266078324,6.00199968542637,2.44296169281006,26,1,0,0,1,0.150222778320313,29.8142719268799,1,6,1,2.00006675720215,0,2084573184,1.9999617934227,,,,,,,,,,,,,,,,,,,,,,,,,,,,,,,,,
,3873612204.70975,1.99999248981476,-21564.4248046875,-0.0421964901483447,1.25020521251642E-5,1,2,13.1008939743042,2.01243479446242,31.0500003397465,-10.3525733575663,-1.53348087570715,100,-6.49432119324559E-5,,,,,,,,,,,,,,,,,,,,,1.99996280670166,2.00002217292786,-21654.48046875,-21474.369140625,52.2381880114959,5.99759180864728,2.44398617744446,26,1,0,0,1,0.148849487304687,30.7917900085449,1,6,1,2.00002217292786,0,2084573184,1.99999248981476,,,,,,,,,,,,,,,,,,,,,,,,,,,,,,,,,
,3873612311.04214,2.00053286552429,-32209.197265625,-0.0486607517921651,1.27873350021334E-5,1,2,13.1008939743042,2.01294447936443,31.0500003397465,-11.9446066478955,-1.76682912116472,100,-6.50350478349264E-5,,,,,,,,,,,,,,,,,,,,,2.00053286552429,2.00053286552429,-32209.197265625,-32209.197265625,52.4844009950536,5.99330834191565,2.4441282749176,26,1,0,0,1,0.14739990234375,30.7917900085449,1,6,1,2.00053286552429,0,2084573184,2.00053286552429,,,,,,,,,,,,,,,,,,,,,,,,,,,,,,,,,
,3873612435.10506,1.99999988079071,-44644.94140625,-0.0531331742768004,7.24304880406425E-5,1,2,13.1008939743042,2.01358102906792,31.0500003397465,-13.04881275663,-1.94014964593805,1000,-0.000110807005801036,,,,,,,,,,,,,,,,,,,,,1.99979066848755,2.00020909309387,-44725.12109375,-44564.76171875,52.8767785117075,5.98272703649349,2.44139361381531,26,1,0,0,1,0.14801025390625,30.7917900085449,1,6,1,1.99979066848755,0,2084573600,1.99999988079071,,,,,,,,,,,,,,,,,,,,,,,,,,,,,,,,,
,3873612534.13333,1.99985057115555,-45988.947265625,-0.0537615887298068,2.02228504877362E-5,1,2,13.1008939743042,2.01356280622942,31.0500003397465,-13.2268238499158,-1.79993486491945,1000,0.000551926579865877,,,,,,,,,,,,,,,,,,,,,1.99944221973419,2.0002589225769,-46078.8359375,-45899.05859375,53.0100461742364,5.98214017280682,2.43990993499756,26,1,0,0,1,0.14739990234375,30.7917900085449,1,6,1,1.99944221973419,0,2084573728,1.99985057115555,,,,,,,,,,,,,,,,,,,,,,,,,,,,,,,,,
,3873612597.62275,1.99952971935272,-39648.8046875,-0.0518379430466684,1.71226000929707E-5,1,2,13.1008939743042,2.01345153403306,31.0500003397465,-12.745717085007,-1.77972568266196,1000,0.000351518179197854,,,,,,,,,,,,,,,,,,,,,1.998859167099,2.00020027160645,-39738.7109375,-39558.8984375,52.9396996075056,5.9851230723543,2.43957209587097,26,1,0,0,1,0.153427124023438,30.7917900085449,1,6,1,2.00020027160645,0,2084573920,1.99952971935272,,,,,,,,,,,,,,,,,,,,,,,,,,,,,,,,,
,3873612661.14084,2.00007820129395,-33309.548828125,-0.0493717864941287,1.78892007506682E-5,1,2,13.1008939743042,2.01361982486856,31.0500003397465,-12.1395264593905,-1.70720919839474,1000,0.000286418563191935,,,,,,,,,,,,,,,,,,,,,1.99988102912903,2.00027537345886,-33399.4375,-33219.66015625,52.7407751493613,5.97600852311262,2.43691325187683,26,1,0,0,1,0.146331787109375,31.2805480957031,1,6,1,1.99988102912903,0,2084573792,2.00007820129395,,,,,,,,,,,,,,,,,,,,,,,,,,,,,,,,,
,3873612724.63645,1.99953269958496,-26969.416015625,-0.0461130706126518,1.77364948934702E-5,1,2,13.1008939743042,2.01388827192925,31.0500003397465,-11.3397701813595,-1.60424097138446,1000,0.000229621521937719,,,,,,,,,,,,,,,,,,,,,1.99948930740356,1.99957609176636,-27059.3359375,-26879.49609375,52.5731158319863,5.98094693232359,2.43613886833191,26,1,0,0,1,0.146102905273438,30.7917900085449,1,6,1,1.99957609176636,0,2084573696,1.99953269958496,,,,,,,,,,,,,,,,,,,,,,,,,,,,,,,,,
,3873612788.19801,1.9997838139534,-20624.2041015625,-0.0414284404359091,0.00015753583248767,1,2,13.1008939743042,2.01408097879721,31.0500003397465,-10.1913929241783,-1.42934143711242,1000,0.000255874018430781,,,,,,,,,,,,,,,,,,,,,1.9988294839859,2.0007381439209,-20709.111328125,-20539.296875,52.2585103529959,5.98067819040157,2.43211936950684,26,1,0,0,1,0.150146484375,30.7917900085449,1,6,1,1.9988294839859,0,2084573856,1.9997838139534,,,,,,,,,,,,,,,,,,,,,,,,,,,,,,,,,
,3873612911.25761,2.00019574165344,-8328.36669921875,-0.0254198990383607,2.53790036818849E-5,1,2,13.1008939743042,2.01527789583892,31.0500003397465,-6.26108081408729,-0.872868792822289,1000,0.000177895431968361,,,,,,,,,,,,,,,,,,,,,2.00006294250488,2.000328540802,-8413.361328125,-8243.3720703125,52.016596326294,5.96699488061289,2.42374038696289,26,1,0,0,1,0.150680541992187,30.3030319213867,1,6,1,2.00006294250488,0,2084573600,2.00019574165344,,,,,,,,,,,,,,,,,,,,,,,,,,,,,,,,,
,3873613010.54222,2.00015789270401,1597.86218261719,0.00603569414531368,4.21590367780974E-5,1,2,13.1008939743042,2.01519578401578,31.0500003397465,1.47570620035389,0.280989617229234,1000,0.000257522270891433,,,,,,,,,,,,,,,,,,,,,1.99996435642242,2.0003514289856,1512.84948730469,1682.87487792969,52.2995458502555,5.96780757485568,2.42195677757263,26,1,0,0,1,0.145111083984375,30.3030319213867,1,6,1,1.99996435642242,0,2084573536,2.00015789270401,,,,,,,,,,,,,,,,,,,,,,,,,,,,,,,,,
,3873613103.70574,1.99989902973175,10913.6000976562,0.0299118545566107,2.15227227170762E-5,1,2,13.1008939743042,2.00597141282116,31.0500003397465,7.29250800841023,1.09115136928788,100,8.9954208864772E-5,,,,,,,,,,,,,,,,,,,,,1.99989652633667,1.99990153312683,10823.7294921875,11003.470703125,52.270625595044,5.9628842335885,2.42298650741577,26,1,0,0,1,0.151824951171875,30.3030319213867,1,6,1,1.99990153312683,0,2084573184,1.99989902973175,,,,,,,,,,,,,,,,,,,,,,,,,,,,,,,,,
,3873613167.21238,2.00017029047012,17266.0068359375,0.0382716773701796,1.42448251204924E-5,1,2,13.1008939743042,2.00413642666526,31.0500003397465,9.3175191836875,1.37291657390573,100,2.97742016985408E-5,,,,,,,,,,,,,,,,,,,,,1.999636054039,2.00070452690125,17176.142578125,17355.87109375,52.4312502557459,5.9849975946055,2.42762303352356,26,1,0,0,1,0.160903930664062,30.7917900085449,1,6,1,1.999636054039,0,2084573824,2.00017029047012,,,,,,,,,,,,,,,,,,,,,,,,,,,,,,,,,
,3873613246.64986,1.99966561794281,25214.6318359375,0.0448790700731702,1.54783285192889E-5,1,2,13.1008939743042,2.00419938103509,31.0500003397465,10.9265118305216,1.61191772361278,100,4.26309585528247E-5,,,,,,,,,,,,,,,,,,,,,1.99946296215057,1.99986827373505,25129.513671875,25299.75,52.4793204096786,5.97892244634982,2.42693114280701,26,1,0,0,1,0.154266357421875,31.2805480957031,1,6,1,1.99986827373505,0,2084573888,1.99966561794281,,,,,,,,,,,,,,,,,,,,,,,,,,,,,,,,,
,3873613359.8072,2.00046980381012,36554.45703125,0.050577691558142,1.19061984178785E-5,1,2,13.1008939743042,2.00446764260853,31.0500003397465,12.3179676594872,1.81080823533344,100,2.23958662738769E-5,,,,,,,,,,,,,,,,,,,,,2.00023055076599,2.00070905685425,36474.171875,36634.7421875,52.6786356820825,5.97902385476465,2.43025755882263,26,1,0,0,1,0.153350830078125,30.7917900085449,1,6,1,2.00070905685425,0,2084574240,2.00046980381012,,,,,,,,,,,,,,,,,,,,,,,,,,,,,,,,,
,3873613482.01199,2.00030279159546,48807.82421875,0.0547403662543144,0.000493970976510147,1,2,13.1008939743042,2.00462984701343,31.0500003397465,13.3378452872411,1.9326181235825,100,-8.87528205524017E-5,,,,,,,,,,,,,,,,,,,,,1.99953579902649,2.00106978416443,48642.73046875,48972.91796875,53.1007150824672,5.97124259243347,2.42733216285706,26,1,0,0,1,0.152206420898438,30.7917900085449,1,6,1,2.00106978416443,0,2084573888,2.00030279159546,,,,,,,,,,,,,,,,,,,,,,,,,,,,,,,,,
,3873614025.28281,28.0348529815674,26.4772434234619,2.13243605916823E-5,4.00014308804243E-8,1,2,13.1008939743042,1.9854874028612,31.0500003397465,0.00510035362277565,0.000751792176233372,1,1.76779977551664E-8,,,,,,,,,,,,,,,,,,,,,28.0348529815674,28.0348529815674,26.4772434234619,26.4772434234619,51.9673537295824,5.97490545687719,5.87648010253906,26,1,0,0,1,0.1458740234375,30.7917900085449,2,1,1,28.0348529815674,0,2084574208,28.0348529815674,,,,,,,,,,,,,,,,,,,,,,,,,,,,,,,,,
,3873614229.35402,60.0169448852539,26.4772434234619,1.78943813272977E-5,4.17923528445957E-8,1,2,13.1008939743042,1.98758668258523,31.08000010252,0.00428734093087221,0.000640443470534982,1,4.95039413781258E-8,,,,,,,,,,,,,,,,,,,,,60.0169448852539,60.0169448852539,26.4772434234619,26.4772434234619,51.5304233873324,6.0570201531607,6.47203683853149,26,1,0,0,1,0.15869140625,31.2805480957031,2,1,1,60.0169448852539,0,2084574272,60.0169448852539,,,,,,,,,,,,,,,,,,,,,,,,,,,,,,,,,
,3873614429.06224,92.0061111450195,26.4772434234619,1.59166987655766E-5,4.1128652088325E-8,1,2,13.1008939743042,1.99421109217428,31.139999628067,0.00383904266963512,0.000563681530250654,1,4.29381632132461E-9,,,,,,,,,,,,,,,,,,,,,92.0061111450195,92.0061111450195,26.4772434234619,26.4772434234619,51.8438564235439,5.98519761276281,6.69049215316772,26,1,0,0,1,0.150985717773438,30.7917900085449,2,1,1,92.0061111450195,0,2084574208,92.0061111450195,,,,,,,,,,,,,,,,,,,,,,,,,,,,,,,,,
,3873614622.52818,124.022521972656,26.4772434234619,1.42161965070378E-5,3.6628368595364E-8,1,2,13.1008939743042,1.99470169749114,31.2099996954203,0.00343065565914321,0.000502546533246159,1,-9.1958860509452E-10,,,,,,,,,,,,,,,,,,,,,124.022521972656,124.022521972656,26.4772434234619,26.4772434234619,51.7465436728997,5.99678061117336,6.80531787872314,26,1,0,0,1,0.151138305664062,32.7468223571777,2,1,1,124.022521972656,0,2084574336,124.022521972656,,,,,,,,,,,,,,,,,,,,,,,,,,,,,,,,,
,3873614816.16634,156.029174804687,26.4772434234619,1.30422376961744E-5,5.96684341817211E-8,1,2,13.1008939743042,1.99592259221953,31.309999525547,0.00315406597556687,0.000440713386312015,1,-8.72199794988264E-8,,,,,,,,,,,,,,,,,,,,,156.029174804687,156.029174804687,26.4772434234619,26.4772434234619,51.7184050462074,5.97652193757905,6.88748598098755,26,1,0,0,1,0.14862060546875,31.7693061828613,2,1,1,156.029174804687,0,2084574208,156.029174804687,,,,,,,,,,,,,,,,,,,,,,,,,,,,,,,,,
,3873615009.2811,188.022369384766,26.4772434234619,1.20645128815576E-5,4.4286848897813E-8,1,2,13.1008939743042,1.99595755106259,31.41999989748,0.00291593640290346,0.000419824654424844,1,-3.04497785180532E-8,,,,,,,,,,,,,,,,,,,,,188.001892089844,188.042846679687,26.4772434234619,26.4772434234619,52.0044810842459,5.97108552115475,6.99333190917969,26,1,0,0,1,0.148544311523438,30.3030319213867,2,1,1,188.042846679687,0,2084574176,188.022369384766,,,,,,,,,,,,,,,,,,,,,,,,,,,,,,,,,
,3873615201.6282,220.073760986328,26.4772434234619,1.12056181541541E-5,4.17730907728167E-8,1,2,13.1008939743042,1.99519416256107,31.5699987113476,0.00270351857717425,0.000409197498555694,1,5.26667501821072E-8,,,,,,,,,,,,,,,,,,,,,220.073760986328,220.073760986328,26.4772434234619,26.4772434234619,52.3390180904767,5.97963476988136,7.19758415222168,26,1,0,0,1,0.148468017578125,31.7693061828613,2,1,1,220.073760986328,0,2084574272,220.073760986328,,,,,,,,,,,,,,,,,,,,,,,,,,,,,,,,,
,3873615394.5476,252.029006958008,26.4772434234619,1.0525229105699E-5,4.73451688195867E-8,1,2,13.1008939743042,1.99190881619421,31.7200012505054,0.00253205900200992,0.00037896189026875,1,3.20557003509614E-8,,,,,,,,,,,,,,,,,,,,,252.029006958008,252.029006958008,26.4772434234619,26.4772434234619,53.1030599680249,6.007694405023,7.6175684928894,24,1,64,0,0,0.151138305664062,30.7917900085449,2,1,1,252.029006958008,0,2084574176,252.029006958008,,,,,,,,,,,,,,,,,,,,,,,,,,,,,,,,,
,3873615587.67484,284.029754638672,26.4772434234619,9.81087259996646E-6,4.59716010508989E-8,1,2,13.1008939743042,1.9908360399407,31.8999998271465,0.00236028398508388,0.000335908805767954,1,-4.07096085049136E-8,,,,,,,,,,,,,,,,,,,,,284.029754638672,284.029754638672,26.4772434234619,26.4772434234619,53.2246032027653,6.0154688902395,7.7736668586731,26,1,0,0,1,0.149688720703125,31.2805480957031,2,1,1,284.029754638672,0,2084574240,284.029754638672,,,,,,,,,,,,,,,,,,,,,,,,,,,,,,,,,
,3873616369.60406,286.9560546875,26.2053050994873,1.12626492933269E-5,4.03060333795962E-8,1,2,13.1008939743042,1.99459737623001,31.8999998271465,0.00271754335947176,0.000398727693472491,1,1.87968057057988E-9,,,,,,,,,,,,,,,,,,,,,286.9560546875,286.9560546875,26.2053050994873,26.2053050994873,52.4269512988902,5.99358981942795,8.69497680664062,26,1,0,0,1,0.15045166015625,30.7917900085449,2,1,1,286.9560546875,0,2084573184,286.9560546875,,,,,,,,,,,,,,,,,,,,,,,,,,,,,,,,,
,3873616547.74878,254.979888916016,26.2053050994873,1.15516565014066E-5,7.17404598360421E-7,1,2,13.1008939743042,1.99497479984356,31.7699983716011,0.00275627335140816,0.000627482276575318,1,9.06624974451144E-7,,,,,,,,,,,,,,,,,,,,,254.979888916016,254.979888916016,26.2053050994873,26.2053050994873,52.4617337679959,5.98702036615311,8.41193580627441,26,1,0,0,1,0.148773193359375,31.2805480957031,2,1,1,254.979888916016,0,2084574144,254.979888916016,,,,,,,,,,,,,,,,,,,,,,,,,,,,,,,,,
,3873616739.51292,222.989166259766,26.2053050994873,1.17246628486393E-5,5.10150559981538E-8,1,2,13.1008939743042,1.99673555611436,31.6299982368946,0.00283384459108892,0.000422255934396209,1,2.81290127489633E-8,,,,,,,,,,,,,,,,,,,,,222.989166259766,222.989166259766,26.2053050994873,26.2053050994873,52.2999366645151,5.96147509154323,8.09522914886475,24,1,64,0,0,0.146560668945313,30.7917900085449,2,1,1,222.989166259766,0,2084574112,222.989166259766,,,,,,,,,,,,,,,,,,,,,,,,,,,,,,,,,
,3873616929.71764,190.991302490234,26.2053050994873,1.19272889839784E-5,4.22014578248702E-8,1,2,13.1008939743042,1.99678028096971,31.5399989485741,0.00288131716840266,0.000440655760610302,1,7.44562856361606E-8,,,,,,,,,,,,,,,,,,,,,190.991302490234,190.991302490234,26.2053050994873,26.2053050994873,52.2221646268517,5.96641822177789,7.85393571853638,26,1,0,0,1,0.145034790039062,31.2805480957031,2,1,1,190.991302490234,0,2084573856,190.991302490234,,,,,,,,,,,,,,,,,,,,,,,,,,,,,,,,,
,3873617121.84922,158.993881225586,26.2053050994873,1.19524838182967E-5,3.52830321905908E-8,1,2,13.1008939743042,1.99521776754018,31.41999989748,0.00288630944881507,0.00041919010065321,1,-1.54385739988129E-8,,,,,,,,,,,,,,,,,,,,,158.993881225586,158.993881225586,26.2053050994873,26.2053050994873,51.9286631178805,5.98180107770765,7.66306114196777,26,1,0,0,1,0.148849487304687,30.7917900085449,2,1,1,158.993881225586,0,2084573760,158.993881225586,,,,,,,,,,,,,,,,,,,,,,,,,,,,,,,,,
,3873617314.77491,126.973926544189,26.2053050994873,1.17897250655154E-5,4.14431941164394E-8,1,2,13.1008939743042,1.99298017980422,31.3199982047081,0.0028417288945122,0.000407339066428204,1,-3.70791769380997E-8,,,,,,,,,,,,,,,,,,,,,126.959655761719,126.98819732666,26.2053050994873,26.2053050994873,51.8731674930151,6.00084327514207,7.4959979057312,26,1,0,0,1,0.153732299804687,30.7917900085449,2,1,1,126.959655761719,0,2084574208,126.973926544189,,,,,,,,,,,,,,,,,,,,,,,,,,,,,,,,,
,3873617506.10402,94.9880523681641,26.2053050994873,1.16221968249734E-5,5.73438532367979E-8,1,2,13.1008939743042,1.99740759124193,31.2399994581938,0.00281170092323933,0.000413166162930556,1,4.46186847206065E-9,,,,,,,,,,,,,,,,,,,,,94.9880523681641,94.9880523681641,26.2053050994873,26.2053050994873,50.3149910399284,6.0257914870961,7.32138729095459,26,1,0,0,1,0.150833129882813,30.7917900085449,2,1,1,94.9880523681641,0,2084574144,94.9880523681641,,,,,,,,,,,,,,,,,,,,,,,,,,,,,,,,,
,3873617694.42433,62.9608726501465,26.2053050994873,1.18210661975742E-5,2.6800330815428E-7,1,2,13.1008939743042,2.00163464284881,31.1600007116795,0.00286212232307337,0.000484476116031747,1,2.62056393180739E-7,,,,,,,,,,,,,,,,,,,,,62.9608726501465,62.9608726501465,26.2053050994873,26.2053050994873,51.6203106670439,6.02592665494595,7.09781360626221,26,1,0,0,1,0.151443481445313,30.7917900085449,2,1,1,62.9608726501465,0,2084573184,62.9608726501465,,,,,,,,,,,,,,,,,,,,,,,,,,,,,,,,,
,3873617881.24579,30.9876613616943,26.2053050994873,1.21176135228483E-5,4.62314968123839E-8,1,2,13.1008939743042,2.00906990107795,31.0999993234873,0.00296331336046584,0.000440643568270469,1,2.54559760375636E-8,,,,,,,,,,,,,,,,,,,,,30.9876613616943,30.9876613616943,26.2053050994873,26.2053050994873,52.1744852871786,5.94834853715334,6.61015129089356,24,1,64,0,0,0.14495849609375,30.7917900085449,2,1,1,30.9876613616943,0,2084573248,30.9876613616943,,,,,,,,,,,,,,,,,,,,,,,,,,,,,,,,,
,3873619122.54502,3.00932216644287,26.2053050994873,1.66769918528518E-5,3.88557973505134E-8,1,2,13.1008939743042,2.00419187492646,31.0600008815527,0.00406139578594099,0.000591135027181545,1,-1.63838045644655E-8,,,,,,,,,,,,,,,,,,,,,3.00932216644287,3.00932216644287,26.2053050994873,26.2053050994873,51.256462591342,5.98452686641947,2.90711045265198,26,1,0,0,1,0.15380859375,30.7917900085449,6,1,1,3.00932216644287,0,2084574240,3.00932216644287,,,,,,,,,,,,,,,,,,,,,,,,,,,,,,,,,
,3873619334.58428,35.1352157592773,26.2053050994873,1.20214218072762E-5,4.17544801464561E-8,1,2,13.1008939743042,2.0118271965662,31.0600008815527,0.00294808980922026,0.000433795832012251,1,6.96194353314646E-9,,,,,,,,,,,,,,,,,,,,,35.1352157592773,35.1352157592773,26.2053050994873,26.2053050994873,52.2116126418421,5.91346603723336,6.05401372909546,26,1,0,0,1,0.146636962890625,30.7917900085449,2,1,1,35.1352157592773,0,2084574240,35.1352157592773,,,,,,,,,,,,,,,,,,,,,,,,,,,,,,,,,
,3873619537.60844,67.0149154663086,26.2053050994873,1.16799580224571E-5,4.1107519767489E-8,1,2,13.1008939743042,2.00282880739183,31.0999993234873,0.00284111936942714,0.000411234407967652,1,-2.06935750250707E-8,,,,,,,,,,,,,,,,,,,,,67.0149154663086,67.0149154663086,26.2053050994873,26.2053050994873,51.6523574363324,5.98917229331629,6.51530170440674,26,1,0,0,1,0.155868530273438,30.7917900085449,2,1,1,67.0149154663086,0,2084574304,67.0149154663086,,,,,,,,,,,,,,,,,,,,,,,,,,,,,,,,,
,3873619734.80726,99.034049987793,26.2053050994873,1.2069730546137E-5,5.50145862159026E-7,1,2,13.1008939743042,2.00684261933565,31.1600007116795,0.00294743245768793,0.000424190722307672,1,-3.11393765631449E-8,,,,,,,,,,,,,,,,,,,,,99.034049987793,99.034049987793,26.2053050994873,26.2053050994873,51.876294007092,5.95644855559418,6.6982307434082,26,1,0,0,1,0.1495361328125,30.7917900085449,2,1,1,99.034049987793,0,2084574272,99.034049987793,,,,,,,,,,,,,,,,,,,,,,,,,,,,,,,,,
,3873619928.9323,131.007873535156,26.2053050994873,1.13939155085146E-5,4.55381998343864E-8,1,2,13.1008939743042,2.00673105127931,31.2300007790327,0.00278097062552786,0.000408139410853816,1,2.32448731693879E-9,,,,,,,,,,,,,,,,,,,,,131.007873535156,131.007873535156,26.2053050994873,26.2053050994873,51.8700409789382,5.96238722653103,6.80197095870972,26,1,0,0,1,0.149765014648438,31.2805480957031,2,1,1,131.007873535156,0,2084574272,131.007873535156,,,,,,,,,,,,,,,,,,,,,,,,,,,,,,,,,
,3873620121.83401,163.017913818359,26.2053050994873,1.13046619183025E-5,4.0453327935565E-8,1,2,13.1008939743042,2.00627687021977,31.3300006091595,0.00275853719699989,0.000401128145501055,1,-1.26155671692209E-8,,,,,,,,,,,,,,,,,,,,,163.017913818359,163.017913818359,26.2053050994873,26.2053050994873,51.3486947566112,5.96319550139232,6.89063739776611,25,1,64,0,0,0.150604248046875,29.3255138397217,2,1,1,163.017913818359,0,2084574368,163.017913818359,,,,,,,,,,,,,,,,,,,,,,,,,,,,,,,,,
,3873620314.86403,195.025985717773,26.2053050994873,1.11573143138722E-5,3.91493114402877E-8,1,2,13.1008939743042,2.0089862044665,31.4499996602535,0.00272995367318509,0.000394140657841012,1,-2.37837822002501E-8,,,,,,,,,,,,,,,,,,,,,195.007125854492,195.044845581055,26.2053050994873,26.2053050994873,52.3378456476978,5.94068923940976,7.0015082359314,25,1,64,0,0,0.146255493164062,31.2805480957031,2,1,1,195.044845581055,0,2084573216,195.025985717773,,,,,,,,,,,,,,,,,,,,,,,,,,,,,,,,,
,3873620507.99463,227.009841918945,26.2053050994873,1.09765672779101E-5,3.61671549804282E-8,1,2,13.1008939743042,2.00322233189575,31.5999984741211,0.00266834834143454,0.000404809881621713,1,5.53528370032687E-8,,,,,,,,,,,,,,,,,,,,,227.009841918945,227.009841918945,26.2053050994873,26.2053050994873,52.5719433892075,5.99100536159301,7.20013189315796,25,1,64,0,0,0.150909423828125,31.2805480957031,2,1,1,227.009841918945,0,2084574304,227.009841918945,,,,,,,,,,,,,,,,,,,,,,,,,,,,,,,,,
,3873620700.29665,259.028442382813,26.2053050994873,1.07383027233136E-5,4.20291401406657E-8,1,2,13.1008939743042,2.00123534286521,31.75999969244,0.00260651568608857,0.00038851881416911,1,2.63104708046218E-8,,,,,,,,,,,,,,,,,,,,,259.028442382813,259.028442382813,26.2053050994873,26.2053050994873,53.1132211387749,6.01137455200137,7.57193470001221,25,1,64,0,0,0.154266357421875,32.2580642700195,2,1,1,259.028442382813,0,2084574304,259.028442382813,,,,,,,,,,,,,,,,,,,,,,,,,,,,,,,,,
,3873620893.55277,291.012756347656,26.2053050994873,1.04540898356402E-5,5.62724944251191E-8,1,2,13.1008939743042,2.00216041827719,31.9500006735325,0.00254039338969063,0.000374183224017167,1,7.57583872488236E-9,,,,,,,,,,,,,,,,,,,,,291.012756347656,291.012756347656,26.2053050994873,26.2053050994873,53.1554290788133,6.00314133357934,7.49463176727295,25,1,64,0,0,0.153121948242187,30.7917900085449,2,1,1,291.012756347656,0,2084574272,291.012756347656,,,,,,,,,,,,,,,,,,,,,,,,,,,,,,,,,
,3873621262.33873,300.003219604492,42681.63671875,0.000429298919839363,9.61081366168122E-6,1,2,13.1008939743042,2.0030371996542,31.9899991154671,0.119766622167819,-0.0894188611009915,100,-0.000430542677591891,,,,,,,,,,,,,,,,,,,,,300.002899169922,300.003540039063,42601.7421875,42761.53125,52.7708678473517,5.99885689092349,7.48211097717285,25,1,68,0,0,0.151138305664062,30.7917900085449,1,6,1,300.002899169922,0,2084573184,300.003219604492,,,,,,,,,,,,,,,,,,,,,,,,,,,,,,,,,
,3873621325.90112,300.002212524414,36331.158203125,0.000392416211426807,9.72680235578284E-6,1,2,13.1008939743042,1.9921160832202,31.9899991154671,0.106620489401314,-0.0691017185728983,100,-0.000344566078549028,,,,,,,,,,,,,,,,,,,,,300.002014160156,300.002410888672,36251.20703125,36411.109375,50.8015547931496,6.0374359817446,7.58812141418457,24,1,68,0,0,0.15289306640625,31.2805480957031,1,6,1,300.002014160156,0,2084573920,300.002212524414,,,,,,,,,,,,,,,,,,,,,,,,,,,,,,,,,
,3873621389.28151,300.003204345703,30004.9677734375,0.000318769058628444,1.16703516902504E-5,1,2,13.1008939743042,1.99130377318891,32.0000015199184,0.0861332691109138,-0.0532908764341112,100,-0.000268264084576438,,,,,,,,,,,,,,,,,,,,,300.002990722656,300.00341796875,29910.041015625,30099.89453125,50.5123522410342,6.06988370346679,7.74261474609375,26,1,0,0,1,0.155181884765625,31.2805480957031,1,6,1,300.00341796875,0,2084573984,300.003204345703,,,,,,,,,,,,,,,,,,,,,,,,,,,,,,,,,
,3873621478.57892,300.000885009766,21087.376953125,0.000163837249994421,7.75067114453727E-5,1,2,13.1008939743042,1.99160681799996,31.9899991154671,0.0467154826297766,-0.0439987037183723,100,-0.000206875004122811,,,,,,,,,,,,,,,,,,,,,300.000854492188,300.000915527344,21002.5,21172.25390625,51.0231464783516,5.98055345025864,8.03876972198486,25,1,68,0,0,0.147323608398438,30.7917900085449,1,6,1,300.000854492188,0,2084573792,300.000885009766,,,,,,,,,,,,,,,,,,,,,,,,,,,,,,,,,
,3873621550.04554,300.001129150391,13952.216796875,0.00023562859000014,1.10968869447722E-5,1,2,13.1008939743042,1.99573973315329,31.9899991154671,0.0635383094986027,-0.0368354389670602,100,-0.000187024439668194,,,,,,,,,,,,,,,,,,,,,300.000946044922,300.001312255859,13862.185546875,14042.248046875,51.4307657511304,6.12276324613303,8.32682991027832,26,1,0,0,1,0.155410766601562,31.2805480957031,1,6,1,300.000946044922,0,2084573792,300.001129150391,,,,,,,,,,,,,,,,,,,,,,,,,,,,,,,,,
,3873621623.48433,300.000061035156,6612.52514648438,0.000105607277890377,0.000137945751304683,1,2,13.1008939743042,1.99167653962758,31.9899991154671,0.0289156991451106,-0.0201851450502805,100,-9.93635083915022E-5,,,,,,,,,,,,,,,,,,,,,299.999908447266,300.000213623047,6527.54345703125,6697.5068359375,51.1927598670246,5.98459015101652,8.6423454284668,25,1,68,0,0,0.151214599609375,31.7693061828613,1,6,1,300.000213623047,0,2084573728,300.000061035156,,,,,,,,,,,,,,,,,,,,,,,,,,,,,,,,,
,3873621704.01264,300.00048828125,-1439.82080078125,2.61976152678923E-5,1.33192440318413E-5,1,2,13.1008939743042,1.99974899051595,31.9899991154671,0.0148174462816428,-0.0568306711929795,100,-0.00023821549252217,,,,,,,,,,,,,,,,,,,,,300.00048828125,300.00048828125,-1439.82080078125,-1439.82080078125,52.0314472681593,6.0488663395143,8.99044227600098,26,1,0,0,1,0.15167236328125,30.7917900085449,1,6,1,300.00048828125,0,2084573664,300.00048828125,,,,,,,,,,,,,,,,,,,,,,,,,,,,,,,,,
,3873621766.3329,300.000366210937,-7669.3779296875,-9.35590422441293E-5,6.0657383926327E-6,1,2,13.1008939743042,1.99454939337875,31.9899991154671,-0.0199583822122944,-0.021157312253426,100,-7.39753381889044E-5,,,,,,,,,,,,,,,,,,,,,300.000152587891,300.000579833984,-7759.5263671875,-7579.2294921875,51.0407331200342,5.92284991360893,9.1257495880127,26,1,0,0,1,0.152053833007813,30.7917900085449,1,6,1,300.000579833984,0,2084573184,300.000366210937,,,,,,,,,,,,,,,,,,,,,,,,,,,,,,,,,
,3873621833.83428,300.000869750977,-14421.6684570313,-0.000162666419522128,5.60213988158069E-6,1,2,13.1008939743042,1.99941983996129,31.9899991154671,-0.0395811872756377,-0.00475016590403651,10,4.2429326550125E-6,,,,,,,,,,,,,,,,,,,,,300.000305175781,300.001434326172,-14511.767578125,-14331.5693359375,52.4156176853613,5.95879811781508,9.02525424957275,26,1,0,0,1,0.15228271484375,31.2805480957031,1,6,1,300.000305175781,0,2084574048,300.000869750977,,,,,,,,,,,,,,,,,,,,,,,,,,,,,,,,,
,3873621927.10861,300.000244140625,-23753.9892578125,-0.000203023617704407,5.70911435278781E-6,1,2,13.1008939743042,1.99796791038645,32.0000015199184,-0.0507693851720317,0.00387892036552881,100,4.577787920907E-5,,,,,,,,,,,,,,,,,,,,,300.000061035156,300.000427246094,-23844.0703125,-23663.908203125,52.2237278838901,5.94720016672787,8.90295791625977,26,1,0,0,1,0.147323608398438,31.2805480957031,1,6,1,300.000061035156,0,2084573632,300.000244140625,,,,,,,,,,,,,,,,,,,,,,,,,,,,,,,,,
,3873621990.69832,300.000534057617,-30124.2890625,-0.00022674639013274,5.55439014113853E-6,1,2,13.1008939743042,2.00275583482429,31.9899991154671,-0.0570680573720703,0.00509359308706279,100,5.41772380976885E-5,,,,,,,,,,,,,,,,,,,,,300.000366210937,300.000701904297,-30204.482421875,-30044.095703125,52.8150298586883,5.99613685131962,8.83453273773193,26,1,0,0,1,0.15045166015625,31.2805480957031,1,6,1,300.000701904297,0,2084573888,300.000534057617,,,,,,,,,,,,,,,,,,,,,,,,,,,,,,,,,
,3873622054.20888,300.000732421875,-36487.3203125,-0.000255367337651389,4.06079873200661E-6,1,2,13.1008939743042,2.00250058149033,31.9899991154671,-0.0640755550008777,0.00450437030276346,100,5.59530841308265E-5,,,,,,,,,,,,,,,,,,,,,300.000640869141,300.000823974609,-36567.5234375,-36407.1171875,52.7317864213902,5.99670804998823,8.77945613861084,26,1,0,0,1,0.151901245117187,32.7468223571777,1,6,1,300.000640869141,0,2084574016,300.000732421875,,,,,,,,,,,,,,,,,,,,,,,,,,,,,,,,,
,3873622137.49344,300.00048828125,-44834.92578125,-0.000245575862602247,0.000307460425639935,1,2,13.1008939743042,2.00220768601787,31.9899991154671,-0.0495045387395969,-0.078213788517956,1000,-0.000285822685664762,,,,,,,,,,,,,,,,,,,,,300.00048828125,300.00048828125,-44925.234375,-44744.6171875,52.5539659332652,6.0057938041585,8.71591377258301,26,1,0,0,1,0.14923095703125,31.7693061828613,1,6,1,300.00048828125,0,2084573952,300.00048828125,,,,,,,,,,,,,,,,,,,,,,,,,,,,,,,,,
,3873622220.82522,300.000091552734,-47367.044921875,-0.000577964833765577,2.90212617992144E-5,1,2,13.1008939743042,2.00171645172581,31.9899991154671,-0.162970039291877,0.133401127345376,100,0.000633839994564228,,,,,,,,,,,,,,,,,,,,,300.000061035156,300.000122070313,-47456.94140625,-47277.1484375,52.6309563424094,6.0096031767142,8.66157245635986,25,1,68,0,0,0.152053833007813,31.2805480957031,1,6,1,300.000122070313,0,2084574048,300.000091552734,,,,,,,,,,,,,,,,,,,,,,,,,,,,,,,,,
,3873622284.38775,300.000366210937,-41022.158203125,-0.000476995550887344,2.29627101019625E-5,1,2,13.1008939743042,2.00288175780716,31.9899991154671,-0.132594092861109,0.0962038610482359,100,0.000465486067756479,,,,,,,,,,,,,,,,,,,,,300.000274658203,300.000457763672,-41107.05859375,-40937.2578125,52.7497638773325,5.99618710408988,8.62950229644775,24,1,68,0,0,0.14892578125,31.2805480957031,1,6,1,300.00048828125,0,2084573920,300.000366210937,,,,,,,,,,,,,,,,,,,,,,,,,,,,,,,,,
,3873622363.71049,299.998901367188,-33100.271484375,-0.00040917421223699,6.53198532724122E-5,1,2,13.1008939743042,2.00265317576302,31.9899991154671,-0.114029961570431,0.0846449192215075,100,0.00040809265056569,,,,,,,,,,,,,,,,,,,,,299.998901367188,299.998901367188,-33190.265625,-33010.27734375,52.7763392469864,5.99579549116027,8.59398460388184,24,1,68,0,0,0.147933959960938,31.2805480957031,1,6,1,299.998901367188,0,2084574112,299.998901367188,,,,,,,,,,,,,,,,,,,,,,,,,,,,,,,,,
,3873622439.17702,299.999984741211,-25566.9267578125,-0.000328967235357925,1.01945367557741E-5,1,2,13.1008939743042,2.00298682504326,31.9899991154671,-0.0904650024120823,0.0596024345463425,1000,0.00029326621454352,,,,,,,,,,,,,,,,,,,,,299.999908447266,300.000061035156,-25651.83984375,-25482.013671875,52.8572377987268,5.99075101972812,8.56681537628174,26,1,0,0,1,0.150985717773438,32.7468223571777,1,6,1,299.999908447266,0,2084573920,299.999984741211,,,,,,,,,,,,,,,,,,,,,,,,,,,,,,,,,
,3873622514.56384,300.000961303711,-18038.779296875,-6.5736625774184E-5,0.000239439211355232,1,2,13.1008939743042,2.00313461137698,31.9899991154671,-0.0302984255438229,0.0952845353607502,100,0.000401340950308557,,,,,,,,,,,,,,,,,,,,,300.000823974609,300.001098632812,-18133.48828125,-17944.0703125,52.8197196298037,5.99097811447227,8.53984355926514,26,1,0,0,1,0.150222778320313,30.7917900085449,1,6,1,300.000823974609,0,2084573792,300.000961303711,,,,,,,,,,,,,,,,,,,,,,,,,,,,,,,,,
,3873622578.09662,299.999938964844,-11692.4418945313,-0.000246163375380077,1.33371606846422E-5,1,2,13.1008939743042,2.00289789573955,31.9899991154671,-0.0669980599533008,0.0398850708667144,100,0.00020007702297048,,,,,,,,,,,,,,,,,,,,,299.999908447266,299.999969482422,-11782.2138671875,-11602.669921875,52.7567985340056,5.99294244750865,8.51750564575195,26,1,0,0,1,0.151138305664062,31.7693061828613,1,6,1,299.999847412109,0,2084573952,299.999938964844,,,,,,,,,,,,,,,,,,,,,,,,,,,,,,,,,
,3873622641.56181,300.000137329102,-5351.14770507812,-0.000240619794551113,8.45857629083941E-5,1,2,13.1008939743042,2.00286221843422,31.9899991154671,-0.0704846687161566,0.073086563500848,100,0.00033579394929768,,,,,,,,,,,,,,,,,,,,,300.000061035156,300.000213623047,-5446.0185546875,-5256.27685546875,52.7306139786114,5.99595821054185,8.49856185913086,24,1,68,0,0,0.1507568359375,30.7917900085449,1,6,1,300.000213623047,0,2084573568,300.000137329102,,,,,,,,,,,,,,,,,,,,,,,,,,,,,,,,,
,3873622720.91018,300.000991821289,2581.98266601562,1.7204640068823E-6,8.02188068530243E-6,1,2,13.1008939743042,2.00275890173164,31.9899991154671,-0.00675710445000883,0.049022860498017,100,0.000201348503476871,,,,,,,,,,,,,,,,,,,,,300.000946044922,300.001037597656,2491.93896484375,2672.0263671875,52.8111217160921,5.9926290552752,8.47996711730957,26,1,0,0,1,0.151519775390625,30.7917900085449,1,6,1,300.001037597656,0,2084573536,300.000991821289,,,,,,,,,,,,,,,,,,,,,,,,,,,,,,,,,
,3873622794.33105,300.000015258789,9927.5146484375,0.000109006884143689,5.3923663532451E-6,1,2,13.1008939743042,2.00305397453632,31.9899991154671,0.0246404114642683,0.0166728833315377,100,5.25708092698777E-5,,,,,,,,,,,,,,,,,,,,,299.999847412109,300.000183105469,9832.798828125,10022.23046875,52.8552837274287,5.9883071464526,8.46146583557129,26,1,0,0,1,0.1513671875,30.7917900085449,1,6,1,300.000183105469,0,2084573184,300.000015258789,,,,,,,,,,,,,,,,,,,,,,,,,,,,,,,,,
,3873622877.84862,300.000259399414,18281.0849609375,0.000181821520709169,8.80191362281122E-6,1,2,13.1008939743042,2.00319672382666,31.9899991154671,0.0451777926349563,2.53840139572744E-5,10,-2.65421615120246E-5,,,,,,,,,,,,,,,,,,,,,300.000183105469,300.000335693359,18206.0234375,18356.146484375,52.8134666016498,5.98516660821913,8.44722557067871,26,1,0,0,1,0.151290893554687,30.3030319213867,1,6,1,300.000335693359,0,2084574080,300.000259399414,,,,,,,,,,,,,,,,,,,,,,,,,,,,,,,,,
,3873622973.03077,299.999252319336,27808.72265625,0.000215880681132521,6.60356513071314E-6,1,2,13.1008939743042,2.00295146633099,31.9899991154671,0.0538687638716835,-0.00161171608403942,100,-3.82647649280591E-5,,,,,,,,,,,,,,,,,,,,,299.999084472656,299.999420166016,27723.505859375,27893.939453125,52.8259726579575,5.9908820220923,8.43072605133057,26,1,0,0,1,0.151596069335938,32.7468223571777,1,6,1,299.999084472656,0,2084574112,299.999252319336,,,,,,,,,,,,,,,,,,,,,,,,,,,,,,,,,
,3873623046.38257,300.000137329102,35160.826171875,0.00024835075569145,6.50528866175125E-6,1,2,13.1008939743042,2.00313410768755,31.9899991154671,0.0621733003961974,-0.00316159709253541,100,-4.93936494558848E-5,,,,,,,,,,,,,,,,,,,,,300.000122070313,300.000152587891,35070.546875,35251.10546875,52.7653964477171,5.98972994816943,8.4201192855835,26,1,0,0,1,0.149688720703125,31.7693061828613,1,6,1,300.000152587891,0,2084573888,300.000137329102,,,,,,,,,,,,,,,,,,,,,,,,,,,,,,,,,
,3873623141.66037,300.000427246094,44707.6015625,0.000312578775388744,0.000407402537775197,1,2,13.1008939743042,2.00318995849748,31.9899991154671,0.0917067999972716,-0.0957565751792793,100,-0.000439436349223797,,,,,,,,,,,,,,,,,,,,,300,300.000854492188,44612.265625,44802.9375,52.725924207496,5.98825784389619,8.4032564163208,26,1,0,0,1,0.150070190429687,31.2805480957031,1,6,1,300,0,2084574176,300.000427246094,,,,,,,,,,,,,,,,,,,,,,,,,,,,,,,,,
,3873623197.39014,300.000091552734,50000.263671875,0.000274044919161119,4.73136016664724E-6,1,2,13.1008939743042,2.00316803195742,31.9899991154671,0.0666145146283451,0.0101129860376359,100,1.41022496473261E-6,,,,,,,,,,,,,,,,,,,,,300.000030517578,300.000152587891,50000.25,50000.27734375,52.5668628038325,5.9873122530897,8.3946475982666,26,1,0,0,1,0.151824951171875,31.7693061828613,1,4,1,300.000152587891,0,2084573568,300.000091552734,,,,,,,,,,,,,,,,,,,,,,,,,,,,,,,,,