File: LT data/Frome/M1/311-FC-ZFC-RTSIRM-contsweepwithloop-MsT.dat
[Header]
; MPMS3 Data File (default extension .dat)
; Copyright (c) 2007, Quantum Design, Inc. All rights reserved.
TITLE,
FILEOPENTIME,3866275390.52582,07/06/2022,2:20 pm
BYAPP,MPMS3 w/ AC,1.0,1.1
INFO,MPMS3 Measurement Release 1.1.16 Build 424, MultiVu Release 2.3.4.19,APPNAME
INFO,Linear Motor Servo Controller,MOTOR_MODULE_NAME
INFO,3101-100 N2,MOTOR_HW_VERSION
INFO,,MOTOR_SERIAL_NUMBER
INFO,01.04.28,MOTOR_SOFTWARE_VERSION
INFO,Quantum Design Squid Module,SQUID_MODULE_NAME
INFO,3101-501 B0,SQUID_HW_VERSION
INFO,SQM327,SQUID_SERIAL_NUMBER
INFO,01.03.04,SQUID_SOFTWARE_VERSION
INFO,Quantum Design VSM Oven,OVEN_MODULE_NAME
INFO,3101-201 A3,OVEN_HW_VERSION
INFO,OVB365,OVEN_SERIAL_NUMBER
INFO,01.07.07,OVEN_SOFTWARE_VERSION
INFO,SQUID AC,AC_MODULE_NAME
INFO,3101-401 G0,AC_HW_VERSION
INFO,SAC220,AC_SERIAL_NUMBER
INFO,SQUID AC 00.95.07,AC_SOFTWARE_VERSION
INFO,TCI344,COIL_SERIAL_NUMBER
INFO,0,MOMENT_UNITS
INFO,lmst,SAMPLE_MATERIAL
INFO,,SAMPLE_COMMENT
INFO,127.59,SAMPLE_MASS
INFO,,SAMPLE_VOLUME
INFO,,SAMPLE_MOLECULAR_WEIGHT
INFO,,SAMPLE_SIZE
INFO,,SAMPLE_SHAPE
INFO,Straw,SAMPLE_HOLDER
INFO,Standard,SAMPLE_HOLDER_DETAIL
INFO,67.12,SAMPLE_OFFSET
DATATYPE,COMMENT,1
DATATYPE,TIME,2
STARTUPAXIS,X,2
STARTUPAXIS,Y1,5
FIELDGROUP, VSM,2,3,4,5,6,8,9,10,11,14,15
FIELDGROUP, DC, 2,3,4,14,56,57,58,59,60,61,62,63,64,65,66,67,68,69
FIELDGROUP, AC, 2,3,4,11,16,17,18,19,20,21,22,23,24,25,26,27,28,29,30
STARTUPGROUP, All
[Data]
Comment,Time Stamp (sec),Temperature (K),Magnetic Field (Oe),Moment (emu),M. Std. Err. (emu),Transport Action,Averaging Time (sec),Frequency (Hz),Peak Amplitude (mm),Center Position (mm),Lockin Signal' (V),Lockin Signal (V),Range,M. Quad. Signal (emu),AC Moment (emu),AC M. Std Err. (emu),AC Phase (deg),AC Phase Std. Err. (deg),AC Susceptibility (emu/Oe),AC Suscept. Std Err. (emu/Oe),AC X' (emu/Oe),AC X' Std Err. (emu/Oe),AC X'' (emu/Oe),AC X'' Std Err. (emu/Oe),AC Drive (Oe),AC Frequency (Hz),AC Averaging Time (sec),AC Cycles,AC Range,AC Measure Type,AC Signal' (V),AC Signal'' (V),AC Trim Coil Ratio,AC Trim Coil Phase,Min. Temperature (K),Max. Temperature (K),Min. Field (Oe),Max. Field (Oe),Mass (grams),Motor Lag (deg),Pressure (Torr),Measure Count,Measurement Number,SQUID Status (code),Motor Status (code),Measure Status (code),Motor Current (amps),Motor Temp. (C),Temp. Status (code),Field Status (code),Chamber Status (code),Chamber Temp (K),Redirection State,Average Temp (K),Rotation Angle (deg),Rotator state,DC Moment Fixed Ctr (emu),DC Moment Err Fixed Ctr (emu),DC Moment Free Ctr (emu),DC Moment Err Free Ctr (emu),DC Fixed Fit,DC Free Fit,DC Calculated Center (mm),DC Calculated Center Err (mm),DC Scan Length (mm),DC Scan Time (s),DC Number of Points,DC Squid Drift,DC Min V (V),DC Max V (V),DC Scans per Measure,Map 01,Map 02,Map 03,Map 04,Map 05,Map 06,Map 07,Map 08,Map 09,Map 10,Map 11,Map 12,Map 13,Map 14,Map 15,Map 16
,3866276366.73564,100.000907897949,49999.78515625,0.0736263167205421,5.02640634209053E-5,1,2,12.9061126708984,4.99838094621225,40.6600013375282,96.0979249927692,14.0708484346168,100,-3.52431009659621E-5,,,,,,,,,,,,,,,,,,,,,100.000907897949,100.000907897949,49999.78515625,49999.78515625,49.8280364724476,5.41962451613324,7.07221078872681,26,1,0,0,1,0.272750854492187,29.8142719268799,1,1,1,100.000907897949,0,100.000907897949,,,,,,,,,,,,,,,,,,,,,,,,,,,,,,,,,
,3866276453.19259,88.9771156311035,49999.78515625,0.082423892289013,1.83950644516324E-5,1,2,12.9061126708984,4.9956884173407,40.6100004911423,107.495695741044,15.7655985705138,100,-2.00381205593537E-5,,,,,,,,,,,,,,,,,,,,,88.7855529785156,89.1686782836914,49999.78515625,49999.78515625,49.8772790691591,5.42104873711831,7.02574825286865,26,1,0,0,1,0.269241333007813,31.2805480957031,2,1,1,88.7855529785156,0,88.9771156311035,,,,,,,,,,,,,,,,,,,,,,,,,,,,,,,,,
,3866276583.8407,67.3798408508301,49999.78515625,0.109765637237543,3.12711425281907E-5,1,2,12.9061126708984,4.99546833543076,40.5599996447563,143.164569466242,20.8639160873452,1000,-0.00012650291380153,,,,,,,,,,,,,,,,,,,,,67.1208801269531,67.638801574707,49999.78515625,49999.78515625,49.9745918198034,5.42061565152507,6.91722583770752,26,1,0,0,1,0.26824951171875,31.2805480957031,2,1,1,67.1208801269531,0,67.3798408508301,,,,,,,,,,,,,,,,,,,,,,,,,,,,,,,,,
,3866276679.31161,51.1298236846924,49999.78515625,0.1438971811246,5.54160885091436E-5,1,2,12.9061126708984,4.99414722595486,40.5099987983704,187.59981155608,27.4236808273651,1000,-0.000102714963962451,,,,,,,,,,,,,,,,,,,,,50.9360122680664,51.3236351013184,49999.78515625,49999.78515625,49.8893943112072,5.42841762205037,6.78129863739014,26,1,0,0,1,0.270309448242187,31.7693061828613,2,1,1,50.9360122680664,0,51.1298236846924,,,,,,,,,,,,,,,,,,,,,,,,,,,,,,,,,
,3866276757.85634,37.8407402038574,49999.78515625,0.190409374167404,9.71152640047577E-5,1,2,12.9061126708984,4.99474762247988,40.4900014400482,248.290318805809,36.2233974509225,1000,-0.000190077305188643,,,,,,,,,,,,,,,,,,,,,37.7173461914063,37.9641342163086,49999.78515625,49999.78515625,50.1418603229188,5.42769342496171,6.59324073791504,26,1,0,0,1,0.269088745117187,31.2805480957031,2,1,1,37.7173461914063,0,37.8407402038574,,,,,,,,,,,,,,,,,,,,,,,,,,,,,,,,,
,3866276836.54368,24.5081987380981,49999.78515625,0.268326161068033,0.000211745439511143,1,2,12.9061126708984,4.99516899873461,40.4600016772747,349.797977665997,51.9765416322134,1000,0.000440952857561414,,,,,,,,,,,,,,,,,,,,,24.3981094360352,24.6182880401611,49999.78515625,49999.78515625,50.1367797375438,5.42218172947502,6.22765588760376,26,1,0,0,1,0.268936157226562,32.7468223571777,2,1,1,24.3981094360352,0,24.5081987380981,,,,,,,,,,,,,,,,,,,,,,,,,,,,,,,,,
,3866276916.9645,11.433340549469,49999.78515625,0.406838311623514,0.00668421726518938,1,2,12.9061126708984,4.99291653140535,40.4400005936623,529.803973520929,80.3042204965437,1000,0.00185556683297987,,,,,,,,,,,,,,,,,,,,,11.2768411636353,11.5898399353027,49999.78515625,49999.78515625,50.1109859964091,5.43128704235904,5.13081359863281,26,1,0,0,1,0.277633666992187,31.2805480957031,2,1,1,11.2768411636353,0,11.433340549469,,,,,,,,,,,,,,,,,,,,,,,,,,,,,,,,,
,3866276993.58584,4.27239227294922,49999.78515625,0.453763930524816,0.0218617168654797,1,2,12.9061126708984,4.99232151299745,40.4400005936623,590.684345502064,90.4338979029222,1000,0.00274668382001532,,,,,,,,,,,,,,,,,,,,,4.26848077774048,4.27630376815796,49999.78515625,49999.78515625,50.6510913031977,5.43618536516839,3.82896518707275,16,1,68,0,0,0.279998779296875,31.2805480957031,6,1,1,4.26848077774048,0,4.27239227294922,,,,,,,,,,,,,,,,,,,,,,,,,,,,,,,,,
,3866277100.51784,3.9365930557251,49999.78515625,0.403548704368979,0.0303971437906495,1,2,12.9061126708984,4.9920447347956,40.4400005936623,528.600504075085,57.7914376661332,1000,-0.0149263503772014,,,,,,,,,,,,,,,,,,,,,3.93605971336365,3.93712639808655,49999.78515625,49999.78515625,50.49632885639,5.43902481822076,3.61383533477783,15,1,68,0,0,0.27740478515625,31.2805480957031,6,1,1,3.93712639808655,0,3.9365930557251,,,,,,,,,,,,,,,,,,,,,,,,,,,,,,,,,
,3866277207.04839,3.9455394744873,49999.78515625,0.49698175695906,0.0189336116708518,1,2,12.9061126708984,4.99124406598193,40.4400005936623,646.586677013587,100.108500122603,1000,0.00384620483975111,,,,,,,,,,,,,,,,,,,,,3.94357061386108,3.94750833511353,49999.78515625,49999.78515625,50.5060992128803,5.44239833521987,3.60735845565796,18,1,68,0,0,0.281295776367187,31.7693061828613,6,1,1,3.94357061386108,0,3.9455394744873,,,,,,,,,,,,,,,,,,,,,,,,,,,,,,,,,
,3866277288.04526,2.74614858627319,49999.78515625,0.445475719389112,0.0197515349031628,1,2,12.9061126708984,4.99243140513819,40.4400005936623,579.462521584019,91.8520023586169,1000,0.00505055572784233,,,,,,,,,,,,,,,,,,,,,2.74287366867065,2.74942350387573,49999.78515625,49999.78515625,50.3923722633323,5.43823122917237,3.0719723701477,18,1,68,0,0,0.278472900390625,31.7693061828613,6,1,1,2.74050235748291,0,2.74614858627319,,,,,,,,,,,,,,,,,,,,,,,,,,,,,,,,,
,3866277364.4022,2.69317960739136,49999.78515625,0.527681809369913,0.0137205794675378,1,2,12.9061126708984,4.99160241525139,40.4400005936623,688.2504188679,95.0515442599011,1000,-0.00455379522420405,,,,,,,,,,,,,,,,,,,,,2.69310235977173,2.69325685501099,49999.78515625,49999.78515625,50.6577351456111,5.44182844211023,3.02790331840515,21,1,68,0,0,0.278167724609375,31.7693061828613,6,1,1,2.69325685501099,0,2.69317960739136,,,,,,,,,,,,,,,,,,,,,,,,,,,,,,,,,
,3866277442.76545,2.69683015346527,49999.78515625,0.496320254822016,0.0178712832673548,1,2,12.9061126708984,4.99134593903745,40.4400005936623,649.073665837244,77.3172437473286,1000,-0.0135562925694554,,,,,,,,,,,,,,,,,,,,,2.69565510749817,2.69800519943237,49999.78515625,49999.78515625,50.6264700048419,5.44186045060947,3.00638794898987,17,1,68,0,0,0.2813720703125,31.7693061828613,6,1,1,2.69800519943237,0,2.69683015346527,,,,,,,,,,,,,,,,,,,,,,,,,,,,,,,,,
,3866277534.76475,2.60300803184509,49999.78515625,0.501656322016646,0.0201575412101635,1,2,12.9061126708984,4.99225260257176,40.4400005936623,653.051218374286,99.7324366647399,1000,0.00284903784219257,,,,,,,,,,,,,,,,,,,,,2.59905028343201,2.60696578025818,49999.78515625,49999.78515625,50.674149344515,5.43827232184619,2.94338798522949,20,1,68,0,0,0.277175903320313,31.7693061828613,6,1,1,2.59905028343201,0,2.60300803184509,,,,,,,,,,,,,,,,,,,,,,,,,,,,,,,,,
,3866277616.49591,2.56562447547913,49999.78515625,0.473923129256792,0.0232253286257152,1,2,12.9061126708984,4.99334275374166,40.4400005936623,616.615600089607,97.7995165423316,1000,0.00541678458965035,,,,,,,,,,,,,,,,,,,,,2.56499576568604,2.56625318527222,49999.78515625,49999.78515625,50.8078078213035,5.4337051031074,2.88826608657837,13,1,68,0,0,0.275421142578125,31.7693061828613,6,1,1,2.56625318527222,0,2.56562447547913,,,,,,,,,,,,,,,,,,,,,,,,,,,,,,,,,
,3866277718.98984,2.50289368629456,49999.78515625,0.468322622863387,0.0181245600248608,1,2,12.9061126708984,4.99416289829639,40.4400005936623,615.937642736186,52.6363698042516,1000,-0.0284232905868473,,,,,,,,,,,,,,,,,,,,,2.50173330307007,2.50405406951904,49999.78515625,49999.78515625,50.6870462150823,5.4307140121103,2.83189630508423,13,1,68,0,0,0.272140502929687,30.7917900085449,6,1,1,2.50405406951904,0,2.50289368629456,,,,,,,,,,,,,,,,,,,,,,,,,,,,,,,,,
,3866277816.85535,2.49730217456818,49999.78515625,0.47573319928952,0.0209234802938737,1,2,12.9061126708984,4.99324817984651,40.4400005936623,621.260573501495,82.4714397399732,1000,-0.00660864204956981,,,,,,,,,,,,,,,,,,,,,2.49661326408386,2.49799108505249,49999.78515625,49999.78515625,50.6073201061207,5.43500822785246,2.83817219734192,17,1,68,0,0,0.275497436523438,31.7693061828613,6,1,1,2.49799108505249,0,2.49730217456818,,,,,,,,,,,,,,,,,,,,,,,,,,,,,,,,,
,3866277904.07771,2.42247986793518,49999.78515625,0.483132300933606,0.01919743753312,1,2,12.9061126708984,4.99302355021444,40.4400005936623,626.956394425951,110.4784182085,1000,0.0137999411570691,,,,,,,,,,,,,,,,,,,,,2.42049598693848,2.42446374893188,49999.78515625,49999.78515625,50.6948625002746,5.4353568807904,2.81542611122131,18,1,68,0,0,0.282745361328125,32.2580642700195,6,1,1,2.42049598693848,0,2.42247986793518,,,,,,,,,,,,,,,,,,,,,,,,,,,,,,,,,
,3866277990.90928,2.41467785835266,49999.78515625,0.45765784911758,0.0202182781057551,1,2,12.9061126708984,4.99229803911923,40.4400005936623,597.338882445886,80.3893045825969,1000,-0.00553436695615338,,,,,,,,,,,,,,,,,,,,,2.41407752037048,2.41527819633484,49999.78515625,49999.78515625,50.724955198265,5.43855286033826,2.81026887893677,16,1,68,0,0,0.276718139648438,31.7693061828613,6,1,1,2.41407752037048,0,2.41467785835266,,,,,,,,,,,,,,,,,,,,,,,,,,,,,,,,,
,3866278069.58797,2.35140717029572,49999.78515625,0.485144648555079,0.0179777338544472,1,2,12.9061126708984,4.99210244527766,40.4400005936623,630.65970113065,102.368637213261,1000,0.00730146724128453,,,,,,,,,,,,,,,,,,,,,2.35110425949097,2.35171008110046,49999.78515625,49999.78515625,50.7585652245919,5.4383020463187,2.77824401855469,20,1,68,0,0,0.279769897460938,32.7468223571777,6,1,1,2.35171008110046,0,2.35140717029572,,,,,,,,,,,,,,,,,,,,,,,,,,,,,,,,,
,3866278154.26825,2.26150059700012,49999.78515625,0.554695757766747,0.0178054957790891,1,2,12.9061126708984,4.99331339268362,40.4400005936623,722.127020653164,111.573411205223,1000,0.00411977586817138,,,,,,,,,,,,,,,,,,,,,2.2605562210083,2.26244497299194,49999.78515625,49999.78515625,50.60810173464,5.4340923396764,2.70605659484863,15,1,68,0,0,0.285873413085938,32.7468223571777,6,1,1,2.2605562210083,0,2.26150059700012,,,,,,,,,,,,,,,,,,,,,,,,,,,,,,,,,
,3866278239.82248,2.28357970714569,49999.78515625,0.474715816328588,0.0236774848688624,1,2,12.9061126708984,4.99320125256301,40.4400005936623,617.185226100712,100.935036662073,1000,0.00770928366536386,,,,,,,,,,,,,,,,,,,,,2.28133010864258,2.2858293056488,49999.78515625,49999.78515625,50.8027272359284,5.43356549946875,2.70569086074829,17,1,68,0,0,0.282821655273438,31.2805480957031,6,1,1,2.2858293056488,0,2.28357970714569,,,,,,,,,,,,,,,,,,,,,,,,,,,,,,,,,
,3866278321.35542,2.30859959125519,49999.78515625,0.469278324039641,0.0250668568370172,1,2,12.9061126708984,4.99241872526472,40.4400005936623,609.483313047949,103.149782857705,1000,0.0102249479198259,,,,,,,,,,,,,,,,,,,,,2.30804514884949,2.30915403366089,49999.78515625,49999.78515625,50.6350679185534,5.43577822299798,2.73713040351868,15,1,68,0,0,0.283584594726562,31.7693061828613,6,1,1,2.30915403366089,0,2.30859959125519,,,,,,,,,,,,,,,,,,,,,,,,,,,,,,,,,
,3866278401.68351,2.23605346679687,49999.78515625,0.516002282962488,0.0178438247696999,1,2,12.9061126708984,4.99341518846847,40.4400005936623,672.413691017146,99.4349507409726,1000,0.000488207786938148,,,,,,,,,,,,,,,,,,,,,2.23229765892029,2.23980927467346,49999.78515625,49999.78515625,50.6327230329957,5.43348692553401,2.67494249343872,19,1,68,0,0,0.273590087890625,32.7468223571777,6,1,1,2.23229765892029,0,2.23605346679687,,,,,,,,,,,,,,,,,,,,,,,,,,,,,,,,,
,3866278478.24902,2.23006796836853,49999.78515625,0.488919715750239,0.0198509833554956,1,2,12.9061126708984,4.99292632081609,40.4400005936623,636.069343420207,100.771679559626,1000,0.00550319863371064,,,,,,,,,,,,,,,,,,,,,2.22781467437744,2.23232126235962,49999.78515625,49999.78515625,50.65890758839,5.43466431918097,2.66713356971741,19,1,68,0,0,0.276260375976562,31.7693061828613,6,1,1,2.22781467437744,0,2.23006796836853,,,,,,,,,,,,,,,,,,,,,,,,,,,,,,,,,
,3866279082.58009,19.6659202575684,26.2745456695557,0.000157601790328069,2.44933809252048E-7,1,5,12.9061126708984,5.00468896607463,40.4400005936623,0.206057322655584,0.030240567966079,1,-2.35911975286971E-8,,,,,,,,,,,,,,,,,,,,,19.033016204834,20.2988243103027,26.2745456695557,26.2745456695557,49.9702928629476,5.42642540820056,5.5089750289917,65,1,0,0,1,0.27496337890625,31.7693061828613,2,1,1,20.2988243103027,0,19.6659202575684,,,,,,,,,,,,,,,,,,,,,,,,,,,,,,,,,
,3866279307.50176,55.0336799621582,26.2745456695557,3.32005405535417E-5,1.50943762312813E-8,1,5,12.9061126708984,4.99912093865566,40.4600016772747,0.0433477637137655,0.00631199404920456,1,-4.21930689278744E-8,,,,,,,,,,,,,,,,,,,,,55.0336799621582,55.0336799621582,26.2745456695557,26.2745456695557,50.0058569605726,5.45181320685166,6.38364887237549,63,1,64,0,0,0.279998779296875,32.2580642700195,2,1,1,55.0336799621582,0,55.0336799621582,,,,,,,,,,,,,,,,,,,,,,,,,,,,,,,,,
,3866279531.92162,91.030403137207,26.2745456695557,2.14025315605513E-5,7.68304667220112E-9,1,5,12.9061126708984,4.9972030194647,40.5099987983704,0.027929235586532,0.00406423711105371,1,-2.91657280334894E-8,,,,,,,,,,,,,,,,,,,,,91.030403137207,91.030403137207,26.2745456695557,26.2745456695557,49.9460623788514,5.45630134570868,6.67498254776001,65,1,0,0,1,0.27496337890625,31.2805480957031,2,1,1,91.030403137207,0,91.030403137207,,,,,,,,,,,,,,,,,,,,,,,,,,,,,,,,,
,3866279750.64707,127.025512695313,26.2745456695557,1.4354977583329E-5,8.20227352850921E-9,1,5,12.9061126708984,5.00261659166306,40.6000018119812,0.0187608549236377,0.00273079142285236,1,-1.90157999453739E-8,,,,,,,,,,,,,,,,,,,,,127.025512695313,127.025512695313,26.2745456695557,26.2745456695557,50.1551480077457,5.43516138017598,6.80163955688477,65,1,0,0,1,0.27984619140625,31.7693061828613,2,1,1,127.025512695313,0,127.025512695313,,,,,,,,,,,,,,,,,,,,,,,,,,,,,,,,,
,3866279967.66626,163.03385925293,26.2745456695557,1.05129293559704E-5,6.33524162057038E-9,1,5,12.9061126708984,5.00419048084451,40.7099984586239,0.0137459275118293,0.00199885361900629,1,-1.54057027862464E-8,,,,,,,,,,,,,,,,,,,,,163.03385925293,163.03385925293,26.2745456695557,26.2745456695557,50.0773759700822,5.42707691642446,6.9025502204895,63,1,64,0,0,0.275802612304687,31.2805480957031,2,1,1,163.03385925293,0,163.03385925293,,,,,,,,,,,,,,,,,,,,,,,,,,,,,,,,,
,3866280185.29123,199.032180786133,26.2745456695557,8.10798314648648E-6,6.79562601607008E-9,1,5,12.9061126708984,5.00680702887058,40.8499985933304,0.0106071215725998,0.00155656036103055,1,-1.30344211290774E-9,,,,,,,,,,,,,,,,,,,,,199.032180786133,199.032180786133,26.2745456695557,26.2745456695557,50.0019488179764,5.41805179053354,6.99068069458008,64,1,64,0,0,0.271682739257813,31.7693061828613,2,1,1,199.032180786133,0,199.032180786133,,,,,,,,,,,,,,,,,,,,,,,,,,,,,,,,,
,3866280402.85802,235.167404174805,26.2745456695557,6.61578193885812E-6,7.29995811955946E-9,1,5,12.9061126708984,5.00822155640614,41.0199984908104,0.00865917121876504,0.00126531813458135,1,-5.09284738984183E-9,,,,,,,,,,,,,,,,,,,,,235.167404174805,235.167404174805,26.2745456695557,26.2745456695557,50.0367312870822,5.41390348987112,7.19446992874146,65,1,0,0,1,0.2874755859375,32.7468223571777,2,1,1,235.167404174805,0,235.167404174805,,,,,,,,,,,,,,,,,,,,,,,,,,,,,,,,,
,3866280615.56002,270.469741821289,26.2745456695557,5.48807826138234E-6,6.75162903372279E-9,1,5,12.9061126708984,5.0101458899193,41.2000007927418,0.00718710826140638,0.00104958278301239,1,-4.69628307180667E-9,,,,,,,,,,,,,,,,,,,,,270.073394775391,270.866088867187,26.2745456695557,26.2745456695557,49.9761550768418,5.40647835726166,7.43371486663818,65,1,0,0,1,0.278778076171875,31.7693061828613,2,1,1,270.866088867187,0,270.469741821289,,,,,,,,,,,,,,,,,,,,,,,,,,,,,,,,,
,3866283463.49801,1.99954497814178,47365.92578125,0.404329510889034,0.0243902344126675,1,2,12.9061126708984,4.98363445002749,40.4299981892109,527.005272099466,67.062699523998,1000,-0.00780265322410423,,,,,,,,,,,,,,,,,,,,,1.99954497814178,1.99954497814178,47365.92578125,47365.92578125,50.60810173464,5.43009716341436,2.47855687141418,13,1,68,0,0,0.287246704101562,31.7693061828613,1,6,1,1.99954497814178,0,1.99954497814178,,,,,,,,,,,,,,,,,,,,,,,,,,,,,,,,,
,3866283563.50242,1.9975078701973,37377.908203125,0.318757558942965,0.0223200836721078,1,2,12.9061126708984,4.98337800345495,40.4299981892109,416.206809747303,47.6481891013008,1000,-0.0101659943063793,,,,,,,,,,,,,,,,,,,,,1.99501526355743,2.00000047683716,37322.99609375,37432.8203125,50.2575413437649,5.42897347510362,2.46447038650513,14,1,68,0,0,0.274581909179687,31.7693061828613,6,6,1,2.00000047683716,0,1.9975078701973,,,,,,,,,,,,,,,,,,,,,,,,,,,,,,,,,
,3866283643.72273,2.00188380479813,29370.2998046875,0.381620827023453,0.0179263143296122,1,2,12.9061126708984,4.98335130304169,40.4299981892109,497.441598068415,62.7829848437625,1000,-0.00775543821945804,,,,,,,,,,,,,,,,,,,,,1.99884021282196,2.00492739677429,29275.44921875,29465.150390625,50.4189476329861,5.42753948195065,2.47209668159485,18,1,68,0,0,0.271377563476562,29.3255138397217,6,6,1,2.00492739677429,0,2.00188380479813,,,,,,,,,,,,,,,,,,,,,,,,,,,,,,,,,
,3866283722.4614,1.99981307983398,21508.29296875,0.400146355843967,0.00940788804827466,1,2,12.9061126708984,4.98318452634742,40.4299981892109,519.508903472727,79.8234567109995,1000,0.00263776664958885,,,,,,,,,,,,,,,,,,,,,1.99739599227905,2.00223016738892,21438.3125,21578.2734375,50.188367219813,5.42874568684469,2.4680380821228,24,1,68,0,0,0.272750854492187,31.7693061828613,6,6,1,1.99739599227905,0,1.99981307983398,,,,,,,,,,,,,,,,,,,,,,,,,,,,,,,,,
,3866283800.82401,2.00078332424164,13686.4887695313,0.324730642297854,0.00313677608236439,1,2,12.9061126708984,4.98339312896649,40.4299981892109,422.197343907463,60.8645328864835,1000,-0.000874366647079921,,,,,,,,,,,,,,,,,,,,,1.9996075630188,2.00195908546448,13591.814453125,13781.1630859375,50.3779121357265,5.42831158902684,2.46738934516907,26,1,0,0,1,0.281982421875,31.2805480957031,1,6,1,2.00195908546448,0,2.00078332424164,,,,,,,,,,,,,,,,,,,,,,,,,,,,,,,,,
,3866283881.56903,1.99956613779068,5618.29052734375,0.172515785559505,0.000276371333866036,1,2,12.9061126708984,4.98343012681715,40.4299981892109,224.231011583503,32.7917778096181,1000,-0.000113138533076138,,,,,,,,,,,,,,,,,,,,,1.99950730800629,1.99962496757507,5538.36376953125,5698.21728515625,50.2329200454092,5.42739830582982,2.4705662727356,26,1,0,0,1,0.280914306640625,31.7693061828613,1,6,1,1.99962496757507,0,1.99956613779068,,,,,,,,,,,,,,,,,,,,,,,,,,,,,,,,,
,3866283966.11293,2.00027656555176,-2832.22326660156,-0.0932480862638219,0.000321884401560901,1,2,12.9061126708984,4.98355204731743,40.4299981892109,-121.196544312132,-17.7849471306319,100,1.51780794441608E-5,,,,,,,,,,,,,,,,,,,,,2.00015306472778,2.00040006637573,-2917.00122070313,-2747.4453125,50.2931054413899,5.42661807109837,2.46859073638916,26,1,0,0,1,0.278472900390625,32.2580642700195,1,6,1,2.00015306472778,0,2.00027656555176,,,,,,,,,,,,,,,,,,,,,,,,,,,,,,,,,
,3866284064.75742,2.00033450126648,-12696.6923828125,-0.312433228043869,0.000198846880030895,1,2,12.9061126708984,4.98358242294483,40.4299981892109,-406.078285166617,-59.5994361341719,1000,4.36160238588983E-5,,,,,,,,,,,,,,,,,,,,,2.00029397010803,2.00037503242493,-12786.62890625,-12606.755859375,50.3962804059284,5.42629441049839,2.45152831077576,26,1,0,0,1,0.27191162109375,31.2805480957031,1,6,1,2.00037503242493,0,2.00033450126648,,,,,,,,,,,,,,,,,,,,,,,,,,,,,,,,,
,3866284143.48562,2.00007903575897,-20566.791015625,-0.403148726999969,0.00686085487482667,1,2,12.9061126708984,4.98369040977764,40.4299981892109,-523.675062536733,-79.116549670768,1000,-0.00164404192064593,,,,,,,,,,,,,,,,,,,,,1.99980139732361,2.00035667419434,-20676.865234375,-20456.716796875,50.3036574263996,5.42626252286014,2.44365501403809,25,1,68,0,0,0.2789306640625,31.7693061828613,1,6,1,2.00035667419434,0,2.00007903575897,,,,,,,,,,,,,,,,,,,,,,,,,,,,,,,,,
,3866284223.20091,1.9993422627449,-28542.5947265625,-0.430971803101195,0.0124234371532611,1,2,12.9061126708984,4.98376346573571,40.4299981892109,-560.07518606395,-82.8940392148265,1000,-0.000461553682787877,,,,,,,,,,,,,,,,,,,,,1.99868953227997,1.99999499320984,-28702.798828125,-28382.390625,50.3685325934957,5.42698843091853,2.43927526473999,22,1,68,0,0,0.272064208984375,31.2805480957031,1,6,1,1.99999499320984,0,1.9993422627449,,,,,,,,,,,,,,,,,,,,,,,,,,,,,,,,,
,3866284302.44891,2.00259709358215,-36481.51953125,-0.432287232622653,0.0180529813245718,1,2,12.9061126708984,4.98384421543821,40.4299981892109,-561.38194815913,-85.977262114534,1000,-0.00263893029404055,,,,,,,,,,,,,,,,,,,,,2.00071907043457,2.00447511672974,-36576.640625,-36386.3984375,50.5783998509092,5.4285291447774,2.42499804496765,15,1,68,0,0,0.277633666992187,31.7693061828613,6,6,1,2.00071907043457,0,2.00259709358215,,,,,,,,,,,,,,,,,,,,,,,,,,,,,,,,,
,3866284385.03918,1.99474787712097,-44761.92578125,-0.428304650336845,0.0240358926731874,1,2,12.9061126708984,4.98366048679016,40.4299981892109,-555.472662392284,-90.0038743656028,1000,-0.00632547856844195,,,,,,,,,,,,,,,,,,,,,1.98849821090698,2.00099754333496,-44852.01953125,-44671.83203125,50.613182320015,5.42959650298919,2.41750717163086,16,1,68,0,0,0.271835327148438,31.7693061828613,6,6,1,1.98849821090698,0,1.99474787712097,,,,,,,,,,,,,,,,,,,,,,,,,,,,,,,,,
,3866284473.90041,1.99737590551376,-46902.462890625,-0.423987617963933,0.0116840586971773,1,2,12.9061126708984,4.98360976786556,40.4299981892109,-547.715381592043,-103.734320351332,1000,-0.0175249133473368,,,,,,,,,,,,,,,,,,,,,1.99078094959259,2.00397086143494,-47017.1015625,-46787.82421875,50.7691172096015,5.43035611314751,2.42776322364807,14,1,68,0,0,0.270309448242187,32.2580642700195,6,6,1,2.00397086143494,0,1.99737590551376,,,,,,,,,,,,,,,,,,,,,,,,,,,,,,,,,
,3866284556.27455,2.00174188613892,-38678.240234375,-0.398490491631054,0.0267113392528177,1,2,12.9061126708984,4.98354673704684,40.4299981892109,-517.777324391128,-77.0141390093263,1000,-0.000713226828699137,,,,,,,,,,,,,,,,,,,,,1.99750828742981,2.00597548484802,-38773.05859375,-38583.421875,50.66906875914,5.42939486657492,2.427973985672,15,1,68,0,0,0.273361206054687,34.7018585205078,6,6,1,2.00597548484802,0,2.00174188613892,,,,,,,,,,,,,,,,,,,,,,,,,,,,,,,,,
,3866284632.83572,1.99936157464981,-31042.58984375,-0.444897493822634,0.014575635058465,1,2,12.9061126708984,4.98358222623376,40.4299981892109,-575.929382837505,-100.635655719545,1000,-0.0120695077159915,,,,,,,,,,,,,,,,,,,,,1.99921357631683,1.99950957298279,-31137.408203125,-30947.771484375,50.3208532538226,5.42870490088725,2.42014479637146,20,1,68,0,0,0.2728271484375,31.7693061828613,5,6,1,1.99921357631683,0,1.99936157464981,,,,,,,,,,,,,,,,,,,,,,,,,,,,,,,,,
,3866284713.70188,1.99993091821671,-22967.275390625,-0.418931604863671,0.00959793959695188,1,2,12.9061126708984,4.9835599367946,40.4299981892109,-542.918485528384,-90.6372301244984,1000,-0.00819175640551147,,,,,,,,,,,,,,,,,,,,,1.99991619586945,1.99994564056396,-23032.021484375,-22902.529296875,50.2985768410246,5.42757281112453,2.42259693145752,24,1,68,0,0,0.271530151367187,31.7693061828613,1,6,1,1.99991619586945,0,1.99993091821671,,,,,,,,,,,,,,,,,,,,,,,,,,,,,,,,,
,3866284791.99533,1.9999006986618,-15151.2631835938,-0.352009532804668,0.00369472752135815,1,2,12.9061126708984,4.98330413590589,40.4299981892109,-457.478030318545,-67.1627483305332,1000,3.44854729994912E-5,,,,,,,,,,,,,,,,,,,,,1.99959540367126,2.00020599365234,-15246.1826171875,-15056.34375,50.3376582669861,5.42658457730251,2.43252563476562,26,1,0,0,1,0.272979736328125,32.2580642700195,1,6,1,2.00020599365234,0,1.9999006986618,,,,,,,,,,,,,,,,,,,,,,,,,,,,,,,,,
,3866284870.64868,2.00019013881683,-7294.77856445313,-0.21497324298817,0.000259865450858063,1,2,12.9061126708984,4.9835076984935,40.4299981892109,-279.422464254636,-40.8604584010555,1000,0.000142922545947316,,,,,,,,,,,,,,,,,,,,,2.00003528594971,2.00034499168396,-7394.9814453125,-7194.57568359375,50.0898820263899,5.42554034487546,2.43140721321106,26,1,0,0,1,0.271530151367187,31.7693061828613,1,6,1,2.00034499168396,0,2.00019013881683,,,,,,,,,,,,,,,,,,,,,,,,,,,,,,,,,
,3866284963.22901,2.00008177757263,1958.85784912109,0.0687162858063512,0.000352302682757868,1,2,12.9061126708984,4.98366346998755,40.4299981892109,89.3089810789692,13.1463649382493,100,1.95043234871483E-5,,,,,,,,,,,,,,,,,,,,,1.99971747398376,2.0004460811615,1868.95275878906,2048.76293945313,49.9691204201687,5.42566864932771,2.42618942260742,26,1,0,0,1,0.278701782226562,31.7693061828613,1,6,1,2.0004460811615,0,2.00008177757263,,,,,,,,,,,,,,,,,,,,,,,,,,,,,,,,,
,3866285057.88975,1.99989807605743,11424.08203125,0.297526116357374,0.000206305165640242,1,2,12.9061126708984,4.98358550059257,40.4299981892109,386.726103522745,56.6014639966912,1000,-0.000160297777363262,,,,,,,,,,,,,,,,,,,,,1.99931073188782,2.00048542022705,11328.9560546875,11519.2080078125,50.1297450808707,5.42666689042693,2.42817115783691,26,1,0,0,1,0.272216796875,31.2805480957031,1,6,1,1.99931073188782,0,1.99989807605743,,,,,,,,,,,,,,,,,,,,,,,,,,,,,,,,,
,3866285136.73384,1.99969303607941,19310.4013671875,0.400898773399555,0.00462648257446489,1,2,12.9061126708984,4.98355613872302,40.4299981892109,521.341196223326,74.530388315286,1000,-0.00155176352283894,,,,,,,,,,,,,,,,,,,,,1.99948441982269,1.99990165233612,19190.537109375,19430.265625,50.0633066567361,5.42595381204236,2.41810870170593,26,1,0,0,1,0.272750854492187,31.7693061828613,1,6,1,1.99948441982269,0,1.99969303607941,,,,,,,,,,,,,,,,,,,,,,,,,,,,,,,,,
,3866285217.06846,2.00000005960464,27349.6787109375,0.446187165717246,0.0115704680341549,1,2,12.9061126708984,4.98348689028567,40.4299981892109,580.121309225908,83.6492788613882,1000,-0.00118767392515346,,,,,,,,,,,,,,,,,,,,,1.99967181682587,2.00032830238342,27254.52734375,27444.830078125,50.3239797678996,5.42690607057655,2.40543627738953,24,1,68,0,0,0.27069091796875,32.2580642700195,1,6,1,2.00032830238342,0,2.00000005960464,,,,,,,,,,,,,,,,,,,,,,,,,,,,,,,,,
,3866285297.78823,1.99961161613464,35436.474609375,0.466497465588418,0.0146590915334786,1,2,12.9061126708984,4.98347172730342,40.4299981892109,606.277420158381,89.1462986811413,1000,5.83754523061364E-5,,,,,,,,,,,,,,,,,,,,,1.99959111213684,1.99963212013245,35361.34375,35511.60546875,50.4693626724765,5.42767949535389,2.40101957321167,21,1,68,0,0,0.272140502929687,31.7693061828613,1,6,1,1.99959111213684,0,1.99961161613464,,,,,,,,,,,,,,,,,,,,,,,,,,,,,,,,,
,3866285375.48533,2.00062930583954,43222.416015625,0.436267747810589,0.0222986212321185,1,2,12.9061126708984,4.98363189925608,40.4299981892109,569.929988336702,63.5338468250079,1000,-0.0152097803975341,,,,,,,,,,,,,,,,,,,,,2.0002543926239,2.00100421905518,43057.31640625,43387.515625,50.6034119635246,5.4282241967901,2.4067006111145,17,1,68,0,0,0.270919799804687,31.7693061828613,1,6,1,2.0002543926239,0,2.00062930583954,,,,,,,,,,,,,,,,,,,,,,,,,,,,,,,,,
,3866285894.19729,11.0032992362976,26.4625797271729,7.24570579579052E-5,2.43409886267891E-7,1,5,12.9061126708984,4.98367769428293,40.4299981892109,0.0941845055195381,0.0137712032043315,10,-4.93543664302189E-8,,,,,,,,,,,,,,,,,,,,,10.6372690200806,11.3693294525146,26.4625797271729,26.4625797271729,50.157883707563,5.42478133525813,4.66846752166748,65,1,0,0,1,0.277481079101562,31.2805480957031,6,1,1,11.3693294525146,0,11.0032992362976,,,,,,,,,,,,,,,,,,,,,,,,,,,,,,,,,
,3866286126.84554,47.028076171875,26.4625797271729,2.57165147926813E-5,1.00518330202005E-8,1,5,12.9061126708984,4.98084944358366,40.4499992728233,0.0334035859091593,0.00486876557597464,1,-2.90843201152003E-8,,,,,,,,,,,,,,,,,,,,,47.028076171875,47.028076171875,26.4625797271729,26.4625797271729,50.0171905741014,5.44165606061834,6.25338220596313,63,1,64,0,0,0.276107788085938,31.2805480957031,2,1,1,47.028076171875,0,47.028076171875,,,,,,,,,,,,,,,,,,,,,,,,,,,,,,,,,
,3866286352.9826,83.0248260498047,26.4625797271729,1.81154487867011E-5,8.31588589297548E-9,1,5,12.9061126708984,4.98728979958189,40.5000001192093,0.0235740483240243,0.00343014425939527,1,-2.49346282749694E-8,,,,,,,,,,,,,,,,,,,,,83.0248260498047,83.0248260498047,26.4625797271729,26.4625797271729,50.1039513397361,5.45034501030623,6.61029958724976,63,1,64,0,0,0.279617309570313,32.7468223571777,2,1,1,83.0248260498047,0,83.0248260498047,,,,,,,,,,,,,,,,,,,,,,,,,,,,,,,,,
,3866286572.43711,119.11873626709,26.4625797271729,1.30418573937284E-5,6.47750272710602E-9,1,5,12.9061126708984,4.99261265060093,40.5800007283688,0.0169978054992966,0.00246831329313427,1,-2.16736607693644E-8,,,,,,,,,,,,,,,,,,,,,119.11873626709,119.11873626709,26.4625797271729,26.4625797271729,50.1383429945822,5.42912302170041,6.7676157951355,65,1,0,0,1,0.2783203125,31.7693061828613,2,1,1,119.11873626709,0,119.11873626709,,,,,,,,,,,,,,,,,,,,,,,,,,,,,,,,,
,3866286789.30286,155.033416748047,26.4625797271729,9.99084069671511E-6,5.50286262702772E-9,1,5,12.9061126708984,4.99214965187298,40.6900011003017,0.0130198118982999,0.0018894530626129,1,-1.75061050020364E-8,,,,,,,,,,,,,,,,,,,,,155.033416748047,155.033416748047,26.4625797271729,26.4625797271729,50.0953534260245,5.43446373890059,6.86258506774902,65,1,0,0,1,0.2783203125,31.7693061828613,2,1,1,155.033416748047,0,155.033416748047,,,,,,,,,,,,,,,,,,,,,,,,,,,,,,,,,
,3866287006.78094,191.023376464844,26.4625797271729,8.18604511228956E-6,7.22600036585478E-9,1,5,12.9061126708984,4.99489629692542,40.8199988305569,0.0106742192457658,0.00156199228282504,1,-4.63025152931448E-9,,,,,,,,,,,,,,,,,,,,,191.023376464844,191.023376464844,26.4625797271729,26.4625797271729,49.9460623788514,5.42476634894439,6.9477334022522,65,1,0,0,1,0.268173217773438,30.7917900085449,2,1,1,191.023376464844,0,191.023376464844,,,,,,,,,,,,,,,,,,,,,,,,,,,,,,,,,
,3866287223.39336,227.018905639648,26.4625797271729,6.93058766072822E-6,7.03864778200081E-9,1,5,12.9061126708984,4.99691196440721,40.9700013697147,0.00904369318146537,0.00131352462822076,1,-1.13247577023544E-8,,,,,,,,,,,,,,,,,,,,,227.018905639648,227.018905639648,26.4625797271729,26.4625797271729,50.0820657411976,5.41667681657035,7.11359691619873,64,1,64,0,0,0.275039672851562,31.7693061828613,2,1,1,227.018905639648,0,227.018905639648,,,,,,,,,,,,,,,,,,,,,,,,,,,,,,,,,
,3866287441.20316,263.109649658203,26.4625797271729,6.00609046571847E-6,7.27560885948249E-9,1,5,12.9061126708984,4.99820253601368,41.1599986255169,0.00783783189853894,0.00115455074353591,1,2.31574317759963E-9,,,,,,,,,,,,,,,,,,,,,263.109649658203,263.109649658203,26.4625797271729,26.4625797271729,50.0167997598418,5.41160422855222,7.50460004806519,64,1,64,0,0,0.266494750976562,31.7693061828613,2,1,1,263.109649658203,0,263.109649658203,,,,,,,,,,,,,,,,,,,,,,,,,,,,,,,,,
,3866287667.49078,299.007049560547,26.4625797271729,5.26446883373142E-6,8.21422245506307E-9,1,5,12.9061126708984,5.00038137745518,41.3599982857704,0.00687386300642816,0.00101507515378375,1,3.91998249447309E-9,,,,,,,,,,,,,,,,,,,,,299.007049560547,299.007049560547,26.4625797271729,26.4625797271729,49.9671663488707,5.40493748592782,7.2880425453186,65,1,0,0,1,0.279617309570313,31.2805480957031,6,1,1,299.007049560547,0,299.007049560547,,,,,,,,,,,,,,,,,,,,,,,,,,,,,,,,,
,3866288468.436,266.921905517578,26.424976348877,6.75096471801742E-6,6.4376283575393E-9,1,5,12.9061126708984,5.00069000499116,41.2000007927418,0.00881728949304973,0.00129000620371866,1,-4.01018297578361E-9,,,,,,,,,,,,,,,,,,,,,266.921905517578,266.921905517578,26.424976348877,26.424976348877,49.9859254333322,5.40269591114186,7.6853723526001,65,1,0,0,1,0.2801513671875,31.7693061828613,2,1,1,266.921905517578,0,266.921905517578,,,,,,,,,,,,,,,,,,,,,,,,,,,,,,,,,
,3866288683.86027,230.98844909668,26.424976348877,6.87229319911309E-6,6.65896880301114E-9,1,5,12.9061126708984,4.99905408697306,41.0399995744228,0.00897232270477995,0.00130795130009978,1,-7.63469606957393E-9,,,,,,,,,,,,,,,,,,,,,230.98844909668,230.98844909668,26.424976348877,26.424976348877,49.9327746940245,5.40794478625525,7.53279685974121,63,1,64,0,0,0.282211303710938,31.2805480957031,2,1,1,230.98844909668,0,230.98844909668,,,,,,,,,,,,,,,,,,,,,,,,,,,,,,,,,
,3866288901.30013,194.752319335938,26.424976348877,6.90379064407892E-6,6.56843159412475E-9,1,5,12.9061126708984,4.99692978519327,40.9299992024899,0.00900802577504795,0.00131352439506044,1,-7.39319361287039E-9,,,,,,,,,,,,,,,,,,,,,194.752319335938,194.752319335938,26.424976348877,26.424976348877,49.8671178984091,5.41628329643421,7.42620754241943,65,1,0,0,1,0.279922485351562,31.7693061828613,2,1,1,194.752319335938,0,194.752319335938,,,,,,,,,,,,,,,,,,,,,,,,,,,,,,,,,
,3866289116.64714,158.997451782227,26.424976348877,6.75113702318471E-6,6.36463475283372E-9,1,5,12.9061126708984,4.99088586762468,40.8000014722347,0.00879343293490723,0.00128552985693454,1,-4.75145746690695E-9,,,,,,,,,,,,,,,,,,,,,158.997451782227,158.997451782227,26.424976348877,26.424976348877,49.7862193466687,5.43484319694052,7.325439453125,65,1,0,0,1,0.281982421875,31.7693061828613,2,1,1,158.997451782227,0,158.997451782227,,,,,,,,,,,,,,,,,,,,,,,,,,,,,,,,,
,3866289332.94593,122.975318908691,26.424976348877,6.50679183941296E-6,5.89460550934654E-9,1,5,12.9061126708984,4.99341090721132,40.6900011003017,0.00848240941400466,0.00123155423738523,1,-1.09691111693523E-8,,,,,,,,,,,,,,,,,,,,,122.975318908691,122.975318908691,26.424976348877,26.424976348877,49.8874402399091,5.42678369841717,7.22792291641235,63,1,64,0,0,0.275192260742187,31.2805480957031,2,1,1,122.975318908691,0,122.975318908691,,,,,,,,,,,,,,,,,,,,,,,,,,,,,,,,,
,3866289548.13507,86.9835739135742,26.424976348877,5.98383671885032E-6,5.8858018491738E-9,1,5,12.9061126708984,4.9948815682932,40.5899994075298,0.00780322305930898,0.00113761063108908,1,-6.58290441721745E-9,,,,,,,,,,,,,,,,,,,,,86.9835739135742,86.9835739135742,26.424976348877,26.424976348877,49.9667755346111,5.42043980482516,7.09382915496826,64,1,64,0,0,0.268173217773438,31.7693061828613,2,1,1,86.9835739135742,0,86.9835739135742,,,,,,,,,,,,,,,,,,,,,,,,,,,,,,,,,
,3866289759.64108,50.8538780212402,26.424976348877,5.48512287211199E-6,5.94084986401128E-9,1,5,12.9061126708984,4.99697211686059,40.5099987983704,0.00715714650489219,0.00104290312559216,1,-6.42281516427288E-9,,,,,,,,,,,,,,,,,,,,,50.8538780212402,50.8538780212402,26.424976348877,26.424976348877,50.1719530209092,5.41561015998332,6.8562707901001,65,1,0,0,1,0.267791748046875,31.7693061828613,2,1,1,50.8538780212402,0,50.8538780212402,,,,,,,,,,,,,,,,,,,,,,,,,,,,,,,,,
,3866289972.15287,14.8855390548706,26.424976348877,2.52524357185472E-6,9.52766169701304E-9,1,5,12.9061126708984,4.99558036528685,40.4499992728233,0.00329259632556366,0.000487623318678614,1,2.93104443901022E-9,,,,,,,,,,,,,,,,,,,,,14.8855390548706,14.8855390548706,26.424976348877,26.424976348877,50.0902728406495,5.4217672011597,5.89968490600586,65,1,0,0,1,0.266265869140625,31.7693061828613,2,1,1,14.8855390548706,0,14.8855390548706,,,,,,,,,,,,,,,,,,,,,,,,,,,,,,,,,
,3866291318.69746,23.0376853942871,26.424976348877,3.85245065826619E-6,6.60314645612137E-9,1,5,12.9061126708984,4.99606368182343,40.4299981892109,0.00502559397906268,0.000731705731407231,1,-4.96018877564316E-9,,,,,,,,,,,,,,,,,,,,,23.0376853942871,23.0376853942871,26.424976348877,26.424976348877,50.0777667843418,5.41974428344333,5.68557167053223,65,1,0,0,1,0.272064208984375,31.7693061828613,2,1,1,23.0376853942871,0,23.0376853942871,,,,,,,,,,,,,,,,,,,,,,,,,,,,,,,,,
,3866291548.6075,59.1255397796631,26.424976348877,5.65078844355611E-6,6.52668161406393E-9,1,5,12.9061126708984,4.99591427554323,40.4700003564358,0.00737246907969155,0.00106492736695329,1,-1.36367058266741E-8,,,,,,,,,,,,,,,,,,,,,59.1074523925781,59.143627166748,26.424976348877,26.424976348877,50.1485041653322,5.42003799949055,6.44935083389282,65,1,0,0,1,0.267791748046875,32.2580642700195,2,1,1,59.143627166748,0,59.1255397796631,,,,,,,,,,,,,,,,,,,,,,,,,,,,,,,,,
,3866291771.72471,95.0731582641602,26.424976348877,5.96444355028165E-6,5.85013414992368E-9,1,5,12.9061126708984,4.99169095758084,40.5200012028217,0.00777121998841881,0.00113118171349651,1,-7.8867722221796E-9,,,,,,,,,,,,,,,,,,,,,95.0731582641602,95.0731582641602,26.424976348877,26.424976348877,50.1348256662457,5.43361831106865,6.71742916107178,65,1,0,0,1,0.277023315429687,31.7693061828613,2,1,1,95.0731582641602,0,95.0731582641602,,,,,,,,,,,,,,,,,,,,,,,,,,,,,,,,,
,3866291989.78006,131.063690185547,26.424976348877,5.91611567086505E-6,6.08510272662633E-9,1,5,12.9061126708984,4.99286923666563,40.6100004911423,0.00771025417280945,0.00112613583262745,1,-4.94652306955333E-9,,,,,,,,,,,,,,,,,,,,,131.063690185547,131.063690185547,26.424976348877,26.424976348877,50.1766427920245,5.43135994410532,6.84488534927368,65,1,0,0,1,0.277328491210938,32.2580642700195,2,1,1,131.063690185547,0,131.063690185547,,,,,,,,,,,,,,,,,,,,,,,,,,,,,,,,,
,3866292207.21566,167.078323364258,26.424976348877,5.74678100515222E-6,6.33771512086577E-9,1,5,12.9061126708984,4.99266317047491,40.7299995422363,0.00748711916730658,0.00110754760261802,1,5.71520567874094E-9,,,,,,,,,,,,,,,,,,,,,167.078323364258,167.078323364258,26.424976348877,26.424976348877,49.5818234888899,5.42949736108367,6.91856288909912,63,1,64,0,0,0.275115966796875,32.2580642700195,2,1,1,167.078323364258,0,167.078323364258,,,,,,,,,,,,,,,,,,,,,,,,,,,,,,,,,
,3866292424.37539,203.046432495117,26.424976348877,5.64625909227081E-6,6.8006574770294E-9,1,5,12.9061126708984,4.99764356408185,40.8600009977818,0.00736642247247197,0.00108985144552085,1,5.73386081100916E-9,,,,,,,,,,,,,,,,,,,,,203.046432495117,203.046432495117,26.424976348877,26.424976348877,50.0640882852553,5.41438445692301,7.01929092407227,64,1,64,0,0,0.267105102539062,31.7693061828613,2,1,1,203.046432495117,0,203.046432495117,,,,,,,,,,,,,,,,,,,,,,,,,,,,,,,,,
,3866292640.97359,239.024703979492,26.424976348877,5.5064987987996E-6,6.27834260747578E-9,1,5,12.9061126708984,4.99732770891849,41.0300008952618,0.00718414591269495,0.00105802449252499,1,1.94672415337763E-9,,,,,,,,,,,,,,,,,,,,,239.024703979492,239.024703979492,26.424976348877,26.424976348877,50.0433751294957,5.41586513867743,7.18101119995117,64,1,64,0,0,0.269927978515625,31.7693061828613,2,1,1,239.024703979492,0,239.024703979492,,,,,,,,,,,,,,,,,,,,,,,,,,,,,,,,,
,3866292858.60553,275.128540039062,26.424976348877,5.31966508930523E-6,6.70115220984162E-9,1,5,12.9061126708984,4.999024918014,41.2300005555153,0.00694398358511637,0.00102063490595311,1,3.65696872709093E-10,,,,,,,,,,,,,,,,,,,,,275.128540039062,275.128540039062,26.424976348877,26.424976348877,50.0269609305918,5.41003780325762,7.35288429260254,64,1,64,0,0,0.275039672851562,31.2805480957031,2,1,1,275.128540039062,0,275.128540039062,,,,,,,,,,,,,,,,,,,,,,,,,,,,,,,,,
,3866293225.17955,300.005844116211,46497.45703125,0.0216005168954024,5.03175484827074E-6,1,2,12.9061126708984,5.00082555948127,41.3700006902218,28.2120231509131,4.13461020106457,100,-7.52882957178168E-6,,,,,,,,,,,,,,,,,,,,,300.005737304687,300.005950927734,46407.671875,46587.2421875,49.890566753986,5.40426322757428,7.30043458938599,25,1,68,0,0,0.279388427734375,31.7693061828613,1,6,1,300.005950927734,0,300.005844116211,,,,,,,,,,,,,,,,,,,,,,,,,,,,,,,,,
,3866293305.87022,300.004180908203,38440.8046875,0.0178793904320282,7.3519061317893E-6,1,2,12.9061126708984,5.00095743989793,41.3700006902218,23.3501455658789,3.44048871041296,100,7.56724117239794E-6,,,,,,,,,,,,,,,,,,,,,300.003997802734,300.004364013672,38360.90234375,38520.70703125,50.0683872421111,5.40387712281423,7.34951114654541,26,1,0,0,1,0.279617309570313,31.7693061828613,1,6,1,300.003997802734,0,300.004180908203,,,,,,,,,,,,,,,,,,,,,,,,,,,,,,,,,
,3866293382.5543,300.003189086914,30782.7568359375,0.0143407471190686,5.6892305334515E-6,1,2,12.9061126708984,5.00102141662106,41.3700006902218,18.7286068103033,2.76282555614731,100,8.53504998678E-6,,,,,,,,,,,,,,,,,,,,,300.0029296875,300.003448486328,30712.701171875,30852.8125,50.0570536285822,5.40350426374671,7.4458498954773,26,1,0,0,1,0.279541015625,32.2580642700195,1,6,1,300.003448486328,0,300.003189086914,,,,,,,,,,,,,,,,,,,,,,,,,,,,,,,,,
,3866293460.8829,300.003768920898,22966.306640625,0.0107042514253083,4.92701134237011E-6,1,2,12.9061126708984,5.00102891141001,41.3700006902218,13.9791759124605,2.06428437400104,100,7.93712960568065E-6,,,,,,,,,,,,,,,,,,,,,300.003753662109,300.003784179687,22876.62109375,23055.9921875,50.0914452834284,5.40383190280872,7.59321594238281,25,1,68,0,0,0.279464721679687,31.7693061828613,1,6,1,300.003784179687,0,300.003768920898,,,,,,,,,,,,,,,,,,,,,,,,,,,,,,,,,
,3866293539.49396,300.002044677734,15118.9653320313,0.00706820863743134,5.26169740121194E-6,1,2,12.9061126708984,5.00107358628195,41.3700006902218,9.23164215221742,1.35747277578227,100,9.31907909793678E-7,,,,,,,,,,,,,,,,,,,,,300.001983642578,300.002105712891,15018.9755859375,15218.955078125,49.9839713620341,5.40407980424568,7.78094911575317,26,1,0,0,1,0.2813720703125,32.2580642700195,1,6,1,300.001983642578,0,300.002044677734,,,,,,,,,,,,,,,,,,,,,,,,,,,,,,,,,
,3866293620.03793,300.000961303711,7071.98388671875,0.00332790123840993,5.05958115790483E-6,1,2,12.9061126708984,5.00130533417739,41.3799993693829,4.3481992218863,0.629553005642868,100,-6.92836809491305E-6,,,,,,,,,,,,,,,,,,,,,300.000793457031,300.001129150391,6977.095703125,7166.8720703125,49.8229558870726,5.40291092889741,7.97824382781982,26,1,0,0,1,0.278472900390625,31.7693061828613,1,6,1,300.001129150391,0,300.000961303711,,,,,,,,,,,,,,,,,,,,,,,,,,,,,,,,,
,3866293698.65165,300.001327514648,-788.505950927734,-0.000396827676183459,2.28327931879657E-5,1,2,12.9061126708984,5.00103336646414,41.3700006902218,-0.517827998042142,-0.079305895120753,100,-2.42175030801994E-6,,,,,,,,,,,,,,,,,,,,,300.001159667969,300.001495361328,-878.467468261719,-698.54443359375,50.0347772157841,5.40425543570891,7.94979238510132,25,1,68,0,0,0.278091430664062,31.7693061828613,1,6,1,300.001495361328,0,300.001327514648,,,,,,,,,,,,,,,,,,,,,,,,,,,,,,,,,
,3866293781.2006,300.001068115234,-9041.12744140625,-0.00424463807174036,5.22930822033057E-6,1,2,12.9061126708984,5.00104934480317,41.3700006902218,-5.54252263767843,-0.823865515323648,10,-7.20103839510108E-6,,,,,,,,,,,,,,,,,,,,,300.000946044922,300.001190185547,-9136.0966796875,-8946.158203125,49.8870494256495,5.40410230469695,7.88388919830322,26,1,0,0,1,0.2789306640625,30.7917900085449,1,6,1,300.001190185547,0,300.001068115234,,,,,,,,,,,,,,,,,,,,,,,,,,,,,,,,,
,3866293880.13238,300.000900268555,-18931.96484375,-0.00882289941502144,5.30463419498448E-6,1,2,12.9061126708984,5.00099105204095,41.3700006902218,-11.5226461012922,-1.69779939824268,100,-3.74475601097083E-6,,,,,,,,,,,,,,,,,,,,,300.000885009766,300.000915527344,-19047.103515625,-18816.826171875,49.9452807503322,5.40429341010119,7.82914257049561,26,1,0,0,1,0.278396606445313,31.7693061828613,1,6,1,300.000885009766,0,300.000900268555,,,,,,,,,,,,,,,,,,,,,,,,,,,,,,,,,
,3866293962.51895,300.001190185547,-27175.1845703125,-0.0126457012401201,5.41504370524306E-6,1,2,12.9061126708984,5.00121186003304,41.3700006902218,-16.5153668652587,-2.43938388134491,100,-9.81425737923228E-6,,,,,,,,,,,,,,,,,,,,,300.000946044922,300.001434326172,-27270.51171875,-27079.857421875,49.817484487438,5.40330783465504,7.78988695144653,26,1,0,0,1,0.279006958007813,31.7693061828613,1,6,1,300.000946044922,0,300.001190185547,,,,,,,,,,,,,,,,,,,,,,,,,,,,,,,,,
,3866294039.11808,300.000732421875,-34848.8359375,-0.0161995610478919,5.33366694943516E-6,1,2,12.9061126708984,5.00114941961469,41.3700006902218,-21.1557823050686,-3.12881351817061,100,-1.55864870984102E-5,,,,,,,,,,,,,,,,,,,,,300.000274658203,300.001190185547,-34944.09375,-34753.578125,50.0629158424764,5.40369273019639,7.77676630020142,26,1,0,0,1,0.279541015625,31.7693061828613,1,6,1,300.001647949219,0,300.000732421875,,,,,,,,,,,,,,,,,,,,,,,,,,,,,,,,,
,3866294129.76281,299.99983215332,-43930.515625,-0.0204010408464652,5.69579630486932E-6,1,2,12.9061126708984,5.0011522924675,41.3700006902218,-26.6426410980373,-3.94081736081418,100,-2.00263227696098E-5,,,,,,,,,,,,,,,,,,,,,299.999603271484,300.000061035156,-44020.62109375,-43840.41015625,50.0762035273034,5.40270636597834,7.74934434890747,26,1,0,0,1,0.279769897460938,31.7693061828613,1,6,1,299.999603271484,0,299.99983215332,,,,,,,,,,,,,,,,,,,,,,,,,,,,,,,,,
,3866294228.47517,300.000839233398,-46777.513671875,-0.0217422837610642,5.59566073228278E-6,1,2,12.9061126708984,5.00119775504682,41.3700006902218,-28.4001164821842,-4.16235288506172,100,7.44582182780079E-6,,,,,,,,,,,,,,,,,,,,,300.000762939453,300.000915527344,-46877.1640625,-46677.86328125,49.9886611331495,5.40275964988671,7.72563743591309,25,1,68,0,0,0.278396606445313,31.2805480957031,1,6,1,300.000915527344,0,300.000839233398,,,,,,,,,,,,,,,,,,,,,,,,,,,,,,,,,
,3866294309.01439,300.001678466797,-38737.95703125,-0.0180097349195983,5.78103423727425E-6,1,2,12.9061126708984,5.00110411215475,41.3700006902218,-23.5221922425178,-3.45990512035122,100,-3.1757840924687E-6,,,,,,,,,,,,,,,,,,,,,300.00146484375,300.001892089844,-38832.73828125,-38643.17578125,50.101997268438,5.40354222891429,7.71282196044922,26,1,0,0,1,0.279388427734375,32.2580642700195,1,6,1,300.00146484375,0,300.001678466797,,,,,,,,,,,,,,,,,,,,,,,,,,,,,,,,,
,3866294389.73735,299.999069213867,-30678.0595703125,-0.0142806872417811,5.71328336695162E-6,1,2,12.9061126708984,5.00114835230328,41.3700006902218,-18.6517981241771,-2.74478452579412,100,-3.47075720666724E-6,,,,,,,,,,,,,,,,,,,,,299.998931884766,299.999206542969,-30787.9140625,-30568.205078125,50.0672147993322,5.40367948273055,7.71050024032593,26,1,0,0,1,0.280609130859375,31.7693061828613,1,6,1,299.999206542969,0,299.999069213867,,,,,,,,,,,,,,,,,,,,,,,,,,,,,,,,,
,3866294469.47345,299.999618530273,-22717.7939453125,-0.0105565148187403,5.30507854203747E-6,1,2,12.9061126708984,5.00091141603481,41.3700006902218,-13.7877533267175,-2.02233745061388,100,2.42424983322524E-6,,,,,,,,,,,,,,,,,,,,,299.999389648438,299.999847412109,-22882.423828125,-22553.1640625,50.0046845177938,5.40462597962581,7.69536447525024,26,1,0,0,1,0.278854370117187,31.2805480957031,1,6,1,299.999847412109,0,299.999618530273,,,,,,,,,,,,,,,,,,,,,,,,,,,,,,,,,
,3866294546.72619,300.000793457031,-15006.3388671875,-0.00701417721384277,5.19957646710457E-6,1,2,12.9061126708984,5.00091384824499,41.3700006902218,-9.16102959902469,-1.34454061024766,100,9.85560480286324E-7,,,,,,,,,,,,,,,,,,,,,300.000640869141,300.000946044922,-15096.130859375,-14916.546875,49.9988223038995,5.40468850788643,7.68621587753296,26,1,0,0,1,0.279006958007813,32.2580642700195,1,6,1,300.000946044922,0,300.000793457031,,,,,,,,,,,,,,,,,,,,,,,,,,,,,,,,,
,3866294627.4256,300.000473022461,-6944.71655273437,-0.00327473064614376,5.0684618956807E-6,1,2,12.9061126708984,5.00099145377998,41.3700006902218,-4.2785037973003,-0.618400543071771,100,7.61358048421507E-6,,,,,,,,,,,,,,,,,,,,,300.000366210937,300.000579833984,-7024.78125,-6864.65185546875,50.0246160450341,5.40428405754915,7.68542718887329,25,1,68,0,0,0.276107788085938,32.2580642700195,1,6,1,300.000579833984,0,300.000473022461,,,,,,,,,,,,,,,,,,,,,,,,,,,,,,,,,
,3866294715.94626,300.000778198242,1903.93328857422,0.000928997721593642,5.20987539816045E-6,1,2,12.9061126708984,5.00143985274449,41.3700006902218,1.21173228450585,0.190258851281433,100,9.17402813295839E-6,,,,,,,,,,,,,,,,,,,,,300.000762939453,300.000793457031,1808.98266601562,1998.88391113281,49.9855346190726,5.40255427535112,7.67677354812622,26,1,0,0,1,0.279388427734375,32.2580642700195,1,6,1,300.000793457031,0,300.000778198242,,,,,,,,,,,,,,,,,,,,,,,,,,,,,,,,,
,3866294808.60915,300.00048828125,11169.0146484375,0.0052321606508292,4.84469302223562E-6,1,2,12.9061126708984,5.00116701054213,41.3700006902218,6.83295146103842,1.01063099234317,10,5.09288802597499E-6,,,,,,,,,,,,,,,,,,,,,300.000305175781,300.000671386719,11079.0341796875,11258.9951171875,49.9945233470437,5.40315477788697,7.67081069946289,26,1,0,0,1,0.278701782226562,31.7693061828613,1,6,1,300.000671386719,0,300.00048828125,,,,,,,,,,,,,,,,,,,,,,,,,,,,,,,,,
,3866294927.72587,299.999572753906,23081.0498046875,0.010746351813006,5.88843536506444E-6,1,2,12.9061126708984,5.0008918275456,41.3700006902218,14.0351648617642,2.06179477479,100,-9.34290960929553E-8,,,,,,,,,,,,,,,,,,,,,299.999298095703,299.999847412109,22961.05859375,23201.041015625,50.1453776512553,5.40492193423274,7.6587815284729,26,1,0,0,1,0.279693603515625,31.7693061828613,1,6,1,299.999298095703,0,299.999572753906,,,,,,,,,,,,,,,,,,,,,,,,,,,,,,,,,
,3866295008.09146,300.000717163086,31132.06640625,0.0144778393764316,6.54563442031974E-6,1,2,12.9061126708984,5.0010934022637,41.3700006902218,18.908479443793,2.78621033512994,100,6.2561721240948E-6,,,,,,,,,,,,,,,,,,,,,300.000579833984,300.000854492188,31041.873046875,31222.259765625,49.8643821985918,5.40427542095384,7.66174745559692,26,1,0,0,1,0.280227661132813,32.7468223571777,1,6,1,300.000854492188,0,300.000717163086,,,,,,,,,,,,,,,,,,,,,,,,,,,,,,,,,
,3866295088.76188,300.000259399414,39214.400390625,0.0182154873609841,6.32745842493349E-6,1,2,12.9061126708984,5.0010966641693,41.3700006902218,23.7894540771231,3.50907853212548,100,1.06026814428035E-5,,,,,,,,,,,,,,,,,,,,,300.000061035156,300.000457763672,39129.24609375,39299.5546875,49.9679479773899,5.40374235705913,7.65239143371582,26,1,0,0,1,0.27984619140625,31.7693061828613,1,6,1,300.000061035156,0,300.000259399414,,,,,,,,,,,,,,,,,,,,,,,,,,,,,,,,,
,3866295175.56183,300.000106811523,47912.4140625,0.0222320317212889,8.03647698053418E-6,1,2,12.9061126708984,5.00082770363528,41.3700006902218,29.0315488382061,4.29157718775104,100,1.98805768110647E-5,,,,,,,,,,,,,,,,,,,,,299.999938964844,300.000274658203,47847.3046875,47977.5234375,50.0945717975053,5.40458090162209,7.65052890777588,24,1,68,0,0,0.279388427734375,32.2580642700195,1,6,1,299.999938964844,0,300.000106811523,,,,,,,,,,,,,,,,,,,,,,,,,,,,,,,,,
,3866295199.51189,299.999221801758,50000.458984375,0.023216016510312,7.11112905207142E-6,1,2,12.9061126708984,5.00094801064154,41.3700006902218,30.3171066989826,4.4843503468829,100,2.28108705267174E-5,,,,,,,,,,,,,,,,,,,,,299.998962402344,299.999481201172,50000.453125,50000.46484375,49.8366343861591,5.40424334405709,7.64263963699341,26,1,0,0,1,0.27984619140625,31.7693061828613,1,4,1,299.998962402344,0,299.999221801758,,,,,,,,,,,,,,,,,,,,,,,,,,,,,,,,,