File: LT data/Bridport/CREECH-1/321_CR_FULL_SEQUENCE.dat
[Header]
; MPMS3 Data File (default extension .dat)
; Copyright (c) 2007, Quantum Design, Inc. All rights reserved.
TITLE,
FILEOPENTIME,3872931113.02421,09/21/2022,4:23 pm
BYAPP,MPMS3 w/ AC,1.0,1.1
INFO,MPMS3 Measurement Release 1.1.16 Build 424, MultiVu Release 2.3.4.19,APPNAME
INFO,Linear Motor Servo Controller,MOTOR_MODULE_NAME
INFO,3101-100 N0,MOTOR_HW_VERSION
INFO,MMC1047,MOTOR_SERIAL_NUMBER
INFO,01.04.28,MOTOR_SOFTWARE_VERSION
INFO,Quantum Design Squid Module,SQUID_MODULE_NAME
INFO,3101-501 B0,SQUID_HW_VERSION
INFO,SQM278,SQUID_SERIAL_NUMBER
INFO,01.03.04,SQUID_SOFTWARE_VERSION
INFO,Quantum Design VSM Oven,OVEN_MODULE_NAME
INFO,3101-201 A3,OVEN_HW_VERSION
INFO,OVB323,OVEN_SERIAL_NUMBER
INFO,01.07.07,OVEN_SOFTWARE_VERSION
INFO,SQUID AC,AC_MODULE_NAME
INFO,3101-401 G0,AC_HW_VERSION
INFO,SAC258,AC_SERIAL_NUMBER
INFO,SQUID AC 00.95.07,AC_SOFTWARE_VERSION
INFO,TCI127,COIL_SERIAL_NUMBER
INFO,0,MOMENT_UNITS
INFO,sndst,SAMPLE_MATERIAL
INFO,,SAMPLE_COMMENT
INFO,,SAMPLE_MASS
INFO,,SAMPLE_VOLUME
INFO,,SAMPLE_MOLECULAR_WEIGHT
INFO,,SAMPLE_SIZE
INFO,,SAMPLE_SHAPE
INFO,Straw,SAMPLE_HOLDER
INFO,Standard,SAMPLE_HOLDER_DETAIL
INFO,62.2,SAMPLE_OFFSET
DATATYPE,COMMENT,1
DATATYPE,TIME,2
STARTUPAXIS,X,2
STARTUPAXIS,Y1,5
FIELDGROUP, VSM,2,3,4,5,6,8,9,10,11,14,15
FIELDGROUP, DC, 2,3,4,14,56,57,58,59,60,61,62,63,64,65,66,67,68,69
FIELDGROUP, AC, 2,3,4,11,16,17,18,19,20,21,22,23,24,25,26,27,28,29,30
STARTUPGROUP, All
[Data]
Comment,Time Stamp (sec),Temperature (K),Magnetic Field (Oe),Moment (emu),M. Std. Err. (emu),Transport Action,Averaging Time (sec),Frequency (Hz),Peak Amplitude (mm),Center Position (mm),Lockin Signal' (V),Lockin Signal (V),Range,M. Quad. Signal (emu),AC Moment (emu),AC M. Std Err. (emu),AC Phase (deg),AC Phase Std. Err. (deg),AC Susceptibility (emu/Oe),AC Suscept. Std Err. (emu/Oe),AC X' (emu/Oe),AC X' Std Err. (emu/Oe),AC X'' (emu/Oe),AC X'' Std Err. (emu/Oe),AC Drive (Oe),AC Frequency (Hz),AC Averaging Time (sec),AC Cycles,AC Range,AC Measure Type,AC Signal' (V),AC Signal'' (V),AC Trim Coil Ratio,AC Trim Coil Phase,Min. Temperature (K),Max. Temperature (K),Min. Field (Oe),Max. Field (Oe),Mass (grams),Motor Lag (deg),Pressure (Torr),Measure Count,Measurement Number,SQUID Status (code),Motor Status (code),Measure Status (code),Motor Current (amps),Motor Temp. (C),Temp. Status (code),Field Status (code),Chamber Status (code),Chamber Temp (K),Redirection State,Evercool Status,Average Temp (K),Rotation Angle (deg),Rotator state,DC Moment Fixed Ctr (emu),DC Moment Err Fixed Ctr (emu),DC Moment Free Ctr (emu),DC Moment Err Free Ctr (emu),DC Fixed Fit,DC Free Fit,DC Calculated Center (mm),DC Calculated Center Err (mm),DC Scan Length (mm),DC Scan Time (s),DC Number of Points,DC Squid Drift,DC Min V (V),DC Max V (V),DC Scans per Measure,Map 01,Map 02,Map 03,Map 04,Map 05,Map 06,Map 07,Map 08,Map 09,Map 10,Map 11,Map 12,Map 13,Map 14,Map 15,Map 16
"FC",3872931344.25798
,3872932207.38504,87.9916725158691,49999.51953125,0.0754201791886551,1.90362012099962E-5,1,2,13.1008939743042,4.97544239148621,40.3599999845028,87.0507417546093,12.7342396085848,1000,-1.97770252603736E-5,,,,,,,,,,,,,,,,,,,,,87.8443450927734,88.1389999389648,49999.51953125,49999.51953125,52.6282206425921,5.76096100729966,7.53819990158081,26,1,0,0,1,0.297012329101562,31.7693061828613,2,1,1,87.8443450927734,0,2084573184,87.9916725158691,,,,,,,,,,,,,,,,,,,,,,,,,,,,,,,,,
,3872932345.57967,64.9053649902344,49999.51953125,0.106873100645219,0.000147342082129565,1,2,13.1008939743042,4.99070334375944,40.3000004589558,123.860743679051,18.2872229230355,1000,0.000114057478636478,,,,,,,,,,,,,,,,,,,,,64.9053649902344,64.9053649902344,49999.51953125,49999.51953125,52.6360369277844,5.78131610924689,7.35847473144531,26,1,0,0,1,0.298995971679687,32.7468223571777,2,1,1,64.9053649902344,0,2084573184,64.9053649902344,,,,,,,,,,,,,,,,,,,,,,,,,,,,,,,,,
,3872932431.64558,50.2137641906738,49999.51953125,0.141621676273778,5.28232125319171E-5,1,2,13.1008939743042,4.98924553635806,40.2499996125698,164.100041929602,23.9874461824553,1000,-5.23201802834395E-5,,,,,,,,,,,,,,,,,,,,,50.049976348877,50.3775520324707,49999.51953125,49999.51953125,52.5996912016402,5.78470219907297,7.1894736289978,26,1,0,0,1,0.30029296875,31.7693061828613,2,1,1,50.049976348877,0,2084573184,50.2137641906738,,,,,,,,,,,,,,,,,,,,,,,,,,,,,,,,,
,3872932495.15116,39.4397754669189,49999.51953125,0.178231619077773,0.000169725137365494,1,2,13.1008939743042,4.9874906836772,40.2199998497963,206.401704394978,30.2913260962658,1000,3.59412002447311E-5,,,,,,,,,,,,,,,,,,,,,39.2898330688477,39.5897178649902,49999.51953125,49999.51953125,52.6063350440536,5.79010999890292,6.98932409286499,26,1,0,0,1,0.298080444335937,33.2355842590332,2,1,1,39.2898330688477,0,2084573184,39.4397754669189,,,,,,,,,,,,,,,,,,,,,,,,,,,,,,,,,
,3872932558.70333,28.6712503433228,49999.51953125,0.226514820092432,0.000378113459001182,1,2,13.1008939743042,4.98370753064391,40.2299985289574,261.987628325902,38.7956572915498,1000,0.000338967479306746,,,,,,,,,,,,,,,,,,,,,28.530855178833,28.8116455078125,49999.51953125,49999.51953125,52.6172778433229,5.80230350409186,6.67017984390259,26,1,0,0,1,0.296249389648438,34.2131004333496,2,1,1,28.530855178833,0,2084573184,28.6712503433228,,,,,,,,,,,,,,,,,,,,,,,,,,,,,,,,,
,3872932622.17406,18.1492195129395,49999.51953125,0.284284218848951,0.00375349441854412,1,2,13.1008939743042,4.98030014178221,40.2100011706352,329.213199319471,43.6993246227315,1000,-0.00385228214477489,,,,,,,,,,,,,,,,,,,,,18.0030708312988,18.2953681945801,49999.51953125,49999.51953125,52.738039449544,5.81660037021718,6.08317184448242,26,1,0,0,1,0.299224853515625,33.2355842590332,2,1,1,18.0030708312988,0,2084573184,18.1492195129395,,,,,,,,,,,,,,,,,,,,,,,,,,,,,,,,,
,3872932685.72589,8.80160522460937,49999.51953125,0.351803940904848,0.000102269930926936,1,2,13.1008939743042,4.977081328156,40.1900000870228,406.147575319081,60.0814542062709,1000,0.000474157814713614,,,,,,,,,,,,,,,,,,,,,8.70060539245606,8.9026050567627,49999.51953125,49999.51953125,53.1132211387749,5.83214737394158,4.82221508026123,26,1,0,0,1,0.297470092773438,33.7243423461914,6,1,1,8.70060539245606,0,2084573184,8.80160522460937,,,,,,,,,,,,,,,,,,,,,,,,,,,,,,,,,
,3872932749.18199,1.99983936548233,49999.51953125,0.3878478546306,4.19923993291003E-5,1,2,13.1008939743042,4.97476085753661,40.1900000870228,447.491356309417,66.0227161629537,1000,0.00037453238698292,,,,,,,,,,,,,,,,,,,,,1.99960911273956,2.0000696182251,49999.51953125,49999.51953125,53.6314408470249,5.84498598346063,2.5754566192627,26,1,0,0,1,0.30059814453125,32.2580642700195,5,1,1,1.99960911273956,0,2084573184,1.99983936548233,,,,,,,,,,,,,,,,,,,,,,,,,,,,,,,,,
,3872933311.49613,10.2498536109924,26.5019664764404,0.00160945290137394,6.81467228219261E-6,1,5,13.1008939743042,4.98393101570863,40.1900000870228,1.86182464064356,0.274237310827091,100,1.16869991746373E-6,,,,,,,,,,,,,,,,,,,,,10.0411806106567,10.4585266113281,26.5019664764404,26.5019664764404,52.743120034919,5.84849636707438,4.90696620941162,66,1,0,0,1,0.302581787109375,30.7917900085449,6,1,1,10.4585266113281,0,2084573184,10.2498536109924,,,,,,,,,,,,,,,,,,,,,,,,,,,,,,,,,
,3872933516.53336,42.0354385375977,26.5019664764404,0.000111677388945688,2.1645377651878E-7,1,5,13.1008939743042,4.9882881957817,40.1999987661839,0.129346017700119,0.0190616453289138,1,8.92355583482431E-8,,,,,,,,,,,,,,,,,,,,,42.0354385375977,42.0354385375977,26.5019664764404,26.5019664764404,52.5930473592267,5.83213941874071,6.47801160812378,66,1,0,0,1,0.30303955078125,33.2355842590332,2,1,1,42.0354385375977,0,2084573184,42.0354385375977,,,,,,,,,,,,,,,,,,,,,,,,,,,,,,,,,
,3872933718.67586,74.0131301879883,26.5019664764404,8.0061517820028E-5,1.97360036198134E-8,1,5,13.1008939743042,4.98727362017796,40.2400009334087,0.0927035144668102,0.0136492111341568,1,5.34487882080663E-8,,,,,,,,,,,,,,,,,,,,,74.0131301879883,74.0131301879883,26.5019664764404,26.5019664764404,52.6817621961594,5.83571228571119,6.8686146736145,66,1,0,0,1,0.304489135742188,32.7468223571777,2,1,1,74.0131301879883,0,2084574368,74.0131301879883,,,,,,,,,,,,,,,,,,,,,,,,,,,,,,,,,
,3872933914.60796,106.064712524414,26.5019664764404,6.13924110467397E-5,1.55108152635083E-8,1,5,13.1008939743042,4.98561650584921,40.3099991381168,0.0710571160011289,0.0104361035438452,1,1.89988937237171E-8,,,,,,,,,,,,,,,,,,,,,106.064712524414,106.064712524414,26.5019664764404,26.5019664764404,52.6278298283325,5.84178800371396,7.04961919784546,66,1,0,0,1,0.307846069335937,33.2355842590332,2,1,1,106.064712524414,0,2084574464,106.064712524414,,,,,,,,,,,,,,,,,,,,,,,,,,,,,,,,,
,3872934108.3242,138.010269165039,26.5019664764404,4.59775523145629E-5,1.22044877613217E-8,1,5,13.1008939743042,4.98421552967071,40.3899997472763,0.0531932976484617,0.00782160605935996,1,2.19681438567321E-8,,,,,,,,,,,,,,,,,,,,,138.010269165039,138.010269165039,26.5019664764404,26.5019664764404,52.6688653255921,5.84734309885902,7.15487194061279,64,1,64,0,0,0.303726196289063,33.2355842590332,2,1,1,138.010269165039,0,2084574176,138.010269165039,,,,,,,,,,,,,,,,,,,,,,,,,,,,,,,,,
,3872934301.1602,170.002731323242,26.5019664764404,3.5410541294204E-5,3.95221761964062E-8,1,5,13.1008939743042,4.99265452206894,40.5000001192093,0.0410638504391113,0.00604695826982126,1,2.44149267815718E-8,,,,,,,,,,,,,,,,,,,,,170.002731323242,170.002731323242,26.5019664764404,26.5019664764404,52.6305655281498,5.85275302340927,7.25561857223511,65,1,64,0,0,0.308761596679687,33.2355842590332,2,1,1,170.002731323242,0,2084574240,170.002731323242,,,,,,,,,,,,,,,,,,,,,,,,,,,,,,,,,
,3872934493.97459,202.02278137207,26.5019664764404,2.73275719138086E-5,9.6115874891355E-8,1,5,13.1008939743042,4.98807273350091,40.6199991703033,0.0316374245051795,0.00474438827959303,1,9.11341349244279E-8,,,,,,,,,,,,,,,,,,,,,202.02278137207,202.02278137207,26.5019664764404,26.5019664764404,53.0721856415152,5.86816882388612,7.35643243789673,66,1,0,0,1,0.315399169921875,34.2131004333496,2,1,1,202.02278137207,0,2084574144,202.02278137207,,,,,,,,,,,,,,,,,,,,,,,,,,,,,,,,,
,3872934687.4045,234.020904541016,26.5019664764404,2.10287356556632E-5,7.2180541032348E-9,1,5,13.1008939743042,4.98907575387808,40.7700017094612,0.0243622519751933,0.00358227813198631,1,1.00674044557373E-8,,,,,,,,,,,,,,,,,,,,,234.020904541016,234.020904541016,26.5019664764404,26.5019664764404,52.9783902192075,5.86299591538056,7.60021495819092,65,1,64,0,0,0.313568115234375,33.7243423461914,2,1,1,234.020904541016,0,2084574304,234.020904541016,,,,,,,,,,,,,,,,,,,,,,,,,,,,,,,,,
,3872934880.18246,266.088195800781,26.5019664764404,1.59831170325774E-5,7.67800514902314E-9,1,5,13.1008939743042,4.9911350656929,40.9400016069412,0.0185282228295024,0.00271939620787777,1,3.40133411432841E-9,,,,,,,,,,,,,,,,,,,,,266.088195800781,266.088195800781,26.5019664764404,26.5019664764404,52.9182048232268,5.85656732961198,8.08858489990234,64,1,64,0,0,0.309677124023438,33.2355842590332,2,1,1,266.088195800781,0,2084574240,266.088195800781,,,,,,,,,,,,,,,,,,,,,,,,,,,,,,,,,
,3872935074.44694,298.000152587891,26.5019664764404,1.22517828680602E-5,6.30707088655488E-9,1,5,13.1008939743042,4.99244522296396,41.1200001835823,0.014206454308596,0.0020954716692177,1,1.13723659327877E-8,,,,,,,,,,,,,,,,,,,,,298.000152587891,298.000152587891,26.5019664764404,26.5019664764404,52.814248230169,5.8531477760736,7.87290048599243,66,1,0,0,1,0.309371948242188,33.7243423461914,6,1,1,298.000152587891,0,2084574304,298.000152587891,,,,,,,,,,,,,,,,,,,,,,,,,,,,,,,,,
,3872936683.29385,2.00086867809296,42870.84375,0.361440145947493,5.57214253581498E-5,1,2,13.1008939743042,4.99523996205331,40.1900000870228,419.405385866041,62.0590827001429,1000,0.000500975361257145,,,,,,,,,,,,,,,,,,,,,2.00031089782715,2.00142645835876,42780.8984375,42960.7890625,53.2484428726018,5.84818130403595,2.59207987785339,26,1,0,0,1,0.30364990234375,32.7468223571777,1,6,1,2.00031089782715,0,2084573184,2.00086867809296,,,,,,,,,,,,,,,,,,,,,,,,,,,,,,,,,
,3872936746.76496,1.99906641244888,36535.373046875,0.333949662943708,6.1858988573631E-5,1,2,13.1008939743042,4.9956156448565,40.1900000870228,387.547131987339,57.3439537618365,1000,0.000461954342484038,,,,,,,,,,,,,,,,,,,,,1.99882435798645,1.99930846691132,36450.44140625,36620.3046875,53.3715493643806,5.84526951417603,2.58757162094116,26,1,0,0,1,0.300750732421875,30.7917900085449,1,6,1,1.99941527843475,0,2084573184,1.99906641244888,,,,,,,,,,,,,,,,,,,,,,,,,,,,,,,,,
,3872936810.25788,1.99979496002197,30194.2568359375,0.302785645742903,6.46564461390017E-5,1,2,13.1008939743042,4.99642334470686,40.1900000870228,351.469306378315,51.9474902248798,1000,0.000369815265930146,,,,,,,,,,,,,,,,,,,,,1.9997843503952,1.99980556964874,30109.337890625,30279.17578125,52.959631134746,5.84043863179158,2.58038306236267,26,1,0,0,1,0.299453735351562,32.7468223571777,1,6,1,1.99980556964874,0,2084573184,1.99979496002197,,,,,,,,,,,,,,,,,,,,,,,,,,,,,,,,,
,3872936873.75456,2.00014936923981,23857.8583984375,0.266961023799521,7.08276339735582E-5,1,2,13.1008939743042,4.9968029421675,40.1900000870228,309.933443740715,45.6976434195827,1000,0.000232651246767464,,,,,,,,,,,,,,,,,,,,,2.00012898445129,2.00016975402832,23767.92578125,23947.791015625,52.8169839299863,5.83909203034072,2.57685542106628,26,1,0,0,1,0.30120849609375,33.2355842590332,1,6,1,2.00016975402832,0,2084573184,2.00014936923981,,,,,,,,,,,,,,,,,,,,,,,,,,,,,,,,,
,3872936937.26683,1.9999315738678,17511.8427734375,0.224547659700474,8.18726235406581E-5,1,2,13.1008939743042,4.99754753348475,40.1900000870228,260.747944736456,38.4405596143997,1000,0.000191469399988341,,,,,,,,,,,,,,,,,,,,,1.9998904466629,1.99997270107269,17416.91015625,17606.775390625,52.829489986294,5.83535184789411,2.57495045661926,26,1,0,0,1,0.299835205078125,34.7018585205078,1,6,1,1.9998904466629,0,2084573184,1.9999315738678,,,,,,,,,,,,,,,,,,,,,,,,,,,,,,,,,
,3872937000.76538,2.00000619888306,11169.4975585938,0.172134358339043,0.00010411548499023,1,2,13.1008939743042,4.99807876714528,40.1900000870228,199.918803474679,29.4436553412452,1000,0.000122155922502793,,,,,,,,,,,,,,,,,,,,,1.99978542327881,2.0002269744873,11084.4599609375,11254.53515625,52.7149814082267,5.83316347691631,2.5585949420929,26,1,0,0,1,0.312576293945313,33.7243423461914,1,6,1,2.0002269744873,0,2084573184,2.00000619888306,,,,,,,,,,,,,,,,,,,,,,,,,,,,,,,,,
,3872937064.27054,2.00010144710541,4818.27783203125,0.101394791076745,0.00014384504723084,1,2,13.1008939743042,4.99708836607958,40.1900000870228,117.727554743162,17.344601470511,1000,7.69410797822356E-5,,,,,,,,,,,,,,,,,,,,,1.99992489814758,2.00027799606323,4728.27734375,4908.2783203125,52.6309563424094,5.83626842734528,2.5593159198761,26,1,0,0,1,0.30059814453125,32.7468223571777,1,6,1,2.00065803527832,0,2084573376,2.00010144710541,,,,,,,,,,,,,,,,,,,,,,,,,,,,,,,,,
,3872937127.78811,2.00023531913757,-1530.33410644531,-0.0195247029719836,0.000238508349752733,1,2,13.1008939743042,4.99653963838958,40.1900000870228,-22.658540353418,-3.39216060337158,1000,-6.02725678816926E-5,,,,,,,,,,,,,,,,,,,,,2.00006747245789,2.00040316581726,-1620.34069824219,-1440.32751464844,52.6383818133421,5.83853717398146,2.5586895942688,26,1,0,0,1,0.300827026367188,31.7693061828613,1,6,1,2.00048971176147,0,2084573184,2.00023531913757,,,,,,,,,,,,,,,,,,,,,,,,,,,,,,,,,
,3872937211.26959,1.99988931417465,-9875.64794921875,-0.152084358676716,0.000120080845093465,1,2,13.1008939743042,4.99713007276526,40.1900000870228,-176.538229231813,-26.3302721705946,100,-0.000386158936357985,,,,,,,,,,,,,,,,,,,,,1.99985158443451,1.99992704391479,-9950.6982421875,-9800.59765625,52.8795142115248,5.8372905383309,2.54941821098328,26,1,0,0,1,0.299148559570313,32.7468223571777,1,6,1,1.99992704391479,0,2084573184,1.99988931417465,,,,,,,,,,,,,,,,,,,,,,,,,,,,,,,,,
,3872937288.56257,2.00011038780212,-17608.060546875,-0.22302264769021,8.50975116931105E-5,1,2,13.1008939743042,4.99788151292074,40.1900000870228,-258.993326926209,-38.2374951426191,1000,-0.000237034408681878,,,,,,,,,,,,,,,,,,,,,2.00002098083496,2.00019979476929,-17693.203125,-17522.91796875,52.9498607782556,5.8355011161848,2.55254292488098,26,1,0,0,1,0.305023193359375,32.7468223571777,1,6,1,2.00019979476929,0,2084573856,2.00011038780212,,,,,,,,,,,,,,,,,,,,,,,,,,,,,,,,,
,3872937352.01598,2.00002521276474,-23954.701171875,-0.266497915577627,7.89177589545654E-5,1,2,13.1008939743042,4.99719097194976,40.1900000870228,-309.420803282871,-45.6821428235007,1000,-0.00028289508422106,,,,,,,,,,,,,,,,,,,,,1.99941003322601,2.00064039230347,-24044.849609375,-23864.552734375,52.9045263241402,5.83793840665468,2.55063080787659,26,1,0,0,1,0.310287475585937,33.2355842590332,1,6,1,1.99941003322601,0,2084574016,2.00002521276474,,,,,,,,,,,,,,,,,,,,,,,,,,,,,,,,,
,3872937415.54544,2.00040125846863,-30320.302734375,-0.302794560425512,6.71581724056004E-5,1,2,13.1008939743042,4.99808537357515,40.1900000870228,-351.641222134265,-51.987554243899,1000,-0.000382175345159532,,,,,,,,,,,,,,,,,,,,,2.0003490447998,2.00045347213745,-30405.6171875,-30234.98828125,52.9322741365729,5.8353027963869,2.54516053199768,26,1,0,0,1,0.313186645507812,33.2355842590332,1,6,1,2.00045347213745,0,2084574208,2.00040125846863,,,,,,,,,,,,,,,,,,,,,,,,,,,,,,,,,
,3872937479.02589,2.00005215406418,-36678.365234375,-0.334176624235856,6.72927993207858E-5,1,2,13.1008939743042,4.99727230177965,40.1900000870228,-387.985781879162,-57.4422391745891,1000,-0.000490402576728582,,,,,,,,,,,,,,,,,,,,,1.99975097179413,2.00035333633423,-36768.6875,-36588.04296875,53.1386240656499,5.83738349261191,2.54646635055542,26,1,0,0,1,0.299835205078125,33.2355842590332,1,6,1,1.99975097179413,0,2084573856,2.00005215406418,,,,,,,,,,,,,,,,,,,,,,,,,,,,,,,,,
,3872937542.54214,1.99977976083755,-43041.07421875,-0.361833095964962,4.72254991226885E-5,1,2,13.1008939743042,4.99764595571023,40.1900000870228,-420.140099590528,-62.1983764763937,1000,-0.000527290592530021,,,,,,,,,,,,,,,,,,,,,1.99973714351654,1.99982237815857,-43131.359375,-42950.7890625,53.2808804561499,5.83692905305017,2.54074716567993,26,1,0,0,1,0.309524536132812,34.2131004333496,1,6,1,1.99973714351654,0,2084573984,1.99977976083755,,,,,,,,,,,,,,,,,,,,,,,,,,,,,,,,,
,3872937606.06887,1.99997818470001,-49414.408203125,-0.386416665879676,5.19279992198603E-5,1,2,13.1008939743042,4.99775495175147,40.1900000870228,-448.686131019463,-66.513028787244,1000,-0.000637815722053646,,,,,,,,,,,,,,,,,,,,,1.99988460540771,2.00007176399231,-49504.69921875,-49324.1171875,53.4602642013134,5.83738035916662,2.54444932937622,26,1,0,0,1,0.310897827148438,33.2355842590332,1,6,1,1.99988460540771,0,2084573984,1.99997818470001,,,,,,,,,,,,,,,,,,,,,,,,,,,,,,,,,
,3872937671.54956,2.00008219480515,-44600.908203125,-0.368405093151942,6.09603083974796E-5,1,2,13.1008939743042,4.99827218399697,40.1900000870228,-427.851681109574,-63.3015019213671,1000,-0.000504417075838651,,,,,,,,,,,,,,,,,,,,,1.99981367588043,2.00035071372986,-44690.796875,-44511.01953125,53.3395025950922,5.83523504381265,2.53765964508057,26,1,0,0,1,0.304183959960937,33.2355842590332,1,6,1,2.00056028366089,0,2084573952,2.00008219480515,,,,,,,,,,,,,,,,,,,,,,,,,,,,,,,,,
,3872937735.0403,2.00001233816147,-38265.7265625,-0.34180534309426,6.84437040597553E-5,1,2,13.1008939743042,4.99920349502681,40.1900000870228,-397.065712299891,-58.7295689390193,1000,-0.000453602040189186,,,,,,,,,,,,,,,,,,,,,1.99984967708588,2.00017499923706,-38360.609375,-38170.84375,53.2586040433518,5.83136246167249,2.54058337211609,24,1,68,0,0,0.31005859375,33.7243423461914,1,6,1,1.99984967708588,0,2084574048,2.00001233816147,,,,,,,,,,,,,,,,,,,,,,,,,,,,,,,,,
,3872937798.59893,1.99987095594406,-31921.0830078125,-0.311653166451572,6.2721984615979E-5,1,2,13.1008939743042,4.99733545136624,40.1900000870228,-361.84842361039,-53.5277210809998,1000,-0.000419575329866923,,,,,,,,,,,,,,,,,,,,,1.9993554353714,2.00038647651672,-32011.02734375,-31831.138671875,53.081565183746,5.83736992252233,2.53862285614014,26,1,0,0,1,0.29937744140625,33.2355842590332,1,6,1,2.00038647651672,0,2084574016,1.99987095594406,,,,,,,,,,,,,,,,,,,,,,,,,,,,,,,,,
,3872937862.04233,2.00002068281174,-25586.2841796875,-0.277235635704547,6.83328832363389E-5,1,2,13.1008939743042,4.99828375856607,40.1900000870228,-321.988700944794,-47.5222953346557,1000,-0.000281365828276559,,,,,,,,,,,,,,,,,,,,,1.99985039234161,2.00019097328186,-25671.234375,-25501.333984375,53.0526449285345,5.8328231410172,2.53203463554382,26,1,0,0,1,0.299530029296875,32.7468223571777,1,6,1,1.99985039234161,0,2084574080,2.00002068281174,,,,,,,,,,,,,,,,,,,,,,,,,,,,,,,,,
,3872937925.54395,2.00001358985901,-19246.169921875,-0.236911849004234,7.65710667205743E-5,1,2,13.1008939743042,4.99826055545325,40.1900000870228,-275.15019558224,-40.6346351789163,1000,-0.000261703653534028,,,,,,,,,,,,,,,,,,,,,1.9997341632843,2.00029301643372,-19341.046875,-19151.29296875,52.8795142115248,5.83307009234538,2.53469777107239,26,1,0,0,1,0.31280517578125,33.2355842590332,1,6,1,1.9997341632843,0,2084573824,2.00001358985901,,,,,,,,,,,,,,,,,,,,,,,,,,,,,,,,,
,3872937989.06343,1.99979400634766,-12905.537109375,-0.187780065103831,9.34198813903217E-5,1,2,13.1008939743042,4.99899892118364,40.1900000870228,-218.133937499064,-32.2111348120613,1000,-0.000204696407311215,,,,,,,,,,,,,,,,,,,,,1.99977624416351,1.9998117685318,-12990.48828125,-12820.5859375,52.7356945639863,5.82879054392537,2.53554916381836,26,1,0,0,1,0.310592651367188,32.2580642700195,1,6,1,1.99977624416351,0,2084574016,1.99979400634766,,,,,,,,,,,,,,,,,,,,,,,,,,,,,,,,,
,3872938052.53675,1.99975794553757,-6564.23681640625,-0.123363606016744,0.000130388591375832,1,2,13.1008939743042,4.99969465049173,40.1900000870228,-143.33360783983,-21.1595280656836,1000,-0.000129352812163631,,,,,,,,,,,,,,,,,,,,,1.99949729442596,2.00001859664917,-6654.21875,-6474.2548828125,52.7732127329094,5.82709571379348,2.52649068832397,25,1,68,0,0,0.309295654296875,33.7243423461914,1,6,1,1.99949729442596,0,2084573920,1.99975794553757,,,,,,,,,,,,,,,,,,,,,,,,,,,,,,,,,
,3872938116.08119,1.99999308586121,-207.559600830078,-0.0224061972842982,0.000247010613214931,1,2,13.1008939743042,4.99910021222522,40.1900000870228,-26.0374648407301,-3.78449716230333,1000,2.64353397716664E-5,,,,,,,,,,,,,,,,,,,,,1.99985933303833,2.00012683868408,-297.553802490234,-117.565399169922,52.5426323197363,5.82751633119529,2.52779531478882,26,1,0,0,1,0.30364990234375,31.7693061828613,1,6,1,1.99985933303833,0,2084573760,1.99999308586121,,,,,,,,,,,,,,,,,,,,,,,,,,,,,,,,,
,3872938179.5497,2.00010448694229,6137.2080078125,0.105195485641495,0.000855607931790971,1,2,13.1008939743042,4.99935861473941,40.1900000870228,122.193618923875,18.1735163643604,1000,0.000223828471497738,,,,,,,,,,,,,,,,,,,,,1.9999293088913,2.00027966499329,6042.20166015625,6232.21435546875,52.5817137456979,5.82714541523279,2.52373099327087,26,1,0,0,1,0.310745239257812,33.2355842590332,1,6,1,2.00027966499329,0,2084573280,2.00010448694229,,,,,,,,,,,,,,,,,,,,,,,,,,,,,,,,,
,3872938243.08059,1.99990808963776,12494.2934570312,0.179543128669782,0.000107733505567422,1,2,13.1008939743042,4.99956845982342,40.1900000870228,208.592900263196,30.8432893584913,1000,0.000230294578449466,,,,,,,,,,,,,,,,,,,,,1.99956035614014,2.00025582313538,12404.21875,12584.3681640625,52.7063834945152,5.82713481382926,2.52070999145508,26,1,0,0,1,0.308990478515625,33.7243423461914,1,6,1,2.00025582313538,0,2084573952,1.99990808963776,,,,,,,,,,,,,,,,,,,,,,,,,,,,,,,,,
,3872938306.59561,2.00016057491302,18847.2880859375,0.232375373390031,8.14219503174253E-5,1,2,13.1008939743042,4.99940313403524,40.1900000870228,269.964102547189,39.8949619467626,1000,0.000278777616378624,,,,,,,,,,,,,,,,,,,,,2.00001430511475,2.0003068447113,18757.2265625,18937.349609375,52.6512786839094,5.82762343820165,2.5235607624054,26,1,0,0,1,0.3106689453125,34.2131004333496,1,6,1,2.00001430511475,0,2084573984,2.00016057491302,,,,,,,,,,,,,,,,,,,,,,,,,,,,,,,,,
,3872938370.08156,1.99998134374619,25199.458984375,0.274173345529189,7.5674788141192E-5,1,2,13.1008939743042,4.99909573523271,40.1900000870228,318.499096183363,47.0447780730995,1000,0.000309861553467042,,,,,,,,,,,,,,,,,,,,,1.99992763996124,2.00003504753113,25109.341796875,25289.576171875,52.9248486656402,5.82825152143246,2.51719975471497,26,1,0,0,1,0.301055908203125,33.7243423461914,1,6,1,2.00003504753113,0,2084573952,1.99998134374619,,,,,,,,,,,,,,,,,,,,,,,,,,,,,,,,,
,3872938433.60323,1.99997824430466,31563.0712890625,0.309448005429236,6.63716810581818E-5,1,2,13.1008939743042,4.99953731096505,40.1900000870228,359.506869900027,53.2009086759852,1000,0.000433090983012326,,,,,,,,,,,,,,,,,,,,,1.99982345104218,2.00013303756714,31472.841796875,31653.30078125,53.0069196601595,5.82928812940926,2.52094101905823,26,1,0,0,1,0.309371948242188,33.2355842590332,1,6,1,1.99982345104218,0,2084573952,1.99997824430466,,,,,,,,,,,,,,,,,,,,,,,,,,,,,,,,,
,3872938497.13405,1.99996185302734,37932.375,0.339994914283281,6.56551201597104E-5,1,2,13.1008939743042,4.99915097351407,40.1900000870228,394.970949546142,58.3209587722905,1000,0.000367989271204397,,,,,,,,,,,,,,,,,,,,,1.99974417686462,2.00017952919006,37847.578125,38017.171875,53.2371092590729,5.83063218768156,2.52219533920288,26,1,0,0,1,0.309982299804687,32.7468223571777,1,6,1,2.00017952919006,0,2084573984,1.99996185302734,,,,,,,,,,,,,,,,,,,,,,,,,,,,,,,,,
,3872938560.61994,1.9998704791069,44297.25390625,0.36691120430884,5.68678347819939E-5,1,2,13.1008939743042,4.99853018015094,40.1900000870228,426.148751770475,63.0409597851697,1000,0.000495133801457268,,,,,,,,,,,,,,,,,,,,,1.99984884262085,1.99989211559296,44212.4140625,44382.09375,53.5353005391595,5.83395827891095,2.52417683601379,26,1,0,0,1,0.303115844726562,33.2355842590332,1,6,1,1.99989211559296,0,2084573984,1.9998704791069,,,,,,,,,,,,,,,,,,,,,,,,,,,,,,,,,
,3872938933.09777,2.38563883304596,26.1805820465088,0.0135142926600285,3.61832770097941E-5,1,5,13.1008939743042,4.97963810504139,40.1900000870228,15.6153410639076,2.29442398824587,1000,5.03866600352495E-6,,,,,,,,,,,,,,,,,,,,,2.09614872932434,2.67512893676758,26.1805820465088,26.1805820465088,52.5312987062075,5.82421555025545,2.84844017028809,66,1,0,0,1,0.295181274414063,32.2580642700195,6,1,1,2.67512893676758,0,2084574336,2.38563883304596,,,,,,,,,,,,,,,,,,,,,,,,,,,,,,,,,
,3872939143.48695,34.0130081176758,26.1805820465088,0.000117534296416905,9.68326027471488E-8,1,5,13.1008939743042,5.00064125280806,40.1999987661839,0.136595781751798,0.0201722029664295,1,1.29423140393468E-7,,,,,,,,,,,,,,,,,,,,,34.0130081176758,34.0130081176758,26.1805820465088,26.1805820465088,52.5680352466113,5.82267660658847,6.24837493896484,66,1,0,0,1,0.309600830078125,32.7468223571777,2,1,1,34.0130081176758,0,2084574240,34.0130081176758,,,,,,,,,,,,,,,,,,,,,,,,,,,,,,,,,
,3872939346.1908,66.0072631835938,26.1805820465088,7.92165446608758E-5,2.12221795531485E-8,1,5,13.1008939743042,4.99838220561267,40.2299985289574,0.0920163803009717,0.0135131979620863,1,2.35234210701896E-8,,,,,,,,,,,,,,,,,,,,,66.0072631835938,66.0072631835938,26.1805820465088,26.1805820465088,52.5625638469767,5.83112273843767,6.73516893386841,64,1,64,0,0,0.308380126953125,32.7468223571777,2,1,1,66.0072631835938,0,2084574272,66.0072631835938,,,,,,,,,,,,,,,,,,,,,,,,,,,,,,,,,
,3872939544.53175,98.0695266723633,26.1805820465088,6.1361747645307E-5,4.84904138625764E-8,1,5,13.1008939743042,4.99773176058512,40.2900017797947,0.0712603396943762,0.010487886522623,1,3.74783981609416E-8,,,,,,,,,,,,,,,,,,,,,98.0695266723633,98.0695266723633,26.1805820465088,26.1805820465088,52.6743367252267,5.83219749844223,6.9491024017334,65,1,64,0,0,0.299148559570313,33.7243423461914,2,1,1,98.0695266723633,0,2084574272,98.0695266723633,,,,,,,,,,,,,,,,,,,,,,,,,,,,,,,,,
,3872939738.58325,130.052780151367,26.1805820465088,4.59063998469831E-5,1.15635366596007E-8,1,5,13.1008939743042,4.99609388327156,40.3699986636639,0.0532914005156848,0.00781504490932799,1,4.23766176505827E-9,,,,,,,,,,,,,,,,,,,,,130.052780151367,130.052780151367,26.1805820465088,26.1805820465088,52.5613914041979,5.83880773108914,7.05858612060547,66,1,0,0,1,0.301132202148438,32.2580642700195,2,1,1,130.052780151367,0,2084574304,130.052780151367,,,,,,,,,,,,,,,,,,,,,,,,,,,,,,,,,
,3872939931.26713,162.023101806641,26.1805820465088,3.57834711933973E-5,1.57572534436335E-8,1,5,13.1008939743042,4.99446006427283,40.4600016772747,0.0415206286186875,0.00609126809482506,1,5.30793103834201E-9,,,,,,,,,,,,,,,,,,,,,162.023101806641,162.023101806641,26.1805820465088,26.1805820465088,52.5508394191883,5.84565474697582,7.14786005020142,65,1,64,0,0,0.303497314453125,33.2355842590332,2,1,1,162.023101806641,0,2084574528,162.023101806641,,,,,,,,,,,,,,,,,,,,,,,,,,,,,,,,,
,3872940124.15227,194.009582519531,26.1805820465088,2.77622115163737E-5,8.13195793008526E-9,1,5,13.1008939743042,4.99414396809513,40.5899994075298,0.0322104441704484,0.00472558048538456,1,4.25265423005353E-9,,,,,,,,,,,,,,,,,,,,,194.009582519531,194.009582519531,26.1805820465088,26.1805820465088,52.7724311043902,5.84670448649569,7.25080823898315,66,1,0,0,1,0.313339233398438,32.2580642700195,2,1,1,194.009582519531,0,2084574400,194.009582519531,,,,,,,,,,,,,,,,,,,,,,,,,,,,,,,,,
,3872940317.1567,226.050628662109,26.1805820465088,2.11773341449615E-5,8.60437560928219E-9,1,5,13.1008939743042,4.99184773244692,40.7299995422363,0.0245539469790306,0.00360738755242372,1,7.54010889440781E-9,,,,,,,,,,,,,,,,,,,,,226.050628662109,226.050628662109,26.1805820465088,26.1805820465088,52.753281205669,5.85516022776234,7.44992637634277,65,1,64,0,0,0.31036376953125,32.2580642700195,2,1,1,226.050628662109,0,2084574336,226.050628662109,,,,,,,,,,,,,,,,,,,,,,,,,,,,,,,,,
,3872940510.32401,258.036773681641,26.1805820465088,1.65669690978521E-5,9.07744932679577E-9,1,5,13.1008939743042,4.9938230724507,40.8900007605553,0.0192187169718141,0.00282643233663557,1,8.32851857568139E-9,,,,,,,,,,,,,,,,,,,,,258.036773681641,258.036773681641,26.1805820465088,26.1805820465088,52.758361791044,5.84850518729575,7.89869356155395,64,1,64,0,0,0.317001342773438,33.7243423461914,2,1,1,258.036773681641,0,2084574432,258.036773681641,,,,,,,,,,,,,,,,,,,,,,,,,,,,,,,,,
,3872940702.64169,290.016174316406,26.1805820465088,1.27487753375949E-5,8.27091949052331E-9,1,5,13.1008939743042,4.99468079399191,41.0800017416477,0.0147917382163332,0.00218368751426009,1,1.34242715016092E-8,,,,,,,,,,,,,,,,,,,,,290.016174316406,290.016174316406,26.1805820465088,26.1805820465088,52.6680836970729,5.84390883862911,7.95910024642944,65,1,64,0,0,0.313873291015625,33.2355842590332,2,1,1,290.016174316406,0,2084574432,290.016174316406,,,,,,,,,,,,,,,,,,,,,,,,,,,,,,,,,
,3872941492.19651,280.354263305664,26.3165531158447,1.63119756844841E-5,8.82995113318565E-8,1,5,13.1008939743042,4.99531311199418,41.0199984908104,0.0189167298575536,0.00288020171115113,1,9.10087413923545E-8,,,,,,,,,,,,,,,,,,,,,279.796691894531,280.911834716797,26.3165531158447,26.3165531158447,52.7853279749575,5.84155428783614,9.01025485992432,65,1,64,0,0,0.303726196289063,32.7468223571777,2,1,1,279.796691894531,0,2084573184,280.354263305664,,,,,,,,,,,,,,,,,,,,,,,,,,,,,,,,,
,3872941673.76252,248.971786499023,26.3165531158447,1.78678377721082E-5,3.3172120424245E-8,1,5,13.1008939743042,4.99317299843305,40.8799983561039,0.0207233135781776,0.00305268244398034,1,1.3180286706292E-8,,,,,,,,,,,,,,,,,,,,,248.971786499023,248.971786499023,26.3165531158447,26.3165531158447,52.903744695621,5.85402220749089,8.64395809173584,66,1,0,0,1,0.311279296875,34.7018585205078,2,1,1,248.971786499023,0,2084574176,248.971786499023,,,,,,,,,,,,,,,,,,,,,,,,,,,,,,,,,
,3872941866.10964,216.972229003906,26.3165531158447,1.97198902060737E-5,6.02311901323889E-9,1,5,13.1008939743042,4.99268942483102,40.7399982213974,0.0228683384039873,0.00336798798191834,1,1.39801796708356E-8,,,,,,,,,,,,,,,,,,,,,216.972229003906,216.972229003906,26.3165531158447,26.3165531158447,52.9350098363902,5.86057270134086,8.35928630828857,66,1,0,0,1,0.309371948242188,35.190616607666,2,1,1,216.972229003906,0,2084574336,216.972229003906,,,,,,,,,,,,,,,,,,,,,,,,,,,,,,,,,
,3872942057.29709,184.944686889648,26.3165531158447,2.16963846266401E-5,1.41157691153885E-8,1,5,13.1008939743042,4.99163714598685,40.6400002539158,0.0251559935279623,0.00368383053113204,1,-2.4133604881734E-9,,,,,,,,,,,,,,,,,,,,,184.944686889648,184.944686889648,26.3165531158447,26.3165531158447,52.6235308714767,5.8569129103908,8.13866710662842,66,1,0,0,1,0.3106689453125,33.7243423461914,2,1,1,184.944686889648,0,2084574048,184.944686889648,,,,,,,,,,,,,,,,,,,,,,,,,,,,,,,,,
,3872942248.48688,152.966873168945,26.3165531158447,2.37131389264427E-5,9.13732183607364E-9,1,5,13.1008939743042,4.99102487169641,40.5399985611439,0.0274895682659701,0.00402582491204261,1,-2.41227602817384E-9,,,,,,,,,,,,,,,,,,,,,152.966873168945,152.966873168945,26.3165531158447,26.3165531158447,52.6563592692844,5.85721709106842,7.95300388336182,66,1,0,0,1,0.30975341796875,33.7243423461914,2,1,1,152.966873168945,0,2084574240,152.966873168945,,,,,,,,,,,,,,,,,,,,,,,,,,,,,,,,,
,3872942440.648,120.97331237793,26.3165531158447,2.68849091560398E-5,5.83437908496971E-9,1,5,13.1008939743042,4.99122563675002,40.4400005936623,0.0311678225964658,0.00456723070692972,1,-4.30865002186849E-10,,,,,,,,,,,,,,,,,,,,,120.97331237793,120.97331237793,26.3165531158447,26.3165531158447,52.8822499113421,5.85720833384249,7.79125738143921,66,1,0,0,1,0.310592651367188,33.2355842590332,2,1,1,120.97331237793,0,2084573184,120.97331237793,,,,,,,,,,,,,,,,,,,,,,,,,,,,,,,,,
,3872942632.15209,88.9711151123047,26.3165531158447,3.05939379417904E-5,7.34541893575702E-9,1,5,13.1008939743042,4.9937306278794,40.3599999845028,0.0354922775838698,0.00520354260543844,1,1.72095802048614E-9,,,,,,,,,,,,,,,,,,,,,88.9711151123047,88.9711151123047,26.3165531158447,26.3165531158447,52.7071651230344,5.85125022887467,7.61211013793945,66,1,0,0,1,0.305099487304687,33.7243423461914,2,1,1,88.9711151123047,0,2084573728,88.9711151123047,,,,,,,,,,,,,,,,,,,,,,,,,,,,,,,,,
,3872942819.96251,56.9891662597656,26.3165531158447,3.58523743658284E-5,1.18341176927171E-8,1,5,13.1008939743042,4.99571114184859,40.2799993753433,0.0416175625526206,0.00608881340335802,1,-8.74534514726627E-9,,,,,,,,,,,,,,,,,,,,,56.9891662597656,56.9891662597656,26.3165531158447,26.3165531158447,52.6461980985344,5.84318725178648,7.35421895980835,64,1,64,0,0,0.303573608398438,33.2355842590332,2,1,1,56.9891662597656,0,2084573952,56.9891662597656,,,,,,,,,,,,,,,,,,,,,,,,,,,,,,,,,
,3872943006.62318,24.9864559173584,26.3165531158447,6.27835470964792E-5,6.92726387723016E-8,1,5,13.1008939743042,4.99702712386811,40.2400009334087,0.0729034497268173,0.010685510424941,1,1.0825646757824E-9,,,,,,,,,,,,,,,,,,,,,24.9864559173584,24.9864559173584,26.3165531158447,26.3165531158447,52.6661296257748,5.8367647611998,6.7356390953064,65,1,64,0,0,0.29998779296875,33.2355842590332,2,1,1,24.9864559173584,0,2084574016,24.9864559173584,,,,,,,,,,,,,,,,,,,,,,,,,,,,,,,,,
,3872943387.01001,9.01868915557861,26.3165531158447,0.000129355390596111,1.0778391172597E-7,1,5,13.1008939743042,4.99467591013849,40.1999987661839,0.150098846189311,0.0220561154008476,1,4.94914199538569E-8,,,,,,,,,,,,,,,,,,,,,9.01868915557861,9.01868915557861,26.3165531158447,26.3165531158447,52.6762907965248,5.84497304504113,4.7877631187439,66,1,0,0,1,0.304336547851562,32.7468223571777,6,1,1,9.01868915557861,0,2084574208,9.01868915557861,,,,,,,,,,,,,,,,,,,,,,,,,,,,,,,,,
,3872943593.72593,41.0082244873047,26.3165531158447,4.24127534662041E-5,1.87491563829537E-8,1,5,13.1008939743042,4.99582701681495,40.1999987661839,0.0492323611195824,0.00721760435490786,1,2.06568290803435E-9,,,,,,,,,,,,,,,,,,,,,41.0082244873047,41.0082244873047,26.3165531158447,26.3165531158447,52.6153237720248,5.83962714533276,6.44759321212769,66,1,0,0,1,0.3009033203125,33.7243423461914,2,1,1,41.0082244873047,0,2084574528,41.0082244873047,,,,,,,,,,,,,,,,,,,,,,,,,,,,,,,,,
,3872943795.61425,73.0118789672852,26.3165531158447,3.31503246125739E-5,8.15956021366285E-9,1,5,13.1008939743042,4.99421048278803,40.2400009334087,0.0384620338856684,0.00564663360638591,1,8.35594121784943E-9,,,,,,,,,,,,,,,,,,,,,73.0118789672852,73.0118789672852,26.3165531158447,26.3165531158447,52.6121972579479,5.84653079987325,6.89515590667725,66,1,0,0,1,0.304183959960937,33.7243423461914,2,1,1,73.0118789672852,0,2084574528,73.0118789672852,,,,,,,,,,,,,,,,,,,,,,,,,,,,,,,,,
,3872943992.73458,105.017166137695,26.3165531158447,2.85789775039245E-5,7.25655952454137E-9,1,5,13.1008939743042,4.99336404383909,40.3000004589558,0.0331519433153832,0.00485592134840592,1,-2.19309534903024E-9,,,,,,,,,,,,,,,,,,,,,105.017166137695,105.017166137695,26.3165531158447,26.3165531158447,52.6360369277844,5.84954451946833,7.07035160064697,66,1,0,0,1,0.30609130859375,33.7243423461914,2,1,1,105.017166137695,0,2084574560,105.017166137695,,,,,,,,,,,,,,,,,,,,,,,,,,,,,,,,,
,3872944185.9782,137.002563476562,26.3165531158447,2.48085642877879E-5,6.01105311981444E-9,1,5,13.1008939743042,4.99126039412313,40.3899997472763,0.0287612133687589,0.00421298343311129,1,-1.74079126306783E-9,,,,,,,,,,,,,,,,,,,,,137.002563476562,137.002563476562,26.3165531158447,26.3165531158447,52.6665204400344,5.85809387860151,7.17483425140381,66,1,0,0,1,0.3106689453125,33.2355842590332,2,1,1,137.002563476562,0,2084574304,137.002563476562,,,,,,,,,,,,,,,,,,,,,,,,,,,,,,,,,
,3872944378.97874,169.027954101562,26.3165531158447,2.13297650137411E-5,6.8355169402287E-9,1,5,13.1008939743042,4.98629331342493,40.4900014400482,0.0246943682196741,0.00361244473038916,1,-5.57384301215546E-9,,,,,,,,,,,,,,,,,,,,,169.007934570313,169.047973632813,26.3165531158447,26.3165531158447,52.7923626316306,5.87597943811613,7.24941635131836,64,1,64,0,0,0.318145751953125,32.7468223571777,2,1,1,169.047973632813,0,2084574368,169.027954101562,,,,,,,,,,,,,,,,,,,,,,,,,,,,,,,,,
,3872944571.85743,201.033843994141,26.3165531158447,1.8481339116157E-5,6.32068022510504E-9,1,5,13.1008939743042,4.98633599394426,40.6199991703033,0.0213967571952745,0.00313092086486271,1,-4.0929050399594E-9,,,,,,,,,,,,,,,,,,,,,201.033843994141,201.033843994141,26.3165531158447,26.3165531158447,52.9115609808133,5.87582086987073,7.33747291564941,65,1,64,0,0,0.319442749023438,33.7243423461914,2,1,1,201.033843994141,0,2084574272,201.033843994141,,,,,,,,,,,,,,,,,,,,,,,,,,,,,,,,,
,3872944765.27477,233.043487548828,26.3165531158447,1.62516874166905E-5,6.01119357509826E-9,1,5,13.1008939743042,4.98763618798661,40.7700017094612,0.0188209401555418,0.00276317993814566,1,4.15285417390837E-9,,,,,,,,,,,,,,,,,,,,,233.043487548828,233.043487548828,26.3165531158447,26.3165531158447,52.7739943614286,5.87337929016263,7.51626205444336,66,1,0,0,1,0.318527221679687,32.7468223571777,2,1,1,233.043487548828,0,2084574400,233.043487548828,,,,,,,,,,,,,,,,,,,,,,,,,,,,,,,,,
,3872944957.86299,265.008636474609,26.3165531158447,1.4077493300894E-5,6.67680924593524E-9,1,5,13.1008939743042,4.99947262562453,40.9299992024899,0.0163559085327051,0.00241049854377211,1,1.13649054575759E-8,,,,,,,,,,,,,,,,,,,,,265.008636474609,265.008636474609,26.3165531158447,26.3165531158447,52.8193288155441,5.8661388048472,7.95138883590698,64,1,64,0,0,0.311431884765625,32.7468223571777,2,1,1,265.008636474609,0,2084574368,265.008636474609,,,,,,,,,,,,,,,,,,,,,,,,,,,,,,,,,
,3872945151.44276,297.028015136719,26.3165531158447,1.235109870572E-5,6.96588344862521E-9,1,5,13.1008939743042,5.0018937157754,41.1200001835823,0.0143593021845629,0.00211988613850862,1,1.30380717011395E-8,,,,,,,,,,,,,,,,,,,,,297.028015136719,297.028015136719,26.3165531158447,26.3165531158447,52.7603158623421,5.85489473849278,7.75128126144409,64,1,64,0,0,0.30975341796875,34.7018585205078,6,1,1,297.028015136719,0,2084574304,297.028015136719,,,,,,,,,,,,,,,,,,,,,,,,,,,,,,,,,
,3872945481.35402,300.00309753418,42561.806640625,0.0155141384595522,5.20410350259E-6,1,2,13.1008939743042,5.0121587324867,41.1200001835823,18.1014955057924,2.5811008868495,100,-6.02182478710048E-5,,,,,,,,,,,,,,,,,,,,,300.002655029297,300.003540039063,42472.24609375,42651.3671875,52.6071166725729,5.85724550704693,7.80988121032715,25,1,68,0,0,0.311279296875,33.2355842590332,1,6,1,300.002655029297,0,2084573184,300.00309753418,,,,,,,,,,,,,,,,,,,,,,,,,,,,,,,,,
,3872945544.87721,300.001953125,36216.12109375,0.0132168781889976,4.50376042595409E-6,1,2,13.1008939743042,5.01123650450131,41.1200001835823,15.4153300474804,2.2107337220807,100,-4.06689683108512E-5,,,,,,,,,,,,,,,,,,,,,300.001831054687,300.002075195313,36131.34375,36300.8984375,52.6317379709286,5.86146686260911,7.91772031784058,24,1,68,0,0,0.311508178710937,33.7243423461914,1,6,1,300.002075195313,0,2084573824,300.001953125,,,,,,,,,,,,,,,,,,,,,,,,,,,,,,,,,
,3872945636.20174,300.003295898438,27098.5908203125,0.00992408674741114,4.29129525994318E-6,1,2,13.1008939743042,5.00997802005868,41.1200001835823,11.5707099172121,1.65974949281369,100,-3.02191817241751E-5,,,,,,,,,,,,,,,,,,,,,300.003265380859,300.003326416016,27014.083984375,27183.09765625,52.6114156294286,5.87163403202755,8.14756202697754,26,1,0,0,1,0.31219482421875,33.7243423461914,1,6,1,300.003326416016,0,2084573952,300.003295898438,,,,,,,,,,,,,,,,,,,,,,,,,,,,,,,,,
,3872945717.50975,300.001434326172,18975.5205078125,0.00698317991342134,4.6758170673674E-6,1,2,13.1008939743042,5.01107861916716,41.1200001835823,8.14547000738686,1.16056176160278,100,-2.78654381712719E-5,,,,,,,,,,,,,,,,,,,,,300.001220703125,300.001647949219,18886.001953125,19065.0390625,52.7478098060344,5.86646291775623,8.41852378845215,26,1,0,0,1,0.311965942382812,32.7468223571777,1,6,1,300.001647949219,0,2084573920,300.001434326172,,,,,,,,,,,,,,,,,,,,,,,,,,,,,,,,,
,3872945790.97927,300.000442504883,11639.98828125,0.00433694079595495,1.34205277735006E-5,1,2,13.1008939743042,5.01151664754084,41.1200001835823,5.06312602458914,0.695472031932064,100,-3.9082278641234E-5,,,,,,,,,,,,,,,,,,,,,300.000427246094,300.000457763672,11554.95703125,11725.01953125,52.7001304663613,5.86415836711733,8.7022819519043,25,1,68,0,0,0.309600830078125,32.7468223571777,1,6,1,300.000457763672,0,2084573888,300.000442504883,,,,,,,,,,,,,,,,,,,,,,,,,,,,,,,,,
,3872945854.49949,300.000991821289,5293.74951171875,0.00205456930035472,3.56366533542189E-5,1,2,13.1008939743042,5.01350711828286,41.1200001835823,2.40707922544247,0.280812386267455,100,-6.0382916797847E-5,,,,,,,,,,,,,,,,,,,,,300.000885009766,300.001098632812,5208.724609375,5378.7744140625,52.7607066766017,5.85761965853857,8.92432975769043,25,1,68,0,0,0.3070068359375,33.2355842590332,1,6,1,300.001098632812,0,2084573920,300.000991821289,,,,,,,,,,,,,,,,,,,,,,,,,,,,,,,,,
,3872945935.81788,300.000473022461,-2839.12829589844,-0.00109841776915537,4.7242188473308E-6,1,2,13.1008939743042,5.01471874916973,41.1200001835823,-1.27521350299969,-0.232731507918408,100,-3.846037971445E-5,,,,,,,,,,,,,,,,,,,,,300.000366210937,300.000579833984,-2929.22143554687,-2749.03515625,52.746246548996,5.85552167979178,9.24590492248535,26,1,0,0,1,0.3076171875,33.2355842590332,1,6,1,300.000366210937,0,2084573472,300.000473022461,,,,,,,,,,,,,,,,,,,,,,,,,,,,,,,,,
,3872945999.4686,300.000396728516,-9204.53857421875,-0.00342481572673802,4.06151511145878E-6,1,2,13.1008939743042,5.01482797118142,41.1200001835823,-3.99307027756218,-0.610401614221353,100,-2.11442070127525E-5,,,,,,,,,,,,,,,,,,,,,300.000183105469,300.000610351562,-9289.619140625,-9119.4580078125,52.8873304967171,5.85311066192572,9.433180809021,26,1,0,0,1,0.311279296875,33.7243423461914,1,6,1,300.000183105469,0,2084573408,300.000396728516,,,,,,,,,,,,,,,,,,,,,,,,,,,,,,,,,
,3872946074.73257,299.999908447266,-16732.568359375,-0.00617584874740455,3.9389880178483E-6,1,2,13.1008939743042,5.01510266770063,41.1200001835823,-7.20462620855277,-1.07682761552677,10,-1.75880659995585E-5,,,,,,,,,,,,,,,,,,,,,299.999877929687,299.999938964844,-16822.716796875,-16642.419921875,52.773603547169,5.85033627767697,9.35931968688965,26,1,0,0,1,0.304641723632812,34.2131004333496,1,6,1,299.999938964844,0,2084573760,299.999908447266,,,,,,,,,,,,,,,,,,,,,,,,,,,,,,,,,
,3872946150.14184,300.000885009766,-24274.6845703125,-0.00892020289812366,3.90896120607446E-6,1,2,13.1008939743042,5.01519417910501,41.1200001835823,-10.4081344475287,-1.54355553723822,100,-1.52757442225382E-5,,,,,,,,,,,,,,,,,,,,,300.000732421875,300.001037597656,-24364.740234375,-24184.62890625,52.671991839669,5.84920922898171,9.27310371398926,24,1,68,0,0,0.306396484375,33.7243423461914,1,6,1,300.000732421875,0,2084573952,300.000885009766,,,,,,,,,,,,,,,,,,,,,,,,,,,,,,,,,
,3872946213.68801,300.000595092773,-30640.8603515625,-0.011236367974423,4.16400761007976E-6,1,2,13.1008939743042,5.01525625557526,41.1200001835823,-13.1116551879277,-1.93904460564719,100,-1.46713206692658E-5,,,,,,,,,,,,,,,,,,,,,300.000579833984,300.000610351562,-30736.11328125,-30545.607421875,52.614151329246,5.84832749341246,9.2098274230957,25,1,68,0,0,0.306625366210937,33.2355842590332,1,6,1,300.000579833984,0,2084574272,300.000595092773,,,,,,,,,,,,,,,,,,,,,,,,,,,,,,,,,
,3872946287.12828,300.000503540039,-38000.453125,-0.0138988933989625,4.75565993967519E-6,1,2,13.1008939743042,5.01525974163579,41.1200001835823,-16.2186922402621,-2.3975926194124,100,-1.73572213093998E-5,,,,,,,,,,,,,,,,,,,,,300.000457763672,300.000549316406,-38090.25,-37910.65625,52.7732127329094,5.84930430845981,9.15223598480225,24,1,68,0,0,0.304031372070313,33.2355842590332,1,6,1,300.000549316406,0,2084573984,300.000503540039,,,,,,,,,,,,,,,,,,,,,,,,,,,,,,,,,
,3872946402.1752,300.000274658203,-49529.34765625,-0.0180797168992286,4.19402278104875E-6,1,2,13.1008939743042,5.01198546674512,41.1200001835823,-21.0776613265089,-3.11878189111053,100,-2.50066076624679E-5,,,,,,,,,,,,,,,,,,,,,300.000091552734,300.000457763672,-49624.55078125,-49434.14453125,52.5719433892075,5.8609584575221,9.0885534286499,26,1,0,0,1,0.310211181640625,32.7468223571777,1,6,1,300.000091552734,0,2084574240,300.000274658203,,,,,,,,,,,,,,,,,,,,,,,,,,,,,,,,,
,3872946473.63778,300.000228881836,-44601.6328125,-0.0163512270089726,4.37101979607737E-6,1,2,13.1008939743042,5.01173719719367,41.1200001835823,-19.0780942839605,-2.70539414679456,100,7.60356177446895E-5,,,,,,,,,,,,,,,,,,,,,299.999938964844,300.000518798828,-44691.50390625,-44511.76171875,52.7016937233998,5.8620827736434,9.05516719818115,23,1,68,0,0,0.309982299804687,33.2355842590332,1,6,1,300.000518798828,0,2084574208,300.000228881836,,,,,,,,,,,,,,,,,,,,,,,,,,,,,,,,,
,3872946545.10332,300,-37463.0390625,-0.0137538348028598,5.4689231284629E-6,1,2,13.1008939743042,5.01175622578283,41.1200001835823,-16.0463173082483,-2.28457321762322,100,5.63081526570194E-5,,,,,,,,,,,,,,,,,,,,,299.999877929687,300.000122070313,-37552.9765625,-37373.1015625,52.6786356820825,5.86057193808773,9.02113151550293,25,1,68,0,0,0.311126708984375,33.7243423461914,1,6,1,300.000122070313,0,2084574048,300,,,,,,,,,,,,,,,,,,,,,,,,,,,,,,,,,
,3872946608.57926,300.001358032227,-31123.330078125,-0.0114522533014368,9.43705385761221E-6,1,2,13.1008939743042,5.01278504202458,41.1200001835823,-13.3657808443805,-1.89709257693651,100,5.1792725638384E-5,,,,,,,,,,,,,,,,,,,,,300.001342773438,300.001373291016,-31213.287109375,-31033.373046875,52.7118548941498,5.85572902924391,8.99682140350342,24,1,68,0,0,0.311050415039063,34.2131004333496,1,6,1,300.001373291016,0,2084573696,300.001358032227,,,,,,,,,,,,,,,,,,,,,,,,,,,,,,,,,
,3872946689.98932,300.001251220703,-23001.087890625,-0.00848915357860716,4.81208363893586E-6,1,2,13.1008939743042,5.01310587296118,41.1200001835823,-9.90742158561109,-1.41353062618572,100,3.22565123560153E-5,,,,,,,,,,,,,,,,,,,,,300.001251220703,300.001251220703,-23086.0078125,-22916.16796875,52.7845463464383,5.85489140241258,8.96866321563721,25,1,68,0,0,0.308456420898438,34.2131004333496,1,6,1,300.001251220703,0,2084574112,300.001251220703,,,,,,,,,,,,,,,,,,,,,,,,,,,,,,,,,
,3872946763.3851,300.000106811523,-15672.7119140625,-0.00585251883288433,1.89410716143967E-5,1,2,13.1008939743042,5.0129664623283,41.1200001835823,-6.83218978141183,-0.959684658890001,100,3.49110780785579E-5,,,,,,,,,,,,,,,,,,,,,300.000061035156,300.000152587891,-15767.58203125,-15577.841796875,52.8705254835537,5.85548760561518,8.95269584655762,25,1,68,0,0,0.308074951171875,32.7468223571777,1,6,1,300.000183105469,0,2084573952,300.000106811523,,,,,,,,,,,,,,,,,,,,,,,,,,,,,,,,,
,3872946826.8752,299.999649047852,-9323.5751953125,-0.00350564580868504,7.48139939183514E-6,1,2,13.1008939743042,5.01378688023364,41.1200001835823,-4.09556448268202,-0.560227149767294,100,3.35576167944835E-5,,,,,,,,,,,,,,,,,,,,,299.999450683594,299.999847412109,-9413.55078125,-9233.599609375,52.7751668042075,5.85177768147591,8.93298244476318,24,1,68,0,0,0.3076171875,33.7243423461914,1,6,1,299.999847412109,0,2084573792,299.999649047852,,,,,,,,,,,,,,,,,,,,,,,,,,,,,,,,,
,3872946890.42349,300.000595092773,-2977.32421875,-0.00118596515703371,4.76690175333291E-6,1,2,13.1008939743042,5.01448388788012,41.1200001835823,-1.39342404405667,-0.137571568127906,100,5.5908593104377E-5,,,,,,,,,,,,,,,,,,,,,300.000579833984,300.000610351562,-3067.33081054687,-2887.31762695313,52.7396027065825,5.8508217905312,8.92573833465576,24,1,68,0,0,0.309066772460937,33.2355842590332,1,6,1,300.000579833984,0,2084573856,300.000595092773,,,,,,,,,,,,,,,,,,,,,,,,,,,,,,,,,
,3872946961.89124,300.001235961914,4166.72998046875,0.00159081529683889,6.86183001206186E-6,1,2,13.1008939743042,5.01381181322967,41.1200001835823,1.84937781038252,0.316643858363349,100,3.82744071660213E-5,,,,,,,,,,,,,,,,,,,,,300.001190185547,300.001281738281,4081.62451171875,4251.83544921875,52.7861096034767,5.853007654337,8.91141605377197,26,1,0,0,1,0.306243896484375,32.7468223571777,1,6,1,300.001281738281,0,2084573472,300.001235961914,,,,,,,,,,,,,,,,,,,,,,,,,,,,,,,,,
,3872947025.3846,300.000091552734,10522.4365234375,0.00391915642169677,4.21315416419703E-6,1,2,13.1008939743042,5.0140329823481,41.1200001835823,4.56918937433602,0.693112349088542,100,1.97045761080778E-5,,,,,,,,,,,,,,,,,,,,,299.999938964844,300.000244140625,10432.2939453125,10612.5791015625,52.7325680499094,5.85089173702461,8.89865112304687,26,1,0,0,1,0.30670166015625,34.2131004333496,1,6,1,300.000244140625,0,2084573504,300.000091552734,,,,,,,,,,,,,,,,,,,,,,,,,,,,,,,,,
,3872947092.8887,299.999038696289,17274.740234375,0.00639148898288396,4.1334277791024E-6,1,2,13.1008939743042,5.01514432452775,41.1200001835823,7.45662369143244,1.11205689536917,10,1.61604114969134E-5,,,,,,,,,,,,,,,,,,,,,299.998565673828,299.99951171875,17184.59765625,17364.8828125,52.7900177460729,5.84626801739641,8.88500118255615,26,1,0,0,1,0.315017700195313,33.7243423461914,1,6,1,299.998565673828,0,2084574080,299.999038696289,,,,,,,,,,,,,,,,,,,,,,,,,,,,,,,,,
,3872947176.19367,300.000595092773,25608.5576171875,0.00943218352872155,3.80329728758941E-6,1,2,13.1008939743042,5.01475854027289,41.1200001835823,11.0041697124795,1.63202405801343,100,1.62152558605416E-5,,,,,,,,,,,,,,,,,,,,,300.00048828125,300.000701904297,25518.513671875,25698.6015625,52.6692561398517,5.85028664232378,8.8721752166748,26,1,0,0,1,0.30517578125,33.2355842590332,1,6,1,300.000701904297,0,2084573184,300.000595092773,,,,,,,,,,,,,,,,,,,,,,,,,,,,,,,,,
,3872947247.60952,299.999877929687,32764.7646484375,0.012041163486922,3.66454465223254E-6,1,2,13.1008939743042,5.01381156848231,41.1200001835823,14.0445553628998,2.08089398775944,100,1.89819591175067E-5,,,,,,,,,,,,,,,,,,,,,299.999847412109,299.999908447266,32674.517578125,32855.01171875,52.776730061246,5.85121675060632,8.8589563369751,26,1,0,0,1,0.31219482421875,33.2355842590332,1,6,1,299.999847412109,0,2084574080,299.999877929687,,,,,,,,,,,,,,,,,,,,,,,,,,,,,,,,,
,3872947363.891,299.999450683594,44421.265625,0.0162279158155091,4.31286512892643E-6,1,2,13.1008939743042,5.01409402893645,41.1200001835823,18.9297900910165,2.80187355042258,100,2.32037296036528E-5,,,,,,,,,,,,,,,,,,,,,299.999450683594,299.999450683594,44421.265625,44421.265625,52.6215768001786,5.85069701397499,8.84874820709229,26,1,0,0,1,0.306015014648438,34.2131004333496,1,6,1,299.999450683594,0,2084573984,299.999450683594,,,,,,,,,,,,,,,,,,,,,,,,,,,,,,,,,
,3872947426.28977,300.000381469727,50000.318359375,0.0183004820759145,2.54567148737154E-6,1,2,13.1008939743042,5.01366068363526,41.1200001835823,21.3453891172227,3.15566937015618,1000,2.30238449789905E-5,,,,,,,,,,,,,,,,,,,,,300.000335693359,300.000427246094,50000.3125,50000.32421875,52.5832770027363,5.85203025136585,8.84048652648926,26,1,0,0,1,0.307388305664063,33.2355842590332,1,4,1,300.000427246094,0,2084574368,300.000381469727,,,,,,,,,,,,,,,,,,,,,,,,,,,,,,,,,