File: LT data/Bridport/CREECH-1/325-FC-ZFC-RTSIRM-contsweepwithloop.dat
[Header]
; MPMS3 Data File (default extension .dat)
; Copyright (c) 2007, Quantum Design, Inc. All rights reserved.
TITLE,
FILEOPENTIME,3865576667.81968,06/28/2022,12:15 pm
BYAPP,MPMS3 w/ AC,1.0,1.1
INFO,MPMS3 Measurement Release 1.1.16 Build 424, MultiVu Release 2.3.4.19,APPNAME
INFO,Linear Motor Servo Controller,MOTOR_MODULE_NAME
INFO,3101-100 N2,MOTOR_HW_VERSION
INFO,,MOTOR_SERIAL_NUMBER
INFO,01.04.28,MOTOR_SOFTWARE_VERSION
INFO,Quantum Design Squid Module,SQUID_MODULE_NAME
INFO,3101-501 B0,SQUID_HW_VERSION
INFO,SQM327,SQUID_SERIAL_NUMBER
INFO,01.03.04,SQUID_SOFTWARE_VERSION
INFO,Quantum Design VSM Oven,OVEN_MODULE_NAME
INFO,3101-201 A3,OVEN_HW_VERSION
INFO,OVB365,OVEN_SERIAL_NUMBER
INFO,01.07.07,OVEN_SOFTWARE_VERSION
INFO,SQUID AC,AC_MODULE_NAME
INFO,3101-401 G0,AC_HW_VERSION
INFO,SAC220,AC_SERIAL_NUMBER
INFO,SQUID AC 00.95.07,AC_SOFTWARE_VERSION
INFO,TCI344,COIL_SERIAL_NUMBER
INFO,0,MOMENT_UNITS
INFO,oil stained sst,SAMPLE_MATERIAL
INFO,,SAMPLE_COMMENT
INFO,259.11,SAMPLE_MASS
INFO,,SAMPLE_VOLUME
INFO,,SAMPLE_MOLECULAR_WEIGHT
INFO,,SAMPLE_SIZE
INFO,,SAMPLE_SHAPE
INFO,Straw,SAMPLE_HOLDER
INFO,Standard,SAMPLE_HOLDER_DETAIL
INFO,57.77,SAMPLE_OFFSET
DATATYPE,COMMENT,1
DATATYPE,TIME,2
STARTUPAXIS,X,2
STARTUPAXIS,Y1,5
FIELDGROUP, VSM,2,3,4,5,6,8,9,10,11,14,15
FIELDGROUP, DC, 2,3,4,14,56,57,58,59,60,61,62,63,64,65,66,67,68,69
FIELDGROUP, AC, 2,3,4,11,16,17,18,19,20,21,22,23,24,25,26,27,28,29,30
STARTUPGROUP, All
[Data]
Comment,Time Stamp (sec),Temperature (K),Magnetic Field (Oe),Moment (emu),M. Std. Err. (emu),Transport Action,Averaging Time (sec),Frequency (Hz),Peak Amplitude (mm),Center Position (mm),Lockin Signal' (V),Lockin Signal (V),Range,M. Quad. Signal (emu),AC Moment (emu),AC M. Std Err. (emu),AC Phase (deg),AC Phase Std. Err. (deg),AC Susceptibility (emu/Oe),AC Suscept. Std Err. (emu/Oe),AC X' (emu/Oe),AC X' Std Err. (emu/Oe),AC X'' (emu/Oe),AC X'' Std Err. (emu/Oe),AC Drive (Oe),AC Frequency (Hz),AC Averaging Time (sec),AC Cycles,AC Range,AC Measure Type,AC Signal' (V),AC Signal'' (V),AC Trim Coil Ratio,AC Trim Coil Phase,Min. Temperature (K),Max. Temperature (K),Min. Field (Oe),Max. Field (Oe),Mass (grams),Motor Lag (deg),Pressure (Torr),Measure Count,Measurement Number,SQUID Status (code),Motor Status (code),Measure Status (code),Motor Current (amps),Motor Temp. (C),Temp. Status (code),Field Status (code),Chamber Status (code),Chamber Temp (K),Redirection State,Average Temp (K),Rotation Angle (deg),Rotator state,DC Moment Fixed Ctr (emu),DC Moment Err Fixed Ctr (emu),DC Moment Free Ctr (emu),DC Moment Err Free Ctr (emu),DC Fixed Fit,DC Free Fit,DC Calculated Center (mm),DC Calculated Center Err (mm),DC Scan Length (mm),DC Scan Time (s),DC Number of Points,DC Squid Drift,DC Min V (V),DC Max V (V),DC Scans per Measure,Map 01,Map 02,Map 03,Map 04,Map 05,Map 06,Map 07,Map 08,Map 09,Map 10,Map 11,Map 12,Map 13,Map 14,Map 15,Map 16
,3865579642.24928,2.00020694732666,25.4597358703613,0.0124156033833128,5.70359422527915E-7,1,5,12.9061126708984,4.99317014462746,33.4499999880791,16.1785259570287,2.38827494491351,10,8.61710421573629E-6,,,,,,,,,,,,,,,,,,,,,2.00020694732666,2.00020694732666,25.4597358703613,25.4597358703613,49.9824081049957,5.4329330242165,2.51831412315369,65,1,0,0,1,0.273818969726562,31.7693061828613,1,1,1,2.00020694732666,0,2.00020694732666,,,,,,,,,,,,,,,,,,,,,,,,,,,,,,,,,
,3865579828.09801,29.0945816040039,25.4597358703613,0.000285583860215366,4.30902747932891E-7,1,5,12.9061126708984,4.99454191147144,33.4599986672401,0.372319725547044,0.0546996840914279,1,1.38062443491312E-9,,,,,,,,,,,,,,,,,,,,,29.0945816040039,29.0945816040039,25.4597358703613,25.4597358703613,50.0222711594764,5.42702990071939,5.90029621124268,65,1,0,0,1,0.268478393554687,31.7693061828613,2,1,1,29.0945816040039,0,29.0945816040039,,,,,,,,,,,,,,,,,,,,,,,,,,,,,,,,,
,3865580006.29535,57.0238037109375,25.4597358703613,0.000193010913677048,4.48032219035526E-8,1,5,12.9061126708984,4.99351562895507,33.4799997508526,0.251579121639693,0.0368180040885967,1,-1.06441933326302E-7,,,,,,,,,,,,,,,,,,,,,57.0238037109375,57.0238037109375,25.4597358703613,25.4597358703613,49.9695112344284,5.43520230501798,6.4474778175354,65,1,0,0,1,0.271835327148438,31.7693061828613,2,1,1,57.0238037109375,0,57.0238037109375,,,,,,,,,,,,,,,,,,,,,,,,,,,,,,,,,
,3865580181.70386,85.0368499755859,25.4597358703613,0.00014462431632302,3.23833148266387E-8,1,5,12.9061126708984,4.99287118389656,33.5300005972385,0.18848358645384,0.0275295035284145,1,-1.20790393200773E-7,,,,,,,,,,,,,,,,,,,,,85.0368499755859,85.0368499755859,25.4597358703613,25.4597358703613,50.0179722026207,5.43656418237102,6.6812105178833,63,1,64,0,0,0.274734497070313,31.7693061828613,2,1,1,85.0368499755859,0,85.0368499755859,,,,,,,,,,,,,,,,,,,,,,,,,,,,,,,,,
,3865580351.82726,113.030090332031,25.4597358703613,0.00011721719491953,2.99687691451061E-8,1,5,12.9061126708984,4.99317224871629,33.5900001227856,0.152779393438233,0.0223035914655381,1,-1.06189683926279E-7,,,,,,,,,,,,,,,,,,,,,113.030090332031,113.030090332031,25.4597358703613,25.4597358703613,50.0805024841591,5.43382250555866,6.80197143554687,65,1,0,0,1,0.275955200195313,31.2805480957031,2,1,1,113.030090332031,0,113.030090332031,,,,,,,,,,,,,,,,,,,,,,,,,,,,,,,,,
,3865580520.41819,141.018936157227,25.4597358703613,9.39530544495382E-5,2.0418175451685E-8,1,5,12.9061126708984,4.99541355746458,33.670000731945,0.122535484933479,0.0178801252013092,1,-9.13387391016753E-8,,,,,,,,,,,,,,,,,,,,,141.018936157227,141.018936157227,25.4597358703613,25.4597358703613,50.1696081353515,5.42771107071078,6.89222192764282,65,1,0,0,1,0.267791748046875,31.2805480957031,2,1,1,141.018936157227,0,141.018936157227,,,,,,,,,,,,,,,,,,,,,,,,,,,,,,,,,
,3865580690.1815,169.024459838867,25.4597358703613,7.71667838779861E-5,1.666405799501E-8,1,5,12.9061126708984,4.99628961930726,33.7500013411045,0.100668970755736,0.014677315349361,1,-8.40963907490536E-8,,,,,,,,,,,,,,,,,,,,,169.024459838867,169.024459838867,25.4597358703613,25.4597358703613,50.2337016739284,5.42331560201164,6.96153020858765,64,1,64,0,0,0.27191162109375,31.2805480957031,2,1,1,169.024459838867,0,169.024459838867,,,,,,,,,,,,,,,,,,,,,,,,,,,,,,,,,
,3865580858.71722,197.005126953125,25.4597358703613,6.40224418737527E-5,1.24686187099937E-8,1,5,12.9061126708984,4.99667632001061,33.8600017130375,0.0835303848124432,0.0121786687025678,1,-6.9680398323782E-8,,,,,,,,,,,,,,,,,,,,,197.005126953125,197.005126953125,25.4597358703613,25.4597358703613,50.1465500940341,5.42131007899736,7.03236389160156,64,1,64,0,0,0.26824951171875,31.7693061828613,2,1,1,197.005126953125,0,197.005126953125,,,,,,,,,,,,,,,,,,,,,,,,,,,,,,,,,
,3865581027.16014,225.0390625,25.4597358703613,5.26802374400152E-5,1.27731371032448E-8,1,5,12.9061126708984,4.99684153039928,33.9899994432926,0.0687359021889196,0.0100177474106151,1,-6.02601105319758E-8,,,,,,,,,,,,,,,,,,,,,225.0390625,225.0390625,25.4597358703613,25.4597358703613,50.2372190022649,5.41887439273661,7.19156551361084,64,1,64,0,0,0.272598266601562,31.7693061828613,2,1,1,225.0390625,0,225.0390625,,,,,,,,,,,,,,,,,,,,,,,,,,,,,,,,,
,3865581196.45852,253.124816894531,25.4597358703613,4.31435217589985E-5,9.89200433041823E-9,1,5,12.9061126708984,4.99767643259253,34.1299995779991,0.0563052037248564,0.00821026142091446,1,-4.62029368223307E-8,,,,,,,,,,,,,,,,,,,,,253.124816894531,253.124816894531,25.4597358703613,25.4597358703613,50.2454261017169,5.41557911278959,7.49029397964478,64,1,64,0,0,0.267105102539062,31.7693061828613,2,1,1,253.124816894531,0,253.124816894531,,,,,,,,,,,,,,,,,,,,,,,,,,,,,,,,,
,3865581364.85575,281.035247802734,25.4597358703613,3.5504219071735E-5,8.95561350852624E-9,1,5,12.9061126708984,4.99808144350538,34.2900007963181,0.0463377367331491,0.0067771623862037,1,-2.27716561292466E-8,,,,,,,,,,,,,,,,,,,,,281.035247802734,281.035247802734,25.4597358703613,25.4597358703613,50.2208048033611,5.41242618987557,7.73412847518921,64,1,64,0,0,0.270614624023438,31.7693061828613,2,1,1,281.035247802734,0,281.035247802734,,,,,,,,,,,,,,,,,,,,,,,,,,,,,,,,,
,3865584192.04139,2.00089561939239,46402.48046875,0.513644727083045,0.00640018194101068,1,2,12.9061126708984,4.99264315295744,33.4499999880791,669.67351213309,95.7113469187648,1000,-0.00200656603533638,,,,,,,,,,,,,,,,,,,,,2.00066375732422,2.00112748146057,46307.47265625,46497.48828125,50.9680416677458,5.43979395541547,2.47657251358032,24,1,68,0,0,0.282440185546875,31.7693061828613,5,6,1,2.00066375732422,0,2.00089561939239,,,,,,,,,,,,,,,,,,,,,,,,,,,,,,,,,
,3865584254.81989,1.99937433004379,40137.8828125,0.486401393084054,0.00198356527347051,1,2,12.9061126708984,4.99327887015463,33.4499999880791,633.877989091153,93.3043372119068,1000,0.000135737606193232,,,,,,,,,,,,,,,,,,,,,1.99909293651581,1.99965572357178,40078.0390625,40197.7265625,50.9430295551304,5.43628316618339,2.47550535202026,26,1,0,0,1,0.278167724609375,31.7693061828613,5,6,1,1.99909293651581,0,1.99937433004379,,,,,,,,,,,,,,,,,,,,,,,,,,,,,,,,,
,3865584312.98892,1.99998962879181,34332.3671875,0.447618753759595,0.00445072087753715,1,2,12.9061126708984,4.99319781704504,33.4499999880791,583.133530849437,87.1539065526651,1000,0.00111556241269292,,,,,,,,,,,,,,,,,,,,,1.99960231781006,2.00037693977356,34247.3203125,34417.4140625,50.8414178476304,5.43627068271445,2.45660805702209,25,1,68,0,0,0.275726318359375,31.7693061828613,5,6,1,2.00037693977356,0,1.99998962879181,,,,,,,,,,,,,,,,,,,,,,,,,,,,,,,,,
,3865584375.40325,2.00029689073563,28097.783203125,0.407658629803135,0.00366419308600058,1,2,12.9061126708984,4.99360225095756,33.4499999880791,531.40663859261,77.5400428123423,1000,-0.00039760547294136,,,,,,,,,,,,,,,,,,,,,1.99898064136505,2.0016131401062,28007.927734375,28187.638671875,50.5053175843611,5.43455780962157,2.46521949768066,24,1,68,0,0,0.280303955078125,31.7693061828613,1,6,1,2.0016131401062,0,2.00029689073563,,,,,,,,,,,,,,,,,,,,,,,,,,,,,,,,,
,3865584439.82901,1.99982327222824,21663.0634765625,0.357280433400116,0.00257388907936262,1,2,12.9061126708984,4.99362563765378,33.4499999880791,465.816170526967,67.4314913889753,1000,-0.000752533127099399,,,,,,,,,,,,,,,,,,,,,1.99922049045563,2.00042605400085,21568.26953125,21757.857421875,50.2770820567457,5.43396998948489,2.46070957183838,26,1,0,0,1,0.274658203125,31.7693061828613,1,6,1,2.00042605400085,0,1.99982327222824,,,,,,,,,,,,,,,,,,,,,,,,,,,,,,,,,
,3865584502.29148,2.00256049633026,15433.451171875,0.298262153166098,0.00012065874561735,1,2,12.9061126708984,4.99353347586056,33.4499999880791,388.717873347129,57.252314248883,1000,0.000109203211455505,,,,,,,,,,,,,,,,,,,,,2.00063729286194,2.00448369979858,15338.6318359375,15528.2705078125,50.2919329986111,5.43302189121844,2.46800494194031,26,1,0,0,1,0.272598266601562,31.2805480957031,1,6,1,2.00063729286194,0,2.00256049633026,,,,,,,,,,,,,,,,,,,,,,,,,,,,,,,,,
,3865584564.07282,1.99996310472488,9260.56884765625,0.218112552546199,0.00016309433482692,1,2,12.9061126708984,4.99411043428331,33.4499999880791,284.319449366952,41.7886496833377,1000,1.42741187672598E-5,,,,,,,,,,,,,,,,,,,,,1.9996896982193,2.00023651123047,9095.6826171875,9425.455078125,50.218850732063,5.4306833100029,2.46090912818909,26,1,0,0,1,0.271759033203125,30.7917900085449,1,6,1,2.00023651123047,0,1.99996310472488,,,,,,,,,,,,,,,,,,,,,,,,,,,,,,,,,
,3865584623.22094,1.98593091964722,3349.32153320313,0.111913516122889,0.000245872431051479,1,2,12.9061126708984,4.9939047855073,33.4499999880791,145.877866995282,21.426718658435,1000,-3.25743427308537E-6,,,,,,,,,,,,,,,,,,,,,1.9810516834259,1.99081015586853,3249.55737304687,3449.08569335937,50.0312598874476,5.43199297760505,2.45152807235718,26,1,0,0,1,0.271987915039062,31.7693061828613,6,6,1,1.99081015586853,0,1.98593091964722,,,,,,,,,,,,,,,,,,,,,,,,,,,,,,,,,
,3865584703.79207,2.00015008449554,-4701.44555664063,-0.117013327591917,0.000255331518337884,1,2,12.9061126708984,4.99413339580136,33.4499999880791,-152.514313256781,-22.546718011385,100,-0.00010565070621364,,,,,,,,,,,,,,,,,,,,,2.00011372566223,2.00018644332886,-4786.35546875,-4616.53564453125,50.1191930958611,5.43160447794579,2.46270513534546,26,1,0,0,1,0.270614624023438,34.7018585205078,5,6,1,2.00011372566223,0,2.00015008449554,,,,,,,,,,,,,,,,,,,,,,,,,,,,,,,,,
,3865584784.3249,1.99984508752823,-12761.7709960938,-0.260096296140803,0.000149229125738356,1,2,12.9061126708984,4.99335732643464,33.4499999880791,-338.953557196563,-49.9707979812684,1000,-0.00013129556686018,,,,,,,,,,,,,,,,,,,,,1.99905860424042,2.00063157081604,-12856.765625,-12666.7763671875,50.1371705518034,5.43384514993377,2.45147800445557,26,1,0,0,1,0.275497436523438,31.7693061828613,5,6,1,2.00063157081604,0,1.99984508752823,,,,,,,,,,,,,,,,,,,,,,,,,,,,,,,,,
,3865584843.17738,1.99964886903763,-18646.8251953125,-0.32853478316172,0.000140214097605752,1,2,12.9061126708984,4.99320415245134,33.4499999880791,-428.092221232893,-63.3272242760916,1000,-0.000327327632459579,,,,,,,,,,,,,,,,,,,,,1.99931609630585,1.99998164176941,-18766.734375,-18526.916015625,50.1997008333418,5.43466640155721,2.44340395927429,26,1,0,0,1,0.272750854492187,31.2805480957031,1,6,1,1.99931609630585,0,1.99964886903763,,,,,,,,,,,,,,,,,,,,,,,,,,,,,,,,,
,3865584905.26773,1.9995185136795,-24847.1728515625,-0.385338726895893,0.00017439571044858,1,2,12.9061126708984,4.99373061074255,33.4499999880791,-502.066831511257,-75.0849213222439,1000,-0.000995685905512604,,,,,,,,,,,,,,,,,,,,,1.999307513237,1.99972951412201,-24947.04296875,-24747.302734375,50.4939839708323,5.43438335010995,2.44086742401123,26,1,0,0,1,0.2716064453125,32.2580642700195,1,6,1,1.99944508075714,0,1.9995185136795,,,,,,,,,,,,,,,,,,,,,,,,,,,,,,,,,
,3865584965.97752,2.00035887956619,-30931.88671875,-0.426386783729278,0.00453055033268587,1,2,12.9061126708984,4.9944412445973,33.4499999880791,-555.639686241726,-83.2392884559928,1000,-0.00120867600765338,,,,,,,,,,,,,,,,,,,,,1.99955570697784,2.00116205215454,-30987.017578125,-30876.755859375,50.5819171792457,5.43170311759099,2.42137408256531,26,1,0,0,1,0.271682739257813,31.7693061828613,1,6,1,2.00116205215454,0,2.00035887956619,,,,,,,,,,,,,,,,,,,,,,,,,,,,,,,,,
,3865585028.27814,1.99952870607376,-37173.44140625,-0.463641100052758,0.00479213960426759,1,2,12.9061126708984,4.99443780024747,33.4499999880791,-604.093128735432,-91.1476811802394,1000,-0.00180189165391031,,,,,,,,,,,,,,,,,,,,,1.99947428703308,1.99958312511444,-37248.72265625,-37098.16015625,50.7585652245919,5.43192323688772,2.42493653297424,25,1,68,0,0,0.270538330078125,30.7917900085449,1,6,1,1.99947428703308,0,1.99952870607376,,,,,,,,,,,,,,,,,,,,,,,,,,,,,,,,,
,3865585090.62342,1.9990508556366,-43424.40625,-0.503502119750379,0.00219201921528869,1,2,12.9061126708984,4.99488662936545,33.4499999880791,-656.411237122742,-96.959706396001,1000,-0.00039468007484649,,,,,,,,,,,,,,,,,,,,,1.99896085262299,1.99914085865021,-43509.5234375,-43339.2890625,50.8535330896785,5.43134747562125,2.41472578048706,26,1,0,0,1,0.27313232421875,31.2805480957031,5,6,1,1.99896085262299,0,1.9990508556366,,,,,,,,,,,,,,,,,,,,,,,,,,,,,,,,,
,3865585150.97352,1.99987977743149,-49465.01953125,-0.51124895277295,0.00986008128698328,1,2,12.9061126708984,4.99467630769294,33.4499999880791,-665.524477998243,-104.89102624564,1000,-0.00534437609692827,,,,,,,,,,,,,,,,,,,,,1.99960172176361,2.00015783309937,-49560.203125,-49369.8359375,51.08567675989,5.4318042137851,2.41534209251404,24,1,68,0,0,0.27099609375,30.7917900085449,1,6,1,1.99960172176361,0,1.99987977743149,,,,,,,,,,,,,,,,,,,,,,,,,,,,,,,,,
,3865585211.72205,1.99983143806458,-45075.9296875,-0.505293114991213,0.00591322722910045,1,2,12.9061126708984,4.99439740248101,33.4499999880791,-658.221977246861,-100.243375136865,1000,-0.00266058022245945,,,,,,,,,,,,,,,,,,,,,1.99970781803131,1.99995505809784,-45140.8125,-45011.046875,50.9313051273419,5.4327125597583,2.41394257545471,25,1,68,0,0,0.270156860351562,31.2805480957031,1,6,1,1.99970781803131,0,1.99983143806458,,,,,,,,,,,,,,,,,,,,,,,,,,,,,,,,,
,3865585271.99947,1.99997663497925,-39062.619140625,-0.477894152210646,0.00390769501183035,1,2,12.9061126708984,4.99429193177581,33.4499999880791,-622.83640127645,-92.5980691887247,1000,-0.00082340737157853,,,,,,,,,,,,,,,,,,,,,1.99996876716614,1.99998450279236,-39172.53125,-38952.70703125,50.8683840315438,5.43241241230758,2.42861890792847,26,1,0,0,1,0.270843505859375,31.2805480957031,1,6,1,1.99996876716614,0,1.99997663497925,,,,,,,,,,,,,,,,,,,,,,,,,,,,,,,,,
,3865585334.28444,1.99962478876114,-32844.07421875,-0.441400540066484,0.00356811549099799,1,2,12.9061126708984,4.9941959946487,33.4499999880791,-574.926876288439,-87.7854744970564,1000,-0.00249482683022237,,,,,,,,,,,,,,,,,,,,,1.99943864345551,1.99981093406677,-32933.890625,-32754.2578125,50.6682871306207,5.43256894209069,2.42202210426331,25,1,68,0,0,0.270309448242187,33.7243423461914,1,6,1,1.99981093406677,0,1.99962478876114,,,,,,,,,,,,,,,,,,,,,,,,,,,,,,,,,
,3865585396.7955,1.9992938041687,-26606.283203125,-0.400724562750702,0.000147059841834455,1,2,12.9061126708984,4.99406948387241,33.4499999880791,-522.24921621569,-77.5040405408863,1000,-0.000585661120100301,,,,,,,,,,,,,,,,,,,,,1.99876809120178,1.99981951713562,-26695.994140625,-26516.572265625,50.5213409690053,5.43285088376233,2.42814970016479,26,1,0,0,1,0.277175903320313,31.7693061828613,1,6,1,1.99981951713562,0,1.9992938041687,,,,,,,,,,,,,,,,,,,,,,,,,,,,,,,,,
,3865585455.27017,1.99984687566757,-20766.1875,-0.352145163582457,0.000111174277761516,1,2,12.9061126708984,4.99400147932266,33.4499999880791,-459.014878789116,-67.5207681154139,1000,-6.49234142774221E-5,,,,,,,,,,,,,,,,,,,,,1.99912965297699,2.00056409835815,-20846.0078125,-20686.3671875,50.4416148600438,5.43418113076221,2.42097783088684,26,1,0,0,1,0.277786254882813,31.2805480957031,1,6,1,1.99912965297699,0,1.99984687566757,,,,,,,,,,,,,,,,,,,,,,,,,,,,,,,,,
,3865585517.75441,1.99917459487915,-14527.4243164062,-0.288294464421009,0.000136672383274846,1,2,12.9061126708984,4.9942111954472,33.4499999880791,-375.793793833078,-55.3831531777478,1000,-0.000131354920213889,,,,,,,,,,,,,,,,,,,,,1.99784207344055,2.00050711631775,-14627.201171875,-14427.6474609375,50.1598377788611,5.43214914957569,2.44128346443176,26,1,0,0,1,0.269699096679687,31.7693061828613,1,6,1,2.00050711631775,0,1.99917459487915,,,,,,,,,,,,,,,,,,,,,,,,,,,,,,,,,
,3865585576.45006,1.99890321493149,-8668.58251953125,-0.210802296171311,0.000170000418139144,1,2,12.9061126708984,4.99412374933891,33.4499999880791,-274.799694165788,-40.3306066578114,1000,3.03958140471726E-5,,,,,,,,,,,,,,,,,,,,,1.99862921237946,1.99917721748352,-8723.4755859375,-8613.689453125,50.1313083379091,5.43182759868565,2.43429756164551,26,1,0,0,1,0.274276733398438,31.2805480957031,1,6,1,1.99917721748352,0,1.99890321493149,,,,,,,,,,,,,,,,,,,,,,,,,,,,,,,,,
,3865585634.49471,1.99980533123016,-2868.40710449219,-0.100326450196969,0.000253193998290168,1,2,12.9061126708984,4.99439465631581,33.4499999880791,-130.792118265137,-19.211890724558,1000,2.18041702269953E-6,,,,,,,,,,,,,,,,,,,,,1.99955606460571,2.00005459785461,-2958.29345703125,-2778.52075195313,50.152803122188,5.43018512896191,2.4366991519928,26,1,0,0,1,0.269699096679687,31.2805480957031,1,6,1,1.99955606460571,0,1.99980533123016,,,,,,,,,,,,,,,,,,,,,,,,,,,,,,,,,
,3865585727.4725,2.00034201145172,6427.900390625,0.154572951332622,0.000223609252634486,1,2,12.9061126708984,4.99441400051335,33.4499999880791,201.5145577471,29.5858937208964,1000,-1.41175200484527E-5,,,,,,,,,,,,,,,,,,,,,1.9996190071106,2.00106501579285,6308.03515625,6547.765625,50.1692173210919,5.43130560495633,2.44500827789307,26,1,0,0,1,0.27008056640625,32.2580642700195,1,6,1,1.9996190071106,0,2.00034201145172,,,,,,,,,,,,,,,,,,,,,,,,,,,,,,,,,
,3865585791.80168,1.99942177534103,12859.134765625,0.26165186950366,0.000158496322366624,1,2,12.9061126708984,4.99432911246571,33.4499999880791,341.096942054825,50.1259793040795,1000,1.13404023994438E-5,,,,,,,,,,,,,,,,,,,,,1.99908697605133,1.99975657463074,12779.0576171875,12939.2119140625,50.1856315199957,5.43135045971632,2.44125270843506,26,1,0,0,1,0.27099609375,31.2805480957031,1,6,1,1.99975657463074,0,1.99942177534103,,,,,,,,,,,,,,,,,,,,,,,,,,,,,,,,,
,3865585854.30891,1.99961322546005,19110.4716796875,0.333769276960636,0.000120041846579431,1,2,12.9061126708984,4.99424480374182,33.4499999880791,435.053154833609,64.2659052488796,1000,0.000264189435246504,,,,,,,,,,,,,,,,,,,,,1.99921572208405,2.00001072883606,19000.509765625,19220.43359375,50.3919814490726,5.43273652512695,2.43282771110535,26,1,0,0,1,0.2685546875,32.2580642700195,5,6,1,2.00001072883606,0,1.99961322546005,,,,,,,,,,,,,,,,,,,,,,,,,,,,,,,,,
,3865585916.60734,1.9998140335083,25346.470703125,0.389677386608303,0.000162541155070657,1,2,12.9061126708984,4.99441344043387,33.4499999880791,507.900922171002,75.3744948477775,1000,0.00056936783562138,,,,,,,,,,,,,,,,,,,,,1.99956774711609,2.00006031990051,25241.4921875,25451.44921875,50.2895881130534,5.43222043609897,2.42251443862915,26,1,0,0,1,0.27435302734375,30.7917900085449,1,6,1,2.00006031990051,0,1.9998140335083,,,,,,,,,,,,,,,,,,,,,,,,,,,,,,,,,
,3865585976.29421,1.99970602989197,31322.408203125,0.429518656057267,0.00446602651681493,1,2,12.9061126708984,4.99474963192785,33.4499999880791,559.88448897191,83.0745458084835,1000,0.000616685697034293,,,,,,,,,,,,,,,,,,,,,1.99958300590515,1.99982905387878,31162.140625,31482.67578125,50.6549994457938,5.43146221160284,2.41807699203491,25,1,68,0,0,0.26885986328125,31.2805480957031,1,6,1,1.99982905387878,0,1.99970602989197,,,,,,,,,,,,,,,,,,,,,,,,,,,,,,,,,
,3865586037.50003,2.00012111663818,37455.87890625,0.468843967873646,0.00404678749322738,1,2,12.9061126708984,4.99393248248932,33.4499999880791,611.192757042752,89.3849799691993,1000,-0.000304837889467378,,,,,,,,,,,,,,,,,,,,,1.99994874000549,2.00029349327087,37375.734375,37536.0234375,50.8081986355631,5.43556470746709,2.42473411560059,26,1,0,0,1,0.2734375,31.7693061828613,1,6,1,1.99994874000549,0,2.00012111663818,,,,,,,,,,,,,,,,,,,,,,,,,,,,,,,,,
,3865586099.96075,1.9997336268425,43718.38671875,0.498137600619957,0.00580254814299908,1,2,12.9061126708984,4.9947662311956,33.4499999880791,650.16744668313,90.6696715262788,1000,-0.00363909675552966,,,,,,,,,,,,,,,,,,,,,1.99953150749207,1.99993574619293,43638.203125,43798.5703125,50.9133276713996,5.43288677038798,2.41134452819824,24,1,68,0,0,0.270233154296875,31.2805480957031,1,6,1,1.99993574619293,0,1.9997336268425,,,,,,,,,,,,,,,,,,,,,,,,,,,,,,,,,
,3865586158.29276,1.99795365333557,49560.72265625,0.523031583166599,0.00740161468686406,1,2,12.9061126708984,4.99366857387498,33.4499999880791,682.168600377492,97.0776065741781,1000,-0.00235852016994188,,,,,,,,,,,,,,,,,,,,,1.9975198507309,1.99838745594025,49470.53515625,49650.91015625,51.0415147485535,5.43781861487821,2.41029262542725,24,1,68,0,0,0.273590087890625,31.2805480957031,6,6,1,1.99838745594025,0,1.99795365333557,,,,,,,,,,,,,,,,,,,,,,,,,,,,,,,,,
,3865586717.5337,26.6823215484619,25.484806060791,0.000301585512759543,8.01678944013168E-7,1,5,12.9061126708984,5.00555813670535,33.4499999880791,0.394381760594632,0.058043435423358,1,7.81721202256539E-8,,,,,,,,,,,,,,,,,,,,,26.6823215484619,26.6823215484619,25.484806060791,25.484806060791,50.0855830695341,5.42680713287322,5.78431129455566,65,1,0,0,1,0.274810791015625,30.7917900085449,2,1,1,26.6823215484619,0,26.6823215484619,,,,,,,,,,,,,,,,,,,,,,,,,,,,,,,,,
,3865586904.96711,56.0112228393555,25.484806060791,0.00016134087991612,3.53556443373224E-8,1,5,12.9061126708984,5.0030772922042,33.4799997508526,0.210861874460696,0.0308696803592632,1,-8.10748160460049E-8,,,,,,,,,,,,,,,,,,,,,56.0112228393555,56.0112228393555,25.484806060791,25.484806060791,50.0930085404668,5.43912729963315,6.39450740814209,64,1,64,0,0,0.278472900390625,31.2805480957031,2,1,1,56.0112228393555,0,56.0112228393555,,,,,,,,,,,,,,,,,,,,,,,,,,,,,,,,,
,3865587081.16412,84.1565628051758,25.484806060791,0.000126745445392467,2.75685134798368E-8,1,5,12.9061126708984,5.00131487684414,33.5199981927872,0.165571079496485,0.0242055389789732,1,-8.89293421322869E-8,,,,,,,,,,,,,,,,,,,,,84.1565628051758,84.1565628051758,25.484806060791,25.484806060791,50.1180206530822,5.44497879704069,6.64884614944458,65,1,0,0,1,0.283432006835938,31.2805480957031,2,1,1,84.1565628051758,0,84.1565628051758,,,,,,,,,,,,,,,,,,,,,,,,,,,,,,,,,
,3865587251.25951,112.083358764648,25.484806060791,0.000101735668714551,2.79431061490231E-8,1,5,12.9061126708984,5.00323719138588,33.5999988019466,0.132974611026755,0.0194194513700165,1,-8.68662311724148E-8,,,,,,,,,,,,,,,,,,,,,112.083358764648,112.083358764648,25.484806060791,25.484806060791,50.1012156399188,5.43940514132724,6.77404356002808,63,1,64,0,0,0.279464721679687,31.2805480957031,2,1,1,112.083358764648,0,112.083358764648,,,,,,,,,,,,,,,,,,,,,,,,,,,,,,,,,
,3865587420.12949,140.064468383789,25.484806060791,8.07424190135423E-5,1.8000454054502E-8,1,5,12.9061126708984,5.00425085965026,33.670000731945,0.105568544230287,0.0153931841327937,1,-8.68534921529885E-8,,,,,,,,,,,,,,,,,,,,,140.064468383789,140.064468383789,25.484806060791,25.484806060791,50.1105951821495,5.43382971857641,6.8645133972168,65,1,0,0,1,0.276718139648438,31.2805480957031,2,1,1,140.064468383789,0,140.064468383789,,,,,,,,,,,,,,,,,,,,,,,,,,,,,,,,,
,3865587589.6712,168.013473510742,25.484806060791,6.64599660122124E-5,1.30887080018927E-8,1,5,12.9061126708984,5.0048042026786,33.7500013411045,0.0869102240758934,0.0126575746662842,1,-8.27207464962321E-8,,,,,,,,,,,,,,,,,,,,,168.013473510742,168.013473510742,25.484806060791,25.484806060791,50.1215379814188,5.43211329053063,6.92327165603638,65,1,0,0,1,0.279159545898438,32.2580642700195,2,1,1,168.013473510742,0,168.013473510742,,,,,,,,,,,,,,,,,,,,,,,,,,,,,,,,,
,3865587758.23021,196.116836547852,25.484806060791,5.53211654214721E-5,1.19733900283836E-8,1,5,12.9061126708984,5.00511944585472,33.8600017130375,0.0723495985175995,0.010541866024179,1,-6.51909049014386E-8,,,,,,,,,,,,,,,,,,,,,196.116836547852,196.116836547852,25.484806060791,25.484806060791,50.1676540640534,5.42866082484758,7.01212167739868,63,1,64,0,0,0.27801513671875,31.2805480957031,2,1,1,196.116836547852,0,196.116836547852,,,,,,,,,,,,,,,,,,,,,,,,,,,,,,,,,
,3865587926.88781,224.033996582031,25.484806060791,4.65957589052953E-5,1.0107059461894E-8,1,5,12.9061126708984,5.00684230551395,33.9800007641315,0.0609695554799811,0.00887128786137036,1,-6.42056580897006E-8,,,,,,,,,,,,,,,,,,,,,224.033996582031,224.033996582031,25.484806060791,25.484806060791,50.1551480077457,5.42323023057396,7.16486692428589,64,1,64,0,0,0.272445678710938,31.7693061828613,2,1,1,224.033996582031,0,224.033996582031,,,,,,,,,,,,,,,,,,,,,,,,,,,,,,,,,
,3865588095.62103,252.030731201172,25.484806060791,3.94727127812352E-5,8.81580945670289E-9,1,5,12.9061126708984,5.00697080585681,34.1299995779991,0.0516489083368322,0.00753003114528549,1,-4.32168238509976E-8,,,,,,,,,,,,,,,,,,,,,252.030731201172,252.030731201172,25.484806060791,25.484806060791,50.1649183642361,5.42214925575296,7.50888824462891,63,1,64,0,0,0.271377563476562,31.7693061828613,2,1,1,252.030731201172,0,252.030731201172,,,,,,,,,,,,,,,,,,,,,,,,,,,,,,,,,
,3865588264.45514,280.008483886719,25.484806060791,3.33070592638402E-5,8.32214793259869E-9,1,5,12.9061126708984,5.00816267499463,34.2799983918667,0.0435964596102848,0.00635172189741396,1,-3.96991760547369E-8,,,,,,,,,,,,,,,,,,,,,280.008483886719,280.008483886719,25.484806060791,25.484806060791,50.1864131485149,5.41801101428694,7.84345006942749,64,1,64,0,0,0.2789306640625,31.7693061828613,2,1,1,280.008483886719,0,280.008483886719,,,,,,,,,,,,,,,,,,,,,,,,,,,,,,,,,
,3865589040.32209,293.934295654297,25.2591648101807,4.58318964922137E-5,7.44826850285821E-9,1,5,12.9061126708984,4.98839825272046,34.340001642704,0.0596576328257845,0.00870186466563695,1,-4.70044170411587E-8,,,,,,,,,,,,,,,,,,,,,293.934295654297,293.934295654297,25.2591648101807,25.2591648101807,50.193447805188,5.41285676250255,8.25962257385254,65,1,0,0,1,0.279083251953125,30.7917900085449,2,1,1,293.934295654297,0,293.934295654297,,,,,,,,,,,,,,,,,,,,,,,,,,,,,,,,,
,3865589200.93217,265.860809326172,25.2591648101807,4.84118724524275E-5,8.23570708869218E-9,1,5,12.9061126708984,4.98880179482248,34.2199988663197,0.0630241217106447,0.00918542684819282,1,-5.52805372549087E-8,,,,,,,,,,,,,,,,,,,,,265.860809326172,265.860809326172,25.2591648101807,25.2591648101807,50.1942294337072,5.41439589127024,8.44249725341797,64,1,64,0,0,0.277633666992187,31.7693061828613,2,1,1,265.860809326172,0,265.860809326172,,,,,,,,,,,,,,,,,,,,,,,,,,,,,,,,,
,3865589368.23267,237.936019897461,25.2591648101807,4.00502032301818E-5,1.28096417015638E-8,1,5,12.9061126708984,4.98745647352295,34.0999998152256,0.0521153687036934,0.00762006212091694,1,-2.72767312850137E-8,,,,,,,,,,,,,,,,,,,,,237.936019897461,237.936019897461,25.2591648101807,25.2591648101807,50.1785968633226,5.41951644659034,8.19671154022217,65,1,0,0,1,0.281982421875,31.7693061828613,2,1,1,237.908782958984,0,237.936019897461,,,,,,,,,,,,,,,,,,,,,,,,,,,,,,,,,
,3865589536.23301,209.987060546875,25.2591648101807,3.97572266948777E-5,8.80817756567743E-9,1,5,12.9061126708984,4.98586144266377,34.000001847744,0.0517121685510966,0.00755229509221667,1,-3.37111390077092E-8,,,,,,,,,,,,,,,,,,,,,209.987060546875,209.987060546875,25.2591648101807,25.2591648101807,50.0976983115822,5.42670189671609,8.03521919250488,65,1,0,0,1,0.279083251953125,32.2580642700195,2,1,1,209.987060546875,0,209.987060546875,,,,,,,,,,,,,,,,,,,,,,,,,,,,,,,,,
,3865589704.76567,181.867034912109,25.2591648101807,4.16925693478688E-5,9.31902443606738E-9,1,5,12.9061126708984,4.98428130898553,33.9000001549721,0.0542074095922418,0.00790222684559557,1,-4.62610182673357E-8,,,,,,,,,,,,,,,,,,,,,181.867034912109,181.867034912109,25.2591648101807,25.2591648101807,50.3450837379188,5.43134086362492,7.88322877883911,65,1,0,0,1,0.26947021484375,31.7693061828613,2,1,1,181.867034912109,0,181.867034912109,,,,,,,,,,,,,,,,,,,,,,,,,,,,,,,,,
,3865589872.60473,153.957824707031,25.2591648101807,4.22599405326855E-5,1.02699116455181E-8,1,5,12.9061126708984,4.98321601029649,33.8100008666515,0.0549289058431678,0.00800520367654832,1,-4.85488175278063E-8,,,,,,,,,,,,,,,,,,,,,153.957824707031,153.957824707031,25.2591648101807,25.2591648101807,50.0363404728226,5.43868845204217,7.74508190155029,63,1,64,0,0,0.276260375976562,31.7693061828613,2,1,1,153.957824707031,0,153.957824707031,,,,,,,,,,,,,,,,,,,,,,,,,,,,,,,,,
,3865590041.13351,125.996849060059,25.2591648101807,4.14756765359931E-5,7.74253395517259E-9,1,5,12.9061126708984,4.98491101186017,33.7300002574921,0.0539356215737656,0.00785816629007783,1,-4.93636081012095E-8,,,,,,,,,,,,,,,,,,,,,125.996849060059,125.996849060059,25.2591648101807,25.2591648101807,49.9300389942072,5.42622293693329,7.61933851242065,64,1,64,0,0,0.268478393554687,30.3030319213867,2,1,1,125.996849060059,0,125.996849060059,,,,,,,,,,,,,,,,,,,,,,,,,,,,,,,,,
,3865590209.17384,97.8979110717773,25.2591648101807,3.77067725892492E-5,1.64060854055807E-8,1,5,12.9061126708984,4.98486246558816,33.6499996483326,0.0490329251235832,0.00715001071155054,1,-4.02512485776812E-8,,,,,,,,,,,,,,,,,,,,,97.8979110717773,97.8979110717773,25.2591648101807,25.2591648101807,49.9132339810437,5.43124253368662,7.48112678527832,65,1,0,0,1,0.276565551757813,31.7693061828613,2,1,1,97.8979110717773,0,97.8979110717773,,,,,,,,,,,,,,,,,,,,,,,,,,,,,,,,,
,3865590373.89547,69.8918304443359,25.2591648101807,3.75610755560001E-5,7.83229330139434E-9,1,5,12.9061126708984,4.98620209387531,33.5800014436245,0.048862390192812,0.00712174632577957,1,-4.26526001047672E-8,,,,,,,,,,,,,,,,,,,,,69.8918304443359,69.8918304443359,25.2591648101807,25.2591648101807,50.1105951821495,5.42422134638498,7.28997993469238,65,1,0,0,1,0.274124145507813,31.7693061828613,2,1,1,69.8918304443359,0,69.8918304443359,,,,,,,,,,,,,,,,,,,,,,,,,,,,,,,,,
,3865590538.42623,41.9452857971191,25.2591648101807,3.41894040979725E-5,1.35601150094055E-8,1,5,12.9061126708984,4.98775544908213,33.5199981927872,0.0444944805092245,0.00649368454858149,1,-3.23790461851734E-8,,,,,,,,,,,,,,,,,,,,,41.9452857971191,41.9452857971191,25.2591648101807,25.2591648101807,50.0480649006111,5.41778756959926,6.95722913742065,65,1,0,0,1,0.286483764648438,31.7693061828613,2,1,1,41.9452857971191,0,41.9452857971191,,,,,,,,,,,,,,,,,,,,,,,,,,,,,,,,,
,3865590704.30724,13.9761648178101,25.2591648101807,-6.12980023323107E-6,5.57129205664393E-8,1,5,12.9061126708984,4.9850312709024,33.4799997508526,-0.00797238516231454,-0.0011557928869717,1,1.162227131414E-8,,,,,,,,,,,,,,,,,,,,,13.9761648178101,13.9761648178101,25.2591648101807,25.2591648101807,49.9777183338803,5.42923995208333,5.89035987854004,65,1,0,0,1,0.279998779296875,31.2805480957031,2,1,1,13.9761648178101,0,13.9761648178101,,,,,,,,,,,,,,,,,,,,,,,,,,,,,,,,,
,3865592062.49609,16.0172023773193,25.2591648101807,-4.06195909237158E-6,4.82601263177045E-8,1,5,12.9061126708984,4.98379190420696,33.4599986672401,-0.00528169776502974,-0.000761674613715712,1,1.07428056463543E-8,,,,,,,,,,,,,,,,,,,,,16.0172023773193,16.0172023773193,25.2591648101807,25.2591648101807,50.2469893587553,5.4346556528846,5.30749034881592,65,1,0,0,1,0.279388427734375,31.7693061828613,2,1,1,16.0172023773193,0,16.0172023773193,,,,,,,,,,,,,,,,,,,,,,,,,,,,,,,,,
,3865592241.98308,44.0307502746582,25.2591648101807,3.3816343304392E-5,1.23269246843748E-8,1,5,12.9061126708984,4.9881453586646,33.4700010716915,0.0440140892986181,0.0064215969128052,1,-3.35134777431938E-8,,,,,,,,,,,,,,,,,,,,,44.0307502746582,44.0307502746582,25.2591648101807,25.2591648101807,50.1821141916592,5.41657193903494,6.27770137786865,65,1,0,0,1,0.281524658203125,31.7693061828613,2,1,1,44.0307502746582,0,44.0307502746582,,,,,,,,,,,,,,,,,,,,,,,,,,,,,,,,,
,3865592418.52968,72.0488739013672,25.2591648101807,3.71075668812335E-5,5.98923982202356E-9,1,5,12.9061126708984,4.98335787105447,33.5099995136261,0.048233243144756,0.00703360498185996,1,-3.94576459238851E-8,,,,,,,,,,,,,,,,,,,,,72.0488739013672,72.0488739013672,25.2591648101807,25.2591648101807,50.152803122188,5.43673093754101,6.61486959457398,65,1,0,0,1,0.28411865234375,31.7693061828613,2,1,1,72.0488739013672,0,72.0488739013672,,,,,,,,,,,,,,,,,,,,,,,,,,,,,,,,,
,3865592590.9572,100.018020629883,25.2591648101807,3.64658638232178E-5,5.91711303990897E-9,1,5,12.9061126708984,4.98388314388994,33.5600003600121,0.0474071685353924,0.00690615267096099,1,-4.40402980178048E-8,,,,,,,,,,,,,,,,,,,,,100.018020629883,100.018020629883,25.2591648101807,25.2591648101807,50.1000431971399,5.43369958996491,6.7673864364624,65,1,0,0,1,0.276107788085938,31.7693061828613,2,1,1,100.018020629883,0,100.018020629883,,,,,,,,,,,,,,,,,,,,,,,,,,,,,,,,,
,3865592760.46313,128.090637207031,25.2591648101807,3.56389978630222E-5,6.33660313148593E-9,1,5,12.9061126708984,4.98492829824803,33.6299985647202,0.046345873307095,0.00675143952329847,1,-4.3121820594159E-8,,,,,,,,,,,,,,,,,,,,,128.090637207031,128.090637207031,25.2591648101807,25.2591648101807,50.1856315199957,5.43161549554899,6.86880350112915,65,1,0,0,1,0.269546508789062,31.2805480957031,2,1,1,128.090637207031,0,128.090637207031,,,,,,,,,,,,,,,,,,,,,,,,,,,,,,,,,
,3865592930.26277,156.113784790039,25.2591648101807,3.4258033984479E-5,6.09443762238427E-9,1,5,12.9061126708984,4.98233780434891,33.7099991738796,0.0445199091539462,0.00646874287274343,1,-5.40345596266118E-8,,,,,,,,,,,,,,,,,,,,,156.113784790039,156.113784790039,25.2591648101807,25.2591648101807,50.1957926907457,5.43860512652474,6.94699335098267,65,1,0,0,1,0.275344848632813,32.2580642700195,2,1,1,156.113784790039,0,156.113784790039,,,,,,,,,,,,,,,,,,,,,,,,,,,,,,,,,
,3865593098.41265,184.038269042969,25.2591648101807,3.30143686632454E-5,7.2474306237142E-9,1,5,12.9061126708984,4.98683239523634,33.8100008666515,0.0429560647306273,0.00625558714110721,1,-4.14826918599667E-8,,,,,,,,,,,,,,,,,,,,,184.038269042969,184.038269042969,25.2591648101807,25.2591648101807,50.1391246231015,5.42189787818081,7.01281976699829,64,1,64,0,0,0.277938842773438,31.7693061828613,2,1,1,184.038269042969,0,184.038269042969,,,,,,,,,,,,,,,,,,,,,,,,,,,,,,,,,
,3865593267.58619,212.110931396484,25.2591648101807,3.17870567674708E-5,6.30157338745153E-9,1,5,12.9061126708984,4.98725115565927,33.9299999177456,0.0413639159751437,0.00602463171973784,1,-3.9259299550792E-8,,,,,,,,,,,,,,,,,,,,,212.110931396484,212.110931396484,25.2591648101807,25.2591648101807,50.0679964278515,5.42150797917007,7.11673593521118,63,1,64,0,0,0.2716064453125,31.2805480957031,2,1,1,212.110931396484,0,212.110931396484,,,,,,,,,,,,,,,,,,,,,,,,,,,,,,,,,
,3865593437.18099,240.171798706055,25.2591648101807,3.11042008694483E-5,5.95180041657295E-9,1,5,12.9061126708984,4.98703447802896,34.060001373291,0.0404713531632065,0.00590509953721121,1,-3.05373313187476E-8,,,,,,,,,,,,,,,,,,,,,240.171798706055,240.171798706055,25.2591648101807,25.2591648101807,50.2082987470534,5.42108044328741,7.36434555053711,63,1,64,0,0,0.26763916015625,31.2805480957031,2,1,1,240.171798706055,0,240.171798706055,,,,,,,,,,,,,,,,,,,,,,,,,,,,,,,,,
,3865593604.97374,268.021301269531,25.2591648101807,2.9798590256231E-5,7.03392316480501E-9,1,5,12.9061126708984,4.98753448585821,34.2100001871586,0.0387762101091522,0.00567028603754706,1,-1.9833936825143E-8,,,,,,,,,,,,,,,,,,,,,268.021301269531,268.021301269531,25.2591648101807,25.2591648101807,50.2805993850822,5.41765277428269,7.75670528411865,63,1,64,0,0,0.273208618164062,31.7693061828613,2,1,1,268.021301269531,0,268.021301269531,,,,,,,,,,,,,,,,,,,,,,,,,,,,,,,,,
,3865593774.59631,296.134521484375,25.2591648101807,2.87212090969177E-5,6.74274422074563E-9,1,5,12.9061126708984,4.98834997732444,34.3800000846386,0.0373761994370335,0.00551158386758028,1,1.55022598373084E-8,,,,,,,,,,,,,,,,,,,,,296.134521484375,296.134521484375,25.2591648101807,25.2591648101807,50.3200716253034,5.41420420651408,7.58582735061646,63,1,64,0,0,0.278396606445313,31.7693061828613,2,1,1,296.134521484375,0,296.134521484375,,,,,,,,,,,,,,,,,,,,,,,,,,,,,,,,,
,3865594041.68126,300.004898071289,43517.220703125,0.0212727989073865,6.26361830876802E-6,1,2,12.9061126708984,4.98873026268532,34.3899987637997,27.6935048676211,4.03302831199999,100,-2.66612029894233E-5,,,,,,,,,,,,,,,,,,,,,300.004699707031,300.005096435547,43352.40234375,43682.0390625,50.1692173210919,5.41478216097362,7.54459095001221,26,1,0,0,1,0.280303955078125,29.3255138397217,1,6,1,300.005096435547,0,300.004898071289,,,,,,,,,,,,,,,,,,,,,,,,,,,,,,,,,
,3865594100.86332,300.003265380859,37607.24609375,0.0184603566562895,6.00378681537065E-6,1,2,12.9061126708984,4.98877118561555,34.3899987637997,24.0324673975643,3.49987401210302,100,-2.31321159680021E-5,,,,,,,,,,,,,,,,,,,,,300.003112792969,300.00341796875,37512.5703125,37701.921875,50.1481133510726,5.41498171755931,7.57455968856812,24,1,68,0,0,0.277862548828125,31.7693061828613,1,6,1,300.00341796875,0,300.003265380859,,,,,,,,,,,,,,,,,,,,,,,,,,,,,,,,,
,3865594163.3178,300.003356933594,31371.685546875,0.015468242066256,5.76408274119255E-6,1,2,12.9061126708984,4.98906436172228,34.3899987637997,20.1380316540993,2.93853840090576,100,-1.50089747064466E-5,,,,,,,,,,,,,,,,,,,,,300.003234863281,300.003479003906,31281.8671875,31461.50390625,50.2004824618611,5.41330389749497,7.6544828414917,26,1,0,0,1,0.282669067382813,31.2805480957031,1,6,1,300.003234863281,0,300.003356933594,,,,,,,,,,,,,,,,,,,,,,,,,,,,,,,,,
,3865594225.73103,300.00260925293,25137.2333984375,0.0124743436311371,5.75906071990583E-6,1,2,12.9061126708984,4.98892671537037,34.3899987637997,16.2400003075748,2.36737531555157,100,-1.38812181170358E-5,,,,,,,,,,,,,,,,,,,,,300.002563476562,300.002655029297,25042.326171875,25232.140625,50.2122068896495,5.41444281450111,7.75223731994629,25,1,68,0,0,0.285568237304687,31.7693061828613,1,6,1,300.002655029297,0,300.00260925293,,,,,,,,,,,,,,,,,,,,,,,,,,,,,,,,,
,3865594290.2144,300.001205444336,18703.1728515625,0.00937953147834131,5.6394941312689E-6,1,2,12.9061126708984,4.98919288781933,34.3899987637997,12.2124689513341,1.77606591524842,100,-1.35951356411646E-5,,,,,,,,,,,,,,,,,,,,,300.000823974609,300.001586914063,18613.19921875,18793.146484375,50.2094711898322,5.41320734608887,7.90256214141846,26,1,0,0,1,0.277481079101562,31.7693061828613,1,6,1,300.001586914063,0,300.001205444336,,,,,,,,,,,,,,,,,,,,,,,,,,,,,,,,,
,3865594350.97618,300.001190185547,12632.767578125,0.00647494049220203,5.23786399890989E-6,1,2,12.9061126708984,4.98920001114915,34.3899987637997,8.43092131679253,1.22394631567994,100,-1.10150052920624E-5,,,,,,,,,,,,,,,,,,,,,300.001098632812,300.001281738281,12572.8603515625,12692.6748046875,50.2837258991592,5.41354818924497,8.04874706268311,26,1,0,0,1,0.282745361328125,31.7693061828613,1,6,1,300.001098632812,0,300.001190185547,,,,,,,,,,,,,,,,,,,,,,,,,,,,,,,,,
,3865594411.24944,300.002532958984,6611.9912109375,0.00355748584089559,5.2795371067894E-6,1,2,12.9061126708984,4.98902991514262,34.3899987637997,4.6329367746102,0.665555692357125,100,-1.13352057016906E-5,,,,,,,,,,,,,,,,,,,,,300.002319335937,300.002746582031,6517.12841796875,6706.85400390625,50.2032181616784,5.41487573827893,8.21978569030762,26,1,0,0,1,0.28350830078125,32.7468223571777,1,6,1,300.002319335937,0,300.002532958984,,,,,,,,,,,,,,,,,,,,,,,,,,,,,,,,,
,3865594469.84154,300.000747680664,755.9072265625,0.000619315163406291,7.00503575357834E-6,1,2,12.9061126708984,4.98929122065902,34.3899987637997,0.810904440495422,0.0865565250368511,100,-2.44939341171039E-5,,,,,,,,,,,,,,,,,,,,,300.000610351562,300.000885009766,700.951293945313,810.863159179688,50.2938870699092,5.4135149332734,8.38363170623779,24,1,68,0,0,0.275344848632813,31.7693061828613,1,6,1,300.000885009766,0,300.000747680664,,,,,,,,,,,,,,,,,,,,,,,,,,,,,,,,,
,3865594533.31816,300.001358032227,-5586.41259765625,-0.00308492291552937,5.47921199917613E-6,1,2,12.9061126708984,4.98935550793125,34.3899987637997,-4.01559017814392,-0.592805754436233,100,-2.15922265520446E-6,,,,,,,,,,,,,,,,,,,,,300.001220703125,300.001495361328,-5746.3916015625,-5426.43359375,50.2313567883707,5.41294719178708,8.54151248931885,26,1,0,0,1,0.276947021484375,31.7693061828613,1,6,1,300.001495361328,0,300.001358032227,,,,,,,,,,,,,,,,,,,,,,,,,,,,,,,,,
,3865594608.51191,300.001373291016,-13106.86328125,-0.0066835551844534,5.52510536869428E-6,1,2,12.9061126708984,4.98955567590953,34.400001168251,-8.7007433099685,-1.28176775451513,10,-2.65661946555897E-6,,,,,,,,,,,,,,,,,,,,,300.001098632812,300.001647949219,-13196.8056640625,-13016.9208984375,50.2231496889188,5.41230347519342,8.82318210601807,26,1,0,0,1,0.27740478515625,32.2580642700195,1,6,1,300.001098632812,0,300.001373291016,,,,,,,,,,,,,,,,,,,,,,,,,,,,,,,,,
,3865594683.01972,299.999603271484,-20562.02734375,-0.0102952182336184,5.63851612669693E-6,1,2,12.9061126708984,4.98948941383561,34.3899987637997,-13.4029444841472,-1.96934474080463,100,-2.2963637850904E-7,,,,,,,,,,,,,,,,,,,,,299.999389648438,299.999816894531,-20657.072265625,-20466.982421875,50.2235405031784,5.41251582164123,8.90326976776123,26,1,0,0,1,0.284271240234375,31.7693061828613,1,6,1,299.999389648438,0,299.999603271484,,,,,,,,,,,,,,,,,,,,,,,,,,,,,,,,,
,3865594743.85873,299.999267578125,-26644.5791015625,-0.013209376575847,5.54165573091428E-6,1,2,12.9061126708984,4.98925017112063,34.3899987637997,-17.1973286099056,-2.5149634074787,100,8.65684320500541E-6,,,,,,,,,,,,,,,,,,,,,299.999237060547,299.999298095703,-26699.591796875,-26589.56640625,50.2211956176207,5.41283560912045,8.86556625366211,26,1,0,0,1,0.283737182617187,30.7917900085449,1,6,1,299.999298095703,0,299.999267578125,,,,,,,,,,,,,,,,,,,,,,,,,,,,,,,,,
,3865594806.04084,300.001419067383,-32875.419921875,-0.0162101705364474,6.3578862274314E-6,1,2,12.9061126708984,4.98920853316221,34.3899987637997,-21.1027179234458,-3.09378715042646,100,4.83752911044489E-6,,,,,,,,,,,,,,,,,,,,,300.001251220703,300.001586914063,-32960.53125,-32790.30859375,50.2348741167072,5.41312981496134,8.81989479064941,24,1,68,0,0,0.28350830078125,31.7693061828613,1,6,1,300.001586914063,0,300.001419067383,,,,,,,,,,,,,,,,,,,,,,,,,,,,,,,,,
,3865594866.35847,300.000686645508,-38916.509765625,-0.0191128071666487,5.60592074576261E-6,1,2,12.9061126708984,4.98919943386361,34.3899987637997,-24.8811117709143,-3.649473289501,100,4.38734035136571E-6,,,,,,,,,,,,,,,,,,,,,300.000640869141,300.000732421875,-39011.6875,-38821.33203125,50.1543663792265,5.4133621438325,8.79336929321289,26,1,0,0,1,0.283432006835938,32.2580642700195,1,6,1,300.000640869141,0,300.000686645508,,,,,,,,,,,,,,,,,,,,,,,,,,,,,,,,,
,3865594935.13248,299.999298095703,-45808.841796875,-0.0223977593313918,5.40323132665269E-6,1,2,12.9061126708984,4.98928051624716,34.3899987637997,-29.1582428248004,-4.27609733837789,100,5.69062029900395E-6,,,,,,,,,,,,,,,,,,,,,299.999237060547,299.999359130859,-45873.99609375,-45743.6875,50.056272000063,5.41239177728999,8.75283145904541,26,1,0,0,1,0.283737182617187,31.2805480957031,1,6,1,299.999237060547,0,299.999298095703,,,,,,,,,,,,,,,,,,,,,,,,,,,,,,,,,
,3865595008.76196,300.000625610352,-47465.916015625,-0.0231961458974643,5.88429312617992E-6,1,2,12.9061126708984,4.98934303275668,34.3899987637997,-30.2044907651859,-4.38539510157686,100,3.90819266067217E-5,,,,,,,,,,,,,,,,,,,,,300.000518798828,300.000732421875,-47625.5625,-47306.26953125,50.1164573960438,5.41195764095542,8.72689914703369,24,1,68,0,0,0.283203125,31.2805480957031,1,6,1,300.000732421875,0,300.000625610352,,,,,,,,,,,,,,,,,,,,,,,,,,,,,,,,,
,3865595065.85951,300.000183105469,-41767.4296875,-0.0204846312279624,6.2730415402931E-6,1,2,12.9061126708984,4.98912065297406,34.3899987637997,-26.6703570766229,-3.88415853998375,100,2.55740392597924E-5,,,,,,,,,,,,,,,,,,,,,299.999938964844,300.000427246094,-41857.38671875,-41677.47265625,50.1938386194476,5.41286997247371,8.71509838104248,26,1,0,0,1,0.284576416015625,32.2580642700195,1,6,1,300.000427246094,0,300.000183105469,,,,,,,,,,,,,,,,,,,,,,,,,,,,,,,,,
,3865595128.57676,300.000503540039,-35508.93359375,-0.0174929233991864,5.88341823236413E-6,1,2,12.9061126708984,4.98919656681856,34.3899987637997,-22.7758610046812,-3.31608571303219,100,2.25120300044075E-5,,,,,,,,,,,,,,,,,,,,,300.00048828125,300.000518798828,-35568.81640625,-35449.05078125,50.1563204505245,5.41347905584129,8.68702983856201,26,1,0,0,1,0.282745361328125,31.7693061828613,1,6,1,300.000518798828,0,300.000503540039,,,,,,,,,,,,,,,,,,,,,,,,,,,,,,,,,
,3865595188.87666,300.001068115234,-29490.384765625,-0.0145956047787449,5.68337034092184E-6,1,2,12.9061126708984,4.9890806156847,34.3899987637997,-19.0021732568692,-2.77184093645434,100,1.48791327287765E-5,,,,,,,,,,,,,,,,,,,,,300.000762939453,300.001373291016,-29600.197265625,-29380.572265625,50.1766427920245,5.4138225216918,8.67490768432617,26,1,0,0,1,0.283355712890625,31.7693061828613,1,6,1,300.001373291016,0,300.001068115234,,,,,,,,,,,,,,,,,,,,,,,,,,,,,,,,,
,3865595249.13315,300.000534057617,-23470.96875,-0.0116953361410451,5.99394983155396E-6,1,2,12.9061126708984,4.98895118817854,34.3899987637997,-15.2262554892074,-2.2173830239468,100,1.46798183516237E-5,,,,,,,,,,,,,,,,,,,,,300.000335693359,300.000732421875,-23560.94921875,-23380.98828125,50.1840682629572,5.41456435284299,8.66505432128906,25,1,68,0,0,0.283584594726562,31.7693061828613,1,6,1,300.000732421875,0,300.000534057617,,,,,,,,,,,,,,,,,,,,,,,,,,,,,,,,,
,3865595311.56499,299.999694824219,-17242.220703125,-0.0086951071229702,5.50734258997042E-6,1,2,12.9061126708984,4.98891211296669,34.3899987637997,-11.3203105051277,-1.64715590892316,100,1.19734650407736E-5,,,,,,,,,,,,,,,,,,,,,299.999420166016,299.999969482422,-17332.013671875,-17152.427734375,50.1879764055534,5.41487883650348,8.64277935028076,26,1,0,0,1,0.277557373046875,31.7693061828613,1,6,1,299.999969482422,0,299.999694824219,,,,,,,,,,,,,,,,,,,,,,,,,,,,,,,,,
,3865595372.44099,299.999603271484,-11161.8002929688,-0.00578563803917056,5.19816015157296E-6,1,2,12.9061126708984,4.98900270427118,34.3899987637997,-7.53318772817177,-1.09212601949074,100,1.09655333870902E-5,,,,,,,,,,,,,,,,,,,,,299.999420166016,299.999786376953,-11281.671875,-11041.9287109375,50.2630127433996,5.41482869357297,8.6289529800415,26,1,0,0,1,0.278244018554687,31.7693061828613,1,6,1,299.999420166016,0,299.999603271484,,,,,,,,,,,,,,,,,,,,,,,,,,,,,,,,,
,3865595436.62896,300.000091552734,-4751.56274414063,-0.00265654651404348,5.44674544088679E-6,1,2,12.9061126708984,4.98907907697008,34.3899987637997,-3.46079962590427,-0.489425939202364,100,1.42903352906959E-5,,,,,,,,,,,,,,,,,,,,,300,300.000183105469,-4826.50634765625,-4676.619140625,50.2176782892842,5.41421646157254,8.62178039550781,26,1,0,0,1,0.277252197265625,31.2805480957031,1,6,1,300,0,300.000091552734,,,,,,,,,,,,,,,,,,,,,,,,,,,,,,,,,
,3865595499.24834,299.999603271484,1509.45770263672,0.00100636583742903,5.75536061785627E-6,1,2,12.9061126708984,4.98910464204247,34.3899987637997,1.30783099161175,0.207294364284697,100,1.13997949323663E-5,,,,,,,,,,,,,,,,,,,,,299.999267578125,299.999938964844,1389.51733398438,1629.39807128906,50.2356557452265,5.41429624125222,8.61393547058105,26,1,0,0,1,0.2777099609375,31.2805480957031,1,6,1,299.999938964844,0,299.999603271484,,,,,,,,,,,,,,,,,,,,,,,,,,,,,,,,,
,3865595561.44645,300.000823974609,7728.79711914062,0.00410433759791814,5.31647734088065E-6,1,2,12.9061126708984,4.98923094088417,34.3899987637997,5.34289279912748,0.785025561921294,100,7.22589279811935E-8,,,,,,,,,,,,,,,,,,,,,300.000671386719,300.0009765625,7628.6318359375,7828.96240234375,50.2716106571111,5.4135815659087,8.59599304199219,26,1,0,0,1,0.282745361328125,31.2805480957031,1,6,1,300.0009765625,0,300.000823974609,,,,,,,,,,,,,,,,,,,,,,,,,,,,,,,,,
,3865595621.81221,299.999923706055,13764.5415039062,0.00702064965149064,5.34618049113923E-6,1,2,12.9061126708984,4.98913908328207,34.3899987637997,9.13923366108371,1.34130801234772,10,-1.0117852788636E-6,,,,,,,,,,,,,,,,,,,,,299.999847412109,300,13669.7099609375,13859.373046875,50.2200231748419,5.41371041387006,8.59548282623291,25,1,68,0,0,0.277633666992187,32.7468223571777,1,6,1,299.999847412109,0,299.999923706055,,,,,,,,,,,,,,,,,,,,,,,,,,,,,,,,,
,3865595706.66734,300.000518798828,22251.4833984375,0.0110988388539049,5.31634979420089E-6,1,2,12.9061126708984,4.9892026544028,34.3899987637997,14.4496264024955,2.11169881405231,100,-8.35395358419486E-6,,,,,,,,,,,,,,,,,,,,,300.00048828125,300.000549316406,22141.49609375,22361.470703125,50.1997008333418,5.41421671904914,8.58274364471436,26,1,0,0,1,0.276947021484375,31.7693061828613,1,6,1,300.000518798828,0,300.000518798828,,,,,,,,,,,,,,,,,,,,,,,,,,,,,,,,,
,3865595766.87746,299.999145507812,28276.998046875,0.0140027813903421,5.59001476700758E-6,1,2,12.9061126708984,4.9891720163916,34.3899987637997,18.2302471930959,2.66335463510839,100,-1.11805048563552E-5,,,,,,,,,,,,,,,,,,,,,299.999084472656,299.999206542969,28186.84765625,28367.1484375,50.2254945744765,5.41445083667091,8.57482814788818,26,1,0,0,1,0.284652709960938,31.2805480957031,1,6,1,299.999206542969,0,299.999145507812,,,,,,,,,,,,,,,,,,,,,,,,,,,,,,,,,
,3865595829.29671,300.001113891602,34534.802734375,0.0170102330194093,5.71254182938796E-6,1,2,12.9061126708984,4.98921350271506,34.3899987637997,22.1461013350925,3.23413007474471,100,-1.45690164767772E-5,,,,,,,,,,,,,,,,,,,,,300.0009765625,300.001251220703,34439.625,34629.98046875,50.147722536813,5.41390616538318,8.56697273254394,26,1,0,0,1,0.283737182617187,32.2580642700195,1,6,1,300.001251220703,0,300.001113891602,,,,,,,,,,,,,,,,,,,,,,,,,,,,,,,,,
,3865595904.99363,299.999969482422,42115.4296875,0.0205942911669681,5.51700388514011E-6,1,2,12.9061126708984,4.98907797341087,34.3899987637997,26.8108969763142,3.91791938295236,100,-1.57127884295612E-5,,,,,,,,,,,,,,,,,,,,,299.999969482422,299.999969482422,42115.4296875,42115.4296875,50.1082502965918,5.41425685490947,8.55318927764893,26,1,0,0,1,0.277175903320313,31.2805480957031,1,6,1,299.999969482422,0,299.999969482422,,,,,,,,,,,,,,,,,,,,,,,,,,,,,,,,,
,3865595962.37309,299.999221801758,47872.609375,0.0234027421249254,5.99579837035482E-6,1,2,12.9061126708984,4.98909294074315,34.3899987637997,30.4656325241425,4.46314773461645,100,-9.46548246182865E-6,,,,,,,,,,,,,,,,,,,,,299.999206542969,299.999237060547,47787.4609375,47957.7578125,50.0996523828803,5.41438736184991,8.5549955368042,26,1,0,0,1,0.284500122070313,31.7693061828613,1,6,1,299.999237060547,0,299.999221801758,,,,,,,,,,,,,,,,,,,,,,,,,,,,,,,,,
,3865595986.45628,299.999465942383,50000.18359375,0.0244327441211751,1.60612064581998E-6,1,2,12.9061126708984,4.98920293207196,34.3899987637997,31.8074822936227,4.65964596904806,100,-9.9420776525006E-6,,,,,,,,,,,,,,,,,,,,,299.999298095703,299.999633789063,50000.15234375,50000.21484375,50.0984799401015,5.41384410074187,8.54401111602783,26,1,0,0,1,0.278854370117187,31.7693061828613,1,4,1,299.999298095703,0,299.999465942383,,,,,,,,,,,,,,,,,,,,,,,,,,,,,,,,,