File: LT data/Bridport/CREECH-1/331_CR_FULL_SEQUENCE.dat
[Header]
; MPMS3 Data File (default extension .dat)
; Copyright (c) 2007, Quantum Design, Inc. All rights reserved.
TITLE,
FILEOPENTIME,3872910347.70639,09/21/2022,10:37 am
BYAPP,MPMS3 w/ AC,1.0,1.1
INFO,MPMS3 Measurement Release 1.1.16 Build 424, MultiVu Release 2.3.4.19,APPNAME
INFO,Linear Motor Servo Controller,MOTOR_MODULE_NAME
INFO,3101-100 N0,MOTOR_HW_VERSION
INFO,MMC1047,MOTOR_SERIAL_NUMBER
INFO,01.04.28,MOTOR_SOFTWARE_VERSION
INFO,Quantum Design Squid Module,SQUID_MODULE_NAME
INFO,3101-501 B0,SQUID_HW_VERSION
INFO,SQM278,SQUID_SERIAL_NUMBER
INFO,01.03.04,SQUID_SOFTWARE_VERSION
INFO,Quantum Design VSM Oven,OVEN_MODULE_NAME
INFO,3101-201 A3,OVEN_HW_VERSION
INFO,OVB323,OVEN_SERIAL_NUMBER
INFO,01.07.07,OVEN_SOFTWARE_VERSION
INFO,SQUID AC,AC_MODULE_NAME
INFO,3101-401 G0,AC_HW_VERSION
INFO,SAC258,AC_SERIAL_NUMBER
INFO,SQUID AC 00.95.07,AC_SOFTWARE_VERSION
INFO,TCI127,COIL_SERIAL_NUMBER
INFO,0,MOMENT_UNITS
INFO,sndst,SAMPLE_MATERIAL
INFO,,SAMPLE_COMMENT
INFO,,SAMPLE_MASS
INFO,,SAMPLE_VOLUME
INFO,,SAMPLE_MOLECULAR_WEIGHT
INFO,,SAMPLE_SIZE
INFO,,SAMPLE_SHAPE
INFO,Straw,SAMPLE_HOLDER
INFO,Standard,SAMPLE_HOLDER_DETAIL
INFO,61.51,SAMPLE_OFFSET
DATATYPE,COMMENT,1
DATATYPE,TIME,2
STARTUPAXIS,X,2
STARTUPAXIS,Y1,5
FIELDGROUP, VSM,2,3,4,5,6,8,9,10,11,14,15
FIELDGROUP, DC, 2,3,4,14,56,57,58,59,60,61,62,63,64,65,66,67,68,69
FIELDGROUP, AC, 2,3,4,11,16,17,18,19,20,21,22,23,24,25,26,27,28,29,30
STARTUPGROUP, All
[Data]
Comment,Time Stamp (sec),Temperature (K),Magnetic Field (Oe),Moment (emu),M. Std. Err. (emu),Transport Action,Averaging Time (sec),Frequency (Hz),Peak Amplitude (mm),Center Position (mm),Lockin Signal' (V),Lockin Signal (V),Range,M. Quad. Signal (emu),AC Moment (emu),AC M. Std Err. (emu),AC Phase (deg),AC Phase Std. Err. (deg),AC Susceptibility (emu/Oe),AC Suscept. Std Err. (emu/Oe),AC X' (emu/Oe),AC X' Std Err. (emu/Oe),AC X'' (emu/Oe),AC X'' Std Err. (emu/Oe),AC Drive (Oe),AC Frequency (Hz),AC Averaging Time (sec),AC Cycles,AC Range,AC Measure Type,AC Signal' (V),AC Signal'' (V),AC Trim Coil Ratio,AC Trim Coil Phase,Min. Temperature (K),Max. Temperature (K),Min. Field (Oe),Max. Field (Oe),Mass (grams),Motor Lag (deg),Pressure (Torr),Measure Count,Measurement Number,SQUID Status (code),Motor Status (code),Measure Status (code),Motor Current (amps),Motor Temp. (C),Temp. Status (code),Field Status (code),Chamber Status (code),Chamber Temp (K),Redirection State,Evercool Status,Average Temp (K),Rotation Angle (deg),Rotator state,DC Moment Fixed Ctr (emu),DC Moment Err Fixed Ctr (emu),DC Moment Free Ctr (emu),DC Moment Err Free Ctr (emu),DC Fixed Fit,DC Free Fit,DC Calculated Center (mm),DC Calculated Center Err (mm),DC Scan Length (mm),DC Scan Time (s),DC Number of Points,DC Squid Drift,DC Min V (V),DC Max V (V),DC Scans per Measure,Map 01,Map 02,Map 03,Map 04,Map 05,Map 06,Map 07,Map 08,Map 09,Map 10,Map 11,Map 12,Map 13,Map 14,Map 15,Map 16
"FC",3872910578.43662
,3872911454.07985,86.2277374267578,49999.51953125,0.0844398427004971,2.0571836540494E-5,1,2,13.1008939743042,4.99482607247745,36.7499999701977,97.9820159073427,14.4169692971858,100,4.84237005336571E-5,,,,,,,,,,,,,,,,,,,,,86.2277374267578,86.2277374267578,49999.51953125,49999.51953125,52.5098039219286,5.72138499134646,7.38459491729736,26,1,0,0,1,0.2996826171875,32.7468223571777,2,1,1,86.2277374267578,0,2084573184,86.2277374267578,,,,,,,,,,,,,,,,,,,,,,,,,,,,,,,,,
,3872911589.97381,63.4826354980469,49999.51953125,0.118491984187499,4.41597151477531E-5,1,2,13.1008939743042,4.99564135949788,36.6900004446506,137.543870381683,20.1186985477407,1000,-3.27086719457273E-5,,,,,,,,,,,,,,,,,,,,,63.3247947692871,63.6404762268066,49999.51953125,49999.51953125,52.6899692956113,5.71854609133713,7.20514726638794,26,1,0,0,1,0.300216674804687,32.7468223571777,2,1,1,63.3247947692871,0,2084573184,63.4826354980469,,,,,,,,,,,,,,,,,,,,,,,,,,,,,,,,,
,3872911663.43867,50.954662322998,49999.51953125,0.148621203943803,0.00025178864889279,1,2,13.1008939743042,4.99622830853315,36.6499982774258,172.534027679567,25.3190318522147,1000,2.83638670834363E-5,,,,,,,,,,,,,,,,,,,,,50.8016777038574,51.1076469421387,49999.51953125,49999.51953125,52.644634841496,5.71579024070741,7.05250310897827,26,1,0,0,1,0.298233032226562,31.7693061828613,2,1,1,50.8016777038574,0,2084573184,50.954662322998,,,,,,,,,,,,,,,,,,,,,,,,,,,,,,,,,
,3872911726.91944,40.1249885559082,49999.51953125,0.186442636660668,7.63571932753142E-5,1,2,13.1008939743042,4.9965766834943,36.6300009191036,216.454869424434,31.8138448678191,1000,7.73312400455201E-5,,,,,,,,,,,,,,,,,,,,,39.9532623291016,40.2967147827148,49999.51953125,49999.51953125,52.7173262937844,5.71463514528458,6.86852645874023,26,1,0,0,1,0.296630859375,32.7468223571777,2,1,1,39.9532623291016,0,2084573184,40.1249885559082,,,,,,,,,,,,,,,,,,,,,,,,,,,,,,,,,
,3872911790.41885,29.3349628448486,49999.51953125,0.234668518691707,0.00575676436497203,1,2,13.1008939743042,4.99672408526985,36.6099998354912,272.5267679431,39.555334345201,1000,-0.00032402877263909,,,,,,,,,,,,,,,,,,,,,29.146692276001,29.5232334136963,49999.51953125,49999.51953125,52.636427742044,5.7143928514107,6.56499004364014,26,1,0,0,1,0.299911499023438,31.7693061828613,2,1,1,29.146692276001,0,2084573184,29.3349628448486,,,,,,,,,,,,,,,,,,,,,,,,,,,,,,,,,
,3872911853.92729,18.763692855835,49999.51953125,0.311079357735319,0.000254850503314784,1,2,13.1008939743042,4.99689667403606,36.5899987518787,361.117273727269,53.5627005905383,1000,0.000539459461549026,,,,,,,,,,,,,,,,,,,,,18.621129989624,18.9062557220459,49999.51953125,49999.51953125,52.6755091680056,5.71440088078737,6.00482940673828,26,1,0,0,1,0.299072265625,33.2355842590332,2,1,1,18.621129989624,0,2084573184,18.763692855835,,,,,,,,,,,,,,,,,,,,,,,,,,,,,,,,,
,3872911917.47954,9.29226541519165,49999.51953125,0.40139833641502,0.000146789942353005,1,2,13.1008939743042,4.99702839502583,36.5899987518787,466.018080129145,68.866988202329,1000,0.000481056025604214,,,,,,,,,,,,,,,,,,,,,9.18374156951904,9.40078926086426,49999.51953125,49999.51953125,53.0874273976402,5.71422879997307,4.80067777633667,26,1,0,0,1,0.297012329101562,33.2355842590332,6,1,1,9.18374156951904,0,2084573184,9.29226541519165,,,,,,,,,,,,,,,,,,,,,,,,,,,,,,,,,
,3872911980.97933,2.00023531913757,49999.51953125,0.471052006928115,7.42578931699015E-5,1,2,13.1008939743042,4.9969339694961,36.5899987518787,546.904761337041,80.5820075827158,1000,0.00036373091885524,,,,,,,,,,,,,,,,,,,,,1.99975943565369,2.00071120262146,49999.51953125,49999.51953125,53.6912354287461,5.71834355643082,2.52094745635986,26,1,0,0,1,0.297775268554687,32.7468223571777,5,1,1,1.99975943565369,0,2084573184,2.00023531913757,,,,,,,,,,,,,,,,,,,,,,,,,,,,,,,,,
,3872912382.12356,7.70040655136108,26.4648857116699,0.00278906816940998,1.03285400170672E-5,1,5,13.1008939743042,4.99677640035556,36.5899987518787,3.23816488400597,0.476277873688815,100,1.44579503168468E-6,,,,,,,,,,,,,,,,,,,,,7.35615921020508,8.04465389251709,26.4648857116699,26.4648857116699,52.6043809727556,5.71357829457014,4.38087463378906,66,1,0,0,1,0.298614501953125,32.2580642700195,6,1,1,8.04465389251709,0,2084573184,7.70040655136108,,,,,,,,,,,,,,,,,,,,,,,,,,,,,,,,,
,3872912584.99863,39.0246963500977,26.4648857116699,0.000100540441340863,1.10534708076015E-7,1,5,13.1008939743042,4.99662980603618,36.5899987518787,0.116734457615731,0.0171016238547743,1,-5.204454741538E-9,,,,,,,,,,,,,,,,,,,,,39.0246963500977,39.0246963500977,26.4648857116699,26.4648857116699,52.6411175131594,5.71457212619663,6.29230833053589,66,1,0,0,1,0.299530029296875,33.2355842590332,2,1,1,39.0246963500977,0,2084573184,39.0246963500977,,,,,,,,,,,,,,,,,,,,,,,,,,,,,,,,,
,3872912788.00057,71.0751953125,26.4648857116699,6.56040907534658E-5,1.78468879481174E-8,1,5,13.1008939743042,4.99525995438266,36.6300009191036,0.0761410167011411,0.0111593426794112,1,5.40553248851666E-10,,,,,,,,,,,,,,,,,,,,,71.0751953125,71.0751953125,26.4648857116699,26.4648857116699,52.6661296257748,5.72151575505375,6.6949028968811,66,1,0,0,1,0.299911499023438,33.7243423461914,2,1,1,71.0751953125,0,2084573184,71.0751953125,,,,,,,,,,,,,,,,,,,,,,,,,,,,,,,,,
,3872912984.63258,103.002914428711,26.4648857116699,5.04162498532186E-5,3.3263877183658E-8,1,5,13.1008939743042,4.99334740179267,36.6999991238117,0.0584784459719021,0.00859845593392295,1,2.38487461082949E-8,,,,,,,,,,,,,,,,,,,,,103.002914428711,103.002914428711,26.4648857116699,26.4648857116699,52.7700862188325,5.7268406311987,6.89207363128662,66,1,0,0,1,0.30303955078125,33.7243423461914,2,1,1,103.002914428711,0,2084574016,103.002914428711,,,,,,,,,,,,,,,,,,,,,,,,,,,,,,,,,
,3872913178.33011,135.032440185547,26.4648857116699,3.70246846294622E-5,1.72139306454567E-8,1,5,13.1008939743042,4.99152834212634,36.7700010538101,0.0429309942026652,0.00626010538074145,1,-2.66526386898692E-8,,,,,,,,,,,,,,,,,,,,,135.032440185547,135.032440185547,26.4648857116699,26.4648857116699,52.7915810031113,5.73364893336236,7.00437116622925,66,1,0,0,1,0.29632568359375,32.2580642700195,2,1,1,135.032440185547,0,2084573920,135.032440185547,,,,,,,,,,,,,,,,,,,,,,,,,,,,,,,,,
,3872913370.88162,167.029739379883,26.4648857116699,2.93732341067068E-5,8.04772290278156E-9,1,5,13.1008939743042,4.9886639347043,36.8800014257431,0.0340311654908784,0.00496522771628671,1,-1.87138040201324E-8,,,,,,,,,,,,,,,,,,,,,167.029739379883,167.029739379883,26.4648857116699,26.4648857116699,52.9103885380344,5.74022092033837,7.08963441848755,66,1,0,0,1,0.29388427734375,34.2131004333496,2,1,1,167.029739379883,0,2084574176,167.029739379883,,,,,,,,,,,,,,,,,,,,,,,,,,,,,,,,,
,3872913563.94554,199.048675537109,26.4648857116699,2.31130078988342E-5,6.1391205618442E-9,1,5,13.1008939743042,4.98680244546493,37.0000004768372,0.0267627542813226,0.0039148744392275,1,-6.16377521528703E-9,,,,,,,,,,,,,,,,,,,,,199.048675537109,199.048675537109,26.4648857116699,26.4648857116699,53.2808804561499,5.74535386507067,7.1839919090271,64,1,64,0,0,0.298614501953125,34.7018585205078,2,1,1,199.048675537109,0,2084574080,199.048675537109,,,,,,,,,,,,,,,,,,,,,,,,,,,,,,,,,
,3872913757.53624,231.041458129883,26.4648857116699,1.84234441361046E-5,6.57531156593224E-9,1,5,13.1008939743042,4.9865235129688,37.1499992907047,0.0213308526064126,0.00312128426020699,1,-4.07415706047296E-9,,,,,,,,,,,,,,,,,,,,,231.010513305664,231.072402954102,26.4648857116699,26.4648857116699,52.8025238023806,5.74847126812675,7.41761684417725,66,1,0,0,1,0.294952392578125,35.190616607666,2,1,1,231.072402954102,0,2084574336,231.041458129883,,,,,,,,,,,,,,,,,,,,,,,,,,,,,,,,,
,3872913950.29067,263.130615234375,26.4648857116699,1.48314473913523E-5,6.38515509987597E-9,1,5,13.1008939743042,4.98782303477239,37.3100005090237,0.0171793153720999,0.00250654368651016,1,-9.41464198509077E-9,,,,,,,,,,,,,,,,,,,,,263.130615234375,263.130615234375,26.4648857116699,26.4648857116699,52.7884544890344,5.74483837494445,7.88960456848145,64,1,64,0,0,0.294342041015625,35.190616607666,2,1,1,263.130615234375,0,2084574304,263.130615234375,,,,,,,,,,,,,,,,,,,,,,,,,,,,,,,,,
,3872914142.67952,295.040771484375,26.4648857116699,1.20597434878144E-5,6.31352513485518E-9,1,5,13.1008939743042,4.98692625306119,37.5000014901161,0.0139660277844522,0.00203278951420863,1,-1.18155507692238E-8,,,,,,,,,,,,,,,,,,,,,295.040771484375,295.040771484375,26.4648857116699,26.4648857116699,52.763442376419,5.75253705112945,7.76193904876709,66,1,0,0,1,0.2978515625,33.2355842590332,2,1,1,295.040771484375,0,2084574368,295.040771484375,,,,,,,,,,,,,,,,,,,,,,,,,,,,,,,,,
,3872915761.02158,1.99990689754486,43581.212890625,0.446409846079135,6.47972683970121E-5,1,2,13.1008939743042,4.98346203594051,36.5899987518787,516.32479827121,76.1678975239293,1000,0.000422215697833533,,,,,,,,,,,,,,,,,,,,,1.99986588954926,1.99994790554047,43491.25,43671.17578125,53.5208404115537,5.72438732256742,2.53642892837524,26,1,0,0,1,0.299606323242188,32.2580642700195,1,6,1,1.99986588954926,0,2084573184,1.99990689754486,,,,,,,,,,,,,,,,,,,,,,,,,,,,,,,,,
,3872915824.56186,1.99988734722137,37234.90625,0.417375508249758,7.17427921688019E-5,1,2,13.1008939743042,4.9832538589278,36.5800000727177,482.709123419899,71.2494949273426,1000,0.000429077766574333,,,,,,,,,,,,,,,,,,,,,1.99896121025085,2.00081348419189,37150,37319.8125,53.2961222122749,5.72480495689237,2.52438378334045,25,1,68,0,0,0.299530029296875,32.7468223571777,1,6,1,1.99896121025085,0,2084573184,1.99988734722137,,,,,,,,,,,,,,,,,,,,,,,,,,,,,,,,,
,3872915888.03424,1.99878865480423,30898.59375,0.383379866720623,8.0290387490208E-5,1,2,13.1008939743042,4.98316629160723,36.5800000727177,443.387712598202,65.399220037435,1000,0.000354946459934911,,,,,,,,,,,,,,,,,,,,,1.99842870235443,1.99914860725403,30808.6484375,30988.5390625,53.122209866746,5.72449022542299,2.51028919219971,26,1,0,0,1,0.300750732421875,32.7468223571777,1,6,1,1.99914860725403,0,2084573184,1.99878865480423,,,,,,,,,,,,,,,,,,,,,,,,,,,,,,,,,
,3872915951.5813,2.0000284910202,24552.4228515625,0.342551171246624,0.000114508297217542,1,2,13.1008939743042,4.98311611162855,36.5800000727177,396.159824209914,58.4537962151029,1000,0.000334612607032394,,,,,,,,,,,,,,,,,,,,,1.99981546401978,2.00024151802063,24467.484375,24637.361328125,53.1945105047749,5.72368159404366,2.50748825073242,26,1,0,0,1,0.299835205078125,32.7468223571777,1,6,1,1.99981546401978,0,2084573184,2.0000284910202,,,,,,,,,,,,,,,,,,,,,,,,,,,,,,,,,
,3872916015.03173,1.99760627746582,18216.8212890625,0.292473120330293,0.000103880031333334,1,2,13.1008939743042,4.98296460999485,36.5899987518787,338.235043997506,49.8733573159548,1000,0.000257279139210195,,,,,,,,,,,,,,,,,,,,,1.99741518497467,1.99779736995697,18126.876953125,18306.765625,52.8814682828229,5.72411380443896,2.49897265434265,26,1,0,0,1,0.293655395507812,31.7693061828613,1,6,1,1.99779736995697,0,2084573184,1.99760627746582,,,,,,,,,,,,,,,,,,,,,,,,,,,,,,,,,
,3872916078.55296,1.99991518259048,11874.673828125,0.228088845910373,0.000128936708555694,1,2,13.1008939743042,4.98263739476352,36.5800000727177,263.768956638181,38.7789720634002,1000,0.000103961379694059,,,,,,,,,,,,,,,,,,,,,1.99982440471649,2.00000596046448,11784.63671875,11964.7109375,52.8771693259671,5.72511436428416,2.49389958381653,26,1,0,0,1,0.300674438476562,32.7468223571777,1,6,1,1.99982440471649,0,2084573184,1.99991518259048,,,,,,,,,,,,,,,,,,,,,,,,,,,,,,,,,
,3872916142.05629,1.99989354610443,5528.26220703125,0.13944179804767,0.000179266383978547,1,2,13.1008939743042,4.98233288534303,36.5800000727177,161.235294471561,23.744130101206,1000,9.7014759571988E-5,,,,,,,,,,,,,,,,,,,,,1.99974417686462,2.00004291534424,5438.26806640625,5618.25634765625,52.710682451371,5.72564110399761,2.48879051208496,26,1,0,0,1,0.30120849609375,32.7468223571777,1,6,1,2.00004291534424,0,2084573184,1.99989354610443,,,,,,,,,,,,,,,,,,,,,,,,,,,,,,,,,
,3872916205.56153,2.00000822544098,-819.972625732422,-0.00916158580159289,0.000483450330665156,1,2,13.1008939743042,4.98219314497395,36.5800000727177,-10.5551575048008,-1.81847882965393,1000,-0.000229925417806979,,,,,,,,,,,,,,,,,,,,,1.9999144077301,2.00010204315186,-910.065734863281,-729.879516601562,52.7536720199287,5.72665267750964,2.47355222702026,26,1,0,0,1,0.300369262695313,33.2355842590332,1,6,1,1.9999144077301,0,2084573184,2.00000822544098,,,,,,,,,,,,,,,,,,,,,,,,,,,,,,,,,
,3872916269.05473,2.00016313791275,-7168.92456054687,-0.152472910460037,0.000185421862283055,1,2,13.1008939743042,4.98245138765216,36.5800000727177,-176.304192015586,-25.9962790718343,1000,-0.000134051989667007,,,,,,,,,,,,,,,,,,,,,1.99998247623444,2.00034379959106,-7258.96826171875,-7078.880859375,52.7478098060344,5.7265356966261,2.47437214851379,26,1,0,0,1,0.300521850585937,32.7468223571777,1,6,1,1.99998247623444,0,2084573184,2.00016313791275,,,,,,,,,,,,,,,,,,,,,,,,,,,,,,,,,
,3872916332.63697,2.00011873245239,-13530.775390625,-0.242261643525259,0.000126696417748049,1,2,13.1008939743042,4.98288744482405,36.5899987518787,-280.160240640147,-41.3162879707062,1000,-0.000218325988200981,,,,,,,,,,,,,,,,,,,,,1.99998879432678,2.000248670578,-13620.4912109375,-13441.0595703125,52.9275843654575,5.72433258304855,2.46723699569702,26,1,0,0,1,0.299148559570313,33.2355842590332,1,6,1,2.000248670578,0,2084573184,2.00011873245239,,,,,,,,,,,,,,,,,,,,,,,,,,,,,,,,,
,3872916396.10376,2.00003117322922,-19877.99609375,-0.305402773922731,9.9790379211563E-5,1,2,13.1008939743042,4.98262273057906,36.5899987518787,-353.154289782973,-52.0695516159982,1000,-0.000265542504211348,,,,,,,,,,,,,,,,,,,,,1.99985682964325,2.00020551681519,-19962.630859375,-19793.361328125,52.9377455362075,5.72442176832619,2.46064066886902,26,1,0,0,1,0.300674438476562,33.2355842590332,1,6,1,1.99985682964325,0,2084573184,2.00003117322922,,,,,,,,,,,,,,,,,,,,,,,,,,,,,,,,,
,3872916459.63352,1.9999440908432,-26230.7490234375,-0.353872811548674,8.59302927739589E-5,1,2,13.1008939743042,4.98236139820055,36.5899987518787,-409.180951845732,-60.2734194103866,1000,-0.000259625078423903,,,,,,,,,,,,,,,,,,,,,1.9997570514679,2.00013113021851,-26315.6015625,-26145.896484375,53.0889906546787,5.72748196751003,2.45598220825195,26,1,0,0,1,0.301055908203125,32.7468223571777,1,6,1,1.9997570514679,0,2084573696,1.9999440908432,,,,,,,,,,,,,,,,,,,,,,,,,,,,,,,,,
,3872916523.05837,1.99970096349716,-32589.1083984375,-0.393123283293569,8.11272366974423E-5,1,2,13.1008939743042,4.98239873105328,36.5899987518787,-454.541023562524,-67.1626883369597,1000,-0.000464156747477193,,,,,,,,,,,,,,,,,,,,,1.99934303760529,2.00005888938904,-32679.1640625,-32499.052734375,53.2160052890537,5.72885006169763,2.450026512146,26,1,0,0,1,0.30029296875,32.2580642700195,1,6,1,1.99934303760529,0,2084573824,1.99970096349716,,,,,,,,,,,,,,,,,,,,,,,,,,,,,,,,,
,3872916586.62928,1.99991822242737,-38961.978515625,-0.425943527084988,0.000129976754503397,1,2,13.1008939743042,4.98242878676628,36.5899987518787,-492.483989188363,-72.8315673912994,1000,-0.000555765403765982,,,,,,,,,,,,,,,,,,,,,1.99979591369629,2.00004053115845,-39051.8125,-38872.14453125,53.3012027976499,5.72866969207709,2.451824426651,26,1,0,0,1,0.30120849609375,31.7693061828613,1,6,1,1.99979591369629,0,2084574048,1.99991822242737,,,,,,,,,,,,,,,,,,,,,,,,,,,,,,,,,
,3872916650.08561,1.99970483779907,-45320.552734375,-0.453750784297415,0.000103712215502061,1,2,13.1008939743042,4.98249262141145,36.5800000727177,-524.666603778468,-77.4381851120607,1000,-0.000462769549672935,,,,,,,,,,,,,,,,,,,,,1.99934458732605,2.00006508827209,-45415.38671875,-45225.71875,53.4841038711499,5.72901040094515,2.44459199905396,26,1,0,0,1,0.301742553710937,33.2355842590332,1,6,1,1.99934458732605,0,2084573952,1.99970483779907,,,,,,,,,,,,,,,,,,,,,,,,,,,,,,,,,
,3872916713.65033,2.000075340271,-48949.462890625,-0.468353880873899,0.000107438645086069,1,2,13.1008939743042,4.98250301460637,36.5800000727177,-541.556585313257,-79.9100686162611,1000,-0.000459893739169707,,,,,,,,,,,,,,,,,,,,,1.9999885559082,2.00016212463379,-49033.90625,-48865.01953125,53.6173715336788,5.72981711914209,2.44115734100342,26,1,0,0,1,0.300827026367188,32.7468223571777,1,6,1,1.9999885559082,0,2084574304,2.000075340271,,,,,,,,,,,,,,,,,,,,,,,,,,,,,,,,,
,3872916777.15023,1.99998992681503,-42609.478515625,-0.442874835455616,7.74921149605996E-5,1,2,13.1008939743042,4.98220871285584,36.5800000727177,-512.047154332584,-75.5951484312364,1000,-0.000468210099255093,,,,,,,,,,,,,,,,,,,,,1.99987757205963,2.00010228157043,-42693.98828125,-42524.96875,53.4993456272749,5.73101921926345,2.43711304664612,26,1,0,0,1,0.300216674804687,31.7693061828613,1,6,1,1.99987757205963,0,2084574080,1.99998992681503,,,,,,,,,,,,,,,,,,,,,,,,,,,,,,,,,
,3872916840.6589,2.00024843215942,-36270.033203125,-0.413252825098982,6.34368730258162E-5,1,2,13.1008939743042,4.98226759746759,36.5800000727177,-477.801442987208,-70.5740503579913,1000,-0.000466269593952899,,,,,,,,,,,,,,,,,,,,,2.00014781951904,2.0003490447998,-36354.78125,-36185.28515625,53.3789748353133,5.73013354296101,2.4338014125824,26,1,0,0,1,0.300140380859375,32.2580642700195,1,6,1,2.0003490447998,0,2084574016,2.00024843215942,,,,,,,,,,,,,,,,,,,,,,,,,,,,,,,,,
,3872916904.14211,2.00010287761688,-29935.6103515625,-0.378431547404816,8.67726618973249E-5,1,2,13.1008939743042,4.98193380982349,36.5800000727177,-437.513809025303,-64.5277596246493,1000,-0.000346076685621409,,,,,,,,,,,,,,,,,,,,,2.00002765655518,2.00017809867859,-30025.123046875,-29846.09765625,53.132371037496,5.73070992547055,2.43277215957642,26,1,0,0,1,0.294036865234375,31.2805480957031,1,6,1,2.00002765655518,0,2084574016,2.00010287761688,,,,,,,,,,,,,,,,,,,,,,,,,,,,,,,,,
,3872916967.66335,1.99978458881378,-23590.1259765625,-0.336563452127324,9.21081926163501E-5,1,2,13.1008939743042,4.98173114955193,36.5800000727177,-389.087576989896,-57.3807823072771,1000,-0.000303792385089178,,,,,,,,,,,,,,,,,,,,,1.99966907501221,1.99990010261536,-23674.6015625,-23505.650390625,52.9584586919671,5.73093591216961,2.43047976493835,26,1,0,0,1,0.299911499023438,33.7243423461914,1,6,1,1.99966907501221,0,2084573888,1.99978458881378,,,,,,,,,,,,,,,,,,,,,,,,,,,,,,,,,
,3872917031.13502,1.99983412027359,-17255.1162109375,-0.284729024301221,0.000103951016638062,1,2,13.1008939743042,4.98177561020598,36.5800000727177,-329.168118478692,-48.5432030322783,1000,-0.00025620674543021,,,,,,,,,,,,,,,,,,,,,1.99973034858704,1.99993789196014,-17344.634765625,-17165.59765625,52.8588010557652,5.73004475136063,2.42308855056763,26,1,0,0,1,0.30059814453125,33.7243423461914,1,6,1,1.99993789196014,0,2084573984,1.99983412027359,,,,,,,,,,,,,,,,,,,,,,,,,,,,,,,,,
,3872917094.64278,2.00020265579224,-10912.828125,-0.217536499524173,0.000127072801115464,1,2,13.1008939743042,4.98156397855368,36.5800000727177,-251.479266756721,-37.0462878976509,1000,-0.000161917019237386,,,,,,,,,,,,,,,,,,,,,2.00010466575623,2.00030064582825,-11002.6806640625,-10822.9755859375,52.7450741062171,5.73083536459139,2.42285633087158,26,1,0,0,1,0.302963256835937,33.7243423461914,1,6,1,2.00010466575623,0,2084573856,2.00020265579224,,,,,,,,,,,,,,,,,,,,,,,,,,,,,,,,,
,3872917158.16593,2.00003266334534,-4561.73754882812,-0.123269109604639,0.000192408134265636,1,2,13.1008939743042,4.98163925196389,36.5899987518787,-142.509903761124,-20.9672461083107,1000,-6.94134155266312E-5,,,,,,,,,,,,,,,,,,,,,1.99998998641968,2.000075340271,-4646.3486328125,-4477.12646484375,52.7337404926883,5.73039985713112,2.41875100135803,26,1,0,0,1,0.299911499023438,33.2355842590332,1,6,1,1.99998998641968,0,2084573760,2.00003266334534,,,,,,,,,,,,,,,,,,,,,,,,,,,,,,,,,
,3872917221.64799,1.9999840259552,1781.73828125,0.0369937134521842,0.000285426194026438,1,2,13.1008939743042,4.98150361757519,36.5800000727177,42.7583353724585,6.34679328760552,1000,6.8102306492904E-5,,,,,,,,,,,,,,,,,,,,,1.99998068809509,1.99998736381531,1692.13342285156,1871.34313964844,52.6805897533806,5.73056329449408,2.42263698577881,26,1,0,0,1,0.300827026367188,33.7243423461914,1,6,1,1.99998736381531,0,2084573568,1.9999840259552,,,,,,,,,,,,,,,,,,,,,,,,,,,,,,,,,
,3872917285.15258,2.00010216236114,8132.00024414062,0.168757459089268,0.000171857059767298,1,2,13.1008939743042,4.98143073358642,36.5800000727177,195.073049839606,28.7978293322267,1000,0.000177205104836128,,,,,,,,,,,,,,,,,,,,,2.00008821487427,2.00011610984802,8042.28466796875,8221.7158203125,52.685279524496,5.73116279841238,2.41851115226746,26,1,0,0,1,0.301361083984375,32.7468223571777,1,6,1,2.00011610984802,0,2084573184,2.00010216236114,,,,,,,,,,,,,,,,,,,,,,,,,,,,,,,,,
,3872917348.69529,1.99999845027924,14489.0795898438,0.25333844633558,0.000117927893517681,1,2,13.1008939743042,4.98133074325491,36.5800000727177,292.844455487547,43.1663965445569,1000,0.000210967780055698,,,,,,,,,,,,,,,,,,,,,1.99998259544373,2.00001430511475,14403.9677734375,14574.19140625,52.7763392469864,5.73222563285697,2.4151930809021,26,1,0,0,1,0.301055908203125,33.7243423461914,1,6,1,1.99998259544373,0,2084574112,1.99999845027924,,,,,,,,,,,,,,,,,,,,,,,,,,,,,,,,,
,3872917412.16134,2.00017297267914,20841.8759765625,0.313682157736051,9.04312822643977E-5,1,2,13.1008939743042,4.98129185832617,36.5800000727177,362.604937133413,53.3751648060362,1000,0.000198397987825549,,,,,,,,,,,,,,,,,,,,,1.99996662139893,2.00037932395935,20747.123046875,20936.62890625,52.8998365530248,5.73216304100408,2.40985608100891,26,1,0,0,1,0.301132202148438,33.2355842590332,1,6,1,2.00037932395935,0,2084574048,2.00017297267914,,,,,,,,,,,,,,,,,,,,,,,,,,,,,,,,,
,3872917475.65294,1.99995577335358,27192.076171875,0.36042571184303,8.5242754623864E-5,1,2,13.1008939743042,4.98126171797318,36.5800000727177,416.609471178369,61.5040483451905,1000,0.000379916853646467,,,,,,,,,,,,,,,,,,,,,1.99978613853455,2.00012540817261,27102.25390625,27281.8984375,53.1038415965441,5.73332200066072,2.4117443561554,26,1,0,0,1,0.30303955078125,32.7468223571777,1,6,1,1.99978613853455,0,2084573888,1.99995577335358,,,,,,,,,,,,,,,,,,,,,,,,,,,,,,,,,
,3872917539.16677,2.0000411272049,33561.875,0.398578882779304,5.93805307000655E-5,1,2,13.1008939743042,4.98120385502829,36.5800000727177,460.714367780748,67.9326347569046,1000,0.000350179910750193,,,,,,,,,,,,,,,,,,,,,2.00003838539124,2.00004386901855,33466.83203125,33656.91796875,53.2308562309191,5.73437932398242,2.4165198802948,26,1,0,0,1,0.292892456054687,34.2131004333496,1,6,1,2.00003838539124,0,2084574048,2.0000411272049,,,,,,,,,,,,,,,,,,,,,,,,,,,,,,,,,
,3872917602.71514,1.99987369775772,39931.04296875,0.430483219414315,0.000103315202781929,1,2,13.1008939743042,4.98112846544811,36.5800000727177,497.593632305143,73.287962628299,1000,0.000308316864148111,,,,,,,,,,,,,,,,,,,,,1.99975633621216,1.99999105930328,39840.73828125,40021.34765625,53.442286745371,5.73513065429611,2.41484093666077,26,1,0,0,1,0.293731689453125,33.2355842590332,1,6,1,1.99975633621216,0,2084574048,1.99987369775772,,,,,,,,,,,,,,,,,,,,,,,,,,,,,,,,,
,3872917666.23388,2.00019800662994,46300.64453125,0.457802171458159,6.62237932344833E-5,1,2,13.1008939743042,4.98142924323341,36.5800000727177,529.180719464359,78.1882934923951,1000,0.000537891007876236,,,,,,,,,,,,,,,,,,,,,2.00010800361633,2.00028800964355,46215.37890625,46385.91015625,53.6197164192364,5.73478045102935,2.41323590278626,26,1,0,0,1,0.3009033203125,33.2355842590332,1,6,1,2.00010800361633,0,2084574112,2.00019800662994,,,,,,,,,,,,,,,,,,,,,,,,,,,,,,,,,
,3872918087.85552,12.0230340957642,26.4401626586914,0.00153769042447357,5.52108989022908E-6,1,5,13.1008939743042,5.00146049001972,36.5800000727177,1.78781842042129,0.261660551275017,100,-2.94522422353826E-7,,,,,,,,,,,,,,,,,,,,,12.0230340957642,12.0230340957642,26.4401626586914,26.4401626586914,52.6207951716594,5.73282961603411,4.87520980834961,66,1,0,0,1,0.303115844726562,31.2805480957031,6,1,1,12.0230340957642,0,2084574304,12.0230340957642,,,,,,,,,,,,,,,,,,,,,,,,,,,,,,,,,
,3872918299.89378,45.0024642944336,26.4401626586914,7.79309343501947E-5,6.97200507484693E-8,1,5,13.1008939743042,5.00082164519452,36.6000011563301,0.0905973869680518,0.0132175694193813,1,-5.03273709390978E-8,,,,,,,,,,,,,,,,,,,,,45.0024642944336,45.0024642944336,26.4401626586914,26.4401626586914,52.6735550967075,5.73484994449983,6.3301510810852,65,1,64,0,0,0.29327392578125,32.7468223571777,2,1,1,45.0024642944336,0,2084574208,45.0024642944336,,,,,,,,,,,,,,,,,,,,,,,,,,,,,,,,,
,3872918502.13002,77.0364532470703,26.4401626586914,5.69825625166505E-5,1.42964251793187E-8,1,5,13.1008939743042,4.99909355263484,36.6399995982647,0.0662081605470114,0.00968717767756595,1,-1.33409992480362E-8,,,,,,,,,,,,,,,,,,,,,77.0364532470703,77.0364532470703,26.4401626586914,26.4401626586914,52.6387726276017,5.7411943709691,6.65718030929565,66,1,0,0,1,0.293502807617188,31.7693061828613,2,1,1,77.0364532470703,0,2084574304,77.0364532470703,,,,,,,,,,,,,,,,,,,,,,,,,,,,,,,,,
,3872918697.00848,109.006446838379,26.4401626586914,4.45779834903069E-5,1.17852118982698E-8,1,5,13.1008939743042,4.99704351568773,36.6999991238117,0.0517666387580845,0.00756643518385867,1,-1.69677628922852E-8,,,,,,,,,,,,,,,,,,,,,109.006446838379,109.006446838379,26.4401626586914,26.4401626586914,52.682153010419,5.74924081666616,6.82531023025513,64,1,64,0,0,0.2996826171875,33.2355842590332,2,1,1,109.006446838379,0,2084574432,109.006446838379,,,,,,,,,,,,,,,,,,,,,,,,,,,,,,,,,
,3872918890.58552,141.033920288086,26.4401626586914,3.36630381615906E-5,9.80056866997079E-9,1,5,13.1008939743042,4.9953415850722,36.7899984121323,0.0390742345597787,0.00570202051147838,1,-2.06057773999626E-8,,,,,,,,,,,,,,,,,,,,,141.033920288086,141.033920288086,26.4401626586914,26.4401626586914,52.7020845376594,5.75697456324714,6.92721557617187,65,1,64,0,0,0.30059814453125,33.7243423461914,2,1,1,141.033920288086,0,2084574432,141.033920288086,,,,,,,,,,,,,,,,,,,,,,,,,,,,,,,,,
,3872919084.11865,173.04670715332,26.4401626586914,2.66523416851413E-5,8.08432632464343E-9,1,5,13.1008939743042,4.99551304723256,36.8999987840652,0.0309369279791295,0.00452261653343764,1,-9.5190856673866E-9,,,,,,,,,,,,,,,,,,,,,173.04670715332,173.04670715332,26.4401626586914,26.4401626586914,52.7833739036594,5.756471226347,7.01546573638916,64,1,64,0,0,0.300216674804687,32.2580642700195,2,1,1,173.04670715332,0,2084574400,173.04670715332,,,,,,,,,,,,,,,,,,,,,,,,,,,,,,,,,
,3872919276.36721,205.056411743164,26.4401626586914,2.11501650032352E-5,6.90039500788447E-9,1,5,13.1008939743042,4.99420336387967,37.0200015604496,0.0245413294798458,0.00358688397396279,1,-8.20447376091769E-9,,,,,,,,,,,,,,,,,,,,,205.056411743164,205.056411743164,26.4401626586914,26.4401626586914,53.1343251087941,5.75828418854994,7.13632869720459,64,1,64,0,0,0.302047729492188,34.7018585205078,2,1,1,205.056411743164,0,2084574240,205.056411743164,,,,,,,,,,,,,,,,,,,,,,,,,,,,,,,,,
,3872919469.9672,237.024490356445,26.4401626586914,1.70698524319787E-5,6.56558558220534E-9,1,5,13.1008939743042,4.99598127631536,37.1799990534782,0.0198159653817248,0.00290110227755607,1,-2.5205513418476E-9,,,,,,,,,,,,,,,,,,,,,237.024490356445,237.024490356445,26.4401626586914,26.4401626586914,52.8029146166402,5.75139825425233,7.44525909423828,65,1,64,0,0,0.299606323242188,33.2355842590332,2,1,1,237.024490356445,0,2084574368,237.024490356445,,,,,,,,,,,,,,,,,,,,,,,,,,,,,,,,,
,3872919662.708,269.035736083984,26.4401626586914,1.38963292063642E-5,6.62958838698739E-9,1,5,13.1008939743042,4.99587673314879,37.3499989509583,0.0161317578910267,0.00235943314619096,1,-3.98561851552084E-9,,,,,,,,,,,,,,,,,,,,,269.035736083984,269.035736083984,26.4401626586914,26.4401626586914,52.8287083577748,5.7518817711867,8.08038997650146,64,1,64,0,0,0.2984619140625,38.1231689453125,2,1,1,269.035736083984,0,2084574368,269.035736083984,,,,,,,,,,,,,,,,,,,,,,,,,,,,,,,,,
"RTSIRM",3872919998.50696
,3872920632.90974,269.977508544922,26.4896049499512,1.57375071201065E-5,5.8058617800073E-9,1,5,13.1008939743042,4.97598979507291,37.3600013554096,0.0181682229982959,0.00265058792159366,1,-1.01951112507173E-8,,,,,,,,,,,,,,,,,,,,,269.977508544922,269.977508544922,26.4896049499512,26.4896049499512,52.786891231996,5.75391105715642,8.86316776275635,66,1,0,0,1,0.29876708984375,34.7018585205078,2,1,1,269.977508544922,0,2084574560,269.977508544922,,,,,,,,,,,,,,,,,,,,,,,,,,,,,,,,,
,3872920828.06325,237.991485595703,26.4896049499512,1.73698798649872E-5,6.3673579244342E-9,1,5,13.1008939743042,4.9856614378666,37.2200012207031,0.0201078167205707,0.00293071763639506,1,-1.36551350349416E-8,,,,,,,,,,,,,,,,,,,,,237.991485595703,237.991485595703,26.4896049499512,26.4896049499512,52.8033054308998,5.75799334373344,8.47666263580322,64,1,64,0,0,0.298309326171875,32.7468223571777,2,1,1,237.991485595703,0,2084573984,237.991485595703,,,,,,,,,,,,,,,,,,,,,,,,,,,,,,,,,
,3872921017.89559,205.98176574707,26.4896049499512,1.91307321266883E-5,6.71007922316555E-9,1,5,13.1008939743042,4.98535069019618,37.0999984443188,0.0221432700037703,0.00323448974799561,1,-9.02944570954012E-9,,,,,,,,,,,,,,,,,,,,,205.98176574707,205.98176574707,26.4896049499512,26.4896049499512,52.6762907965248,5.75551306472989,8.20031547546387,66,1,0,0,1,0.298995971679687,33.2355842590332,2,1,1,205.98176574707,0,2084573792,205.98176574707,,,,,,,,,,,,,,,,,,,,,,,,,,,,,,,,,
,3872921210.19129,173.936172485352,26.4896049499512,2.10573053086741E-5,5.85212932200359E-9,1,5,13.1008939743042,4.98510312220159,37.0000004768372,0.0243723472023409,0.00355437103165434,1,-1.47795868531487E-8,,,,,,,,,,,,,,,,,,,,,173.936172485352,173.936172485352,26.4896049499512,26.4896049499512,52.6805897533806,5.75799524410482,7.9830265045166,65,1,64,0,0,0.299911499023438,33.7243423461914,2,1,1,173.936172485352,0,2084573856,173.936172485352,,,,,,,,,,,,,,,,,,,,,,,,,,,,,,,,,
,3872921402.36598,141.988662719727,26.4896049499512,2.30955793083052E-5,6.20680124757148E-9,1,5,13.1008939743042,4.98631401443197,36.8999987840652,0.0267410238221438,0.00389691047219748,1,-1.86622384652271E-8,,,,,,,,,,,,,,,,,,,,,141.988662719727,141.988662719727,26.4896049499512,26.4896049499512,52.768522961794,5.7524555150264,7.7978949546814,66,1,0,0,1,0.297317504882812,31.2805480957031,2,1,1,141.988662719727,0,2084574304,141.988662719727,,,,,,,,,,,,,,,,,,,,,,,,,,,,,,,,,
,3872921594.26537,109.987678527832,26.4896049499512,2.50483737912341E-5,4.61121784191788E-8,1,5,13.1008939743042,4.98496318979492,36.8000008165836,0.0289878711618977,0.00424640872986186,1,-1.56800731168857E-9,,,,,,,,,,,,,,,,,,,,,109.987678527832,109.987678527832,26.4896049499512,26.4896049499512,52.695440695246,5.75717692328246,7.61891222000122,66,1,0,0,1,0.299301147460937,33.7243423461914,2,1,1,109.987678527832,0,2084573920,109.987678527832,,,,,,,,,,,,,,,,,,,,,,,,,,,,,,,,,
,3872921785.27387,77.9823379516602,26.4896049499512,2.80208611046755E-5,6.78398647272554E-9,1,5,13.1008939743042,4.98442016715556,36.7200002074242,0.0324257788586629,0.00473000197326189,1,-1.86949864209754E-8,,,,,,,,,,,,,,,,,,,,,77.9823379516602,77.9823379516602,26.4896049499512,26.4896049499512,52.7376486352844,5.76006908923564,7.40775775909424,66,1,0,0,1,0.299072265625,32.7468223571777,2,1,1,77.9823379516602,0,2084573888,77.9823379516602,,,,,,,,,,,,,,,,,,,,,,,,,,,,,,,,,
,3872921971.98945,45.9798126220703,26.4896049499512,3.42040750430628E-5,1.26594601823867E-8,1,5,13.1008939743042,4.9859615255563,36.6600006818771,0.0395965195888733,0.0057874532848102,1,-1.31415899918045E-8,,,,,,,,,,,,,,,,,,,,,45.9798126220703,45.9798126220703,26.4896049499512,26.4896049499512,52.7016937233998,5.75461453575712,7.07449626922607,64,1,64,0,0,0.29815673828125,33.2355842590332,2,1,1,45.9798126220703,0,2084573184,45.9798126220703,,,,,,,,,,,,,,,,,,,,,,,,,,,,,,,,,
,3872922160.98005,13.9976234436035,26.4896049499512,9.20466663360441E-5,9.42871997353492E-8,1,5,13.1008939743042,4.98585502442771,36.6000011563301,0.106556272693217,0.0155661341451136,1,-4.2301200887267E-8,,,,,,,,,,,,,,,,,,,,,13.9976234436035,13.9976234436035,26.4896049499512,26.4896049499512,52.727878278794,5.75574986047415,5.90864276885986,65,1,64,0,0,0.297927856445313,32.7468223571777,2,1,1,13.9976234436035,0,2084573216,13.9976234436035,,,,,,,,,,,,,,,,,,,,,,,,,,,,,,,,,
,3872922533.01352,20.012508392334,26.4896049499512,8.14794561030966E-5,7.25319923593548E-8,1,5,13.1008939743042,4.98481639063047,36.5800000727177,0.0942940048765296,0.0137871679863701,1,-2.69953907554992E-8,,,,,,,,,,,,,,,,,,,,,20.012508392334,20.012508392334,26.4896049499512,26.4896049499512,52.6188411003613,5.75885364005057,5.67064476013184,66,1,0,0,1,0.300140380859375,34.7018585205078,2,1,1,20.012508392334,0,2084574144,20.012508392334,,,,,,,,,,,,,,,,,,,,,,,,,,,,,,,,,
,3872922739.03839,52.0255584716797,26.4896049499512,3.27434803307348E-5,9.87126857205884E-9,1,5,13.1008939743042,4.98382664111308,36.6099998354912,0.037882610101296,0.00553899453823591,1,-1.08477989459074E-8,,,,,,,,,,,,,,,,,,,,,52.0255584716797,52.0255584716797,26.4896049499512,26.4896049499512,52.641508327419,5.76359488639667,6.5187406539917,66,1,0,0,1,0.300445556640625,33.7243423461914,2,1,1,52.0255584716797,0,2084574432,52.0255584716797,,,,,,,,,,,,,,,,,,,,,,,,,,,,,,,,,
,3872922939.43626,84.0163040161133,26.4896049499512,2.73508004506042E-5,5.61845866753772E-9,1,5,13.1008939743042,4.98302174931374,36.6499982774258,0.0316367658651487,0.00462305145658974,1,-1.13540865966298E-8,,,,,,,,,,,,,,,,,,,,,84.0163040161133,84.0163040161133,26.4896049499512,26.4896049499512,52.6547960122459,5.76771830485293,6.81365823745727,66,1,0,0,1,0.30059814453125,33.7243423461914,2,1,1,84.0163040161133,0,2084574592,84.0163040161133,,,,,,,,,,,,,,,,,,,,,,,,,,,,,,,,,
,3872923133.93208,116.002746582031,26.4896049499512,2.4258171258023E-5,4.92738220286405E-9,1,5,13.1008939743042,4.98252885678538,36.7200002074242,0.0280561797338996,0.00409591660014686,1,-1.33778795683378E-8,,,,,,,,,,,,,,,,,,,,,116.002746582031,116.002746582031,26.4896049499512,26.4896049499512,52.7091191943325,5.77025831505334,6.94842147827148,65,1,64,0,0,0.30120849609375,33.7243423461914,2,1,1,116.002746582031,0,2084574144,116.002746582031,,,,,,,,,,,,,,,,,,,,,,,,,,,,,,,,,
,3872923327.10126,148.009552001953,26.4896049499512,2.18575283506637E-5,6.5126682715611E-9,1,5,13.1008939743042,4.98477567974163,36.8099994957447,0.0252954304004639,0.00369448968870196,1,-1.06881244087518E-8,,,,,,,,,,,,,,,,,,,,,148.009552001953,148.009552001953,26.4896049499512,26.4896049499512,52.7188895508229,5.76235131812428,7.03498458862305,66,1,0,0,1,0.3009033203125,34.2131004333496,2,1,1,148.009552001953,0,2084574400,148.009552001953,,,,,,,,,,,,,,,,,,,,,,,,,,,,,,,,,
,3872923520.42346,180.036163330078,26.4896049499512,1.96891787929647E-5,5.63029930061249E-8,1,5,13.1008939743042,4.98216379747586,36.9199998676777,0.0227696554865116,0.00332304083748487,1,-1.17870123484265E-8,,,,,,,,,,,,,,,,,,,,,180.036163330078,180.036163330078,26.4896049499512,26.4896049499512,52.8048686879383,5.77076523069675,7.1088695526123,66,1,0,0,1,0.288238525390625,34.7018585205078,2,1,1,180.036163330078,0,2084574208,180.036163330078,,,,,,,,,,,,,,,,,,,,,,,,,,,,,,,,,
,3872923707.65745,211.118751525879,26.4896049499512,1.75754336087367E-5,6.33295137497968E-9,1,5,13.1008939743042,4.98009144805695,37.0500013232231,0.0203152351695668,0.00295168131904061,1,-2.16681920644131E-8,,,,,,,,,,,,,,,,,,,,,211.055969238281,211.181533813477,26.4896049499512,26.4896049499512,52.7974432170056,5.77877972929778,7.21826553344727,64,1,64,0,0,0.292205810546875,33.7243423461914,2,1,1,211.181533813477,0,2084574336,211.118751525879,,,,,,,,,,,,,,,,,,,,,,,,,,,,,,,,,
,3872923899.88714,243.029258728027,26.4896049499512,1.57247574215409E-5,5.24593578077087E-9,1,5,13.1008939743042,4.98978902050861,37.2000001370907,0.0182252367577619,0.002651223756924,1,-1.66771389788337E-8,,,,,,,,,,,,,,,,,,,,,243.011810302734,243.04670715332,26.4896049499512,26.4896049499512,52.7141997797075,5.77970033980462,7.44601249694824,65,1,64,0,0,0.293731689453125,33.2355842590332,2,1,1,243.04670715332,0,2084574336,243.029258728027,,,,,,,,,,,,,,,,,,,,,,,,,,,,,,,,,
,3872924092.86315,275.033813476562,26.4896049499512,1.40277805352359E-5,8.06973099845351E-9,1,5,13.1008939743042,4.98777646440859,37.3799987137318,0.0162484681253425,0.00236894885845002,1,-1.04090387079784E-8,,,,,,,,,,,,,,,,,,,,,275.033813476562,275.033813476562,26.4896049499512,26.4896049499512,52.7485914345536,5.78572498591113,7.75856494903564,65,1,64,0,0,0.297317504882812,33.2355842590332,2,1,1,275.033813476562,0,2084574272,275.033813476562,,,,,,,,,,,,,,,,,,,,,,,,,,,,,,,,,
,3872924517.477,300.004669189453,47345.9140625,0.0199141030119515,8.30994967886746E-6,1,2,13.1008939743042,4.99849248984061,37.5199988484383,23.1488326978863,3.28602273350966,100,-8.97597237945907E-5,,,,,,,,,,,,,,,,,,,,,300.004669189453,300.004669189453,47345.9140625,47345.9140625,52.664957182996,5.78494703222336,7.64526891708374,25,1,68,0,0,0.29510498046875,34.7018585205078,1,6,1,300.004669189453,0,2084573184,300.004669189453,,,,,,,,,,,,,,,,,,,,,,,,,,,,,,,,,
,3872924579.85334,300.00390625,41114.064453125,0.0172583152039905,6.09953523660516E-6,1,2,13.1008939743042,4.99910080582361,37.5199988484383,20.0642341012072,2.85398981828261,100,-7.28719710396319E-5,,,,,,,,,,,,,,,,,,,,,300.003875732422,300.003936767578,41024.09375,41204.03515625,52.7657872619767,5.78203109292073,7.71732950210571,25,1,68,0,0,0.292739868164063,33.2355842590332,1,6,1,300.003875732422,0,2084573952,300.00390625,,,,,,,,,,,,,,,,,,,,,,,,,,,,,,,,,
,3872924643.3415,300.002136230469,34773.015625,0.0146139847480636,5.7120006502062E-6,1,2,13.1008939743042,4.99884812491693,37.5199988484383,16.9875733398599,2.42474230313536,100,-5.46366181613417E-5,,,,,,,,,,,,,,,,,,,,,300.002014160156,300.002258300781,34683.02734375,34863.00390625,52.817374744246,5.78218221759591,7.84538650512695,26,1,0,0,1,0.294036865234375,33.2355842590332,1,6,1,300.002258300781,0,2084574304,300.002136230469,,,,,,,,,,,,,,,,,,,,,,,,,,,,,,,,,
,3872924714.81516,300.001739501953,27637.7822265625,0.0116301540813163,4.58528379812391E-6,1,2,13.1008939743042,4.99881621945522,37.5199988484383,13.5195870294296,1.92558404303146,100,-4.69808421810644E-5,,,,,,,,,,,,,,,,,,,,,300.001556396484,300.001922607422,27552.73828125,27722.826171875,52.7200619936017,5.78291073036545,8.04336357116699,26,1,0,0,1,0.292510986328125,33.2355842590332,1,6,1,300.001922607422,0,2084574176,300.001739501953,,,,,,,,,,,,,,,,,,,,,,,,,,,,,,,,,
,3872924802.11196,300.0009765625,18920.5380859375,0.00799372530197436,5.81747554709372E-6,1,2,13.1008939743042,4.99849037223121,37.5199988484383,9.29259524170248,1.31616460191619,100,-3.85078311315712E-5,,,,,,,,,,,,,,,,,,,,,300.0009765625,300.0009765625,18835.9765625,19005.099609375,52.7673505190152,5.78546659367616,8.34493350982666,26,1,0,0,1,0.296096801757812,34.2131004333496,1,6,1,300.0009765625,0,2084574176,300.0009765625,,,,,,,,,,,,,,,,,,,,,,,,,,,,,,,,,
,3872924873.57431,300.001113891602,11784.5874023437,0.00501714172121685,4.64489915541814E-6,1,2,13.1008939743042,4.99898987214285,37.5199988484383,5.83500127082566,0.813715796994918,100,-3.49025428636994E-5,,,,,,,,,,,,,,,,,,,,,300.001007080078,300.001220703125,11694.9580078125,11874.216796875,52.7427292206594,5.78319943045245,8.63387966156006,26,1,0,0,1,0.292739868164063,33.7243423461914,1,6,1,300.001007080078,0,2084573952,300.001113891602,,,,,,,,,,,,,,,,,,,,,,,,,,,,,,,,,
,3872924944.99926,300.000549316406,4648.49951171875,0.00203478184411724,6.56827132531656E-6,1,2,13.1008939743042,4.99828256483985,37.5199988484383,2.37076106300428,0.29752607071981,100,-4.2068542773015E-5,,,,,,,,,,,,,,,,,,,,,300.000457763672,300.000640869141,4558.4990234375,4738.5,52.677072425044,5.78597715659012,8.8997220993042,25,1,68,0,0,0.2960205078125,33.2355842590332,1,6,1,300.000457763672,0,2084573760,300.000549316406,,,,,,,,,,,,,,,,,,,,,,,,,,,,,,,,,
,3872925026.39767,299.999786376953,-3494.67517089844,-0.00152719646929178,5.57869783941706E-6,1,2,13.1008939743042,4.99930014867874,37.5199988484383,-1.76791962014094,-0.30492158738591,100,-3.86115631540573E-5,,,,,,,,,,,,,,,,,,,,,299.999725341797,299.999847412109,-3579.70654296875,-3409.64379882812,52.6786356820825,5.78175581065482,9.21022129058838,26,1,0,0,1,0.292739868164063,33.7243423461914,1,6,1,299.999725341797,0,2084573184,299.999786376953,,,,,,,,,,,,,,,,,,,,,,,,,,,,,,,,,
,3872925089.90238,300.000534057617,-9845.3330078125,-0.00419203814068507,4.67796128374241E-6,1,2,13.1008939743042,4.99961997617453,37.5199988484383,-4.86959123455343,-0.725484916554446,100,-9.96741702105706E-6,,,,,,,,,,,,,,,,,,,,,300.000518798828,300.000549316406,-9930.4384765625,-9760.2275390625,52.7470281775152,5.78047087453335,9.43879795074463,26,1,0,0,1,0.291824340820313,32.7468223571777,1,6,1,300.000518798828,0,2084573312,300.000534057617,,,,,,,,,,,,,,,,,,,,,,,,,,,,,,,,,
,3872925179.15657,300.000335693359,-18773.541015625,-0.00792731117442031,4.53321063007143E-6,1,2,13.1008939743042,4.99806037298289,37.5199988484383,-9.20881492834014,-1.34236444984078,100,6.08180637213929E-6,,,,,,,,,,,,,,,,,,,,,300.000122070313,300.000549316406,-18863.56640625,-18683.515625,52.7247517647171,5.78702917567524,9.35508728027344,26,1,0,0,1,0.294342041015625,33.7243423461914,1,6,1,300.000549316406,0,2084573792,300.000335693359,,,,,,,,,,,,,,,,,,,,,,,,,,,,,,,,,
,3872925242.68268,300.000427246094,-25124.8486328125,-0.0105800850136147,5.07282002808792E-6,1,2,13.1008939743042,4.99753832137316,37.5199988484383,-12.2881882424679,-1.79432808255647,100,5.51628254121145E-6,,,,,,,,,,,,,,,,,,,,,300.000396728516,300.000457763672,-25214.966796875,-25034.73046875,52.7056018659959,5.78896757986503,9.28108978271484,26,1,0,0,1,0.295639038085937,33.2355842590332,1,6,1,300.000457763672,0,2084574016,300.000427246094,,,,,,,,,,,,,,,,,,,,,,,,,,,,,,,,,
,3872925306.19057,300.000061035156,-31492.5146484375,-0.0132337871977492,4.79092721899242E-6,1,2,13.1008939743042,4.99753472903334,37.5199988484383,-15.3702771198425,-2.24455164857519,100,6.75215330936251E-6,,,,,,,,,,,,,,,,,,,,,300.000030517578,300.000091552734,-31587.75,-31397.279296875,52.6301747138902,5.78942851656293,9.22214221954346,26,1,0,0,1,0.295028686523438,33.7243423461914,1,6,1,300.000091552734,0,2084574304,300.000061035156,,,,,,,,,,,,,,,,,,,,,,,,,,,,,,,,,
,3872925405.44149,300.000228881836,-41437.970703125,-0.0173762021628953,4.60337909667765E-6,1,2,13.1008939743042,4.99789548063132,37.5199988484383,-20.1827945207685,-2.95218884163282,100,4.77252176512822E-6,,,,,,,,,,,,,,,,,,,,,300.000122070313,300.000335693359,-41528.2109375,-41347.73046875,52.7255333932363,5.78762322441294,9.14717292785645,26,1,0,0,1,0.294723510742188,33.7243423461914,1,6,1,300.000122070313,0,2084574112,300.000228881836,,,,,,,,,,,,,,,,,,,,,,,,,,,,,,,,,
,3872925496.08518,300.000305175781,-50000.27734375,-0.0209491266088574,3.15908640447847E-6,1,2,13.1008939743042,4.9975096234176,37.5199988484383,-24.3281987787068,-3.57239712771976,100,-5.92118543549101E-6,,,,,,,,,,,,,,,,,,,,,300.000305175781,300.000305175781,-50000.27734375,-50000.27734375,52.5492761621498,5.7896246075497,9.08777523040771,26,1,0,0,1,0.2972412109375,33.7243423461914,1,6,1,300.000305175781,0,2084574272,300.000305175781,,,,,,,,,,,,,,,,,,,,,,,,,,,,,,,,,
,3872925560.19702,300.000595092773,-43622.83984375,-0.0183400855466946,5.5080633037027E-6,1,2,13.1008939743042,4.99706521020282,37.5199988484383,-21.3139199248582,-3.00257434257368,100,0.000102050663918584,,,,,,,,,,,,,,,,,,,,,300.000457763672,300.000732421875,-43712.72265625,-43532.95703125,52.7595342338229,5.79167036325545,9.05073356628418,24,1,68,0,0,0.295791625976562,33.7243423461914,1,6,1,300.000732421875,0,2084573184,300.000595092773,,,,,,,,,,,,,,,,,,,,,,,,,,,,,,,,,
,3872925623.73135,300.000732421875,-37277.705078125,-0.0156825353976926,6.15387890337757E-6,1,2,13.1008939743042,4.99718860366051,37.5199988484383,-18.2248116344329,-2.57622966857765,100,7.9813045475219E-5,,,,,,,,,,,,,,,,,,,,,300.000701904297,300.000762939453,-37372.59375,-37182.81640625,52.6508878696498,5.79066547917807,9.02670574188232,25,1,68,0,0,0.298309326171875,33.7243423461914,1,6,1,300.000701904297,0,2084573952,300.000732421875,,,,,,,,,,,,,,,,,,,,,,,,,,,,,,,,,
,3872925705.15629,299.99967956543,-29146.17578125,-0.0122942889329053,9.26356201055373E-6,1,2,13.1008939743042,4.99679400259036,37.5199988484383,-14.2832785981384,-2.03607549572244,100,4.82130631457292E-5,,,,,,,,,,,,,,,,,,,,,299.999145507812,300.000213623047,-29236.046875,-29056.3046875,52.7056018659959,5.79319484730029,8.99148273468018,24,1,68,0,0,0.297317504882812,33.2355842590332,1,6,1,300.000213623047,0,2084574016,299.99967956543,,,,,,,,,,,,,,,,,,,,,,,,,,,,,,,,,
,3872925792.51502,299.999221801758,-20419.6240234375,-0.00863671718500907,6.31460892690807E-6,1,2,13.1008939743042,4.99651340165194,37.5199988484383,-10.034149105114,-1.42368463350945,100,3.95047278535866E-5,,,,,,,,,,,,,,,,,,,,,299.999145507812,299.999298095703,-20499.59375,-20339.654296875,52.6758999822652,5.7934409231465,8.96633338928223,26,1,0,0,1,0.29754638671875,34.2131004333496,1,6,1,299.999145507812,0,2084573888,299.999221801758,,,,,,,,,,,,,,,,,,,,,,,,,,,,,,,,,
,3872925855.91273,299.999481201172,-14089.2138671875,-0.00598941769460834,4.56832843397609E-6,1,2,13.1008939743042,4.99518061372824,37.5199988484383,-6.95806531065583,-0.972257813664281,100,4.00401127110502E-5,,,,,,,,,,,,,,,,,,,,,299.999114990234,299.999847412109,-14179.1708984375,-13999.2568359375,52.7392118923229,5.79913919596951,8.94001579284668,26,1,0,0,1,0.298614501953125,33.2355842590332,1,6,1,299.999847412109,0,2084573856,299.999481201172,,,,,,,,,,,,,,,,,,,,,,,,,,,,,,,,,
,3872925919.46972,299.999435424805,-7739.39038085938,-0.00333717736583913,4.81289576765191E-6,1,2,13.1008939743042,4.99482436971409,37.5300012528896,-3.87965332964196,-0.520152807345339,100,4.08490693642784E-5,,,,,,,,,,,,,,,,,,,,,299.999420166016,299.999450683594,-7824.47119140625,-7654.3095703125,52.7095100085921,5.80101874373206,8.92251586914062,26,1,0,0,1,0.298538208007812,34.2131004333496,1,6,1,299.999420166016,0,2084573728,299.999435424805,,,,,,,,,,,,,,,,,,,,,,,,,,,,,,,,,
,3872925982.90223,300.000534057617,-1397.78723144531,-0.000673735615645965,5.50086065552427E-6,1,2,13.1008939743042,4.99668273118845,37.5199988484383,-0.794357520460832,-0.0320932246732789,100,7.10971572003395E-5,,,,,,,,,,,,,,,,,,,,,300.000427246094,300.000640869141,-1487.92980957031,-1307.64465332031,52.6895784813517,5.79313194303978,8.9047679901123,26,1,0,0,1,0.2984619140625,33.7243423461914,1,6,1,300.000640869141,0,2084573696,300.000534057617,,,,,,,,,,,,,,,,,,,,,,,,,,,,,,,,,
,3872926054.41348,299.999969482422,5746.55737304687,0.00248478486238028,1.08763193252832E-5,1,2,13.1008939743042,4.99503248772835,37.5199988484383,2.8796480219515,0.450231324631903,100,2.37965159533613E-5,,,,,,,,,,,,,,,,,,,,,299.999938964844,300,5661.50732421875,5831.607421875,52.7833739036594,5.80086830218249,8.89671421051025,24,1,68,0,0,0.297698974609375,32.2580642700195,1,6,1,300,0,2084573216,299.999969482422,,,,,,,,,,,,,,,,,,,,,,,,,,,,,,,,,
,3872926117.89475,299.999984741211,12098.4760742187,0.00514031836881493,4.77874589176393E-6,1,2,13.1008939743042,4.99488862836156,37.5199988484383,5.9641970619097,0.881835686886463,100,6.54969442866218E-6,,,,,,,,,,,,,,,,,,,,,299.999908447266,300.000061035156,12003.3642578125,12193.587890625,52.7853279749575,5.80069782740946,8.88101863861084,26,1,0,0,1,0.299758911132812,34.2131004333496,1,6,1,299.999908447266,0,2084574112,299.999984741211,,,,,,,,,,,,,,,,,,,,,,,,,,,,,,,,,
,3872926197.23975,300.000381469727,20036.705078125,0.00846051737916938,4.34097713340131E-6,1,2,13.1008939743042,4.99471969233443,37.5199988484383,9.81836130672074,1.4358255220884,100,-2.60320042167659E-6,,,,,,,,,,,,,,,,,,,,,300.000152587891,300.000610351562,19946.599609375,20126.810546875,52.8083860162748,5.80056412495691,8.86087036132813,26,1,0,0,1,0.298995971679687,33.2355842590332,1,6,1,300.000152587891,0,2084574272,300.000381469727,,,,,,,,,,,,,,,,,,,,,,,,,,,,,,,,,
,3872926260.73937,299.999649047852,26390.4765625,0.0111120816743341,5.13980092460458E-6,1,2,13.1008939743042,4.99378869565499,37.5199988484383,12.8927926539334,1.88069895500423,100,-7.40872802635956E-6,,,,,,,,,,,,,,,,,,,,,299.999572753906,299.999725341797,26300.28515625,26480.66796875,52.6477613555729,5.80540996032526,8.85751533508301,26,1,0,0,1,0.30181884765625,34.2131004333496,1,6,1,299.999572753906,0,2084573888,299.999649047852,,,,,,,,,,,,,,,,,,,,,,,,,,,,,,,,,
,3872926332.4153,300.000137329102,33572.072265625,0.014100935701758,4.70531799116521E-6,1,2,13.1008939743042,4.99519857102487,37.5300012528896,16.3665625448333,2.39102185725594,100,-6.36729980508091E-6,,,,,,,,,,,,,,,,,,,,,300.000030517578,300.000244140625,33496.8046875,33647.33984375,52.7274874645344,5.79873138795834,8.84302806854248,26,1,0,0,1,0.299301147460937,33.7243423461914,1,6,1,300.000030517578,0,2084573792,300.000137329102,,,,,,,,,,,,,,,,,,,,,,,,,,,,,,,,,
,3872926403.65552,300.000381469727,40713.388671875,0.0170859375057943,4.14450595560033E-6,1,2,13.1008939743042,4.99387391922364,37.5199988484383,19.8237191994001,2.89669970280551,100,-7.19591146593501E-6,,,,,,,,,,,,,,,,,,,,,300.000305175781,300.000457763672,40623.5,40803.27734375,52.5766331603229,5.80534560344689,8.83150386810303,26,1,0,0,1,0.301055908203125,33.7243423461914,1,6,1,300.000457763672,0,2084573984,300.000381469727,,,,,,,,,,,,,,,,,,,,,,,,,,,,,,,,,
,3872926503.02821,299.999603271484,50000.294921875,0.0209571181649168,1.80538410675587E-6,1,2,13.1008939743042,4.99546669527347,37.5300012528896,24.3233095327059,3.57337584780463,100,7.35443211975694E-6,,,,,,,,,,,,,,,,,,,,,299.999481201172,299.999725341797,50000.2890625,50000.30078125,52.7247517647171,5.79815865120701,8.82368564605713,26,1,0,0,1,0.299301147460937,33.7243423461914,1,4,1,299.999542236328,0,2084574112,299.999603271484,,,,,,,,,,,,,,,,,,,,,,,,,,,,,,,,,