File: LT data/Bridport/CREECH-1/334-FC-ZFC-RTSIRM-contsweepwithloop-MsT-AC.dat
[Header]
; MPMS3 Data File (default extension .dat)
; Copyright (c) 2007, Quantum Design, Inc. All rights reserved.
TITLE,
FILEOPENTIME,3866030370.69556,07/03/2022,6:17 pm
BYAPP,MPMS3 w/ AC,1.0,1.1
INFO,MPMS3 Measurement Release 1.1.16 Build 424, MultiVu Release 2.3.4.19,APPNAME
INFO,Linear Motor Servo Controller,MOTOR_MODULE_NAME
INFO,3101-100 N2,MOTOR_HW_VERSION
INFO,,MOTOR_SERIAL_NUMBER
INFO,01.04.28,MOTOR_SOFTWARE_VERSION
INFO,Quantum Design Squid Module,SQUID_MODULE_NAME
INFO,3101-501 B0,SQUID_HW_VERSION
INFO,SQM327,SQUID_SERIAL_NUMBER
INFO,01.03.04,SQUID_SOFTWARE_VERSION
INFO,Quantum Design VSM Oven,OVEN_MODULE_NAME
INFO,3101-201 A3,OVEN_HW_VERSION
INFO,OVB365,OVEN_SERIAL_NUMBER
INFO,01.07.07,OVEN_SOFTWARE_VERSION
INFO,SQUID AC,AC_MODULE_NAME
INFO,3101-401 G0,AC_HW_VERSION
INFO,SAC220,AC_SERIAL_NUMBER
INFO,SQUID AC 00.95.07,AC_SOFTWARE_VERSION
INFO,TCI344,COIL_SERIAL_NUMBER
INFO,0,MOMENT_UNITS
INFO,sndst,SAMPLE_MATERIAL
INFO,,SAMPLE_COMMENT
INFO,127.1,SAMPLE_MASS
INFO,,SAMPLE_VOLUME
INFO,,SAMPLE_MOLECULAR_WEIGHT
INFO,,SAMPLE_SIZE
INFO,,SAMPLE_SHAPE
INFO,Straw,SAMPLE_HOLDER
INFO,Standard,SAMPLE_HOLDER_DETAIL
INFO,55.07,SAMPLE_OFFSET
DATATYPE,COMMENT,1
DATATYPE,TIME,2
STARTUPAXIS,X,2
STARTUPAXIS,Y1,5
FIELDGROUP, VSM,2,3,4,5,6,8,9,10,11,14,15
FIELDGROUP, DC, 2,3,4,14,56,57,58,59,60,61,62,63,64,65,66,67,68,69
FIELDGROUP, AC, 2,3,4,11,16,17,18,19,20,21,22,23,24,25,26,27,28,29,30
STARTUPGROUP, All
[Data]
Comment,Time Stamp (sec),Temperature (K),Magnetic Field (Oe),Moment (emu),M. Std. Err. (emu),Transport Action,Averaging Time (sec),Frequency (Hz),Peak Amplitude (mm),Center Position (mm),Lockin Signal' (V),Lockin Signal (V),Range,M. Quad. Signal (emu),AC Moment (emu),AC M. Std Err. (emu),AC Phase (deg),AC Phase Std. Err. (deg),AC Susceptibility (emu/Oe),AC Suscept. Std Err. (emu/Oe),AC X' (emu/Oe),AC X' Std Err. (emu/Oe),AC X'' (emu/Oe),AC X'' Std Err. (emu/Oe),AC Drive (Oe),AC Frequency (Hz),AC Averaging Time (sec),AC Cycles,AC Range,AC Measure Type,AC Signal' (V),AC Signal'' (V),AC Trim Coil Ratio,AC Trim Coil Phase,Min. Temperature (K),Max. Temperature (K),Min. Field (Oe),Max. Field (Oe),Mass (grams),Motor Lag (deg),Pressure (Torr),Measure Count,Measurement Number,SQUID Status (code),Motor Status (code),Measure Status (code),Motor Current (amps),Motor Temp. (C),Temp. Status (code),Field Status (code),Chamber Status (code),Chamber Temp (K),Redirection State,Average Temp (K),Rotation Angle (deg),Rotator state,DC Moment Fixed Ctr (emu),DC Moment Err Fixed Ctr (emu),DC Moment Free Ctr (emu),DC Moment Err Free Ctr (emu),DC Fixed Fit,DC Free Fit,DC Calculated Center (mm),DC Calculated Center Err (mm),DC Scan Length (mm),DC Scan Time (s),DC Number of Points,DC Squid Drift,DC Min V (V),DC Max V (V),DC Scans per Measure,Map 01,Map 02,Map 03,Map 04,Map 05,Map 06,Map 07,Map 08,Map 09,Map 10,Map 11,Map 12,Map 13,Map 14,Map 15,Map 16
,3866031405.71542,100.001640319824,49999.6875,0.133515297751603,3.93294460703773E-5,1,2,12.9061126708984,4.97624207978205,40.3099991381168,173.157209859625,25.5330279263911,100,7.11978218931493E-5,,,,,,,,,,,,,,,,,,,,,100.001640319824,100.001640319824,49999.6875,49999.6875,49.9503613357072,5.37831122640948,7.40670585632324,26,1,0,0,1,0.276641845703125,29.8142719268799,1,1,1,100.001640319824,0,100.001640319824,,,,,,,,,,,,,,,,,,,,,,,,,,,,,,,,,
,3866031498.79391,87.8888549804687,49999.6875,0.152541305669785,5.25752564330908E-5,1,2,12.9061126708984,4.97625381403797,40.3099991381168,197.873488541072,28.8951105000978,1000,-0.000131827146123921,,,,,,,,,,,,,,,,,,,,,87.7415542602539,88.0361557006836,49999.6875,49999.6875,49.9632582062745,5.37916049307863,7.34542608261108,26,1,0,0,1,0.276870727539062,30.7917900085449,2,1,1,87.7415542602539,0,87.8888549804687,,,,,,,,,,,,,,,,,,,,,,,,,,,,,,,,,
,3866031570.88644,76.1840972900391,49999.6875,0.178896486009568,5.75354508241944E-5,1,2,12.9061126708984,4.97611736633296,40.3099991381168,232.050175523363,33.8981468227673,1000,-0.000145337042744084,,,,,,,,,,,,,,,,,,,,,75.9858779907227,76.3823165893555,49999.6875,49999.6875,49.9796724051784,5.37934254933041,7.28212785720825,26,1,0,0,1,0.2764892578125,31.2805480957031,2,1,1,75.9858779907227,0,76.1840972900391,,,,,,,,,,,,,,,,,,,,,,,,,,,,,,,,,
,3866031641.6205,64.0758743286133,49999.6875,0.215453028120766,9.09048434439935E-5,1,2,12.9061126708984,4.97607811863014,40.3099991381168,279.459085648015,40.8668240311882,1000,-0.000142478839435175,,,,,,,,,,,,,,,,,,,,,63.9735717773437,64.1781768798828,49999.6875,49999.6875,49.9503613357072,5.37981421614132,7.2152886390686,26,1,0,0,1,0.277633666992187,30.7917900085449,2,1,1,63.9735717773437,0,64.0758743286133,,,,,,,,,,,,,,,,,,,,,,,,,,,,,,,,,
,3866031716.34656,51.5229797363281,49999.6875,0.271634425768294,0.000126525586652325,1,2,12.9061126708984,4.97598905677437,40.3099991381168,352.305542843387,51.6325267811492,1000,-9.43580862042456E-5,,,,,,,,,,,,,,,,,,,,,51.3362884521484,51.7096710205078,49999.6875,49999.6875,49.9870978761111,5.37964125343937,7.10129070281982,26,1,0,0,1,0.27923583984375,30.7917900085449,2,1,1,51.3362884521484,0,51.5229797363281,,,,,,,,,,,,,,,,,,,,,,,,,,,,,,,,,
,3866031788.45523,39.2063407897949,49999.6875,0.350688506291157,0.000175815157522892,1,2,12.9061126708984,4.97599407838197,40.3099991381168,454.819216284623,66.7876810713938,1000,-2.28264007558869E-5,,,,,,,,,,,,,,,,,,,,,39.0182113647461,39.3944702148438,49999.6875,49999.6875,49.9976498611207,5.38031378495538,6.92519760131836,26,1,0,0,1,0.288238525390625,31.7693061828613,2,1,1,39.0182113647461,0,39.2063407897949,,,,,,,,,,,,,,,,,,,,,,,,,,,,,,,,,
,3866031860.30952,27.015549659729,49999.6875,0.458921727117875,0.000509317731508146,1,2,12.9061126708984,4.9759797918893,40.3099991381168,595.234923293342,87.0803889659159,1000,-0.000276351934445636,,,,,,,,,,,,,,,,,,,,,26.7347373962402,27.2963619232178,49999.6875,49999.6875,50.0754218987841,5.3808507737748,6.62845420837402,24,1,68,0,0,0.287933349609375,31.2805480957031,2,1,1,26.7347373962402,0,27.015549659729,,,,,,,,,,,,,,,,,,,,,,,,,,,,,,,,,
,3866031931.63298,15.302047252655,49999.6875,0.582238091303514,0.00326256596285988,1,2,12.9061126708984,4.97601329605862,40.3099991381168,755.561972719185,107.928431862724,1000,-0.00231855581885223,,,,,,,,,,,,,,,,,,,,,15.1564359664917,15.4476585388184,49999.6875,49999.6875,50.1637459214572,5.38149206739192,5.90458154678345,26,1,0,0,1,0.27740478515625,30.7917900085449,2,1,1,15.1564359664917,0,15.302047252655,,,,,,,,,,,,,,,,,,,,,,,,,,,,,,,,,
,3866032006.08008,4.30833959579468,49999.6875,0.712055385603355,0.000167576602815923,1,2,12.9061126708984,4.97603479121368,40.3099991381168,923.481761672892,135.722415785979,1000,3.98747387042112E-5,,,,,,,,,,,,,,,,,,,,,4.12718963623047,4.48948955535889,49999.6875,49999.6875,50.6213894194669,5.38400176233789,3.85469436645508,26,1,0,0,1,0.288238525390625,31.2805480957031,6,1,1,4.12718963623047,0,4.30833959579468,,,,,,,,,,,,,,,,,,,,,,,,,,,,,,,,,
,3866032078.57977,2.26268100738525,49999.6875,0.725541850277681,0.000159496789477126,1,2,12.9061126708984,4.97614357946131,40.3099991381168,940.951419893385,138.639037796964,1000,0.000304135105351058,,,,,,,,,,,,,,,,,,,,,2.26147699356079,2.26388502120972,49999.6875,49999.6875,50.9168449997361,5.38541403433741,2.68212246894836,26,1,0,0,1,0.287399291992187,30.7917900085449,6,1,1,2.26147699356079,0,2.26268100738525,,,,,,,,,,,,,,,,,,,,,,,,,,,,,,,,,
,3866032149.44142,2.23889267444611,49999.6875,0.725731833635345,0.000184122989109538,1,2,12.9061126708984,4.97609764110291,40.3099991381168,941.183228808778,138.689561907856,1000,0.000316568841969945,,,,,,,,,,,,,,,,,,,,,2.23649835586548,2.24128699302673,49999.6875,49999.6875,50.9285694275246,5.3849510276471,2.66761589050293,26,1,0,0,1,0.278472900390625,31.7693061828613,6,1,1,2.23649835586548,0,2.23889267444611,,,,,,,,,,,,,,,,,,,,,,,,,,,,,,,,,
,3866032221.58038,2.18294596672058,49999.6875,0.726035646051719,0.000164158756047087,1,2,12.9061126708984,4.97614927065531,40.3099991381168,941.592699798689,138.737949619859,1000,0.000307682458229834,,,,,,,,,,,,,,,,,,,,,2.18107175827026,2.1848201751709,49999.6875,49999.6875,50.9727314388612,5.38540716753138,2.62151527404785,26,1,0,0,1,0.287322998046875,30.7917900085449,2,1,1,2.1848201751709,0,2.18294596672058,,,,,,,,,,,,,,,,,,,,,,,,,,,,,,,,,
,3866032292.29201,1.99908953905106,49999.6875,0.726727495802216,0.000165369316005831,1,2,12.9061126708984,4.97615464655123,40.3099991381168,942.488250561359,138.891732996357,1000,0.000324450024629499,,,,,,,,,,,,,,,,,,,,,1.99880373477936,1.99937534332275,49999.6875,49999.6875,50.89261451564,5.38542028901679,2.49941158294678,26,1,0,0,1,0.277633666992187,31.2805480957031,5,1,1,1.99937534332275,0,1.99908953905106,,,,,,,,,,,,,,,,,,,,,,,,,,,,,,,,,
,3866032711.94102,10.6804671287537,26.5252590179443,0.00213871835721778,9.69599544838061E-6,1,5,12.9061126708984,5.0068041600562,40.3099991381168,2.79817476646847,0.408970856321649,100,-1.58007163090126E-6,,,,,,,,,,,,,,,,,,,,,10.3325710296631,11.0283632278442,26.5252590179443,26.5252590179443,50.0988707543611,5.38029942190543,4.97742700576782,65,1,0,0,1,0.276412963867187,31.2805480957031,6,1,1,11.0283632278442,0,10.6804671287537,,,,,,,,,,,,,,,,,,,,,,,,,,,,,,,,,
,3866032926.89219,44.0977058410645,26.5252590179443,0.000194343316374594,5.98439763214444E-8,1,5,12.9061126708984,5.00672873492833,40.3099991381168,0.254246926770689,0.0372655609730902,1,-6.44243145153612E-8,,,,,,,,,,,,,,,,,,,,,44.0894393920898,44.1059722900391,26.5252590179443,26.5252590179443,50.0996523828803,5.38073697613118,6.57324647903442,65,1,0,0,1,0.267410278320313,31.7693061828613,2,1,1,44.1059722900391,0,44.0977058410645,,,,,,,,,,,,,,,,,,,,,,,,,,,,,,,,,
,3866033134.61487,77.0223999023437,26.5252590179443,0.000141728328260286,3.61272683017903E-8,1,5,12.9061126708984,5.00672903265622,40.3099991381168,0.185422702717365,0.0271181526180855,1,-9.16436349935295E-8,,,,,,,,,,,,,,,,,,,,,77.0223999023437,77.0223999023437,26.5252590179443,26.5252590179443,50.0468924578322,5.3814132114851,6.95880937576294,65,1,0,0,1,0.267181396484375,30.7917900085449,2,1,1,77.0223999023437,0,77.0223999023437,,,,,,,,,,,,,,,,,,,,,,,,,,,,,,,,,
,3866033336.66074,110.166053771973,26.5252590179443,0.000107695131819196,3.11979244722763E-8,1,5,12.9061126708984,5.00663053076951,40.3099991381168,0.140901604676324,0.0205492273302244,1,-1.12814246763505E-7,,,,,,,,,,,,,,,,,,,,,110.166053771973,110.166053771973,26.5252590179443,26.5252590179443,50.0414210581976,5.38114189054165,7.12989377975464,65,1,0,0,1,0.277481079101562,31.7693061828613,2,1,1,110.166053771973,0,110.166053771973,,,,,,,,,,,,,,,,,,,,,,,,,,,,,,,,,
,3866033535.29156,143.06266784668,26.5252590179443,8.03714063993502E-5,2.16693735258244E-8,1,5,12.9061126708984,5.00658827618677,40.3099991381168,0.105145222390922,0.0153795342501658,1,-5.04735018043505E-8,,,,,,,,,,,,,,,,,,,,,143.06266784668,143.06266784668,26.5252590179443,26.5252590179443,50.0633066567361,5.38153617647396,7.24092054367065,65,1,0,0,1,0.277481079101562,31.2805480957031,2,1,1,143.06266784668,0,143.06266784668,,,,,,,,,,,,,,,,,,,,,,,,,,,,,,,,,
,3866033734.67765,176.026306152344,26.5252590179443,6.07650716119775E-5,1.79894340221179E-8,1,5,12.9061126708984,5.00651993568411,40.3099991381168,0.0794991816302214,0.0115914420142308,1,-6.57461416289381E-8,,,,,,,,,,,,,,,,,,,,,176.026306152344,176.026306152344,26.5252590179443,26.5252590179443,50.1113768106688,5.38219428564345,7.3194375038147,65,1,0,0,1,0.2679443359375,32.7468223571777,2,1,1,176.026306152344,0,176.026306152344,,,,,,,,,,,,,,,,,,,,,,,,,,,,,,,,,
,3866033934.29745,209.030532836914,26.5252590179443,4.4507450885454E-5,1.36064477795873E-8,1,5,12.9061126708984,5.00554714870418,40.3099991381168,0.0582145354643667,0.00848043328253538,1,-5.38333937085834E-8,,,,,,,,,,,,,,,,,,,,,209.030532836914,209.030532836914,26.5252590179443,26.5252590179443,50.0328231444861,5.38538864620299,7.40806293487549,65,1,0,0,1,0.269699096679687,31.2805480957031,2,1,1,209.030532836914,0,209.030532836914,,,,,,,,,,,,,,,,,,,,,,,,,,,,,,,,,
,3866034132.49189,242.026763916016,26.5252590179443,3.21041395452065E-5,1.00552444903289E-8,1,5,12.9061126708984,5.0052267215213,40.3099991381168,0.0419895646170302,0.00610305744235233,1,-4.91594771283833E-8,,,,,,,,,,,,,,,,,,,,,242.026763916016,242.026763916016,26.5252590179443,26.5252590179443,50.0711229419284,5.3868994938654,7.54282426834106,65,1,0,0,1,0.26947021484375,31.7693061828613,2,1,1,242.026763916016,0,242.026763916016,,,,,,,,,,,,,,,,,,,,,,,,,,,,,,,,,
,3866034331.48022,275.045227050781,26.5252590179443,2.25570291769927E-5,9.72735770890865E-9,1,5,12.9061126708984,5.00552172547119,40.3099991381168,0.0295029404001571,0.00430363197023793,1,-2.29596605259144E-8,,,,,,,,,,,,,,,,,,,,,275.045227050781,275.045227050781,26.5252590179443,26.5252590179443,50.0500189719091,5.38520946460719,7.61604690551758,65,1,0,0,1,0.270004272460938,31.7693061828613,2,1,1,275.045227050781,0,275.045227050781,,,,,,,,,,,,,,,,,,,,,,,,,,,,,,,,,
,3866036025.41515,2.00010478496552,45863.6328125,0.697800060918247,0.000152898526109333,1,2,12.9061126708984,5.00699420725928,40.3099991381168,912.792994272117,134.915855339646,1000,0.000610972152921642,,,,,,,,,,,,,,,,,,,,,2.00002884864807,2.00018072128296,45688.91796875,46038.34765625,50.8273485342842,5.38563900408339,2.54714345932007,26,1,0,0,1,0.2764892578125,30.7917900085449,1,6,1,2.00002884864807,0,2.00010478496552,,,,,,,,,,,,,,,,,,,,,,,,,,,,,,,,,
,3866036100.52002,1.99984174966812,38366.2734375,0.636926574821152,0.000136648435582275,1,2,12.9061126708984,5.00698915003928,40.3099991381168,833.159444227099,123.171320228011,1000,0.000576933101115394,,,,,,,,,,,,,,,,,,,,,1.99983811378479,1.99984538555145,38271.47265625,38461.07421875,50.6424933894861,5.38455996360247,2.53699088096619,26,1,0,0,1,0.276641845703125,30.7917900085449,1,6,1,1.99984538555145,0,1.99984174966812,,,,,,,,,,,,,,,,,,,,,,,,,,,,,,,,,
,3866036172.33438,1.99987125396729,31197.3095703125,0.568997469902053,0.000162612825562282,1,2,12.9061126708984,5.0069451226094,40.3099991381168,744.347498588759,109.660408226874,1000,0.000230162062744129,,,,,,,,,,,,,,,,,,,,,1.99981200695038,1.99993050098419,31032.6484375,31361.970703125,50.5178236406688,5.38386652194309,2.5400242805481,26,1,0,0,1,0.276336669921875,30.7917900085449,1,6,1,1.99993050098419,0,1.99987125396729,,,,,,,,,,,,,,,,,,,,,,,,,,,,,,,,,
,3866036243.75363,1.99990016222,24069.53515625,0.493160679482712,0.00014444234181947,1,2,12.9061126708984,5.00698289054872,40.3099991381168,645.122081500858,95.2127069876703,1000,0.000327128671714327,,,,,,,,,,,,,,,,,,,,,1.99985694885254,1.99994337558746,23954.765625,24184.3046875,50.2923238128707,5.38316022795945,2.53816652297974,24,1,68,0,0,0.266876220703125,30.7917900085449,1,6,1,1.99994337558746,0,1.99990016222,,,,,,,,,,,,,,,,,,,,,,,,,,,,,,,,,
,3866036316.08384,1.99994611740112,16845.921875,0.40085748157379,0.000173712511480249,1,2,12.9061126708984,5.00691328512683,40.3099991381168,524.376496326157,77.3231424380253,1000,0.000214364005151369,,,,,,,,,,,,,,,,,,,,,1.99974155426025,2.00015068054199,16756.103515625,16935.740234375,50.1977467620438,5.38221037991702,2.53491163253784,26,1,0,0,1,0.28656005859375,31.7693061828613,1,6,1,1.99974155426025,0,1.99994611740112,,,,,,,,,,,,,,,,,,,,,,,,,,,,,,,,,
,3866036386.78301,1.99971586465836,9785.53857421875,0.288283763808848,0.000207815216769758,1,2,12.9061126708984,5.00688807426838,40.3099991381168,377.111161164063,55.6136051330038,1000,0.000158511690240639,,,,,,,,,,,,,,,,,,,,,1.99954330921173,1.99988842010498,9715.615234375,9855.4619140625,50.1860223342553,5.38194056991053,2.54283332824707,26,1,0,0,1,0.27557373046875,31.2805480957031,1,6,1,1.99954330921173,0,1.99971586465836,,,,,,,,,,,,,,,,,,,,,,,,,,,,,,,,,
,3866036457.10579,2.00035774707794,2754.96655273438,0.128876666819339,0.000313635528193008,1,2,12.9061126708984,5.00682413068681,40.3099991381168,168.593560372106,24.7948045761022,1000,1.98767568687116E-5,,,,,,,,,,,,,,,,,,,,,2.00031638145447,2.00039911270142,2660.13500976562,2849.79809570313,50.1473317225534,5.38132919491555,2.5415027141571,26,1,0,0,1,0.26702880859375,30.3030319213867,1,6,1,2.00031638145447,0,2.00035774707794,,,,,,,,,,,,,,,,,,,,,,,,,,,,,,,,,
,3866036549.12581,2.00009107589722,-6440.66772460937,-0.200773390257445,0.000278341317386118,1,2,12.9061126708984,5.00683940496006,40.3099991381168,-262.647567339806,-38.6326972230121,1000,-3.50878550515212E-5,,,,,,,,,,,,,,,,,,,,,2.00007748603821,2.00010466575623,-6595.48828125,-6285.84716796875,50.1356072947649,5.38155559967507,2.52884793281555,26,1,0,0,1,0.277328491210938,31.2805480957031,1,6,1,2.00007748603821,0,2.00009107589722,,,,,,,,,,,,,,,,,,,,,,,,,,,,,,,,,
,3866036620.47896,1.99978393316269,-13581.6474609375,-0.346018591368908,0.000231191113547597,1,2,12.9061126708984,5.00691387255551,40.3099991381168,-452.659028305029,-66.6140910277827,1000,-8.49415346368549E-5,,,,,,,,,,,,,,,,,,,,,1.99975001811981,1.99981784820557,-13696.63671875,-13466.658203125,50.1825050059188,5.38199085837904,2.52044463157654,26,1,0,0,1,0.276260375976562,30.7917900085449,1,6,1,1.99981784820557,0,1.99978393316269,,,,,,,,,,,,,,,,,,,,,,,,,,,,,,,,,
,3866036692.8132,2.00007206201553,-20811.88671875,-0.451694906162308,0.000144382844158194,1,2,12.9061126708984,5.00693149971937,40.3099991381168,-590.880956266,-87.1357049047426,1000,-0.000246034831324194,,,,,,,,,,,,,,,,,,,,,1.99998390674591,2.00016021728516,-20906.818359375,-20716.955078125,50.2727830998899,5.38203762386087,2.50562715530396,26,1,0,0,1,0.276870727539062,31.2805480957031,1,6,1,2.00016021728516,0,2.00007206201553,,,,,,,,,,,,,,,,,,,,,,,,,,,,,,,,,
,3866036765.64196,2.00000208616257,-28101.9892578125,-0.536607646391892,0.000143238168060416,1,2,12.9061126708984,5.00697978385914,40.3099991381168,-701.951232580137,-103.633812577954,1000,-0.000381211187007903,,,,,,,,,,,,,,,,,,,,,1.99991428852081,2.00008988380432,-28162.103515625,-28041.875,50.4971104849092,5.383306418851,2.50195860862732,26,1,0,0,1,0.2667236328125,31.2805480957031,1,6,1,2.00008988380432,0,2.00000208616257,,,,,,,,,,,,,,,,,,,,,,,,,,,,,,,,,
,3866036835.86818,1.99307322502136,-35134.240234375,-0.606952927897391,0.00016587937528167,1,2,12.9061126708984,5.00697363148287,40.3099991381168,-793.995189329466,-117.050953939762,1000,-0.000302555563651358,,,,,,,,,,,,,,,,,,,,,1.99261999130249,1.99352645874023,-35224.390625,-35044.08984375,50.6303781474381,5.38354803886704,2.4852991104126,26,1,0,0,1,0.266876220703125,30.7917900085449,1,6,1,1.99236917495728,0,1.99307322502136,,,,,,,,,,,,,,,,,,,,,,,,,,,,,,,,,
,3866036907.74469,1.99414765834808,-42337.623046875,-0.67038935820218,0.00019003347431612,1,2,12.9061126708984,5.00700236705451,40.3099991381168,-876.907810471563,-129.828906948199,1000,-0.000749374755479631,,,,,,,,,,,,,,,,,,,,,1.99149978160858,1.99679553508759,-42487.86328125,-42187.3828125,50.7929568794381,5.38453645928184,2.44755721092224,26,1,0,0,1,0.26702880859375,31.2805480957031,1,6,1,1.99149978160858,0,1.99414765834808,,,,,,,,,,,,,,,,,,,,,,,,,,,,,,,,,
,3866036979.09047,2.00023138523102,-49484.98828125,-0.724548591174233,0.000232616511982777,1,2,12.9061126708984,5.00699605995397,40.3099991381168,-947.813789815508,-139.879836051722,1000,-0.000475575756008641,,,,,,,,,,,,,,,,,,,,,2.00006246566772,2.00040030479431,-49600.27734375,-49369.69921875,50.9227072136304,5.38487552958854,2.4291090965271,26,1,0,0,1,0.266952514648438,31.2805480957031,1,6,1,2.00040030479431,0,2.00023138523102,,,,,,,,,,,,,,,,,,,,,,,,,,,,,,,,,
,3866037051.39804,1.99985140562058,-43938.365234375,-0.682790827707238,0.000158276468725171,1,2,12.9061126708984,5.00703806305244,40.3099991381168,-893.165860242372,-132.046032083554,1000,-0.000621153567963206,,,,,,,,,,,,,,,,,,,,,1.99979722499847,1.99990558624268,-44033.109375,-43843.62109375,50.755438710515,5.38416021337238,2.43026304244995,26,1,0,0,1,0.27679443359375,30.7917900085449,5,6,1,1.99979722499847,0,1.99985140562058,,,,,,,,,,,,,,,,,,,,,,,,,,,,,,,,,
,3866037123.9231,1.99215090274811,-36701.89453125,-0.621622369108498,0.000175898438042316,1,2,12.9061126708984,5.00701194795322,40.3099991381168,-813.122797451663,-120.365620086403,1000,-0.000680110466788178,,,,,,,,,,,,,,,,,,,,,1.985191822052,1.99910998344421,-36796.9765625,-36606.8125,50.6378036183707,5.38401333931145,2.41824197769165,26,1,0,0,1,0.286331176757813,30.7917900085449,1,6,1,1.985191822052,0,1.99215090274811,,,,,,,,,,,,,,,,,,,,,,,,,,,,,,,,,
,3866037194.50997,2.00019478797913,-29650.3828125,-0.554064388155716,0.000143834363340193,1,2,12.9061126708984,5.00697159992719,40.3099991381168,-724.836289557121,-106.657325757255,1000,-0.000127898871784413,,,,,,,,,,,,,,,,,,,,,1.99979710578918,2.00059247016907,-29750.123046875,-29550.642578125,50.4685810439573,5.38341766479309,2.40797924995422,26,1,0,0,1,0.286865234375,30.7917900085449,1,6,1,1.99979710578918,0,2.00019478797913,,,,,,,,,,,,,,,,,,,,,,,,,,,,,,,,,
,3866037266.93908,2.00011897087097,-22423.453125,-0.473480635785791,0.000168609437972221,1,2,12.9061126708984,5.00699923561097,40.3099991381168,-619.370279457986,-91.484518419716,1000,-0.000368304043559506,,,,,,,,,,,,,,,,,,,,,2.00003695487976,2.00020098686218,-22513.40234375,-22333.50390625,50.381429464063,5.38316760867648,2.41604614257813,26,1,0,0,1,0.267410278320313,30.7917900085449,1,6,1,2.00003695487976,0,2.00011897087097,,,,,,,,,,,,,,,,,,,,,,,,,,,,,,,,,
,3866037337.70559,2.00005894899368,-15360.9458007813,-0.379788619912978,0.000173893603283072,1,2,12.9061126708984,5.006949352362,40.3099991381168,-496.845352052622,-73.0909591693287,1000,-7.40264649481567E-5,,,,,,,,,,,,,,,,,,,,,1.99996554851532,2.00015234947205,-15475.671875,-15246.2197265625,50.2055630472361,5.38199542661773,2.41697239875793,26,1,0,0,1,0.276718139648438,31.2805480957031,1,6,1,1.99996554851532,0,2.00005894899368,,,,,,,,,,,,,,,,,,,,,,,,,,,,,,,,,
,3866037409.95757,2.00583636760712,-8139.50634765625,-0.256475192672087,0.000202022696454956,1,2,12.9061126708984,5.00697964692684,40.3099991381168,-335.517518263163,-49.4285139083496,1000,-0.00010274291474635,,,,,,,,,,,,,,,,,,,,,1.99923086166382,2.01244187355042,-8234.337890625,-8044.6748046875,50.1535847507072,5.38171921854717,2.42138671875,26,1,0,0,1,0.266876220703125,31.7693061828613,6,6,1,1.99923086166382,0,2.00583636760712,,,,,,,,,,,,,,,,,,,,,,,,,,,,,,,,,
,3866037481.77116,2.00018566846848,-969.763977050781,-0.0681195757663148,0.000397411087996679,1,2,12.9061126708984,5.00695311311091,40.3099991381168,-89.1155130838872,-13.1074544625096,1000,-1.15299043692366E-5,,,,,,,,,,,,,,,,,,,,,1.99997580051422,2.00039553642273,-1139.52062988281,-800.00732421875,50.0734678274861,5.38152140024331,2.42056155204773,26,1,0,0,1,0.267105102539062,29.8142719268799,1,6,1,2.00039553642273,0,2.00018566846848,,,,,,,,,,,,,,,,,,,,,,,,,,,,,,,,,
,3866037571.20627,1.99983936548233,7978.66918945313,0.236706872891539,0.000258814387525124,1,2,12.9061126708984,5.00697143848863,40.3099991381168,309.675820137299,45.4847117619209,1000,-7.52546729844082E-6,,,,,,,,,,,,,,,,,,,,,1.99983751773834,1.99984121322632,7878.716796875,8078.62158203125,50.1649183642361,5.38194387009293,2.41946363449097,26,1,0,0,1,0.277099609375,31.7693061828613,1,6,1,1.99984121322632,0,1.99983936548233,,,,,,,,,,,,,,,,,,,,,,,,,,,,,,,,,
,3866037642.04752,1.99402892589569,15059.2080078125,0.369717193145464,0.000173026023651425,1,2,12.9061126708984,5.00696940545593,40.3099991381168,483.654207087156,71.2773748177915,1000,0.000167059842480298,,,,,,,,,,,,,,,,,,,,,1.9852774143219,2.00278043746948,14999.181640625,15119.234375,50.2454261017169,5.38227867232014,2.39527177810669,26,1,0,0,1,0.2764892578125,31.7693061828613,6,6,1,2.00278043746948,0,1.99402892589569,,,,,,,,,,,,,,,,,,,,,,,,,,,,,,,,,
,3866037714.52513,2.00022614002228,22311.0888671875,0.469951360380906,0.000159177296066883,1,2,12.9061126708984,5.00697541671919,40.3099991381168,614.81400280361,90.3627147989403,1000,2.97825905216725E-5,,,,,,,,,,,,,,,,,,,,,2.00022506713867,2.00022721290588,22191.0859375,22431.091796875,50.320462439563,5.38277607376424,2.39423990249634,26,1,0,0,1,0.285720825195313,30.7917900085449,1,6,1,2.00022506713867,0,2.00022614002228,,,,,,,,,,,,,,,,,,,,,,,,,,,,,,,,,
,3866037786.70236,1.99855089187622,29533.7939453125,0.551972044865048,0.000165968817673831,1,2,12.9061126708984,5.007047638659,40.3099991381168,722.080503900757,106.487464291323,1000,0.000303720439078975,,,,,,,,,,,,,,,,,,,,,1.99790501594543,1.99919676780701,29438.63671875,29628.951171875,50.498282927688,5.38363641880251,2.38347721099854,26,1,0,0,1,0.276412963867187,31.7693061828613,1,6,1,1.99790501594543,0,1.99855089187622,,,,,,,,,,,,,,,,,,,,,,,,,,,,,,,,,
,3866037857.42097,2.00289404392242,36623.625,0.620156738274426,0.000181832337767975,1,2,12.9061126708984,5.00707040497412,40.3099991381168,811.267525877548,119.752823490727,1000,0.000425532773767808,,,,,,,,,,,,,,,,,,,,,2.00255084037781,2.00323724746704,36553.40234375,36693.84765625,50.6338954757746,5.38424898941242,2.38793849945068,25,1,68,0,0,0.26702880859375,30.7917900085449,1,6,1,2.00323724746704,0,2.00289404392242,,,,,,,,,,,,,,,,,,,,,,,,,,,,,,,,,
,3866037929.81027,2.00047159194946,43878.615234375,0.681901775041871,0.000183930364808452,1,2,12.9061126708984,5.00704976980906,40.3099991381168,892.019886066143,131.778634285804,1000,0.000547047760573319,,,,,,,,,,,,,,,,,,,,,1.99989175796509,2.00105142593384,43778.4375,43978.79296875,50.8066353785246,5.38488370646374,2.38051080703735,26,1,0,0,1,0.285873413085938,32.2580642700195,1,6,1,1.99989175796509,0,2.00047159194946,,,,,,,,,,,,,,,,,,,,,,,,,,,,,,,,,
,3866038350.01231,4.02310276031494,26.1867980957031,0.0174892311296549,0.000226710563169078,1,5,12.9061126708984,4.97612329873701,40.3099991381168,22.6835422457011,3.32840449848802,1000,-3.06144170500914E-6,,,,,,,,,,,,,,,,,,,,,4.02310276031494,4.02310276031494,26.1867980957031,26.1867980957031,50.0722953847072,5.3806534324617,3.33648896217346,65,1,0,0,1,0.277786254882813,30.3030319213867,6,1,1,4.02310276031494,0,4.02310276031494,,,,,,,,,,,,,,,,,,,,,,,,,,,,,,,,,
,3866038572.93359,38.0188217163086,26.1867980957031,0.00019157609505072,5.81189549445044E-8,1,5,12.9061126708984,4.97601743892648,40.3099991381168,0.248465824117708,0.0364651331291453,1,-2.80904668343417E-8,,,,,,,,,,,,,,,,,,,,,38.0188217163086,38.0188217163086,26.1867980957031,26.1867980957031,50.0336047730053,5.38088611679704,6.41149044036865,65,1,0,0,1,0.279006958007813,30.7917900085449,2,1,1,38.0188217163086,0,38.0188217163086,,,,,,,,,,,,,,,,,,,,,,,,,,,,,,,,,
,3866038781.49952,71.0186767578125,26.1867980957031,0.000144029858321076,4.29226607037275E-8,1,5,12.9061126708984,4.97601037548365,40.3099991381168,0.186808051858033,0.0273605915956687,1,-6.3065931461624E-8,,,,,,,,,,,,,,,,,,,,,71.0186767578125,71.0186767578125,26.1867980957031,26.1867980957031,50.1156757675245,5.38072523155395,6.8914589881897,65,1,0,0,1,0.276870727539062,31.2805480957031,2,1,1,71.0186767578125,0,71.0186767578125,,,,,,,,,,,,,,,,,,,,,,,,,,,,,,,,,
,3866038984.2304,104.015907287598,26.1867980957031,0.000109975942295808,2.97057457117892E-8,1,5,12.9061126708984,4.97596237720824,40.3099991381168,0.142642808315098,0.0208576739957319,1,-7.40560232112096E-8,,,,,,,,,,,,,,,,,,,,,104.015907287598,104.015907287598,26.1867980957031,26.1867980957031,50.1469409082938,5.38082967837182,7.08938074111938,65,1,0,0,1,0.286407470703125,30.7917900085449,2,1,1,104.015907287598,0,104.015907287598,,,,,,,,,,,,,,,,,,,,,,,,,,,,,,,,,
,3866039183.89017,137.023147583008,26.1867980957031,8.228320674977E-5,2.00090541066354E-8,1,5,12.9061126708984,4.97600749777274,40.3099991381168,0.106729423700046,0.0155802909595435,1,-7.50464735065413E-8,,,,,,,,,,,,,,,,,,,,,137.023147583008,137.023147583008,26.1867980957031,26.1867980957031,50.1188022816015,5.38136875876767,7.19644737243652,65,1,0,0,1,0.288009643554687,31.7693061828613,2,1,1,137.023147583008,0,137.023147583008,,,,,,,,,,,,,,,,,,,,,,,,,,,,,,,,,
,3866039383.48146,170.011337280273,26.1867980957031,6.2035672840044E-5,1.68024832118142E-8,1,5,12.9061126708984,4.97593276566971,40.3099991381168,0.0804670002943402,0.0117303696672111,1,-6.87710533412518E-8,,,,,,,,,,,,,,,,,,,,,170.011337280273,170.011337280273,26.1867980957031,26.1867980957031,50.0910544691688,5.38177657566844,7.27620553970337,65,1,0,0,1,0.287933349609375,31.2805480957031,2,1,1,170.011337280273,0,170.011337280273,,,,,,,,,,,,,,,,,,,,,,,,,,,,,,,,,
,3866039583.25087,203.156135559082,26.1867980957031,4.61451520801066E-5,1.37515457218997E-8,1,5,12.9061126708984,4.97551895623087,40.3099991381168,0.059848381798834,0.0087238109434943,1,-5.17627316122189E-8,,,,,,,,,,,,,,,,,,,,,203.139709472656,203.172561645508,26.1867980957031,26.1867980957031,50.107077853813,5.38318171947817,7.36382579803467,65,1,0,0,1,0.288925170898438,31.7693061828613,2,1,1,203.172561645508,0,203.156135559082,,,,,,,,,,,,,,,,,,,,,,,,,,,,,,,,,
,3866039781.30751,236.032989501953,26.1867980957031,3.33377036541843E-5,1.09474694478652E-8,1,5,12.9061126708984,4.97473191684137,40.3099991381168,0.0432282206883717,0.00629976242152458,1,-3.84590493084809E-8,,,,,,,,,,,,,,,,,,,,,236.032989501953,236.032989501953,26.1867980957031,26.1867980957031,50.0480649006111,5.3865606144383,7.55392646789551,65,1,0,0,1,0.269699096679687,30.7917900085449,2,1,1,236.032989501953,0,236.032989501953,,,,,,,,,,,,,,,,,,,,,,,,,,,,,,,,,
,3866039980.50855,269.070831298828,26.1867980957031,2.40717253330897E-5,8.7109343693269E-9,1,5,12.9061126708984,4.97478952127479,40.3099991381168,0.0312142185250365,0.00454568652342491,1,-3.02191410058223E-8,,,,,,,,,,,,,,,,,,,,,269.070831298828,269.070831298828,26.1867980957031,26.1867980957031,50.0277425591111,5.38704450645971,7.79118919372559,65,1,0,0,1,0.279006958007813,32.7468223571777,2,1,1,269.070831298828,0,269.070831298828,,,,,,,,,,,,,,,,,,,,,,,,,,,,,,,,,
,3866040747.45567,299.998870849609,26.249475479126,2.04020519648833E-5,6.66518269926199E-9,1,5,12.9061126708984,4.9757004272344,40.3099991381168,0.0264615129055472,0.00386047115237628,1,-2.03916652777904E-8,,,,,,,,,,,,,,,,,,,,,299.998870849609,299.998870849609,26.249475479126,26.249475479126,50.0148456885438,5.38264872742143,8.17928600311279,65,1,0,0,1,0.28839111328125,30.3030319213867,6,1,1,299.998870849609,0,299.998870849609,,,,,,,,,,,,,,,,,,,,,,,,,,,,,,,,,
,3866040966.89827,266.961273193359,26.249475479126,2.49305405850624E-5,7.86592861595413E-9,1,5,12.9061126708984,4.97575818196442,40.3099991381168,0.0323349526598892,0.00472116841682262,1,-2.20333339078708E-8,,,,,,,,,,,,,,,,,,,,,266.961273193359,266.961273193359,26.249475479126,26.249475479126,50.0844106267553,5.38180499107216,7.98885774612427,65,1,0,0,1,0.267715454101562,30.7917900085449,2,1,1,266.961273193359,0,266.961273193359,,,,,,,,,,,,,,,,,,,,,,,,,,,,,,,,,
,3866041166.94165,233.988021850586,26.249475479126,2.97696793521849E-5,7.51696679096543E-9,1,5,12.9061126708984,4.97592037482091,40.3099991381168,0.0386166615545787,0.00561354969210309,1,-4.50309952125066E-8,,,,,,,,,,,,,,,,,,,,,233.988021850586,233.988021850586,26.249475479126,26.249475479126,50.0988707543611,5.3809645050418,7.85847043991089,65,1,0,0,1,0.277938842773438,31.2805480957031,2,1,1,233.988021850586,0,233.988021850586,,,,,,,,,,,,,,,,,,,,,,,,,,,,,,,,,
,3866041362.92211,200.999649047852,26.249475479126,3.45406904726177E-5,7.87665593655006E-9,1,5,12.9061126708984,4.97585644376658,40.3099991381168,0.0448085461875609,0.00648701351863015,1,-7.23493030183901E-8,,,,,,,,,,,,,,,,,,,,,200.999649047852,200.999649047852,26.249475479126,26.249475479126,50.1051237825149,5.38169736499722,7.77507209777832,65,1,0,0,1,0.289306640625,31.2805480957031,2,1,1,200.999649047852,0,200.999649047852,,,,,,,,,,,,,,,,,,,,,,,,,,,,,,,,,
,3866041561.71118,167.946212768555,26.249475479126,3.93541668123951E-5,7.7128876563562E-9,1,5,12.9061126708984,4.97581598181613,40.3099991381168,0.0510527360914038,0.00738819234504781,1,-8.45485882493105E-8,,,,,,,,,,,,,,,,,,,,,167.946212768555,167.946212768555,26.249475479126,26.249475479126,50.0679964278515,5.38166921667945,7.68812656402588,65,1,0,0,1,0.278549194335938,31.2805480957031,2,1,1,167.946212768555,0,167.946212768555,,,,,,,,,,,,,,,,,,,,,,,,,,,,,,,,,
,3866041759.6256,134.985244750977,26.249475479126,4.45123389544489E-5,1.02921025071745E-8,1,5,12.9061126708984,4.97591212541789,40.3099991381168,0.057737745640003,0.00841172819096511,1,-5.32719701255009E-8,,,,,,,,,,,,,,,,,,,,,134.985244750977,134.985244750977,26.249475479126,26.249475479126,50.127400195313,5.38136121924267,7.60034322738647,65,1,0,0,1,0.277557373046875,31.7693061828613,2,1,1,134.985244750977,0,134.985244750977,,,,,,,,,,,,,,,,,,,,,,,,,,,,,,,,,
,3866041956.76119,101.981903076172,26.249475479126,4.96891148565186E-5,1.6835133778666E-8,1,5,12.9061126708984,4.97594710171761,40.3099991381168,0.0644514976073657,0.00940217527469573,1,-5.01591994961138E-8,,,,,,,,,,,,,,,,,,,,,101.981903076172,101.981903076172,26.249475479126,26.249475479126,50.1754703492457,5.38124572877747,7.50763750076294,65,1,0,0,1,0.277786254882813,31.7693061828613,2,1,1,101.981903076172,0,101.981903076172,,,,,,,,,,,,,,,,,,,,,,,,,,,,,,,,,
,3866042153.57087,68.8765640258789,26.249475479126,5.46019759095997E-5,3.10421626208395E-8,1,5,12.9061126708984,4.97601830966636,40.3099991381168,0.0708221902321365,0.0103536442408296,1,-3.84258228019465E-8,,,,,,,,,,,,,,,,,,,,,68.8765640258789,68.8765640258789,26.249475479126,26.249475479126,50.1688265068322,5.38122674468195,7.35221242904663,65,1,0,0,1,0.26824951171875,31.2805480957031,2,1,1,68.8765640258789,0,68.8765640258789,,,,,,,,,,,,,,,,,,,,,,,,,,,,,,,,,
,3866042345.9044,35.9237403869629,26.249475479126,5.97497638828879E-5,1.19830493771493E-8,1,5,12.9061126708984,4.97606764874134,40.3099991381168,0.0775011723528686,0.0113238235093923,1,-4.67549957727246E-8,,,,,,,,,,,,,,,,,,,,,35.9237403869629,35.9237403869629,26.249475479126,26.249475479126,50.1356072947649,5.38157890876884,6.98492765426636,65,1,0,0,1,0.277557373046875,31.7693061828613,2,1,1,35.9237403869629,0,35.9237403869629,,,,,,,,,,,,,,,,,,,,,,,,,,,,,,,,,
,3866042604.78031,2.93633365631103,26.249475479126,8.42595821454214E-5,5.5220340347222E-8,1,5,12.9061126708984,4.97618279235996,40.3099991381168,0.109324560034864,0.0157772040578964,1,-2.14169846247037E-7,,,,,,,,,,,,,,,,,,,,,2.93633365631103,2.93633365631103,26.249475479126,26.249475479126,50.1211471671591,5.38072471044762,3.44745254516602,65,1,0,0,1,0.277633666992187,31.7693061828613,6,1,1,2.93633365631103,0,2.93633365631103,,,,,,,,,,,,,,,,,,,,,,,,,,,,,,,,,
,3866043166.75263,32.0167922973633,26.249475479126,6.11392230177297E-5,8.59976338068602E-9,1,5,12.9061126708984,4.97619506213566,40.3099991381168,0.0793079123146117,0.0115765376599606,1,-5.63501933510318E-8,,,,,,,,,,,,,,,,,,,,,32.0167922973633,32.0167922973633,26.249475479126,26.249475479126,50.1027788969572,5.38058525784963,6.31207799911499,65,1,0,0,1,0.28778076171875,31.7693061828613,2,1,1,32.0167922973633,0,32.0167922973633,,,,,,,,,,,,,,,,,,,,,,,,,,,,,,,,,
,3866043376.87,65.0859603881836,26.249475479126,5.53940838186017E-5,6.66290786060295E-9,1,5,12.9061126708984,4.97611230263395,40.3099991381168,0.0718579883059959,0.0104600505168368,1,-7.29646878584822E-8,,,,,,,,,,,,,,,,,,,,,65.0859603881836,65.0859603881836,26.249475479126,26.249475479126,50.1410786943995,5.38083148738732,6.89432525634766,65,1,0,0,1,0.277633666992187,30.7917900085449,2,1,1,65.0859603881836,0,65.0859603881836,,,,,,,,,,,,,,,,,,,,,,,,,,,,,,,,,
,3866043580.84876,98.0169906616211,26.249475479126,4.9467878986944E-5,7.96365932475997E-9,1,5,12.9061126708984,4.97606641928296,40.3099991381168,0.0641682068536859,0.00935036245931063,1,-5.78516787756124E-8,,,,,,,,,,,,,,,,,,,,,98.0169906616211,98.0169906616211,26.249475479126,26.249475479126,50.1164573960438,5.38107736714875,7.10737037658691,65,1,0,0,1,0.28717041015625,31.2805480957031,2,1,1,98.0169906616211,0,98.0169906616211,,,,,,,,,,,,,,,,,,,,,,,,,,,,,,,,,
,3866043780.18388,131.026168823242,26.249475479126,4.38033673033508E-5,1.0575051101256E-8,1,5,12.9061126708984,4.97609395441274,40.3099991381168,0.0568236939752693,0.0082601606405009,1,-6.63137769696955E-8,,,,,,,,,,,,,,,,,,,,,131.026168823242,131.026168823242,26.249475479126,26.249475479126,50.0652607280341,5.38151590864623,7.23079204559326,65,1,0,0,1,0.277557373046875,30.7917900085449,2,1,1,131.026168823242,0,131.026168823242,,,,,,,,,,,,,,,,,,,,,,,,,,,,,,,,,
,3866043979.66372,164.021820068359,26.249475479126,3.84429480926034E-5,8.17584811018179E-9,1,5,12.9061126708984,4.97605019922745,40.3099991381168,0.0498680861195408,0.0072575038780557,1,-5.18246397716495E-8,,,,,,,,,,,,,,,,,,,,,164.021820068359,164.021820068359,26.249475479126,26.249475479126,50.1715622066495,5.38137793508089,7.30863332748413,65,1,0,0,1,0.2783203125,30.7917900085449,2,1,1,164.021820068359,0,164.021820068359,,,,,,,,,,,,,,,,,,,,,,,,,,,,,,,,,
,3866044178.79807,197.002212524414,26.249475479126,3.33385303274193E-5,7.70354464554591E-9,1,5,12.9061126708984,4.97559276101743,40.3099991381168,0.0432423047196969,0.00628454193885508,1,-5.15007837310091E-8,,,,,,,,,,,,,,,,,,,,,197.002212524414,197.002212524414,26.249475479126,26.249475479126,50.0629158424764,5.38342151927437,7.38219833374023,65,1,0,0,1,0.289230346679687,31.2805480957031,2,1,1,197.002212524414,0,197.002212524414,,,,,,,,,,,,,,,,,,,,,,,,,,,,,,,,,
,3866044377.8682,230.066131591797,26.249475479126,2.84998828279285E-5,7.25925357112362E-9,1,5,12.9061126708984,4.97505321085944,40.3099991381168,0.0369613506895317,0.00536659026950347,1,-4.78928984539705E-8,,,,,,,,,,,,,,,,,,,,,230.066131591797,230.066131591797,26.249475479126,26.249475479126,50.0621342139572,5.38590696272362,7.50033760070801,65,1,0,0,1,0.27923583984375,30.7917900085449,2,1,1,230.066131591797,0,230.066131591797,,,,,,,,,,,,,,,,,,,,,,,,,,,,,,,,,
,3866044577.33076,263.113922119141,26.249475479126,2.34925595701927E-5,6.55201221465197E-9,1,5,12.9061126708984,4.97489198895214,40.3099991381168,0.0304645946318803,0.00443299354186116,1,-3.21548641615374E-8,,,,,,,,,,,,,,,,,,,,,263.113922119141,263.113922119141,26.249475479126,26.249475479126,50.0996523828803,5.38645607990388,7.78962850570679,65,1,0,0,1,0.269546508789062,31.2805480957031,2,1,1,263.113922119141,0,263.113922119141,,,,,,,,,,,,,,,,,,,,,,,,,,,,,,,,,
,3866044775.34478,296.001831054687,26.249475479126,1.86829567442263E-5,7.45521325351334E-9,1,5,12.9061126708984,4.97531560830346,40.3099991381168,0.0242302680185268,0.00352756309498211,1,-2.42543164294142E-8,,,,,,,,,,,,,,,,,,,,,296.001831054687,296.001831054687,26.249475479126,26.249475479126,50.0570536285822,5.38490400821241,7.63211107254028,65,1,0,0,1,0.289306640625,31.7693061828613,2,1,1,296.001831054687,0,296.001831054687,,,,,,,,,,,,,,,,,,,,,,,,,,,,,,,,,
,3866045058.04137,300.004165649414,42229.4296875,0.0366599296669874,9.95742590376547E-6,1,2,12.9061126708984,4.97561694069924,40.3099991381168,47.545668994703,6.94498929779589,100,-3.01865255777818E-5,,,,,,,,,,,,,,,,,,,,,300.00390625,300.004425048828,42114.52734375,42344.33203125,49.9761550768418,5.3835669428943,7.68109369277954,26,1,0,0,1,0.278244018554687,31.2805480957031,1,6,1,300.00390625,0,300.004165649414,,,,,,,,,,,,,,,,,,,,,,,,,,,,,,,,,
,3866045149.56584,300.004028320313,33089.43359375,0.0288324766776676,9.87357711632892E-6,1,2,12.9061126708984,4.97561805637178,40.3099991381168,37.3937042658838,5.46384881471112,100,-2.24158703672551E-5,,,,,,,,,,,,,,,,,,,,,300.004028320313,300.004028320313,33089.43359375,33089.43359375,49.9925692757457,5.38370326888228,7.77545690536499,26,1,0,0,1,0.288925170898438,31.2805480957031,1,6,1,300.004028320313,0,300.004028320313,,,,,,,,,,,,,,,,,,,,,,,,,,,,,,,,,
,3866045229.24352,300.002563476562,25137.0390625,0.0218752805904256,9.44938618078931E-6,1,2,12.9061126708984,4.97568104745892,40.3099991381168,28.3717394707225,4.14192958236126,100,-1.97688673128153E-5,,,,,,,,,,,,,,,,,,,,,300.002349853516,300.002777099609,25062.158203125,25211.919921875,50.1051237825149,5.38385069272608,7.8950891494751,26,1,0,0,1,0.278244018554687,31.2805480957031,1,6,1,300.002777099609,0,300.002563476562,,,,,,,,,,,,,,,,,,,,,,,,,,,,,,,,,
,3866045299.56208,300.003494262695,18118.39453125,0.0157855079549534,9.37777212326851E-6,1,2,12.9061126708984,4.97566832193044,40.3099991381168,20.4743589058262,2.9821302536228,100,-1.94576678901928E-5,,,,,,,,,,,,,,,,,,,,,300.003295898438,300.003692626953,18023.587890625,18213.201171875,50.1160665817842,5.38387587797735,8.034912109375,26,1,0,0,1,0.2880859375,31.7693061828613,1,6,1,300.003692626953,0,300.003494262695,,,,,,,,,,,,,,,,,,,,,,,,,,,,,,,,,
,3866045372.43724,300.002639770508,10838.9658203125,0.00951829764179466,9.31637492564894E-6,1,2,12.9061126708984,4.97560947543937,40.3099991381168,12.346002702767,1.79375990429432,100,-1.50993395745383E-5,,,,,,,,,,,,,,,,,,,,,300.002349853516,300.0029296875,10784.03515625,10893.896484375,50.1062962252938,5.38376669958839,8.20408344268799,26,1,0,0,1,0.288238525390625,31.2805480957031,1,6,1,300.0029296875,0,300.002639770508,,,,,,,,,,,,,,,,,,,,,,,,,,,,,,,,,
,3866045442.59627,300.000259399414,3824.51354980469,0.00341161861468403,9.38056089211662E-6,1,2,12.9061126708984,4.97559123743066,40.3099991381168,4.42730019898806,0.628107777111096,100,-1.68416229715987E-5,,,,,,,,,,,,,,,,,,,,,300.000091552734,300.000427246094,3729.6318359375,3919.39526367188,50.0660423565534,5.38405467294833,8.26633739471436,26,1,0,0,1,0.278854370117187,31.2805480957031,1,6,1,300.000427246094,0,300.000259399414,,,,,,,,,,,,,,,,,,,,,,,,,,,,,,,,,
,3866045515.12308,300.000991821289,-3422.22229003906,-0.00307772993984623,9.41612919965159E-6,1,2,12.9061126708984,4.97558926170078,40.3099991381168,-3.98987683096224,-0.594745430866875,100,-6.48331161689846E-6,,,,,,,,,,,,,,,,,,,,,300.000946044922,300.001037597656,-3517.16674804687,-3327.27783203125,50.173125463688,5.3839303101949,8.19382572174072,26,1,0,0,1,0.277862548828125,31.7693061828613,1,6,1,300.001037597656,0,300.000991821289,,,,,,,,,,,,,,,,,,,,,,,,,,,,,,,,,
,3866045589.65072,300.001754760742,-10871.3891601562,-0.00953054934717579,9.38128194343904E-6,1,2,12.9061126708984,4.97559633860542,40.3099991381168,-12.3587874501625,-1.81689635465652,10,-9.47434832007786E-7,,,,,,,,,,,,,,,,,,,,,300.001525878906,300.001983642578,-10966.33984375,-10776.4384765625,50.0980891258418,5.38397571448811,8.14768695831299,26,1,0,0,1,0.278396606445313,31.7693061828613,1,6,1,300.001525878906,0,300.001754760742,,,,,,,,,,,,,,,,,,,,,,,,,,,,,,,,,
,3866045676.28277,300.000961303711,-19536.912109375,-0.0170347580915474,9.58422625251761E-6,1,2,12.9061126708984,4.97556795118217,40.3099991381168,-22.0920901236661,-3.23140344227283,100,1.06937411281976E-5,,,,,,,,,,,,,,,,,,,,,300.000732421875,300.001190185547,-19626.873046875,-19446.951171875,50.0398578011591,5.38390138707583,8.12585258483887,26,1,0,0,1,0.278167724609375,31.7693061828613,1,6,1,300.001190185547,0,300.000961303711,,,,,,,,,,,,,,,,,,,,,,,,,,,,,,,,,
,3866045746.99707,299.999465942383,-26609.5244140625,-0.02313545361726,9.70820596119755E-6,1,2,12.9061126708984,4.97559120817233,40.3099991381168,-30.0035801046528,-4.39276144593496,100,1.13930582978091E-5,,,,,,,,,,,,,,,,,,,,,299.999389648438,299.999542236328,-26679.53515625,-26539.513671875,50.1203655386399,5.38393405775236,8.09642314910889,26,1,0,0,1,0.279312133789062,31.2805480957031,1,6,1,299.999542236328,0,299.999465942383,,,,,,,,,,,,,,,,,,,,,,,,,,,,,,,,,
,3866045819.43163,300.001571655273,-33867.568359375,-0.02941867551194,9.96257003933042E-6,1,2,12.9061126708984,4.97561334233891,40.3099991381168,-38.1537786260375,-5.57583760238535,100,2.21701668105769E-5,,,,,,,,,,,,,,,,,,,,,300.001342773438,300.001800537109,-33972.7421875,-33762.39453125,50.0902728406495,5.38341986754047,8.08236026763916,26,1,0,0,1,0.277481079101562,31.2805480957031,1,6,1,300.001342773438,0,300.001571655273,,,,,,,,,,,,,,,,,,,,,,,,,,,,,,,,,
,3866045896.10927,300.000473022461,-41551.63671875,-0.0360546357592899,9.48607805174707E-6,1,2,12.9061126708984,4.97564696059598,40.3099991381168,-46.7571808113906,-6.85662743480705,100,9.44647326527783E-6,,,,,,,,,,,,,,,,,,,,,300.000305175781,300.000640869141,-41666.7578125,-41436.515625,49.9753734483226,5.3832555025343,8.07615756988525,26,1,0,0,1,0.267486572265625,31.2805480957031,1,6,1,300.000640869141,0,300.000473022461,,,,,,,,,,,,,,,,,,,,,,,,,,,,,,,,,
,3866045987.78035,300,-49999.59765625,-0.0433929242338187,4.60559885075512E-6,1,2,12.9061126708984,4.9756966858031,40.3099991381168,-56.2751678704094,-8.24826027349093,100,1.44763092880004E-5,,,,,,,,,,,,,,,,,,,,,300,300,-49999.59765625,-49999.59765625,49.9253492230918,5.38271827933509,8.0569486618042,26,1,0,0,1,0.278244018554687,31.7693061828613,1,6,1,300,0,300,,,,,,,,,,,,,,,,,,,,,,,,,,,,,,,,,
,3866046057.44097,300.000915527344,-43064.873046875,-0.0374362979313858,1.06323368050638E-5,1,2,12.9061126708984,4.97568710898112,40.3099991381168,-48.5538282851902,-7.09020678740582,100,3.2369018499672E-5,,,,,,,,,,,,,,,,,,,,,300.000762939453,300.001068115234,-43184.5234375,-42945.22265625,49.9917876472264,5.38260147654111,8.05299377441406,26,1,0,0,1,0.288314819335937,31.2805480957031,1,6,1,300.000762939453,0,300.000915527344,,,,,,,,,,,,,,,,,,,,,,,,,,,,,,,,,
,3866046129.54108,299.999099731445,-35873.001953125,-0.031168779760551,1.04769264880991E-5,1,2,12.9061126708984,4.97568501714438,40.3099991381168,-40.4245414721221,-5.9063566970701,100,2.44952365854467E-5,,,,,,,,,,,,,,,,,,,,,299.998931884766,299.999267578125,-35967.73828125,-35778.265625,49.9714653057264,5.38257996194994,8.0440149307251,26,1,0,0,1,0.278167724609375,31.7693061828613,1,6,1,299.999267578125,0,299.999099731445,,,,,,,,,,,,,,,,,,,,,,,,,,,,,,,,,
,3866046200.43094,300.000549316406,-28796.546875,-0.0250773684823368,1.01696792748714E-5,1,2,12.9061126708984,4.97568783747067,40.3099991381168,-32.5249340633113,-4.74756941425716,100,2.3173080546124E-5,,,,,,,,,,,,,,,,,,,,,300.000457763672,300.000640869141,-28851.408203125,-28741.685546875,50.1180206530822,5.38286610373318,8.04011344909668,26,1,0,0,1,0.277252197265625,31.7693061828613,1,6,1,300.000640869141,0,300.000549316406,,,,,,,,,,,,,,,,,,,,,,,,,,,,,,,,,
,3866046272.74986,299.999496459961,-21574.0107421875,-0.0188119381277035,9.19204350860765E-6,1,2,12.9061126708984,4.97567775006029,40.3099991381168,-24.3981799554735,-3.56497754211109,100,1.46304427223692E-5,,,,,,,,,,,,,,,,,,,,,299.999328613281,299.999664306641,-21653.974609375,-21494.046875,50.0949626117649,5.38309662214097,8.03447532653809,26,1,0,0,1,0.288162231445313,31.7693061828613,1,6,1,299.999664306641,0,299.999496459961,,,,,,,,,,,,,,,,,,,,,,,,,,,,,,,,,
,3866046343.09187,300.000610351562,-14552.08203125,-0.0127167951589272,9.69482915223891E-6,1,2,12.9061126708984,4.9756771260223,40.3099991381168,-16.4937234663822,-2.40545837443683,100,1.33230254915308E-5,,,,,,,,,,,,,,,,,,,,,300.000244140625,300.0009765625,-14646.857421875,-14457.306640625,50.0719045704476,5.38296183253504,8.03236770629883,26,1,0,0,1,0.278778076171875,31.7693061828613,1,6,1,300.000244140625,0,300.000610351562,,,,,,,,,,,,,,,,,,,,,,,,,,,,,,,,,
,3866046415.97778,300.000518798828,-7269.29370117187,-0.0064341819466872,9.43804563825505E-6,1,2,12.9061126708984,4.97560159804148,40.3099991381168,-8.34658071499237,-1.20611551722601,100,1.51639097461573E-5,,,,,,,,,,,,,,,,,,,,,300.00048828125,300.000549316406,-7324.21826171875,-7214.369140625,50.1293542666111,5.3832723243821,8.02981090545654,26,1,0,0,1,0.289459228515625,31.2805480957031,1,6,1,300.000549316406,0,300.000518798828,,,,,,,,,,,,,,,,,,,,,,,,,,,,,,,,,
,3866046486.15469,300.000686645508,-259.924964904785,-0.000261505702239268,1.01493239767322E-5,1,2,12.9061126708984,4.97561524567803,40.3099991381168,-0.345124221041971,-0.00891998358640357,100,3.15394927345406E-5,,,,,,,,,,,,,,,,,,,,,300.000671386719,300.000701904297,-359.820892333984,-160.029037475586,50.1238828669765,5.3827159860402,8.0234956741333,26,1,0,0,1,0.288467407226562,31.7693061828613,1,6,1,300.000701904297,0,300.000686645508,,,,,,,,,,,,,,,,,,,,,,,,,,,,,,,,,
,3866046564.88778,300.000396728516,7613.68334960937,0.00670077515563327,9.27317371411538E-6,1,2,12.9061126708984,4.97560108970191,40.3099991381168,8.68990926985212,1.27311693173154,100,-2.66153966486683E-6,,,,,,,,,,,,,,,,,,,,,300.000305175781,300.00048828125,7538.72705078125,7688.6396484375,50.2039997901976,5.38297608551385,8.0177583694458,26,1,0,0,1,0.278244018554687,31.7693061828613,1,6,1,300.000305175781,0,300.000396728516,,,,,,,,,,,,,,,,,,,,,,,,,,,,,,,,,
,3866046651.6298,299.999526977539,16289.6865234375,0.0142076366893144,9.0348688114678E-6,1,2,12.9061126708984,4.97559995074477,40.3099991381168,18.4275026146725,2.68362241803043,100,-1.77990530112485E-5,,,,,,,,,,,,,,,,,,,,,299.999481201172,299.999572753906,16229.72265625,16349.650390625,50.0726861989668,5.38330513532285,8.02061653137207,26,1,0,0,1,0.278396606445313,31.2805480957031,1,6,1,299.999572753906,0,299.999526977539,,,,,,,,,,,,,,,,,,,,,,,,,,,,,,,,,
,3866046721.85124,299.999862670898,23316.4169921875,0.0203118085019721,9.46466214624209E-6,1,2,12.9061126708984,4.97552124936035,40.3099991381168,26.3419889069709,3.85098110783511,100,-1.43014072488488E-5,,,,,,,,,,,,,,,,,,,,,299.999633789063,300.000091552734,23221.296875,23411.537109375,50.0840198124957,5.3829351765397,8.01790714263916,26,1,0,0,1,0.288925170898438,31.7693061828613,1,6,1,299.999633789063,0,299.999862670898,,,,,,,,,,,,,,,,,,,,,,,,,,,,,,,,,
,3866046796.36726,300.00016784668,30776.52734375,0.0267709106560954,9.86821740133092E-6,1,2,12.9061126708984,4.97557251451255,40.3099991381168,34.7191372924145,5.07592078758279,100,-1.86455295844922E-5,,,,,,,,,,,,,,,,,,,,,300.000122070313,300.000213623047,30681.1875,30871.8671875,50.0855830695341,5.38311291658842,8.00937080383301,26,1,0,0,1,0.267868041992187,31.7693061828613,1,6,1,300.000213623047,0,300.00016784668,,,,,,,,,,,,,,,,,,,,,,,,,,,,,,,,,
,3866046868.22705,299.99951171875,37976.89453125,0.0330613996735916,9.84860571561753E-6,1,2,12.9061126708984,4.97555967726979,40.3099991381168,42.875958741115,6.2764036025598,100,-1.7017807826712E-5,,,,,,,,,,,,,,,,,,,,,299.999450683594,299.999572753906,37816.49609375,38137.29296875,49.9784999623995,5.38253912075432,8.00504493713379,26,1,0,0,1,0.289382934570313,32.2580642700195,1,6,1,299.999450683594,0,299.99951171875,,,,,,,,,,,,,,,,,,,,,,,,,,,,,,,,,
,3866046947.45005,299.998916625977,45912.923828125,0.039868886872481,1.0429387441324E-5,1,2,12.9061126708984,4.97556722644798,40.3099991381168,51.7034566360758,7.5752964539816,100,-1.54803260443584E-5,,,,,,,,,,,,,,,,,,,,,299.998718261719,299.999114990234,45822.7734375,46003.07421875,50.0199262739188,5.38293492602654,8.00373935699463,26,1,0,0,1,0.278396606445313,31.2805480957031,1,6,1,299.998718261719,0,299.998916625977,,,,,,,,,,,,,,,,,,,,,,,,,,,,,,,,,
,3866049930.56035,41.7333450317383,24.7953510284424,,,5,,,,40.3200015425682,,,,,2.67207268662797E-5,5.16732814662116E-8,0.0969170192772357,0.0016301486819933,8.9069087854495E-6,1.72244268266975E-8,8.90689604303471E-6,9.26590699845623E-9,1.50662168512877E-8,1.45197743441218E-8,3.00000005725119,1.00057637691498,19.98847910208,20,1,3,0.0940371110026129,0.00130123389033001,0.000440529227489606,233.85717010498,41.7324066162109,41.7338333129883,24.7953510284424,24.7953510284424,,,6.58084106445313,,1,,,,,,1,1,1,41.7333335876465,0,41.7333468094613,,,,,,,,,,,,,,,,,,,,,,,,,,,,,,,,,
,3866054350.83584,150.98560333252,24.7953510284424,,,5,,,,40.3200015425682,,,,,5.62331266234176E-6,6.00927872550599E-8,0.21441297879215,0.0082909818268583,1.87443752149526E-6,2.00309287364449E-8,1.87442439655478E-6,1.26376081830881E-8,7.01452703682721E-9,1.55412021882247E-8,3.00000005220552,1.00057637691498,19.98847910208,20,1,3,0.0197892824395059,0.000314304986594962,0.000132515648147091,268.421318054199,150.935775756836,150.999725341797,24.7953510284424,24.7953510284424,,,7.27844429016113,,1,,,,,,1,1,1,150.992385864258,0,150.983050766812,,,,,,,,,,,,,,,,,,,,,,,,,,,,,,,,,
,3866058853.29061,260.246826171875,24.7953510284424,,,5,,,,40.3200015425682,,,,,3.30264762639233E-6,7.11235981508866E-8,0.0258928082894402,0.0126855405624939,1.10088254927061E-6,2.37078662040542E-8,1.10088243685567E-6,1.91581718340834E-8,4.97505053067642E-10,1.39652200815121E-8,2.99999998054334,1.00057637691498,19.98847910208,20,1,3,0.0116230581080902,0.000146336193225552,0.000128425162984058,248.312408447266,260.189514160156,260.269348144531,24.7953510284424,24.7953510284424,,,7.84077119827271,,1,,,,,,1,1,1,260.256988525391,0,260.245227647864,,,,,,,,,,,,,,,,,,,,,,,,,,,,,,,,,
,3866060694.80817,299.99772644043,24.7953510284424,,,5,,,,40.3200015425682,,,,,2.88693920153119E-6,3.14336384545544E-9,0.3266558812941,0.000955464945721224,9.62398585860385E-7,1.04788106313651E-9,9.62382945040923E-7,5.01901000646506E-10,5.48681696688622E-9,9.19864179121104E-10,2.99973342017151,100.057640075684,10,1000,1,3,0.0100560563713385,0.00124081744845435,0.0122927036136389,197.763656616211,299.989532470703,300.007080078125,24.7953510284424,24.7953510284424,,,8.12674808502197,,1,,,,,,1,1,1,299.996490478516,0,299.998437375438,,,,,,,,,,,,,,,,,,,,,,,,,,,,,,,,,