File: LT data/Bridport/CREECH-1/Creech 318 Full sequence.dat
[Header]
; MPMS3 Data File (default extension .dat)
; Copyright (c) 2007, Quantum Design, Inc. All rights reserved.
TITLE,
FILEOPENTIME,3869996322.56049,08/18/2022,5:10 pm
BYAPP,MPMS3 w/ AC,1.0,1.1
INFO,MPMS3 Measurement Release 1.1.16 Build 424, MultiVu Release 2.3.4.19,APPNAME
INFO,Linear Motor Servo Controller,MOTOR_MODULE_NAME
INFO,3101-100 N0,MOTOR_HW_VERSION
INFO,MMC1047,MOTOR_SERIAL_NUMBER
INFO,01.04.28,MOTOR_SOFTWARE_VERSION
INFO,Quantum Design Squid Module,SQUID_MODULE_NAME
INFO,3101-501 B0,SQUID_HW_VERSION
INFO,SQM278,SQUID_SERIAL_NUMBER
INFO,01.03.04,SQUID_SOFTWARE_VERSION
INFO,Quantum Design VSM Oven,OVEN_MODULE_NAME
INFO,3101-201 A3,OVEN_HW_VERSION
INFO,OVB323,OVEN_SERIAL_NUMBER
INFO,01.07.07,OVEN_SOFTWARE_VERSION
INFO,SQUID AC,AC_MODULE_NAME
INFO,3101-401 G0,AC_HW_VERSION
INFO,SAC258,AC_SERIAL_NUMBER
INFO,SQUID AC 00.95.07,AC_SOFTWARE_VERSION
INFO,TCI127,COIL_SERIAL_NUMBER
INFO,0,MOMENT_UNITS
INFO,Sandstone,SAMPLE_MATERIAL
INFO,,SAMPLE_COMMENT
INFO,,SAMPLE_MASS
INFO,,SAMPLE_VOLUME
INFO,,SAMPLE_MOLECULAR_WEIGHT
INFO,,SAMPLE_SIZE
INFO,,SAMPLE_SHAPE
INFO,Straw,SAMPLE_HOLDER
INFO,Standard,SAMPLE_HOLDER_DETAIL
INFO,61.01,SAMPLE_OFFSET
DATATYPE,COMMENT,1
DATATYPE,TIME,2
STARTUPAXIS,X,2
STARTUPAXIS,Y1,5
FIELDGROUP, VSM,2,3,4,5,6,8,9,10,11,14,15
FIELDGROUP, DC, 2,3,4,14,56,57,58,59,60,61,62,63,64,65,66,67,68,69
FIELDGROUP, AC, 2,3,4,11,16,17,18,19,20,21,22,23,24,25,26,27,28,29,30
STARTUPGROUP, All
[Data]
Comment,Time Stamp (sec),Temperature (K),Magnetic Field (Oe),Moment (emu),M. Std. Err. (emu),Transport Action,Averaging Time (sec),Frequency (Hz),Peak Amplitude (mm),Center Position (mm),Lockin Signal' (V),Lockin Signal (V),Range,M. Quad. Signal (emu),AC Moment (emu),AC M. Std Err. (emu),AC Phase (deg),AC Phase Std. Err. (deg),AC Susceptibility (emu/Oe),AC Suscept. Std Err. (emu/Oe),AC X' (emu/Oe),AC X' Std Err. (emu/Oe),AC X'' (emu/Oe),AC X'' Std Err. (emu/Oe),AC Drive (Oe),AC Frequency (Hz),AC Averaging Time (sec),AC Cycles,AC Range,AC Measure Type,AC Signal' (V),AC Signal'' (V),AC Trim Coil Ratio,AC Trim Coil Phase,Min. Temperature (K),Max. Temperature (K),Min. Field (Oe),Max. Field (Oe),Mass (grams),Motor Lag (deg),Pressure (Torr),Measure Count,Measurement Number,SQUID Status (code),Motor Status (code),Measure Status (code),Motor Current (amps),Motor Temp. (C),Temp. Status (code),Field Status (code),Chamber Status (code),Chamber Temp (K),Redirection State,Evercool Status,Average Temp (K),Rotation Angle (deg),Rotator state,DC Moment Fixed Ctr (emu),DC Moment Err Fixed Ctr (emu),DC Moment Free Ctr (emu),DC Moment Err Free Ctr (emu),DC Fixed Fit,DC Free Fit,DC Calculated Center (mm),DC Calculated Center Err (mm),DC Scan Length (mm),DC Scan Time (s),DC Number of Points,DC Squid Drift,DC Min V (V),DC Max V (V),DC Scans per Measure,Map 01,Map 02,Map 03,Map 04,Map 05,Map 06,Map 07,Map 08,Map 09,Map 10,Map 11,Map 12,Map 13,Map 14,Map 15,Map 16
"FC",3869996746.15547
,3869997576.74962,90.3243103027344,49999.57421875,0.0771153653637732,1.88982048351726E-5,1,2,14.0008964538574,4.99278397066207,43.7199994921684,89.386717837161,13.4738713444367,100,6.48520091203151E-5,,,,,,,,,,,,,,,,,,,,,90.1525573730469,90.4960632324219,49999.57421875,49999.57421875,52.4629062107748,6.13612596843766,7.86888408660889,28,1,0,0,1,0.338821411132812,32.7468223571777,2,1,1,90.1525573730469,0,2084573184,90.3243103027344,,,,,,,,,,,,,,,,,,,,,,,,,,,,,,,,,
,3869997700.73461,69.9683685302734,49999.57421875,0.102485365428299,0.000391458601775004,1,2,14.0008964538574,4.99122285382727,43.6500012874603,118.688594961604,18.2538832950386,1000,0.000392648118019434,,,,,,,,,,,,,,,,,,,,,69.8012924194336,70.1354446411133,49999.57421875,49999.57421875,52.5969555018229,6.14272108706509,7.6994743347168,28,1,0,0,1,0.336761474609375,32.2580642700195,2,1,1,69.8012924194336,0,2084573184,69.9683685302734,,,,,,,,,,,,,,,,,,,,,,,,,,,,,,,,,
,3869997788.72199,54.9479274749756,49999.57421875,0.132643215378017,0.000540312633033723,1,2,14.0008964538574,4.98990487569273,43.6099991202354,153.753889544341,22.3073876227398,1000,-0.000622077625556763,,,,,,,,,,,,,,,,,,,,,54.7475242614746,55.1483306884766,49999.57421875,49999.57421875,52.7181079223037,6.14951593466282,7.5320873260498,28,1,0,0,1,0.33660888671875,33.7243423461914,2,1,1,54.7475242614746,0,2084573184,54.9479274749756,,,,,,,,,,,,,,,,,,,,,,,,,,,,,,,,,
,3869997852.69317,44.0268306732178,49999.57421875,0.164766620799476,6.03451974532046E-5,1,2,14.0008964538574,4.98951182455451,43.5900017619133,190.841338386632,28.5570238223754,1000,-3.85719004742291E-5,,,,,,,,,,,,,,,,,,,,,43.8309669494629,44.2226943969727,49999.57421875,49999.57421875,52.7712586616114,6.15137906965084,7.34108543395996,28,1,0,0,1,0.338058471679687,33.2355842590332,2,1,1,43.8309669494629,0,2084573184,44.0268306732178,,,,,,,,,,,,,,,,,,,,,,,,,,,,,,,,,
,3869997916.7021,33.2066307067871,49999.57421875,0.209834025251241,8.40084995730638E-5,1,2,14.0008964538574,4.98890586506543,43.5700006783009,242.973882062618,36.5321805225613,1000,9.79846184225913E-5,,,,,,,,,,,,,,,,,,,,,33.008186340332,33.4050750732422,49999.57421875,49999.57421875,52.8466858137171,6.15385863159647,7.0518946647644,28,1,0,0,1,0.337371826171875,32.7468223571777,2,1,1,33.008186340332,0,2084573184,33.2066307067871,,,,,,,,,,,,,,,,,,,,,,,,,,,,,,,,,
,3869997980.6839,22.4144859313965,49999.57421875,0.271536090373695,0.000119769133094886,1,2,14.0008964538574,4.98816208717457,43.5700006783009,314.352851120128,47.2796517332822,1000,0.00013974849304534,,,,,,,,,,,,,,,,,,,,,22.2586536407471,22.5703182220459,49999.57421875,49999.57421875,52.9854248758806,6.15728975644624,6.57549571990967,28,1,0,0,1,0.33721923828125,33.7243423461914,2,1,1,22.2586536407471,0,2084573184,22.4144859313965,,,,,,,,,,,,,,,,,,,,,,,,,,,,,,,,,
,3869998044.77145,11.970235824585,49999.57421875,0.358245753474383,0.000172964624022401,1,2,14.0008964538574,4.98776744940018,43.5599982738495,414.649354952191,62.6365267343504,1000,0.000414126892135182,,,,,,,,,,,,,,,,,,,,,11.849045753479,12.0914258956909,49999.57421875,49999.57421875,52.9834708045825,6.16041228332298,5.52145719528198,28,1,0,0,1,0.339431762695313,33.7243423461914,2,1,1,11.849045753479,0,2084573184,11.970235824585,,,,,,,,,,,,,,,,,,,,,,,,,,,,,,,,,
,3869998108.70764,2.85719442367554,49999.57421875,0.433473576342562,0.00634939572068565,1,2,14.0008964538574,4.98660337553485,43.5499995946884,502.491926692495,69.5283976340161,1000,-0.00488777618677168,,,,,,,,,,,,,,,,,,,,,2.72620248794556,2.98818635940552,49999.57421875,49999.57421875,53.5360821676787,6.1673445944865,3.37398529052734,27,1,68,0,0,0.341033935546875,33.2355842590332,6,1,1,2.72620248794556,0,2084574752,2.85719442367554,,,,,,,,,,,,,,,,,,,,,,,,,,,,,,,,,
,3869998172.69672,1.99975395202637,49999.57421875,0.449829975019787,4.26571119011484E-5,1,2,14.0008964538574,4.98550629275701,43.5499995946884,520.28866579402,78.8228924884188,1000,0.000713213278370358,,,,,,,,,,,,,,,,,,,,,1.9997398853302,1.99976801872253,49999.57421875,49999.57421875,53.6459009746307,6.1721664637801,2.5961606502533,28,1,0,0,1,0.339126586914063,33.7243423461914,5,1,1,2.00057125091553,0,2084574336,1.99975395202637,,,,,,,,,,,,,,,,,,,,,,,,,,,,,,,,,
,3869999046.44265,29.1574068069458,26.4154415130615,0.000197877082691324,4.6499653163664E-7,1,5,14.0008964538574,4.98288813106095,43.5400009155273,0.22871514058537,0.0345663276228969,1,2.42988801993233E-7,,,,,,,,,,,,,,,,,,,,,29.0900192260742,29.2247943878174,26.4154415130615,26.4154415130615,52.8713071120729,6.17558963756371,6.18960809707642,70,1,0,0,1,0.337295532226562,33.7243423461914,2,1,1,29.2247943878174,0,2084574400,29.1574068069458,,,,,,,,,,,,,,,,,,,,,,,,,,,,,,,,,
,3869999249.72097,61.003002166748,26.4154415130615,9.26019952604061E-5,2.53872316552916E-8,1,5,14.0008964538574,4.98356904370948,43.5700006783009,0.107065977424765,0.0160995547565194,1,4.46956701003699E-8,,,,,,,,,,,,,,,,,,,,,61.003002166748,61.003002166748,26.4154415130615,26.4154415130615,52.8138574159094,6.17373899953431,6.84029245376587,70,1,0,0,1,0.342025756835937,33.7243423461914,2,1,1,61.003002166748,0,2084574368,61.003002166748,,,,,,,,,,,,,,,,,,,,,,,,,,,,,,,,,
,3869999448.9863,93.0085983276367,26.4154415130615,7.02990169711739E-5,1.56887621081713E-8,1,5,14.0008964538574,4.9825715702936,43.6300002038479,0.0812596580329055,0.0121979954856227,1,1.61200126161271E-8,,,,,,,,,,,,,,,,,,,,,93.0085983276367,93.0085983276367,26.4154415130615,26.4154415130615,52.873261183371,6.17859501045425,7.07865953445435,70,1,0,0,1,0.3350830078125,34.2131004333496,2,1,1,93.0085983276367,0,2084574432,93.0085983276367,,,,,,,,,,,,,,,,,,,,,,,,,,,,,,,,,
,3869999642.55383,125.030303955078,26.4154415130615,5.2099005595901E-5,1.45822024496267E-8,1,5,14.0008964538574,4.99244945998552,43.699998408556,0.0603937005840738,0.00903630010462568,1,-1.29247527939394E-8,,,,,,,,,,,,,,,,,,,,,125.030303955078,125.030303955078,26.4154415130615,26.4154415130615,52.8666173409575,6.18129459075663,7.21227216720581,69,1,64,0,0,0.334396362304687,33.2355842590332,2,1,1,125.030303955078,0,2084574592,125.030303955078,,,,,,,,,,,,,,,,,,,,,,,,,,,,,,,,,
,3869999835.48823,157.012588500977,26.4154415130615,4.09812572704142E-5,9.82398457219987E-9,1,5,14.0008964538574,4.99182159669188,43.809998780489,0.0474970896314898,0.00710963862933668,1,-7.65936887041308E-9,,,,,,,,,,,,,,,,,,,,,157.012588500977,157.012588500977,26.4154415130615,26.4154415130615,52.7524995771498,6.18418768811098,7.31958770751953,70,1,0,0,1,0.333633422851562,34.7018585205078,2,1,1,157.012588500977,0,2084574528,157.012588500977,,,,,,,,,,,,,,,,,,,,,,,,,,,,,,,,,
,3870000029.03613,189.051956176758,26.4154415130615,3.20951260200641E-5,8.64645729768462E-9,1,5,14.0008964538574,4.99000461207982,43.919999152422,0.037179675929374,0.00556160274574671,1,-9.09375479282034E-9,,,,,,,,,,,,,,,,,,,,,189.051956176758,189.051956176758,26.4154415130615,26.4154415130615,52.8189380012844,6.18803298449566,7.43752002716065,68,1,64,0,0,0.338134765625,35.6793746948242,2,1,1,189.051956176758,0,2084574560,189.051956176758,,,,,,,,,,,,,,,,,,,,,,,,,,,,,,,,,
,3870000221.46821,221.021995544434,26.4154415130615,2.51574965804616E-5,7.59222922988241E-9,1,5,14.0008964538574,4.98680429922101,44.0599992871284,0.0291152559258708,0.00436574429202182,1,1.72477004445787E-9,,,,,,,,,,,,,,,,,,,,,221.000885009766,221.043106079102,26.4154415130615,26.4154415130615,53.2636846287268,6.20116077352129,7.61196994781494,68,1,64,0,0,0.339889526367188,34.2131004333496,2,1,1,221.043106079102,0,2084574560,221.021995544434,,,,,,,,,,,,,,,,,,,,,,,,,,,,,,,,,
,3870000414.65314,253.012985229492,26.4154415130615,1.96854955724314E-5,7.46392243419237E-9,1,5,14.0008964538574,4.99405096314361,44.2200005054474,0.022831064990937,0.00340797451671171,1,-1.17006960427325E-8,,,,,,,,,,,,,,,,,,,,,253.012985229492,253.012985229492,26.4154415130615,26.4154415130615,53.4801957285537,6.20234740739925,8.05044174194336,70,1,0,0,1,0.339584350585937,32.7468223571777,2,1,1,253.012985229492,0,2084574560,253.012985229492,,,,,,,,,,,,,,,,,,,,,,,,,,,,,,,,,
,3870000607.78169,285.078460693359,26.4154415130615,1.54108066695287E-5,6.95118990949593E-9,1,5,14.0008964538574,4.99394322196388,44.3999990820885,0.0178722038025134,0.00267168866409123,1,-5.85411517100711E-9,,,,,,,,,,,,,,,,,,,,,285.078460693359,285.078460693359,26.4154415130615,26.4154415130615,53.577508479198,6.20550495883692,8.47472763061523,69,1,64,0,0,0.3411865234375,33.7243423461914,2,1,1,285.078460693359,0,2084574496,285.078460693359,,,,,,,,,,,,,,,,,,,,,,,,,,,,,,,,,
,3870002275.93944,2.00067520141602,45498.30859375,0.4296776452293,0.00548894681520932,1,2,14.0008964538574,4.98322396849344,43.5400009155273,496.423513972735,76.8269480832982,1000,0.0020509857908604,,,,,,,,,,,,,,,,,,,,,2.00000762939453,2.0013427734375,45408.3515625,45588.265625,53.5102884265441,6.1775878881684,2.61866164207458,28,1,0,0,1,0.334854125976562,34.7018585205078,1,6,1,2.0013427734375,0,2084574400,2.00067520141602,,,,,,,,,,,,,,,,,,,,,,,,,,,,,,,,,
,3870002339.93436,2.05242598056793,39106.890625,0.34922481996001,0.0104859421728989,1,2,14.0008964538574,4.98273193530915,43.5400009155273,406.676349449421,40.6886204426995,1000,-0.0171431500846593,,,,,,,,,,,,,,,,,,,,,2.05091786384583,2.05393409729004,39016.9765625,39196.8046875,53.345755623246,6.17856221568521,2.64121675491333,26,1,68,0,0,0.335845947265625,33.2355842590332,6,6,1,2.05393409729004,0,2084574048,2.05242598056793,,,,,,,,,,,,,,,,,,,,,,,,,,,,,,,,,
,3870002403.95056,1.99987018108368,32716.412109375,0.362624331183389,0.00597860410551344,1,2,14.0008964538574,4.9825137138079,43.5400009155273,419.773964302064,58.7963939263034,1000,-0.00348422689345747,,,,,,,,,,,,,,,,,,,,,1.99943971633911,2.00030064582825,32626.50390625,32806.3203125,53.2375000733326,6.17907241469763,2.59830641746521,28,1,0,0,1,0.335845947265625,32.2580642700195,5,6,1,1.99943971633911,0,2084574208,1.99987018108368,,,,,,,,,,,,,,,,,,,,,,,,,,,,,,,,,
,3870002467.90739,1.99935811758041,26330.0380859375,0.324410024689135,0.0083496282220184,1,2,14.0008964538574,4.98241606398157,43.5400009155273,376.161182807012,48.3658589158941,1000,-0.0067790942748974,,,,,,,,,,,,,,,,,,,,,1.9990086555481,1.99970757961273,26235.119140625,26424.95703125,53.1585555928902,6.17832874919678,2.59266686439514,27,1,68,0,0,0.338211059570313,33.7243423461914,1,6,1,1.99970757961273,0,2084574176,1.99935811758041,,,,,,,,,,,,,,,,,,,,,,,,,,,,,,,,,
,3870002532.02559,2.00000077486038,19924.640625,0.302956375791796,0.00153303814410094,1,2,14.0008964538574,4.98201461854013,43.5499995946884,350.131478805988,52.5949924014632,1000,0.000100177702058998,,,,,,,,,,,,,,,,,,,,,1.99967610836029,2.00032544136047,19845.12890625,20004.15234375,53.1014967109864,6.17929669516055,2.58419466018677,27,1,68,0,0,0.343017578125,33.7243423461914,1,6,1,1.99967610836029,0,2084574176,2.00000077486038,,,,,,,,,,,,,,,,,,,,,,,,,,,,,,,,,
,3870002595.98062,1.99985986948013,13543.28515625,0.249261903521114,0.000103373257433292,1,2,14.0008964538574,4.98240804373964,43.5400009155273,288.0705767022,43.5266651406654,1000,0.000297453133161814,,,,,,,,,,,,,,,,,,,,,1.99974846839905,1.99997127056122,13453.7294921875,13632.8408203125,53.0143451310921,6.17727286788098,2.57596254348755,28,1,0,0,1,0.336685180664063,35.190616607666,5,6,1,1.99997127056122,0,2084574176,1.99985986948013,,,,,,,,,,,,,,,,,,,,,,,,,,,,,,,,,
,3870002659.8819,1.99997627735138,7157.86108398438,0.168865764226664,0.000163814716338101,1,2,14.0008964538574,4.9822400765653,43.5400009155273,195.152885146703,29.4536309704882,1000,0.000173232600656057,,,,,,,,,,,,,,,,,,,,,1.99993777275085,2.0000147819519,7068.0400390625,7247.68212890625,52.9115609808133,6.17751709644572,2.57535123825073,28,1,0,0,1,0.337066650390625,33.7243423461914,1,6,1,2.0000147819519,0,2084574304,1.99997627735138,,,,,,,,,,,,,,,,,,,,,,,,,,,,,,,,,
,3870002723.88363,2.00018405914307,756.393859863281,0.0362537732339365,0.000281453343981137,1,2,14.0008964538574,4.98226491885154,43.5400009155273,41.9071464546014,6.26004891393614,1000,-1.76531971947055E-5,,,,,,,,,,,,,,,,,,,,,2.00006055831909,2.00030755996704,661.337829589844,851.449890136719,52.8533296561306,6.17735379946446,2.57706999778748,28,1,0,0,1,0.336227416992188,33.7243423461914,1,6,1,2.00006055831909,0,2084573952,2.00018405914307,,,,,,,,,,,,,,,,,,,,,,,,,,,,,,,,,
,3870002787.89592,1.99981725215912,-5643.05883789063,-0.129839186733439,0.000203213458626923,1,2,14.0008964538574,4.98210124809628,43.5400009155273,-150.038017162065,-22.6938154340742,1000,-0.000174812869455362,,,,,,,,,,,,,,,,,,,,,1.99957418441772,2.00006031990051,-5738.09619140625,-5548.021484375,52.8212828868421,6.17795259651563,2.56948161125183,28,1,0,0,1,0.337905883789063,33.7243423461914,1,6,1,1.99957418441772,0,2084573632,1.99981725215912,,,,,,,,,,,,,,,,,,,,,,,,,,,,,,,,,
,3870002851.99549,2.0000262260437,-12049.9780273437,-0.22836147023908,0.000120340731441781,1,2,14.0008964538574,4.98205808596944,43.5400009155273,-263.885715898833,-39.9021045202167,1000,-0.000297643661671817,,,,,,,,,,,,,,,,,,,,,1.9999988079071,2.0000536441803,-12130.052734375,-11969.9033203125,52.9322741365729,6.17830970027437,2.5694363117218,28,1,0,0,1,0.336685180664063,31.7693061828613,1,6,1,2.0000536441803,0,2084574176,2.0000262260437,,,,,,,,,,,,,,,,,,,,,,,,,,,,,,,,,
,3870002915.90248,1.99982213973999,-18447.2109375,-0.290872439354474,8.93861081871609E-5,1,2,14.0008964538574,4.98210532847382,43.5400009155273,-336.121461231013,-50.8520925755169,1000,-0.00040216205000369,,,,,,,,,,,,,,,,,,,,,1.99969732761383,1.99994695186615,-18542.31640625,-18352.10546875,52.9830799903229,6.17843704545817,2.56292414665222,28,1,0,0,1,0.337905883789063,34.7018585205078,1,6,1,1.99994695186615,0,2084574048,1.99982213973999,,,,,,,,,,,,,,,,,,,,,,,,,,,,,,,,,
,3870002979.90269,2.00008928775787,-24848.59765625,-0.33630113776249,7.01809571842362E-5,1,2,14.0008964538574,4.98223709677461,43.5400009155273,-388.618828610558,-58.8816266711214,1000,-0.000538711616203813,,,,,,,,,,,,,,,,,,,,,1.99999189376831,2.00018668174744,-24933.751953125,-24763.443359375,53.1190833526691,6.17852534609819,2.56221747398376,28,1,0,0,1,0.341949462890625,35.6793746948242,1,6,1,1.99999189376831,0,2084574208,2.00008928775787,,,,,,,,,,,,,,,,,,,,,,,,,,,,,,,,,
,3870003043.94304,2.00056135654449,-31265.763671875,-0.372483871540268,6.26150941192132E-5,1,2,14.0008964538574,4.98215555605551,43.5400009155273,-430.436606659398,-65.1081468535981,1000,-0.000504032857703023,,,,,,,,,,,,,,,,,,,,,2.00036072731018,2.00076198577881,-31356.1171875,-31175.41015625,53.2718917281787,6.17949283644523,2.55043435096741,28,1,0,0,1,0.343551635742188,34.2131004333496,1,6,1,2.00036072731018,0,2084574112,2.00056135654449,,,,,,,,,,,,,,,,,,,,,,,,,,,,,,,,,
,3870003107.90033,1.99998515844345,-37674.044921875,-0.402811710337175,5.87583591415804E-5,1,2,14.0008964538574,4.98288990207401,43.5400009155273,-465.582851241638,-70.3994820223719,1000,-0.00052400114745133,,,,,,,,,,,,,,,,,,,,,1.99988806247711,2.00008225440979,-37759.2734375,-37588.81640625,53.3985155482941,6.17781615488872,2.55140471458435,28,1,0,0,1,0.343170166015625,34.2131004333496,1,6,1,1.99988806247711,0,2084574272,1.99998515844345,,,,,,,,,,,,,,,,,,,,,,,,,,,,,,,,,
,3870003171.92491,1.99984532594681,-44092.6171875,-0.428950769702469,7.06017057507211E-5,1,2,14.0008964538574,4.98307019606299,43.5400009155273,-495.79104558224,-75.1673292362576,1000,-0.00072729108754688,,,,,,,,,,,,,,,,,,,,,1.99980998039246,1.99988067150116,-44182.796875,-44002.4375,53.4043777621883,6.17765862943615,2.54516553878784,28,1,0,0,1,0.340957641601562,32.7468223571777,1,6,1,1.99980998039246,0,2084574112,1.99984532594681,,,,,,,,,,,,,,,,,,,,,,,,,,,,,,,,,
,3870003237.30138,2.00002264976501,-50000.041015625,-0.450441690585386,5.9397060285855E-5,1,2,14.0008964538574,4.98293584553694,43.5400009155273,-520.646054626876,-78.6968116643766,1000,-0.000561750454247114,,,,,,,,,,,,,,,,,,,,,2.00002264976501,2.00002264976501,-50000.36328125,-49999.71875,53.6509815600057,6.17907910097399,2.54706287384033,28,1,0,0,1,0.341644287109375,32.7468223571777,1,6,1,2.00002264976501,0,2084574272,2.00002264976501,,,,,,,,,,,,,,,,,,,,,,,,,,,,,,,,,
,3870003301.94258,1.99997222423553,-43553.3203125,-0.427269360310406,7.22046676013078E-5,1,2,14.0008964538574,4.98335062282911,43.5400009155273,-493.899521263798,-74.7924009759459,1000,-0.000649891382636153,,,,,,,,,,,,,,,,,,,,,1.99990916252136,2.00003528594971,-43643.265625,-43463.375,53.4469765164864,6.17754055903093,2.54484415054321,28,1,0,0,1,0.341033935546875,33.7243423461914,1,6,1,2.00003528594971,0,2084574272,1.99997222423553,,,,,,,,,,,,,,,,,,,,,,,,,,,,,,,,,
,3870003365.938,2.00008475780487,-37168.71875,-0.401028510102625,6.28386912201693E-5,1,2,14.0008964538574,4.98336165995894,43.5400009155273,-463.571512749641,-70.1758102505022,1000,-0.000589726241061853,,,,,,,,,,,,,,,,,,,,,1.99959468841553,2.00057482719421,-37253.23828125,-37084.19921875,53.3430199234287,6.17616545413121,2.53985190391541,28,1,0,0,1,0.340652465820313,33.7243423461914,1,6,1,1.99959468841553,0,2084574208,2.00008475780487,,,,,,,,,,,,,,,,,,,,,,,,,,,,,,,,,
,3870003429.88581,2.00002133846283,-30779.1181640625,-0.370701089369344,8.17383978089226E-5,1,2,14.0008964538574,4.98342025783737,43.5400009155273,-428.523974767773,-64.8527084252593,1000,-0.000530262545960075,,,,,,,,,,,,,,,,,,,,,1.99992775917053,2.00011491775513,-30863.591796875,-30694.64453125,53.1843493340249,6.17520611991856,2.53458333015442,28,1,0,0,1,0.34027099609375,33.7243423461914,1,6,1,1.99992775917053,0,2084574144,2.00002133846283,,,,,,,,,,,,,,,,,,,,,,,,,,,,,,,,,
,3870003493.92881,2.00024259090424,-24383.806640625,-0.334480261999708,6.70431347344268E-5,1,2,14.0008964538574,4.98359375035225,43.5400009155273,-386.675746864935,-58.4952439333952,1000,-0.000458016350941102,,,,,,,,,,,,,,,,,,,,,2.0001163482666,2.00036883354187,-24473.306640625,-24294.306640625,53.0581163281691,6.17315341567358,2.53028464317322,28,1,0,0,1,0.33935546875,34.2131004333496,1,6,1,2.0001163482666,0,2084574368,2.00024259090424,,,,,,,,,,,,,,,,,,,,,,,,,,,,,,,,,
,3870003557.83598,1.99989205598831,-18004.3037109375,-0.28942426934328,9.18320881546165E-5,1,2,14.0008964538574,4.98341256803415,43.5400009155273,-334.569755858223,-50.626282855439,1000,-0.000407728069010933,,,,,,,,,,,,,,,,,,,,,1.99982631206512,1.9999577999115,-18094.23046875,-17914.376953125,52.9506424067748,6.17393015795036,2.53172993659973,28,1,0,0,1,0.334701538085937,33.7243423461914,1,6,1,1.99982631206512,0,2084574304,1.99989205598831,,,,,,,,,,,,,,,,,,,,,,,,,,,,,,,,,
,3870003621.88452,2.0000091791153,-11608.0224609375,-0.228527146797528,0.000117887164284249,1,2,14.0008964538574,4.98342053956876,43.5400009155273,-264.180707118418,-39.9312152054649,1000,-0.000284755381447523,,,,,,,,,,,,,,,,,,,,,1.99995732307434,2.00006103515625,-11693.0537109375,-11522.9912109375,52.7521087628902,6.17304415789892,2.52615642547607,28,1,0,0,1,0.33966064453125,33.7243423461914,1,6,1,1.99995732307434,0,2084574368,2.0000091791153,,,,,,,,,,,,,,,,,,,,,,,,,,,,,,,,,
,3870003685.86275,2.00016391277313,-5216.78393554687,-0.136088480574864,0.000187882551558438,1,2,14.0008964538574,4.98357925549149,43.5499995946884,-157.330825681516,-23.7566020223467,1000,-0.000149164745874918,,,,,,,,,,,,,,,,,,,,,2.00014638900757,2.0001814365387,-5306.7841796875,-5126.78369140625,52.7603158623421,6.17222438931901,2.53227663040161,28,1,0,0,1,0.3411865234375,33.7243423461914,1,6,1,2.00014638900757,0,2084574016,2.00016391277313,,,,,,,,,,,,,,,,,,,,,,,,,,,,,,,,,
,3870003749.81514,1.99983620643616,1181.47607421875,0.0211149321805115,0.000297482670020868,1,2,14.0008964538574,4.98342260764224,43.5400009155273,24.4039559183999,3.72435208764677,1000,5.64738961280516E-5,,,,,,,,,,,,,,,,,,,,,1.99979019165039,1.99988222122192,1091.42626953125,1271.52587890625,52.7751668042075,6.1727541532912,2.52710509300232,28,1,0,0,1,0.341873168945313,35.6793746948242,1,6,1,1.99979019165039,0,2084573984,1.99983620643616,,,,,,,,,,,,,,,,,,,,,,,,,,,,,,,,,
,3870003813.89104,2.00005918741226,7586.35522460937,0.165451067585696,0.000174864213218495,1,2,14.0008964538574,4.98371901026021,43.5400009155273,191.274360288738,28.9491583702062,1000,0.00023814268066786,,,,,,,,,,,,,,,,,,,,,1.99990546703339,2.00021290779114,7501.23095703125,7671.4794921875,52.6868427815344,6.17178527412123,2.52538371086121,28,1,0,0,1,0.33935546875,33.7243423461914,1,6,1,1.99990546703339,0,2084573792,2.00005918741226,,,,,,,,,,,,,,,,,,,,,,,,,,,,,,,,,
,3870003877.87656,2.00022947788239,13988.0888671875,0.25004329693028,0.000106053863105067,1,2,14.0008964538574,4.98379268974821,43.5400009155273,289.087187519465,43.6738029274172,1000,0.000292914918126569,,,,,,,,,,,,,,,,,,,,,2.00014734268188,2.00031161308289,13902.8662109375,14073.3115234375,52.8822499113421,6.17146002649402,2.52409148216248,28,1,0,0,1,0.339126586914063,34.7018585205078,1,6,1,2.00014734268188,0,2084574272,2.00022947788239,,,,,,,,,,,,,,,,,,,,,,,,,,,,,,,,,
,3870003941.80635,2.00000751018524,20386.193359375,0.306129504312576,8.00947265369964E-5,1,2,14.0008964538574,4.98424240128464,43.5400009155273,353.966631635546,53.5390336600744,1000,0.000412375356174927,,,,,,,,,,,,,,,,,,,,,1.9999566078186,2.00005841255188,20296.0078125,20476.37890625,52.8869396824575,6.17159502929752,2.52453017234802,28,1,0,0,1,0.341873168945313,32.7468223571777,1,6,1,2.00005841255188,0,2084574272,2.00000751018524,,,,,,,,,,,,,,,,,,,,,,,,,,,,,,,,,
,3870004005.83742,2.00018668174744,26790.8017578125,0.337061018258773,0.00467750203658276,1,2,14.0008964538574,4.98422866644356,43.5400009155273,390.455192278463,54.11072164186,1000,-0.00372903537496925,,,,,,,,,,,,,,,,,,,,,2.00001907348633,2.00035429000854,26700.546875,26881.056640625,53.0760937841114,6.17181747619965,2.52228212356567,27,1,68,0,0,0.34210205078125,33.7243423461914,1,6,1,2.00001907348633,0,2084574080,2.00018668174744,,,,,,,,,,,,,,,,,,,,,,,,,,,,,,,,,
,3870004069.84852,1.99989777803421,33210.77734375,0.36792908015761,0.0069393616230093,1,2,14.0008964538574,4.9844600538764,43.5400009155273,426.253827359698,58.9833391220408,1000,-0.00414549413664331,,,,,,,,,,,,,,,,,,,,,1.99967968463898,2.00011587142944,33125.54296875,33296.01171875,53.1226006810056,6.17199296011925,2.51680898666382,27,1,68,0,0,0.34149169921875,33.7243423461914,1,6,1,1.99967968463898,0,2084574464,1.99989777803421,,,,,,,,,,,,,,,,,,,,,,,,,,,,,,,,,
,3870004133.96319,1.99999350309372,39634.9140625,0.371905678310435,0.00950504254486787,1,2,14.0008964538574,4.98450696222601,43.5400009155273,431.618922632679,54.6012634469604,1000,-0.00853097620999049,,,,,,,,,,,,,,,,,,,,,1.99993431568146,2.00005269050598,39559.734375,39710.09375,53.3098007113614,6.17218687477978,2.51822757720947,28,1,0,0,1,0.341567993164063,34.7018585205078,1,6,1,1.99993431568146,0,2084574272,1.99999350309372,,,,,,,,,,,,,,,,,,,,,,,,,,,,,,,,,
,3870004197.79542,1.99978196620941,46034.974609375,0.375032416836387,0.00986720754764329,1,2,14.0008964538574,4.98473082802687,43.5400009155273,434.499455605826,60.238962317654,1000,-0.00412844107240192,,,,,,,,,,,,,,,,,,,,,1.99969840049744,1.99986553192139,45944.66015625,46125.2890625,53.4391602312941,6.17217459750543,2.50708937644958,26,1,68,0,0,0.34088134765625,33.7243423461914,1,6,1,1.99986553192139,0,2084574304,1.99978196620941,,,,,,,,,,,,,,,,,,,,,,,,,,,,,,,,,
,3870004612.72504,11.0438585281372,26.4030799865723,0.00146144964630795,5.18890680586442E-6,1,5,14.0008964538574,5.00545742812483,43.5499995946884,1.70020271985213,0.255108632436329,100,2.41756521929791E-7,,,,,,,,,,,,,,,,,,,,,11.0438585281372,11.0438585281372,26.4030799865723,26.4030799865723,52.7001304663613,6.16754637789326,4.95901679992676,70,1,0,0,1,0.342559814453125,33.7243423461914,6,1,1,11.0438585281372,0,2084574528,11.0438585281372,,,,,,,,,,,,,,,,,,,,,,,,,,,,,,,,,
,3870004818.85554,43.0645027160645,26.4030799865723,0.000104513915250953,4.00900926932906E-8,1,5,14.0008964538574,5.00660256316228,43.5599982738495,0.121618429112402,0.018306622314057,1,6.62514410442782E-8,,,,,,,,,,,,,,,,,,,,,43.0645027160645,43.0645027160645,26.4030799865723,26.4030799865723,52.715763036746,6.16310665521241,6.49242687225342,70,1,0,0,1,0.340499877929687,33.7243423461914,2,1,1,43.0645027160645,0,2084574592,43.0645027160645,,,,,,,,,,,,,,,,,,,,,,,,,,,,,,,,,
,3870005020.54775,75.0358276367187,26.4030799865723,7.67737698653591E-5,1.72220235646441E-8,1,5,14.0008964538574,5.00551267442683,43.6099991202354,0.0893152871397379,0.0134163040556057,1,2.52269757251809E-8,,,,,,,,,,,,,,,,,,,,,75.0358276367187,75.0358276367187,26.4030799865723,26.4030799865723,52.685279524496,6.16831799865322,6.88409948348999,70,1,0,0,1,0.337753295898438,34.2131004333496,2,1,1,75.0358276367187,0,2084574528,75.0358276367187,,,,,,,,,,,,,,,,,,,,,,,,,,,,,,,,,
,3870005216.99509,107.03636932373,26.4030799865723,5.97546593273242E-5,1.56454173091079E-8,1,5,14.0008964538574,5.00406453032281,43.6599999666214,0.0694924310427949,0.0104074985779065,1,-6.56752524594145E-9,,,,,,,,,,,,,,,,,,,,,107.03636932373,107.03636932373,26.4030799865723,26.4030799865723,52.6962223237652,6.17479841162667,7.05189275741577,69,1,64,0,0,0.339508056640625,31.7693061828613,2,1,1,107.03636932373,0,2084574592,107.03636932373,,,,,,,,,,,,,,,,,,,,,,,,,,,,,,,,,
,3870005410.15704,139.041061401367,26.4030799865723,4.51134375574861E-5,1.054498906007E-8,1,5,14.0008964538574,5.00347610474029,43.7400005757809,0.0524547469349584,0.00786856515955147,1,5.72985662715408E-9,,,,,,,,,,,,,,,,,,,,,139.041061401367,139.041061401367,26.4030799865723,26.4030799865723,52.659876597621,6.17607457701479,7.16625213623047,70,1,0,0,1,0.339431762695313,34.7018585205078,2,1,1,139.041061401367,0,2084574528,139.041061401367,,,,,,,,,,,,,,,,,,,,,,,,,,,,,,,,,
,3870005603.86308,171.163177490234,26.4030799865723,3.54761501260454E-5,9.88645131731074E-9,1,5,14.0008964538574,5.00237898023374,43.8500009477138,0.0412372682710463,0.00618084594250995,1,2.80515993158676E-10,,,,,,,,,,,,,,,,,,,,,171.163177490234,171.163177490234,26.4030799865723,26.4030799865723,52.6352552992652,6.17985632030439,7.26607799530029,70,1,0,0,1,0.3411865234375,35.6793746948242,2,1,1,171.163177490234,0,2084574560,171.163177490234,,,,,,,,,,,,,,,,,,,,,,,,,,,,,,,,,
,3870005796.39958,203.033264160156,26.4030799865723,2.79953989056929E-5,8.37189409985009E-9,1,5,14.0008964538574,4.99925034928019,43.9900010824204,0.032514245230258,0.00486635943897863,1,-5.70437080233745E-9,,,,,,,,,,,,,,,,,,,,,203.033264160156,203.033264160156,26.4030799865723,26.4030799865723,53.0749213413325,6.18989550463228,7.40240907669067,68,1,64,0,0,0.3411865234375,33.7243423461914,2,1,1,203.033264160156,0,2084574624,203.033264160156,,,,,,,,,,,,,,,,,,,,,,,,,,,,,,,,,
,3870005989.07085,235.000137329102,26.4030799865723,2.19475906220136E-5,7.6212719193506E-9,1,5,14.0008964538574,4.99677142961086,44.1300012171268,0.0254729088167776,0.00381002852708683,1,-6.54891803303817E-9,,,,,,,,,,,,,,,,,,,,,235.000137329102,235.000137329102,26.4030799865723,26.4030799865723,52.9572862491883,6.19889683151154,7.71177816390991,69,1,64,0,0,0.350494384765625,33.7243423461914,2,1,1,235.000137329102,0,2084574528,235.000137329102,,,,,,,,,,,,,,,,,,,,,,,,,,,,,,,,,
,3870006181.58985,267.001708984375,26.4030799865723,1.753674302005E-5,8.63097689286423E-9,1,5,14.0008964538574,4.99432003730047,44.2899987101555,0.020338872928018,0.0030470328241335,1,-1.09098197684203E-9,,,,,,,,,,,,,,,,,,,,,267.001708984375,267.001708984375,26.4030799865723,26.4030799865723,53.3473188802845,6.20543454863872,8.33492755889893,69,1,64,0,0,0.340042114257812,33.7243423461914,2,1,1,267.001708984375,0,2084574432,267.001708984375,,,,,,,,,,,,,,,,,,,,,,,,,,,,,,,,,
,3870006384.60416,299.001617431641,26.4030799865723,1.37365188838305E-5,6.39846704038943E-9,1,5,14.0008964538574,4.99467678350659,44.4700010120869,0.0159340411555338,0.00238015616557784,1,-6.73554361669627E-9,,,,,,,,,,,,,,,,,,,,,299.001617431641,299.001617431641,26.4030799865723,26.4030799865723,53.4458040737076,6.20552398506862,8.28619289398193,70,1,0,0,1,0.3399658203125,33.7243423461914,6,1,1,299.001617431641,0,2084574720,299.001617431641,,,,,,,,,,,,,,,,,,,,,,,,,,,,,,,,,
,3870007148.32579,271.964202880859,26.4030799865723,1.807868114705E-5,2.54669328990639E-7,1,5,14.0008964538574,5.00555066813598,44.3300008773804,0.0210291891995589,0.00317925790358581,1,2.30916557518533E-8,,,,,,,,,,,,,,,,,,,,,271.964202880859,271.964202880859,26.4030799865723,26.4030799865723,53.308237454323,6.20519924479559,9.3563232421875,68,1,64,0,0,0.346527099609375,33.7243423461914,2,1,1,271.964202880859,0,2084574560,271.964202880859,,,,,,,,,,,,,,,,,,,,,,,,,,,,,,,,,
,3870007343.32227,239.982162475586,26.4030799865723,2.07178426744973E-5,8.30839925879055E-9,1,5,14.0008964538574,5.00350751504769,44.1900007426739,0.0240886308000858,0.00361917232945252,1,7.43878075192437E-9,,,,,,,,,,,,,,,,,,,,,239.982162475586,239.982162475586,26.4030799865723,26.4030799865723,53.740087211198,6.23494825150321,9.22727966308594,70,1,0,0,1,0.3509521484375,33.7243423461914,2,1,1,239.982162475586,0,2084574304,239.982162475586,,,,,,,,,,,,,,,,,,,,,,,,,,,,,,,,,
,3870007534.01433,207.978942871094,26.4030799865723,2.31296523384663E-5,6.28335185050291E-9,1,5,14.0008964538574,5.00682236779832,44.0599992871284,0.026919509429425,0.00403256418720218,1,-1.72063871893883E-9,,,,,,,,,,,,,,,,,,,,,207.978942871094,207.978942871094,26.4030799865723,26.4030799865723,52.6356461135248,6.20152916035371,8.88775062561035,69,1,64,0,0,0.343246459960937,33.7243423461914,2,1,1,207.978942871094,0,2084574240,207.978942871094,,,,,,,,,,,,,,,,,,,,,,,,,,,,,,,,,
,3870007725.50615,175.94075012207,26.4030799865723,2.59878530127823E-5,6.43010826966783E-9,1,5,14.0008964538574,5.007015528255,43.9699999988079,0.0302459865164131,0.00454232814363282,1,7.69252003261884E-9,,,,,,,,,,,,,,,,,,,,,175.94075012207,175.94075012207,26.4030799865723,26.4030799865723,52.5465404623325,6.20398938327025,8.61421966552734,70,1,0,0,1,0.342864990234375,34.2131004333496,2,1,1,175.94075012207,0,2084574016,175.94075012207,,,,,,,,,,,,,,,,,,,,,,,,,,,,,,,,,
,3870007910.21333,145.268615722656,26.4030799865723,2.90761912743286E-5,3.39298063286429E-8,1,5,14.0008964538574,5.00750962041593,43.869998306036,0.0338456893300617,0.00507836880093605,1,4.77473339101982E-9,,,,,,,,,,,,,,,,,,,,,144.879272460938,145.657958984375,26.4030799865723,26.4030799865723,52.7759484327267,6.20455065585287,8.38278484344482,70,1,0,0,1,0.342788696289063,34.2131004333496,2,1,1,144.879272460938,0,2084574272,145.268615722656,,,,,,,,,,,,,,,,,,,,,,,,,,,,,,,,,
,3870008098.32898,113.91561126709,26.4030799865723,3.22954359926482E-5,5.99409688082486E-9,1,5,14.0008964538574,5.00786929085679,43.7799990177155,0.0375971632255776,0.0056386177777465,1,3.08550110446111E-9,,,,,,,,,,,,,,,,,,,,,113.91561126709,113.91561126709,26.4030799865723,26.4030799865723,52.8298808005537,6.2035847007105,8.17598915100098,70,1,0,0,1,0.343399047851562,34.2131004333496,2,1,1,113.91561126709,0,2084574432,113.91561126709,,,,,,,,,,,,,,,,,,,,,,,,,,,,,,,,,
,3870008289.87011,81.9947052001953,26.4030799865723,3.6196130929947E-5,9.0837110225462E-9,1,5,14.0008964538574,5.00807861275585,43.6899997293949,0.0421399432771783,0.00632488865999262,1,7.63273378734377E-9,,,,,,,,,,,,,,,,,,,,,81.9947052001953,81.9947052001953,26.4030799865723,26.4030799865723,52.9080436524768,6.20305001917322,7.91991138458252,68,1,64,0,0,0.345535278320313,35.6793746948242,2,1,1,81.9947052001953,0,2084574592,81.9947052001953,,,,,,,,,,,,,,,,,,,,,,,,,,,,,,,,,
,3870008475.38982,49.9994201660156,26.4030799865723,4.21552707230517E-5,9.7305651061315E-9,1,5,14.0008964538574,5.00950584917964,43.6300002038479,0.0490968598877879,0.00737134557678897,1,1.08005186537038E-8,,,,,,,,,,,,,,,,,,,,,49.9994201660156,49.9994201660156,26.4030799865723,26.4030799865723,52.964711720121,6.19510078995574,7.56678104400635,70,1,0,0,1,0.343780517578125,34.2131004333496,2,1,1,49.9994201660156,0,2084573856,49.9994201660156,,,,,,,,,,,,,,,,,,,,,,,,,,,,,,,,,
,3870008664.02803,17.9735870361328,26.4030799865723,8.55938435452031E-5,8.69338165996858E-8,1,5,14.0008964538574,5.00941772890842,43.5700006783009,0.0996792850902137,0.0150107825337139,1,5.97589122434369E-8,,,,,,,,,,,,,,,,,,,,,17.9735870361328,17.9735870361328,26.4030799865723,26.4030799865723,52.9158599376691,6.19673185246386,6.5554051399231,69,1,64,0,0,0.341949462890625,33.2355842590332,2,1,1,17.9735870361328,0,2084574272,17.9735870361328,,,,,,,,,,,,,,,,,,,,,,,,,,,,,,,,,
,3870009042.84419,16.0215644836426,26.4030799865723,9.62278716134529E-5,8.14884532644409E-8,1,5,14.0008964538574,5.01015310154393,43.5499995946884,0.112086925389977,0.0168747035223785,1,6.33590929108734E-8,,,,,,,,,,,,,,,,,,,,,16.0215644836426,16.0215644836426,26.4030799865723,26.4030799865723,53.0073104744191,6.19456815043326,5.64944219589233,70,1,0,0,1,0.339431762695313,35.190616607666,2,1,1,16.0215644836426,0,2084574624,16.0215644836426,,,,,,,,,,,,,,,,,,,,,,,,,,,,,,,,,
,3870009248.1919,48.018970489502,26.4030799865723,4.3527896215144E-5,1.24302531030724E-8,1,5,14.0008964538574,5.01058455015769,43.5700006783009,0.0507124456632758,0.00760247530144878,1,1.55541136591413E-9,,,,,,,,,,,,,,,,,,,,,48.018970489502,48.018970489502,26.4030799865723,26.4030799865723,52.9600219490056,6.1911073095336,6.72155284881592,68,1,64,0,0,0.340042114257812,32.2580642700195,2,1,1,48.018970489502,0,2084574656,48.018970489502,,,,,,,,,,,,,,,,,,,,,,,,,,,,,,,,,
,3870009450.02897,80.0733222961426,26.4030799865723,3.66117208281773E-5,6.70627795211406E-9,1,5,14.0008964538574,5.01029401507006,43.6099991202354,0.0426504106552224,0.00639963454810517,1,6.14929232010711E-9,,,,,,,,,,,,,,,,,,,,,80.0537185668945,80.0929260253906,26.4030799865723,26.4030799865723,52.9690106769768,6.19253591001098,7.0572714805603,70,1,0,0,1,0.343856811523438,33.7243423461914,2,1,1,80.0929260253906,0,2084574496,80.0733222961426,,,,,,,,,,,,,,,,,,,,,,,,,,,,,,,,,
,3870009644.41858,112.022750854492,26.4030799865723,3.2245800609511E-5,7.08863214304334E-9,1,5,14.0008964538574,5.00955279159695,43.6800010502338,0.0375582410746828,0.00562446154358487,1,-3.90458756429972E-9,,,,,,,,,,,,,,,,,,,,,112.022750854492,112.022750854492,26.4030799865723,26.4030799865723,52.8349613859287,6.19448776309528,7.206223487854,69,1,64,0,0,0.341110229492188,34.7018585205078,2,1,1,112.022750854492,0,2084574624,112.022750854492,,,,,,,,,,,,,,,,,,,,,,,,,,,,,,,,,
,3870009837.46291,144.036895751953,26.4030799865723,2.85820681420518E-5,6.97632636999445E-9,1,5,14.0008964538574,5.00839946504449,43.7600016593933,0.0332803955454984,0.00498251879043419,1,-4.57167014959872E-9,,,,,,,,,,,,,,,,,,,,,144.036895751953,144.036895751953,26.4030799865723,26.4030799865723,52.8201104440633,6.19895620517354,7.31084823608398,70,1,0,0,1,0.339279174804687,34.2131004333496,2,1,1,144.036895751953,0,2084574368,144.036895751953,,,,,,,,,,,,,,,,,,,,,,,,,,,,,,,,,
,3870010030.8045,176.011947631836,26.4030799865723,2.51487222595915E-5,6.95768487571321E-9,1,5,14.0008964538574,5.00673811766533,43.869998306036,0.0292689292308053,0.00438308770336658,1,-3.06540338759731E-9,,,,,,,,,,,,,,,,,,,,,176.011947631836,176.011947631836,26.4030799865723,26.4030799865723,52.7556260912267,6.20831192399483,7.39670753479004,70,1,0,0,1,0.34637451171875,34.2131004333496,2,1,1,176.011947631836,0,2084574528,176.011947631836,,,,,,,,,,,,,,,,,,,,,,,,,,,,,,,,,
,3870010224.07063,208.037536621094,26.4030799865723,2.23136677055961E-5,2.36591405422815E-7,1,5,14.0008964538574,5.00214204802707,43.9999997615814,0.0259743134517869,0.0036287647735611,1,-2.22297013105817E-7,,,,,,,,,,,,,,,,,,,,,208.037536621094,208.037536621094,26.4030799865723,26.4030799865723,53.4325163888806,6.2245469510858,7.48907947540283,68,1,64,0,0,0.346603393554687,35.190616607666,2,1,1,208.037536621094,0,2084574720,208.037536621094,,,,,,,,,,,,,,,,,,,,,,,,,,,,,,,,,
,3870010417.09794,240.001358032227,26.4030799865723,1.94363126952671E-5,6.13072777394082E-9,1,5,14.0008964538574,4.99927780391469,44.1600009799004,0.0225730164191759,0.00338365937593005,1,4.09616629664641E-10,,,,,,,,,,,,,,,,,,,,,240.001358032227,240.001358032227,26.4030799865723,26.4030799865723,53.4032053194095,6.23148140349356,7.73536252975464,70,1,0,0,1,0.350341796875,34.2131004333496,2,1,1,240.001358032227,0,2084574784,240.001358032227,,,,,,,,,,,,,,,,,,,,,,,,,,,,,,,,,
,3870010609.68201,272.006286621094,26.4030799865723,1.6964781369063E-5,6.58540362995269E-9,1,5,14.0008964538574,4.99970870504227,44.3300008773804,0.0197052057136549,0.0029523538414564,1,-8.42562118501503E-10,,,,,,,,,,,,,,,,,,,,,272.006286621094,272.006286621094,26.4030799865723,26.4030799865723,53.4289990605441,6.22338740780566,8.31878852844238,68,1,64,0,0,0.349807739257812,33.7243423461914,2,1,1,272.006286621094,0,2084574496,272.006286621094,,,,,,,,,,,,,,,,,,,,,,,,,,,,,,,,,
,3870011039.31875,300.003845214844,48224.416015625,0.0191320360829707,8.43190402326662E-6,1,2,14.0008964538574,5.01128107306516,44.4799996912479,22.3098926651031,3.23768548565926,100,-8.90091928196496E-5,,,,,,,,,,,,,,,,,,,,,300.003143310547,300.004547119141,48064.51953125,48384.3125,53.3840554206883,6.21855718630875,8.01220512390137,26,1,68,0,0,0.353546142578125,34.2131004333496,1,6,1,300.003143310547,0,2084573184,300.003845214844,,,,,,,,,,,,,,,,,,,,,,,,,,,,,,,,,
,3870011111.9831,300.002365112305,40963.91015625,0.016279392423851,4.68290315663336E-6,1,2,14.0008964538574,5.01078914687017,44.4799996912479,18.9780069825675,2.77330713956331,100,-5.96466039046127E-5,,,,,,,,,,,,,,,,,,,,,300.002136230469,300.002593994141,40873.99609375,41053.82421875,53.3461464375056,6.22064204095562,8.07441139221191,26,1,68,0,0,0.351638793945313,34.7018585205078,1,6,1,300.002136230469,0,2084574400,300.002365112305,,,,,,,,,,,,,,,,,,,,,,,,,,,,,,,,,
,3870011199.98831,300.00276184082,32176.5166015625,0.0128179003458264,4.12723515401426E-6,1,2,14.0008964538574,5.01042800942828,44.4799996912479,14.9405049871111,2.18805243229837,100,-4.29688048772597E-5,,,,,,,,,,,,,,,,,,,,,300.002746582031,300.002777099609,32086.52734375,32266.505859375,53.4501030305633,6.22145213594223,8.23528480529785,26,1,68,0,0,0.350189208984375,34.2131004333496,1,6,1,300.002777099609,0,2084574304,300.00276184082,,,,,,,,,,,,,,,,,,,,,,,,,,,,,,,,,
,3870011271.98314,300.000900268555,24986.7255859375,0.0100171575618667,4.17889739561048E-5,1,2,14.0008964538574,5.01042677111216,44.4799996912479,11.670404225776,1.74705147647753,100,-1.73956660395494E-6,,,,,,,,,,,,,,,,,,,,,300.000854492188,300.000946044922,24896.744140625,25076.70703125,53.4571376872364,6.22076873008803,8.40715885162354,28,1,0,0,1,0.351486206054687,34.7018585205078,1,6,1,300.000854492188,0,2084574112,300.000900268555,,,,,,,,,,,,,,,,,,,,,,,,,,,,,,,,,
,3870011336.03674,300.00129699707,18591.2666015625,0.00745840212630088,4.4749551722663E-6,1,2,14.0008964538574,5.01029833761357,44.4799996912479,8.6940254024576,1.26745723395102,100,-2.98672721911207E-5,,,,,,,,,,,,,,,,,,,,,300.001281738281,300.001312255859,18496.28515625,18686.248046875,53.4868395709672,6.22259221788406,8.61383628845215,26,1,68,0,0,0.3485107421875,34.7018585205078,1,6,1,300.001281738281,0,2084574240,300.00129699707,,,,,,,,,,,,,,,,,,,,,,,,,,,,,,,,,
,3870011407.96112,300.000625610352,11405.203125,0.0046250350069549,1.58312647549516E-5,1,2,14.0008964538574,5.01055965672053,44.4799996912479,5.39541764854261,0.76089099311791,100,-4.00909102367543E-5,,,,,,,,,,,,,,,,,,,,,300.000549316406,300.000701904297,11315.1904296875,11495.2158203125,53.4645631581691,6.22363832934395,8.88022422790527,28,1,0,0,1,0.350189208984375,34.2131004333496,1,6,1,300.000549316406,0,2084573984,300.000625610352,,,,,,,,,,,,,,,,,,,,,,,,,,,,,,,,,
,3870011472.02728,300.001647949219,5003.89038085937,0.0021025000432776,4.13915279832189E-6,1,2,14.0008964538574,5.01095682548797,44.4799996912479,2.45724070484894,0.317510609983978,100,-4.26177255997968E-5,,,,,,,,,,,,,,,,,,,,,300.001617431641,300.001678466797,4918.8095703125,5088.97119140625,53.4989548130153,6.22248220977015,9.11150169372559,28,1,0,0,1,0.3485107421875,34.2131004333496,1,6,1,300.001617431641,0,2084574080,300.001647949219,,,,,,,,,,,,,,,,,,,,,,,,,,,,,,,,,
,3870011551.99194,300.001342773438,-2988.94348144531,-0.00125406102694761,2.76860177638698E-5,1,2,14.0008964538574,5.01059117787215,44.4799996912479,-1.44979434327242,-0.294159565640981,100,-6.45287437670308E-5,,,,,,,,,,,,,,,,,,,,,300.001312255859,300.001373291016,-3078.96240234375,-2898.92456054687,53.4247001036883,6.22573609150979,9.3970308303833,28,1,0,0,1,0.347366333007812,33.7243423461914,1,6,1,300.001342773438,0,2084573984,300.001342773438,,,,,,,,,,,,,,,,,,,,,,,,,,,,,,,,,
,3870011615.98314,300.000793457031,-9389.341796875,-0.00381294026058838,4.24179591326353E-6,1,2,14.0008964538574,5.01054377141274,44.4799996912479,-4.44004395634373,-0.680598103459928,100,-1.27081742772534E-5,,,,,,,,,,,,,,,,,,,,,300.000701904297,300.000885009766,-9479.4716796875,-9299.2119140625,53.4207919610922,6.22649868025474,9.60442638397217,28,1,0,0,1,0.347976684570313,35.6793746948242,1,6,1,300.000885009766,0,2084574112,300.000793457031,,,,,,,,,,,,,,,,,,,,,,,,,,,,,,,,,
,3870011697.98727,299.999862670898,-17597.201171875,-0.00705778564976226,4.30448574871684E-6,1,2,14.0008964538574,5.01032473741297,44.4799996912479,-8.22200618572372,-1.23337275811635,100,-9.10244881781424E-7,,,,,,,,,,,,,,,,,,,,,299.999755859375,299.999969482422,-17682.349609375,-17512.052734375,53.4672988579864,6.2276228583029,9.87876129150391,28,1,0,0,1,0.350189208984375,33.7243423461914,1,6,1,299.999969482422,0,2084574112,299.999862670898,,,,,,,,,,,,,,,,,,,,,,,,,,,,,,,,,
,3870011761.9752,300.000701904297,-23993.798828125,-0.00958394581800296,4.44935735451138E-6,1,2,14.0008964538574,5.01015176971682,44.4799996912479,-11.1646927042233,-1.67233832351102,100,8.31871418037161E-7,,,,,,,,,,,,,,,,,,,,,300.000701904297,300.000701904297,-24083.984375,-23903.61328125,53.4766784002172,6.228195948262,10.0995969772339,27,1,68,0,0,0.350418090820313,34.7018585205078,1,6,1,300.000701904297,0,2084574368,300.000701904297,,,,,,,,,,,,,,,,,,,,,,,,,,,,,,,,,
,3870011849.94628,299.999862670898,-32804.17578125,-0.0132654942321964,0.00018681084728832,1,2,14.0008964538574,5.0094958943165,44.4799996912479,-15.456830744076,-2.27299637629839,100,3.6632815989678E-5,,,,,,,,,,,,,,,,,,,,,299.999786376953,299.999938964844,-32899.3984375,-32708.953125,53.4313439461018,6.23033952631462,10.2312707901001,27,1,68,0,0,0.352935791015625,34.2131004333496,1,6,1,299.999938964844,0,2084574272,299.999862670898,,,,,,,,,,,,,,,,,,,,,,,,,,,,,,,,,
,3870011937.9198,300.000259399414,-41627.16796875,-0.0165531625142564,4.51976049607458E-6,1,2,14.0008964538574,5.00966083154363,44.4799996912479,-19.2796505591689,-2.89536174114471,100,-4.86019118886673E-6,,,,,,,,,,,,,,,,,,,,,300.000152587891,300.000366210937,-41717,-41537.3359375,53.4731610718807,6.22932714388531,10.191873550415,28,1,0,0,1,0.352859497070313,34.2131004333496,1,6,1,300.000152587891,0,2084574368,300.000259399414,,,,,,,,,,,,,,,,,,,,,,,,,,,,,,,,,
,3870012045.92458,300.000900268555,-48159.990234375,-0.0191979021161702,5.3573025654228E-6,1,2,14.0008964538574,5.00932335648824,44.4799996912479,-22.376155795532,-3.2358558798958,100,9.89341798549928E-5,,,,,,,,,,,,,,,,,,,,,300.000640869141,300.001159667969,-48244.8671875,-48075.11328125,53.3512270228807,6.22899752372711,10.1103830337524,25,1,68,0,0,0.352554321289063,34.2131004333496,1,6,1,300.001159667969,0,2084574560,300.000900268555,,,,,,,,,,,,,,,,,,,,,,,,,,,,,,,,,
,3870012109.91883,300.00032043457,-41770.12890625,-0.0166576366675227,4.88061004895263E-6,1,2,14.0008964538574,5.0092838490738,44.4799996912479,-19.4125442008608,-2.82490907379255,100,7.10296766877305E-5,,,,,,,,,,,,,,,,,,,,,300.000152587891,300.00048828125,-41865.046875,-41675.2109375,53.3316863098999,6.22907976379335,10.0666551589966,27,1,68,0,0,0.355377197265625,33.2355842590332,1,6,1,300.000152587891,0,2084574336,300.00032043457,,,,,,,,,,,,,,,,,,,,,,,,,,,,,,,,,
,3870012173.92961,300.000534057617,-35375.86328125,-0.0141335630857667,7.02907753668995E-6,1,2,14.0008964538574,5.00926807685302,44.4799996912479,-16.4710027233601,-2.39654215642947,100,6.05310434324497E-5,,,,,,,,,,,,,,,,,,,,,300.000427246094,300.000640869141,-35465.39453125,-35286.33203125,53.4278266177653,6.22858304405132,10.0306606292725,27,1,68,0,0,0.353622436523438,34.2131004333496,1,6,1,300.000640869141,0,2084574368,300.000534057617,,,,,,,,,,,,,,,,,,,,,,,,,,,,,,,,,
,3870012237.89347,300.000335693359,-28996.3671875,-0.0116096968947938,1.10364394192833E-5,1,2,14.0008964538574,5.00911763537448,44.4799996912479,-13.5285667909842,-1.97250113925837,100,4.62886816335676E-5,,,,,,,,,,,,,,,,,,,,,300.000335693359,300.000335693359,-29086.318359375,-28906.416015625,53.4344704601787,6.22965693664693,9.99338150024414,27,1,68,0,0,0.354232788085937,32.7468223571777,1,6,1,300.000335693359,0,2084574272,300.000335693359,,,,,,,,,,,,,,,,,,,,,,,,,,,,,,,,,
,3870012319.90759,300.000625610352,-20809.001953125,-0.00835836812108794,6.64265233630551E-6,1,2,14.0008964538574,5.00961548675532,44.4799996912479,-9.74206263172455,-1.41457934218251,100,3.8231626445891E-5,,,,,,,,,,,,,,,,,,,,,300.000610351562,300.000640869141,-20898.51953125,-20719.484375,53.4688621150249,6.22839557725228,9.96570205688477,27,1,68,0,0,0.351486206054687,34.2131004333496,1,6,1,300.000610351562,0,2084574336,300.000625610352,,,,,,,,,,,,,,,,,,,,,,,,,,,,,,,,,
,3870012383.9013,300.000137329102,-14414.2270507813,-0.00581986561034359,8.19317644536994E-6,1,2,14.0008964538574,5.0093753912608,44.4799996912479,-6.78456394106522,-0.973570438367612,100,3.63432970512266E-5,,,,,,,,,,,,,,,,,,,,,300.000122070313,300.000152587891,-14499.1845703125,-14329.26953125,53.3098007113614,6.22937352673501,9.93972206115723,27,1,68,0,0,0.353240966796875,33.7243423461914,1,6,1,300.000122070313,0,2084574080,300.000137329102,,,,,,,,,,,,,,,,,,,,,,,,,,,,,,,,,
,3870012457.935,299.999694824219,-7014.98046875,-0.00291956820925851,1.66782703336762E-5,1,2,14.0008964538574,5.00925277115014,44.4799996912479,-3.40483935860043,-0.478763956385265,100,2.64888651739448E-5,,,,,,,,,,,,,,,,,,,,,299.99951171875,299.999877929687,-7104.974609375,-6924.986328125,53.3465372517652,6.22999502384799,9.90735149383545,28,1,0,0,1,0.35369873046875,33.7243423461914,1,6,1,299.99951171875,0,2084574112,299.999694824219,,,,,,,,,,,,,,,,,,,,,,,,,,,,,,,,,
,3870012521.9535,299.999694824219,-618.587310791016,-0.000329182932605212,1.00003295278869E-5,1,2,14.0008964538574,5.00911726574138,44.4799996912479,-0.395901948096359,0.0262132399239898,100,7.18455478150751E-5,,,,,,,,,,,,,,,,,,,,,299.999664306641,299.999725341797,-698.556762695313,-538.617858886719,53.3664687790057,6.22981925302813,9.88713550567627,27,1,68,0,0,0.35369873046875,34.2131004333496,1,6,1,299.999725341797,0,2084574144,299.999694824219,,,,,,,,,,,,,,,,,,,,,,,,,,,,,,,,,
,3870012585.97194,300.000869750977,5781.17431640625,0.00238421685747798,5.03084521867825E-6,1,2,14.0008964538574,5.00899352385852,44.4799996912479,2.77155327300828,0.449334649666409,100,2.85065902132682E-5,,,,,,,,,,,,,,,,,,,,,300.000701904297,300.001037597656,5701.08740234375,5861.26123046875,53.3547443512172,6.23132830506325,9.87108039855957,28,1,0,0,1,0.353851318359375,32.7468223571777,1,6,1,300.001037597656,0,2084573792,300.000869750977,,,,,,,,,,,,,,,,,,,,,,,,,,,,,,,,,
,3870012657.87168,300.000152587891,12973.0102539062,0.00524838460505887,3.98190872330736E-6,1,2,14.0008964538574,5.0092755354519,44.4799996912479,6.1108214509324,0.927070472439552,100,9.40520448412179E-6,,,,,,,,,,,,,,,,,,,,,300.000122070313,300.000183105469,12882.9111328125,13063.109375,53.2988579120922,6.23036985305755,9.85694026947021,28,1,0,0,1,0.35614013671875,34.7018585205078,1,6,1,300.000183105469,0,2084574016,300.000152587891,,,,,,,,,,,,,,,,,,,,,,,,,,,,,,,,,
,3870012755.87463,300,22777.3408203125,0.00912500589750659,3.79460434532725E-6,1,2,14.0008964538574,5.00881876326182,44.4799996912479,10.6255091154158,1.59563054679552,100,2.61415659366696E-6,,,,,,,,,,,,,,,,,,,,,299.999938964844,300.000061035156,22687.279296875,22867.40234375,53.3379393380537,6.23126125965784,9.83508586883545,28,1,0,0,1,0.355148315429687,32.7468223571777,1,6,1,300.000061035156,0,2084574176,300,,,,,,,,,,,,,,,,,,,,,,,,,,,,,,,,,
,3870012819.87121,299.999435424805,29191.5478515625,0.0116598636890304,3.83238724344454E-6,1,2,14.0008964538574,5.0089663680658,44.4799996912479,13.577543891787,2.04037506068016,100,4.5480377542071E-6,,,,,,,,,,,,,,,,,,,,,299.999114990234,299.999755859375,29106.26953125,29276.826171875,53.3606065651114,6.2297395066747,9.82206916809082,28,1,0,0,1,0.35400390625,34.7018585205078,1,6,1,299.999114990234,0,2084574080,299.999435424805,,,,,,,,,,,,,,,,,,,,,,,,,,,,,,,,,
,3870012891.8267,299.999954223633,36402.802734375,0.0145158796221592,4.51626959430586E-6,1,2,14.0008964538574,5.00867391779291,44.4799996912479,16.9016918842143,2.54136707175481,100,6.88263548999121E-6,,,,,,,,,,,,,,,,,,,,,299.999786376953,300.000122070313,36312.56640625,36493.0390625,53.2668111428037,6.23191612416426,9.81005764007568,28,1,0,0,1,0.352630615234375,34.2131004333496,1,6,1,300.000122070313,0,2084574336,299.999954223633,,,,,,,,,,,,,,,,,,,,,,,,,,,,,,,,,
,3870013003.80942,300.00032043457,47629.0859375,0.018936005148846,2.29483759631521E-5,1,2,14.0008964538574,5.00872304730243,44.4799996912479,22.0459699152665,3.33285532097079,100,2.40837200076845E-5,,,,,,,,,,,,,,,,,,,,,300.000274658203,300.000366210937,47538.80859375,47719.36328125,53.3418474806499,6.23203788505623,9.78775501251221,28,1,0,0,1,0.354385375976562,35.190616607666,1,6,1,300.000274658203,0,2084574336,300.00032043457,,,,,,,,,,,,,,,,,,,,,,,,,,,,,,,,,
,3870013030.27267,300.000518798828,50000.18359375,0.0199002705330036,2.86404980706392E-6,1,2,14.0008964538574,5.00871905655189,44.4799996912479,23.1681913248148,3.5051356139222,100,2.75149735036956E-5,,,,,,,,,,,,,,,,,,,,,300.000213623047,300.000823974609,50000.1640625,50000.203125,53.3375485237941,6.23177057460506,9.79514026641846,28,1,0,0,1,0.354766845703125,34.2131004333496,1,4,1,300.000823974609,0,2084574400,300.000518798828,,,,,,,,,,,,,,,,,,,,,,,,,,,,,,,,,