File: LT data/Sherwood/K1/232-2K-300K-loop.dat
[Header]
; MPMS3 Data File (default extension .dat)
; Copyright (c) 2007, Quantum Design, Inc. All rights reserved.
TITLE,
FILEOPENTIME,3865566513.83638,06/28/2022,9:26 am
BYAPP,MPMS3 w/ AC,1.0,1.1
INFO,MPMS3 Measurement Release 1.1.16 Build 424, MultiVu Release 2.3.4.19,APPNAME
INFO,Linear Motor Servo Controller,MOTOR_MODULE_NAME
INFO,3101-100 N2,MOTOR_HW_VERSION
INFO,,MOTOR_SERIAL_NUMBER
INFO,01.04.28,MOTOR_SOFTWARE_VERSION
INFO,Quantum Design Squid Module,SQUID_MODULE_NAME
INFO,3101-501 B0,SQUID_HW_VERSION
INFO,SQM327,SQUID_SERIAL_NUMBER
INFO,01.03.04,SQUID_SOFTWARE_VERSION
INFO,Quantum Design VSM Oven,OVEN_MODULE_NAME
INFO,3101-201 A3,OVEN_HW_VERSION
INFO,OVB365,OVEN_SERIAL_NUMBER
INFO,01.07.07,OVEN_SOFTWARE_VERSION
INFO,SQUID AC,AC_MODULE_NAME
INFO,3101-401 G0,AC_HW_VERSION
INFO,SAC220,AC_SERIAL_NUMBER
INFO,SQUID AC 00.95.07,AC_SOFTWARE_VERSION
INFO,TCI344,COIL_SERIAL_NUMBER
INFO,0,MOMENT_UNITS
INFO,oil stained sst,SAMPLE_MATERIAL
INFO,,SAMPLE_COMMENT
INFO,285.13,SAMPLE_MASS
INFO,,SAMPLE_VOLUME
INFO,,SAMPLE_MOLECULAR_WEIGHT
INFO,,SAMPLE_SIZE
INFO,,SAMPLE_SHAPE
INFO,Straw,SAMPLE_HOLDER
INFO,Standard,SAMPLE_HOLDER_DETAIL
INFO,58.41,SAMPLE_OFFSET
DATATYPE,COMMENT,1
DATATYPE,TIME,2
STARTUPAXIS,X,2
STARTUPAXIS,Y1,5
FIELDGROUP, VSM,2,3,4,5,6,8,9,10,11,14,15
FIELDGROUP, DC, 2,3,4,14,56,57,58,59,60,61,62,63,64,65,66,67,68,69
FIELDGROUP, AC, 2,3,4,11,16,17,18,19,20,21,22,23,24,25,26,27,28,29,30
STARTUPGROUP, All
[Data]
Comment,Time Stamp (sec),Temperature (K),Magnetic Field (Oe),Moment (emu),M. Std. Err. (emu),Transport Action,Averaging Time (sec),Frequency (Hz),Peak Amplitude (mm),Center Position (mm),Lockin Signal' (V),Lockin Signal (V),Range,M. Quad. Signal (emu),AC Moment (emu),AC M. Std Err. (emu),AC Phase (deg),AC Phase Std. Err. (deg),AC Susceptibility (emu/Oe),AC Suscept. Std Err. (emu/Oe),AC X' (emu/Oe),AC X' Std Err. (emu/Oe),AC X'' (emu/Oe),AC X'' Std Err. (emu/Oe),AC Drive (Oe),AC Frequency (Hz),AC Averaging Time (sec),AC Cycles,AC Range,AC Measure Type,AC Signal' (V),AC Signal'' (V),AC Trim Coil Ratio,AC Trim Coil Phase,Min. Temperature (K),Max. Temperature (K),Min. Field (Oe),Max. Field (Oe),Mass (grams),Motor Lag (deg),Pressure (Torr),Measure Count,Measurement Number,SQUID Status (code),Motor Status (code),Measure Status (code),Motor Current (amps),Motor Temp. (C),Temp. Status (code),Field Status (code),Chamber Status (code),Chamber Temp (K),Redirection State,Average Temp (K),Rotation Angle (deg),Rotator state,DC Moment Fixed Ctr (emu),DC Moment Err Fixed Ctr (emu),DC Moment Free Ctr (emu),DC Moment Err Free Ctr (emu),DC Fixed Fit,DC Free Fit,DC Calculated Center (mm),DC Calculated Center Err (mm),DC Scan Length (mm),DC Scan Time (s),DC Number of Points,DC Squid Drift,DC Min V (V),DC Max V (V),DC Scans per Measure,Map 01,Map 02,Map 03,Map 04,Map 05,Map 06,Map 07,Map 08,Map 09,Map 10,Map 11,Map 12,Map 13,Map 14,Map 15,Map 16
,3865569573.5383,1.99915385246277,49999.880859375,0.076905055346289,0.0226267594318906,1,2,12.9061126708984,4.99832822029237,38.0900017917156,101.945611010132,4.01238460511729,1000,-0.00822380758307475,,,,,,,,,,,,,,,,,,,,,1.99915385246277,1.99915385246277,49999.875,49999.88671875,50.1395154373611,5.44225862775762,2.61925935745239,17,1,68,0,0,0.282135009765625,31.7693061828613,1,4,1,1.99915385246277,0,1.99915385246277,,,,,,,,,,,,,,,,,,,,,,,,,,,,,,,,,
,3865569607.39403,1.99728584289551,46865.80859375,0.0923350800023013,0.0231204931413245,1,2,12.9061126708984,4.99897560949553,38.0900017917156,124.217638018213,-7.40490033426241,1000,-0.019237820992638,,,,,,,,,,,,,,,,,,,,,1.99482691287994,1.99974477291107,46766.1015625,46965.515625,50.1571020790438,5.43744793459088,2.5968074798584,19,1,68,0,0,0.279693603515625,31.2805480957031,1,6,1,1.99482691287994,0,1.99728584289551,,,,,,,,,,,,,,,,,,,,,,,,,,,,,,,,,
,3865569641.63472,1.99889492988586,43446.482421875,0.127315567044097,0.0192498532098709,1,2,12.9061126708984,4.99905857304663,38.0900017917156,169.000801203939,5.30771651986944,1000,-0.0146379812233525,,,,,,,,,,,,,,,,,,,,,1.99802851676941,1.99976134300232,43351.625,43541.33984375,50.0906636549092,5.43809409780449,2.60349726676941,17,1,68,0,0,0.277099609375,30.7917900085449,1,6,1,1.99802851676941,0,1.99889492988586,,,,,,,,,,,,,,,,,,,,,,,,,,,,,,,,,
,3865569677.19256,1.99948632717133,39897.40625,0.117095585096022,0.0193820550036877,1,2,12.9061126708984,4.99932301135584,38.1000004708767,154.241564550287,13.081407138665,1000,-0.00718212358484648,,,,,,,,,,,,,,,,,,,,,1.99911224842072,1.99986040592194,39737.55859375,40057.25390625,50.0242252307745,5.43636799764307,2.59363007545471,19,1,68,0,0,0.286788940429687,31.2805480957031,1,6,1,1.99911224842072,0,1.99948632717133,,,,,,,,,,,,,,,,,,,,,,,,,,,,,,,,,
,3865569712.42046,2.00038939714432,36383.109375,0.13037054441502,0.0181946536813594,1,2,12.9061126708984,4.99964933057661,38.0900017917156,171.374006817141,17.0802449102183,1000,-0.00607040340833864,,,,,,,,,,,,,,,,,,,,,1.9993759393692,2.00140285491943,36323.18359375,36443.03515625,50.0132824315053,5.43372928020079,2.58497738838196,18,1,68,0,0,0.285873413085938,31.2805480957031,1,6,1,2.00120186805725,0,2.00038939714432,,,,,,,,,,,,,,,,,,,,,,,,,,,,,,,,,
,3865569748.38614,2.00047159194946,32788.517578125,0.123123814583831,0.0174944105142373,1,2,12.9061126708984,4.99924501986593,38.0900017917156,163.983091793517,1.47146839356084,1000,-0.0169610513631324,,,,,,,,,,,,,,,,,,,,,1.99982762336731,2.00111556053162,32698.6875,32878.34765625,49.839760900236,5.43568588312429,2.58523035049438,20,1,68,0,0,0.278549194335938,31.2805480957031,1,6,1,2.00111556053162,0,2.00047159194946,,,,,,,,,,,,,,,,,,,,,,,,,,,,,,,,,
,3865569784.99921,1.99934452772141,29134.8564453125,0.154382305875644,0.0176293945662893,1,2,12.9061126708984,4.99926766762622,38.0900017917156,199.900063774586,40.7537724987877,1000,0.00853786603194187,,,,,,,,,,,,,,,,,,,,,1.99925875663757,1.99943029880524,29075.029296875,29194.68359375,49.8010702885341,5.43552908976113,2.59137558937073,21,1,68,0,0,0.270233154296875,30.7917900085449,1,6,1,1.99925875663757,0,1.99934452772141,,,,,,,,,,,,,,,,,,,,,,,,,,,,,,,,,
,3865569816.88896,2.00036370754242,25950.478515625,0.136077075649172,0.0201641411724565,1,2,12.9061126708984,4.99994985716819,38.0900017917156,175.226582603433,42.7683233559471,1000,0.0127640355299054,,,,,,,,,,,,,,,,,,,,,2.00026607513428,2.00046133995056,25850.68359375,26050.2734375,49.8018519170534,5.43242605281699,2.58169054985046,22,1,68,0,0,0.27587890625,31.2805480957031,1,6,1,2.00046133995056,0,2.00036370754242,,,,,,,,,,,,,,,,,,,,,,,,,,,,,,,,,
,3865569853.16395,2.00051736831665,22331.5419921875,0.215992648113941,0.0128910383232284,1,2,12.9061126708984,4.99898002836232,38.1000004708767,274.796424586548,90.0705187802445,1000,0.0372699439907432,,,,,,,,,,,,,,,,,,,,,2.000084400177,2.0009503364563,22236.728515625,22426.35546875,49.6420088848706,5.43596116678514,2.59355115890503,22,1,68,0,0,0.28717041015625,30.3030319213867,1,6,1,2.000084400177,0,2.00051736831665,,,,,,,,,,,,,,,,,,,,,,,,,,,,,,,,,
,3865569889.50606,1.99992114305496,18697.4873046875,0.18625479112857,0.0119446928342399,1,2,12.9061126708984,5.00026124875924,38.0900017917156,237.552634244762,74.259415121423,1000,0.0295057019954789,,,,,,,,,,,,,,,,,,,,,1.99929893016815,2.00054335594177,18592.52734375,18802.447265625,49.5724439466591,5.42873703132138,2.57696151733398,21,1,68,0,0,0.2838134765625,31.7693061828613,1,6,1,2.00054335594177,0,1.99992114305496,,,,,,,,,,,,,,,,,,,,,,,,,,,,,,,,,
,3865569923.66726,1.99970465898514,15287.9575195313,0.17762662137184,0.0136591048769793,1,2,12.9061126708984,4.99971373902306,38.0900017917156,228.449684410028,57.6283355011137,1000,0.0180438039884548,,,,,,,,,,,,,,,,,,,,,1.99967992305756,1.99972939491272,15198.1083984375,15377.806640625,49.6533424983995,5.43173616234308,2.59132146835327,23,1,68,0,0,0.278396606445313,30.7917900085449,1,6,1,1.99967992305756,0,1.99970465898514,,,,,,,,,,,,,,,,,,,,,,,,,,,,,,,,,
,3865569959.92282,2.00067788362503,11668.1430664062,0.193431533701463,0.0115127161132909,1,2,12.9061126708984,4.9999320573388,38.0900017917156,247.716097023924,70.0830886386701,1000,0.0252580384298106,,,,,,,,,,,,,,,,,,,,,1.99987876415253,2.00147700309753,11573.298828125,11762.9873046875,49.5259370497649,5.43282075269811,2.59344601631165,22,1,68,0,0,0.269546508789062,30.7917900085449,1,6,1,2.00147700309753,0,2.00067788362503,,,,,,,,,,,,,,,,,,,,,,,,,,,,,,,,,
,3865569994.14304,1.99888706207275,8250.65283203125,0.183611076313942,0.0075349501253179,1,2,12.9061126708984,5.00046283792248,38.0900017917156,233.675405956972,76.7396081186179,1000,0.0317901300723003,,,,,,,,,,,,,,,,,,,,,1.99799680709839,1.99977731704712,8155.8525390625,8345.453125,49.6353650424572,5.43017291825291,2.5787136554718,22,1,68,0,0,0.28472900390625,31.2805480957031,1,6,1,1.99977731704712,0,1.99888706207275,,,,,,,,,,,,,,,,,,,,,,,,,,,,,,,,,
,3865570030.41387,1.99710726737976,4623.21728515625,0.146316164246797,0.00734682782741604,1,2,12.9061126708984,4.99957063010567,38.0900017917156,188.954860242349,42.1464896380502,1000,0.0107869831083685,,,,,,,,,,,,,,,,,,,,,1.99354839324951,2.00066614151001,4528.3857421875,4718.048828125,49.4614526969283,5.43301912607295,2.5886709690094,24,1,68,0,0,0.279159545898438,31.7693061828613,1,6,1,2.00066614151001,0,1.99710726737976,,,,,,,,,,,,,,,,,,,,,,,,,,,,,,,,,
,3865570067.03164,1.99927747249603,964.900207519531,0.0643158963781071,0.000405475441193084,1,2,12.9061126708984,4.99976740624122,38.0900017917156,83.9804044728791,12.283180363241,1000,-4.08311217911341E-5,,,,,,,,,,,,,,,,,,,,,1.99817776679993,2.00037717819214,909.906677246094,1019.89373779297,49.6338017854187,5.43202726724079,2.5862557888031,26,1,0,0,1,0.278549194335938,31.2805480957031,1,6,1,2.00037717819214,0,1.99927747249603,,,,,,,,,,,,,,,,,,,,,,,,,,,,,,,,,
,3865570117.10494,2.00176179409027,-4042.70776367188,-0.132693263714317,0.00350974510545049,1,2,12.9061126708984,4.99923339815679,38.0900017917156,-170.920382897767,-41.1149029175489,1000,-0.0120011604226465,,,,,,,,,,,,,,,,,,,,,2.00088357925415,2.00264000892639,-4147.64306640625,-3937.7724609375,49.5228105356879,5.43572840761324,2.5897855758667,25,1,68,0,0,0.278549194335938,30.7917900085449,1,6,1,2.00088357925415,0,2.00176179409027,,,,,,,,,,,,,,,,,,,,,,,,,,,,,,,,,
,3865570149.26557,2.00042045116425,-7256.5576171875,-0.160350527025557,0.0109366145563376,1,2,12.9061126708984,4.99988116593553,38.0900017917156,-206.736911074647,-48.6445996480837,1000,-0.0136992177586481,,,,,,,,,,,,,,,,,,,,,2.00020337104797,2.00063753128052,-7346.5693359375,-7166.5458984375,49.580651046111,5.43015096526005,2.582524061203,25,1,68,0,0,0.27923583984375,31.2805480957031,1,6,1,2.00063753128052,0,2.00042045116425,,,,,,,,,,,,,,,,,,,,,,,,,,,,,,,,,
,3865570185.91932,2.00102508068085,-10916.9365234375,-0.183300879029334,0.0117766899421159,1,2,12.9061126708984,5.00015734739209,38.0900017917156,-233.89621783117,-72.2773226061173,1000,-0.028423369533797,,,,,,,,,,,,,,,,,,,,,2.00028443336487,2.00176572799683,-10976.90625,-10856.966796875,49.5169483217937,5.42816410275663,2.56968402862549,24,1,68,0,0,0.27862548828125,31.2805480957031,1,6,1,2.00028443336487,0,2.00102508068085,,,,,,,,,,,,,,,,,,,,,,,,,,,,,,,,,
,3865570221.79955,2.00018191337585,-14512.46875,-0.194432882202348,0.0111960058032028,1,2,12.9061126708984,5.00057104214022,38.0900017917156,-247.681902953697,-79.7235051012003,1000,-0.032483406033092,,,,,,,,,,,,,,,,,,,,,1.99899578094482,2.00136804580688,-14607.4189453125,-14417.5185546875,49.6150427009572,5.42433300394489,2.55846452713013,24,1,68,0,0,0.276718139648438,30.7917900085449,5,6,1,1.99899578094482,0,2.00018191337585,,,,,,,,,,,,,,,,,,,,,,,,,,,,,,,,,
,3865570258.34921,2.00000530481338,-18167.40234375,-0.177133398087494,0.015209941669981,1,2,12.9061126708984,5.001556208253,38.0900017917156,-228.438492075185,-54.0566379244735,1000,-0.0153592455140639,,,,,,,,,,,,,,,,,,,,,1.99972784519196,2.00028276443481,-18227.328125,-18107.4765625,49.5841683744476,5.42218247710381,2.53963160514832,25,1,68,0,0,0.281600952148438,30.7917900085449,5,6,1,1.99945175647736,0,2.00000530481338,,,,,,,,,,,,,,,,,,,,,,,,,,,,,,,,,
,3865570292.72095,2.00057375431061,-21607.4931640625,-0.161255279809748,0.0164072819398151,1,2,12.9061126708984,5.0019655815943,38.0900017917156,-207.281592075749,-54.006388118757,1000,-0.0176487095411107,,,,,,,,,,,,,,,,,,,,,1.99909019470215,2.00205731391907,-21727.658203125,-21487.328125,49.7807479470341,5.42112323244307,2.53239631652832,24,1,68,0,0,0.288238525390625,31.2805480957031,1,6,1,2.00205731391907,0,2.00057375431061,,,,,,,,,,,,,,,,,,,,,,,,,,,,,,,,,
,3865570328.89096,2.00210905075073,-25217.8310546875,-0.177648554206469,0.0163158119501562,1,2,12.9061126708984,4.99810324396487,38.1000004708767,-227.423100401301,-64.0874798984845,1000,-0.0230099747366894,,,,,,,,,,,,,,,,,,,,,2.00046372413635,2.00375437736511,-25337.916015625,-25097.74609375,49.766678633688,5.43922142590984,2.58668565750122,26,1,0,0,1,0.281143188476562,31.2805480957031,1,6,1,2.00046372413635,0,2.00210905075073,,,,,,,,,,,,,,,,,,,,,,,,,,,,,,,,,
,3865570365.10119,1.99933403730392,-28849.02734375,-0.166376377401776,0.0191311395646209,1,2,12.9061126708984,4.99739198079146,38.0900017917156,-214.245041908729,-51.1949119139623,1000,-0.0147945806931838,,,,,,,,,,,,,,,,,,,,,1.99615561962128,2.00251245498657,-28964.35546875,-28733.69921875,49.8831412830534,5.44234013842086,2.60019040107727,24,1,68,0,0,0.280303955078125,31.2805480957031,1,6,1,1.99615561962128,0,1.99933403730392,,,,,,,,,,,,,,,,,,,,,,,,,,,,,,,,,
,3865570401.39011,1.99051910638809,-32480.2314453125,-0.193965589701687,0.0157174114991033,1,2,12.9061126708984,4.99776010205189,38.1000004708767,-250.618118310423,-54.1067453352932,1000,-0.0129688468413576,,,,,,,,,,,,,,,,,,,,,1.97778952121735,2.00324869155884,-32600.435546875,-32360.02734375,49.9374644651399,5.44041043756771,2.59222841262817,25,1,68,0,0,0.271377563476562,31.2805480957031,6,6,1,2.00324869155884,0,1.99051910638809,,,,,,,,,,,,,,,,,,,,,,,,,,,,,,,,,
,3865570435.33011,2.00143504142761,-35881.44140625,-0.172314158390329,0.0224950489617802,1,2,12.9061126708984,4.99696629829034,38.0900017917156,-225.238472227178,-30.0510149585411,1000,0.00228021926385208,,,,,,,,,,,,,,,,,,,,,2.001145362854,2.00172472000122,-35976.44921875,-35786.43359375,50.0191446453995,5.44327989599577,2.60522198677063,22,1,68,0,0,0.27374267578125,30.7917900085449,5,6,1,2.001145362854,0,2.00143504142761,,,,,,,,,,,,,,,,,,,,,,,,,,,,,,,,,
,3865570471.60762,1.99914562702179,-39518.1171875,-0.131046979566094,0.0183045667518015,1,2,12.9061126708984,4.99781863201996,38.0900017917156,-170.486535259391,-28.6520025901213,1000,-0.00270476578161313,,,,,,,,,,,,,,,,,,,,,1.9989116191864,1.99937963485718,-39613.15625,-39423.078125,50.0957442402841,5.44192047007464,2.59569382667542,23,1,68,0,0,0.272674560546875,31.7693061828613,1,6,1,1.9989116191864,0,1.99914562702179,,,,,,,,,,,,,,,,,,,,,,,,,,,,,,,,,
,3865570505.83622,1.9970685839653,-42944.77734375,-0.143620108089693,0.0201998760835727,1,2,12.9061126708984,4.99723116021337,38.0900017917156,-189.440268429979,-13.5114737439553,1000,0.0107433599775417,,,,,,,,,,,,,,,,,,,,,1.99545574188232,1.99868142604828,-43039.9296875,-42849.625,50.1582745218226,5.44425675879895,2.5896487236023,20,1,68,0,0,0.28076171875,31.2805480957031,6,6,1,1.99868142604828,0,1.9970685839653,,,,,,,,,,,,,,,,,,,,,,,,,,,,,,,,,
,3865570540.47817,2.00094103813171,-46415.611328125,-0.12723783028329,0.0216227414274662,1,2,12.9061126708984,4.99786045319554,38.0900017917156,-168.100669886353,-10.3413295560271,1000,0.010767811771133,,,,,,,,,,,,,,,,,,,,,2.00020861625671,2.00167346000671,-46535.93359375,-46295.2890625,50.1918845481495,5.44211126222859,2.59323811531067,19,1,68,0,0,0.281524658203125,31.2805480957031,5,6,1,2.00167346000671,0,2.00094103813171,,,,,,,,,,,,,,,,,,,,,,,,,,,,,,,,,
,3865570576.71712,1.99738675355911,-49965.658203125,-0.119346130993162,0.019608973333619,1,2,12.9061126708984,4.99813029770166,38.0900017917156,-157.313544078845,-12.2390046561077,1000,0.00815490842043122,,,,,,,,,,,,,,,,,,,,,1.99590599536896,1.99886751174927,-49999.609375,-49931.70703125,50.3329684958707,5.440863539862,2.57563614845276,22,1,68,0,0,0.281448364257813,31.7693061828613,1,6,1,1.99590599536896,0,1.99738675355911,,,,,,,,,,,,,,,,,,,,,,,,,,,,,,,,,
,3865570610.59696,1.97588700056076,-47330.9296875,-0.13377852425886,0.0198573334036512,1,2,12.9061126708984,4.99763835790228,38.0900017917156,-174.976769497808,-22.8125039268211,1000,0.00217065046951982,,,,,,,,,,,,,,,,,,,,,1.9652613401413,1.98651266098022,-47425.8984375,-47235.9609375,50.1602285931207,5.44293731081885,2.57080292701721,22,1,68,0,0,0.274505615234375,31.2805480957031,6,6,1,1.9652613401413,0,1.97588700056076,,,,,,,,,,,,,,,,,,,,,,,,,,,,,,,,,
,3865570643.14168,2.00018692016602,-44082.5,-0.155711096469054,0.0193756993677024,1,2,12.9061126708984,4.99757332271094,38.0900017917156,-203.255146778515,-29.3075034310033,1000,0.000414785745292738,,,,,,,,,,,,,,,,,,,,,2.00005316734314,2.00032067298889,-44142.39453125,-44022.60546875,50.1981375763034,5.44358428377542,2.58434224128723,22,1,68,0,0,0.273895263671875,30.7917900085449,5,6,1,2.00005316734314,0,2.00018692016602,,,,,,,,,,,,,,,,,,,,,,,,,,,,,,,,,
,3865570679.09365,2.00096654891968,-40494.32421875,-0.130844527663618,0.0174772030281635,1,2,12.9061126708984,4.99861871352032,38.0900017917156,-171.435245386437,-20.6235397621265,1000,0.00342151972899855,,,,,,,,,,,,,,,,,,,,,2.00050377845764,2.00142931938171,-40589.5,-40399.1484375,50.0945717975053,5.4396337154908,2.58218908309937,24,1,68,0,0,0.273895263671875,31.2805480957031,5,6,1,2.00047850608826,0,2.00096654891968,,,,,,,,,,,,,,,,,,,,,,,,,,,,,,,,,
,3865570715.61821,2.00085914134979,-36851.3515625,-0.151558323715032,0.0177075145867674,1,2,12.9061126708984,4.99809105345283,38.0900017917156,-198.209545628896,-26.1718593685052,1000,0.00221072500039487,,,,,,,,,,,,,,,,,,,,,2.00027465820313,2.00144362449646,-36916.19140625,-36786.51171875,50.0836289982361,5.44300017167607,2.58777141571045,23,1,68,0,0,0.289764404296875,31.2805480957031,1,6,1,2.00144362449646,0,2.00085914134979,,,,,,,,,,,,,,,,,,,,,,,,,,,,,,,,,
,3865570751.95501,2.00116628408432,-33223.0625,-0.114182454198847,0.0193221629145107,1,2,12.9061126708984,4.9976069952346,38.1000004708767,-149.701703171958,-17.0400337167088,1000,0.0037155218157294,,,,,,,,,,,,,,,,,,,,,1.99973285198212,2.00259971618652,-33282.95703125,-33163.16796875,50.1066870395534,5.44371670352795,2.60202097892761,25,1,68,0,0,0.273284912109375,31.2805480957031,1,6,1,1.99973285198212,0,2.00116628408432,,,,,,,,,,,,,,,,,,,,,,,,,,,,,,,,,
,3865570785.96451,1.99958050251007,-29824.5634765625,-0.170562538339412,0.0194047751388216,1,2,12.9061126708984,4.99716282818569,38.0900017917156,-221.674402716963,-38.5058724007702,1000,-0.00445627921227864,,,,,,,,,,,,,,,,,,,,,1.99937701225281,1.99978399276733,-29909.484375,-29739.642578125,49.7373675642168,5.44329686925978,2.59458661079407,24,1,68,0,0,0.275039672851562,31.2805480957031,1,6,1,1.99978399276733,0,1.99958050251007,,,,,,,,,,,,,,,,,,,,,,,,,,,,,,,,,
,3865570818.09382,1.99881386756897,-26620.5986328125,-0.190214434830584,0.0152781484164708,1,2,12.9061126708984,4.99750883489624,38.1000004708767,-247.733386064494,-39.5834506371774,1000,-0.00239219338346573,,,,,,,,,,,,,,,,,,,,,1.99582886695862,2.00179886817932,-26715.2734375,-26525.923828125,49.880405583236,5.44181881791479,2.59852862358093,23,1,68,0,0,0.281982421875,31.7693061828613,1,6,1,1.99582886695862,0,1.99881386756897,,,,,,,,,,,,,,,,,,,,,,,,,,,,,,,,,
,3865570850.57433,2.00107038021088,-23380.8251953125,-0.14957535744765,0.0174619354584015,1,2,12.9061126708984,4.99727354404768,38.0900017917156,-194.242460145645,-34.8691827665618,1000,-0.00475126486526279,,,,,,,,,,,,,,,,,,,,,2.00106549263,2.00107526779175,-23450.8359375,-23310.814453125,49.9472348216303,5.44163337298563,2.61103892326355,25,1,68,0,0,0.273056030273438,32.2580642700195,1,6,1,2.00106549263,0,2.00107038021088,,,,,,,,,,,,,,,,,,,,,,,,,,,,,,,,,
,3865570882.56987,2.00064611434937,-20181.4482421875,-0.157358444620615,0.0160008335595607,1,2,12.9061126708984,4.99650020343541,38.1000004708767,-202.568702937064,-48.4974740270474,1000,-0.0140613260285535,,,,,,,,,,,,,,,,,,,,,2.00033926963806,2.00095295906067,-20276.341796875,-20086.5546875,49.616215143736,5.44419841195955,2.62246823310852,25,1,68,0,0,0.284042358398438,31.2805480957031,1,6,1,2.00095295906067,0,2.00064611434937,,,,,,,,,,,,,,,,,,,,,,,,,,,,,,,,,
,3865570916.19522,1.9994592666626,-16827.53125,-0.187918024786617,0.0152266367028375,1,2,12.9061126708984,4.99681408517393,38.0900017917156,-241.673092311405,-59.6668191946272,1000,-0.0181303757350684,,,,,,,,,,,,,,,,,,,,,1.99941170215607,1.99950683116913,-16982.18359375,-16672.87890625,49.6635036691495,5.44196703876291,2.61172795295715,24,1,68,0,0,0.27618408203125,31.2805480957031,1,6,1,1.99941170215607,0,1.9994592666626,,,,,,,,,,,,,,,,,,,,,,,,,,,,,,,,,
,3865570952.40303,1.9986829161644,-13214.3120117188,-0.201890043245274,0.0128485309307594,1,2,12.9061126708984,4.99552162621369,38.0900017917156,-256.629003891364,-83.9474280944114,1000,-0.0347133680156224,,,,,,,,,,,,,,,,,,,,,1.99770617485046,1.99965965747833,-13379.1357421875,-13049.48828125,49.6431813276495,5.44373910013203,2.63555932044983,23,1,68,0,0,0.275421142578125,30.7917900085449,1,6,1,1.99965965747833,0,1.9986829161644,,,,,,,,,,,,,,,,,,,,,,,,,,,,,,,,,
,3865570987.53123,1.99983316659927,-9702.27197265625,-0.176233448060899,0.00897519495755518,1,2,12.9061126708984,4.9957081651744,38.0900017917156,-224.935053581787,-67.1075024988185,1000,-0.0255665851634747,,,,,,,,,,,,,,,,,,,,,1.99857103824615,2.00109529495239,-9772.314453125,-9632.2294921875,49.5099136651206,5.44428303755227,2.63358497619629,24,1,68,0,0,0.273971557617187,30.7917900085449,1,6,1,2.00109529495239,0,1.99983316659927,,,,,,,,,,,,,,,,,,,,,,,,,,,,,,,,,
,3865571023.76111,2.0006707906723,-6080.43310546875,-0.161680828238962,0.00700686193164642,1,2,12.9061126708984,4.99593217933953,38.0900017917156,-206.714581187552,-59.2504800479455,1000,-0.0216770004500239,,,,,,,,,,,,,,,,,,,,,2.00024557113647,2.00109601020813,-6155.376953125,-6005.4892578125,49.4673149108225,5.44328421650351,2.63762044906616,25,1,68,0,0,0.275726318359375,31.2805480957031,1,6,1,2.00109601020813,0,2.0006707906723,,,,,,,,,,,,,,,,,,,,,,,,,,,,,,,,,
,3865571057.87029,2.00248467922211,-2678.06713867187,-0.117789826224252,0.00204591340045744,1,2,12.9061126708984,4.99643553999926,38.0900017917156,-152.899799564797,-27.6515556390914,1000,-0.00389393127576031,,,,,,,,,,,,,,,,,,,,,2.00092935562134,2.00404000282288,-2777.85668945313,-2578.27758789062,49.4376130270918,5.44344927912608,2.62989711761475,25,1,68,0,0,0.275344848632813,31.2805480957031,1,6,1,2.00404000282288,0,2.00248467922211,,,,,,,,,,,,,,,,,,,,,,,,,,,,,,,,,
,3865571104.5722,1.9994410276413,1994.43377685547,0.0725973705734711,0.000769947445026606,1,2,12.9061126708984,4.99545448221199,38.0900017917156,94.5412042586463,14.7884647549879,1000,0.000675071608061866,,,,,,,,,,,,,,,,,,,,,1.9979076385498,2.00097441673279,1899.48937988281,2089.37817382813,49.4751311960148,5.44799336479058,2.63293051719666,26,1,0,0,1,0.27496337890625,31.2805480957031,1,6,1,1.9979076385498,0,1.9994410276413,,,,,,,,,,,,,,,,,,,,,,,,,,,,,,,,,
,3865571136.3993,2.00091123580933,5173.986328125,0.148041660357352,0.00641051890574897,1,2,12.9061126708984,4.99666102160918,38.1000004708767,188.476625780363,59.9708807402187,1000,0.0242237024079648,,,,,,,,,,,,,,,,,,,,,2.00052714347839,2.00129532814026,5079.0859375,5268.88671875,49.6592047122937,5.43968628602713,2.62931251525879,25,1,68,0,0,0.272140502929687,31.2805480957031,1,6,1,2.00129532814026,0,2.00091123580933,,,,,,,,,,,,,,,,,,,,,,,,,,,,,,,,,
,3865571172.65417,2.00148725509644,8799.16552734375,0.150387103109723,0.011680347346431,1,2,12.9061126708984,4.99723556860372,38.0900017917156,192.552126611045,53.7251880030558,1000,0.0190846547609427,,,,,,,,,,,,,,,,,,,,,2.00038504600525,2.00258946418762,8709.2353515625,8889.095703125,49.316460606611,5.43919525139146,2.61007761955261,22,1,68,0,0,0.283660888671875,31.2805480957031,1,6,1,2.00038504600525,0,2.00148725509644,,,,,,,,,,,,,,,,,,,,,,,,,,,,,,,,,
,3865571208.94893,1.99831748008728,12429.578125,0.156091405889187,0.0109453097754263,1,2,12.9061126708984,4.9970202310737,38.1000004708767,199.469281363882,58.3083601031734,1000,0.0217621438434155,,,,,,,,,,,,,,,,,,,,,1.99737453460693,1.99926042556763,12339.4345703125,12519.7216796875,49.5943295451976,5.44043163714786,2.61665081977844,23,1,68,0,0,0.2740478515625,31.2805480957031,1,6,1,1.99926042556763,0,1.99831748008728,,,,,,,,,,,,,,,,,,,,,,,,,,,,,,,,,
,3865571241.58474,1.99966484308243,15689.9731445313,0.163784191480139,0.0132155587460744,1,2,12.9061126708984,4.99749631875881,38.1000004708767,208.752491539053,65.10650492627,1000,0.0258361427437357,,,,,,,,,,,,,,,,,,,,,1.99839174747467,2.00093793869019,15570.08984375,15809.8564453125,49.6787454252745,5.43846680872357,2.60617446899414,24,1,68,0,0,0.271987915039062,29.3255138397217,1,6,1,2.00093793869019,0,1.99966484308243,,,,,,,,,,,,,,,,,,,,,,,,,,,,,,,,,
,3865571277.70629,2.0007232427597,19305.9697265625,0.175600229439344,0.0154218043694107,1,2,12.9061126708984,4.997109916188,38.0900017917156,226.398350414056,52.0309296577061,1000,0.0140833956948093,,,,,,,,,,,,,,,,,,,,,2.00025582313538,2.00119066238403,19191.11328125,19420.826171875,49.7549542058995,5.4384265894951,2.60102224349976,23,1,68,0,0,0.273284912109375,31.2805480957031,1,6,1,2.00025582313538,0,2.0007232427597,,,,,,,,,,,,,,,,,,,,,,,,,,,,,,,,,
,3865571311.67998,1.99942952394485,22707.033203125,0.162709684007801,0.0180730044727142,1,2,12.9061126708984,4.99738977067087,38.0900017917156,209.819003622488,48.0535584635462,1000,0.0129256671344156,,,,,,,,,,,,,,,,,,,,,1.99896943569183,1.99988961219788,22612.0078125,22802.05859375,49.6435721419091,5.43705675543634,2.6033878326416,20,1,68,0,0,0.281448364257813,31.2805480957031,1,6,1,1.99988961219788,0,1.99942952394485,,,,,,,,,,,,,,,,,,,,,,,,,,,,,,,,,
,3865571347.92261,1.99761086702347,26333.5146484375,0.0961130276914187,0.0217420799069791,1,2,12.9061126708984,4.99707458387798,38.1000004708767,125.517028025481,17.5779461444705,1000,-0.000646668725629976,,,,,,,,,,,,,,,,,,,,,1.99743807315826,1.99778366088867,26243.3828125,26423.646484375,49.7600347912745,5.43924777915631,2.59136724472046,21,1,68,0,0,0.27130126953125,32.2580642700195,1,6,1,1.99778366088867,0,1.99761086702347,,,,,,,,,,,,,,,,,,,,,,,,,,,,,,,,,
,3865571384.20116,1.99826574325562,29965.53125,0.112418985774364,0.019269959371017,1,2,12.9061126708984,4.99751293499506,38.1000004708767,144.895034758364,33.730517950779,1000,0.00933547649661482,,,,,,,,,,,,,,,,,,,,,1.99812698364258,1.99840450286865,29870.361328125,30060.701171875,49.8182661159572,5.43873732365477,2.58771395683289,18,1,68,0,0,0.274276733398438,31.2805480957031,1,6,1,1.99840450286865,0,1.99826574325562,,,,,,,,,,,,,,,,,,,,,,,,,,,,,,,,,
,3865571418.44104,1.99979257583618,33397.94140625,0.114304151474571,0.021688936560762,1,2,12.9061126708984,4.99792586756136,38.1000004708767,151.384483681634,6.78255909966302,1000,-0.0115949826684892,,,,,,,,,,,,,,,,,,,,,1.99750518798828,2.00207996368408,33307.65234375,33488.23046875,49.9808448479572,5.44001083551522,2.58415341377258,22,1,68,0,0,0.278549194335938,31.2805480957031,1,6,1,2.00207996368408,0,1.99979257583618,,,,,,,,,,,,,,,,,,,,,,,,,,,,,,,,,
,3865571453.92895,2.00158619880676,36955.37109375,0.1334339224664,0.0198515561689228,1,2,12.9061126708984,4.99779314101686,38.1000004708767,174.904673951927,20.2290143954215,1000,-0.00410061328596483,,,,,,,,,,,,,,,,,,,,,2.00026059150696,2.00291180610657,36785.04296875,37125.69921875,50.0195354596591,5.4401207347344,2.58956575393677,20,1,68,0,0,0.273056030273438,31.7693061828613,1,6,1,2.00026059150696,0,2.00158619880676,,,,,,,,,,,,,,,,,,,,,,,,,,,,,,,,,
,3865571491.34541,2.00109827518463,40707.9921875,0.0930195818960246,0.0210129255943462,1,2,12.9061126708984,4.99774815615726,38.1000004708767,123.139925980121,5.85368071805872,1000,-0.00917963242283315,,,,,,,,,,,,,,,,,,,,,2.00079607963562,2.00140047073364,40652.87890625,40763.10546875,50.1207563528995,5.44110578139785,2.57809567451477,21,1,68,0,0,0.2728271484375,31.7693061828613,1,6,1,2.00140047073364,0,2.00109827518463,,,,,,,,,,,,,,,,,,,,,,,,,,,,,,,,,
,3865571527.23927,1.9998494386673,44305.09375,0.105753014121043,0.0201703283332361,1,2,12.9061126708984,4.99741003392928,38.1000004708767,137.154464470853,25.9094893755222,1000,0.00432132024682982,,,,,,,,,,,,,,,,,,,,,1.99640107154846,2.00329780578613,44209.97265625,44400.21484375,50.091836097688,5.44330206777089,2.58458399772644,21,1,68,0,0,0.279998779296875,30.7917900085449,1,6,1,2.00329780578613,0,1.9998494386673,,,,,,,,,,,,,,,,,,,,,,,,,,,,,,,,,
,3865571561.87292,1.99817264080048,47772.392578125,0.0826437824177184,0.0183130310533831,1,2,12.9061126708984,4.9973628065451,38.0900017917156,109.08348298899,7.3039771886476,1000,-0.00654327562236258,,,,,,,,,,,,,,,,,,,,,1.99596500396729,2.00038027763367,47656.7890625,47887.99609375,50.3161634827072,5.4449964018222,2.5780827999115,21,1,68,0,0,0.273284912109375,31.2805480957031,1,6,1,2.00038027763367,0,1.99817264080048,,,,,,,,,,,,,,,,,,,,,,,,,,,,,,,,,
,3865572407.48413,300.007873535156,49213.080078125,0.0288214868538927,6.9438624631743E-6,1,2,12.9061126708984,5.00253921902979,39.0500016510487,37.660034575146,5.52776325922902,1000,-3.6770426167862E-6,,,,,,,,,,,,,,,,,,,,,300.007720947266,300.008026123047,49113.30859375,49312.8515625,50.198528390563,5.41387073536739,7.80994367599487,26,1,0,0,1,0.281295776367187,30.7917900085449,1,6,1,300.007720947266,0,300.007873535156,,,,,,,,,,,,,,,,,,,,,,,,,,,,,,,,,
,3865572448.77631,300.005920410156,45089.16796875,0.0265587001618126,8.94139987557203E-6,1,2,12.9061126708984,5.00291712431667,39.0500016510487,34.7024141690203,5.12552944008674,100,2.04981953028404E-5,,,,,,,,,,,,,,,,,,,,,300.005920410156,300.005920410156,45089.16796875,45089.16796875,50.3454745521784,5.41259661178328,7.7779803276062,26,1,0,0,1,0.276565551757813,30.3030319213867,1,6,1,300.005920410156,0,300.005920410156,,,,,,,,,,,,,,,,,,,,,,,,,,,,,,,,,
,3865572518.47845,300.004608154297,38130.900390625,0.0225945652728417,7.03993762157129E-6,1,2,12.9061126708984,5.0021023148635,39.0500016510487,29.514604917814,4.36915091908678,100,2.48241161790734E-5,,,,,,,,,,,,,,,,,,,,,300.004364013672,300.004852294922,38010.99609375,38250.8046875,50.1668724355342,5.41467145451268,7.73490619659424,26,1,0,0,1,0.276947021484375,31.2805480957031,1,6,1,300.004852294922,0,300.004608154297,,,,,,,,,,,,,,,,,,,,,,,,,,,,,,,,,
,3865572578.64236,300.003845214844,32125.10546875,0.0191944161192105,5.86495076337613E-6,1,2,12.9061126708984,5.00198914055251,39.0500016510487,25.0709879986533,3.72045416136868,100,2.7911311994545E-5,,,,,,,,,,,,,,,,,,,,,300.003692626953,300.003997802734,32030.41796875,32219.79296875,50.3177267397457,5.41482862253489,7.71731615066528,26,1,0,0,1,0.2783203125,31.2805480957031,1,6,1,300.003692626953,0,300.003845214844,,,,,,,,,,,,,,,,,,,,,,,,,,,,,,,,,
,3865572640.4374,300.002838134766,25955.8564453125,0.0156746600666935,6.11414314434178E-6,1,2,12.9061126708984,5.00197305460469,39.0399992465973,20.4740143934443,3.03490559964097,100,2.02667784135693E-5,,,,,,,,,,,,,,,,,,,,,300.002258300781,300.00341796875,25791.17578125,26120.537109375,50.2989676552842,5.41519996623041,7.7082028388977,26,1,0,0,1,0.278472900390625,30.7917900085449,1,6,1,300.002258300781,0,300.002838134766,,,,,,,,,,,,,,,,,,,,,,,,,,,,,,,,,
,3865572727.44768,300.003631591797,17269.73046875,0.010755490088858,6.1980772892052E-6,1,2,12.9061126708984,5.00211478945336,39.0399992465973,14.0496710364392,2.07949593375701,100,1.15723249223881E-5,,,,,,,,,,,,,,,,,,,,,300.003356933594,300.00390625,17095.19140625,17444.26953125,50.3063931262169,5.41299521455573,7.71735620498657,26,1,0,0,1,0.280914306640625,31.2805480957031,1,6,1,300.00390625,0,300.003631591797,,,,,,,,,,,,,,,,,,,,,,,,,,,,,,,,,
,3865572770.07762,300.00309753418,13017.2895507813,0.00833744355792028,6.38077092429235E-6,1,2,12.9061126708984,5.00198808386982,39.0399992465973,10.8911376584105,1.60854867015485,100,6.38471471121326E-6,,,,,,,,,,,,,,,,,,,,,300.002838134766,300.003356933594,12922.52734375,13112.0517578125,50.2735647284092,5.4131378843438,7.73582983016968,26,1,0,0,1,0.278244018554687,31.2805480957031,1,6,1,300.003356933594,0,300.00309753418,,,,,,,,,,,,,,,,,,,,,,,,,,,,,,,,,
,3865572804.30071,300.001937866211,9595.04833984375,0.00637120422344224,6.30996351122636E-6,1,2,12.9061126708984,5.00235091039519,39.0199981629849,8.32395659869072,1.2262157863887,100,2.49885386091002E-6,,,,,,,,,,,,,,,,,,,,,300.001922607422,300.001953125,9504.9423828125,9685.154296875,50.3224165108611,5.41206725021774,7.75715160369873,25,1,68,0,0,0.276641845703125,30.7917900085449,1,6,1,300.001953125,0,300.001937866211,,,,,,,,,,,,,,,,,,,,,,,,,,,,,,,,,
,3865572836.71958,300.002502441406,6357.14331054687,0.00449466266303033,6.34745615479008E-6,1,2,12.9061126708984,5.00239583901428,39.0199981629849,5.87290061789195,0.861215274998083,100,-1.18231896285201E-6,,,,,,,,,,,,,,,,,,,,,300.002349853516,300.002655029297,6247.37548828125,6466.9111328125,50.2966227697265,5.41193997886149,7.77952194213867,26,1,0,0,1,0.280227661132813,31.2805480957031,1,6,1,300.002655029297,0,300.002502441406,,,,,,,,,,,,,,,,,,,,,,,,,,,,,,,,,
,3865572870.76352,300.001907348633,2954.04406738281,0.00245774547221113,6.85168994861252E-6,1,2,12.9061126708984,5.00249252383818,39.0199981629849,3.21349059616125,0.457200528791127,100,-1.11598461273692E-5,,,,,,,,,,,,,,,,,,,,,300.001892089844,300.001922607422,2859.08715820313,3049.0009765625,50.2208048033611,5.41146854294638,7.8302960395813,26,1,0,0,1,0.279541015625,31.2805480957031,1,6,1,300.001892089844,0,300.001907348633,,,,,,,,,,,,,,,,,,,,,,,,,,,,,,,,,
,3865572905.02462,300.001327514648,-473.944717407227,0.000105247730112653,9.50164726004411E-6,1,2,12.9061126708984,5.00268152054854,39.0199981629849,0.140652698708756,-0.00107576275127977,100,-1.62853155942671E-5,,,,,,,,,,,,,,,,,,,,,300.000854492188,300.001800537109,-568.989379882812,-378.900054931641,50.3501643232938,5.4104022430768,7.87310647964478,26,1,0,0,1,0.281448364257813,31.2805480957031,1,6,1,300.001800537109,0,300.001327514648,,,,,,,,,,,,,,,,,,,,,,,,,,,,,,,,,
,3865572947.52399,300.001022338867,-4721.853515625,-0.00304097524684326,8.35041095519606E-6,1,2,12.9061126708984,5.00276217993715,39.0199981629849,-3.97211940979364,-0.594608767878337,100,-8.2858018363916E-6,,,,,,,,,,,,,,,,,,,,,300.001007080078,300.001037597656,-4796.8349609375,-4646.8720703125,50.3325776816111,5.4104254911256,7.96246767044067,26,1,0,0,1,0.279998779296875,30.7917900085449,1,6,1,300.001037597656,0,300.001022338867,,,,,,,,,,,,,,,,,,,,,,,,,,,,,,,,,
,3865572992.01169,300.000213623047,-9171.5908203125,-0.0058763253674171,6.78602490432165E-6,1,2,12.9061126708984,5.00308464823318,39.0199981629849,-7.67725545322121,-1.1429110268452,100,-1.12641256512472E-5,,,,,,,,,,,,,,,,,,,,,299.999938964844,300.00048828125,-9286.6484375,-9056.533203125,50.4486495167169,5.40870236838388,8.04898452758789,26,1,0,0,1,0.280303955078125,31.2805480957031,1,6,1,300.00048828125,0,300.000213623047,,,,,,,,,,,,,,,,,,,,,,,,,,,,,,,,,
,3865573060.14308,300.00163269043,-15981.7944335938,-0.00995952878060442,6.76626697038971E-6,1,2,12.9061126708984,5.0032000151846,39.0199981629849,-13.0125672942979,-1.93508878902603,100,-1.75270325107203E-5,,,,,,,,,,,,,,,,,,,,,300.001525878906,300.001739501953,-16076.8017578125,-15886.787109375,50.3857284209188,5.40886833128373,8.23018550872803,26,1,0,0,1,0.276947021484375,31.2805480957031,1,6,1,300.001525878906,0,300.00163269043,,,,,,,,,,,,,,,,,,,,,,,,,,,,,,,,,
,3865573098.55812,300.000350952148,-19827.1298828125,-0.0121812280759545,6.93568414205444E-6,1,2,12.9061126708984,5.00333487318433,39.0199981629849,-15.9161563931901,-2.36521215970303,100,-2.01885152606724E-5,,,,,,,,,,,,,,,,,,,,,300.000274658203,300.000427246094,-19937.29296875,-19716.966796875,50.4584198732073,5.40837930002998,8.33631992340088,26,1,0,0,1,0.282821655273438,31.7693061828613,1,6,1,300.000427246094,0,300.000350952148,,,,,,,,,,,,,,,,,,,,,,,,,,,,,,,,,
,3865573134.76811,299.999954223633,-23442.505859375,-0.0142675170453634,6.97043588681201E-6,1,2,12.9061126708984,5.0035032226767,39.0300005674362,-18.6423084162422,-2.7751937333547,100,-2.7287603349377E-5,,,,,,,,,,,,,,,,,,,,,299.999786376953,300.000122070313,-23547.66015625,-23337.3515625,50.2172874750245,5.40811759962643,8.43432807922363,26,1,0,0,1,0.2764892578125,31.2805480957031,1,6,1,299.999786376953,0,299.999954223633,,,,,,,,,,,,,,,,,,,,,,,,,,,,,,,,,
,3865573171.07297,300.000549316406,-27080.466796875,-0.0163360635646671,6.73059955327332E-6,1,2,12.9061126708984,5.00377819564714,39.0199981629849,-21.3473540997,-3.1737969854778,100,-2.81859850841299E-5,,,,,,,,,,,,,,,,,,,,,300.000244140625,300.000854492188,-27190.810546875,-26970.123046875,50.244253658938,5.40609501134952,8.51872634887695,26,1,0,0,1,0.277328491210938,30.7917900085449,1,6,1,300.000854492188,0,300.000549316406,,,,,,,,,,,,,,,,,,,,,,,,,,,,,,,,,
,3865573222.99588,300.001159667969,-32279.498046875,-0.0191955857564577,7.0086409328866E-6,1,2,12.9061126708984,5.00407193300632,39.0199981629849,-25.0863902410162,-3.72789264873904,100,-3.17707994747793E-5,,,,,,,,,,,,,,,,,,,,,300.001159667969,300.001159667969,-32279.498046875,-32279.498046875,50.2235405031784,5.4050675686611,8.64755058288574,26,1,0,0,1,0.277252197265625,31.2805480957031,1,6,1,300.001159667969,0,300.001159667969,,,,,,,,,,,,,,,,,,,,,,,,,,,,,,,,,
,3865573259.56963,299.999893188477,-35946.0078125,-0.0213700011606243,7.39475290831582E-6,1,2,12.9061126708984,5.00403538232616,39.0300005674362,-27.9277182774759,-4.15077141914305,100,-3.58572118908978E-5,,,,,,,,,,,,,,,,,,,,,299.999847412109,299.999938964844,-36036.18359375,-35855.83203125,50.2399547020822,5.4051654349923,8.78151321411133,26,1,0,0,1,0.277023315429687,31.2805480957031,1,6,1,299.999938964844,0,299.999893188477,,,,,,,,,,,,,,,,,,,,,,,,,,,,,,,,,
,3865573293.83207,300.000091552734,-39377.642578125,-0.0232906101607248,7.17522632976004E-6,1,2,12.9061126708984,5.0037388464887,39.0199981629849,-30.4355458945344,-4.52089504755412,100,-3.71305364061984E-5,,,,,,,,,,,,,,,,,,,,,300.000030517578,300.000152587891,-39472.83203125,-39282.453125,50.2262762029957,5.4064917420432,8.83343029022217,26,1,0,0,1,0.279388427734375,31.2805480957031,1,6,1,300.000030517578,0,300.000091552734,,,,,,,,,,,,,,,,,,,,,,,,,,,,,,,,,
,3865573349.61929,300.000854492188,-44967.765625,-0.0263774200394666,6.71653805687698E-6,1,2,12.9061126708984,5.0035853437713,39.0199981629849,-34.4702079430212,-5.10363896580749,100,-2.96486969592003E-5,,,,,,,,,,,,,,,,,,,,,300.000854492188,300.000854492188,-44972.78515625,-44962.74609375,50.2454261017169,5.407100984008,8.7960205078125,26,1,0,0,1,0.281753540039062,30.7917900085449,1,6,1,300.000854492188,0,300.000854492188,,,,,,,,,,,,,,,,,,,,,,,,,,,,,,,,,
,3865573396.57072,300.001251220703,-49670.86328125,-0.0291077673465252,7.02074820053651E-6,1,2,12.9061126708984,5.00307734260721,39.0199981629849,-38.0307868020516,-5.64509917237936,100,-4.34144005650514E-5,,,,,,,,,,,,,,,,,,,,,300.0009765625,300.001525878906,-49761.05078125,-49580.67578125,50.2516791298707,5.4092091015755,8.76139259338379,26,1,0,0,1,0.278778076171875,31.7693061828613,1,6,1,300.0009765625,0,300.001251220703,,,,,,,,,,,,,,,,,,,,,,,,,,,,,,,,,
,3865573457.43599,300.001190185547,-44672.328125,-0.0262547025895702,6.45221020845632E-6,1,2,12.9061126708984,5.00342322934424,39.0199981629849,-34.3153768005542,-5.03138463064828,100,7.42978537219948E-6,,,,,,,,,,,,,,,,,,,,,300.001098632812,300.001281738281,-44722.25,-44622.40625,50.2692657715534,5.40771137202207,8.74121284484863,24,1,68,0,0,0.278244018554687,32.2580642700195,1,6,1,300.001281738281,0,300.001190185547,,,,,,,,,,,,,,,,,,,,,,,,,,,,,,,,,
,3865573518.91545,300.000671386719,-38538.689453125,-0.0228529653679511,6.61430320802644E-6,1,2,12.9061126708984,5.00336515379199,39.0199981629849,-29.8671098839235,-4.39063651619132,100,-2.12033943041956E-6,,,,,,,,,,,,,,,,,,,,,300.000671386719,300.000671386719,-38543.66015625,-38533.71875,50.2618403006207,5.40821826131843,8.71426200866699,26,1,0,0,1,0.275497436523438,31.7693061828613,1,6,1,300.000671386719,0,300.000671386719,,,,,,,,,,,,,,,,,,,,,,,,,,,,,,,,,
,3865573569.84988,299.999618530273,-33453.404296875,-0.0198993339633294,6.23678632151027E-6,1,2,12.9061126708984,5.00343850701527,39.0199981629849,-26.0076848394906,-3.82177862008796,100,-7.2266248920487E-7,,,,,,,,,,,,,,,,,,,,,299.999267578125,299.999969482422,-33543.37109375,-33363.4375,50.2688749572938,5.40851650398459,8.69030475616455,26,1,0,0,1,0.274810791015625,31.7693061828613,1,6,1,299.999969482422,0,299.999618530273,,,,,,,,,,,,,,,,,,,,,,,,,,,,,,,,,
,3865573616.29133,299.999481201172,-28816.947265625,-0.0172835623860351,6.51929886098444E-6,1,2,12.9061126708984,5.00339540914607,39.0199981629849,-22.5891551513643,-3.31624593392005,100,1.75885283077593E-6,,,,,,,,,,,,,,,,,,,,,299.998962402344,300,-28921.732421875,-28712.162109375,50.3224165108611,5.40857557126815,8.68038749694824,26,1,0,0,1,0.276947021484375,32.2580642700195,1,6,1,300,0,299.999481201172,,,,,,,,,,,,,,,,,,,,,,,,,,,,,,,,,
,3865573680.79074,299.999893188477,-22378.5693359375,-0.013635293808355,6.50284347573036E-6,1,2,12.9061126708984,5.00320273986227,39.0199981629849,-17.8201273671812,-2.61526732463524,100,2.02574451184244E-6,,,,,,,,,,,,,,,,,,,,,299.999786376953,300,-22453.431640625,-22303.70703125,50.2630127433996,5.40885029294446,8.6683292388916,26,1,0,0,1,0.276947021484375,31.2805480957031,1,6,1,299.999786376953,0,299.999893188477,,,,,,,,,,,,,,,,,,,,,,,,,,,,,,,,,
,3865573714.90826,299.99836730957,-18974.6416015625,-0.0116925014834201,6.67778898921421E-6,1,2,12.9061126708984,5.00344282159058,39.0199981629849,-15.2827922971473,-2.2380442362363,100,5.36656649675154E-6,,,,,,,,,,,,,,,,,,,,,299.998077392578,299.998657226562,-19069.455078125,-18879.828125,50.249334244313,5.40811143520371,8.66205310821533,26,1,0,0,1,0.276336669921875,31.2805480957031,1,6,1,299.998657226562,0,299.99836730957,,,,,,,,,,,,,,,,,,,,,,,,,,,,,,,,,
,3865573751.10931,300.000900268555,-15361.095703125,-0.00962769157492794,6.39186395264628E-6,1,2,12.9061126708984,5.00350007720183,39.0300005674362,-12.5844891457947,-1.84064483928466,100,6.10727735696939E-6,,,,,,,,,,,,,,,,,,,,,300.000640869141,300.001159667969,-15455.876953125,-15266.314453125,50.2243221316976,5.40744741488541,8.653977394104,26,1,0,0,1,0.279693603515625,30.7917900085449,1,6,1,300.000640869141,0,300.000900268555,,,,,,,,,,,,,,,,,,,,,,,,,,,,,,,,,
,3865573787.37945,299.99967956543,-11736.9130859375,-0.00755769786442723,6.24665175153823E-6,1,2,12.9061126708984,5.00312121317794,39.0300005674362,-9.8780259822852,-1.44269426642294,100,6.36371349457244E-6,,,,,,,,,,,,,,,,,,,,,299.999603271484,299.999755859375,-11831.76953125,-11642.056640625,50.259495415063,5.40935933766655,8.64810085296631,26,1,0,0,1,0.2783203125,30.7917900085449,1,6,1,299.999603271484,0,299.99967956543,,,,,,,,,,,,,,,,,,,,,,,,,,,,,,,,,
,3865573823.64351,300.001495361328,-8114.72973632813,-0.00546849333270236,6.17163348084093E-6,1,2,12.9061126708984,5.00366911565447,39.0199981629849,-7.14908125979344,-1.04008480659916,100,7.63409209262976E-6,,,,,,,,,,,,,,,,,,,,,300.001342773438,300.001647949219,-8204.603515625,-8024.85595703125,50.2180691035438,5.40697933755136,8.63949108123779,26,1,0,0,1,0.278549194335938,32.7468223571777,1,6,1,300.001342773438,0,300.001495361328,,,,,,,,,,,,,,,,,,,,,,,,,,,,,,,,,
,3865573859.93807,300.00016784668,-4487.61376953125,-0.00335232109724069,6.67247061356691E-6,1,2,12.9061126708984,5.00329864601448,39.0199981629849,-4.38388685045914,-0.625428046153533,100,1.39409706846082E-5,,,,,,,,,,,,,,,,,,,,,300.000122070313,300.000213623047,-4577.525390625,-4397.7021484375,50.229011902813,5.40828453810421,8.63704109191895,26,1,0,0,1,0.275802612304687,31.7693061828613,1,6,1,300.000122070313,0,300.00016784668,,,,,,,,,,,,,,,,,,,,,,,,,,,,,,,,,
,3865573894.15989,299.999557495117,-1069.69750976562,-0.00124654516117884,7.39932136167059E-6,1,2,12.9061126708984,5.00392522190494,39.0300005674362,-1.63388833947143,-0.208953179167978,100,2.32768130976125E-5,,,,,,,,,,,,,,,,,,,,,299.999542236328,299.999572753906,-1159.64025878906,-979.754760742188,50.2094711898322,5.40620888008317,8.6244535446167,26,1,0,0,1,0.272979736328125,31.2805480957031,1,6,1,299.999542236328,0,299.999557495117,,,,,,,,,,,,,,,,,,,,,,,,,,,,,,,,,
,3865573929.70698,300.000305175781,2483.66552734375,0.00153688494762229,8.14569934522284E-6,1,2,12.9061126708984,5.00319771163282,39.0199981629849,2.00751842942957,0.30193646872832,100,5.25061027524559E-6,,,,,,,,,,,,,,,,,,,,,299.999969482422,300.000640869141,2318.81665039062,2648.51440429687,50.2110344468707,5.40847384635844,8.62358665466309,26,1,0,0,1,0.27496337890625,32.2580642700195,1,6,1,300.000640869141,0,300.000305175781,,,,,,,,,,,,,,,,,,,,,,,,,,,,,,,,,
,3865573964.93058,299.999435424805,6002.93188476563,0.00388212113768731,7.26413218493288E-6,1,2,12.9061126708984,5.00342528535092,39.0300005674362,5.07351866160462,0.7472795325101,100,1.4410692173244E-6,,,,,,,,,,,,,,,,,,,,,299.999206542969,299.999664306641,5937.796875,6068.06689453125,50.1997008333418,5.40790214046842,8.62060928344727,26,1,0,0,1,0.2801513671875,31.7693061828613,1,6,1,299.999664306641,0,299.999435424805,,,,,,,,,,,,,,,,,,,,,,,,,,,,,,,,,
,3865574011.33311,299.999160766602,10643.5043945312,0.00675213068457187,6.64209828685405E-6,1,2,12.9061126708984,5.00365461314583,39.0199981629849,8.82473241064985,1.30083285607902,10,3.28252359178091E-6,,,,,,,,,,,,,,,,,,,,,299.999084472656,299.999237060547,10578.5263671875,10708.482421875,50.3392215240246,5.40690524600671,8.613112449646,26,1,0,0,1,0.2789306640625,31.7693061828613,1,6,1,299.999084472656,0,299.999160766602,,,,,,,,,,,,,,,,,,,,,,,,,,,,,,,,,
,3865574067.401,299.999755859375,16254.3359375,0.0100713076239094,6.66770076314067E-6,1,2,12.9061126708984,5.00376086813682,39.0199981629849,13.1645401278072,1.93081151882885,100,-2.39916703552373E-6,,,,,,,,,,,,,,,,,,,,,299.999542236328,299.999969482422,16159.3603515625,16349.3115234375,50.1938386194476,5.40672221818807,8.6032829284668,26,1,0,0,1,0.274658203125,30.7917900085449,1,6,1,299.999969482422,0,299.999755859375,,,,,,,,,,,,,,,,,,,,,,,,,,,,,,,,,
,3865574115.84634,300.000671386719,21100.4365234375,0.0128494244483845,6.24419792641063E-6,1,2,12.9061126708984,5.00383638542454,39.0199981629849,16.7963257475108,2.46304413882585,100,-3.38498972920339E-6,,,,,,,,,,,,,,,,,,,,,300.000549316406,300.000793457031,21000.55859375,21200.314453125,50.2954503269476,5.4062972622534,8.60825824737549,26,1,0,0,1,0.278701782226562,31.7693061828613,1,6,1,300.000793457031,0,300.000671386719,,,,,,,,,,,,,,,,,,,,,,,,,,,,,,,,,
,3865574152.15546,300.000045776367,24731.232421875,0.014917788936142,6.75060014154838E-6,1,2,12.9061126708984,5.00383844509301,39.0199981629849,19.4994586179006,2.86342289184258,100,-9.44439689894636E-7,,,,,,,,,,,,,,,,,,,,,299.999786376953,300.000305175781,24631.38671875,24831.078125,50.2825534563803,5.40608285430101,8.604323387146,26,1,0,0,1,0.27740478515625,31.2805480957031,1,6,1,300.000305175781,0,300.000045776367,,,,,,,,,,,,,,,,,,,,,,,,,,,,,,,,,
,3865574192.68336,300.000778198242,28792.0537109375,0.0172051157962229,6.45182371751399E-6,1,2,12.9061126708984,5.00368862123619,39.0199981629849,22.4888185779153,3.29910610319166,100,-3.55556410217334E-6,,,,,,,,,,,,,,,,,,,,,300.000762939453,300.000793457031,28736.8984375,28847.208984375,50.1684356925726,5.40690540848668,8.59365653991699,26,1,0,0,1,0.278244018554687,29.8142719268799,1,6,1,300.000793457031,0,300.000778198242,,,,,,,,,,,,,,,,,,,,,,,,,,,,,,,,,
,3865574234.7661,299.99983215332,33005.865234375,0.0196028507348711,6.93371618033218E-6,1,2,12.9061126708984,5.0036938369218,39.0199981629849,25.6221502271109,3.76423574393379,100,4.58809221737035E-8,,,,,,,,,,,,,,,,,,,,,299.999725341797,299.999938964844,32895.28125,33116.44921875,50.2106436326111,5.4071887214473,8.59493446350098,26,1,0,0,1,0.279312133789062,31.7693061828613,1,6,1,299.999938964844,0,299.99983215332,,,,,,,,,,,,,,,,,,,,,,,,,,,,,,,,,
,3865574271.07688,300.000030517578,36648.67578125,0.0216540661630746,7.29269023871825E-6,1,2,12.9061126708984,5.00356724010603,39.0199981629849,28.3017709545434,4.16099296985871,100,2.3612918183755E-6,,,,,,,,,,,,,,,,,,,,,299.999542236328,300.000518798828,36533.1796875,36764.171875,50.1836774486976,5.40705479007696,8.58667373657227,26,1,0,0,1,0.27435302734375,31.2805480957031,1,6,1,300.000518798828,0,300.000030517578,,,,,,,,,,,,,,,,,,,,,,,,,,,,,,,,,
,3865574315.21646,300.000259399414,41073.1484375,0.0241625450749593,1.13569693776278E-5,1,2,12.9061126708984,5.00357497761131,39.0300005674362,31.5809954550587,4.63904396714148,100,-4.12017889936003E-7,,,,,,,,,,,,,,,,,,,,,300.000213623047,300.000305175781,40983.04296875,41163.25390625,50.025788487813,5.40804872468301,8.58766937255859,26,1,0,0,1,0.277557373046875,31.2805480957031,1,6,1,300.000213623047,0,300.000259399414,,,,,,,,,,,,,,,,,,,,,,,,,,,,,,,,,
,3865574357.94634,299.999740600586,45351.2421875,0.0265488938343619,7.37152803042132E-6,1,2,12.9061126708984,5.00356932607191,39.0199981629849,34.6996528149079,5.09923953618399,100,1.10880773121893E-6,,,,,,,,,,,,,,,,,,,,,299.999633789063,299.999847412109,45301.15625,45401.328125,50.1344348519861,5.40788654058588,8.58472347259522,26,1,0,0,1,0.273971557617187,31.2805480957031,1,6,1,299.999847412109,0,299.999740600586,,,,,,,,,,,,,,,,,,,,,,,,,,,,,,,,,
,3865574410.96999,300.000915527344,50000.25390625,0.029201314132491,3.89992396570019E-6,1,2,12.9061126708984,5.00371164387206,39.0199981629849,38.1681559171082,5.60724147641941,100,-5.88961280411144E-8,,,,,,,,,,,,,,,,,,,,,300.000915527344,300.000915527344,50000.25390625,50000.25390625,50.1332624092072,5.40673546013252,8.58474636077881,26,1,0,0,1,0.27740478515625,30.7917900085449,1,4,1,300.000915527344,0,300.000915527344,,,,,,,,,,,,,,,,,,,,,,,,,,,,,,,,,
,3865576186.704,300.000442504883,24.7702808380127,0.000485683463455284,5.63629198026534E-8,1,2,12.9061126708984,5.00436279999874,39.0199981629849,0.634929162229232,0.0933368866982105,1,4.40569516743842E-8,,,,,,,,,,,,,,,,,,,,,300.000244140625,300.000640869141,24.7702808380127,24.7702808380127,50.0711229419284,5.40525766876424,8.55381107330322,26,1,0,0,1,0.276947021484375,30.3030319213867,1,1,1,300.000640869141,0,300.000442504883,,,,,,,,,,,,,,,,,,,,,,,,,,,,,,,,,
,3865576222.96274,299.999694824219,24.7702808380127,0.000485670398682864,5.98828753741287E-8,1,2,12.9061126708984,5.00437291841977,39.0300005674362,0.63491485718961,0.0933279838713624,1,3.89642593235891E-8,,,,,,,,,,,,,,,,,,,,,299.999694824219,299.999694824219,24.7702808380127,24.7702808380127,50.1348256662457,5.40578651521978,8.54527378082275,26,1,0,0,1,0.274734497070313,30.3030319213867,1,1,1,299.999694824219,0,299.999694824219,,,,,,,,,,,,,,,,,,,,,,,,,,,,,,,,,
,3865576259.24175,299.999862670898,24.7702808380127,0.000485623510459019,9.75511922782077E-8,1,2,12.9061126708984,5.00420844919704,39.0199981629849,0.634816897021308,0.0933654888781551,1,7.78262385580172E-8,,,,,,,,,,,,,,,,,,,,,299.999847412109,299.999877929687,24.7702808380127,24.7702808380127,50.0726861989668,5.40628586564862,8.55236053466797,26,1,0,0,1,0.276947021484375,30.7917900085449,1,1,1,299.999877929687,0,299.999862670898,,,,,,,,,,,,,,,,,,,,,,,,,,,,,,,,,
,3865576291.77481,300.000335693359,24.7702808380127,0.000485634852200785,8.15723329965531E-8,1,2,12.9061126708984,5.00431781902171,39.0199981629849,0.634864328340287,0.0932807581286312,1,9.16154975338825E-9,,,,,,,,,,,,,,,,,,,,,300.000274658203,300.000396728516,24.7702808380127,24.7702808380127,50.1160665817842,5.40624790263142,8.545729637146,26,1,0,0,1,0.275421142578125,30.7917900085449,1,1,1,300.000274658203,0,300.000335693359,,,,,,,,,,,,,,,,,,,,,,,,,,,,,,,,,
,3865576326.07443,300.001678466797,24.7702808380127,0.000485594203890812,5.25840255763952E-8,1,2,12.9061126708984,5.00425101157012,39.0199981629849,0.634801520045499,0.0932562948626231,1,-2.2469312923288E-9,,,,,,,,,,,,,,,,,,,,,300.001373291016,300.001983642578,24.7702808380127,24.7702808380127,50.0980891258418,5.40598817289417,8.54983043670654,26,1,0,0,1,0.276260375976562,31.2805480957031,1,1,1,300.001373291016,0,300.001678466797,,,,,,,,,,,,,,,,,,,,,,,,,,,,,,,,,
,3865576362.18519,299.999450683594,24.7702808380127,0.000485561927542544,1.38864249590988E-7,1,2,12.9061126708984,5.00449119900568,39.0300005674362,0.634796885159572,0.0932909234934453,1,2.41910136354779E-8,,,,,,,,,,,,,,,,,,,,,299.999114990234,299.999786376953,24.7702808380127,24.7702808380127,50.1844590772169,5.40497223015122,8.55642223358154,26,1,0,0,1,0.277175903320313,31.2805480957031,1,1,1,299.999114990234,0,299.999450683594,,,,,,,,,,,,,,,,,,,,,,,,,,,,,,,,,
,3865576398.41479,299.998794555664,24.7702808380127,0.000485566085473983,1.06800534433843E-7,1,2,12.9061126708984,5.0038640770879,39.0300005674362,0.634693795764511,0.0932562999046124,1,9.60820238108499E-9,,,,,,,,,,,,,,,,,,,,,299.998413085937,299.999176025391,24.7702808380127,24.7702808380127,50.1649183642361,5.40703985958551,8.55139255523682,26,1,0,0,1,0.279769897460938,30.7917900085449,1,1,1,299.999176025391,0,299.998794555664,,,,,,,,,,,,,,,,,,,,,,,,,,,,,,,,,
,3865576414.38639,299.998733520508,24.7702808380127,0.000485527330634402,1.15196575204265E-7,1,2,12.9061126708984,5.00414249810749,39.0199981629849,0.634685687530605,0.0933029022222051,1,4.53960218581981E-8,,,,,,,,,,,,,,,,,,,,,299.998657226562,299.998809814453,24.7702808380127,24.7702808380127,50.1430327656976,5.40612974198553,8.54773616790771,26,1,0,0,1,0.277175903320313,30.7917900085449,1,1,1,299.998809814453,0,299.998733520508,,,,,,,,,,,,,,,,,,,,,,,,,,,,,,,,,