File: LT data/Sherwood/K1/232-FC-ZFC-RTSIRM-contsweep.dat
[Header]
; MPMS3 Data File (default extension .dat)
; Copyright (c) 2007, Quantum Design, Inc. All rights reserved.
TITLE,
FILEOPENTIME,3865488570.28375,06/27/2022,11:47 am
BYAPP,MPMS3 w/ AC,1.0,1.1
INFO,MPMS3 Measurement Release 1.1.16 Build 424, MultiVu Release 2.3.4.19,APPNAME
INFO,Linear Motor Servo Controller,MOTOR_MODULE_NAME
INFO,3101-100 N2,MOTOR_HW_VERSION
INFO,,MOTOR_SERIAL_NUMBER
INFO,01.04.28,MOTOR_SOFTWARE_VERSION
INFO,Quantum Design Squid Module,SQUID_MODULE_NAME
INFO,3101-501 B0,SQUID_HW_VERSION
INFO,SQM327,SQUID_SERIAL_NUMBER
INFO,01.03.04,SQUID_SOFTWARE_VERSION
INFO,Quantum Design VSM Oven,OVEN_MODULE_NAME
INFO,3101-201 A3,OVEN_HW_VERSION
INFO,OVB365,OVEN_SERIAL_NUMBER
INFO,01.07.07,OVEN_SOFTWARE_VERSION
INFO,SQUID AC,AC_MODULE_NAME
INFO,3101-401 G0,AC_HW_VERSION
INFO,SAC220,AC_SERIAL_NUMBER
INFO,SQUID AC 00.95.07,AC_SOFTWARE_VERSION
INFO,TCI344,COIL_SERIAL_NUMBER
INFO,0,MOMENT_UNITS
INFO,oil stained sst,SAMPLE_MATERIAL
INFO,,SAMPLE_COMMENT
INFO,285.13,SAMPLE_MASS
INFO,,SAMPLE_VOLUME
INFO,,SAMPLE_MOLECULAR_WEIGHT
INFO,,SAMPLE_SIZE
INFO,,SAMPLE_SHAPE
INFO,Straw,SAMPLE_HOLDER
INFO,Standard,SAMPLE_HOLDER_DETAIL
INFO,79.53,SAMPLE_OFFSET
DATATYPE,COMMENT,1
DATATYPE,TIME,2
STARTUPAXIS,X,2
STARTUPAXIS,Y1,5
FIELDGROUP, VSM,2,3,4,5,6,8,9,10,11,14,15
FIELDGROUP, DC, 2,3,4,14,56,57,58,59,60,61,62,63,64,65,66,67,68,69
FIELDGROUP, AC, 2,3,4,11,16,17,18,19,20,21,22,23,24,25,26,27,28,29,30
STARTUPGROUP, All
[Data]
Comment,Time Stamp (sec),Temperature (K),Magnetic Field (Oe),Moment (emu),M. Std. Err. (emu),Transport Action,Averaging Time (sec),Frequency (Hz),Peak Amplitude (mm),Center Position (mm),Lockin Signal' (V),Lockin Signal (V),Range,M. Quad. Signal (emu),AC Moment (emu),AC M. Std Err. (emu),AC Phase (deg),AC Phase Std. Err. (deg),AC Susceptibility (emu/Oe),AC Suscept. Std Err. (emu/Oe),AC X' (emu/Oe),AC X' Std Err. (emu/Oe),AC X'' (emu/Oe),AC X'' Std Err. (emu/Oe),AC Drive (Oe),AC Frequency (Hz),AC Averaging Time (sec),AC Cycles,AC Range,AC Measure Type,AC Signal' (V),AC Signal'' (V),AC Trim Coil Ratio,AC Trim Coil Phase,Min. Temperature (K),Max. Temperature (K),Min. Field (Oe),Max. Field (Oe),Mass (grams),Motor Lag (deg),Pressure (Torr),Measure Count,Measurement Number,SQUID Status (code),Motor Status (code),Measure Status (code),Motor Current (amps),Motor Temp. (C),Temp. Status (code),Field Status (code),Chamber Status (code),Chamber Temp (K),Redirection State,Average Temp (K),Rotation Angle (deg),Rotator state,DC Moment Fixed Ctr (emu),DC Moment Err Fixed Ctr (emu),DC Moment Free Ctr (emu),DC Moment Err Free Ctr (emu),DC Fixed Fit,DC Free Fit,DC Calculated Center (mm),DC Calculated Center Err (mm),DC Scan Length (mm),DC Scan Time (s),DC Number of Points,DC Squid Drift,DC Min V (V),DC Max V (V),DC Scans per Measure,Map 01,Map 02,Map 03,Map 04,Map 05,Map 06,Map 07,Map 08,Map 09,Map 10,Map 11,Map 12,Map 13,Map 14,Map 15,Map 16
,3865492126.45668,1.99995577335358,25.5224132537842,0.0145659538484813,1.11410385097502E-6,1,5,12.9061126708984,4.98829161622181,37.9300005733967,18.9546193121594,2.79787081648735,10,9.95073223907707E-6,,,,,,,,,,,,,,,,,,,,,1.99995577335358,1.99995577335358,25.5224132537842,25.5224132537842,50.0164089455822,5.43535887934168,2.67230772972107,65,1,0,0,1,0.289306640625,31.2805480957031,5,1,1,1.99995577335358,0,1.99995577335358,,,,,,,,,,,,,,,,,,,,,,,,,,,,,,,,,
,3865492214.94695,14.1192331314087,25.5224132537842,0.000638363969243697,1.27564131001677E-7,1,5,12.9061126708984,4.98972519840623,37.9300005733967,0.831087010466793,0.122318803275046,1,1.67677283861456E-7,,,,,,,,,,,,,,,,,,,,,13.649097442627,14.5893688201904,25.5224132537842,25.5224132537842,49.9679479773899,5.4275451488413,5.30765628814697,65,1,0,0,1,0.278472900390625,31.7693061828613,6,1,1,14.5893688201904,0,14.1192331314087,,,,,,,,,,,,,,,,,,,,,,,,,,,,,,,,,
,3865492286.41223,25.0785808563232,25.5224132537842,0.000635430355417543,4.9801052981907E-8,1,5,12.9061126708984,4.99048119982935,37.9300005733967,0.827452334078062,0.121723339814564,1,1.2142040717497E-7,,,,,,,,,,,,,,,,,,,,,25.0785808563232,25.0785808563232,25.5224132537842,25.5224132537842,49.9335563225437,5.42542299838041,5.93739986419678,65,1,0,0,1,0.282821655273438,31.2805480957031,2,1,1,25.0785808563232,0,25.0785808563232,,,,,,,,,,,,,,,,,,,,,,,,,,,,,,,,,
,3865492363.55082,37.1142501831055,25.5224132537842,0.000630996349272506,4.79574222039242E-8,1,5,12.9061126708984,4.99045619727388,37.9399992525578,0.821763983028349,0.120251284851805,1,-3.56938462293762E-7,,,,,,,,,,,,,,,,,,,,,37.1142501831055,37.1142501831055,25.5224132537842,25.5224132537842,50.1993100190822,5.42697458344256,6.30643463134766,65,1,0,0,1,0.280075073242187,31.2805480957031,2,1,1,37.1142501831055,0,37.1142501831055,,,,,,,,,,,,,,,,,,,,,,,,,,,,,,,,,
,3865492440.5401,49.1577339172363,25.5224132537842,0.00062251031371366,4.58646463112835E-8,1,5,12.9061126708984,4.99060600249407,37.9500016570091,0.810765301174473,0.118511316576906,1,-4.5023613394665E-7,,,,,,,,,,,,,,,,,,,,,49.1577339172363,49.1577339172363,25.5224132537842,25.5224132537842,50.0695596848899,5.42748139196007,6.53054285049438,65,1,0,0,1,0.282440185546875,31.7693061828613,2,1,1,49.1577339172363,0,49.1577339172363,,,,,,,,,,,,,,,,,,,,,,,,,,,,,,,,,
,3865492515.60821,61.0228080749512,25.5224132537842,0.000613367937597999,4.19788239783314E-8,1,5,12.9061126708984,4.98861660647236,37.9699990153313,0.798401922819642,0.116769105316394,1,-3.94755310170336E-7,,,,,,,,,,,,,,,,,,,,,61.0228080749512,61.0228080749512,25.5224132537842,25.5224132537842,49.9464531931111,5.43428854413595,6.70310735702515,65,1,0,0,1,0.2880859375,31.2805480957031,2,1,1,61.0228080749512,0,61.0228080749512,,,,,,,,,,,,,,,,,,,,,,,,,,,,,,,,,
,3865492591.06107,73.0214614868164,25.5224132537842,0.000604380722089464,3.38236349378557E-8,1,5,12.9061126708984,4.98700288268137,37.9900000989437,0.786317490079021,0.115201966498427,1,-2.38281886344188E-7,,,,,,,,,,,,,,,,,,,,,73.0214614868164,73.0214614868164,25.5224132537842,25.5224132537842,50.0379037298611,5.43891359454611,6.81010150909424,63,1,64,0,0,0.27435302734375,30.7917900085449,2,1,1,73.0214614868164,0,73.0214614868164,,,,,,,,,,,,,,,,,,,,,,,,,,,,,,,,,
,3865492665.77383,85.0168151855469,25.5224132537842,0.000596032189955803,6.41061951574698E-8,1,5,12.9061126708984,4.98846384682363,38.0100011825562,0.775823558788235,0.11332518628767,1,-4.90223556574483E-7,,,,,,,,,,,,,,,,,,,,,85.0168151855469,85.0168151855469,25.5224132537842,25.5224132537842,50.0480649006111,5.43371481580679,6.89826583862305,63,1,64,0,0,0.288162231445313,34.2131004333496,2,1,1,85.0168151855469,0,85.0168151855469,,,,,,,,,,,,,,,,,,,,,,,,,,,,,,,,,
,3865492738.86793,97.1006164550781,25.5224132537842,0.000586467910595336,3.11294000845269E-8,1,5,12.9061126708984,4.98696975939751,38.0299985408783,0.762989537573581,0.111893607366111,1,-1.48915609066192E-7,,,,,,,,,,,,,,,,,,,,,97.1006164550781,97.1006164550781,25.5224132537842,25.5224132537842,50.0085926603899,5.43873142011418,6.96110200881958,65,1,0,0,1,0.281906127929687,31.2805480957031,2,1,1,97.1006164550781,0,97.1006164550781,,,,,,,,,,,,,,,,,,,,,,,,,,,,,,,,,
,3865492811.60279,109.00675201416,25.5224132537842,0.000577608331196145,5.33871701889427E-8,1,5,12.9061126708984,4.9884422545834,38.0599983036518,0.751835958029349,0.109832913122244,1,-4.66333051557412E-7,,,,,,,,,,,,,,,,,,,,,109.00675201416,109.00675201416,25.5224132537842,25.5224132537842,50.107077853813,5.43313186243889,7.02102327346802,65,1,0,0,1,0.287857055664062,31.7693061828613,2,1,1,109.00675201416,0,109.00675201416,,,,,,,,,,,,,,,,,,,,,,,,,,,,,,,,,
,3865492883.92864,121.010009765625,25.5224132537842,0.000567052643859461,3.9004351774665E-8,1,5,12.9061126708984,4.98874804758626,38.0900017917156,0.738162129341193,0.107819195255391,1,-4.69964980558944E-7,,,,,,,,,,,,,,,,,,,,,121.010009765625,121.010009765625,25.5224132537842,25.5224132537842,50.0441567580149,5.43240380611967,7.0606369972229,65,1,0,0,1,0.2874755859375,31.2805480957031,2,1,1,121.010009765625,0,121.010009765625,,,,,,,,,,,,,,,,,,,,,,,,,,,,,,,,,
,3865492957.34539,133.126495361328,25.5224132537842,0.00055824225901261,4.3240712599293E-8,1,5,12.9061126708984,4.98914436447363,38.1200015544891,0.726772425185341,0.106168062187633,1,-4.53264482380705E-7,,,,,,,,,,,,,,,,,,,,,133.126495361328,133.126495361328,25.5224132537842,25.5224132537842,50.0922269119476,5.43074947351025,7.09111261367798,63,1,64,0,0,0.285720825195313,31.2805480957031,2,1,1,133.126495361328,0,133.126495361328,,,,,,,,,,,,,,,,,,,,,,,,,,,,,,,,,
,3865493029.50795,145.089553833008,25.5224132537842,0.000549890516897323,6.87840915758028E-8,1,5,12.9061126708984,4.98967808676227,38.1599999964237,0.716005557825733,0.104604055152687,1,-4.39840613732011E-7,,,,,,,,,,,,,,,,,,,,,145.089553833008,145.089553833008,25.5224132537842,25.5224132537842,50.1379521803226,5.4288557323449,7.12813520431519,64,1,64,0,0,0.285415649414062,31.2805480957031,2,1,1,145.089553833008,0,145.089553833008,,,,,,,,,,,,,,,,,,,,,,,,,,,,,,,,,
,3865493102.23073,157.078140258789,25.5224132537842,0.000541988485965206,4.42057868678058E-8,1,5,12.9061126708984,4.98846210264169,38.1999984383583,0.705491264250316,0.102955175741249,1,-5.18372710855486E-7,,,,,,,,,,,,,,,,,,,,,157.078140258789,157.078140258789,25.5224132537842,25.5224132537842,50.1289634523515,5.43581727071023,7.16266059875488,65,1,0,0,1,0.286865234375,31.7693061828613,2,1,1,157.078140258789,0,157.078140258789,,,,,,,,,,,,,,,,,,,,,,,,,,,,,,,,,
,3865493174.17822,169.072509765625,25.5224132537842,0.000534508151758093,5.2483947744399E-8,1,5,12.9061126708984,4.98919550217275,38.2400006055832,0.695888411000166,0.101619805771249,1,-4.61572030849254E-7,,,,,,,,,,,,,,,,,,,,,169.072509765625,169.072509765625,25.5224132537842,25.5224132537842,50.0777667843418,5.43258690916558,7.19432401657105,65,1,0,0,1,0.2862548828125,31.7693061828613,2,1,1,169.072509765625,0,169.072509765625,,,,,,,,,,,,,,,,,,,,,,,,,,,,,,,,,
,3865493245.99016,181.005737304687,25.5224132537842,0.000526170451314305,3.93353355862454E-8,1,5,12.9061126708984,4.98945209450492,38.2900014519691,0.685026431643685,0.100425674880799,1,-1.59562682289925E-7,,,,,,,,,,,,,,,,,,,,,181.005737304687,181.005737304687,25.5224132537842,25.5224132537842,50.1199747243803,5.42956095965063,7.21594619750977,63,1,64,0,0,0.286331176757813,31.2805480957031,2,1,1,181.005737304687,0,181.005737304687,,,,,,,,,,,,,,,,,,,,,,,,,,,,,,,,,
,3865493318.94726,193.020935058594,25.5224132537842,0.000518225287197507,3.61786002390808E-8,1,5,12.9061126708984,4.98966772843881,38.3299998939037,0.674791139681091,0.0984546189821305,1,-5.1095815913526E-7,,,,,,,,,,,,,,,,,,,,,193.020935058594,193.020935058594,25.5224132537842,25.5224132537842,50.051191414688,5.43182818000821,7.26813840866089,63,1,64,0,0,0.286102294921875,31.7693061828613,2,1,1,193.020935058594,0,193.020935058594,,,,,,,,,,,,,,,,,,,,,,,,,,,,,,,,,
,3865493391.87448,205.114669799805,25.5224132537842,0.000509323587337292,4.0566253105719E-8,1,5,12.9061126708984,4.99062223690745,38.3800007402897,0.663371454867506,0.0968346871839598,1,-4.67416388590404E-7,,,,,,,,,,,,,,,,,,,,,205.114669799805,205.114669799805,25.5224132537842,25.5224132537842,50.1516306794092,5.42828545168266,7.31964683532715,64,1,64,0,0,0.283355712890625,31.7693061828613,2,1,1,205.114669799805,0,205.114669799805,,,,,,,,,,,,,,,,,,,,,,,,,,,,,,,,,
,3865493463.99705,217.094589233398,25.5224132537842,0.000501321240306411,2.48420477064757E-8,1,5,12.9061126708984,4.9918697830558,38.4400002658367,0.653108450364791,0.0958184998092443,1,-9.78953178043686E-8,,,,,,,,,,,,,,,,,,,,,217.094589233398,217.094589233398,25.5224132537842,25.5224132537842,50.0066385890918,5.42252937649937,7.3949990272522,65,1,0,0,1,0.27862548828125,31.2805480957031,2,1,1,217.094589233398,0,217.094589233398,,,,,,,,,,,,,,,,,,,,,,,,,,,,,,,,,
,3865493536.31268,229.06005859375,25.5224132537842,0.000493793582321271,2.96182907018766E-8,1,5,12.9061126708984,4.99175097995008,38.4900011122227,0.643343867689675,0.0939427397547895,1,-4.29453169614436E-7,,,,,,,,,,,,,,,,,,,,,229.06005859375,229.06005859375,25.5224132537842,25.5224132537842,50.1004340113995,5.42397519622633,7.488844871521,64,1,64,0,0,0.279159545898438,31.7693061828613,2,1,1,229.06005859375,0,229.06005859375,,,,,,,,,,,,,,,,,,,,,,,,,,,,,,,,,
,3865493608.1633,241.046966552734,25.5224132537842,0.000487077566629466,4.87594363828242E-8,1,5,12.9061126708984,4.99160276729151,38.5500006377697,0.634525719474618,0.0929449373955385,1,-2.05778158213522E-7,,,,,,,,,,,,,,,,,,,,,241.046966552734,241.046966552734,25.5224132537842,25.5224132537842,50.0449383865341,5.42452914708219,7.63860034942627,64,1,64,0,0,0.279159545898438,31.7693061828613,2,1,1,241.046966552734,0,241.046966552734,,,,,,,,,,,,,,,,,,,,,,,,,,,,,,,,,
,3865493680.23543,253.032531738281,25.5224132537842,0.000480922905332388,3.03979257827113E-8,1,5,12.9061126708984,4.99196604800336,38.6100001633167,0.626570878145329,0.0917867173879434,1,-1.97917804855043E-7,,,,,,,,,,,,,,,,,,,,,253.032531738281,253.032531738281,25.5224132537842,25.5224132537842,50.1496766081111,5.42420742092182,7.80773878097534,63,1,64,0,0,0.278701782226562,31.2805480957031,2,1,1,253.032531738281,0,253.032531738281,,,,,,,,,,,,,,,,,,,,,,,,,,,,,,,,,
,3865493752.89395,265.013092041016,25.5224132537842,0.0004749487335872,5.02148836358235E-8,1,5,12.9061126708984,4.99332508797647,38.6799983680248,0.618977405498069,0.0909964252688404,1,4.64665000174612E-8,,,,,,,,,,,,,,,,,,,,,265.013092041016,265.013092041016,25.5224132537842,25.5224132537842,50.1262277525342,5.42005869832224,8.01865673065186,64,1,64,0,0,0.27862548828125,31.7693061828613,2,1,1,265.013092041016,0,265.013092041016,,,,,,,,,,,,,,,,,,,,,,,,,,,,,,,,,
,3865493824.69766,277.024536132813,25.5224132537842,0.000467392400109713,2.97179504478773E-8,1,5,12.9061126708984,4.9938062308662,38.7500002980232,0.609232898799518,0.0894179900324545,1,-6.38303467032547E-8,,,,,,,,,,,,,,,,,,,,,277.024536132813,277.024536132813,25.5224132537842,25.5224132537842,50.0785484128611,5.41643856416453,8.29697322845459,63,1,64,0,0,0.27435302734375,31.7693061828613,2,1,1,277.024536132813,0,277.024536132813,,,,,,,,,,,,,,,,,,,,,,,,,,,,,,,,,
,3865493896.9661,289.028472900391,25.5224132537842,0.000460108846428977,2.44291083703659E-8,1,5,12.9061126708984,4.99492095351891,38.8199985027313,0.599917571930428,0.088114332681108,1,-1.51118405766354E-8,,,,,,,,,,,,,,,,,,,,,289.028472900391,289.028472900391,25.5224132537842,25.5224132537842,50.0367312870822,5.41216656742587,8.12147426605225,64,1,64,0,0,0.267410278320313,31.7693061828613,2,1,1,289.028472900391,0,289.028472900391,,,,,,,,,,,,,,,,,,,,,,,,,,,,,,,,,
,3865496692.02323,2.03549909591675,25.2842388153076,0.0148442759105149,8.51044445757412E-7,1,5,12.9061126708984,5.00012796545263,37.9300005733967,19.3809663621502,2.86173418636843,10,1.08385378962733E-5,,,,,,,,,,,,,,,,,,,,,2.03549909591675,2.03549909591675,25.2842388153076,25.2842388153076,49.9405909792168,5.43010785546116,2.61110067367554,65,1,0,0,1,0.287704467773438,32.2580642700195,6,1,1,2.03549909591675,0,2.03549909591675,,,,,,,,,,,,,,,,,,,,,,,,,,,,,,,,,
,3865496783.68818,14.5486211776733,25.2842388153076,0.000570142777695858,7.95657119597435E-8,1,5,12.9061126708984,5.00065848935106,37.9300005733967,0.744541856791616,0.10964410134396,1,1.96942289707919E-7,,,,,,,,,,,,,,,,,,,,,14.5486211776733,14.5486211776733,25.2842388153076,25.2842388153076,49.9437174932937,5.42846775950624,5.29469060897827,65,1,0,0,1,0.284194946289062,31.2805480957031,6,1,1,14.5486211776733,0,14.5486211776733,,,,,,,,,,,,,,,,,,,,,,,,,,,,,,,,,
,3865496852.22579,25.0921192169189,25.2842388153076,0.000585204910050818,4.35271639515154E-8,1,5,12.9061126708984,5.00279382007353,37.9300005733967,0.764676543806635,0.112551516617079,1,1.58927104842039E-7,,,,,,,,,,,,,,,,,,,,,25.0921192169189,25.0921192169189,25.2842388153076,25.2842388153076,49.900727924736,5.41922535245956,5.94248580932617,65,1,0,0,1,0.2783203125,31.7693061828613,2,1,1,25.0921192169189,0,25.0921192169189,,,,,,,,,,,,,,,,,,,,,,,,,,,,,,,,,
,3865496929.39652,37.1726112365723,25.2842388153076,0.000584965298869112,5.13703079302052E-8,1,5,12.9061126708984,5.00692993003874,37.9399992525578,0.765354091060948,0.111912710021351,1,-3.93711446572243E-7,,,,,,,,,,,,,,,,,,,,,37.1726112365723,37.1726112365723,25.2842388153076,25.2842388153076,49.9949141613034,5.40651581542931,6.30626392364502,65,1,0,0,1,0.27862548828125,31.7693061828613,2,1,1,37.1726112365723,0,37.1726112365723,,,,,,,,,,,,,,,,,,,,,,,,,,,,,,,,,
,3865497005.27253,49.0192909240723,25.2842388153076,0.000581019554793476,4.60231630049447E-8,1,5,12.9061126708984,5.00214646739319,37.9500016570091,0.759126785628259,0.11134037062869,1,-1.37610526373891E-7,,,,,,,,,,,,,,,,,,,,,49.0192909240723,49.0192909240723,25.2842388153076,25.2842388153076,49.9534878497841,5.4254370862326,6.53194570541382,65,1,0,0,1,0.281295776367187,31.7693061828613,2,1,1,49.0192909240723,0,49.0192909240723,,,,,,,,,,,,,,,,,,,,,,,,,,,,,,,,,
,3865497081.41486,61.0913238525391,25.2842388153076,0.00057546047387969,4.44976881674377E-8,1,5,12.9061126708984,4.99865155462923,37.9699990153313,0.751137490963389,0.110102535538608,1,-1.85833436064168E-7,,,,,,,,,,,,,,,,,,,,,61.0913238525391,61.0913238525391,25.2842388153076,25.2842388153076,50.0203170881784,5.44099207676705,6.6854829788208,65,1,0,0,1,0.279998779296875,31.7693061828613,2,1,1,61.0913238525391,0,61.0913238525391,,,,,,,,,,,,,,,,,,,,,,,,,,,,,,,,,
,3865497156.52246,73.0127334594727,25.2842388153076,0.000569593614538556,5.21778714689674E-8,1,5,12.9061126708984,4.99777157445475,37.9900000989437,0.74331409313548,0.108831441080386,1,-2.77211714259395E-7,,,,,,,,,,,,,,,,,,,,,73.0127334594727,73.0127334594727,25.2842388153076,25.2842388153076,49.9671663488707,5.44323212776229,6.79674434661865,64,1,64,0,0,0.2716064453125,31.7693061828613,2,1,1,73.0127334594727,0,73.0127334594727,,,,,,,,,,,,,,,,,,,,,,,,,,,,,,,,,
,3865497231.50993,85.0568695068359,25.2842388153076,0.0005630949689257,2.97459269335356E-8,1,5,12.9061126708984,4.99707450563344,38.0100011825562,0.734698535901773,0.107509278919146,1,-3.19614688161617E-7,,,,,,,,,,,,,,,,,,,,,85.0568695068359,85.0568695068359,25.2842388153076,25.2842388153076,50.0722953847072,5.44529124208305,6.88552188873291,64,1,64,0,0,0.28167724609375,31.7693061828613,2,1,1,85.0568695068359,0,85.0568695068359,,,,,,,,,,,,,,,,,,,,,,,,,,,,,,,,,
,3865497304.12731,97.0758666992188,25.2842388153076,0.000556996762603222,4.49377165889593E-8,1,5,12.9061126708984,4.99818888096582,38.0499996244907,0.726972779602712,0.106352550097319,1,-3.35814225562119E-7,,,,,,,,,,,,,,,,,,,,,97.0758666992188,97.0758666992188,25.2842388153076,25.2842388153076,49.9718561199861,5.43788255841907,6.95492935180664,65,1,0,0,1,0.279693603515625,31.2805480957031,2,1,1,97.0758666992188,0,97.0758666992188,,,,,,,,,,,,,,,,,,,,,,,,,,,,,,,,,
,3865497377.1691,109.095420837402,25.2842388153076,0.000549952246231851,3.7049353911762E-8,1,5,12.9061126708984,4.99994439129231,38.0599983036518,0.718144630860441,0.104971263422322,1,-3.98874710461761E-7,,,,,,,,,,,,,,,,,,,,,109.095420837402,109.095420837402,25.2842388153076,25.2842388153076,50.0316507017072,5.43101691295123,7.00206279754639,63,1,64,0,0,0.283889770507813,31.7693061828613,2,1,1,109.095420837402,0,109.095420837402,,,,,,,,,,,,,,,,,,,,,,,,,,,,,,,,,
,3865497449.33148,121.063842773437,25.2842388153076,0.00054234684025129,5.09042459162733E-8,1,5,12.9061126708984,4.99956908374032,38.0900017917156,0.70814111275864,0.10349293971466,1,-4.0543770765316E-7,,,,,,,,,,,,,,,,,,,,,121.063842773437,121.063842773437,25.2842388153076,25.2842388153076,50.025788487813,5.43335222708437,7.04572916030884,65,1,0,0,1,0.286483764648438,32.7468223571777,2,1,1,121.063842773437,0,121.063842773437,,,,,,,,,,,,,,,,,,,,,,,,,,,,,,,,,
,3865497521.56607,133.033386230469,25.2842388153076,0.000534952656576771,4.59808447613755E-8,1,5,12.9061126708984,4.99928658606685,38.1200015544891,0.698396928343849,0.102307542735253,1,-2.20912555551813E-7,,,,,,,,,,,,,,,,,,,,,133.033386230469,133.033386230469,25.2842388153076,25.2842388153076,50.0320415159668,5.43532695816726,7.0888032913208,64,1,64,0,0,0.278396606445313,32.2580642700195,2,1,1,133.033386230469,0,133.033386230469,,,,,,,,,,,,,,,,,,,,,,,,,,,,,,,,,
,3865497594.59873,145.047698974609,25.2842388153076,0.000529065290616258,4.94035053246025E-8,1,5,12.9061126708984,4.99968339807039,38.1599999964237,0.690827032302038,0.100924391001179,1,-4.24109040767428E-7,,,,,,,,,,,,,,,,,,,,,145.047698974609,145.047698974609,25.2842388153076,25.2842388153076,50.0429843152361,5.43344787603728,7.12173223495483,63,1,64,0,0,0.283737182617187,32.2580642700195,2,1,1,145.047698974609,0,145.047698974609,,,,,,,,,,,,,,,,,,,,,,,,,,,,,,,,,
,3865497666.91444,157.017074584961,25.2842388153076,0.00052305487618999,2.79115513682267E-8,1,5,12.9061126708984,5.00137969339129,38.1899997591972,0.68329669017769,0.0998714849665718,1,-3.83902092040587E-7,,,,,,,,,,,,,,,,,,,,,157.017074584961,157.017074584961,25.2842388153076,25.2842388153076,50.0109375459476,5.42764146440193,7.14255237579346,63,1,64,0,0,0.283126831054687,31.7693061828613,2,1,1,157.017074584961,0,157.017074584961,,,,,,,,,,,,,,,,,,,,,,,,,,,,,,,,,
,3865497738.82299,169.015762329102,25.2842388153076,0.000516732398352083,3.70302080661003E-8,1,5,12.9061126708984,5.00211532763226,38.2299982011318,0.675172561657626,0.0987100352459209,1,-3.59792074929291E-7,,,,,,,,,,,,,,,,,,,,,169.015762329102,169.015762329102,25.2842388153076,25.2842388153076,50.1316991521688,5.42422314634847,7.17216873168945,65,1,0,0,1,0.282745361328125,32.2580642700195,2,1,1,169.015762329102,0,169.015762329102,,,,,,,,,,,,,,,,,,,,,,,,,,,,,,,,,
,3865497812.0193,181.113739013672,25.2842388153076,0.000510782945570496,3.94782330665199E-8,1,5,12.9061126708984,5.00299429259426,38.2799990475178,0.667537883999194,0.0977690053154076,1,-2.24432989573224E-7,,,,,,,,,,,,,,,,,,,,,181.113739013672,181.113739013672,25.2842388153076,25.2842388153076,50.1160665817842,5.41954580633626,7.21298694610596,63,1,64,0,0,0.280532836914062,31.7693061828613,2,1,1,181.113739013672,0,181.113739013672,,,,,,,,,,,,,,,,,,,,,,,,,,,,,,,,,
,3865497884.25091,193.042327880859,25.2842388153076,0.00050410506373115,4.32032729505348E-8,1,5,12.9061126708984,5.00316808003662,38.3299998939037,0.658872265460268,0.0962939071613216,1,-3.75742143115036E-7,,,,,,,,,,,,,,,,,,,,,193.042327880859,193.042327880859,25.2842388153076,25.2842388153076,50.1805509346207,5.41953594738733,7.25383901596069,64,1,64,0,0,0.2813720703125,31.2805480957031,2,1,1,193.042327880859,0,193.042327880859,,,,,,,,,,,,,,,,,,,,,,,,,,,,,,,,,
,3865497956.26511,205.018600463867,25.2842388153076,0.000497726071120098,2.97628842779072E-8,1,5,12.9061126708984,5.00394658533034,38.3800007402897,0.650642343875992,0.0953287388138943,1,-1.93016009990791E-7,,,,,,,,,,,,,,,,,,,,,205.018600463867,205.018600463867,25.2842388153076,25.2842388153076,50.2411271448611,5.41747445172823,7.29989671707153,63,1,64,0,0,0.277786254882813,32.2580642700195,2,1,1,205.018600463867,0,205.018600463867,,,,,,,,,,,,,,,,,,,,,,,,,,,,,,,,,
,3865498028.81581,217.079940795898,25.2842388153076,0.000491222833389452,3.19640194556866E-8,1,5,12.9061126708984,5.00361486210097,38.4400002658367,0.642074520292815,0.0941222245748607,1,-1.53945260541553E-7,,,,,,,,,,,,,,,,,,,,,217.079940795898,217.079940795898,25.2842388153076,25.2842388153076,50.203608975938,5.41969674732408,7.36319637298584,64,1,64,0,0,0.278701782226562,31.7693061828613,2,1,1,217.079940795898,0,217.079940795898,,,,,,,,,,,,,,,,,,,,,,,,,,,,,,,,,
,3865498101.11746,229.006118774414,25.2842388153076,0.000484980517334136,2.87690619468361E-8,1,5,12.9061126708984,5.00338596937392,38.4900011122227,0.633909622460918,0.0926820506080359,1,-3.34204233991303E-7,,,,,,,,,,,,,,,,,,,,,229.006118774414,229.006118774414,25.2842388153076,25.2842388153076,50.1328715949476,5.42155355601164,7.4480619430542,64,1,64,0,0,0.280609130859375,31.7693061828613,2,1,1,229.006118774414,0,229.006118774414,,,,,,,,,,,,,,,,,,,,,,,,,,,,,,,,,
,3865498173.63692,241.039337158203,25.2842388153076,0.000479910403628458,4.09876263987458E-8,1,5,12.9061126708984,5.00343267555602,38.5500006377697,0.6272981270587,0.0916641869599367,1,-3.69073609181504E-7,,,,,,,,,,,,,,,,,,,,,241.039337158203,241.039337158203,25.2842388153076,25.2842388153076,50.2919329986111,5.42135195935109,7.59617948532104,64,1,64,0,0,0.281753540039062,31.7693061828613,2,1,1,241.039337158203,0,241.039337158203,,,,,,,,,,,,,,,,,,,,,,,,,,,,,,,,,
,3865498246.47492,253.122116088867,25.2842388153076,0.000475372566784349,1.04616473997813E-7,1,5,12.9061126708984,5.00458794526079,38.6100001633167,0.621561182419258,0.0908694960705415,1,-3.32918992415732E-7,,,,,,,,,,,,,,,,,,,,,253.122116088867,253.122116088867,25.2842388153076,25.2842388153076,50.0808932984188,5.41649261114894,7.72140264511108,64,1,64,0,0,0.276565551757813,30.7917900085449,2,1,1,253.122116088867,0,253.122116088867,,,,,,,,,,,,,,,,,,,,,,,,,,,,,,,,,
,3865498318.59653,265.225250244141,25.2842388153076,0.000470711197558812,3.61324026366435E-8,1,5,12.9061126708984,5.00476888290294,38.6799983680248,0.615469051410263,0.0901764326373312,1,-1.81714619853022E-7,,,,,,,,,,,,,,,,,,,,,265.225250244141,265.225250244141,25.2842388153076,25.2842388153076,50.0980891258418,5.41613170022536,7.9311671257019,64,1,64,0,0,0.275344848632813,31.7693061828613,2,1,1,265.225250244141,0,265.225250244141,,,,,,,,,,,,,,,,,,,,,,,,,,,,,,,,,
,3865498390.32159,277.061401367187,25.2842388153076,0.000465859807876985,3.20584838536768E-8,1,5,12.9061126708984,5.0057575010266,38.7500002980232,0.609266657988638,0.0894583447052843,1,-3.71245333463695E-8,,,,,,,,,,,,,,,,,,,,,277.061401367187,277.061401367187,25.2842388153076,25.2842388153076,50.0824565554572,5.41167898921538,8.08344841003418,64,1,64,0,0,0.27374267578125,32.2580642700195,2,1,1,277.061401367187,0,277.061401367187,,,,,,,,,,,,,,,,,,,,,,,,,,,,,,,,,
,3865498462.38596,289.107788085937,25.2842388153076,0.000460650253657721,4.66709166671884E-8,1,5,12.9061126708984,5.00654024410007,38.8199985027313,0.602561227390369,0.0886406737386986,1,8.81741022134195E-8,,,,,,,,,,,,,,,,,,,,,289.107788085937,289.107788085937,25.2842388153076,25.2842388153076,50.0805024841591,5.40943432861004,7.93040704727173,64,1,64,0,0,0.279998779296875,32.2580642700195,2,1,1,289.107788085937,0,289.107788085937,,,,,,,,,,,,,,,,,,,,,,,,,,,,,,,,,
,3865499108.38332,300.002258300781,25.4221286773682,0.00048985381533588,2.55243848697518E-8,1,5,12.9061126708984,5.00815706541204,38.8699993491173,0.641029083607624,0.0944510475025219,1,2.07080865115914E-7,,,,,,,,,,,,,,,,,,,,,300.002258300781,300.002258300781,25.4221286773682,25.4221286773682,50.1023880826976,5.40605496176095,8.32131290435791,65,1,0,0,1,0.284042358398438,30.7917900085449,1,1,1,300.002258300781,0,300.002258300781,,,,,,,,,,,,,,,,,,,,,,,,,,,,,,,,,
,3865499210.11394,288.910888671875,25.4221286773682,0.000489067664990711,3.26733099737551E-8,1,5,12.9061126708984,5.00741531337886,38.8099998235703,0.639965630317547,0.0936137143907064,1,-3.0242899671334E-7,,,,,,,,,,,,,,,,,,,,,288.910888671875,288.910888671875,25.4221286773682,25.4221286773682,50.0472832720918,5.40781243303526,8.55233573913574,64,1,64,0,0,0.269393920898438,31.2805480957031,2,1,1,288.910888671875,0,288.910888671875,,,,,,,,,,,,,,,,,,,,,,,,,,,,,,,,,
,3865499272.5963,276.967315673828,25.4221286773682,0.000489313680729107,3.41716769422329E-8,1,5,12.9061126708984,5.00862940205483,38.7500002980232,0.640500701099106,0.0937195362902404,1,-2.81973616662845E-7,,,,,,,,,,,,,,,,,,,,,276.967315673828,276.967315673828,25.4221286773682,25.4221286773682,50.0453292007938,5.40067683387451,8.77672958374023,64,1,64,0,0,0.276260375976562,31.2805480957031,2,1,1,276.967315673828,0,276.967315673828,,,,,,,,,,,,,,,,,,,,,,,,,,,,,,,,,
,3865499347.00302,264.976867675781,25.4221286773682,0.000489844775122809,5.07833493118549E-8,1,5,12.9061126708984,5.0066150430709,38.6900007724762,0.640841433184902,0.0937265069048243,1,-3.14374007660288E-7,,,,,,,,,,,,,,,,,,,,,264.976867675781,264.976867675781,25.4221286773682,25.4221286773682,50.0832381839765,5.41106447954047,8.75168228149414,64,1,64,0,0,0.280609130859375,31.2805480957031,2,1,1,264.976867675781,0,264.976867675781,,,,,,,,,,,,,,,,,,,,,,,,,,,,,,,,,
,3865499419.8138,252.954727172852,25.4221286773682,0.000489848007053781,3.29646017490324E-8,1,5,12.9061126708984,5.00505265174711,38.6399999260902,0.640569626078637,0.0936607578854463,1,-3.3383902423473E-7,,,,,,,,,,,,,,,,,,,,,252.954727172852,252.954727172852,25.4221286773682,25.4221286773682,49.9519245927457,5.41939527954427,8.63403224945068,64,1,64,0,0,0.275039672851562,31.7693061828613,2,1,1,252.954727172852,0,252.954727172852,,,,,,,,,,,,,,,,,,,,,,,,,,,,,,,,,
,3865499491.63454,240.987945556641,25.4221286773682,0.000489387095245007,6.763955204249E-8,1,5,12.9061126708984,5.00445993249206,38.6000014841557,0.639816859655676,0.0938565262879162,1,-1.04508756327297E-7,,,,,,,,,,,,,,,,,,,,,240.987945556641,240.987945556641,25.4221286773682,25.4221286773682,49.9534878497841,5.42017753033569,8.53906440734863,64,1,64,0,0,0.275802612304687,34.2131004333496,2,1,1,240.987945556641,0,240.987945556641,,,,,,,,,,,,,,,,,,,,,,,,,,,,,,,,,
,3865499563.6978,228.956024169922,25.4221286773682,0.000488676864585132,5.16110665092677E-8,1,5,12.9061126708984,5.00360087634613,38.5500006377697,0.638788757790671,0.0933307342547306,1,-3.85197335790537E-7,,,,,,,,,,,,,,,,,,,,,228.956024169922,228.956024169922,25.4221286773682,25.4221286773682,49.9061993243707,5.42078352318136,8.45114040374756,65,1,0,0,1,0.279083251953125,31.7693061828613,2,1,1,228.956024169922,0,228.956024169922,,,,,,,,,,,,,,,,,,,,,,,,,,,,,,,,,
,3865499634.6166,216.924118041992,25.4221286773682,0.000487903175855776,3.2419886591233E-8,1,5,12.9061126708984,5.00057398120674,38.4900011122227,0.637227250171055,0.0931724363958576,1,-3.3222623553883E-7,,,,,,,,,,,,,,,,,,,,,216.924118041992,216.924118041992,25.4221286773682,25.4221286773682,49.9613041349764,5.43029059868533,8.37924289703369,63,1,64,0,0,0.28472900390625,31.2805480957031,2,1,1,216.924118041992,0,216.924118041992,,,,,,,,,,,,,,,,,,,,,,,,,,,,,,,,,
,3865499706.69041,204.825057983398,25.4221286773682,0.000487348839212887,3.88678575036319E-8,1,5,12.9061126708984,5.00038981722782,38.4499989449978,0.6364720465761,0.0930507559212885,1,-3.402887125002E-7,,,,,,,,,,,,,,,,,,,,,204.825057983398,204.825057983398,25.4221286773682,25.4221286773682,49.9034636245534,5.43020477325735,8.31509780883789,64,1,64,0,0,0.275726318359375,31.7693061828613,2,1,1,204.825057983398,0,204.825057983398,,,,,,,,,,,,,,,,,,,,,,,,,,,,,,,,,
,3865499778.6946,192.848892211914,25.4221286773682,0.000486338443023811,3.11363132515225E-8,1,5,12.9061126708984,5.00498167217787,38.4100005030632,0.635966429954565,0.0929957119720575,1,-3.2545038228687E-7,,,,,,,,,,,,,,,,,,,,,192.848892211914,192.848892211914,25.4221286773682,25.4221286773682,50.086755512313,5.41504776416444,8.24127292633057,65,1,0,0,1,0.276870727539062,31.2805480957031,2,1,1,192.848892211914,0,192.848892211914,,,,,,,,,,,,,,,,,,,,,,,,,,,,,,,,,
,3865499850.55166,180.949859619141,25.4221286773682,0.000485389859455172,2.28065642683593E-8,1,5,12.9061126708984,5.00317792233409,38.3699983358383,0.634369912522117,0.0930123638774822,1,-1.37462776582454E-7,,,,,,,,,,,,,,,,,,,,,180.949859619141,180.949859619141,25.4221286773682,25.4221286773682,49.9757642625822,5.42176424848717,8.18664455413818,63,1,64,0,0,0.281906127929687,32.2580642700195,2,1,1,180.949859619141,0,180.949859619141,,,,,,,,,,,,,,,,,,,,,,,,,,,,,,,,,
,3865499922.48034,168.944351196289,25.4221286773682,0.00048442600249382,4.48303254982492E-8,1,5,12.9061126708984,5.00230581690033,38.3399985730648,0.632947695661836,0.0928597448350415,1,-9.53011603043908E-8,,,,,,,,,,,,,,,,,,,,,168.944351196289,168.944351196289,25.4221286773682,25.4221286773682,49.9839713620341,5.42432114088422,8.12020397186279,64,1,64,0,0,0.281524658203125,31.7693061828613,2,1,1,168.944351196289,0,168.944351196289,,,,,,,,,,,,,,,,,,,,,,,,,,,,,,,,,
,3865499994.48905,156.822563171387,25.4221286773682,0.000482964368096645,3.27337116393259E-8,1,5,12.9061126708984,5.0016991624822,38.3000001311302,0.630978663190726,0.0922379679277947,1,-3.44472471929849E-7,,,,,,,,,,,,,,,,,,,,,156.810089111328,156.835037231445,25.4221286773682,25.4221286773682,49.8573475419187,5.42348037047528,8.06052970886231,65,1,0,0,1,0.282135009765625,31.7693061828613,2,1,1,156.810089111328,0,156.822563171387,,,,,,,,,,,,,,,,,,,,,,,,,,,,,,,,,
,3865500067.42356,144.894439697266,25.4221286773682,0.000482171958885318,2.79373306829592E-8,1,5,12.9061126708984,5.00374178256218,38.2600016891956,0.630308999999577,0.0921023364959825,1,-3.72172606294548E-7,,,,,,,,,,,,,,,,,,,,,144.894439697266,144.894439697266,25.4221286773682,25.4221286773682,49.9144064238226,5.4131014887865,8.00984859466553,65,1,0,0,1,0.280075073242187,31.7693061828613,2,1,1,144.894439697266,0,144.894439697266,,,,,,,,,,,,,,,,,,,,,,,,,,,,,,,,,
,3865500138.65811,132.919418334961,25.4221286773682,0.000481550876001294,3.23494437529793E-8,1,5,12.9061126708984,5.00688436499757,38.2299982011318,0.630073576496812,0.0919064433236954,1,-4.92542523376655E-7,,,,,,,,,,,,,,,,,,,,,132.919418334961,132.919418334961,25.4221286773682,25.4221286773682,49.9448899360726,5.40100366453729,7.95884895324707,65,1,0,0,1,0.274276733398438,31.7693061828613,2,1,1,132.919418334961,0,132.919418334961,,,,,,,,,,,,,,,,,,,,,,,,,,,,,,,,,
,3865500210.68762,120.886985778809,25.4221286773682,0.000480512360474076,3.91126384584341E-8,1,5,12.9061126708984,5.00782572785039,38.1899997591972,0.628876530536266,0.0917565924993435,1,-4.72957595431535E-7,,,,,,,,,,,,,,,,,,,,,120.886985778809,120.886985778809,25.4221286773682,25.4221286773682,49.9218318947553,5.39911475200068,7.88862609863281,64,1,64,0,0,0.270843505859375,31.7693061828613,2,1,1,120.886985778809,0,120.886985778809,,,,,,,,,,,,,,,,,,,,,,,,,,,,,,,,,
,3865500282.84414,108.925491333008,25.4221286773682,0.000479091086817866,3.42372044678966E-8,1,5,12.9061126708984,5.00740941304462,38.1599999964237,0.62694418071806,0.091470063577305,1,-4.74991829448763E-7,,,,,,,,,,,,,,,,,,,,,108.925491333008,108.925491333008,25.4221286773682,25.4221286773682,49.8510945137649,5.4015379082076,7.82097816467285,64,1,64,0,0,0.2801513671875,32.2580642700195,2,1,1,108.925491333008,0,108.925491333008,,,,,,,,,,,,,,,,,,,,,,,,,,,,,,,,,
,3865500353.42133,96.9661331176758,25.4221286773682,0.000477376753169487,4.98284134376199E-8,1,5,12.9061126708984,5.00479535482981,38.1300002336502,0.624223251880337,0.0912214996883155,1,-3.62160744943306E-7,,,,,,,,,,,,,,,,,,,,,96.9661331176758,96.9661331176758,25.4221286773682,25.4221286773682,49.9460623788514,5.41076593208003,7.75391244888306,65,1,0,0,1,0.276260375976562,32.2580642700195,2,1,1,96.9661331176758,0,96.9661331176758,,,,,,,,,,,,,,,,,,,,,,,,,,,,,,,,,
,3865500426.785,84.8600463867187,25.4221286773682,0.000475578115508075,2.83452555596323E-8,1,5,12.9061126708984,5.00555470577328,38.1000004708767,0.621969532403953,0.0911273483672788,1,-1.84725766170255E-7,,,,,,,,,,,,,,,,,,,,,84.8600463867187,84.8600463867187,25.4221286773682,25.4221286773682,50.0293058161495,5.40922479610497,7.67484188079834,65,1,0,0,1,0.274887084960938,31.7693061828613,2,1,1,84.8600463867187,0,84.8600463867187,,,,,,,,,,,,,,,,,,,,,,,,,,,,,,,,,
,3865500496.31822,72.9476165771484,25.4221286773682,0.000473806182031192,2.87741653587644E-8,1,5,12.9061126708984,5.00595932328279,38.0700007081032,0.619758277901509,0.0905528217876247,1,-3.71566272754337E-7,,,,,,,,,,,,,,,,,,,,,72.9476165771484,72.9476165771484,25.4221286773682,25.4221286773682,49.9304298084668,5.4070107822866,7.58639144897461,64,1,64,0,0,0.274276733398438,31.7693061828613,2,1,1,72.9476165771484,0,72.9476165771484,,,,,,,,,,,,,,,,,,,,,,,,,,,,,,,,,
,3865500566.28132,60.9529266357422,25.4221286773682,0.000471182085918454,5.80299300631359E-8,1,5,12.9061126708984,5.00468818737208,38.0400009453297,0.616097447155685,0.0900835739162796,1,-3.20361115535378E-7,,,,,,,,,,,,,,,,,,,,,60.9529266357422,60.9529266357422,25.4221286773682,25.4221286773682,49.9003371104764,5.41326950973216,7.47749805450439,65,1,0,0,1,0.275802612304687,31.7693061828613,2,1,1,60.9529266357422,0,60.9529266357422,,,,,,,,,,,,,,,,,,,,,,,,,,,,,,,,,
,3865500636.29754,48.9972915649414,25.4221286773682,0.000467895038067885,2.04961317584665E-8,1,5,12.9061126708984,5.00611801454071,38.0199998617172,0.612061577110621,0.089371385775845,1,-4.09498600407419E-7,,,,,,,,,,,,,,,,,,,,,48.9972915649414,48.9972915649414,25.4221286773682,25.4221286773682,50.0101559174284,5.40899804532223,7.32923412322998,64,1,64,0,0,0.272674560546875,31.7693061828613,2,1,1,48.9972915649414,0,48.9972915649414,,,,,,,,,,,,,,,,,,,,,,,,,,,,,,,,,
,3865500707.24246,36.9854545593262,25.4221286773682,0.000462411278016863,2.76832448362703E-8,1,5,12.9061126708984,5.0048042931439,38.0100011825562,0.604651758840796,0.0883890674307256,1,-3.30090656422004E-7,,,,,,,,,,,,,,,,,,,,,36.9854545593262,36.9854545593262,25.4221286773682,25.4221286773682,49.9890519474091,5.41398730564674,7.11654663085938,65,1,0,0,1,0.274810791015625,31.7693061828613,2,1,1,36.9854545593262,0,36.9854545593262,,,,,,,,,,,,,,,,,,,,,,,,,,,,,,,,,
,3865500777.56415,24.9952945709229,25.4221286773682,0.000451605553617056,5.37236597691643E-8,1,5,12.9061126708984,5.00685196448202,37.9800014197826,0.590829821205597,0.08657962781449,1,-1.64423103460148E-7,,,,,,,,,,,,,,,,,,,,,24.9952945709229,24.9952945709229,25.4221286773682,25.4221286773682,50.0222711594764,5.40652865891741,6.76893186569214,64,1,64,0,0,0.2874755859375,31.2805480957031,2,1,1,24.9952945709229,0,24.9952945709229,,,,,,,,,,,,,,,,,,,,,,,,,,,,,,,,,
,3865500850.07497,12.9900226593018,25.4221286773682,0.000419747759961119,1.40067762628898E-7,1,5,12.9061126708984,5.0052878169993,37.9600003361702,0.548881176182758,0.0806376919463538,1,7.75418118080472E-10,,,,,,,,,,,,,,,,,,,,,12.9900226593018,12.9900226593018,25.4221286773682,25.4221286773682,50.0300874446688,5.41158589900312,5.99779939651489,65,1,0,0,1,0.274658203125,31.7693061828613,2,1,1,12.9900226593018,0,12.9900226593018,,,,,,,,,,,,,,,,,,,,,,,,,,,,,,,,,
,3865502642.64452,1.99964827299118,25.4221286773682,0.000324114233178662,2.13423227815922E-8,1,5,12.9061126708984,5.00453287380217,37.9399992525578,0.423769602103144,0.0620304733008608,1,-1.69155919407394E-7,,,,,,,,,,,,,,,,,,,,,1.99963784217834,1.99965870380402,25.4221286773682,25.4221286773682,49.9910060187072,5.41562633699644,2.58435010910034,65,1,0,0,1,0.276031494140625,31.2805480957031,1,1,1,1.99965870380402,0,1.99964827299118,,,,,,,,,,,,,,,,,,,,,,,,,,,,,,,,,
,3865502723.56412,13.0992450714111,25.4221286773682,0.000410325185838568,1.6152120478499E-7,1,5,12.9061126708984,5.00426876210894,37.9500016570091,0.536441312591855,0.0785710397496458,1,-1.78260068906693E-7,,,,,,,,,,,,,,,,,,,,,13.0992450714111,13.0992450714111,25.4221286773682,25.4221286773682,49.9433266790341,5.4166437530307,5.14317560195923,65,1,0,0,1,0.276260375976562,31.7693061828613,6,1,1,13.0992450714111,0,13.0992450714111,,,,,,,,,,,,,,,,,,,,,,,,,,,,,,,,,
,3865502801.09849,25.0088291168213,25.4221286773682,0.000450213208518608,4.7710502112908E-8,1,5,12.9061126708984,5.00598487510043,37.9399992525578,0.588881430157194,0.0861836533515824,1,-2.46591624752536E-7,,,,,,,,,,,,,,,,,,,,,25.0088291168213,25.0088291168213,25.4221286773682,25.4221286773682,50.0875371408322,5.40813124107308,5.93438768386841,65,1,0,0,1,0.273971557617187,31.2805480957031,2,1,1,25.0088291168213,0,25.0088291168213,,,,,,,,,,,,,,,,,,,,,,,,,,,,,,,,,
,3865502878.47059,37.0345573425293,25.4221286773682,0.000462006359038372,3.16160873325198E-8,1,5,12.9061126708984,5.00939644649699,37.9399992525578,0.604902983428014,0.088389390950718,1,-3.57022102763164E-7,,,,,,,,,,,,,,,,,,,,,37.0345573425293,37.0345573425293,25.4221286773682,25.4221286773682,50.1148941390053,5.39757396469696,6.29097414016724,65,1,0,0,1,0.2825927734375,31.2805480957031,2,1,1,37.0345573425293,0,37.0345573425293,,,,,,,,,,,,,,,,,,,,,,,,,,,,,,,,,
,3865502955.14678,49.085750579834,25.4221286773682,0.000467106496632331,3.95857831922931E-8,1,5,12.9061126708984,5.00394452822453,37.9600003361702,0.610658696390452,0.0891679074775578,1,-4.07785317304785E-7,,,,,,,,,,,,,,,,,,,,,49.085750579834,49.085750579834,25.4221286773682,25.4221286773682,50.1727346494284,5.41924984423337,6.5433611869812,65,1,0,0,1,0.277862548828125,32.2580642700195,2,1,1,49.085750579834,0,49.085750579834,,,,,,,,,,,,,,,,,,,,,,,,,,,,,,,,,
,3865503030.56899,61.0415382385254,25.4221286773682,0.000469812797452496,3.97867786580331E-8,1,5,12.9061126708984,5.00130211634016,37.9699990153313,0.613697379119732,0.0899267442796395,1,-1.73954913523185E-7,,,,,,,,,,,,,,,,,,,,,61.0415382385254,61.0415382385254,25.4221286773682,25.4221286773682,49.9601316921976,5.4296646534917,6.70443153381348,65,1,0,0,1,0.280303955078125,31.7693061828613,2,1,1,61.0415382385254,0,61.0415382385254,,,,,,,,,,,,,,,,,,,,,,,,,,,,,,,,,
,3865503107.01676,73.1417846679688,25.4221286773682,0.000472029173925063,2.0636047824096E-8,1,5,12.9061126708984,5.00077153229185,37.9900000989437,0.616506107272823,0.0903023891395462,1,-2.01704177920902E-7,,,,,,,,,,,,,,,,,,,,,73.1417846679688,73.1417846679688,25.4221286773682,25.4221286773682,50.0265701163322,5.43158564846805,6.8129734992981,65,1,0,0,1,0.282516479492187,31.7693061828613,2,1,1,73.1417846679688,0,73.1417846679688,,,,,,,,,,,,,,,,,,,,,,,,,,,,,,,,,
,3865503180.48937,85.0128936767578,25.4221286773682,0.000473356594173058,3.35676070794337E-8,1,5,12.9061126708984,5.0018554514586,38.0100011825562,0.618415502435535,0.0906652895874243,1,-1.39908946941865E-7,,,,,,,,,,,,,,,,,,,,,85.0128936767578,85.0128936767578,25.4221286773682,25.4221286773682,50.0539271145053,5.42557743331743,6.88925743103027,65,1,0,0,1,0.281600952148438,31.2805480957031,2,1,1,85.0128936767578,0,85.0128936767578,,,,,,,,,,,,,,,,,,,,,,,,,,,,,,,,,
,3865503253.63297,97.0216293334961,25.4221286773682,0.00047426829267726,2.96275350361163E-8,1,5,12.9061126708984,4.99777852859574,38.0299985408783,0.618951093330884,0.0903837501941338,1,-4.10291317744143E-7,,,,,,,,,,,,,,,,,,,,,97.0216293334961,97.0216293334961,25.4221286773682,25.4221286773682,49.9460623788514,5.43801532889771,6.95630264282227,63,1,64,0,0,0.289764404296875,31.2805480957031,2,1,1,97.0216293334961,0,97.0216293334961,,,,,,,,,,,,,,,,,,,,,,,,,,,,,,,,,
,3865503326.78769,109.034965515137,25.4221286773682,0.00047478446070859,3.22601297116474E-8,1,5,12.9061126708984,4.99993642358729,38.0599983036518,0.619973690930058,0.0907129702442166,1,-2.75855258295992E-7,,,,,,,,,,,,,,,,,,,,,109.034965515137,109.034965515137,25.4221286773682,25.4221286773682,50.0425935009765,5.42838168364805,7.01676034927368,64,1,64,0,0,0.286941528320313,31.7693061828613,2,1,1,109.034965515137,0,109.034965515137,,,,,,,,,,,,,,,,,,,,,,,,,,,,,,,,,
,3865503398.6557,121.002182006836,25.4221286773682,0.000475451206455423,3.93755881271118E-8,1,5,12.9061126708984,4.99979569052739,38.0900017917156,0.620818439467569,0.0908463872557703,1,-2.68883016065535E-7,,,,,,,,,,,,,,,,,,,,,121.002182006836,121.002182006836,25.4221286773682,25.4221286773682,50.0640882852553,5.4326650775414,7.05375814437866,65,1,0,0,1,0.275955200195313,31.7693061828613,2,1,1,121.002182006836,0,121.002182006836,,,,,,,,,,,,,,,,,,,,,,,,,,,,,,,,,
,3865503472.42444,133.112274169922,25.4221286773682,0.000475630652143206,3.47443450837718E-8,1,5,12.9061126708984,4.99970691986117,38.1300002336502,0.621065093177665,0.0906892630593804,1,-4.13860997737404E-7,,,,,,,,,,,,,,,,,,,,,133.112274169922,133.112274169922,25.4221286773682,25.4221286773682,50.1516306794092,5.43408882393584,7.09742879867554,65,1,0,0,1,0.282821655273438,31.7693061828613,2,1,1,133.112274169922,0,133.112274169922,,,,,,,,,,,,,,,,,,,,,,,,,,,,,,,,,
,3865503544.47575,145.060852050781,25.4221286773682,0.000475741958830218,3.87093243774681E-8,1,5,12.9061126708984,5.00122274666719,38.1599999964237,0.621452863298245,0.0908944082153734,1,-3.02636890149693E-7,,,,,,,,,,,,,,,,,,,,,145.060852050781,145.060852050781,25.4221286773682,25.4221286773682,49.9738101912841,5.42777629302276,7.12866401672363,63,1,64,0,0,0.283660888671875,31.7693061828613,2,1,1,145.060852050781,0,145.060852050781,,,,,,,,,,,,,,,,,,,,,,,,,,,,,,,,,
,3865503616.83839,157.027847290039,25.4221286773682,0.000475697526621254,4.29217935133161E-8,1,5,12.9061126708984,5.00124975214018,38.1999984383583,0.621404629376931,0.0908518338195991,1,-3.29230351153787E-7,,,,,,,,,,,,,,,,,,,,,157.027847290039,157.027847290039,25.4221286773682,25.4221286773682,50.0023396322361,5.42502550015431,7.14608144760132,63,1,64,0,0,0.285110473632813,31.7693061828613,2,1,1,157.027847290039,0,157.027847290039,,,,,,,,,,,,,,,,,,,,,,,,,,,,,,,,,
,3865503689.04069,169.024871826172,25.4221286773682,0.000475647451507863,3.47024110513855E-8,1,5,12.9061126708984,5.00319179786932,38.2400006055832,0.621676332790129,0.0908964417279401,1,-3.255372896186E-7,,,,,,,,,,,,,,,,,,,,,169.024871826172,169.024871826172,25.4221286773682,25.4221286773682,50.0382945441207,5.4180624346806,7.18019390106201,65,1,0,0,1,0.280227661132813,32.2580642700195,2,1,1,169.024871826172,0,169.024871826172,,,,,,,,,,,,,,,,,,,,,,,,,,,,,,,,,
,3865503761.28352,181.038604736328,25.4221286773682,0.000475475843260254,3.00727282398741E-8,1,5,12.9061126708984,5.00431937616153,38.2799990475178,0.621648521375934,0.0908892779270357,1,-3.2773937429574E-7,,,,,,,,,,,,,,,,,,,,,181.038604736328,181.038604736328,25.4221286773682,25.4221286773682,49.9839713620341,5.41702957534104,7.21789121627808,63,1,64,0,0,0.277786254882813,32.7468223571777,2,1,1,181.038604736328,0,181.038604736328,,,,,,,,,,,,,,,,,,,,,,,,,,,,,,,,,
,3865503833.86267,193.026596069336,25.4221286773682,0.000474993767663989,2.42715130050468E-8,1,5,12.9061126708984,5.00480890049981,38.3299998939037,0.621100705004895,0.0908269282683453,1,-3.14120577458117E-7,,,,,,,,,,,,,,,,,,,,,193.026596069336,193.026596069336,25.4221286773682,25.4221286773682,50.0046845177938,5.41598990615798,7.24456453323364,63,1,64,0,0,0.278396606445313,32.2580642700195,2,1,1,193.026596069336,0,193.026596069336,,,,,,,,,,,,,,,,,,,,,,,,,,,,,,,,,
,3865503907.18027,205.177833557129,25.4221286773682,0.000474685930759973,3.08045569909668E-8,1,5,12.9061126708984,5.00464558821025,38.3800007402897,0.620682133129427,0.090680213353268,1,-3.77941678832361E-7,,,,,,,,,,,,,,,,,,,,,205.163696289062,205.191970825195,25.4221286773682,25.4221286773682,50.1414695086592,5.41604995869166,7.30537748336792,63,1,64,0,0,0.278701782226562,31.7693061828613,2,1,1,205.191970825195,0,205.177833557129,,,,,,,,,,,,,,,,,,,,,,,,,,,,,,,,,
,3865503979.35871,217.176910400391,25.4221286773682,0.000474548579794006,3.01462957124382E-8,1,5,12.9061126708984,5.00358965271009,38.4300015866756,0.620291530304363,0.090816362045013,1,-2.33110542374985E-7,,,,,,,,,,,,,,,,,,,,,217.176910400391,217.176910400391,25.4221286773682,25.4221286773682,50.244253658938,5.41942898682424,7.36312437057495,64,1,64,0,0,0.280380249023438,31.7693061828613,2,1,1,217.176910400391,0,217.176910400391,,,,,,,,,,,,,,,,,,,,,,,,,,,,,,,,,
,3865504051.55373,229.144302368164,25.4221286773682,0.000474479893724592,6.60679936332296E-8,1,5,12.9061126708984,5.00357713662409,38.4900011122227,0.620186747017108,0.0908902378973982,1,-1.66254185672395E-7,,,,,,,,,,,,,,,,,,,,,229.144302368164,229.144302368164,25.4221286773682,25.4221286773682,50.1316991521688,5.41895889645499,7.45672512054443,64,1,64,0,0,0.277633666992187,32.2580642700195,2,1,1,229.144302368164,0,229.144302368164,,,,,,,,,,,,,,,,,,,,,,,,,,,,,,,,,
,3865504123.31747,241.153961181641,25.4221286773682,0.00047454448366649,3.48651926404102E-8,1,5,12.9061126708984,5.00351257971679,38.5500006377697,0.620277832195166,0.0907793861477754,1,-2.59301424923676E-7,,,,,,,,,,,,,,,,,,,,,241.153961181641,241.153961181641,25.4221286773682,25.4221286773682,50.1219287956784,5.42064807793044,7.60171461105347,63,1,64,0,0,0.279998779296875,32.2580642700195,2,1,1,241.153961181641,0,241.153961181641,,,,,,,,,,,,,,,,,,,,,,,,,,,,,,,,,
,3865504196.25507,253.135101318359,25.4221286773682,0.000474481260295037,4.38099944414141E-8,1,5,12.9061126708984,5.00437035966887,38.6199988424778,0.620332019388236,0.0908706577120914,1,-1.96858638217024E-7,,,,,,,,,,,,,,,,,,,,,253.135101318359,253.135101318359,25.4221286773682,25.4221286773682,50.101997268438,5.41688168241952,7.76103448867798,64,1,64,0,0,0.277099609375,31.7693061828613,2,1,1,253.135101318359,0,253.135101318359,,,,,,,,,,,,,,,,,,,,,,,,,,,,,,,,,
,3865504267.73636,265.036895751953,25.4221286773682,0.00047414499847226,6.93747672037101E-8,1,5,12.9061126708984,5.00490609943631,38.6799983680248,0.61995299437519,0.0910395041465978,1,-2.873374919227E-8,,,,,,,,,,,,,,,,,,,,,265.036895751953,265.036895751953,25.4221286773682,25.4221286773682,50.1848498914765,5.41378774629196,7.95409679412842,65,1,0,0,1,0.276565551757813,32.2580642700195,2,1,1,265.036895751953,0,265.036895751953,,,,,,,,,,,,,,,,,,,,,,,,,,,,,,,,,
,3865504339.95524,277.005310058594,25.4221286773682,0.00047175203064707,5.51518650514719E-8,1,5,12.9061126708984,5.00545043239273,38.7400016188622,0.616840137591925,0.0911239355281483,1,3.76789265717136E-7,,,,,,,,,,,,,,,,,,,,,277.005310058594,277.005310058594,25.4221286773682,25.4221286773682,50.1860223342553,5.41323562792952,8.14127731323242,63,1,64,0,0,0.273971557617187,31.7693061828613,2,1,1,277.005310058594,0,277.005310058594,,,,,,,,,,,,,,,,,,,,,,,,,,,,,,,,,
,3865504412.32988,289.007019042969,25.4221286773682,0.00046941076981111,6.63731335238128E-8,1,5,12.9061126708984,5.00611797963673,38.8199985027313,0.613924442980878,0.0904769257319631,1,2.13071410934123E-7,,,,,,,,,,,,,,,,,,,,,289.007019042969,289.007019042969,25.4221286773682,25.4221286773682,50.0164089455822,5.41148275193348,8.01251316070557,63,1,64,0,0,0.273971557617187,31.7693061828613,2,1,1,289.007019042969,0,289.007019042969,,,,,,,,,,,,,,,,,,,,,,,,,,,,,,,,,
,3865504558.96034,299.945098876953,25.4221286773682,0.000464182760317166,6.53372069201027E-8,1,5,12.9061126708984,5.00665433101918,38.8699993491173,0.607124330783385,0.0898474287398394,1,4.89543434592855E-7,,,,,,,,,,,,,,,,,,,,,299.945098876953,299.945098876953,25.4221286773682,25.4221286773682,50.0629158424764,5.40990850044455,7.83794641494751,65,1,0,0,1,0.2728271484375,32.2580642700195,1,1,1,299.945098876953,0,299.945098876953,,,,,,,,,,,,,,,,,,,,,,,,,,,,,,,,,