File: LT data/Sherwood/K1/235_SH_FULL_SEQUENCE_2.dat
[Header]
; MPMS3 Data File (default extension .dat)
; Copyright (c) 2007, Quantum Design, Inc. All rights reserved.
TITLE,
FILEOPENTIME,3873103217.52703,09/23/2022,4:11 pm
BYAPP,MPMS3 w/ AC,1.0,1.1
INFO,MPMS3 Measurement Release 1.1.16 Build 424, MultiVu Release 2.3.4.19,APPNAME
INFO,Linear Motor Servo Controller,MOTOR_MODULE_NAME
INFO,3101-100 N0,MOTOR_HW_VERSION
INFO,MMC1047,MOTOR_SERIAL_NUMBER
INFO,01.04.28,MOTOR_SOFTWARE_VERSION
INFO,Quantum Design Squid Module,SQUID_MODULE_NAME
INFO,3101-501 B0,SQUID_HW_VERSION
INFO,SQM278,SQUID_SERIAL_NUMBER
INFO,01.03.04,SQUID_SOFTWARE_VERSION
INFO,Quantum Design VSM Oven,OVEN_MODULE_NAME
INFO,3101-201 A3,OVEN_HW_VERSION
INFO,OVB323,OVEN_SERIAL_NUMBER
INFO,01.07.07,OVEN_SOFTWARE_VERSION
INFO,SQUID AC,AC_MODULE_NAME
INFO,3101-401 G0,AC_HW_VERSION
INFO,SAC258,AC_SERIAL_NUMBER
INFO,SQUID AC 00.95.07,AC_SOFTWARE_VERSION
INFO,TCI127,COIL_SERIAL_NUMBER
INFO,0,MOMENT_UNITS
INFO,sndst,SAMPLE_MATERIAL
INFO,,SAMPLE_COMMENT
INFO,,SAMPLE_MASS
INFO,,SAMPLE_VOLUME
INFO,,SAMPLE_MOLECULAR_WEIGHT
INFO,,SAMPLE_SIZE
INFO,,SAMPLE_SHAPE
INFO,Straw,SAMPLE_HOLDER
INFO,Standard,SAMPLE_HOLDER_DETAIL
INFO,65.01,SAMPLE_OFFSET
DATATYPE,COMMENT,1
DATATYPE,TIME,2
STARTUPAXIS,X,2
STARTUPAXIS,Y1,5
FIELDGROUP, VSM,2,3,4,5,6,8,9,10,11,14,15
FIELDGROUP, DC, 2,3,4,14,56,57,58,59,60,61,62,63,64,65,66,67,68,69
FIELDGROUP, AC, 2,3,4,11,16,17,18,19,20,21,22,23,24,25,26,27,28,29,30
STARTUPGROUP, All
[Data]
Comment,Time Stamp (sec),Temperature (K),Magnetic Field (Oe),Moment (emu),M. Std. Err. (emu),Transport Action,Averaging Time (sec),Frequency (Hz),Peak Amplitude (mm),Center Position (mm),Lockin Signal' (V),Lockin Signal (V),Range,M. Quad. Signal (emu),AC Moment (emu),AC M. Std Err. (emu),AC Phase (deg),AC Phase Std. Err. (deg),AC Susceptibility (emu/Oe),AC Suscept. Std Err. (emu/Oe),AC X' (emu/Oe),AC X' Std Err. (emu/Oe),AC X'' (emu/Oe),AC X'' Std Err. (emu/Oe),AC Drive (Oe),AC Frequency (Hz),AC Averaging Time (sec),AC Cycles,AC Range,AC Measure Type,AC Signal' (V),AC Signal'' (V),AC Trim Coil Ratio,AC Trim Coil Phase,Min. Temperature (K),Max. Temperature (K),Min. Field (Oe),Max. Field (Oe),Mass (grams),Motor Lag (deg),Pressure (Torr),Measure Count,Measurement Number,SQUID Status (code),Motor Status (code),Measure Status (code),Motor Current (amps),Motor Temp. (C),Temp. Status (code),Field Status (code),Chamber Status (code),Chamber Temp (K),Redirection State,Evercool Status,Average Temp (K),Rotation Angle (deg),Rotator state,DC Moment Fixed Ctr (emu),DC Moment Err Fixed Ctr (emu),DC Moment Free Ctr (emu),DC Moment Err Free Ctr (emu),DC Fixed Fit,DC Free Fit,DC Calculated Center (mm),DC Calculated Center Err (mm),DC Scan Length (mm),DC Scan Time (s),DC Number of Points,DC Squid Drift,DC Min V (V),DC Max V (V),DC Scans per Measure,Map 01,Map 02,Map 03,Map 04,Map 05,Map 06,Map 07,Map 08,Map 09,Map 10,Map 11,Map 12,Map 13,Map 14,Map 15,Map 16
"FC",3873103385.59798
,3873104253.20564,86.6857452392578,49999.57421875,0.0789739260205988,0.000462393990923278,1,2,13.1008939743042,2.00340173108944,32.7799990773201,19.2354246046736,2.68098814617117,100,-0.000555330481923092,,,,,,,,,,,,,,,,,,,,,86.5555953979492,86.8158950805664,49999.57421875,49999.57421875,52.4015483720152,5.7895069555594,7.66543531417847,26,1,0,0,1,0.13702392578125,30.7917900085449,2,1,1,86.5555953979492,0,2084573184,86.6857452392578,,,,,,,,,,,,,,,,,,,,,,,,,,,,,,,,,
,3873104388.14265,64.0982627868652,49999.57421875,0.115190151882846,5.30393872473049E-5,1,2,13.1008939743042,2.00497485335866,32.6999984681606,28.0718643400033,4.09619244317397,1000,-7.16166611551898E-5,,,,,,,,,,,,,,,,,,,,,63.9175109863281,64.2790145874023,49999.57421875,49999.57421875,52.2972009646978,5.7721901929945,7.46723508834839,26,1,0,0,1,0.133056640625,31.2805480957031,2,1,1,63.9175109863281,0,2084573184,64.0982627868652,,,,,,,,,,,,,,,,,,,,,,,,,,,,,,,,,
,3873104528.10767,40.2198219299316,49999.57421875,0.185832088042615,0.000752750295220693,1,2,13.1008939743042,2.00693530388338,32.660000026226,45.332504070697,6.88459137986249,100,0.000966314408175051,,,,,,,,,,,,,,,,,,,,,40.2198219299316,40.2198219299316,49999.57421875,49999.57421875,52.4308594414863,5.75633413768869,7.09925699234009,26,1,0,0,1,0.130767822265625,31.2805480957031,2,1,1,40.2198219299316,0,2084573184,40.2198219299316,,,,,,,,,,,,,,,,,,,,,,,,,,,,,,,,,
,3873104659.10298,18.185998916626,49999.57421875,0.298285054709268,0.000938412036174981,1,2,13.1008939743042,2.002162517835,32.6399989426136,72.4508644059362,10.9082759672264,100,0.0011696936127675,,,,,,,,,,,,,,,,,,,,,18.185998916626,18.185998916626,49999.57421875,49999.57421875,52.5871851453325,5.80813641726926,6.16083574295044,26,1,0,0,1,0.135574340820312,30.3030319213867,2,1,1,18.185998916626,0,2084573184,18.185998916626,,,,,,,,,,,,,,,,,,,,,,,,,,,,,,,,,
,3873104786.99865,2.08399677276611,49999.57421875,0.418000185530285,8.82090343526539E-5,1,2,13.1008939743042,2.00324567441316,32.6099991798401,101.672450270417,15.0306871003424,100,0.00052423277615727,,,,,,,,,,,,,,,,,,,,,2.08373785018921,2.08425569534302,49999.57421875,49999.57421875,53.5778992934576,5.80373896933963,2.6669442653656,26,1,0,0,1,0.136871337890625,31.2805480957031,2,1,1,2.08425569534302,0,2084573184,2.08399677276611,,,,,,,,,,,,,,,,,,,,,,,,,,,,,,,,,
,3873104854.56956,2.1085569858551,49999.57421875,0.417919932331662,0.000108819439072236,1,2,13.1008939743042,2.00279357461365,32.6099991798401,101.611801297758,15.0055447357762,100,0.000459021625855345,,,,,,,,,,,,,,,,,,,,,2.10613536834717,2.11097860336304,49999.57421875,49999.57421875,53.5610942802941,5.80697406472525,2.66480898857117,26,1,0,0,1,0.13916015625,31.2805480957031,2,1,1,2.11097860336304,0,2084573184,2.1085569858551,,,,,,,,,,,,,,,,,,,,,,,,,,,,,,,,,
,3873104921.99591,2.20759546756744,49999.57421875,0.417010583098661,8.80033966411315E-5,1,2,13.1008939743042,2.0011746225322,32.6099991798401,101.237589942901,14.9357831449416,100,0.000399569562922885,,,,,,,,,,,,,,,,,,,,,2.20594191551209,2.2092490196228,49999.57421875,49999.57421875,53.5376454247172,5.82344443881719,2.74084711074829,26,1,0,0,1,0.133285522460938,31.7693061828613,2,1,1,2.2092490196228,0,2084573184,2.20759546756744,,,,,,,,,,,,,,,,,,,,,,,,,,,,,,,,,
,3873104989.42507,2.22216725349426,49999.57421875,0.416845708886332,8.68455532166585E-5,1,2,13.1008939743042,2.00098858796312,32.6099991798401,101.179349309997,14.9299320891578,100,0.000410464771654208,,,,,,,,,,,,,,,,,,,,,2.22118020057678,2.22315430641174,49999.57421875,49999.57421875,53.5016905128326,5.82642039224265,2.75779604911804,26,1,0,0,1,0.135116577148438,31.2805480957031,2,1,1,2.22315430641174,0,2084573184,2.22216725349426,,,,,,,,,,,,,,,,,,,,,,,,,,,,,,,,,
,3873105056.94523,2.26438701152802,49999.57421875,0.416509600132742,7.62967240218315E-5,1,2,13.1008939743042,1.99997123135757,32.6099991798401,100.989377134169,14.9788197177203,100,0.000720579357878582,,,,,,,,,,,,,,,,,,,,,2.26365041732788,2.26512360572815,49999.57421875,49999.57421875,53.5591402089961,5.83384652983645,2.78679275512695,26,1,0,0,1,0.137939453125,31.2805480957031,2,1,1,2.26512360572815,0,2084573184,2.26438701152802,,,,,,,,,,,,,,,,,,,,,,,,,,,,,,,,,
,3873105124.38837,2.23740255832672,49999.57421875,0.416852089085841,0.000172010172386881,1,2,13.1008939743042,2.00075136389506,32.6099991798401,101.158122793148,14.927163439438,100,0.000411937107723515,,,,,,,,,,,,,,,,,,,,,2.23685884475708,2.23794627189636,49999.57421875,49999.57421875,53.4649539724287,5.82427787314281,2.76636123657227,26,1,0,0,1,0.134963989257812,31.7693061828613,2,1,1,2.23685884475708,0,2084573184,2.23740255832672,,,,,,,,,,,,,,,,,,,,,,,,,,,,,,,,,
,3873105191.85987,2.1939332485199,49999.57421875,0.417099525469999,0.000135845079787039,1,2,13.1008939743042,2.00120872881373,32.6099991798401,101.259038672308,14.9627400751175,100,0.000495568663150143,,,,,,,,,,,,,,,,,,,,,2.1937689781189,2.1940975189209,49999.57421875,49999.57421875,53.4848854996691,5.82252361570289,2.73984789848328,26,1,0,0,1,0.13336181640625,30.3030319213867,2,1,1,2.1937689781189,0,2084573888,2.1939332485199,,,,,,,,,,,,,,,,,,,,,,,,,,,,,,,,,
,3873105259.36155,2.19250798225403,49999.57421875,0.417215611146102,8.49935141239925E-5,1,2,13.1008939743042,2.00085296259236,32.6099991798401,101.255527466501,14.9453837404102,100,0.000427809766542294,,,,,,,,,,,,,,,,,,,,,2.19162440299988,2.19339156150818,49999.57421875,49999.57421875,53.4907477135634,5.82508085576274,2.73865652084351,26,1,0,0,1,0.134429931640625,31.2805480957031,2,1,1,2.19162440299988,0,2084573824,2.19250798225403,,,,,,,,,,,,,,,,,,,,,,,,,,,,,,,,,
,3873105326.82458,2.19870638847351,49999.57421875,0.416895664148305,0.000102587324982971,1,2,13.1008939743042,2.00017526939265,32.6099991798401,101.104803064159,14.980042781401,100,0.000657106923324615,,,,,,,,,,,,,,,,,,,,,2.19812297821045,2.19928979873657,49999.57421875,49999.57421875,53.4923109706018,5.83101475557864,2.74040722846985,26,1,0,0,1,0.135345458984375,31.2805480957031,2,1,1,2.19812297821045,0,2084574272,2.19870638847351,,,,,,,,,,,,,,,,,,,,,,,,,,,,,,,,,
,3873105394.34767,2.1917724609375,49999.57421875,0.417138842874713,9.00513097029936E-5,1,2,13.1008939743042,2.00080547317602,32.6099991798401,101.230864641958,14.9520589533003,100,0.000469330783680233,,,,,,,,,,,,,,,,,,,,,2.18998336791992,2.19356155395508,49999.57421875,49999.57421875,53.445413259448,5.82507032568833,2.73652696609497,26,1,0,0,1,0.133743286132812,31.2805480957031,2,1,1,2.19356155395508,0,2084574016,2.1917724609375,,,,,,,,,,,,,,,,,,,,,,,,,,,,,,,,,
,3873105461.75958,2.14412081241608,49999.57421875,0.417297937015078,6.25950030282364E-5,1,2,13.1008939743042,2.00102250792847,32.6099991798401,101.292262227735,14.9473421278403,100,0.000413928847049937,,,,,,,,,,,,,,,,,,,,,2.14051628112793,2.14772534370422,49999.57421875,49999.57421875,53.4770692144768,5.82696075164648,2.70466113090515,26,1,0,0,1,0.1336669921875,32.7468223571777,2,1,1,2.14051628112793,0,2084573984,2.14412081241608,,,,,,,,,,,,,,,,,,,,,,,,,,,,,,,,,
,3873105529.24531,1.99951028823853,49999.57421875,0.41771945827186,0.00011196645201448,1,2,13.1008939743042,2.00070599433638,32.6099991798401,101.359989497826,14.9866790040579,100,0.000532690222758068,,,,,,,,,,,,,,,,,,,,,1.99939477443695,1.9996258020401,49999.57421875,49999.57421875,53.5059894696884,5.82519881759528,2.60935926437378,26,1,0,0,1,0.13427734375,32.2580642700195,5,1,1,1.99939477443695,0,2085105664,1.99951028823853,,,,,,,,,,,,,,,,,,,,,,,,,,,,,,,,,
,3873105964.85898,6.01992034912109,26.4401626586914,0.0026075802862051,2.80499588855047E-5,1,2,13.1008939743042,1.98160991535319,32.6099991798401,0.62133305342901,0.0918530342846079,100,3.26464225252524E-6,,,,,,,,,,,,,,,,,,,,,6.01992034912109,6.01992034912109,26.4401626586914,26.4401626586914,52.4605613252171,5.81682734707342,4.08263731002808,26,1,0,0,1,0.1324462890625,30.3030319213867,6,1,1,6.01992034912109,0,2084574080,6.01992034912109,,,,,,,,,,,,,,,,,,,,,,,,,,,,,,,,,
,3873106186.2501,40.0370559692383,26.4401626586914,0.000278937754156047,1.03806134177716E-7,1,2,13.1008939743042,1.98515159845046,32.6200015842915,0.0667021243485514,0.00978111823640253,1,2.33977214687288E-8,,,,,,,,,,,,,,,,,,,,,40.0370559692383,40.0370559692383,26.4401626586914,26.4401626586914,52.4886999519094,5.77963067841748,6.45637845993042,24,1,64,0,0,0.140380859375,31.7693061828613,2,1,1,40.0370559692383,0,2084574208,40.0370559692383,,,,,,,,,,,,,,,,,,,,,,,,,,,,,,,,,
,3873106401.28124,74.0673599243164,26.4401626586914,0.000239225252325284,6.3595278309229E-8,1,2,13.1008939743042,1.98108070669669,32.660000026226,0.0569904643637289,0.00830747783690362,1,-1.83509337442115E-7,,,,,,,,,,,,,,,,,,,,,74.0673599243164,74.0673599243164,26.4401626586914,26.4401626586914,52.4222615277748,5.81898827504058,6.89288425445557,26,1,0,0,1,0.133743286132812,30.7917900085449,2,1,1,74.0673599243164,0,2084574240,74.0673599243164,,,,,,,,,,,,,,,,,,,,,,,,,,,,,,,,,
,3873106609.62211,108.017288208008,26.4401626586914,0.00022076415241141,1.50022543447176E-6,1,2,13.1008939743042,1.9896133007526,32.7199995517731,0.052977783910551,0.00803749805057843,1,1.11466910214894E-6,,,,,,,,,,,,,,,,,,,,,108.017288208008,108.017288208008,26.4401626586914,26.4401626586914,52.4371124696402,5.8148479148068,7.08075666427612,26,1,0,0,1,0.133590698242188,31.2805480957031,2,1,1,108.017288208008,0,2084574400,108.017288208008,,,,,,,,,,,,,,,,,,,,,,,,,,,,,,,,,
,3873106815.03807,142.055358886719,26.4401626586914,0.000204661009481555,5.78402342984934E-8,1,2,13.1008939743042,1.99190399736411,32.8099988400936,0.0492627589988528,0.00718050796343295,1,-1.59050604006661E-7,,,,,,,,,,,,,,,,,,,,,142.055358886719,142.055358886719,26.4401626586914,26.4401626586914,52.4750214528228,5.80074733378917,7.19712018966675,26,1,0,0,1,0.135345458984375,31.2805480957031,2,1,1,142.055358886719,0,2084574432,142.055358886719,,,,,,,,,,,,,,,,,,,,,,,,,,,,,,,,,
,3873107020.11821,176.016952514648,26.4401626586914,0.000190315419663333,4.72141740535436E-8,1,2,13.1008939743042,1.99198455276037,32.930001616478,0.045813267993624,0.00667743228247799,1,-1.49041413203256E-7,,,,,,,,,,,,,,,,,,,,,176.016952514648,176.016952514648,26.4401626586914,26.4401626586914,52.3855249873709,5.80089278467921,7.32658624649048,26,1,0,0,1,0.132904052734375,30.7917900085449,2,1,1,176.016952514648,0,2084574208,176.016952514648,,,,,,,,,,,,,,,,,,,,,,,,,,,,,,,,,
,3873107225.3314,210.010284423828,26.4401626586914,0.000171328206076247,4.80399605752844E-8,1,2,13.1008939743042,1.99285253588617,33.0700017511845,0.0412730839157934,0.00604078785804875,1,-3.21473223667236E-8,,,,,,,,,,,,,,,,,,,,,210.010284423828,210.010284423828,26.4401626586914,26.4401626586914,52.4101462857267,5.78707108792718,7.49560832977295,25,1,64,0,0,0.1385498046875,31.2805480957031,2,1,1,210.051086425781,0,2084574272,210.010284423828,,,,,,,,,,,,,,,,,,,,,,,,,,,,,,,,,
,3873107430.25775,244.086837768555,26.4401626586914,0.000159423409902144,5.40422301727492E-8,1,2,13.1008939743042,1.99472564917547,33.2299992442131,0.0384470719878758,0.00581248979433819,1,7.21896970413566E-7,,,,,,,,,,,,,,,,,,,,,244.086837768555,244.086837768555,26.4401626586914,26.4401626586914,52.519574278419,5.77019392612716,7.87986993789673,25,1,64,0,0,0.135269165039062,31.2805480957031,2,1,1,244.086837768555,0,2084574432,244.086837768555,,,,,,,,,,,,,,,,,,,,,,,,,,,,,,,,,
,3873107635.04617,278.02880859375,26.4401626586914,0.00015098436404745,5.44130645058727E-8,1,2,13.1008939743042,1.99649927731391,33.4200002253056,0.0364541179894082,0.00564475163593522,1,1.22422316261114E-6,,,,,,,,,,,,,,,,,,,,,278.02880859375,278.02880859375,26.4401626586914,26.4401626586914,52.4672051676305,5.75492556118188,8.2026252746582,26,1,0,0,1,0.131301879882812,31.7693061828613,2,1,1,278.02880859375,0,2084574336,278.02880859375,,,,,,,,,,,,,,,,,,,,,,,,,,,,,,,,,
,3873109593.70281,2.00031316280365,44879.03125,0.401605552038336,9.17337876424914E-5,1,2,13.1008939743042,2.00130875008026,32.600000500679,97.5418050599679,14.1694694518757,1000,-0.000506285171652955,,,,,,,,,,,,,,,,,,,,,2.00009489059448,2.00053143501282,44789.1171875,44968.9453125,53.3875727490249,5.8201248246939,2.61378598213196,26,1,0,0,1,0.13458251953125,31.2805480957031,1,6,1,2.00053143501282,0,2084573184,2.00031316280365,,,,,,,,,,,,,,,,,,,,,,,,,,,,,,,,,
,3873109661.15679,1.99991792440414,38137.66796875,0.376555297895723,8.16877223610756E-5,1,2,13.1008939743042,2.00159154703932,32.600000500679,91.482492499825,13.2864671646283,1000,-0.000485962661117837,,,,,,,,,,,,,,,,,,,,,1.99982249736786,2.00001335144043,38047.75390625,38227.58203125,53.2226491314672,5.81790493822345,2.60326910018921,26,1,0,0,1,0.132522583007812,31.7693061828613,1,6,1,1.99982249736786,0,2084573408,1.99991792440414,,,,,,,,,,,,,,,,,,,,,,,,,,,,,,,,,
,3873109728.62278,2.00032699108124,31402.625,0.347266772944586,7.64507885133233E-5,1,2,13.1008939743042,2.00149604221902,32.600000500679,84.3592348976965,12.2526922584244,1000,-0.000445052166740687,,,,,,,,,,,,,,,,,,,,,2.00011682510376,2.00053715705872,31307.662109375,31497.587890625,52.9830799903229,5.81672566932163,2.59502387046814,26,1,0,0,1,0.13336181640625,30.7917900085449,1,6,1,2.00011682510376,0,2084573728,2.00032699108124,,,,,,,,,,,,,,,,,,,,,,,,,,,,,,,,,
,3873109796.11393,1.99988907575607,24661.5458984375,0.312561856712298,7.75621497650843E-5,1,2,13.1008939743042,2.00154903947377,32.600000500679,75.9301702602116,11.0440012843944,1000,-0.000337759254603535,,,,,,,,,,,,,,,,,,,,,1.9997216463089,2.00005650520325,24566.66796875,24756.423828125,52.8634908268806,5.81464726145603,2.59139776229858,26,1,0,0,1,0.133590698242188,31.2805480957031,1,6,1,1.9997216463089,0,2084573632,1.99988907575607,,,,,,,,,,,,,,,,,,,,,,,,,,,,,,,,,
,3873109863.59966,2.000528216362,17926.640625,0.269210093673446,0.000101726224967346,1,2,13.1008939743042,2.00053635688447,32.600000500679,65.3326168378786,9.52703976233493,1000,-0.000192269275362356,,,,,,,,,,,,,,,,,,,,,1.99998307228088,2.00107336044312,17836.7265625,18016.5546875,52.6844978959767,5.82369582888383,2.58759593963623,26,1,0,0,1,0.136795043945312,31.7693061828613,1,6,1,2.00107336044312,0,2084573856,2.000528216362,,,,,,,,,,,,,,,,,,,,,,,,,,,,,,,,,
,3873109931.0355,1.99990367889404,11184.5537109375,0.212629581826837,0.000103741397236824,1,2,13.1008939743042,2.0013828028403,32.600000500679,51.6465472223196,7.50571058088693,1000,-0.000254974263229115,,,,,,,,,,,,,,,,,,,,,1.99983310699463,1.99997425079346,11094.546875,11274.560546875,52.5824953742171,5.81581540154334,2.58157181739807,26,1,0,0,1,0.132522583007812,31.7693061828613,1,6,1,1.99997425079346,0,2084573728,1.99990367889404,,,,,,,,,,,,,,,,,,,,,,,,,,,,,,,,,
,3873109998.53296,1.99995678663254,4438.6533203125,0.128645598987741,0.000170823509582569,1,2,13.1008939743042,2.00130306868179,32.600000500679,31.247609083587,4.52259962815098,1000,-0.000229125175172509,,,,,,,,,,,,,,,,,,,,,1.99957621097565,2.00033736228943,4349.02978515625,4528.27685546875,52.4183533851786,5.81391498123369,2.57807946205139,26,1,0,0,1,0.133285522460938,31.2805480957031,1,6,1,2.00033736228943,0,2084573792,1.99995678663254,,,,,,,,,,,,,,,,,,,,,,,,,,,,,,,,,
,3873110070.09003,1.99996435642242,-2709.75817871094,-0.0626794192363348,0.000351458590111558,1,2,13.1008939743042,2.00100665446974,32.600000500679,-15.2097296483954,-2.275452251818,100,-0.000187190000995724,,,,,,,,,,,,,,,,,,,,,1.99993526935577,1.99999344348907,-2789.40625,-2630.11010742187,52.5047233365536,5.81651871522811,2.57673001289368,24,1,68,0,0,0.133132934570312,31.2805480957031,1,6,1,1.99993526935577,0,2084573472,1.99996435642242,,,,,,,,,,,,,,,,,,,,,,,,,,,,,,,,,
,3873110145.36507,1.99980640411377,-10240.1240234375,-0.198187143334068,0.000133077037116778,1,2,13.1008939743042,2.00085151910465,32.600000500679,-48.0985951160666,-7.09991208050935,100,-0.000205345565326063,,,,,,,,,,,,,,,,,,,,,1.99960207939148,2.00001072883606,-10330.1923828125,-10150.0556640625,52.5563108188229,5.81841583626692,2.57549381256104,26,1,0,0,1,0.134735107421875,31.2805480957031,1,6,1,2.00001072883606,0,2084573184,1.99980640411377,,,,,,,,,,,,,,,,,,,,,,,,,,,,,,,,,
,3873110212.86045,2.00003731250763,-16993.1318359375,-0.26069219886003,9.34512688243831E-5,1,2,13.1008939743042,2.00079968395335,32.600000500679,-63.2695584747618,-9.30766909293392,100,-0.000142456411750139,,,,,,,,,,,,,,,,,,,,,1.99991011619568,2.00016450881958,-17083.17578125,-16903.087890625,52.6887968528325,5.81930527781177,2.57158446311951,26,1,0,0,1,0.13397216796875,31.2805480957031,1,6,1,2.00016450881958,0,2084573408,2.00003731250763,,,,,,,,,,,,,,,,,,,,,,,,,,,,,,,,,
,3873110304.29622,1.99989295005798,-26141.4833984375,-0.319607453171693,8.50005296452459E-5,1,2,13.1008939743042,2.0008771638406,32.600000500679,-77.5714166494437,-11.428820913305,100,-0.000243959612937056,,,,,,,,,,,,,,,,,,,,,1.99980175495148,1.99998414516449,-26216.67578125,-26066.291015625,52.9862065043998,5.81649669878541,2.56520867347717,26,1,0,0,1,0.133590698242188,31.2805480957031,1,6,1,1.99980175495148,0,2084573952,1.99989295005798,,,,,,,,,,,,,,,,,,,,,,,,,,,,,,,,,
,3873110426.32563,1.99951207637787,-38366.185546875,-0.376266539523917,0.000109768660840666,1,2,13.1008939743042,2.00060037227699,32.600000500679,-91.3172084526104,-13.3279515708878,1000,0.000221346123941417,,,,,,,,,,,,,,,,,,,,,1.99951207637787,1.99951207637787,-38371.1796875,-38361.19140625,53.2750182422556,5.82387174828687,2.56570792198181,26,1,0,0,1,0.134124755859375,30.3030319213867,1,6,1,1.99951207637787,0,2084573888,1.99951207637787,,,,,,,,,,,,,,,,,,,,,,,,,,,,,,,,,
,3873110500.64814,1.99974966049194,-45812.11328125,-0.403971765505339,0.000204918963704882,1,2,13.1008939743042,2.00069495547424,32.600000500679,-98.0413790827376,-14.3684011201173,1000,-5.37906184364373E-7,,,,,,,,,,,,,,,,,,,,,1.99974465370178,1.9997546672821,-45897.3671875,-45726.859375,53.4993456272749,5.82283965812778,2.56424927711487,26,1,0,0,1,0.135726928710938,31.2805480957031,1,6,1,1.99999976158142,0,2084573856,1.99974966049194,,,,,,,,,,,,,,,,,,,,,,,,,,,,,,,,,
,3873110568.06039,1.99998497962952,-47965.73828125,-0.411798345529239,0.000130878615281628,1,2,13.1008939743042,2.00082809902934,32.600000500679,-99.9713855808866,-14.5261740931628,1000,0.000503925869064554,,,,,,,,,,,,,,,,,,,,,1.99996495246887,2.00000500679016,-48055.26171875,-47876.21484375,53.5052078411691,5.82163245802041,2.56082963943481,26,1,0,0,1,0.134963989257812,31.7693061828613,1,6,1,2.00000500679016,0,2084574240,1.99998497962952,,,,,,,,,,,,,,,,,,,,,,,,,,,,,,,,,
,3873110635.60866,2.00011903047562,-41221.603515625,-0.388110710088892,8.8629020954094E-5,1,2,13.1008939743042,2.0007624778862,32.600000500679,-94.2081531199183,-13.7360257393874,1000,0.000284246147044979,,,,,,,,,,,,,,,,,,,,,1.99989998340607,2.00033807754517,-41306.5546875,-41136.65234375,53.3195710678518,5.82228430523733,2.56056118011475,26,1,0,0,1,0.135040283203125,32.7468223571777,1,6,1,2.00033807754517,0,2084574112,2.00011903047562,,,,,,,,,,,,,,,,,,,,,,,,,,,,,,,,,
,3873110703.1445,1.99999886751175,-34477.513671875,-0.361057927341246,9.06714311847057E-5,1,2,13.1008939743042,2.00079347759391,32.600000500679,-87.6467284448969,-12.7607496413537,1000,0.000339410736542013,,,,,,,,,,,,,,,,,,,,,1.99972951412201,2.00026822090149,-34557.0078125,-34398.01953125,53.1280720806402,5.82244256423767,2.55990099906921,26,1,0,0,1,0.13519287109375,31.2805480957031,1,6,1,2.00026822090149,0,2084573984,1.99999886751175,,,,,,,,,,,,,,,,,,,,,,,,,,,,,,,,,
,3873110770.58371,2.00025582313538,-27743.1650390625,-0.329105080399814,0.000235519295302156,1,2,13.1008939743042,2.00082627203952,32.600000500679,-79.8956976733537,-11.611104519431,1000,0.000394686631321449,,,,,,,,,,,,,,,,,,,,,2.00005912780762,2.00045251846313,-27828.078125,-27658.251953125,52.8951467819094,5.82132124735159,2.55681228637695,26,1,0,0,1,0.13580322265625,30.7917900085449,1,6,1,2.00005912780762,0,2084573888,2.00025582313538,,,,,,,,,,,,,,,,,,,,,,,,,,,,,,,,,
,3873110838.07505,1.99981904029846,-21008.3291015625,-0.290202909425988,0.000115706445644765,1,2,13.1008939743042,2.00054145044795,32.600000500679,-70.4273591223273,-10.2712937026163,1000,0.000201935995281895,,,,,,,,,,,,,,,,,,,,,1.99977791309357,1.99986016750336,-21088.19921875,-20928.458984375,52.8185471870248,5.82283799438003,2.55645346641541,25,1,68,0,0,0.1348876953125,31.2805480957031,1,6,1,1.99977791309357,0,2084574112,1.99981904029846,,,,,,,,,,,,,,,,,,,,,,,,,,,,,,,,,
,3873110905.49881,1.99989151954651,-14274.1518554687,-0.240817359873548,0.00010805650217383,1,2,13.1008939743042,2.00065691272778,32.600000500679,-58.4491460327462,-8.52131069406127,1000,0.000179883744902785,,,,,,,,,,,,,,,,,,,,,1.99966812133789,2.00011491775513,-14359.083984375,-14189.2197265625,52.6665204400344,5.82241971068523,2.55480098724365,24,1,68,0,0,0.134506225585938,33.2355842590332,1,6,1,2.00011491775513,0,2084573760,1.99989151954651,,,,,,,,,,,,,,,,,,,,,,,,,,,,,,,,,
,3873110972.9299,1.99968731403351,-7534.4267578125,-0.171948247418115,0.00013828935563965,1,2,13.1008939743042,2.00080146493461,32.600000500679,-41.7414091966106,-6.07240496515455,1000,0.000181210897085172,,,,,,,,,,,,,,,,,,,,,1.99964320659637,1.99973142147064,-7624.3837890625,-7444.4697265625,52.4832285522748,5.82158969293921,2.55174446105957,26,1,0,0,1,0.134201049804688,31.2805480957031,1,6,1,1.99973142147064,0,2084573824,1.99968731403351,,,,,,,,,,,,,,,,,,,,,,,,,,,,,,,,,
,3873111040.43296,1.9999343752861,-788.353210449219,-0.0541504926786845,0.00029141536544158,1,2,13.1008939743042,2.00048728803282,32.600000500679,-13.1513880777457,-1.84381066235085,1000,0.000337153419970302,,,,,,,,,,,,,,,,,,,,,1.99992573261261,1.99994301795959,-878.421569824219,-698.284851074219,52.4894815804286,5.82122229303097,2.55362749099731,26,1,0,0,1,0.136184692382812,30.7917900085449,1,6,1,1.99994301795959,0,2084573664,1.9999343752861,,,,,,,,,,,,,,,,,,,,,,,,,,,,,,,,,
,3873111111.88482,2.00014460086822,6351.51025390625,0.14559483573512,0.000177932677554334,1,2,13.1008939743042,2.00046575328292,32.600000500679,35.3181273670374,5.23977099516955,100,0.000257371054467968,,,,,,,,,,,,,,,,,,,,,2.00011038780212,2.00017881393433,6261.84375,6441.1767578125,52.4894815804286,5.82197243224627,2.55170440673828,26,1,0,0,1,0.135955810546875,31.2805480957031,1,6,1,2.00011038780212,0,2084573184,2.00014460086822,,,,,,,,,,,,,,,,,,,,,,,,,,,,,,,,,
,3873111179.34717,1.99976223707199,13103.6411132812,0.227804848449448,0.000118888735188089,1,2,13.1008939743042,1.99990828100661,32.600000500679,55.2349730466261,8.1690807880836,100,0.000299628347560143,,,,,,,,,,,,,,,,,,,,,1.99972987174988,1.9997946023941,13013.4306640625,13193.8515625,52.5625638469767,5.82643869671818,2.55000638961792,26,1,0,0,1,0.13641357421875,30.7917900085449,1,6,1,1.99972987174988,0,2084573888,1.99976223707199,,,,,,,,,,,,,,,,,,,,,,,,,,,,,,,,,
,3873111246.82415,1.99990439414978,19851.859375,0.281503136021351,8.04821812331503E-5,1,2,13.1008939743042,2.00034413101949,32.600000500679,68.289364472004,10.0566444624245,100,0.000196214291345827,,,,,,,,,,,,,,,,,,,,,1.99980592727661,2.00000286102295,19757.193359375,19946.525390625,52.7517179486306,5.82466540646437,2.5476188659668,26,1,0,0,1,0.136337280273438,31.7693061828613,1,6,1,1.99980592727661,0,2084574240,1.99990439414978,,,,,,,,,,,,,,,,,,,,,,,,,,,,,,,,,
,3873111322.24297,2.00099414587021,27402.50390625,0.326520460751632,9.28785731106809E-5,1,2,13.1008939743042,1.99987898176575,32.600000500679,79.1679842061658,11.7086259032319,100,0.00042917359094214,,,,,,,,,,,,,,,,,,,,,1.99988043308258,2.00210785865784,27312.28125,27492.7265625,53.0217706020248,5.82857430838289,2.55108070373535,26,1,0,0,1,0.13763427734375,30.7917900085449,1,6,1,2.00210785865784,0,2084574048,2.00099414587021,,,,,,,,,,,,,,,,,,,,,,,,,,,,,,,,,
,3873111431.36065,1.99985826015472,38337.662109375,0.376547514542651,8.56508765948473E-5,1,2,13.1008939743042,1.99964418936485,32.600000500679,91.278017605945,13.49403382336,100,0.000472251518558827,,,,,,,,,,,,,,,,,,,,,1.99974322319031,1.99997329711914,38247.39453125,38427.9296875,53.2804896418903,5.82805634075783,2.54808878898621,24,1,68,0,0,0.137939453125,30.7917900085449,1,6,1,1.99997329711914,0,2084573952,1.99985826015472,,,,,,,,,,,,,,,,,,,,,,,,,,,,,,,,,
,3873111518.71197,1.99971842765808,47098.29296875,0.408461369244878,7.22825382683431E-5,1,2,13.1008939743042,1.99961076840071,32.600000500679,99.0251891427894,14.5407397842725,1000,0.000114239455600487,,,,,,,,,,,,,,,,,,,,,1.9996246099472,1.99981224536896,47008.125,47188.4609375,53.4985639987557,5.8314223660579,2.54906058311462,26,1,0,0,1,0.137405395507812,30.7917900085449,1,6,1,1.9996246099472,0,2084574016,1.99971842765808,,,,,,,,,,,,,,,,,,,,,,,,,,,,,,,,,
,3873112016.2899,18.6782913208008,26.1805820465088,0.000291844298784663,8.16267388082653E-7,1,2,13.1008939743042,1.98019064327845,32.600000500679,0.0694795039075861,0.0100380616610298,1,-5.93863410528032E-7,,,,,,,,,,,,,,,,,,,,,18.6782913208008,18.6782913208008,26.1805820465088,26.1805820465088,52.4859642520921,5.82337806197642,5.62142372131348,26,1,0,0,1,0.127410888671875,30.7917900085449,2,1,1,18.6782913208008,0,2084574240,18.6782913208008,,,,,,,,,,,,,,,,,,,,,,,,,,,,,,,,,
,3873112230.62356,52.0088844299316,26.1805820465088,0.000232195831372342,1.43048152456722E-6,1,2,13.1008939743042,1.98521006532324,32.6399989426136,0.0555026487550463,0.00831466305143389,1,7.39220252435933E-7,,,,,,,,,,,,,,,,,,,,,52.0088844299316,52.0088844299316,26.1805820465088,26.1805820465088,52.4386757266786,5.77949273361594,6.61737966537476,26,1,0,0,1,0.139007568359375,30.7917900085449,2,1,1,52.0088844299316,0,2084574368,52.0088844299316,,,,,,,,,,,,,,,,,,,,,,,,,,,,,,,,,
,3873112444.12552,86.0295867919922,26.1805820465088,0.000211416628712369,5.75534254129091E-8,1,2,13.1008939743042,1.98124799847819,32.6800011098385,0.0503681889389464,0.00738060242567526,1,-4.15713202134158E-9,,,,,,,,,,,,,,,,,,,,,86.0295867919922,86.0295867919922,26.1805820465088,26.1805820465088,52.5723342034671,5.81712169273828,6.92709922790527,26,1,0,0,1,0.133285522460938,29.8142719268799,2,1,1,86.0295867919922,0,2084574304,86.0295867919922,,,,,,,,,,,,,,,,,,,,,,,,,,,,,,,,,
,3873112649.91278,120.06014251709,26.1805820465088,0.000197647453814827,2.25532605396936E-7,1,2,13.1008939743042,1.98197133048333,32.7499993145466,0.0471293821709864,0.00684359127989773,1,-2.60200562169361E-7,,,,,,,,,,,,,,,,,,,,,120.06014251709,120.06014251709,26.1805820465088,26.1805820465088,52.5285630063902,5.80611195885737,7.07536554336548,26,1,0,0,1,0.130538940429688,31.7693061828613,2,1,1,120.06014251709,0,2084574304,120.06014251709,,,,,,,,,,,,,,,,,,,,,,,,,,,,,,,,,
,3873112855.12855,154.026153564453,26.1805820465088,0.000185808989126972,6.19311154761489E-8,1,2,13.1008939743042,1.98262703101821,32.8599996864796,0.0443282875861945,0.00647871021149567,1,-7.27909567782133E-8,,,,,,,,,,,,,,,,,,,,,154.026153564453,154.026153564453,26.1805820465088,26.1805820465088,52.5660811753133,5.80012203120981,7.17086458206177,24,1,64,0,0,0.136642456054688,31.2805480957031,2,1,1,154.026153564453,0,2084574656,154.026153564453,,,,,,,,,,,,,,,,,,,,,,,,,,,,,,,,,
,3873113060.44553,188.047271728516,26.1805820465088,0.00017292328783073,5.05621458916266E-8,1,2,13.1008939743042,1.98281549063332,32.9799987375736,0.0412655539784682,0.00600350676830701,1,-1.80893783329456E-7,,,,,,,,,,,,,,,,,,,,,188.047271728516,188.047271728516,26.1805820465088,26.1805820465088,52.4343767698229,5.80093391812743,7.28326272964478,26,1,0,0,1,0.141525268554688,31.2805480957031,2,1,1,188.047271728516,0,2084574560,188.047271728516,,,,,,,,,,,,,,,,,,,,,,,,,,,,,,,,,
,3873113265.55966,222.031021118164,26.1805820465088,0.000158344677954849,5.23568493947558E-8,1,2,13.1008939743042,1.9837235407009,33.1199988722801,0.0378084535003464,0.00557700014968461,1,1.47802535030354E-7,,,,,,,,,,,,,,,,,,,,,222.031021118164,222.031021118164,26.1805820465088,26.1805820465088,52.3069713211882,5.78596894260548,7.52043151855469,26,1,0,0,1,0.140380859375,31.2805480957031,2,1,1,222.031021118164,0,2084574176,222.031021118164,,,,,,,,,,,,,,,,,,,,,,,,,,,,,,,,,
,3873113470.25757,256.031890869141,26.1805820465088,0.000150221778456433,5.43375979406933E-8,1,2,13.1008939743042,1.98604414100687,33.3000011742115,0.0359309175655199,0.00542301584532725,1,6.43123820307648E-7,,,,,,,,,,,,,,,,,,,,,256.031890869141,256.031890869141,26.1805820465088,26.1805820465088,52.417962570919,5.7718092369125,7.98748350143433,25,1,64,0,0,0.135040283203125,31.2805480957031,2,1,1,256.031890869141,0,2084574432,256.031890869141,,,,,,,,,,,,,,,,,,,,,,,,,,,,,,,,,
,3873113675.62593,290.093444824219,26.1805820465088,0.000144203622032741,7.16284725748103E-8,1,2,13.1008939743042,1.9870412698934,33.500000834465,0.0345078065370477,0.00532332846285038,1,1.08742337585186E-6,,,,,,,,,,,,,,,,,,,,,290.093444824219,290.093444824219,26.1805820465088,26.1805820465088,52.5586557043806,5.75877604160563,8.05124473571777,26,1,0,0,1,0.137176513671875,31.7693061828613,2,1,1,290.093444824219,0,2084574496,290.093444824219,,,,,,,,,,,,,,,,,,,,,,,,,,,,,,,,,
,3873114458.79757,278.991943359375,26.4525241851807,0.000166341390639022,5.59780875255112E-8,1,2,13.1008939743042,1.97792192523399,33.4200002253056,0.039467720910752,0.00603086498478314,1,1.0171711499166E-6,,,,,,,,,,,,,,,,,,,,,278.991943359375,278.991943359375,26.4525241851807,26.4525241851807,52.5625638469767,5.74394026767438,9.05870246887207,26,1,0,0,1,0.126495361328125,30.7917900085449,2,1,1,278.991943359375,0,2084573184,278.991943359375,,,,,,,,,,,,,,,,,,,,,,,,,,,,,,,,,
,3873114659.17911,244.987762451172,26.4525241851807,0.000162365475434638,1.06273924750206E-7,1,2,13.1008939743042,1.9769059593317,33.2800000905991,0.0384960029786852,0.00581820619566035,1,7.28287140586148E-7,,,,,,,,,,,,,,,,,,,,,244.987762451172,244.987762451172,26.4525241851807,26.4525241851807,52.5008151939575,5.75271067110598,8.68016242980957,26,1,0,0,1,0.127944946289062,31.7693061828613,2,1,1,244.987762451172,0,2084573920,244.987762451172,,,,,,,,,,,,,,,,,,,,,,,,,,,,,,,,,
,3873114861.91847,210.855590820313,26.4525241851807,0.000159524204837563,1.39573639009338E-7,1,2,13.1008939743042,1.98494430556219,33.1300012767315,0.0381453000439349,0.00555188911124522,1,-1.57328688282043E-7,,,,,,,,,,,,,,,,,,,,,210.818862915039,210.892318725586,26.4525241851807,26.4525241851807,52.595783059044,5.78458117780394,8.37312698364258,26,1,0,0,1,0.1336669921875,31.2805480957031,2,1,1,210.818862915039,0,2084573184,210.855590820313,,,,,,,,,,,,,,,,,,,,,,,,,,,,,,,,,
,3873115065.49768,176.983932495117,26.4525241851807,0.000158693901349289,5.39357042611656E-8,1,2,13.1008939743042,1.98261285551088,33.0299995839596,0.0378596991735228,0.00552809453572505,1,-8.35603871614386E-8,,,,,,,,,,,,,,,,,,,,,176.983932495117,176.983932495117,26.4525241851807,26.4525241851807,52.3030631785921,5.80641484810085,8.14201545715332,24,1,64,0,0,0.136871337890625,31.2805480957031,2,1,1,176.983932495117,0,2084573728,176.983932495117,,,,,,,,,,,,,,,,,,,,,,,,,,,,,,,,,
,3873115269.99592,142.950302124023,26.4525241851807,0.000157279173001949,6.88436327784641E-8,1,2,13.1008939743042,1.98265484460271,32.9199992120266,0.0375262634000873,0.00546150252290279,1,-1.56298177709904E-7,,,,,,,,,,,,,,,,,,,,,142.950302124023,142.950302124023,26.4525241851807,26.4525241851807,52.224900326669,5.80636114348385,7.95115232467651,26,1,0,0,1,0.132522583007812,31.2805480957031,2,1,1,142.950302124023,0,2084573952,142.950302124023,,,,,,,,,,,,,,,,,,,,,,,,,,,,,,,,,
,3873115473.67331,108.971122741699,26.4525241851807,0.000156276885689574,4.61538767546458E-8,1,2,13.1008939743042,1.98274627887145,32.8299999237061,0.0372862574612205,0.0054553280908494,1,-3.72924529267397E-8,,,,,,,,,,,,,,,,,,,,,108.971122741699,108.971122741699,26.4525241851807,26.4525241851807,52.4543082970632,5.80534195025387,7.77079916000366,25,1,64,0,0,0.130157470703125,31.2805480957031,2,1,1,108.971122741699,0,2084573920,108.971122741699,,,,,,,,,,,,,,,,,,,,,,,,,,,,,,,,,
,3873115676.32527,74.9872589111328,26.4525241851807,0.000156134442333107,5.19631237982178E-8,1,2,13.1008939743042,1.98478839216734,32.7499993145466,0.037326725958039,0.00544985347200939,1,-8.39280666472121E-8,,,,,,,,,,,,,,,,,,,,,74.9872589111328,74.9872589111328,26.4525241851807,26.4525241851807,52.478929595419,5.78723568860805,7.55100584030151,26,1,0,0,1,0.140228271484375,29.8142719268799,2,1,1,74.9872589111328,0,2084573504,74.9872589111328,,,,,,,,,,,,,,,,,,,,,,,,,,,,,,,,,
,3873115874.12584,40.9588890075684,26.4525241851807,0.000160771244653702,3.67682523309833E-7,1,2,13.1008939743042,1.98740507530109,32.6699987053871,0.0385150716642114,0.00573714737945902,1,3.7845804061605E-7,,,,,,,,,,,,,,,,,,,,,40.9588890075684,40.9588890075684,26.4525241851807,26.4525241851807,52.4265604846305,5.7596465928561,7.16743421554565,26,1,0,0,1,0.135498046875,29.3255138397217,2,1,1,40.9588890075684,0,2084573632,40.9588890075684,,,,,,,,,,,,,,,,,,,,,,,,,,,,,,,,,
,3873116144.40325,6.96410417556763,26.4525241851807,0.000306108219133911,2.81268851645377E-7,1,2,13.1008939743042,1.98370858617854,32.6200015842915,0.0731164849265757,0.0105961583049959,1,-4.89027081420429E-7,,,,,,,,,,,,,,,,,,,,,6.96410417556763,6.96410417556763,26.4525241851807,26.4525241851807,52.4468828261306,5.79709897191714,4.65538263320923,26,1,0,0,1,0.14434814453125,31.2805480957031,6,1,1,6.96410417556763,0,2084575328,6.96410417556763,,,,,,,,,,,,,,,,,,,,,,,,,,,,,,,,,
,3873117195.51421,29.0463523864746,26.4525241851807,0.000171165780887293,5.3859051429447E-8,1,2,13.1008939743042,1.98517170530749,32.6099991798401,0.0409312875523485,0.00600359147062447,1,2.0405481435821E-8,,,,,,,,,,,,,,,,,,,,,29.0463523864746,29.0463523864746,26.4525241851807,26.4525241851807,52.4937805372844,5.78081991302373,6.13800191879272,26,1,0,0,1,0.139923095703125,31.7693061828613,2,1,1,29.0463523864746,0,2084574368,29.0463523864746,,,,,,,,,,,,,,,,,,,,,,,,,,,,,,,,,
,3873117412.54724,63.032901763916,26.4525241851807,0.000156080396056666,4.97895714675852E-8,1,2,13.1008939743042,1.98374594636792,32.6399989426136,0.0372796939641039,0.00542168539629193,1,-1.71227406639442E-7,,,,,,,,,,,,,,,,,,,,,63.032901763916,63.032901763916,26.4525241851807,26.4525241851807,52.478929595419,5.79514872354483,6.79887390136719,26,1,0,0,1,0.141754150390625,30.7917900085449,2,1,1,63.032901763916,0,2084574336,63.032901763916,,,,,,,,,,,,,,,,,,,,,,,,,,,,,,,,,
,3873117623.01486,97.0211410522461,26.4525241851807,0.000153936168176722,5.85327637422173E-8,1,2,13.1008939743042,1.98109954509188,32.6999984681606,0.0366707861578977,0.00535929317632312,1,-6.13345939392042E-8,,,,,,,,,,,,,,,,,,,,,97.0211410522461,97.0211410522461,26.4525241851807,26.4525241851807,52.5019876367363,5.82341456917872,7.02940320968628,25,1,64,0,0,0.133895874023438,31.2805480957031,2,1,1,97.0211410522461,0,2084574304,97.0211410522461,,,,,,,,,,,,,,,,,,,,,,,,,,,,,,,,,
,3873117828.54593,131.029983520508,26.4525241851807,0.000153583110060172,9.46460258044222E-8,1,2,13.1008939743042,1.9821293781933,32.7799990773201,0.0366236667969684,0.00534620012210798,1,-8.66785133432702E-8,,,,,,,,,,,,,,,,,,,,,131.029983520508,131.029983520508,26.4525241851807,26.4525241851807,52.4707224959671,5.81400915733836,7.1536660194397,26,1,0,0,1,0.137176513671875,30.7917900085449,2,1,1,131.029983520508,0,2084574368,131.029983520508,,,,,,,,,,,,,,,,,,,,,,,,,,,,,,,,,
,3873118033.89935,165.006851196289,26.4525241851807,0.00015292540592719,7.72314686849165E-8,1,2,13.1008939743042,1.9826964664134,32.8899994492531,0.0364916533780358,0.00529189931602473,1,-2.30064019980597E-7,,,,,,,,,,,,,,,,,,,,,165.006851196289,165.006851196289,26.4525241851807,26.4525241851807,52.4523542257652,5.80736073842324,7.25363779067993,26,1,0,0,1,0.136184692382812,31.7693061828613,2,1,1,165.006851196289,0,2084574336,165.006851196289,,,,,,,,,,,,,,,,,,,,,,,,,,,,,,,,,
,3873118239.21992,199.025444030762,26.4525241851807,0.000152031477333458,6.72880390456445E-8,1,2,13.1008939743042,1.98474501795355,33.0200009047985,0.036341944252296,0.00532271477449426,1,-1.35548000342628E-8,,,,,,,,,,,,,,,,,,,,,199.004852294922,199.046035766602,26.4525241851807,26.4525241851807,52.5410690626979,5.77955185210203,7.38148164749145,25,1,64,0,0,0.142822265625,31.7693061828613,2,1,1,199.046035766602,0,2084574368,199.025444030762,,,,,,,,,,,,,,,,,,,,,,,,,,,,,,,,,
,3873118444.00277,233.013931274414,26.4525241851807,0.000151229774688474,5.63078434354158E-8,1,2,13.1008939743042,1.98527256708838,33.1799983978271,0.0361548712424661,0.00539052908121884,1,3.76267379216071E-7,,,,,,,,,,,,,,,,,,,,,233.013931274414,233.013931274414,26.4525241851807,26.4525241851807,52.5375517343613,5.77093277127094,7.63779878616333,24,1,64,0,0,0.140838623046875,30.7917900085449,2,1,1,233.057418823242,0,2084574304,233.013931274414,,,,,,,,,,,,,,,,,,,,,,,,,,,,,,,,,
,3873118648.68166,267.012786865234,26.4525241851807,0.000150273450241284,4.66663077263659E-8,1,2,13.1008939743042,1.98727571849932,33.3600006997585,0.0359772166936048,0.00548819467392627,1,8.80938974877403E-7,,,,,,,,,,,,,,,,,,,,,267.012786865234,267.012786865234,26.4525241851807,26.4525241851807,52.5152753215633,5.76270598429905,8.10836791992188,26,1,0,0,1,0.137100219726562,32.2580642700195,2,1,1,267.012786865234,0,2084574464,267.012786865234,,,,,,,,,,,,,,,,,,,,,,,,,,,,,,,,,
,3873119084.45347,300.005645751953,50000.44921875,0.0185463118409358,4.4425522981053E-6,1,2,13.1008939743042,1.98919130890904,33.5399992763996,4.45203700721798,0.653233822069447,10,3.15649565854845E-6,,,,,,,,,,,,,,,,,,,,,300.005645751953,300.005645751953,50000.44921875,50000.44921875,52.3863066158902,5.74156548342182,7.80828094482422,26,1,0,0,1,0.133743286132812,30.3030319213867,1,4,1,300.005615234375,0,2084573184,300.005645751953,,,,,,,,,,,,,,,,,,,,,,,,,,,,,,,,,
,3873119173.19851,300.003555297852,41404.361328125,0.0157877558114898,0.000193061378745577,1,2,13.1008939743042,1.98932932296888,33.5399992763996,3.8096714240132,0.42427257617964,100,-0.000546584859952975,,,,,,,,,,,,,,,,,,,,,300.003265380859,300.003845214844,41314.44140625,41494.28125,52.4195258279575,5.7385424058656,7.88734531402588,24,1,68,0,0,0.134429931640625,30.3030319213867,1,6,1,300.003265380859,0,2084573184,300.003555297852,,,,,,,,,,,,,,,,,,,,,,,,,,,,,,,,,
,3873119256.5524,300.003128051758,33076.25390625,0.0125841197785387,8.96297600308857E-6,1,2,13.1008939743042,1.98943470075082,33.5399992763996,3.03194946887926,0.372140838490615,100,-0.00029437434721709,,,,,,,,,,,,,,,,,,,,,300.002960205078,300.003295898438,32986.24609375,33166.26171875,52.4785387811594,5.74003730341049,8.03677082061768,24,1,68,0,0,0.133285522460938,31.7693061828613,1,6,1,300.003295898438,0,2084573920,300.003128051758,,,,,,,,,,,,,,,,,,,,,,,,,,,,,,,,,
,3873119324.0871,300.001815795898,26335.0498046875,0.010143884021897,1.93574214511462E-5,1,2,13.1008939743042,1.98944499594706,33.5399992763996,2.44423031114065,0.298656679952727,100,-0.000242804373741813,,,,,,,,,,,,,,,,,,,,,300.001617431641,300.002014160156,26245.1171875,26424.982421875,52.5559200045633,5.74089298839545,8.21490573883057,26,1,0,0,1,0.131454467773438,31.2805480957031,1,6,1,300.002014160156,0,2084573856,300.001815795898,,,,,,,,,,,,,,,,,,,,,,,,,,,,,,,,,
,3873119399.48848,300.001937866211,18806.5830078125,0.00739698401877569,2.59698965138806E-5,1,2,13.1008939743042,1.98968919720718,33.5399992763996,1.78277996800657,0.21771700063312,100,-0.000177537545454933,,,,,,,,,,,,,,,,,,,,,300.001892089844,300.001983642578,18716.65625,18896.509765625,52.4543082970632,5.74007734434908,8.46641254425049,26,1,0,0,1,0.133743286132812,32.2580642700195,1,6,1,300.001983642578,0,2084574016,300.001937866211,,,,,,,,,,,,,,,,,,,,,,,,,,,,,,,,,
,3873119466.90911,300.001708984375,12074.7426757813,0.00493989954924524,0.000118560893593361,1,2,13.1008939743042,1.98978064735003,33.5399992763996,1.18943354050616,0.153989242109185,100,-8.28448387913201E-5,,,,,,,,,,,,,,,,,,,,,300.001495361328,300.001922607422,11984.7607421875,12164.724609375,52.568426060871,5.73984714411284,8.72320365905762,26,1,0,0,1,0.133056640625,31.7693061828613,1,6,1,300.001922607422,0,2084573920,300.001708984375,,,,,,,,,,,,,,,,,,,,,,,,,,,,,,,,,
,3873119534.36032,300.001129150391,5328.81787109375,0.00251822949166379,9.50856879001899E-5,1,2,13.1008939743042,1.98981509099451,33.5399992763996,0.61238517373807,0.0373999094839817,100,-0.000213350133320344,,,,,,,,,,,,,,,,,,,,,300.001007080078,300.001251220703,5239.25634765625,5418.37939453125,52.5027692652556,5.73993245317042,8.97613334655762,24,1,68,0,0,0.130538940429688,29.8142719268799,1,6,1,300.001251220703,0,2084573920,300.001129150391,,,,,,,,,,,,,,,,,,,,,,,,,,,,,,,,,
,3873119609.81256,300.0009765625,-2214.00817871094,-0.000899217685687321,4.32381241628159E-5,1,2,13.1008939743042,1.98977380167233,33.5399992763996,-0.206658551838793,-0.095272522134869,100,-0.000264873313653506,,,,,,,,,,,,,,,,,,,,,300.000915527344,300.001037597656,-2299.11987304687,-2128.896484375,52.6075074868325,5.73908727133197,9.24994277954102,26,1,0,0,1,0.132980346679688,30.7917900085449,1,6,1,300.000915527344,0,2084573632,300.0009765625,,,,,,,,,,,,,,,,,,,,,,,,,,,,,,,,,
,3873119685.19751,299.999771118164,-9749.583984375,-0.00396830454821532,6.55952888233524E-6,1,2,13.1008939743042,1.98975563476346,33.5399992763996,-0.950989521355226,-0.154266356717628,100,-6.07144543973951E-5,,,,,,,,,,,,,,,,,,,,,299.999725341797,299.999816894531,-9839.7080078125,-9659.4599609375,52.548103719371,5.73662784226028,9.51292514801025,26,1,0,0,1,0.133819580078125,31.2805480957031,1,6,1,299.999725341797,0,2084573664,299.999771118164,,,,,,,,,,,,,,,,,,,,,,,,,,,,,,,,,
,3873119756.71763,300.000640869141,-16902.1865234375,-0.00663280608014919,7.47230458623852E-6,1,2,13.1008939743042,1.98969006711718,33.5399992763996,-1.59291085653113,-0.23406765121635,10,-2.53387711040608E-6,,,,,,,,,,,,,,,,,,,,,300.000518798828,300.000762939453,-16992.236328125,-16812.13671875,52.5215283497171,5.7368934211797,9.45596408843994,26,1,0,0,1,0.133209228515625,31.2805480957031,1,6,1,300.000732421875,0,2084573888,300.000640869141,,,,,,,,,,,,,,,,,,,,,,,,,,,,,,,,,
,3873119836.06791,300.000228881836,-24843.9072265625,-0.00951893964381154,6.63894014448076E-6,1,2,13.1008939743042,1.98961025324049,33.5399992763996,-2.2869848671951,-0.328219521110712,100,2.83119663427584E-5,,,,,,,,,,,,,,,,,,,,,300.000213623047,300.000244140625,-24934.037109375,-24753.77734375,52.5688168751306,5.73695613306783,9.36856460571289,26,1,0,0,1,0.133056640625,30.7917900085449,1,6,1,300.000213623047,0,2084573984,300.000228881836,,,,,,,,,,,,,,,,,,,,,,,,,,,,,,,,,
,3873119903.56612,300.000183105469,-31602.0205078125,-0.0119519781522926,8.2263225441664E-6,1,2,13.1008939743042,1.98973243823463,33.5399992763996,-2.87216037518574,-0.410192490880326,100,4.37417141143415E-5,,,,,,,,,,,,,,,,,,,,,300.000122070313,300.000244140625,-31687.23046875,-31516.810546875,52.4906540232075,5.73749965699863,9.30601596832275,26,1,0,0,1,0.138168334960938,31.2805480957031,1,6,1,300.000244140625,0,2084574144,300.000183105469,,,,,,,,,,,,,,,,,,,,,,,,,,,,,,,,,
,3873119979.01226,300.001113891602,-39161.841796875,-0.0146864726706452,7.69368224190357E-6,1,2,13.1008939743042,1.98969688611808,33.5399992763996,-3.52930886517957,-0.503026230709666,100,5.79013099361272E-5,,,,,,,,,,,,,,,,,,,,,300.000915527344,300.001312255859,-39242.05859375,-39081.625,52.4500093402075,5.73912227407616,9.24601554870605,26,1,0,0,1,0.132980346679688,32.7468223571777,1,6,1,300.001312255859,0,2084574144,300.001113891602,,,,,,,,,,,,,,,,,,,,,,,,,,,,,,,,,
,3873120064.26167,300.000991821289,-47710.310546875,-0.0177126337059612,5.43617556350959E-5,1,2,13.1008939743042,1.98979305731279,33.5399992763996,-4.25469804242543,-0.621866801742842,100,6.81621838961897E-6,,,,,,,,,,,,,,,,,,,,,300.000946044922,300.001037597656,-47800.515625,-47620.10546875,52.3710648597652,5.73897462307729,9.19231128692627,26,1,0,0,1,0.1336669921875,31.2805480957031,1,6,1,300.000946044922,0,2084574016,300.000991821289,,,,,,,,,,,,,,,,,,,,,,,,,,,,,,,,,
,3873120141.69152,300.000244140625,-44986.404296875,-0.0169739705947028,5.72396448423934E-5,1,2,13.1008939743042,1.98973604330945,33.5399992763996,-4.09764632093195,-0.455325190530846,100,0.000591824438914694,,,,,,,,,,,,,,,,,,,,,300.000213623047,300.000274658203,-45071.28125,-44901.52734375,52.4359400268613,5.74062657397261,9.15144443511963,23,1,68,0,0,0.13397216796875,32.7468223571777,1,6,1,300.000213623047,0,2084574304,300.000244140625,,,,,,,,,,,,,,,,,,,,,,,,,,,,,,,,,
,3873120209.17117,299.999526977539,-38251.517578125,-0.0145053379344513,1.7037623416004E-5,1,2,13.1008939743042,1.98967009274381,33.5399992763996,-3.49884899382365,-0.40702872908245,100,0.000431016297664653,,,,,,,,,,,,,,,,,,,,,299.999359130859,299.999694824219,-38341.44921875,-38161.5859375,52.5355976630632,5.74256671289629,9.11963653564453,25,1,68,0,0,0.133132934570312,31.2805480957031,1,6,1,299.999359130859,0,2084574048,299.999526977539,,,,,,,,,,,,,,,,,,,,,,,,,,,,,,,,,
,3873120276.67724,300.000793457031,-31518.1572265625,-0.0120817321860885,3.56064875939569E-5,1,2,13.1008939743042,1.98970704046799,33.5399992763996,-2.91159408325252,-0.357843952223653,100,0.000280677364813615,,,,,,,,,,,,,,,,,,,,,300.000762939453,300.000823974609,-31603.052734375,-31433.26171875,52.5121488074863,5.74041814013603,9.09104824066162,24,1,68,0,0,0.133590698242188,31.2805480957031,1,6,1,300.000762939453,0,2084573920,300.000793457031,,,,,,,,,,,,,,,,,,,,,,,,,,,,,,,,,
,3873120352.07756,300.000427246094,-23984.478515625,-0.00929929276766733,1.0380812486428E-5,1,2,13.1008939743042,1.98970615840258,33.5399992763996,-2.24192380430803,-0.269456477952406,100,0.000240916045430307,,,,,,,,,,,,,,,,,,,,,300.000396728516,300.000457763672,-24074.466796875,-23894.490234375,52.4933897230248,5.74009681883545,9.06147956848145,26,1,0,0,1,0.133514404296875,31.7693061828613,1,6,1,300.000457763672,0,2084574016,300.000427246094,,,,,,,,,,,,,,,,,,,,,,,,,,,,,,,,,
,3873120443.28568,300.00016784668,-14879.1865234375,-0.00598533455731808,1.68746688637686E-5,1,2,13.1008939743042,1.9897996110506,33.5399992763996,-1.44508838430307,-0.159915367250656,100,0.000211396012376279,,,,,,,,,,,,,,,,,,,,,300.000152587891,300.000183105469,-14969.1865234375,-14789.1865234375,52.5164477643421,5.73738509569574,9.03573417663574,26,1,0,0,1,0.132522583007812,31.7693061828613,1,6,1,300.000183105469,0,2084573952,300.00016784668,,,,,,,,,,,,,,,,,,,,,,,,,,,,,,,,,
,3873120518.70817,300.000137329102,-7340.05590820312,-0.00322578520451871,2.56350914780462E-5,1,2,13.1008939743042,1.98985096359357,33.5399992763996,-0.781124744057114,-0.0707769988952949,100,0.000178098388865377,,,,,,,,,,,,,,,,,,,,,300.000122070313,300.000152587891,-7424.93896484375,-7255.1728515625,52.5101947361882,5.73747499983401,9.01430225372314,26,1,0,0,1,0.132827758789062,31.7693061828613,1,6,1,300.000152587891,0,2084573536,300.000137329102,,,,,,,,,,,,,,,,,,,,,,,,,,,,,,,,,
,3873120594.22235,299.999954223633,206.74995803833,-0.000225959297778497,5.39816032301536E-5,1,2,13.1008939743042,1.98964236326056,33.5399992763996,-0.0688636212776359,0.0916525127833528,100,0.000414747780758168,,,,,,,,,,,,,,,,,,,,,299.999847412109,300.000061035156,121.718696594238,291.781219482422,52.5695985036498,5.73850162980942,8.99513149261475,24,1,68,0,0,0.133438110351562,31.2805480957031,1,6,1,300.000061035156,0,2084573824,299.999954223633,,,,,,,,,,,,,,,,,,,,,,,,,,,,,,,,,
,3873120671.57133,299.999481201172,7941.98071289063,0.00326737939533885,7.85622611023535E-6,1,2,13.1008939743042,1.98971388134136,33.5399992763996,0.780973227906148,0.140735202257037,100,0.000107124102720352,,,,,,,,,,,,,,,,,,,,,299.999359130859,299.999603271484,7851.912109375,8032.04931640625,52.5801504886594,5.73956342600482,8.97984504699707,26,1,0,0,1,0.133590698242188,31.7693061828613,1,6,1,299.999359130859,0,2084573184,299.999481201172,,,,,,,,,,,,,,,,,,,,,,,,,,,,,,,,,
,3873120743.00082,299.999923706055,15089.6381835938,0.00597424068495571,6.95403623180824E-6,1,2,13.1008939743042,1.98972652803565,33.5399992763996,1.43397809722873,0.216456555147528,10,2.56896892904817E-5,,,,,,,,,,,,,,,,,,,,,299.999786376953,300.000061035156,14994.5390625,15184.7373046875,52.5406782484383,5.74009737071735,8.96689224243164,26,1,0,0,1,0.13336181640625,31.2805480957031,1,6,1,300.000061035156,0,2084573952,299.999923706055,,,,,,,,,,,,,,,,,,,,,,,,,,,,,,,,,
,3873120850.17898,300.000915527344,25813.912109375,0.00988105751212433,1.40528239584426E-5,1,2,13.1008939743042,1.98968320230284,33.5399992763996,2.37368720094775,0.343893961529139,100,-1.6212063238561E-5,,,,,,,,,,,,,,,,,,,,,300.000915527344,300.000915527344,25728.638671875,25899.185546875,52.5864035168132,5.74055657982547,8.95088958740234,24,1,68,0,0,0.133056640625,31.2805480957031,1,6,1,300.000915527344,0,2084574016,300.000915527344,,,,,,,,,,,,,,,,,,,,,,,,,,,,,,,,,
,3873120917.62004,300.000198364258,32569.287109375,0.0123177150485679,6.85401496633076E-6,1,2,13.1008939743042,1.98958327789576,33.550001680851,2.95921293256109,0.425525479684304,100,-3.32500389590951E-5,,,,,,,,,,,,,,,,,,,,,300.000152587891,300.000244140625,32474.14453125,32664.4296875,52.4390665409382,5.74398691794835,8.9367733001709,26,1,0,0,1,0.134353637695312,31.7693061828613,1,6,1,300.000152587891,0,2084574272,300.000198364258,,,,,,,,,,,,,,,,,,,,,,,,,,,,,,,,,
,3873120985.1842,300.000137329102,39339.390625,0.0147580039930354,8.99894142646417E-6,1,2,13.1008939743042,1.9894940374424,33.5399992763996,3.54576388727603,0.505713953492494,100,-5.67865025837673E-5,,,,,,,,,,,,,,,,,,,,,299.999938964844,300.000335693359,39249.0703125,39429.7109375,52.4109279142459,5.74310031750736,8.92768478393555,26,1,0,0,1,0.1336669921875,28.8367557525635,1,6,1,299.999938964844,0,2084574048,300.000137329102,,,,,,,,,,,,,,,,,,,,,,,,,,,,,,,,,
,3873121052.59039,299.999938964844,46100.1796875,0.0173315918390339,0.000439738932548669,1,2,13.1008939743042,1.98946527097163,33.5399992763996,4.14744107367479,0.706746398522104,100,0.000403326115006385,,,,,,,,,,,,,,,,,,,,,299.999755859375,300.000122070313,46015.2890625,46185.0703125,52.4316410700055,5.74316552340844,8.91689395904541,26,1,0,0,1,0.133132934570312,30.7917900085449,1,6,1,300.000122070313,0,2084574080,299.999938964844,,,,,,,,,,,,,,,,,,,,,,,,,,,,,,,,,
,3873121094.45338,300.000518798828,50000.232421875,0.0185709250664811,4.30829009359892E-6,1,2,13.1008939743042,1.98936827916951,33.5399992763996,4.45884108789311,0.653231008071657,100,-9.21350004222636E-7,,,,,,,,,,,,,,,,,,,,,300.000457763672,300.000579833984,50000.2265625,50000.23828125,52.433204327044,5.74211753647847,8.9102725982666,26,1,0,0,1,0.133132934570312,31.7693061828613,1,4,1,300.000579833984,0,2084574016,300.000518798828,,,,,,,,,,,,,,,,,,,,,,,,,,,,,,,,,