File: LT data/Sherwood/K1/260-FC-ZFC-RTSIRM-contsweepwithloop-MsT-AC.dat
[Header]
; MPMS3 Data File (default extension .dat)
; Copyright (c) 2007, Quantum Design, Inc. All rights reserved.
TITLE,
FILEOPENTIME,3865843246.80756,07/01/2022,2:18 pm
BYAPP,MPMS3 w/ AC,1.0,1.1
INFO,MPMS3 Measurement Release 1.1.16 Build 424, MultiVu Release 2.3.4.19,APPNAME
INFO,Linear Motor Servo Controller,MOTOR_MODULE_NAME
INFO,3101-100 N2,MOTOR_HW_VERSION
INFO,,MOTOR_SERIAL_NUMBER
INFO,01.04.28,MOTOR_SOFTWARE_VERSION
INFO,Quantum Design Squid Module,SQUID_MODULE_NAME
INFO,3101-501 B0,SQUID_HW_VERSION
INFO,SQM327,SQUID_SERIAL_NUMBER
INFO,01.03.04,SQUID_SOFTWARE_VERSION
INFO,Quantum Design VSM Oven,OVEN_MODULE_NAME
INFO,3101-201 A3,OVEN_HW_VERSION
INFO,OVB365,OVEN_SERIAL_NUMBER
INFO,01.07.07,OVEN_SOFTWARE_VERSION
INFO,SQUID AC,AC_MODULE_NAME
INFO,3101-401 G0,AC_HW_VERSION
INFO,SAC220,AC_SERIAL_NUMBER
INFO,SQUID AC 00.95.07,AC_SOFTWARE_VERSION
INFO,TCI344,COIL_SERIAL_NUMBER
INFO,0,MOMENT_UNITS
INFO,sndst,SAMPLE_MATERIAL
INFO,,SAMPLE_COMMENT
INFO,139.46,SAMPLE_MASS
INFO,,SAMPLE_VOLUME
INFO,,SAMPLE_MOLECULAR_WEIGHT
INFO,,SAMPLE_SIZE
INFO,,SAMPLE_SHAPE
INFO,Straw,SAMPLE_HOLDER
INFO,Standard,SAMPLE_HOLDER_DETAIL
INFO,59.97,SAMPLE_OFFSET
DATATYPE,COMMENT,1
DATATYPE,TIME,2
STARTUPAXIS,X,2
STARTUPAXIS,Y1,5
FIELDGROUP, VSM,2,3,4,5,6,8,9,10,11,14,15
FIELDGROUP, DC, 2,3,4,14,56,57,58,59,60,61,62,63,64,65,66,67,68,69
FIELDGROUP, AC, 2,3,4,11,16,17,18,19,20,21,22,23,24,25,26,27,28,29,30
STARTUPGROUP, All
[Data]
Comment,Time Stamp (sec),Temperature (K),Magnetic Field (Oe),Moment (emu),M. Std. Err. (emu),Transport Action,Averaging Time (sec),Frequency (Hz),Peak Amplitude (mm),Center Position (mm),Lockin Signal' (V),Lockin Signal (V),Range,M. Quad. Signal (emu),AC Moment (emu),AC M. Std Err. (emu),AC Phase (deg),AC Phase Std. Err. (deg),AC Susceptibility (emu/Oe),AC Suscept. Std Err. (emu/Oe),AC X' (emu/Oe),AC X' Std Err. (emu/Oe),AC X'' (emu/Oe),AC X'' Std Err. (emu/Oe),AC Drive (Oe),AC Frequency (Hz),AC Averaging Time (sec),AC Cycles,AC Range,AC Measure Type,AC Signal' (V),AC Signal'' (V),AC Trim Coil Ratio,AC Trim Coil Phase,Min. Temperature (K),Max. Temperature (K),Min. Field (Oe),Max. Field (Oe),Mass (grams),Motor Lag (deg),Pressure (Torr),Measure Count,Measurement Number,SQUID Status (code),Motor Status (code),Measure Status (code),Motor Current (amps),Motor Temp. (C),Temp. Status (code),Field Status (code),Chamber Status (code),Chamber Temp (K),Redirection State,Average Temp (K),Rotation Angle (deg),Rotator state,DC Moment Fixed Ctr (emu),DC Moment Err Fixed Ctr (emu),DC Moment Free Ctr (emu),DC Moment Err Free Ctr (emu),DC Fixed Fit,DC Free Fit,DC Calculated Center (mm),DC Calculated Center Err (mm),DC Scan Length (mm),DC Scan Time (s),DC Number of Points,DC Squid Drift,DC Min V (V),DC Max V (V),DC Scans per Measure,Map 01,Map 02,Map 03,Map 04,Map 05,Map 06,Map 07,Map 08,Map 09,Map 10,Map 11,Map 12,Map 13,Map 14,Map 15,Map 16
,3865844347.00911,100.001686096191,49999.7109375,0.0264617807431271,3.08488203540663E-6,1,2,12.9061126708984,4.99568654593368,46.6499999165535,34.5148734874984,5.03469273642378,100,-2.69614189227919E-5,,,,,,,,,,,,,,,,,,,,,100.001686096191,100.001686096191,49999.7109375,49999.7109375,49.6455262132072,5.39325495130748,7.45492839813232,26,1,0,0,1,0.288467407226562,30.3030319213867,1,1,1,100.001686096191,0,100.001686096191,,,,,,,,,,,,,,,,,,,,,,,,,,,,,,,,,
,3865844416.22433,91.3600730895996,49999.7109375,0.0288288963584277,9.54488679513523E-5,1,2,12.9061126708984,4.99590618294692,46.6299988329411,37.5875618549378,5.60198643878004,100,6.00151351766966E-5,,,,,,,,,,,,,,,,,,,,,91.1978149414062,91.522331237793,49999.7109375,49999.7109375,49.6525608698802,5.39247368487757,7.40604782104492,26,1,0,0,1,0.2886962890625,31.2805480957031,2,1,1,91.1978149414062,0,91.3600730895996,,,,,,,,,,,,,,,,,,,,,,,,,,,,,,,,,
,3865844492.77235,79.1683349609375,49999.7109375,0.0340524373486938,0.000174674350473107,1,2,12.9061126708984,4.9964489751328,46.5900003910065,44.4552078872542,6.27529407731575,100,-0.000191857550092947,,,,,,,,,,,,,,,,,,,,,78.9806213378906,79.3560485839844,49999.7109375,49999.7109375,49.7201717367937,5.3910351664141,7.34650373458862,26,1,0,0,1,0.2880859375,31.2805480957031,2,1,1,78.9806213378906,0,79.1683349609375,,,,,,,,,,,,,,,,,,,,,,,,,,,,,,,,,
,3865844597.64898,61.3734531402588,49999.7109375,0.044353828825066,1.74562289374793E-5,1,2,12.9061126708984,4.99642545385116,46.5399995446205,57.861532486296,8.45735447708031,100,-3.2372601476134E-5,,,,,,,,,,,,,,,,,,,,,61.2511329650879,61.4957733154297,49999.7109375,49999.7109375,49.7358043071783,5.38986466136522,7.24258852005005,26,1,0,0,1,0.278778076171875,31.7693061828613,2,1,1,61.2511329650879,0,61.3734531402588,,,,,,,,,,,,,,,,,,,,,,,,,,,,,,,,,
,3865844710.83352,42.2625064849854,49999.7109375,0.0644564650824375,7.07958956701733E-5,1,2,12.9061126708984,4.99686551088999,46.4899986982346,84.086086089043,12.3642127504418,100,8.28815173009823E-6,,,,,,,,,,,,,,,,,,,,,42.1840553283691,42.3409576416016,49999.7109375,49999.7109375,49.6728832113803,5.38938652982509,6.99332094192505,25,1,64,0,0,0.278167724609375,31.7693061828613,2,1,1,42.1840553283691,0,42.2625064849854,,,,,,,,,,,,,,,,,,,,,,,,,,,,,,,,,
,3865844839.70519,20.7661771774292,49999.7109375,0.11198966969833,0.000106276815984377,1,2,12.9061126708984,4.99702995985185,46.459998935461,146.110013672062,21.4274286233525,100,-2.83111124438414E-5,,,,,,,,,,,,,,,,,,,,,20.690845489502,20.8415088653564,49999.7109375,49999.7109375,49.7858285324091,5.38905762273556,6.28992795944214,24,1,64,0,0,0.277252197265625,32.2580642700195,2,1,1,20.690845489502,0,20.7661771774292,,,,,,,,,,,,,,,,,,,,,,,,,,,,,,,,,
,3865844946.34526,4.89359450340271,49999.7109375,0.193254797053953,0.000121761225297513,1,2,12.9061126708984,4.9971842516717,46.4400015771389,252.154889689051,36.9133849235185,1000,-9.82337566493851E-5,,,,,,,,,,,,,,,,,,,,,4.68752288818359,5.09966611862183,49999.7109375,49999.7109375,50.1434235799572,5.39168489021841,4.00610685348511,26,1,0,0,1,0.278472900390625,31.7693061828613,6,1,1,4.68752288818359,0,4.89359450340271,,,,,,,,,,,,,,,,,,,,,,,,,,,,,,,,,
,3865845020.7705,2.25946748256683,49999.7109375,0.207208042869661,2.84106309118603E-5,1,2,12.9061126708984,4.99721392490799,46.4400015771389,270.363388442885,39.5765912515462,1000,-0.000107102309891805,,,,,,,,,,,,,,,,,,,,,2.25721788406372,2.26171708106995,49999.7109375,49999.7109375,50.3931538918515,5.39371827147055,2.7111554145813,26,1,0,0,1,0.287399291992187,31.7693061828613,6,1,1,2.25721788406372,0,2.25946748256683,,,,,,,,,,,,,,,,,,,,,,,,,,,,,,,,,
,3865845089.09706,2.19080674648285,49999.7109375,0.20749888450359,5.47069702342427E-5,1,2,12.9061126708984,4.99728654874443,46.4400015771389,270.745894630484,39.6499364984935,1000,-9.42325698844214E-5,,,,,,,,,,,,,,,,,,,,,2.18940615653992,2.19220733642578,49999.7109375,49999.7109375,50.4240282183611,5.39392932717489,2.65875601768494,26,1,0,0,1,0.286331176757813,30.7917900085449,2,1,1,2.19220733642578,0,2.19080674648285,,,,,,,,,,,,,,,,,,,,,,,,,,,,,,,,,
,3865845158.02274,2.21302103996277,49999.7109375,0.207432776917851,2.61318081265557E-5,1,2,12.9061126708984,4.99733083806719,46.4400015771389,270.664902875896,39.6248344894571,1000,-0.000104137226953732,,,,,,,,,,,,,,,,,,,,,2.21207857131958,2.21396350860596,49999.7109375,49999.7109375,50.389636563515,5.39378219308991,2.67283463478088,26,1,0,0,1,0.287322998046875,32.2580642700195,2,1,1,2.21207857131958,0,2.21302103996277,,,,,,,,,,,,,,,,,,,,,,,,,,,,,,,,,
,3865845230.41335,1.99549406766891,49999.7109375,0.208136971750369,2.91212609451182E-5,1,2,12.9061126708984,4.99732521315803,46.4400015771389,271.584685915301,39.7500635530751,1000,-0.000111562694639038,,,,,,,,,,,,,,,,,,,,,1.99450552463531,1.99648261070251,49999.7109375,49999.7109375,50.4412240457842,5.39309911306633,2.56210064888,26,1,0,0,1,0.279693603515625,31.2805480957031,6,1,1,1.99648261070251,0,1.99549406766891,,,,,,,,,,,,,,,,,,,,,,,,,,,,,,,,,
,3865845302.75512,1.999551653862,49999.7109375,0.208128556655797,1.41073868575842E-5,1,2,12.9061126708984,4.99738038103021,46.4400015771389,271.579451309551,39.7385589988885,1000,-0.000119615151346367,,,,,,,,,,,,,,,,,,,,,1.9995219707489,1.9995813369751,49999.7109375,49999.7109375,50.4947655993515,5.3932261052916,2.54012155532837,26,1,0,0,1,0.28594970703125,31.7693061828613,5,1,1,1.9995813369751,0,1.999551653862,,,,,,,,,,,,,,,,,,,,,,,,,,,,,,,,,
,3865845813.6063,32.0281753540039,26.2369422912598,0.000299000562285317,2.51728194208706E-8,1,5,12.9061126708984,4.97620494597901,46.4400015771389,0.387819635697034,0.0568583763146237,1,-8.79822061901177E-8,,,,,,,,,,,,,,,,,,,,,32.0281753540039,32.0281753540039,26.2369422912598,26.2369422912598,49.7619888625726,5.38828707004998,6.26296901702881,65,1,0,0,1,0.2880859375,31.7693061828613,2,1,1,32.0281753540039,0,32.0281753540039,,,,,,,,,,,,,,,,,,,,,,,,,,,,,,,,,
,3865846016.5816,64.0080642700195,26.2369422912598,0.000284704585287952,1.71726039935135E-8,1,5,12.9061126708984,4.97631884840714,46.4800000190735,0.369305769805637,0.0540266497255214,1,-1.72382519748353E-7,,,,,,,,,,,,,,,,,,,,,64.0080642700195,64.0080642700195,26.2369422912598,26.2369422912598,49.7580807199764,5.3880423984767,6.84905004501343,65,1,0,0,1,0.277328491210938,31.7693061828613,2,1,1,64.0080642700195,0,64.0080642700195,,,,,,,,,,,,,,,,,,,,,,,,,,,,,,,,,
,3865846215.02546,96.0211181640625,26.2369422912598,0.000272919494629399,1.89277804570809E-8,1,5,12.9061126708984,4.97627735962702,46.5300008654594,0.354021108971308,0.0517449183046311,1,-1.99740677217659E-7,,,,,,,,,,,,,,,,,,,,,96.0211181640625,96.0211181640625,26.2369422912598,26.2369422912598,49.7846560896303,5.38823979306146,7.07660102844238,64,1,64,0,0,0.288162231445313,31.2805480957031,2,1,1,96.0211181640625,0,96.0211181640625,,,,,,,,,,,,,,,,,,,,,,,,,,,,,,,,,
,3865846408.6971,128.022186279297,26.2369422912598,0.000256078043783863,2.61362134268968E-8,1,5,12.9061126708984,4.97623236764444,46.6100014746189,0.33217199852542,0.0485428648740793,1,-1.93841193799049E-7,,,,,,,,,,,,,,,,,,,,,128.022186279297,128.022186279297,26.2369422912598,26.2369422912598,49.7291604647649,5.38836034431898,7.20199489593506,64,1,64,0,0,0.287399291992187,31.7693061828613,2,1,1,128.022186279297,0,128.022186279297,,,,,,,,,,,,,,,,,,,,,,,,,,,,,,,,,
,3865846602.20694,160.050659179687,26.2369422912598,0.000245916416824368,2.71129719045874E-8,1,5,12.9061126708984,4.97620427576003,46.7099994421005,0.318991101332969,0.0465971326414879,1,-2.00872281271567E-7,,,,,,,,,,,,,,,,,,,,,160.050659179687,160.050659179687,26.2369422912598,26.2369422912598,49.7338502358803,5.38890681753908,7.28869295120239,64,1,64,0,0,0.287933349609375,32.2580642700195,2,1,1,160.050659179687,0,160.050659179687,,,,,,,,,,,,,,,,,,,,,,,,,,,,,,,,,
,3865846795.25714,192.142578125,26.2369422912598,0.000235932708778902,3.46736769933385E-8,1,5,12.9061126708984,4.98690115149453,46.8299984931946,0.306980595003135,0.0447398759181845,1,-2.70080427735338E-7,,,,,,,,,,,,,,,,,,,,,192.142578125,192.142578125,26.2369422912598,26.2369422912598,49.7096197517841,5.38860488964775,7.36084699630737,65,1,0,0,1,0.267105102539062,31.7693061828613,2,1,1,192.142578125,0,192.142578125,,,,,,,,,,,,,,,,,,,,,,,,,,,,,,,,,
,3865846987.46187,224.019409179687,26.2369422912598,0.000226461586018216,5.27434380095744E-8,1,5,12.9061126708984,4.9868963541968,46.9699986279011,0.294663701089834,0.0428980342207971,1,-2.94426356889044E-7,,,,,,,,,,,,,,,,,,,,,224.019409179687,224.019409179687,26.2369422912598,26.2369422912598,49.6681934402649,5.38831224823055,7.49271869659424,63,1,64,0,0,0.277023315429687,31.7693061828613,2,1,1,224.019409179687,0,224.019409179687,,,,,,,,,,,,,,,,,,,,,,,,,,,,,,,,,
,3865847179.74311,256.019653320313,26.2369422912598,0.000219049153015098,5.04079440338258E-8,1,5,12.9061126708984,4.9869511528791,47.12999984622,0.285020458201533,0.041513945320699,1,-2.69885502717772E-7,,,,,,,,,,,,,,,,,,,,,256.019653320313,256.019653320313,26.2369422912598,26.2369422912598,49.6549057554379,5.38891973066281,7.71370697021484,63,1,64,0,0,0.268096923828125,32.2580642700195,2,1,1,256.019653320313,0,256.019653320313,,,,,,,,,,,,,,,,,,,,,,,,,,,,,,,,,
,3865847373.52017,288.0185546875,26.2369422912598,0.000211199993516745,2.58398344590378E-8,1,5,12.9061126708984,4.98700642367282,47.3099984228611,0.274806740775201,0.0400603136211609,1,-2.34611144805946E-7,,,,,,,,,,,,,,,,,,,,,288.0185546875,288.0185546875,26.2369422912598,26.2369422912598,49.6369282994956,5.38830130406297,7.67323446273804,64,1,64,0,0,0.267868041992187,31.7693061828613,2,1,1,288.0185546875,0,288.0185546875,,,,,,,,,,,,,,,,,,,,,,,,,,,,,,,,,
,3865849029.16445,1.99993395805359,42893.228515625,0.198077634091,2.67410757332947E-5,1,2,12.9061126708984,4.97663466691581,46.4400015771389,256.935177621463,37.7616092986124,1000,1.13328744786267E-5,,,,,,,,,,,,,,,,,,,,,1.99982690811157,2.00004100799561,42783.47265625,43002.984375,50.2454261017169,5.39238996638446,2.63137984275818,26,1,0,0,1,0.276947021484375,31.2805480957031,1,6,1,1.99982690811157,0,1.99993395805359,,,,,,,,,,,,,,,,,,,,,,,,,,,,,,,,,
,3865849099.54626,1.99991196393967,35864.2890625,0.186026553376239,2.64664212304621E-5,1,2,12.9061126708984,4.97661527209577,46.4400015771389,241.302619091734,35.4588908905947,1000,6.7112844731526E-6,,,,,,,,,,,,,,,,,,,,,1.99983906745911,1.99998486042023,35774.515625,35954.0625,50.1066870395534,5.39177690763669,2.62825322151184,26,1,0,0,1,0.27679443359375,31.2805480957031,1,6,1,1.99998486042023,0,1.99991196393967,,,,,,,,,,,,,,,,,,,,,,,,,,,,,,,,,
,3865849168.12206,2.0000216960907,29015.48046875,0.171391072370818,3.72396516456629E-5,1,2,12.9061126708984,4.97668203530891,46.4400015771389,222.324705748176,32.6550447876268,1000,-5.19886366349171E-6,,,,,,,,,,,,,,,,,,,,,1.9998996257782,2.0001437664032,28935.62109375,29095.33984375,49.9433266790341,5.38957934964605,2.63058757781982,26,1,0,0,1,0.277175903320313,31.2805480957031,1,6,1,2.0001437664032,0,2.0000216960907,,,,,,,,,,,,,,,,,,,,,,,,,,,,,,,,,
,3865849238.50038,1.99993824958801,21992.185546875,0.151714590671729,3.88916451434853E-5,1,2,12.9061126708984,4.97659101774707,46.4400015771389,196.808020874205,28.8217947107636,1000,-6.90186350153409E-5,,,,,,,,,,,,,,,,,,,,,1.99987828731537,1.99999821186066,21897.08984375,22087.28125,49.9484072644091,5.38963582151817,2.628746509552,26,1,0,0,1,0.267257690429687,31.2805480957031,1,6,1,1.99999821186066,0,1.99993824958801,,,,,,,,,,,,,,,,,,,,,,,,,,,,,,,,,
,3865849311.03038,1.9998699426651,14748.984375,0.123345754494459,5.6485189135827E-5,1,2,12.9061126708984,4.97663130769769,46.4400015771389,160.000568529692,23.4905843205967,1000,-1.15092742107491E-5,,,,,,,,,,,,,,,,,,,,,1.99975955486298,1.99998033046722,14659.1796875,14838.7890625,49.8639913843322,5.38882455334693,2.63179206848145,26,1,0,0,1,0.267257690429687,32.2580642700195,1,6,1,1.99975955486298,0,1.9998699426651,,,,,,,,,,,,,,,,,,,,,,,,,,,,,,,,,
,3865849379.77595,1.99972206354141,7886.451171875,0.083344826469352,7.66877686772085E-5,1,2,12.9061126708984,4.97655284467755,46.4400015771389,108.116434063355,15.8292483817001,1000,-4.09320305821892E-5,,,,,,,,,,,,,,,,,,,,,1.99969601631165,1.99974811077118,7816.52783203125,7956.37451171875,49.7569082771976,5.38883498063156,2.62600827217102,26,1,0,0,1,0.287094116210938,32.2580642700195,1,6,1,1.99969601631165,0,1.99972206354141,,,,,,,,,,,,,,,,,,,,,,,,,,,,,,,,,
,3865849492.34406,1.99996829032898,-3367.66125488281,-0.0401549572205936,0.000116805484199541,1,2,12.9061126708984,4.97655678590942,46.4400015771389,-52.0823976251766,-7.67683987430858,100,-1.91418330174013E-5,,,,,,,,,,,,,,,,,,,,,1.99985647201538,2.00008010864258,-3457.6103515625,-3277.71215820313,49.7893458607457,5.38873144353897,2.62163043022156,26,1,0,0,1,0.277938842773438,31.2805480957031,1,6,1,2.00008010864258,0,1.99996829032898,,,,,,,,,,,,,,,,,,,,,,,,,,,,,,,,,
,3865849563.08803,2.00011521577835,-10436.5361328125,-0.0984922982727717,6.64482461556693E-5,1,2,12.9061126708984,4.97656470108764,46.4400015771389,-127.744282838897,-18.8570113847933,100,-6.79009185399236E-5,,,,,,,,,,,,,,,,,,,,,1.99997794628143,2.00025248527527,-10506.53515625,-10366.537109375,49.8084957594668,5.38893755872322,2.60894918441772,26,1,0,0,1,0.277252197265625,31.7693061828613,1,6,1,2.00025248527527,0,2.00011521577835,,,,,,,,,,,,,,,,,,,,,,,,,,,,,,,,,
,3865849664.63577,1.99981617927551,-20597.390625,-0.146099305310305,4.42018996126652E-5,1,2,12.9061126708984,4.97659601464393,46.4400015771389,-189.476048483742,-28.0814604279534,100,-0.000185153587223871,,,,,,,,,,,,,,,,,,,,,1.99981617927551,1.99981617927551,-20597.390625,-20597.390625,49.8979922249187,5.38925198018841,2.59613490104675,24,1,68,0,0,0.267105102539062,32.2580642700195,1,6,1,1.99981617927551,0,1.99981617927551,,,,,,,,,,,,,,,,,,,,,,,,,,,,,,,,,
,3865849740.1357,1.99997961521149,-28152.890625,-0.168863761289412,3.14924272223059E-5,1,2,12.9061126708984,4.97665662246542,46.4400015771389,-219.049091512662,-32.1438031560217,1000,2.7851293207511E-5,,,,,,,,,,,,,,,,,,,,,1.99986410140991,2.00009512901306,-28243.03515625,-28062.74609375,49.9886611331495,5.38998501717149,2.57725811004639,26,1,0,0,1,0.2862548828125,31.7693061828613,1,6,1,2.00009512901306,0,1.99997961521149,,,,,,,,,,,,,,,,,,,,,,,,,,,,,,,,,
,3865849808.89364,1.99998688697815,-35039.90625,-0.184119263866416,2.58668060129921E-5,1,2,12.9061126708984,4.97667826081765,46.4400015771389,-238.838278037391,-35.0590092427097,1000,2.1845951778897E-5,,,,,,,,,,,,,,,,,,,,,1.99987411499023,2.00009965896606,-35155.0703125,-34924.7421875,50.1109859964091,5.3904629545888,2.57051920890808,26,1,0,0,1,0.26885986328125,31.7693061828613,1,6,1,1.99987411499023,0,1.99998688697815,,,,,,,,,,,,,,,,,,,,,,,,,,,,,,,,,
,3865849881.25295,1.99984294176102,-42293.423828125,-0.196899319931195,3.46504578150668E-5,1,2,12.9061126708984,4.97669610471735,46.4400015771389,-255.404055952547,-37.5860561963424,1000,-4.85998136295311E-5,,,,,,,,,,,,,,,,,,,,,1.9998083114624,1.99987757205963,-42398.6328125,-42188.21484375,50.2383914450438,5.39158809617826,2.54385781288147,26,1,0,0,1,0.26885986328125,31.7693061828613,1,6,1,1.9998083114624,0,1.99984294176102,,,,,,,,,,,,,,,,,,,,,,,,,,,,,,,,,
,3865849951.64955,1.99982005357742,-49340.580078125,-0.207142071672143,2.77320053759157E-5,1,2,12.9061126708984,4.97674090080543,46.4400015771389,-268.711600321056,-39.419548334134,1000,4.3109765539685E-5,,,,,,,,,,,,,,,,,,,,,1.99965035915375,1.9999897480011,-49430.734375,-49250.42578125,50.3353133814284,5.39208635066601,2.52093648910522,26,1,0,0,1,0.27679443359375,31.7693061828613,1,6,1,1.99965035915375,0,1.99982005357742,,,,,,,,,,,,,,,,,,,,,,,,,,,,,,,,,
,3865850020.4753,1.99953919649124,-44477.650390625,-0.200401631194007,2.83262455199998E-5,1,2,12.9061126708984,4.97675920811882,46.4400015771389,-259.970691496121,-38.1256601249162,1000,5.0469179005154E-5,,,,,,,,,,,,,,,,,,,,,1.99952340126038,1.99955499172211,-44592.51953125,-44362.78125,50.3067839404765,5.39180729563978,2.50984144210815,26,1,0,0,1,0.266952514648438,31.7693061828613,5,6,1,1.99955499172211,0,1.99953919649124,,,,,,,,,,,,,,,,,,,,,,,,,,,,,,,,,
,3865850090.66985,2.00008988380432,-37471.12109375,-0.188849382263337,2.52497761187435E-5,1,2,12.9061126708984,4.9767123397218,46.4400015771389,-244.96784990015,-36.0190289424406,1000,-2.306774877238E-5,,,,,,,,,,,,,,,,,,,,,1.99975442886353,2.00042533874512,-37565.921875,-37376.3203125,50.1828958201784,5.39128992511099,2.50090718269348,26,1,0,0,1,0.267868041992187,32.2580642700195,1,6,1,2.00042533874512,0,2.00008988380432,,,,,,,,,,,,,,,,,,,,,,,,,,,,,,,,,
,3865850161.15887,2.00007617473602,-30433.9560546875,-0.174558904637932,3.23991344959854E-5,1,2,12.9061126708984,4.97671110195157,46.4400015771389,-226.43072958548,-33.2934531939476,1000,-2.13549648716812E-5,,,,,,,,,,,,,,,,,,,,,1.99975061416626,2.00040173530579,-30528.84375,-30339.068359375,50.0339955872649,5.39061303428711,2.50485801696777,26,1,0,0,1,0.276718139648438,31.2805480957031,1,6,1,2.00040173530579,0,2.00007617473602,,,,,,,,,,,,,,,,,,,,,,,,,,,,,,,,,
,3865850234.98848,1.99990427494049,-23067.384765625,-0.15479363872565,4.11724830871947E-5,1,2,12.9061126708984,4.97668412967493,46.4400015771389,-200.797201592499,-29.4777838057915,1000,1.62426202608275E-5,,,,,,,,,,,,,,,,,,,,,1.99983847141266,1.99997007846832,-23231.888671875,-22902.880859375,49.9867070618514,5.38971802973391,2.5006103515625,26,1,0,0,1,0.286026000976562,31.7693061828613,5,6,1,1.99983847141266,0,1.99990427494049,,,,,,,,,,,,,,,,,,,,,,,,,,,,,,,,,
,3865850306.40804,1.99956327676773,-15939.775390625,-0.128743588902288,5.1219606511017E-5,1,2,12.9061126708984,4.9766786892269,46.4400015771389,-167.000489337302,-24.5477090144995,1000,-1.01935440747135E-5,,,,,,,,,,,,,,,,,,,,,1.99910914897919,2.00001740455627,-16014.638671875,-15864.912109375,49.8616464987745,5.38911255963686,2.49610424041748,26,1,0,0,1,0.277252197265625,31.7693061828613,1,6,1,2.00001740455627,0,1.99956327676773,,,,,,,,,,,,,,,,,,,,,,,,,,,,,,,,,
,3865850376.80362,2.0000216960907,-8903.87548828125,-0.0902926205185711,8.46605570745279E-5,1,2,12.9061126708984,4.97656010373123,46.4400015771389,-117.126727510069,-17.1675777805485,1000,2.990005681385E-5,,,,,,,,,,,,,,,,,,,,,1.99963545799255,2.00040793418884,-9003.771484375,-8803.9794921875,49.7643337481303,5.38919482922567,2.50307583808899,26,1,0,0,1,0.27679443359375,31.2805480957031,1,6,1,2.00040793418884,0,2.0000216960907,,,,,,,,,,,,,,,,,,,,,,,,,,,,,,,,,
,3865850475.43411,2.00011646747589,948.973724365234,0.0105816275257879,0.000151518179911396,1,2,12.9061126708984,4.97662331978728,46.4400015771389,13.7242205137468,2.02836222791202,100,9.14912094937697E-6,,,,,,,,,,,,,,,,,,,,,1.99997353553772,2.00025939941406,859.112487792969,1038.8349609375,49.7451838494091,5.38860955921211,2.49934649467468,26,1,0,0,1,0.277175903320313,31.7693061828613,5,6,1,2.00025939941406,0,2.00011646747589,,,,,,,,,,,,,,,,,,,,,,,,,,,,,,,,,
,3865850556.33413,2.00004374980927,9038.23779296875,0.0894289626165172,7.58030252803076E-5,1,2,12.9061126708984,4.97665151051707,46.4400015771389,115.990353366256,17.1334311438583,100,7.03146083206043E-5,,,,,,,,,,,,,,,,,,,,,2.00001788139343,2.0000696182251,8978.2490234375,9098.2265625,49.7834836468514,5.38889359617824,2.49713158607483,26,1,0,0,1,0.276718139648438,30.7917900085449,1,6,1,2.0000696182251,0,2.00004374980927,,,,,,,,,,,,,,,,,,,,,,,,,,,,,,,,,
,3865850637.05658,2.00007939338684,17114.39453125,0.133134768489087,4.8903113749241E-5,1,2,12.9061126708984,4.97668427431185,46.4400015771389,172.682119667206,25.4849883030666,100,8.76066914043893E-5,,,,,,,,,,,,,,,,,,,,,2.00003266334534,2.00012612342834,17009.458984375,17219.330078125,49.8663362698899,5.38996945484937,2.47556710243225,26,1,0,0,1,0.28656005859375,31.7693061828613,1,6,1,2.00012612342834,0,2.00007939338684,,,,,,,,,,,,,,,,,,,,,,,,,,,,,,,,,
,3865850727.43869,2.00013136863709,26152.181640625,0.163791817137441,3.33036446860252E-5,1,2,12.9061126708984,4.97671150860484,46.4400015771389,212.469245104634,31.2050080578108,1000,-6.83001409649377E-6,,,,,,,,,,,,,,,,,,,,,2.00005865097046,2.00020408630371,26041.8359375,26262.52734375,49.9616949492361,5.39042890382563,2.46771812438965,26,1,0,0,1,0.27679443359375,32.2580642700195,1,6,1,2.00020408630371,0,2.00013136863709,,,,,,,,,,,,,,,,,,,,,,,,,,,,,,,,,
,3865850795.7433,1.99998331069946,33000.783203125,0.180201451138097,3.05240501666677E-5,1,2,12.9061126708984,4.97670182464452,46.4400015771389,233.758520546921,34.3074713136556,1000,-2.58195576564004E-5,,,,,,,,,,,,,,,,,,,,,1.99939656257629,2.00057005882263,32905.22265625,33096.34375,50.0535363002457,5.39111731601154,2.4608256816864,26,1,0,0,1,0.267257690429687,31.2805480957031,1,6,1,1.99939656257629,0,1.99998331069946,,,,,,,,,,,,,,,,,,,,,,,,,,,,,,,,,
,3865850864.27523,1.99957829713821,39865.138671875,0.193065960633077,2.66672269777694E-5,1,2,12.9061126708984,4.97671721782682,46.4400015771389,250.445620194518,36.7698796203339,1000,-1.76012433954528E-5,,,,,,,,,,,,,,,,,,,,,1.99937927722931,1.99977731704712,39769.82421875,39960.453125,50.218850732063,5.39188497374003,2.45227527618408,26,1,0,0,1,0.2764892578125,33.2355842590332,6,6,1,1.99937927722931,0,1.99957829713821,,,,,,,,,,,,,,,,,,,,,,,,,,,,,,,,,
,3865850934.75584,2.00165867805481,46929.37109375,0.203901826614927,3.1722506626683E-5,1,2,12.9061126708984,4.97672477959874,46.4400015771389,264.495562077033,38.8808814775617,1000,1.77987797780637E-5,,,,,,,,,,,,,,,,,,,,,2.00079369544983,2.00252366065979,46834.21875,47024.5234375,50.3939355203707,5.39233994184123,2.46177625656128,26,1,0,0,1,0.267486572265625,31.7693061828613,1,6,1,2.00252366065979,0,2.00165867805481,,,,,,,,,,,,,,,,,,,,,,,,,,,,,,,,,
,3865851428.61837,18.9642143249512,26.4375095367432,0.000289077452438951,3.69454300584795E-8,1,5,12.9061126708984,4.97659125230004,46.4400015771389,0.374957948745344,0.0551941152235265,1,8.20188602659899E-8,,,,,,,,,,,,,,,,,,,,,18.9642143249512,18.9642143249512,26.4375095367432,26.4375095367432,49.7784030614764,5.3877938160405,5.70964431762695,65,1,0,0,1,0.266952514648438,31.7693061828613,2,1,1,18.9642143249512,0,18.9642143249512,,,,,,,,,,,,,,,,,,,,,,,,,,,,,,,,,
,3865851626.54894,50.0463066101074,26.4375095367432,0.000271835115468622,1.3576799435737E-8,1,5,12.9061126708984,4.97654765308818,46.459998935461,0.352626137984064,0.051647418535235,1,-1.18648321039965E-7,,,,,,,,,,,,,,,,,,,,,50.0463066101074,50.0463066101074,26.4375095367432,26.4375095367432,49.7612072340533,5.38820130825529,6.6401309967041,65,1,0,0,1,0.27618408203125,31.7693061828613,2,1,1,50.0463066101074,0,50.0463066101074,,,,,,,,,,,,,,,,,,,,,,,,,,,,,,,,,
,3865851827.77454,82.107536315918,26.4375095367432,0.000262343557351832,1.99675995151335E-8,1,5,12.9061126708984,4.97660422275801,46.509999781847,0.340324818873449,0.0498057630644947,1,-1.44648944910021E-7,,,,,,,,,,,,,,,,,,,,,82.107536315918,82.107536315918,26.4375095367432,26.4375095367432,49.7385400069956,5.38738925814902,6.97049188613892,65,1,0,0,1,0.287399291992187,30.7917900085449,2,1,1,82.107536315918,0,82.107536315918,,,,,,,,,,,,,,,,,,,,,,,,,,,,,,,,,
,3865852022.21618,114.027610778809,26.4375095367432,0.000248724750350555,2.8666306251855E-8,1,5,12.9061126708984,4.97650190612073,46.5800017118454,0.322645852721043,0.0472369432633,1,-1.23210280516714E-7,,,,,,,,,,,,,,,,,,,,,114.027610778809,114.027610778809,26.4375095367432,26.4375095367432,49.7389308212553,5.3885804669633,7.13006830215454,63,1,64,0,0,0.279159545898438,31.7693061828613,2,1,1,114.027610778809,0,114.027610778809,,,,,,,,,,,,,,,,,,,,,,,,,,,,,,,,,
,3865852215.12483,146.000076293945,26.4375095367432,0.000237034765365355,1.46387769225732E-8,1,5,12.9061126708984,4.97648284765517,46.6599985957146,0.307483377904133,0.0449931945073966,1,-1.354479220043E-7,,,,,,,,,,,,,,,,,,,,,146.000076293945,146.000076293945,26.4375095367432,26.4375095367432,49.7225166223514,5.38847571341776,7.22641038894653,64,1,64,0,0,0.266876220703125,32.2580642700195,2,1,1,146.000076293945,0,146.000076293945,,,,,,,,,,,,,,,,,,,,,,,,,,,,,,,,,
,3865852408.66933,178.010635375977,26.4375095367432,0.000228964745993422,1.6123124370879E-8,1,5,12.9061126708984,4.97643386558604,46.7699989676476,0.29701631829039,0.0434230117268497,1,-1.59944313308718E-7,,,,,,,,,,,,,,,,,,,,,178.010635375977,178.010635375977,26.4375095367432,26.4375095367432,49.6986769525149,5.38892766797981,7.2913031578064,64,1,64,0,0,0.276947021484375,33.2355842590332,2,1,1,178.010635375977,0,178.010635375977,,,,,,,,,,,,,,,,,,,,,,,,,,,,,,,,,
,3865852601.66378,210.090805053711,26.4375095367432,0.00022096732742254,1.49923480905148E-8,1,5,12.9061126708984,4.97642518050764,46.900000423193,0.286643825904527,0.0418886669722371,1,-1.67877875201549E-7,,,,,,,,,,,,,,,,,,,,,210.090805053711,210.090805053711,26.4375095367432,26.4375095367432,49.6998493952937,5.38891986827735,7.39693450927734,64,1,64,0,0,0.269012451171875,31.2805480957031,2,1,1,210.090805053711,0,210.090805053711,,,,,,,,,,,,,,,,,,,,,,,,,,,,,,,,,
,3865852794.15903,242.01383972168,26.4375095367432,0.000214603882643405,1.73677960509374E-8,1,5,12.9061126708984,4.97637585950639,47.0600016415119,0.27837842129526,0.0407275119592678,1,-1.27788683910352E-7,,,,,,,,,,,,,,,,,,,,,242.01383972168,242.01383972168,26.4375095367432,26.4375095367432,49.717826851236,5.38915506877503,7.61169195175171,64,1,64,0,0,0.277633666992187,32.2580642700195,2,1,1,242.01383972168,0,242.01383972168,,,,,,,,,,,,,,,,,,,,,,,,,,,,,,,,,
,3865852987.79953,274.071746826172,26.4375095367432,0.000208451593970648,2.48289452371677E-8,1,5,12.9061126708984,4.97632140088477,47.240000218153,0.27039837931723,0.039527290013836,1,-1.48821349519565E-7,,,,,,,,,,,,,,,,,,,,,274.071746826172,274.071746826172,26.4375095367432,26.4375095367432,49.6423996991303,5.38999073466599,7.85884618759155,65,1,0,0,1,0.267105102539062,32.2580642700195,2,1,1,274.071746826172,0,274.071746826172,,,,,,,,,,,,,,,,,,,,,,,,,,,,,,,,,
,3865853785.45552,295.996215820313,26.424976348877,0.000240260842980176,2.00938785493716E-8,1,5,12.9061126708984,4.97615832887107,47.350000590086,0.311642368650072,0.0455830461090482,1,-1.51422709906563E-7,,,,,,,,,,,,,,,,,,,,,295.996215820313,295.996215820313,26.424976348877,26.424976348877,49.5982376877937,5.39083965296086,8.30403137207031,63,1,64,0,0,0.27862548828125,31.2805480957031,2,1,1,295.996215820313,0,295.996215820313,,,,,,,,,,,,,,,,,,,,,,,,,,,,,,,,,
,3865853965.84215,263.985717773438,26.424976348877,0.000239823685418293,2.14622019323837E-8,1,5,12.9061126708984,4.97619507799003,47.2000017762184,0.31108141125996,0.0454811984249867,1,-1.66090646585939E-7,,,,,,,,,,,,,,,,,,,,,263.985717773438,263.985717773438,26.424976348877,26.424976348877,49.7068840519668,5.39064841474764,8.08984279632568,63,1,64,0,0,0.287551879882813,31.7693061828613,2,1,1,263.985717773438,0,263.985717773438,,,,,,,,,,,,,,,,,,,,,,,,,,,,,,,,,
,3865854158.61798,231.968338012695,26.424976348877,0.000238267247086082,1.8557337553067E-8,1,5,12.9061126708984,4.97598351412634,47.0600016415119,0.309054859589774,0.0451095911712522,1,-2.2186647174331E-7,,,,,,,,,,,,,,,,,,,,,231.968338012695,231.968338012695,26.424976348877,26.424976348877,49.6697566973033,5.39048948612218,7.95477342605591,63,1,64,0,0,0.287551879882813,33.2355842590332,2,1,1,231.968338012695,0,231.968338012695,,,,,,,,,,,,,,,,,,,,,,,,,,,,,,,,,
,3865854350.08759,199.998992919922,26.424976348877,0.000235928333770563,1.57635656596518E-8,1,5,12.9061126708984,4.97575987101935,46.9399988651276,0.305995924111977,0.0447033902566315,1,-1.89279771261254E-7,,,,,,,,,,,,,,,,,,,,,199.998992919922,199.998992919922,26.424976348877,26.424976348877,49.6631128548899,5.39131123505032,7.85482549667358,63,1,64,0,0,0.28839111328125,31.7693061828613,2,1,1,199.998992919922,0,199.998992919922,,,,,,,,,,,,,,,,,,,,,,,,,,,,,,,,,
,3865854542.08365,167.860702514648,26.424976348877,0.0002325528182724,1.26746852948313E-8,1,5,12.9061126708984,4.9755544127674,46.8299984931946,0.3015992341605,0.0440691776550173,1,-1.80451866265295E-7,,,,,,,,,,,,,,,,,,,,,167.860702514648,167.860702514648,26.424976348877,26.424976348877,49.7326777931014,5.39218947470995,7.75864028930664,65,1,0,0,1,0.268478393554687,32.7468223571777,2,1,1,167.860702514648,0,167.860702514648,,,,,,,,,,,,,,,,,,,,,,,,,,,,,,,,,
,3865854734.23709,135.983764648438,26.424976348877,0.000227858797422145,2.25628868245772E-8,1,5,12.9061126708984,4.97526618376698,46.739999204874,0.295484187878071,0.0431982615614423,1,-1.59743050851289E-7,,,,,,,,,,,,,,,,,,,,,135.983764648438,135.983764648438,26.424976348877,26.424976348877,49.6654577404476,5.39395479946936,7.67817163467407,65,1,0,0,1,0.27923583984375,31.2805480957031,2,1,1,135.983764648438,0,135.983764648438,,,,,,,,,,,,,,,,,,,,,,,,,,,,,,,,,
,3865854926.54037,103.774520874023,26.424976348877,0.000221592016102039,1.69918435409273E-8,1,5,12.9061126708984,4.97537960681733,46.6400012373924,0.287377599223594,0.0419375467101527,1,-2.1240585669251E-7,,,,,,,,,,,,,,,,,,,,,103.774520874023,103.774520874023,26.424976348877,26.424976348877,49.781920389813,5.39260011030836,7.56443691253662,65,1,0,0,1,0.279083251953125,31.7693061828613,2,1,1,103.774520874023,0,103.774520874023,,,,,,,,,,,,,,,,,,,,,,,,,,,,,,,,,
,3865855115.70342,71.9920120239258,26.424976348877,0.000218317178388221,1.75031319002338E-8,1,5,12.9061126708984,4.97588950303971,46.560000628233,0.283166319752179,0.041358094050825,1,-1.82764502688651E-7,,,,,,,,,,,,,,,,,,,,,71.9920120239258,71.9920120239258,26.424976348877,26.424976348877,49.7627704910918,5.3904144620042,7.41650390625,64,1,64,0,0,0.279464721679687,31.7693061828613,2,1,1,71.9920120239258,0,71.9920120239258,,,,,,,,,,,,,,,,,,,,,,,,,,,,,,,,,
,3865855303.35056,39.9612579345703,26.424976348877,0.000216020201182602,1.59264437273628E-8,1,5,12.9061126708984,4.97621811768139,46.5000011026859,0.280206471007182,0.0409717617486555,1,-1.46142177335181E-7,,,,,,,,,,,,,,,,,,,,,39.9612579345703,39.9612579345703,26.424976348877,26.424976348877,49.7061024234476,5.38855022047724,7.09092950820923,63,1,64,0,0,0.279617309570313,32.2580642700195,2,1,1,39.9612579345703,0,39.9612579345703,,,,,,,,,,,,,,,,,,,,,,,,,,,,,,,,,
,3865855514.87168,7.99651145935059,26.424976348877,0.000215323357807126,1.3244009628219E-8,1,5,12.9061126708984,4.97644516838716,46.459998935461,0.279306619491348,0.0409367285597508,1,-7.28052576808425E-8,,,,,,,,,,,,,,,,,,,,,7.99651145935059,7.99651145935059,26.424976348877,26.424976348877,49.7619888625726,5.38837808422304,4.96543741226196,65,1,0,0,1,0.2764892578125,31.7693061828613,6,1,1,7.99651145935059,0,7.99651145935059,,,,,,,,,,,,,,,,,,,,,,,,,,,,,,,,,
,3865856002.40841,26.0913391113281,26.424976348877,0.000215208038836486,2.01438645301812E-8,1,5,12.9061126708984,4.97650831241147,46.4500002563,0.279160724682986,0.0409243321131729,1,-6.59840396808323E-8,,,,,,,,,,,,,,,,,,,,,26.0913391113281,26.0913391113281,26.424976348877,26.424976348877,49.7522185060822,5.38778392932067,6.14105463027954,65,1,0,0,1,0.277175903320313,31.7693061828613,2,1,1,26.0913391113281,0,26.0913391113281,,,,,,,,,,,,,,,,,,,,,,,,,,,,,,,,,
,3865856206.17304,58.0069999694824,26.424976348877,0.000216674445903027,1.43063053541904E-8,1,5,12.9061126708984,4.97648346452727,46.4700013399124,0.281077942479527,0.0410870605665087,1,-1.55737990735587E-7,,,,,,,,,,,,,,,,,,,,,58.0069999694824,58.0069999694824,26.424976348877,26.424976348877,49.710792194563,5.38814177061148,6.80645084381103,65,1,0,0,1,0.287094116210938,31.7693061828613,2,1,1,58.0069999694824,0,58.0069999694824,,,,,,,,,,,,,,,,,,,,,,,,,,,,,,,,,
,3865856406.10316,90.0258331298828,26.424976348877,0.000218063641864688,7.97238032770772E-8,1,5,12.9061126708984,4.97644021683695,46.5199984610081,0.282875831406376,0.041355207594557,1,-1.52708032744678E-7,,,,,,,,,,,,,,,,,,,,,90.0258331298828,90.0258331298828,26.424976348877,26.424976348877,49.7909091177841,5.38882599131296,7.07782649993896,64,1,64,0,0,0.277557373046875,31.2805480957031,2,1,1,90.0258331298828,0,90.0258331298828,,,,,,,,,,,,,,,,,,,,,,,,,,,,,,,,,
,3865856600.67199,122.152610778809,26.424976348877,0.000220275161521195,2.42894473444086E-8,1,5,12.9061126708984,4.97642455283312,46.5900003910065,0.285744585809248,0.0417662682979111,1,-1.60550346855996E-7,,,,,,,,,,,,,,,,,,,,,122.152610778809,122.152610778809,26.424976348877,26.424976348877,49.6779637967553,5.38925244864889,7.20533847808838,65,1,0,0,1,0.287017822265625,31.7693061828613,2,1,1,122.152610778809,0,122.152610778809,,,,,,,,,,,,,,,,,,,,,,,,,,,,,,,,,
,3865856793.11913,154.019454956055,26.424976348877,0.000222145951650891,1.07275603975573E-8,1,5,12.9061126708984,4.97634577690881,46.6899983584881,0.288166289310899,0.0421111890243259,1,-1.68745386921751E-7,,,,,,,,,,,,,,,,,,,,,154.019454956055,154.019454956055,26.424976348877,26.424976348877,49.738149192736,5.38910778302403,7.29692602157593,65,1,0,0,1,0.267181396484375,31.2805480957031,2,1,1,154.019454956055,0,154.019454956055,,,,,,,,,,,,,,,,,,,,,,,,,,,,,,,,,
,3865856986.6058,186.071182250977,26.424976348877,0.000222853447495465,1.40222524710873E-8,1,5,12.9061126708984,4.97629685628087,46.8100011348724,0.289078995027816,0.0422519014740108,1,-1.63747070538478E-7,,,,,,,,,,,,,,,,,,,,,186.071182250977,186.071182250977,26.424976348877,26.424976348877,49.717826851236,5.38909956926412,7.36973381042481,65,1,0,0,1,0.278854370117187,32.2580642700195,2,1,1,186.071182250977,0,186.071182250977,,,,,,,,,,,,,,,,,,,,,,,,,,,,,,,,,
,3865857179.19664,218.006652832031,26.424976348877,0.000222743247861905,1.2483061521816E-8,1,5,12.9061126708984,4.97636791476294,46.9399988651276,0.288941804304717,0.0422321831860898,1,-1.63414335495273E-7,,,,,,,,,,,,,,,,,,,,,218.006652832031,218.006652832031,26.424976348877,26.424976348877,49.7147003371591,5.38871151119364,7.46178293228149,64,1,64,0,0,0.288009643554687,32.2580642700195,2,1,1,218.006652832031,0,218.006652832031,,,,,,,,,,,,,,,,,,,,,,,,,,,,,,,,,
,3865857372.16615,250.112594604492,26.424976348877,0.000223249816923485,1.8273073072931E-8,1,5,12.9061126708984,4.97625898261755,47.1000000834465,0.289593096887385,0.0423058773546371,1,-1.80013840170847E-7,,,,,,,,,,,,,,,,,,,,,250.112594604492,250.112594604492,26.424976348877,26.424976348877,49.6724923971206,5.38950432515223,7.6505880355835,64,1,64,0,0,0.287399291992187,31.7693061828613,2,1,1,250.112594604492,0,250.112594604492,,,,,,,,,,,,,,,,,,,,,,,,,,,,,,,,,
,3865857564.40529,282.025482177734,26.424976348877,0.000222643779126556,6.28430771780364E-8,1,5,12.9061126708984,4.98699200900779,47.2799986600876,0.289705650875638,0.0421641238905091,1,-2.98570672044158E-7,,,,,,,,,,,,,,,,,,,,,282.025482177734,282.025482177734,26.424976348877,26.424976348877,49.6287212000437,5.38817901287435,7.7217116355896,64,1,64,0,0,0.266799926757813,31.7693061828613,2,1,1,282.025482177734,0,282.025482177734,,,,,,,,,,,,,,,,,,,,,,,,,,,,,,,,,
,3865857891.71756,300.005310058594,45489.40234375,0.00686591367197593,2.12039174382362E-6,1,2,12.9061126708984,4.98698281129038,47.3800003528595,8.93924283892834,1.26424473235716,100,-3.68901448967279E-5,,,,,,,,,,,,,,,,,,,,,300.005126953125,300.005493164063,45399.421875,45579.3828125,49.6279395715245,5.38915883664618,7.69411516189575,26,1,0,0,1,0.2667236328125,31.7693061828613,1,6,1,300.005493164063,0,300.005310058594,,,,,,,,,,,,,,,,,,,,,,,,,,,,,,,,,
,3865857960.39708,300.004150390625,38626.025390625,0.00592233799259322,2.59421735949514E-6,1,2,12.9061126708984,4.98696159011129,47.3800003528595,7.70923734000585,1.10035188575845,100,-2.42431040211585E-5,,,,,,,,,,,,,,,,,,,,,300.003936767578,300.004364013672,38511.16796875,38740.8828125,49.6674118117456,5.38914091039288,7.73242855072022,25,1,68,0,0,0.26885986328125,32.2580642700195,1,6,1,300.003936767578,0,300.004150390625,,,,,,,,,,,,,,,,,,,,,,,,,,,,,,,,,
,3865858029.06015,300.004302978516,31771.68359375,0.00498265080899146,1.89375614438322E-6,1,2,12.9061126708984,4.98698792468941,47.3800003528595,6.48531561793672,0.930930021043616,100,-1.64284573908492E-5,,,,,,,,,,,,,,,,,,,,,300.004241943359,300.004364013672,31721.79296875,31821.57421875,49.6259855002264,5.38931493729702,7.80098533630371,26,1,0,0,1,0.268173217773438,31.7693061828613,1,6,1,300.004364013672,0,300.004302978516,,,,,,,,,,,,,,,,,,,,,,,,,,,,,,,,,
,3865858097.2502,300.002426147461,24967.958984375,0.00404183996152156,2.19657244378237E-6,1,2,12.9061126708984,4.98706308531273,47.3800003528595,5.26077813577432,0.75591086252017,100,-1.27572257299842E-5,,,,,,,,,,,,,,,,,,,,,300.002349853516,300.002502441406,24883.150390625,25052.767578125,49.6431813276495,5.3893689766634,7.90262699127197,26,1,0,0,1,0.266952514648438,33.7243423461914,1,6,1,300.002502441406,0,300.002426147461,,,,,,,,,,,,,,,,,,,,,,,,,,,,,,,,,
,3865858167.67022,300.001663208008,17934.203125,0.00306364610898477,2.06536728456064E-6,1,2,12.9061126708984,4.98700363906086,47.3800003528595,3.98817853071395,0.568433437691105,100,-1.31476517755524E-5,,,,,,,,,,,,,,,,,,,,,300.001647949219,300.001678466797,17844.216796875,18024.189453125,49.6533424983995,5.38977045085737,8.03315162658691,26,1,0,0,1,0.268020629882813,32.2580642700195,1,6,1,300.001647949219,0,300.001663208008,,,,,,,,,,,,,,,,,,,,,,,,,,,,,,,,,
,3865858238.33479,300.002380371094,10874.5478515625,0.00207461446208719,1.65963120298082E-6,1,2,12.9061126708984,4.98694877278955,47.3800003528595,2.70106281234916,0.382042657967627,100,-1.11158083810408E-5,,,,,,,,,,,,,,,,,,,,,300.002258300781,300.002502441406,10794.626953125,10954.46875,49.6943779956591,5.39002974426898,8.18686389923096,26,1,0,0,1,0.268173217773438,31.7693061828613,1,6,1,300.002502441406,0,300.002380371094,,,,,,,,,,,,,,,,,,,,,,,,,,,,,,,,,
,3865858308.72279,300.000442504883,3844.99060058594,0.00104353739331888,1.83564117314935E-6,1,2,12.9061126708984,4.98692734478974,47.3800003528595,1.36046372461434,0.179717059640597,100,-1.51616926520082E-5,,,,,,,,,,,,,,,,,,,,,300.000396728516,300.00048828125,3750.09008789063,3939.89111328125,49.6803086823129,5.39027824409282,8.36623287200928,26,1,0,0,1,0.267105102539062,30.7917900085449,1,6,1,300.00048828125,0,300.000442504883,,,,,,,,,,,,,,,,,,,,,,,,,,,,,,,,,
,3865858391.40207,300.000885009766,-4421.6328125,-0.000904274335573229,3.06465486902642E-6,1,2,12.9061126708984,4.98683493028879,47.3800003528595,-1.17504226728436,-0.181819852646122,100,-6.91759302101156E-6,,,,,,,,,,,,,,,,,,,,,300.000762939453,300.001007080078,-4526.54296875,-4316.72265625,49.6939871813995,5.39016450518272,8.40240001678467,26,1,0,0,1,0.26763916015625,31.7693061828613,1,6,1,300.001007080078,0,300.000885009766,,,,,,,,,,,,,,,,,,,,,,,,,,,,,,,,,
,3865858466.03357,300.000579833984,-11881.60546875,-0.00215030850956217,2.07860693653979E-6,1,2,12.9061126708984,4.98681994334117,47.3800003528595,-2.79788498809212,-0.407040887360621,10,3.00915451237287E-6,,,,,,,,,,,,,,,,,,,,,300.000518798828,300.000640869141,-11996.462890625,-11766.748046875,49.6810903108322,5.39020585936813,8.33174991607666,26,1,0,0,1,0.2691650390625,31.7693061828613,1,6,1,300.000518798828,0,300.000579833984,,,,,,,,,,,,,,,,,,,,,,,,,,,,,,,,,
,3865858570.58476,300.001068115234,-22342.0224609375,-0.00365507675359307,1.96960977645681E-6,1,2,12.9061126708984,4.98683115165931,47.3800003528595,-4.75647421686816,-0.687549137221121,100,8.449422134968E-6,,,,,,,,,,,,,,,,,,,,,300.000946044922,300.001190185547,-22437.0234375,-22247.021484375,49.6795270537937,5.3902876020453,8.27721214294434,26,1,0,0,1,0.269622802734375,32.2580642700195,1,6,1,300.001190185547,0,300.001068115234,,,,,,,,,,,,,,,,,,,,,,,,,,,,,,,,,
,3865858643.42138,300.00114440918,-29629.435546875,-0.004666785618965,2.26387956636886E-6,1,2,12.9061126708984,4.98677116708015,47.3800003528595,-6.07313641646994,-0.876524103927461,100,1.18034478962358E-5,,,,,,,,,,,,,,,,,,,,,300.000793457031,300.001495361328,-29694.490234375,-29564.380859375,49.6119161868802,5.39015693263011,8.25214576721191,26,1,0,0,1,0.268707275390625,31.7693061828613,1,6,1,300.000793457031,0,300.00114440918,,,,,,,,,,,,,,,,,,,,,,,,,,,,,,,,,
,3865858713.81915,300.000946044922,-36682.044921875,-0.00563773029045252,2.05975816228076E-6,1,2,12.9061126708984,4.98676446389436,47.3800003528595,-7.33575617826719,-1.06506967698765,100,9.5062308311543E-6,,,,,,,,,,,,,,,,,,,,,300.000823974609,300.001068115234,-36797.50390625,-36566.5859375,49.6201232863322,5.38969059882337,8.23441791534424,26,1,0,0,1,0.269012451171875,32.2580642700195,1,6,1,300.001068115234,0,300.000946044922,,,,,,,,,,,,,,,,,,,,,,,,,,,,,,,,,
,3865858782.11246,299.999984741211,-43524.560546875,-0.00657754603322437,2.08521634745033E-6,1,2,12.9061126708984,4.98678254558631,47.3800003528595,-8.55836520796848,-1.24475511198235,100,9.45292341073319E-6,,,,,,,,,,,,,,,,,,,,,299.999908447266,300.000061035156,-43619.7734375,-43429.34765625,49.5458685770052,5.38967615739855,8.22346210479736,26,1,0,0,1,0.268020629882813,31.2805480957031,1,6,1,299.999908447266,0,299.999984741211,,,,,,,,,,,,,,,,,,,,,,,,,,,,,,,,,
,3865858862.9401,300.001419067383,-48913.404296875,-0.00734241042917194,2.02012070764094E-6,1,2,12.9061126708984,4.98675574801461,47.3800003528595,-9.56176578867,-1.33319469356966,100,5.38274059863856E-5,,,,,,,,,,,,,,,,,,,,,300.001159667969,300.001678466797,-48983.23828125,-48843.5703125,49.5540756764572,5.38967906667887,8.21499443054199,24,1,68,0,0,0.267715454101562,31.7693061828613,1,6,1,300.001678466797,0,300.001419067383,,,,,,,,,,,,,,,,,,,,,,,,,,,,,,,,,
,3865858933.31387,299.999633789063,-41892.59765625,-0.00636827794392568,2.19366479064119E-6,1,2,12.9061126708984,4.98675201952758,47.3800003528595,-8.28997238442505,-1.17813745296865,100,2.99112885938895E-5,,,,,,,,,,,,,,,,,,,,,299.999389648438,299.999877929687,-41997.39453125,-41787.80078125,49.6142610724379,5.38951664271987,8.19176292419434,26,1,0,0,1,0.269241333007813,32.7468223571777,1,6,1,299.999877929687,0,299.999633789063,,,,,,,,,,,,,,,,,,,,,,,,,,,,,,,,,
,3865859003.69924,300.000076293945,-34865.265625,-0.00540065344246442,2.4643081615758E-6,1,2,12.9061126708984,4.98673872495389,47.3800003528595,-7.02998858287358,-1.00145138028931,100,2.35759872895433E-5,,,,,,,,,,,,,,,,,,,,,300.000030517578,300.000122070313,-34960.12890625,-34770.40234375,49.6064447872456,5.38970577422197,8.18425941467285,26,1,0,0,1,0.270233154296875,32.2580642700195,1,6,1,300.000030517578,0,300.000076293945,,,,,,,,,,,,,,,,,,,,,,,,,,,,,,,,,
,3865859074.44477,299.998962402344,-27803.8173828125,-0.00443281563618811,1.88557965826382E-6,1,2,12.9061126708984,4.98676869469399,47.3800003528595,-5.76971448756415,-0.825365824456964,100,1.67564626570147E-5,,,,,,,,,,,,,,,,,,,,,299.998840332031,299.999084472656,-27873.66015625,-27733.974609375,49.6193416578129,5.38997251153582,8.1748046875,26,1,0,0,1,0.269088745117187,30.7917900085449,1,6,1,299.998840332031,0,299.998962402344,,,,,,,,,,,,,,,,,,,,,,,,,,,,,,,,,
,3865859147.07665,300.000427246094,-20551.2841796875,-0.00342974754326216,1.97363082701209E-6,1,2,12.9061126708984,4.9867609034223,47.3800003528595,-4.46404541316343,-0.639105972773963,100,1.25748021821022E-5,,,,,,,,,,,,,,,,,,,,,300.000091552734,300.000762939453,-20666.009765625,-20436.55859375,49.6369282994956,5.3902485406509,8.17481517791748,26,1,0,0,1,0.268325805664062,32.2580642700195,1,6,1,300.000762939453,0,300.000427246094,,,,,,,,,,,,,,,,,,,,,,,,,,,,,,,,,
,3865859219.43027,300.000061035156,-13329.6318359375,-0.00241791623087603,1.69282482730936E-6,1,2,12.9061126708984,4.9867441491481,47.3800003528595,-3.14749514158466,-0.447626276340374,100,1.11180893413715E-5,,,,,,,,,,,,,,,,,,,,,299.999450683594,300.000671386719,-13439.619140625,-13219.64453125,49.6310660856014,5.39030797680505,8.16020202636719,26,1,0,0,1,0.26885986328125,31.7693061828613,1,6,1,300.000671386719,0,300.000061035156,,,,,,,,,,,,,,,,,,,,,,,,,,,,,,,,,
,3865859289.77752,300.001480102539,-6300.66430664062,-0.00140941876924928,1.72178089101763E-6,1,2,12.9061126708984,4.98677907516703,47.3800003528595,-1.83568194046559,-0.254331389677321,100,1.15507734510567E-5,,,,,,,,,,,,,,,,,,,,,300.001312255859,300.001647949219,-6395.50830078125,-6205.8203125,49.6783546110149,5.39053666309155,8.15602588653564,26,1,0,0,1,0.268020629882813,31.7693061828613,1,6,1,300.001312255859,0,300.001480102539,,,,,,,,,,,,,,,,,,,,,,,,,,,,,,,,,
,3865859361.67406,300.000366210937,884.365447998047,0.00010357029532194,4.48143708109145E-6,1,2,12.9061126708984,4.98677702721721,47.3800003528595,0.131931289145163,0.038855490442239,100,1.46531934842052E-5,,,,,,,,,,,,,,,,,,,,,300.000030517578,300.000701904297,729.532409667969,1039.19848632812,49.6853892676879,5.39075384349113,8.15343475341797,26,1,0,0,1,0.268402099609375,32.2580642700195,1,6,1,300.000030517578,0,300.000366210937,,,,,,,,,,,,,,,,,,,,,,,,,,,,,,,,,
,3865859436.85065,300.000778198242,8398.353515625,0.00161632909450033,1.87091489758174E-6,1,2,12.9061126708984,4.98676017562592,47.3800003528595,2.10254644754053,0.309449007423877,10,4.22823016282866E-7,,,,,,,,,,,,,,,,,,,,,300.000579833984,300.0009765625,8308.3857421875,8488.3212890625,49.6912514815822,5.39056815940769,8.14544105529785,25,1,68,0,0,0.26702880859375,31.2805480957031,1,6,1,300.000579833984,0,300.000778198242,,,,,,,,,,,,,,,,,,,,,,,,,,,,,,,,,
,3865859537.58179,299.999710083008,18475.3759765625,0.00311723279291753,2.09281935799638E-6,1,2,12.9061126708984,4.98678009272839,47.3800003528595,4.05637990564248,0.587195453238997,100,-6.56998574860334E-6,,,,,,,,,,,,,,,,,,,,,299.999603271484,299.999816894531,18380.412109375,18570.33984375,49.6353650424572,5.39071887772408,8.13284111022949,26,1,0,0,1,0.268478393554687,31.2805480957031,1,6,1,299.999603271484,0,299.999710083008,,,,,,,,,,,,,,,,,,,,,,,,,,,,,,,,,
,3865859608.43767,300.001602172852,25566.5390625,0.0041060577394625,2.32925025523824E-6,1,2,12.9061126708984,4.98680011530813,47.3800003528595,5.34325466083721,0.772712945385577,100,-9.2325652124196E-6,,,,,,,,,,,,,,,,,,,,,300.001403808594,300.001800537109,25511.544921875,25621.533203125,49.6396639993129,5.39070748730795,8.12963390350342,26,1,0,0,1,0.268402099609375,31.7693061828613,1,6,1,300.001403808594,0,300.001602172852,,,,,,,,,,,,,,,,,,,,,,,,,,,,,,,,,
,3865859676.57829,299.998550415039,32389.37109375,0.00505627661568974,2.16665848001851E-6,1,2,12.9061126708984,4.98676170570484,47.3800003528595,6.58000087456238,0.949563264190184,100,-1.28755945883548E-5,,,,,,,,,,,,,,,,,,,,,299.998382568359,299.998718261719,32294.212890625,32484.529296875,49.6318477141206,5.3902879115125,8.12392425537109,26,1,0,0,1,0.268936157226562,32.2580642700195,1,6,1,299.998718261719,0,299.998550415039,,,,,,,,,,,,,,,,,,,,,,,,,,,,,,,,,
,3865859747.09667,300.000122070313,39459.751953125,0.00602348866753321,2.2158185474128E-6,1,2,12.9061126708984,4.98676537961094,47.3800003528595,7.83809377655837,1.13528676970276,100,-1.22014523483445E-5,,,,,,,,,,,,,,,,,,,,,299.999847412109,300.000396728516,39369.71484375,39549.7890625,49.5482134625629,5.390501984485,8.12160491943359,26,1,0,0,1,0.267181396484375,32.2580642700195,1,6,1,300.000396728516,0,300.000122070313,,,,,,,,,,,,,,,,,,,,,,,,,,,,,,,,,
,3865859817.7166,300.000762939453,46534.185546875,0.00699297259369536,1.71591650209618E-6,1,2,12.9061126708984,4.98675931686025,47.3800003528595,9.09874977656933,1.32395953856786,100,-9.5914298216086E-6,,,,,,,,,,,,,,,,,,,,,300.000579833984,300.000946044922,46454.0390625,46614.33203125,49.5904214026014,5.39023031230944,8.12464332580566,25,1,68,0,0,0.267486572265625,32.2580642700195,1,6,1,300.000946044922,0,300.000762939453,,,,,,,,,,,,,,,,,,,,,,,,,,,,,,,,,
,3865862961.91972,41.7334728240967,24.8580284118652,,,5,,,,46.459998935461,,,,,4.77849857612686E-6,2.41573495130525E-9,0.269956785401373,0.000399413129912048,1.59290412969116E-6,8.05281014291389E-10,1.5928864488847E-6,4.93691494374391E-10,7.50515467176325E-9,6.36196683707601E-10,2.99986577161637,100.057640075684,10,1000,1,3,0.016643537595894,0.00205033511880103,0.0122712943702936,197.774169921875,41.7330474853516,41.7339286804199,24.8580284118652,24.8580284118652,,,6.60109376907349,,1,,,,,,1,1,1,41.7337226867676,0,41.7335295469865,,,,,,,,,,,,,,,,,,,,,,,,,,,,,,,,,
,3865867373.17597,151.000244140625,24.8580284118652,,,5,,,,46.679999679327,,,,,1.5030799347342E-6,8.14953503804737E-9,0.674283880223802,0.00338404881681512,5.01025176905118E-7,2.71650371997959E-9,5.00990482069685E-7,2.12400975869803E-9,5.89616556668327E-9,1.69350967095512E-9,3.00000879001506,10.005763053894,10,100,1,3,0.00525508326687718,0.000577949447756069,0.00377638381905854,254.82177734375,150.997619628906,151.003143310547,24.8580284118652,24.8580284118652,,,7.27604818344116,,1,,,,,,1,1,1,151.000061035156,0,151.000125525133,,,,,,,,,,,,,,,,,,,,,,,,,,,,,,,,,
,3865871832.33937,260.246368408203,24.8580284118652,,,5,,,,47.1500009298325,,,,,1.03238152566592E-6,5.77650058486759E-8,0.83622388267694,0.039192064410675,3.44127177638147E-7,1.92550020847511E-8,3.44090527034091E-7,1.37425908063887E-8,5.02230968764774E-9,1.3486893756975E-8,2.99999997893651,1.00057637691498,19.98847910208,20,1,3,0.00363226575186283,9.71226357461823E-5,0.000104483857285231,240.199966430664,260.183929443359,260.267395019531,24.8580284118652,24.8580284118652,,,7.95431423187256,,1,,,,,,1,1,1,260.254638671875,0,260.243759473165,,,,,,,,,,,,,,,,,,,,,,,,,,,,,,,,,
,3865873696.88277,299.998397827148,24.8580284118652,,,5,,,,47.3899990320206,,,,,9.36673844457338E-7,3.03631619871125E-9,0.58240486691707,0.00243493943321219,3.12255425321579E-7,1.01220527470655E-9,3.12239293590114E-7,6.68293983289514E-10,3.17398505143412E-9,7.60225407390992E-10,2.99970398750541,100.057640075684,10,1000,1,3,0.00326088034440958,0.000417145702080805,0.0122903846204281,197.759140014648,299.990051269531,300.006439208984,24.8580284118652,24.8580284118652,,,8.2612476348877,,1,,,,,,1,1,1,299.996673583984,0,299.999256591797,,,,,,,,,,,,,,,,,,,,,,,,,,,,,,,,,