File: LT data/Sherwood/K1/288_SH_FULL_SEQUENCE_2.dat
[Header]
; MPMS3 Data File (default extension .dat)
; Copyright (c) 2007, Quantum Design, Inc. All rights reserved.
TITLE,
FILEOPENTIME,3873010503.17446,09/22/2022,2:26 pm
BYAPP,MPMS3 w/ AC,1.0,1.1
INFO,MPMS3 Measurement Release 1.1.16 Build 424, MultiVu Release 2.3.4.19,APPNAME
INFO,Linear Motor Servo Controller,MOTOR_MODULE_NAME
INFO,3101-100 N0,MOTOR_HW_VERSION
INFO,MMC1047,MOTOR_SERIAL_NUMBER
INFO,01.04.28,MOTOR_SOFTWARE_VERSION
INFO,Quantum Design Squid Module,SQUID_MODULE_NAME
INFO,3101-501 B0,SQUID_HW_VERSION
INFO,SQM278,SQUID_SERIAL_NUMBER
INFO,01.03.04,SQUID_SOFTWARE_VERSION
INFO,Quantum Design VSM Oven,OVEN_MODULE_NAME
INFO,3101-201 A3,OVEN_HW_VERSION
INFO,OVB323,OVEN_SERIAL_NUMBER
INFO,01.07.07,OVEN_SOFTWARE_VERSION
INFO,SQUID AC,AC_MODULE_NAME
INFO,3101-401 G0,AC_HW_VERSION
INFO,SAC258,AC_SERIAL_NUMBER
INFO,SQUID AC 00.95.07,AC_SOFTWARE_VERSION
INFO,TCI127,COIL_SERIAL_NUMBER
INFO,0,MOMENT_UNITS
INFO,sndst,SAMPLE_MATERIAL
INFO,,SAMPLE_COMMENT
INFO,,SAMPLE_MASS
INFO,,SAMPLE_VOLUME
INFO,,SAMPLE_MOLECULAR_WEIGHT
INFO,,SAMPLE_SIZE
INFO,,SAMPLE_SHAPE
INFO,Straw,SAMPLE_HOLDER
INFO,Standard,SAMPLE_HOLDER_DETAIL
INFO,61.94,SAMPLE_OFFSET
DATATYPE,COMMENT,1
DATATYPE,TIME,2
STARTUPAXIS,X,2
STARTUPAXIS,Y1,5
FIELDGROUP, VSM,2,3,4,5,6,8,9,10,11,14,15
FIELDGROUP, DC, 2,3,4,14,56,57,58,59,60,61,62,63,64,65,66,67,68,69
FIELDGROUP, AC, 2,3,4,11,16,17,18,19,20,21,22,23,24,25,26,27,28,29,30
STARTUPGROUP, All
[Data]
Comment,Time Stamp (sec),Temperature (K),Magnetic Field (Oe),Moment (emu),M. Std. Err. (emu),Transport Action,Averaging Time (sec),Frequency (Hz),Peak Amplitude (mm),Center Position (mm),Lockin Signal' (V),Lockin Signal (V),Range,M. Quad. Signal (emu),AC Moment (emu),AC M. Std Err. (emu),AC Phase (deg),AC Phase Std. Err. (deg),AC Susceptibility (emu/Oe),AC Suscept. Std Err. (emu/Oe),AC X' (emu/Oe),AC X' Std Err. (emu/Oe),AC X'' (emu/Oe),AC X'' Std Err. (emu/Oe),AC Drive (Oe),AC Frequency (Hz),AC Averaging Time (sec),AC Cycles,AC Range,AC Measure Type,AC Signal' (V),AC Signal'' (V),AC Trim Coil Ratio,AC Trim Coil Phase,Min. Temperature (K),Max. Temperature (K),Min. Field (Oe),Max. Field (Oe),Mass (grams),Motor Lag (deg),Pressure (Torr),Measure Count,Measurement Number,SQUID Status (code),Motor Status (code),Measure Status (code),Motor Current (amps),Motor Temp. (C),Temp. Status (code),Field Status (code),Chamber Status (code),Chamber Temp (K),Redirection State,Evercool Status,Average Temp (K),Rotation Angle (deg),Rotator state,DC Moment Fixed Ctr (emu),DC Moment Err Fixed Ctr (emu),DC Moment Free Ctr (emu),DC Moment Err Free Ctr (emu),DC Fixed Fit,DC Free Fit,DC Calculated Center (mm),DC Calculated Center Err (mm),DC Scan Length (mm),DC Scan Time (s),DC Number of Points,DC Squid Drift,DC Min V (V),DC Max V (V),DC Scans per Measure,Map 01,Map 02,Map 03,Map 04,Map 05,Map 06,Map 07,Map 08,Map 09,Map 10,Map 11,Map 12,Map 13,Map 14,Map 15,Map 16
,3873011282.23875,100.089332580566,49999.6484375,0.0128007662624126,1.48084541755869E-6,1,2,13.1008939743042,5.00374249632653,39.8899987339973,14.8891803215588,2.20227814159688,10,1.70172611509642E-5,,,,,,,,,,,,,,,,,,,,,100.089332580566,100.089332580566,49999.6484375,49999.6484375,52.5461496480729,5.84792958011915,7.67981386184692,26,1,0,0,1,0.301666259765625,30.3030319213867,1,1,1,100.089332580566,0,2084573184,100.089332580566,,,,,,,,,,,,,,,,,,,,,,,,,,,,,,,,,
,3873011422.62159,80.8583793640137,49999.6484375,0.0161779359335772,1.1296821864137E-5,1,2,13.1008939743042,4.99635454222378,39.8299992084503,18.7805628619361,2.76320113351872,1000,9.1503649000206E-6,,,,,,,,,,,,,,,,,,,,,80.7362213134766,80.9805374145508,49999.6484375,49999.6484375,52.6571408978036,5.87315127936474,7.47030591964722,25,1,64,0,0,0.307846069335937,32.2580642700195,2,1,1,80.7362213134766,0,2084573184,80.8583793640137,,,,,,,,,,,,,,,,,,,,,,,,,,,,,,,,,
,3873011561.45307,57.2157287597656,49999.6484375,0.0225654252931385,0.00027527758846405,1,2,13.1008939743042,4.99715278485707,39.7900007665157,26.1772868841489,4.02026059354751,100,0.000155034995146697,,,,,,,,,,,,,,,,,,,,,57.1125411987305,57.3189163208008,49999.6484375,49999.6484375,52.6587041548421,5.86851437473732,7.2097110748291,25,1,68,0,0,0.303573608398438,32.7468223571777,2,1,1,57.1125411987305,0,2084573184,57.2157287597656,,,,,,,,,,,,,,,,,,,,,,,,,,,,,,,,,
,3873011694.32085,34.5483055114746,49999.6484375,0.0348358674872263,0.00119106094931246,1,2,13.1008939743042,4.99693355606021,39.7300012409687,40.5199368351527,5.45089273586004,1000,-0.000410951847871439,,,,,,,,,,,,,,,,,,,,,34.4060211181641,34.6905899047852,49999.6484375,49999.6484375,52.722797693419,5.86999292899215,6.79399347305298,26,1,0,0,1,0.305023193359375,32.7468223571777,2,1,1,34.4060211181641,0,2084573184,34.5483055114746,,,,,,,,,,,,,,,,,,,,,,,,,,,,,,,,,
,3873011765.75256,22.4812297821045,49999.6484375,0.0479352754350062,0.00376905409938642,1,2,13.1008939743042,4.99567341067875,39.7199988365173,56.5210959693557,2.14807553453592,1000,-0.00517446994693517,,,,,,,,,,,,,,,,,,,,,22.3421077728271,22.6203517913818,49999.6484375,49999.6484375,52.8271451007364,5.87438369176813,6.34201192855835,25,1,68,0,0,0.305633544921875,33.2355842590332,2,1,1,22.3421077728271,0,2084573184,22.4812297821045,,,,,,,,,,,,,,,,,,,,,,,,,,,,,,,,,
,3873011829.23737,12.2133526802063,49999.6484375,0.0690299301997255,0.00062877504863933,1,2,13.1008939743042,4.99471752119662,39.7000014781952,80.0316847758814,12.2399639149419,1000,0.000431153031456417,,,,,,,,,,,,,,,,,,,,,12.081018447876,12.3456869125366,49999.6484375,49999.6484375,52.9740912623518,5.87838434107862,5.38782739639282,26,1,0,0,1,0.308990478515625,35.6793746948242,2,1,1,12.081018447876,0,2084573184,12.2133526802063,,,,,,,,,,,,,,,,,,,,,,,,,,,,,,,,,
,3873011892.73388,3.1104633808136,49999.6484375,0.0948082614769863,0.00098975827396904,1,2,13.1008939743042,4.99345861482711,39.7000014781952,109.70514797647,17.9958358562642,1000,0.00161881608656099,,,,,,,,,,,,,,,,,,,,,2.95751643180847,3.26341032981873,49999.6484375,49999.6484375,53.371158550121,5.88621957960535,3.50721764564514,26,1,0,0,1,0.310287475585937,33.7243423461914,6,1,1,2.95751643180847,0,2084573184,3.1104633808136,,,,,,,,,,,,,,,,,,,,,,,,,,,,,,,,,
,3873011956.27958,2.53952932357788,49999.6484375,0.0970344748804041,0.000119698741422064,1,2,13.1008939743042,4.99269388509811,39.7000014781952,112.503464637247,16.7332341503544,1000,0.000207229696454296,,,,,,,,,,,,,,,,,,,,,2.53633403778076,2.542724609375,49999.6484375,49999.6484375,53.6220613047941,5.89111064966114,3.013103723526,26,1,0,0,1,0.300979614257812,33.7243423461914,6,1,1,2.542724609375,0,2084573184,2.53952932357788,,,,,,,,,,,,,,,,,,,,,,,,,,,,,,,,,
,3873012019.74158,2.60234522819519,49999.6484375,0.0949455739760891,0.00134194008181853,1,2,13.1008939743042,4.99140601444378,39.7100001573563,110.441220947209,13.6415656487628,1000,-0.00214812040578552,,,,,,,,,,,,,,,,,,,,,2.60229897499084,2.60239148139954,49999.6484375,49999.6484375,53.411803233121,5.89507715307403,3.04185581207275,26,1,0,0,1,0.3070068359375,33.2355842590332,6,1,1,2.60239148139954,0,2084573184,2.60234522819519,,,,,,,,,,,,,,,,,,,,,,,,,,,,,,,,,
,3873012083.26996,2.63412964344025,49999.6484375,0.0965909288733151,0.000517465100665713,1,2,13.1008939743042,4.99186652483821,39.7100001573563,111.926218234237,16.905344595903,1000,0.000424015759578377,,,,,,,,,,,,,,,,,,,,,2.63114023208618,2.63711905479431,49999.6484375,49999.6484375,53.4661264152076,5.89079407239925,3.07655477523804,26,1,0,0,1,0.307159423828125,33.2355842590332,6,1,1,2.63114023208618,0,2084573184,2.63412964344025,,,,,,,,,,,,,,,,,,,,,,,,,,,,,,,,,
,3873012146.85454,2.53171563148499,49999.6484375,0.0962538364549841,0.00285727978284476,1,2,13.1008939743042,4.98984620578644,39.7000014781952,111.728624643478,15.0882962059146,1000,-0.00108628237879655,,,,,,,,,,,,,,,,,,,,,2.53008532524109,2.53334593772888,49999.6484375,49999.6484375,53.5767268506787,5.89929473930113,3.01448369026184,26,1,0,0,1,0.302200317382812,33.2355842590332,6,1,1,2.53008532524109,0,2084574112,2.53171563148499,,,,,,,,,,,,,,,,,,,,,,,,,,,,,,,,,
,3873012210.25537,2.56742131710052,49999.6484375,0.0972337480379474,0.000319925454014926,1,2,13.1008939743042,4.99128192515362,39.7100001573563,112.643672727571,17.0760602632523,1000,0.000479455482215255,,,,,,,,,,,,,,,,,,,,,2.56381440162659,2.57102823257446,49999.6484375,49999.6484375,53.513414940621,5.89551106457813,3.02289319038391,26,1,0,0,1,0.30731201171875,33.2355842590332,6,1,1,2.57102823257446,0,2084574080,2.56742131710052,,,,,,,,,,,,,,,,,,,,,,,,,,,,,,,,,
,3873012273.80016,2.62983441352844,49999.6484375,0.0934806213130525,0.00283395871662422,1,2,13.1008939743042,4.99087710175055,39.7000014781952,108.018825441988,18.2206256241999,1000,0.00201854575090388,,,,,,,,,,,,,,,,,,,,,2.62788867950439,2.63178014755249,49999.6484375,49999.6484375,53.602911406073,5.89665754205416,3.04177236557007,25,1,68,0,0,0.303115844726562,33.2355842590332,6,1,1,2.63178014755249,0,2084574048,2.62983441352844,,,,,,,,,,,,,,,,,,,,,,,,,,,,,,,,,
,3873012337.30342,2.6224513053894,49999.6484375,0.0974729793356637,0.000321105431624941,1,2,13.1008939743042,4.99191378894031,39.7000014781952,113.037730576391,16.4599945035162,1000,-8.95240404816995E-5,,,,,,,,,,,,,,,,,,,,,2.6175057888031,2.62739682197571,49999.6484375,49999.6484375,53.4078950905249,5.89290522697595,3.0212128162384,26,1,0,0,1,0.302810668945313,32.7468223571777,6,1,1,2.62739682197571,0,2084574176,2.6224513053894,,,,,,,,,,,,,,,,,,,,,,,,,,,,,,,,,
,3873012400.83734,2.64680898189545,49999.6484375,0.0835129064379473,0.00605726013687857,1,2,13.1008939743042,4.99204819867607,39.7000014781952,97.6547288539129,8.62660574296002,1000,-0.00479959073743975,,,,,,,,,,,,,,,,,,,,,2.64637231826782,2.64724564552307,49999.6484375,49999.6484375,53.5270934397076,5.89244614504181,3.03209328651428,25,1,64,0,0,0.304946899414063,32.7468223571777,6,1,1,2.64724564552307,0,2084574048,2.64680898189545,,,,,,,,,,,,,,,,,,,,,,,,,,,,,,,,,
,3873012464.32959,2.57157874107361,49999.6484375,0.0976966842364136,0.000123682437877457,1,2,13.1008939743042,4.99326986882173,39.7000014781952,113.282277045179,16.8997323072853,1000,0.000251386959206207,,,,,,,,,,,,,,,,,,,,,2.56554770469666,2.57760977745056,49999.6484375,49999.6484375,53.5188863402557,5.88794038384265,2.99986457824707,26,1,0,0,1,0.30059814453125,33.7243423461914,6,1,1,2.56554770469666,0,2084574144,2.57157874107361,,,,,,,,,,,,,,,,,,,,,,,,,,,,,,,,,
"FC",3873013315.26787
,3873013763.35471,31.0711517333984,26.2053050994873,0.000258250407393641,1.2145306289105E-6,1,2,13.1008939743042,2.00630142407462,39.7000014781952,0.0630545640907756,0.00892198166473516,1,-1.27941312047993E-6,,,,,,,,,,,,,,,,,,,,,31.0711517333984,31.0711517333984,26.2053050994873,26.2053050994873,52.5234824210152,6.08483883771451,6.19140100479126,26,1,0,0,1,0.153045654296875,32.2580642700195,2,1,1,31.0711517333984,0,2084574400,31.0711517333984,,,,,,,,,,,,,,,,,,,,,,,,,,,,,,,,,
,3873013967.22957,63.0107040405273,26.2053050994873,0.000243700139627794,2.19663350823801E-7,1,2,13.1008939743042,2.00064442673607,39.7399999201298,0.0591506164275045,0.00860625344022938,1,-2.51932339590201E-7,,,,,,,,,,,,,,,,,,,,,63.0107040405273,63.0107040405273,26.2053050994873,26.2053050994873,52.4961254228421,6.14563409948497,6.74725818634033,26,1,0,0,1,0.154037475585938,31.7693061828613,2,1,1,63.0107040405273,0,2084574272,63.0107040405273,,,,,,,,,,,,,,,,,,,,,,,,,,,,,,,,,
,3873014164.94218,95.0035781860352,26.2053050994873,0.00023468376717626,1.98226873359753E-7,1,2,13.1008939743042,1.99879890797984,39.7799983620644,0.0568512127855599,0.00835148508403514,1,7.98660821701769E-8,,,,,,,,,,,,,,,,,,,,,95.0035781860352,95.0035781860352,26.2053050994873,26.2053050994873,52.7610974908614,6.14820746472717,6.97541284561157,26,1,0,0,1,0.157623291015625,31.2805480957031,2,1,1,95.0035781860352,0,2084574336,95.0035781860352,,,,,,,,,,,,,,,,,,,,,,,,,,,,,,,,,
,3873014359.31278,127.008331298828,26.2053050994873,0.000226325878943165,1.16499132745563E-7,1,2,13.1008939743042,2.00205123082152,39.8700013756752,0.0549791737317833,0.00819152392136568,1,5.40460874671659E-7,,,,,,,,,,,,,,,,,,,,,127.008331298828,127.008331298828,26.2053050994873,26.2053050994873,52.7102916371113,6.11577560706539,7.09694147109985,26,1,0,0,1,0.154800415039062,31.7693061828613,2,1,1,127.008331298828,0,2084574336,127.008331298828,,,,,,,,,,,,,,,,,,,,,,,,,,,,,,,,,
,3873014552.48624,159.026321411133,26.2053050994873,0.000220130982896325,9.37925209373249E-8,1,2,13.1008939743042,2.00189984900021,39.9699993431568,0.0534720042388252,0.00792962087451524,1,3.75250268346298E-7,,,,,,,,,,,,,,,,,,,,,159.026321411133,159.026321411133,26.2053050994873,26.2053050994873,52.614151329246,6.12212427106526,7.19081974029541,24,1,64,0,0,0.155258178710938,30.7917900085449,2,1,1,159.026321411133,0,2084574240,159.026321411133,,,,,,,,,,,,,,,,,,,,,,,,,,,,,,,,,
,3873014745.5443,191.005966186523,26.2053050994873,0.000216361075045534,1.85297911085539E-7,1,2,13.1008939743042,2.00398580890082,40.0799997150898,0.0526690186235426,0.00774788953829447,1,1.1694475491068E-7,,,,,,,,,,,,,,,,,,,,,191.005966186523,191.005966186523,26.2053050994873,26.2053050994873,52.6962223237652,6.08794570748803,7.30923509597778,26,1,0,0,1,0.15716552734375,30.7917900085449,2,1,1,191.005966186523,0,2084574304,191.005966186523,,,,,,,,,,,,,,,,,,,,,,,,,,,,,,,,,
,3873014938.21329,223.004272460938,26.2053050994873,0.000211145976471432,8.34854117462292E-8,1,2,13.1008939743042,2.00605354310077,40.2199998497963,0.0514963515824062,0.00760070996181676,1,2.15760894842335E-7,,,,,,,,,,,,,,,,,,,,,223.004272460938,223.004272460938,26.2053050994873,26.2053050994873,52.6485429840921,6.06860737017106,7.49514961242676,26,1,0,0,1,0.15472412109375,30.7917900085449,2,1,1,223.004272460938,0,2084574304,223.004272460938,,,,,,,,,,,,,,,,,,,,,,,,,,,,,,,,,
,3873015131.14695,255.024757385254,26.2053050994873,0.000206749854861541,6.9008137232737E-8,1,2,13.1008939743042,2.00822405833713,40.3800010681152,0.0505324439997873,0.00742423763140542,1,7.43020707690454E-8,,,,,,,,,,,,,,,,,,,,,255.006973266602,255.042541503906,26.2053050994873,26.2053050994873,52.7333496784287,6.04771067668212,7.82698202133179,26,1,0,0,1,0.158920288085938,31.2805480957031,2,1,1,255.042541503906,0,2084574336,255.024757385254,,,,,,,,,,,,,,,,,,,,,,,,,,,,,,,,,
,3873015324.20954,287.012359619141,26.2053050994873,0.000204920212666612,6.4229413054866E-8,1,2,13.1008939743042,2.01088213484567,40.5699983239174,0.0502046635910909,0.00741906283916044,1,2.45359113212575E-7,,,,,,,,,,,,,,,,,,,,,287.012359619141,287.012359619141,26.2053050994873,26.2053050994873,52.6817621961594,6.0171504407078,7.8493275642395,26,1,0,0,1,0.152206420898438,30.7917900085449,2,1,1,287.012359619141,0,2084574368,287.012359619141,,,,,,,,,,,,,,,,,,,,,,,,,,,,,,,,,
,3873017254.56336,2.0000067949295,44085.126953125,0.0905904618643977,0.000130601864622154,1,2,13.1008939743042,1.99769976485529,39.6899990737438,21.9339031684471,3.14136854380344,1000,-0.000295759962175443,,,,,,,,,,,,,,,,,,,,,1.99992775917053,2.00008583068848,44000.1640625,44170.08984375,53.3731126214191,6.07665929059188,2.61251068115234,25,1,68,0,0,0.157394409179687,29.8142719268799,1,6,1,2.00008583068848,0,2084573472,2.0000067949295,,,,,,,,,,,,,,,,,,,,,,,,,,,,,,,,,
,3873017318.04755,2.00007510185242,37748.771484375,0.0860132453735858,3.41457424630488E-5,1,2,13.1008939743042,1.99790259957787,39.6899990737438,20.8256233885499,3.01081386265487,1000,-0.000166817265811085,,,,,,,,,,,,,,,,,,,,,1.99992537498474,2.00022482872009,37658.8515625,37838.69140625,53.259385671871,6.07769071077019,2.6051504611969,26,1,0,0,1,0.152969360351562,30.7917900085449,1,6,1,1.99992537498474,0,2084573568,2.00007510185242,,,,,,,,,,,,,,,,,,,,,,,,,,,,,,,,,
,3873017381.53169,1.99995595216751,31407.4951171875,0.0804178686088135,2.79976653333959E-5,1,2,13.1008939743042,1.99772543870027,39.6899990737438,19.4658627482307,2.82628647811195,1000,-0.000107180330856437,,,,,,,,,,,,,,,,,,,,,1.99980747699738,2.00010442733765,31317.57421875,31497.416015625,53.1202557954479,6.07960274796357,2.59678602218628,26,1,0,0,1,0.155715942382813,31.2805480957031,1,6,1,1.99980747699738,0,2084573696,1.99995595216751,,,,,,,,,,,,,,,,,,,,,,,,,,,,,,,,,
,3873017445.03382,1.99990403652191,25066.28125,0.0733831866780248,2.08694041834567E-5,1,2,13.1008939743042,1.99799171911626,39.6899990737438,17.7662019072616,2.58884731487939,1000,-6.00335003386382E-5,,,,,,,,,,,,,,,,,,,,,1.99975776672363,2.00005030632019,24976.3984375,25156.1640625,52.9502515925152,6.07243803627609,2.58902931213379,26,1,0,0,1,0.160598754882813,32.2580642700195,1,6,1,2.00005030632019,0,2084573728,1.99990403652191,,,,,,,,,,,,,,,,,,,,,,,,,,,,,,,,,
,3873017508.54774,1.99994164705276,18720.73046875,0.0641542638287487,0.000172625019190479,1,2,13.1008939743042,1.9977219201045,39.6899990737438,15.5220389753905,2.30260386592718,1000,0.000112459539054999,,,,,,,,,,,,,,,,,,,,,1.99989902973175,1.99998426437378,18625.81640625,18815.64453125,52.8283175435152,6.07374559325991,2.58279967308044,26,1,0,0,1,0.154495239257813,31.2805480957031,1,6,1,1.99989902973175,0,2084573888,1.99994164705276,,,,,,,,,,,,,,,,,,,,,,,,,,,,,,,,,
,3873017642.61198,1.99998486042023,5328.31689453125,0.0294718418227617,4.28090656727197E-5,1,2,13.1008939743042,1.99755183851026,39.7000014781952,7.13539868767915,1.01752832425063,100,-0.000114037252190767,,,,,,,,,,,,,,,,,,,,,1.99998486042023,1.99998486042023,5328.31689453125,5328.31689453125,52.6817621961594,6.07669405491355,2.57391095161438,26,1,0,0,1,0.15594482421875,31.2805480957031,1,6,1,1.99998486042023,0,2084573760,1.99998486042023,,,,,,,,,,,,,,,,,,,,,,,,,,,,,,,,,
,3873017726.19115,2.00007271766663,-3029.58032226562,-0.0162026649745985,5.47941983601116E-5,1,2,13.1008939743042,1.99648160116754,39.6899990737438,-3.90936111418426,-0.623443408156626,1000,-0.000204579821564652,,,,,,,,,,,,,,,,,,,,,2.00007271766663,2.00007271766663,-3029.58032226562,-3029.58032226562,52.6930958096883,6.08243235649457,2.57198929786682,26,1,0,0,1,0.165863037109375,31.2805480957031,1,6,1,2.00007271766663,0,2084573216,2.00007271766663,,,,,,,,,,,,,,,,,,,,,,,,,,,,,,,,,
,3873017818.13244,2.00011920928955,-12221.3935546875,-0.0499952618559735,0.000219011302586982,1,2,13.1008939743042,1.99718383684653,39.6899990737438,-12.0911550076337,-1.78639523718476,100,-5.82761538677604E-5,,,,,,,,,,,,,,,,,,,,,2.00006556510925,2.00017285346985,-12311.5361328125,-12131.2509765625,52.8040870594191,6.07605836735043,2.56835913658142,26,1,0,0,1,0.165786743164062,31.2805480957031,1,6,1,2.00006556510925,0,2084573888,2.00011920928955,,,,,,,,,,,,,,,,,,,,,,,,,,,,,,,,,
,3873017966.20753,1.99977207183838,-27038.408203125,-0.0752021303940887,4.50174297505194E-5,1,2,13.1008939743042,1.99742637092733,39.6899990737438,-18.1910549322252,-2.69086959404742,1000,-0.000100810106201587,,,,,,,,,,,,,,,,,,,,,1.99977207183838,1.99977207183838,-27038.408203125,-27038.408203125,53.0608520279864,6.07651366166292,2.55379486083984,26,1,0,0,1,0.161285400390625,30.7917900085449,1,6,1,1.99977207183838,0,2084574048,1.99977207183838,,,,,,,,,,,,,,,,,,,,,,,,,,,,,,,,,
,3873018095.98444,2.00014364719391,-40045.03515625,-0.0878990543074088,0.00057488777759788,1,2,13.1008939743042,1.99685617471116,39.6899990737438,-21.2614218573674,-3.07157572422376,1000,0.000179556566867905,,,,,,,,,,,,,,,,,,,,,2.00000953674316,2.00027775764465,-40135.27734375,-39954.79296875,53.2933865124576,6.08438381425753,2.54855060577393,26,1,0,0,1,0.156021118164062,30.7917900085449,1,6,1,2.00000953674316,0,2084574272,2.00014364719391,,,,,,,,,,,,,,,,,,,,,,,,,,,,,,,,,
,3873018179.34021,1.99993473291397,-48397.306640625,-0.093872295858402,0.00642149797999695,1,2,13.1008939743042,1.9974413733838,39.6899990737438,-23.1444596178387,-0.378118747935182,1000,0.0121944557128885,,,,,,,,,,,,,,,,,,,,,1.99986755847931,2.00000190734863,-48492.640625,-48301.97265625,53.4622182726114,6.07806860919249,2.55775928497314,26,1,0,0,1,0.156021118164062,31.7693061828613,1,6,1,2.00000190734863,0,2084574240,1.99993473291397,,,,,,,,,,,,,,,,,,,,,,,,,,,,,,,,,
,3873018244.81058,2.00004303455353,-45599.20703125,-0.0916857084443336,0.0059209415499265,1,2,13.1008939743042,1.99755146929684,39.6899990737438,-22.2963412124792,-2.49397657000456,1000,0.00312993175302052,,,,,,,,,,,,,,,,,,,,,2.00003910064697,2.00004696846008,-45689.14453125,-45509.26953125,53.5505422952845,6.07959779997972,2.55135345458984,26,1,0,0,1,0.155792236328125,30.7917900085449,1,6,1,2.00003910064697,0,2084573984,2.00004303455353,,,,,,,,,,,,,,,,,,,,,,,,,,,,,,,,,
,3873018308.37985,1.99991190433502,-39254.0859375,-0.0870375083614346,0.000136181566489816,1,2,13.1008939743042,1.99704319417653,39.6899990737438,-21.0604316174618,-3.01698259312453,1000,0.000281275085158641,,,,,,,,,,,,,,,,,,,,,1.99986600875854,1.9999577999115,-39339.04296875,-39169.12890625,53.2629030002076,6.08441593804598,2.54900979995728,26,1,0,0,1,0.1568603515625,30.7917900085449,1,6,1,1.99986600875854,0,2084573984,1.99991190433502,,,,,,,,,,,,,,,,,,,,,,,,,,,,,,,,,
,3873018371.84658,2.00011599063873,-32914.837890625,-0.0820711669239784,0.00221066403823094,1,2,13.1008939743042,1.99777074642428,39.7000014781952,-19.8911577168509,-2.71907660585262,1000,0.000792953813877858,,,,,,,,,,,,,,,,,,,,,1.99992084503174,2.00031113624573,-32999.80859375,-32829.8671875,53.1745789775345,6.07559633945741,2.54527878761291,26,1,0,0,1,0.158920288085938,31.7693061828613,1,6,1,2.00031113624573,0,2084574304,2.00011599063873,,,,,,,,,,,,,,,,,,,,,,,,,,,,,,,,,
,3873018435.35282,2.00018358230591,-26574.775390625,-0.0751264098213349,4.64846733719961E-5,1,2,13.1008939743042,1.99749278533832,39.6899990737438,-18.1827443933866,-2.62786741979946,1000,0.000149178011340427,,,,,,,,,,,,,,,,,,,,,2.00002408027649,2.00034308433533,-26669.70703125,-26479.84375,53.0518633000152,6.08058217625576,2.54588055610657,26,1,0,0,1,0.154800415039062,31.2805480957031,1,6,1,2.00002408027649,0,2084573952,2.00018358230591,,,,,,,,,,,,,,,,,,,,,,,,,,,,,,,,,
,3873018498.85748,2.00018775463104,-20229.5546875,-0.0664232515885397,4.14338763743167E-5,1,2,13.1008939743042,1.99768212732764,39.6899990737438,-16.0753237957184,-2.35042912457276,1000,2.2084877866622E-5,,,,,,,,,,,,,,,,,,,,,2.00007367134094,2.00030183792114,-20319.41796875,-20139.69140625,52.8861580539383,6.07400628788237,2.5440788269043,26,1,0,0,1,0.161895751953125,32.2580642700195,1,6,1,2.00007367134094,0,2084573920,2.00018775463104,,,,,,,,,,,,,,,,,,,,,,,,,,,,,,,,,
,3873018562.34494,1.9998574256897,-13899.1875,-0.0545115783179248,2.96312768400128E-5,1,2,13.1008939743042,1.99744629725046,39.6899990737438,-13.1920068492957,-1.91198399887694,1000,8.63685040492555E-5,,,,,,,,,,,,,,,,,,,,,1.9997581243515,1.99995672702789,-13989.107421875,-13809.267578125,52.7247517647171,6.07316019154575,2.54151701927185,26,1,0,0,1,0.153656005859375,31.2805480957031,1,6,1,1.99995672702789,0,2084573920,1.9998574256897,,,,,,,,,,,,,,,,,,,,,,,,,,,,,,,,,
,3873018683.40521,2.00049459934235,-1797.41186523438,-0.0127944516191339,5.89890694826564E-5,1,2,13.1008939743042,1.99861939029904,39.7000014781952,-3.10904707484432,-0.38583775950867,1000,0.000282123308195584,,,,,,,,,,,,,,,,,,,,,2.00043988227844,2.00054931640625,-1887.04138183594,-1707.78234863281,52.6825438246787,6.06289217956734,2.53530120849609,26,1,0,0,1,0.15380859375,32.2580642700195,1,6,1,2.00054931640625,0,2084573888,2.00049459934235,,,,,,,,,,,,,,,,,,,,,,,,,,,,,,,,,
,3873018778.7732,2.00013840198517,7742.45629882813,0.0366073059727189,3.98726504548477E-5,1,2,13.1008939743042,1.99982751168522,39.6899990737438,8.87182191313885,1.33674369108828,1000,0.000147558834461037,,,,,,,,,,,,,,,,,,,,,2.00005078315735,2.00022602081299,7662.3076171875,7822.60498046875,52.6794173106017,6.04825101343056,2.5470609664917,26,1,0,0,1,0.150222778320313,30.7917900085449,1,6,1,2.00022602081299,0,2084573184,2.00013840198517,,,,,,,,,,,,,,,,,,,,,,,,,,,,,,,,,
,3873018883.09121,2.00009107589722,18176.294921875,0.0623826770176348,2.18829294651248E-5,1,2,13.1008939743042,1.99947501905109,39.7000014781952,15.1188560028395,2.24039697788016,1000,9.96761624312534E-5,,,,,,,,,,,,,,,,,,,,,2.00009107589722,2.00009107589722,18176.294921875,18176.294921875,52.9170323804479,6.0545546846104,2.54297947883606,26,1,0,0,1,0.1519775390625,30.7917900085449,1,6,1,2.00009107589722,0,2084573824,2.00009107589722,,,,,,,,,,,,,,,,,,,,,,,,,,,,,,,,,
,3873019025.99787,1.99994611740112,32484.84765625,0.0811638152663974,8.0343282308201E-5,1,2,13.1008939743042,1.99872041901078,39.6899990737438,19.6603196860562,2.88693151396723,1000,2.28366629948147E-5,,,,,,,,,,,,,,,,,,,,,1.99994611740112,1.99994611740112,32484.84765625,32484.84765625,53.1073589248806,6.06485739204164,2.54028749465942,26,1,0,0,1,0.15350341796875,32.2580642700195,1,6,1,1.99994611740112,0,2084574048,1.99994611740112,,,,,,,,,,,,,,,,,,,,,,,,,,,,,,,,,
,3873019155.72457,2.00001227855682,45489.3359375,0.0916647020909889,0.00308192066183235,1,2,13.1008939743042,1.99867373297036,39.7000014781952,22.1744336541032,3.45499809885517,1000,0.000829586399793315,,,,,,,,,,,,,,,,,,,,,1.99973034858704,2.00029420852661,45394.07421875,45584.59765625,53.4653447866883,6.0694667539714,2.53618621826172,26,1,0,0,1,0.153579711914062,31.7693061828613,1,6,1,1.99973034858704,0,2084573184,2.00001227855682,,,,,,,,,,,,,,,,,,,,,,,,,,,,,,,,,
,3873019686.43099,21.0076599121094,26.2547473907471,0.000238170642577085,8.35269802671644E-8,1,2,13.1008939743042,1.99071165146188,39.6899990737438,0.0572472549957363,0.00845841638944887,1,2.79572755742886E-7,,,,,,,,,,,,,,,,,,,,,21.0076599121094,21.0076599121094,26.2547473907471,26.2547473907471,52.6333012279671,6.04614342035963,5.74266719818115,26,1,0,0,1,0.15899658203125,31.2805480957031,2,1,1,21.0076599121094,0,2084574272,21.0076599121094,,,,,,,,,,,,,,,,,,,,,,,,,,,,,,,,,
,3873019891.98955,53.0233993530273,26.2547473907471,0.000219537776158797,7.49508870141106E-7,1,2,13.1008939743042,1.98955777764671,39.7199988365173,0.0527031209369915,0.00783941786047901,1,4.71314907599074E-7,,,,,,,,,,,,,,,,,,,,,53.0233993530273,53.0233993530273,26.2547473907471,26.2547473907471,52.7986156597844,6.06405781436258,6.621337890625,26,1,0,0,1,0.147247314453125,31.2805480957031,2,1,1,53.0233993530273,0,2084574496,53.0233993530273,,,,,,,,,,,,,,,,,,,,,,,,,,,,,,,,,
,3873020093.12644,85.0349044799805,26.2547473907471,0.000210635952281261,7.16989685909826E-8,1,2,13.1008939743042,1.98797659904364,39.7600010037422,0.0504988683303879,0.00744927502588118,1,1.98056234216601E-7,,,,,,,,,,,,,,,,,,,,,85.0349044799805,85.0349044799805,26.2547473907471,26.2547473907471,52.7313956071306,6.06784010975955,6.9102725982666,26,1,0,0,1,0.150146484375,32.7468223571777,2,1,1,85.0349044799805,0,2084574368,85.0349044799805,,,,,,,,,,,,,,,,,,,,,,,,,,,,,,,,,
,3873020286.85554,117.018798828125,26.2547473907471,0.000203686787171509,6.52345902786109E-8,1,2,13.1008939743042,1.98768503800204,39.8299992084503,0.0488176942825745,0.00721220493057454,1,2.3613789106897E-7,,,,,,,,,,,,,,,,,,,,,117.018798828125,117.018798828125,26.2547473907471,26.2547473907471,52.7732127329094,6.08128057419961,7.05029392242432,26,1,0,0,1,0.155715942382813,33.2355842590332,2,1,1,117.018798828125,0,2084574240,117.018798828125,,,,,,,,,,,,,,,,,,,,,,,,,,,,,,,,,
,3873020480.52073,149.07112121582,26.2547473907471,0.000198123231834298,6.75502385112125E-8,1,2,13.1008939743042,1.99192140105953,39.9199984967709,0.0476782337568587,0.00703070371392812,1,1.76167885229717E-7,,,,,,,,,,,,,,,,,,,,,149.07112121582,149.07112121582,26.2547473907471,26.2547473907471,52.6524511266883,6.02486969708857,7.14417171478271,26,1,0,0,1,0.154342651367187,30.7917900085449,2,1,1,149.07112121582,0,2084574304,149.07112121582,,,,,,,,,,,,,,,,,,,,,,,,,,,,,,,,,
,3873020673.57036,181.070037841797,26.2547473907471,0.000193852931052416,6.40246885483271E-8,1,2,13.1008939743042,1.99181106596708,40.0499999523163,0.046649184080306,0.00685460100914664,1,7.32986940075399E-8,,,,,,,,,,,,,,,,,,,,,181.070037841797,181.070037841797,26.2547473907471,26.2547473907471,52.651669498169,6.020769899696,7.2397837638855,26,1,0,0,1,0.156478881835938,30.7917900085449,2,1,1,181.070037841797,0,2084574464,181.070037841797,,,,,,,,,,,,,,,,,,,,,,,,,,,,,,,,,
,3873020866.29959,213.018508911133,26.2547473907471,0.000189514019761718,5.97999409199988E-8,1,2,13.1008939743042,1.99118717509037,40.1800014078617,0.0455813353829966,0.00667431594271201,1,-2.34857460333871E-8,,,,,,,,,,,,,,,,,,,,,213.018508911133,213.018508911133,26.2547473907471,26.2547473907471,52.6997396521017,6.01904595516534,7.40875053405762,26,1,0,0,1,0.1580810546875,31.2805480957031,2,1,1,213.018508911133,0,2084574464,213.018508911133,,,,,,,,,,,,,,,,,,,,,,,,,,,,,,,,,
,3873021059.0441,245.005340576172,26.2547473907471,0.000184496481122653,5.92891640087815E-8,1,2,13.1008939743042,1.99199218558893,40.3300002217293,0.0444101899528788,0.00649139233934566,1,-6.93813242201504E-8,,,,,,,,,,,,,,,,,,,,,245.005340576172,245.005340576172,26.2547473907471,26.2547473907471,52.5645179182748,6.01281970990238,7.77383995056152,26,1,0,0,1,0.149459838867187,31.2805480957031,2,1,1,245.005340576172,0,2084574336,245.005340576172,,,,,,,,,,,,,,,,,,,,,,,,,,,,,,,,,
,3873021252.36807,277.010803222656,26.2547473907471,0.000180881210397539,6.04925915089532E-8,1,2,13.1008939743042,1.99255795397421,40.5000001192093,0.0435638584602631,0.00636451038262268,1,-8.09271813613704E-8,,,,,,,,,,,,,,,,,,,,,277.010803222656,277.010803222656,26.2547473907471,26.2547473907471,52.5273905636113,6.01788646458268,8.07034111022949,26,1,0,0,1,0.155181884765625,31.2805480957031,2,1,1,277.010803222656,0,2084574368,277.010803222656,,,,,,,,,,,,,,,,,,,,,,,,,,,,,,,,,
,3873022032.2817,294.9150390625,26.4154415130615,0.000234474932434216,9.56635263025572E-8,1,2,13.1008939743042,1.99826032633778,40.6000018119812,0.056765699578369,0.00838024183702675,1,2.46842340415677E-7,,,,,,,,,,,,,,,,,,,,,294.9150390625,294.9150390625,26.4154415130615,26.4154415130615,52.6407266988998,5.97368973375821,8.69210529327393,26,1,0,0,1,0.143890380859375,32.2580642700195,2,1,1,294.9150390625,0,2084573184,294.9150390625,,,,,,,,,,,,,,,,,,,,,,,,,,,,,,,,,
,3873022204.22589,262.981781005859,26.4154415130615,0.000231478909103009,6.72580174089535E-8,1,2,13.1008939743042,1.9953232348553,40.4499992728233,0.0558847141496477,0.00824786455174241,1,2.3428915031339E-7,,,,,,,,,,,,,,,,,,,,,262.981781005859,262.981781005859,26.4154415130615,26.4154415130615,52.570380132169,5.99895263901047,9.1976146697998,26,1,0,0,1,0.148468017578125,31.2805480957031,2,1,1,262.981781005859,0,2084574304,262.981781005859,,,,,,,,,,,,,,,,,,,,,,,,,,,,,,,,,
,3873022397.57748,230.985122680664,26.4154415130615,0.000224791083614376,8.03508662164639E-8,1,2,13.1008939743042,1.99362060020341,40.3000004589558,0.0541839287398901,0.00798597374942814,1,1.83356673496792E-7,,,,,,,,,,,,,,,,,,,,,230.985122680664,230.985122680664,26.4154415130615,26.4154415130615,52.8416052283421,6.01438877014796,8.75271415710449,26,1,0,0,1,0.154037475585938,30.3030319213867,2,1,1,230.985122680664,0,2084574080,230.985122680664,,,,,,,,,,,,,,,,,,,,,,,,,,,,,,,,,
,3873022581.38302,199.962158203125,26.4154415130615,0.000217218254877349,6.00068783271491E-8,1,2,13.1008939743042,1.99371856155313,40.1800014078617,0.0523600015280229,0.00774112925812266,1,2.74530682339362E-7,,,,,,,,,,,,,,,,,,,,,199.962158203125,199.962158203125,26.4154415130615,26.4154415130615,52.7188895508229,6.01318660833093,8.44428634643555,26,1,0,0,1,0.151519775390625,31.7693061828613,2,1,1,199.962158203125,0,2084573952,199.962158203125,,,,,,,,,,,,,,,,,,,,,,,,,,,,,,,,,
,3873022773.8722,167.968536376953,26.4154415130615,0.000211622755953395,8.9927619314812E-8,1,2,13.1008939743042,1.98865615392415,40.0799997150898,0.0507744779442323,0.00744715531127985,1,2.44742316111712E-8,,,,,,,,,,,,,,,,,,,,,167.968536376953,167.968536376953,26.4154415130615,26.4154415130615,52.7771208755056,6.06080423622029,8.19255924224854,26,1,0,0,1,0.158233642578125,31.2805480957031,2,1,1,167.968536376953,0,2084573184,167.968536376953,,,,,,,,,,,,,,,,,,,,,,,,,,,,,,,,,
,3873022965.97527,135.961959838867,26.4154415130615,0.00020810495128413,1.04829871553251E-7,1,2,13.1008939743042,1.99056049148739,39.9800017476082,0.0500221443657217,0.00732988813260489,1,-4.12190624558507E-9,,,,,,,,,,,,,,,,,,,,,135.961959838867,135.961959838867,26.4154415130615,26.4154415130615,52.7009120948806,6.0240497717797,7.99243211746216,26,1,0,0,1,0.152587890625,31.7693061828613,2,1,1,135.961959838867,0,2084573984,135.961959838867,,,,,,,,,,,,,,,,,,,,,,,,,,,,,,,,,
,3873023158.48939,103.926750183105,26.4154415130615,0.00020455621175721,5.49846487965633E-8,1,2,13.1008939743042,1.99103839186149,39.9000011384487,0.0491892472473222,0.00722366603232424,1,6.03699885156476E-8,,,,,,,,,,,,,,,,,,,,,103.926750183105,103.926750183105,26.4154415130615,26.4154415130615,52.8162023014671,6.02538268432241,7.79850482940674,24,1,64,0,0,0.151596069335938,31.2805480957031,2,1,1,103.926750183105,0,2084574048,103.926750183105,,,,,,,,,,,,,,,,,,,,,,,,,,,,,,,,,
,3873023348.2389,71.9951171875,26.4154415130615,0.000201614945509613,5.83305165796767E-8,1,2,13.1008939743042,1.9896034843976,39.8200005292892,0.0484080078762895,0.00716284633674985,1,2.7925247737548E-7,,,,,,,,,,,,,,,,,,,,,71.9951171875,71.9951171875,26.4154415130615,26.4154415130615,52.6731642824479,6.04766629954716,7.56974840164185,26,1,0,0,1,0.14556884765625,31.2805480957031,2,1,1,71.9951171875,0,2084573856,71.9951171875,,,,,,,,,,,,,,,,,,,,,,,,,,,,,,,,,
,3873023534.6046,39.9624481201172,26.4154415130615,0.000199768328451392,7.08445953148531E-8,1,2,13.1008939743042,1.99427277184441,39.7600010037422,0.0481796666718047,0.00711919947383016,1,2.36688259826774E-7,,,,,,,,,,,,,,,,,,,,,39.9624481201172,39.9624481201172,26.4154415130615,26.4154415130615,52.766568890496,6.01669927025203,7.19259452819824,26,1,0,0,1,0.150909423828125,31.2805480957031,2,1,1,39.9624481201172,0,2084574048,39.9624481201172,,,,,,,,,,,,,,,,,,,,,,,,,,,,,,,,,
,3873023739.20752,7.99240350723267,26.4154415130615,0.000204377697746373,5.5397509757538E-8,1,2,13.1008939743042,1.99116003477351,39.7199988365173,0.0491467389328989,0.00725418556509157,1,2.09949718810742E-7,,,,,,,,,,,,,,,,,,,,,7.99240350723267,7.99240350723267,26.4154415130615,26.4154415130615,52.5277813778709,6.04348502093903,5.193434715271,26,1,0,0,1,0.151901245117187,31.2805480957031,6,1,1,7.99240350723267,0,2084573184,7.99240350723267,,,,,,,,,,,,,,,,,,,,,,,,,,,,,,,,,
,3873025017.18622,26.0679550170898,26.4154415130615,0.000195082140445088,7.6120369361011E-8,1,2,13.1008939743042,1.99018735430154,39.7100001573563,0.0468676196303754,0.00692040997098308,1,2.11107449812089E-7,,,,,,,,,,,,,,,,,,,,,26.0324668884277,26.103443145752,26.4154415130615,26.4154415130615,52.5383333628806,6.0446555593876,6.01608371734619,26,1,0,0,1,0.152359008789062,31.7693061828613,2,1,1,26.103443145752,0,2084574464,26.0679550170898,,,,,,,,,,,,,,,,,,,,,,,,,,,,,,,,,
,3873025221.87593,58.0366516113281,26.4154415130615,0.000195874338888384,6.61702287733157E-8,1,2,13.1008939743042,1.99040647659518,39.7199988365173,0.0470717448046102,0.00692281173721176,1,9.89904988319867E-8,,,,,,,,,,,,,,,,,,,,,58.0366516113281,58.0366516113281,26.4154415130615,26.4154415130615,52.626266571294,6.0395016898298,6.73040103912354,26,1,0,0,1,0.146636962890625,31.7693061828613,2,1,1,58.0366516113281,0,2084574304,58.0366516113281,,,,,,,,,,,,,,,,,,,,,,,,,,,,,,,,,
,3873025415.17563,89.0370025634766,26.4154415130615,0.000197576720925097,9.02797552516138E-8,1,2,13.1008939743042,1.98898394290422,39.7799983620644,0.0474176690919047,0.00696576734824566,1,6.75512522653771E-8,,,,,,,,,,,,,,,,,,,,,89.0370025634766,89.0370025634766,26.4154415130615,26.4154415130615,52.6786356820825,6.06266834361151,6.9815616607666,26,1,0,0,1,0.147247314453125,30.7917900085449,2,1,1,89.0370025634766,0,2084574368,89.0370025634766,,,,,,,,,,,,,,,,,,,,,,,,,,,,,,,,,
,3873025608.92278,121.001258850098,26.4154415130615,0.000199010947287174,4.97968308119097E-8,1,2,13.1008939743042,1.98953113773076,39.8500002920628,0.0477816977786076,0.00705478200377511,1,2.12915253012888E-7,,,,,,,,,,,,,,,,,,,,,121.001258850098,121.001258850098,26.4154415130615,26.4154415130615,52.7356945639863,6.05478171295107,7.11610269546509,26,1,0,0,1,0.158004760742187,31.2805480957031,2,1,1,121.001258850098,0,2084574464,121.001258850098,,,,,,,,,,,,,,,,,,,,,,,,,,,,,,,,,
,3873025801.99333,153.021469116211,26.4154415130615,0.000201033790298949,6.1435243631809E-8,1,2,13.1008939743042,1.98729992545658,39.9399995803833,0.0481716370282193,0.00706454821795778,1,1.97966080803308E-8,,,,,,,,,,,,,,,,,,,,,153.021469116211,153.021469116211,26.4154415130615,26.4154415130615,52.3542598466017,6.04896748776087,7.20824670791626,26,1,0,0,1,0.151214599609375,31.2805480957031,2,1,1,153.021469116211,0,2084574272,153.021469116211,,,,,,,,,,,,,,,,,,,,,,,,,,,,,,,,,
,3873025995.4114,185.08203125,26.4154415130615,0.000201619901436006,6.02055628914227E-8,1,2,13.1008939743042,1.98906697958883,40.0499999523163,0.0483962789349069,0.00707864053767546,1,-5.70352194442074E-8,,,,,,,,,,,,,,,,,,,,,185.08203125,185.08203125,26.4154415130615,26.4154415130615,52.5598281471594,6.04800912801601,7.31554222106934,26,1,0,0,1,0.146102905273438,31.2805480957031,2,1,1,185.08203125,0,2084574432,185.08203125,,,,,,,,,,,,,,,,,,,,,,,,,,,,,,,,,
,3873026188.41211,217.043746948242,26.4154415130615,0.000202804271394337,5.7545280958706E-8,1,2,13.1008939743042,1.98987682561488,40.1900000870228,0.0487199860894501,0.00711325997741151,1,-1.09241898801629E-7,,,,,,,,,,,,,,,,,,,,,217.043746948242,217.043746948242,26.4154415130615,26.4154415130615,52.7165446652652,6.04604331995405,7.47815084457398,26,1,0,0,1,0.153427124023438,31.2805480957031,2,1,1,217.043746948242,0,2084574272,217.043746948242,,,,,,,,,,,,,,,,,,,,,,,,,,,,,,,,,
,3873026380.88817,249.000732421875,26.4154415130615,0.000204020600018967,9.04689439811878E-8,1,2,13.1008939743042,1.99284781498412,40.3399989008903,0.0491469791789154,0.0072037082700314,1,4.33316233348069E-9,,,,,,,,,,,,,,,,,,,,,249.000732421875,249.000732421875,26.4154415130615,26.4154415130615,52.8318348718517,6.01566730315284,7.79477834701538,26,1,0,0,1,0.149688720703125,31.2805480957031,2,1,1,249.000732421875,0,2084574432,249.000732421875,,,,,,,,,,,,,,,,,,,,,,,,,,,,,,,,,
,3873026573.91993,281.045654296875,26.4154415130615,0.000206061761925215,7.29501727758949E-8,1,2,13.1008939743042,1.99444266219804,40.5200012028217,0.0497147257060247,0.00728190091049413,1,-1.60124983677263E-8,,,,,,,,,,,,,,,,,,,,,281.045654296875,281.045654296875,26.4154415130615,26.4154415130615,52.7892361175537,5.9994334139234,8.00685214996338,26,1,0,0,1,0.152130126953125,31.7693061828613,2,1,1,281.045654296875,0,2084574272,281.045654296875,,,,,,,,,,,,,,,,,,,,,,,,,,,,,,,,,
,3873026970.99496,300.005416870117,45652.6796875,0.00376784144848481,1.07013889082828E-5,1,2,13.1008939743042,2.00471731157217,40.6300015747547,0.935523626515243,0.0143837039153697,100,-0.000493146971302097,,,,,,,,,,,,,,,,,,,,,300.005004882812,300.005828857422,45557.72265625,45747.63671875,52.5699893179094,5.99137436010386,7.84503173828125,25,1,68,0,0,0.158538818359375,31.2805480957031,1,6,1,300.005004882812,0,2084573184,300.005416870117,,,,,,,,,,,,,,,,,,,,,,,,,,,,,,,,,
,3873027034.49425,300.004119873047,39306.193359375,0.00328114423692658,8.61235966574485E-6,1,2,13.1008939743042,2.00521960772309,40.6300015747547,0.812867638492441,0.0275415579451537,100,-0.000367863586494962,,,,,,,,,,,,,,,,,,,,,300.004028320313,300.004211425781,39216.16015625,39396.2265625,52.6559684550248,5.98816075065327,7.91327714920044,25,1,68,0,0,0.151214599609375,32.2580642700195,1,6,1,300.004028320313,0,2084574080,300.004119873047,,,,,,,,,,,,,,,,,,,,,,,,,,,,,,,,,
,3873027105.96219,300.001968383789,32171.3125,0.00277191987909118,7.86927925601996E-6,1,2,13.1008939743042,2.00508980181362,40.6300015747547,0.685984329164325,0.0276610644501051,100,-0.000292730950897843,,,,,,,,,,,,,,,,,,,,,300.001922607422,300.002014160156,32086.330078125,32256.294921875,52.5942198020056,5.98852157401175,8.05135631561279,25,1,68,0,0,0.157928466796875,31.2805480957031,1,6,1,300.001922607422,0,2084574176,300.001968383789,,,,,,,,,,,,,,,,,,,,,,,,,,,,,,,,,
,3873027177.40244,300.002548217773,25036.3857421875,0.00229512651768537,3.78982779302229E-5,1,2,13.1008939743042,2.00519181477191,40.6300015747547,0.567757090084255,0.0248632247956982,100,-0.000234345697271177,,,,,,,,,,,,,,,,,,,,,300.002532958984,300.002563476562,24946.484375,25126.287109375,52.5004243796979,5.98927496129233,8.24111938476563,24,1,68,0,0,0.14984130859375,31.2805480957031,1,6,1,300.002563476562,0,2084574016,300.002548217773,,,,,,,,,,,,,,,,,,,,,,,,,,,,,,,,,
,3873027240.9738,300.001617431641,18690.8466796875,0.00180680113939521,1.00018983165323E-5,1,2,13.1008939743042,2.00557195771136,40.6300015747547,0.447249831573567,0.0186809409990463,100,-0.000188173120869164,,,,,,,,,,,,,,,,,,,,,300.001617431641,300.001617431641,18605.939453125,18775.75390625,52.5680352466113,5.97968663662702,8.45021057128906,26,1,0,0,1,0.150680541992187,31.7693061828613,1,6,1,300.001617431641,0,2084574176,300.001617431641,,,,,,,,,,,,,,,,,,,,,,,,,,,,,,,,,
,3873027312.33603,300.001480102539,11564.6728515625,0.00130921975326108,3.90494321332344E-6,1,2,13.1008939743042,2.00566264849687,40.6300015747547,0.325313420660642,0.0053114127202895,100,-0.000170087514207315,,,,,,,,,,,,,,,,,,,,,300.001129150391,300.001831054687,11474.6845703125,11654.6611328125,52.6493246126113,5.98464129476746,8.72725296020508,26,1,0,0,1,0.154190063476562,32.2580642700195,1,6,1,300.001129150391,0,2084573888,300.001480102539,,,,,,,,,,,,,,,,,,,,,,,,,,,,,,,,,
,3873027375.82903,300.001510620117,5218.41552734375,0.000894977693732813,2.62978664427357E-5,1,2,13.1008939743042,2.005813613046,40.6300015747547,0.226186367250176,-0.0221042682556715,100,-0.000221800901541075,,,,,,,,,,,,,,,,,,,,,300.001220703125,300.001800537109,5128.43994140625,5308.39111328125,52.6614398546594,5.98628976309357,8.97579479217529,24,1,68,0,0,0.155105590820313,31.2805480957031,1,6,1,300.001800537109,0,2084573760,300.001510620117,,,,,,,,,,,,,,,,,,,,,,,,,,,,,,,,,
,3873027455.21347,300.000869750977,-2719.79541015625,-0.000104109816532534,1.05036383224897E-5,1,2,13.1008939743042,2.00712259273502,40.6400002539158,-0.0194158261815396,-0.044699940935943,100,-0.000167809407900428,,,,,,,,,,,,,,,,,,,,,300.000518798828,300.001220703125,-2809.44360351562,-2630.14721679687,52.595783059044,5.97154387016025,9.24848365783691,25,1,68,0,0,0.15228271484375,31.2805480957031,1,6,1,300.001220703125,0,2084573440,300.000869750977,,,,,,,,,,,,,,,,,,,,,,,,,,,,,,,,,
,3873027528.67053,300.000137329102,-10070.0122070312,-0.00104165813236317,0.000101110525045227,1,2,13.1008939743042,2.00782525680558,40.6400002539158,-0.250207763358539,-0.0666758753213151,100,-0.000120229542242376,,,,,,,,,,,,,,,,,,,,,299.999938964844,300.000335693359,-10160.1298828125,-9979.89453125,52.7298323500921,5.96782778686175,9.54796886444092,26,1,0,0,1,0.1470947265625,30.7917900085449,1,6,1,300.000335693359,0,2084573568,300.000137329102,,,,,,,,,,,,,,,,,,,,,,,,,,,,,,,,,
,3873027596.19325,299.99983215332,-16817.9638671875,-0.00155020995516347,4.63302729047909E-6,1,2,13.1008939743042,2.00867434069127,40.6300015747547,-0.379914081237423,-0.0498150935320349,10,2.34704276428962E-5,,,,,,,,,,,,,,,,,,,,,299.999786376953,299.999877929687,-16903.125,-16732.802734375,52.5488853478902,5.95594504916027,9.79849910736084,26,1,0,0,1,0.15228271484375,30.3030319213867,1,6,1,299.999786376953,0,2084574144,299.99983215332,,,,,,,,,,,,,,,,,,,,,,,,,,,,,,,,,
,3873027677.5363,300.000564575195,-24959.8974609375,-0.00214499161216999,5.86146421753531E-6,1,2,13.1008939743042,2.00795832383428,40.6400002539158,-0.52567184488265,-0.0665086012578263,10,4.21861611551535E-5,,,,,,,,,,,,,,,,,,,,,300.000335693359,300.000793457031,-25055.052734375,-24864.7421875,52.6696469541113,5.97022209356214,9.75217342376709,24,1,68,0,0,0.1470947265625,30.7917900085449,1,6,1,300.000396728516,0,2084573888,300.000564575195,,,,,,,,,,,,,,,,,,,,,,,,,,,,,,,,,
,3873027762.14098,299.999755859375,-33431.53515625,-0.00273477796572359,5.05212525663029E-6,1,2,13.1008939743042,2.00807243578924,40.6400002539158,-0.670343389759673,-0.08438983837815,100,5.54840616649366E-5,,,,,,,,,,,,,,,,,,,,,299.999633789063,299.999877929687,-33591.5546875,-33271.515625,52.639554256121,5.96597093621985,9.65392684936523,26,1,0,0,1,0.151290893554687,31.7693061828613,1,6,1,299.999633789063,0,2084574208,299.999755859375,,,,,,,,,,,,,,,,,,,,,,,,,,,,,,,,,
,3873027826.34694,300.000518798828,-39869.681640625,-0.00359901225000916,0.000584467264826397,1,2,13.1008939743042,2.0078720639082,40.6400002539158,-0.864966841202537,-0.22737268813972,100,-0.000403092373046484,,,,,,,,,,,,,,,,,,,,,300.000396728516,300.000640869141,-39964.81640625,-39774.546875,52.5090222934094,5.96902248383867,9.58870315551758,24,1,68,0,0,0.148773193359375,30.7917900085449,1,6,1,300.000640869141,0,2084574400,300.000518798828,,,,,,,,,,,,,,,,,,,,,,,,,,,,,,,,,
,3873027889.87929,300.000473022461,-46237.91796875,-0.00358732059063321,6.40310181065388E-6,1,2,13.1008939743042,2.00780097647586,40.6400002539158,-0.87831251341602,-0.115987457256398,100,5.10142708771045E-5,,,,,,,,,,,,,,,,,,,,,300.000335693359,300.000610351562,-46327.77734375,-46148.05859375,52.575460717544,5.97072031457564,9.53398895263672,26,1,0,0,1,0.149917602539062,30.3030319213867,1,6,1,300.000335693359,0,2084573952,300.000473022461,,,,,,,,,,,,,,,,,,,,,,,,,,,,,,,,,
,3873027971.21062,300.000152587891,-46797.525390625,-0.00390251719796511,1.08608432192815E-5,1,2,13.1008939743042,2.00752145869481,40.6400002539158,-0.975801550258594,0.0142049197082308,100,0.000630079843894843,,,,,,,,,,,,,,,,,,,,,299.999847412109,300.000457763672,-46887.41015625,-46707.640625,52.5543567475248,5.96855971578032,9.47301959991455,24,1,68,0,0,0.149917602539062,31.2805480957031,1,6,1,299.999847412109,0,2084574048,300.000152587891,,,,,,,,,,,,,,,,,,,,,,,,,,,,,,,,,
,3873028034.80274,300.001052856445,-40447.958984375,-0.00338558729464117,1.34806016709059E-5,1,2,13.1008939743042,2.0076646339885,40.6400002539158,-0.84428876563526,-0.00385898602800136,100,0.000480372042056324,,,,,,,,,,,,,,,,,,,,,300.000946044922,300.001159667969,-40527.8125,-40368.10546875,52.5688168751306,5.96360196381627,9.43515110015869,23,1,68,0,0,0.152816772460938,31.2805480957031,1,6,1,300.001159667969,0,2084574336,300.001052856445,,,,,,,,,,,,,,,,,,,,,,,,,,,,,,,,,
,3873028106.15858,300.000564575195,-33319.685546875,-0.00288700694649326,3.84758945625665E-5,1,2,13.1008939743042,2.00737670484705,40.6400002539158,-0.7179251557452,-0.0158004716992872,100,0.000358405047861152,,,,,,,,,,,,,,,,,,,,,300.000549316406,300.000579833984,-33409.57421875,-33229.796875,52.5262181208325,5.96902759958286,9.39377593994141,24,1,68,0,0,0.152130126953125,30.7917900085449,1,6,1,300.000549316406,0,2084574048,300.000564575195,,,,,,,,,,,,,,,,,,,,,,,,,,,,,,,,,
,3873028169.68103,300.000396728516,-26979.5595703125,-0.00241656509249493,1.22074629454396E-5,1,2,13.1008939743042,2.00775821671389,40.6400002539158,-0.600171731660026,-0.0199364658594907,100,0.000272554946220534,,,,,,,,,,,,,,,,,,,,,300.000335693359,300.000457763672,-27069.4609375,-26889.658203125,52.6825438246787,5.96562450040744,9.36469173431396,26,1,0,0,1,0.147171020507813,31.2805480957031,1,6,1,300.000457763672,0,2084574080,300.000396728516,,,,,,,,,,,,,,,,,,,,,,,,,,,,,,,,,
,3873028268.89721,299.998565673828,-17075.1416015625,-0.00171626222662875,4.32539040565645E-5,1,2,13.1008939743042,2.0071303544736,40.6400002539158,-0.426531212846892,-0.0104850387533577,100,0.000208582754914932,,,,,,,,,,,,,,,,,,,,,299.99853515625,299.998596191406,-17165.080078125,-16985.203125,52.6551868265056,5.9695075555614,9.32080459594727,26,1,0,0,1,0.154647827148438,31.7693061828613,1,6,1,299.99853515625,0,2084573728,299.998565673828,,,,,,,,,,,,,,,,,,,,,,,,,,,,,,,,,
,3873028342.37134,299.999847412109,-9738.0146484375,-0.00126199561775067,6.89839717817284E-5,1,2,13.1008939743042,2.0079890382573,40.6400002539158,-0.314856886791916,-0.00111490612773117,100,0.000180387037863168,,,,,,,,,,,,,,,,,,,,,299.999847412109,299.999847412109,-9823.021484375,-9653.0078125,52.6762907965248,5.96875857190292,9.29506492614746,25,1,68,0,0,0.149459838867187,31.2805480957031,1,6,1,299.999847412109,0,2084573920,299.999847412109,,,,,,,,,,,,,,,,,,,,,,,,,,,,,,,,,
,3873028415.09614,300.000946044922,-2467.39013671875,-0.000671586910565642,1.36804047821155E-5,1,2,13.1008939743042,2.00765529747136,40.6400002539158,-0.173961468645456,0.0434804814360556,100,0.000276406458869543,,,,,,,,,,,,,,,,,,,,,300.000946044922,300.000946044922,-2467.39013671875,-2467.39013671875,52.6958315095056,5.966158898521,9.27089309692383,26,1,0,0,1,0.152511596679687,30.7917900085449,1,6,1,300.000946044922,0,2084573856,300.000946044922,,,,,,,,,,,,,,,,,,,,,,,,,,,,,,,,,
,3873028489.27617,299.999633789063,4947.017578125,0.000370356710046805,1.50698189261869E-5,1,2,13.1008939743042,2.00776253553052,40.6400002539158,0.0850989356547072,0.0500162512381006,100,0.00015043925678988,,,,,,,,,,,,,,,,,,,,,299.999542236328,299.999725341797,4861.912109375,5032.123046875,52.6391634418613,5.96732738945349,9.24436664581299,26,1,0,0,1,0.145416259765625,31.2805480957031,1,6,1,299.999542236328,0,2084573184,299.999633789063,,,,,,,,,,,,,,,,,,,,,,,,,,,,,,,,,
,3873028552.68854,300.000076293945,11293.4418945312,0.00109641814791485,2.02335020612434E-5,1,2,13.1008939743042,2.00793065519206,40.6400002539158,0.267225368811339,0.0439995743047178,100,1.93779375496882E-5,,,,,,,,,,,,,,,,,,,,,299.999786376953,300.000366210937,11203.2373046875,11383.646484375,52.6743367252267,5.96689049902316,9.2287015914917,25,1,68,0,0,0.148239135742187,30.7917900085449,1,6,1,300.000366210937,0,2084573792,300.000076293945,,,,,,,,,,,,,,,,,,,,,,,,,,,,,,,,,
,3873028620.25475,300.00080871582,18056.2080078125,0.00164507343701226,6.54348354588036E-6,1,2,13.1008939743042,2.00734482212674,40.6400002539158,0.402355779390088,0.0548555825036632,10,-1.64786049142958E-5,,,,,,,,,,,,,,,,,,,,,300.000793457031,300.000823974609,17966.26953125,18146.146484375,52.6524511266883,5.9676858700376,9.2117223739624,26,1,0,0,1,0.153350830078125,31.2805480957031,1,6,1,300.000793457031,0,2084574048,300.00080871582,,,,,,,,,,,,,,,,,,,,,,,,,,,,,,,,,
,3873028683.67683,300.000885009766,24398.6962890625,0.0021011503765319,5.95866072925733E-6,1,2,13.1008939743042,2.00727978415642,40.6400002539158,0.514322134397514,0.0669918289460345,10,-3.36081153742287E-5,,,,,,,,,,,,,,,,,,,,,300.000793457031,300.0009765625,24308.98046875,24488.412109375,52.6266573855537,5.96805826435876,9.19586944580078,24,1,68,0,0,0.151748657226562,30.7917900085449,1,6,1,300.000793457031,0,2084573984,300.000885009766,,,,,,,,,,,,,,,,,,,,,,,,,,,,,,,,,
,3873028755.18484,299.999801635742,31562.8046875,0.00260263646962472,1.22257960292415E-5,1,2,13.1008939743042,2.0083019331236,40.6300015747547,0.63815781902707,0.0798748615242891,10,-5.46633963041868E-5,,,,,,,,,,,,,,,,,,,,,299.999786376953,299.999816894531,31472.568359375,31653.041015625,52.5840586312556,5.95721932365323,9.18172073364258,24,1,68,0,0,0.151596069335938,32.2580642700195,1,6,1,299.999786376953,0,2084574016,299.999801635742,,,,,,,,,,,,,,,,,,,,,,,,,,,,,,,,,
,3873028866.32341,300.001113891602,42702.357421875,0.00335744631049576,6.54168535776842E-6,1,2,13.1008939743042,2.00792718958086,40.6400002539158,0.822512674201513,0.105945781651999,100,-5.8476108990227E-5,,,,,,,,,,,,,,,,,,,,,300.000946044922,300.001281738281,42617.1640625,42787.55078125,52.5926565449671,5.9656170007919,9.15905094146729,26,1,0,0,1,0.14984130859375,33.2355842590332,1,6,1,300.001281738281,0,2084574208,300.001113891602,,,,,,,,,,,,,,,,,,,,,,,,,,,,,,,,,
,3873028943.71404,299.999908447266,50000.21484375,0.00381826673949834,3.11526882379933E-6,1,2,13.1008939743042,2.00907954478475,40.6300015747547,0.933986448978634,0.137236041425422,100,1.43043901292861E-6,,,,,,,,,,,,,,,,,,,,,299.999664306641,300.000152587891,50000.21484375,50000.21484375,52.5359884773229,5.95279072826878,9.14730834960937,26,1,0,0,1,0.147171020507813,31.2805480957031,1,4,1,300.000152587891,0,2084574272,299.999908447266,,,,,,,,,,,,,,,,,,,,,,,,,,,,,,,,,