File: LT data/Sherwood/K1/293-FC-ZFC-RTSIRM-contsweepwithloop-MsT.dat
[Header]
; MPMS3 Data File (default extension .dat)
; Copyright (c) 2007, Quantum Design, Inc. All rights reserved.
TITLE,
FILEOPENTIME,3866169009.74022,07/05/2022,8:47 am
BYAPP,MPMS3 w/ AC,1.0,1.1
INFO,MPMS3 Measurement Release 1.1.16 Build 424, MultiVu Release 2.3.4.19,APPNAME
INFO,Linear Motor Servo Controller,MOTOR_MODULE_NAME
INFO,3101-100 N2,MOTOR_HW_VERSION
INFO,,MOTOR_SERIAL_NUMBER
INFO,01.04.28,MOTOR_SOFTWARE_VERSION
INFO,Quantum Design Squid Module,SQUID_MODULE_NAME
INFO,3101-501 B0,SQUID_HW_VERSION
INFO,SQM327,SQUID_SERIAL_NUMBER
INFO,01.03.04,SQUID_SOFTWARE_VERSION
INFO,Quantum Design VSM Oven,OVEN_MODULE_NAME
INFO,3101-201 A3,OVEN_HW_VERSION
INFO,OVB365,OVEN_SERIAL_NUMBER
INFO,01.07.07,OVEN_SOFTWARE_VERSION
INFO,SQUID AC,AC_MODULE_NAME
INFO,3101-401 G0,AC_HW_VERSION
INFO,SAC220,AC_SERIAL_NUMBER
INFO,SQUID AC 00.95.07,AC_SOFTWARE_VERSION
INFO,TCI344,COIL_SERIAL_NUMBER
INFO,0,MOMENT_UNITS
INFO,sndst,SAMPLE_MATERIAL
INFO,,SAMPLE_COMMENT
INFO,142.58,SAMPLE_MASS
INFO,,SAMPLE_VOLUME
INFO,,SAMPLE_MOLECULAR_WEIGHT
INFO,,SAMPLE_SIZE
INFO,,SAMPLE_SHAPE
INFO,Not Specified,SAMPLE_HOLDER
INFO,Standard,SAMPLE_HOLDER_DETAIL
INFO,61.27,SAMPLE_OFFSET
DATATYPE,COMMENT,1
DATATYPE,TIME,2
STARTUPAXIS,X,2
STARTUPAXIS,Y1,5
FIELDGROUP, VSM,2,3,4,5,6,8,9,10,11,14,15
FIELDGROUP, DC, 2,3,4,14,56,57,58,59,60,61,62,63,64,65,66,67,68,69
FIELDGROUP, AC, 2,3,4,11,16,17,18,19,20,21,22,23,24,25,26,27,28,29,30
STARTUPGROUP, All
[Data]
Comment,Time Stamp (sec),Temperature (K),Magnetic Field (Oe),Moment (emu),M. Std. Err. (emu),Transport Action,Averaging Time (sec),Frequency (Hz),Peak Amplitude (mm),Center Position (mm),Lockin Signal' (V),Lockin Signal (V),Range,M. Quad. Signal (emu),AC Moment (emu),AC M. Std Err. (emu),AC Phase (deg),AC Phase Std. Err. (deg),AC Susceptibility (emu/Oe),AC Suscept. Std Err. (emu/Oe),AC X' (emu/Oe),AC X' Std Err. (emu/Oe),AC X'' (emu/Oe),AC X'' Std Err. (emu/Oe),AC Drive (Oe),AC Frequency (Hz),AC Averaging Time (sec),AC Cycles,AC Range,AC Measure Type,AC Signal' (V),AC Signal'' (V),AC Trim Coil Ratio,AC Trim Coil Phase,Min. Temperature (K),Max. Temperature (K),Min. Field (Oe),Max. Field (Oe),Mass (grams),Motor Lag (deg),Pressure (Torr),Measure Count,Measurement Number,SQUID Status (code),Motor Status (code),Measure Status (code),Motor Current (amps),Motor Temp. (C),Temp. Status (code),Field Status (code),Chamber Status (code),Chamber Temp (K),Redirection State,Average Temp (K),Rotation Angle (deg),Rotator state,DC Moment Fixed Ctr (emu),DC Moment Err Fixed Ctr (emu),DC Moment Free Ctr (emu),DC Moment Err Free Ctr (emu),DC Fixed Fit,DC Free Fit,DC Calculated Center (mm),DC Calculated Center Err (mm),DC Scan Length (mm),DC Scan Time (s),DC Number of Points,DC Squid Drift,DC Min V (V),DC Max V (V),DC Scans per Measure,Map 01,Map 02,Map 03,Map 04,Map 05,Map 06,Map 07,Map 08,Map 09,Map 10,Map 11,Map 12,Map 13,Map 14,Map 15,Map 16
,3866171441.4201,100.000541687012,49999.63671875,0.0107603975322354,1.57907546025034E-6,1,2,12.9061126708984,4.97656693310111,36.4199988543987,13.9592547149213,2.03949133483674,100,-8.50942997596038E-6,,,,,,,,,,,,,,,,,,,,,100.000541687012,100.000541687012,49999.63671875,49999.63671875,50.030869073188,5.37246669756205,7.29720449447632,26,1,0,0,1,0.276107788085938,29.8142719268799,1,1,1,100.000541687012,0,100.000541687012,,,,,,,,,,,,,,,,,,,,,,,,,,,,,,,,,
,3866171542.12014,86.6437225341797,49999.63671875,0.013050647108777,4.03807761917178E-6,1,2,12.9061126708984,4.97613650022484,36.4199988543987,16.928594179104,2.47121148040761,100,-1.19130792089662E-5,,,,,,,,,,,,,,,,,,,,,86.4649276733398,86.8225173950195,49999.63671875,49999.63671875,50.0699504991495,5.37430074288189,7.22040891647339,26,1,0,0,1,0.287322998046875,30.3030319213867,2,1,1,86.4649276733398,0,86.6437225341797,,,,,,,,,,,,,,,,,,,,,,,,,,,,,,,,,
,3866171652.01013,68.2820053100586,49999.63671875,0.0176527025457871,5.81899655813233E-6,1,2,12.9061126708984,4.97578053145414,36.4199988543987,22.8946443580829,3.35034946010071,100,-9.9065743185914E-6,,,,,,,,,,,,,,,,,,,,,68.2820053100586,68.2820053100586,49999.63671875,49999.63671875,50.0152365028034,5.37581072422073,7.12075233459473,26,1,0,0,1,0.267105102539062,30.3030319213867,2,1,1,68.2820053100586,0,68.2820053100586,,,,,,,,,,,,,,,,,,,,,,,,,,,,,,,,,
,3866171791.16656,44.7732238769531,49999.63671875,0.0284987961105394,1.59870059238878E-5,1,2,12.9061126708984,4.97535910220562,36.4199988543987,36.9600974807704,5.38755585929424,100,-3.19227779477193E-5,,,,,,,,,,,,,,,,,,,,,44.7732238769531,44.7732238769531,49999.63671875,49999.63671875,50.0621342139572,5.37704647564756,6.88542413711548,26,1,0,0,1,0.27801513671875,30.7917900085449,2,1,1,44.7732238769531,0,44.7732238769531,,,,,,,,,,,,,,,,,,,,,,,,,,,,,,,,,
,3866171908.96675,24.717098236084,49999.63671875,0.0460411798848035,2.15993176428532E-5,1,2,12.9061126708984,4.97437634206166,36.4199988543987,59.6932411116327,8.70811328205183,1000,-4.64225385723309E-5,,,,,,,,,,,,,,,,,,,,,24.5468406677246,24.8873558044434,49999.63671875,49999.63671875,50.1961835050053,5.3810346812906,6.41224527359009,26,1,0,0,1,0.270309448242187,30.3030319213867,2,1,1,24.5468406677246,0,24.717098236084,,,,,,,,,,,,,,,,,,,,,,,,,,,,,,,,,
,3866172031.70519,5.91595101356506,49999.63671875,0.0813833360368262,0.00019195368353048,1,2,12.9061126708984,4.98407287837757,36.4300012588501,105.764349316415,15.7070993208846,100,0.000127384174838716,,,,,,,,,,,,,,,,,,,,,5.75585556030273,6.07604646682739,49999.63671875,49999.63671875,50.5174328264092,5.38725600053514,4.28219079971313,26,1,0,0,1,0.268478393554687,31.2805480957031,6,1,1,5.75585556030273,0,5.91595101356506,,,,,,,,,,,,,,,,,,,,,,,,,,,,,,,,,
,3866172114.28541,2.49524748325348,49999.63671875,0.0882342359910618,6.56170762018679E-6,1,2,12.9061126708984,4.98367414352546,36.4199988543987,114.679818837737,16.8569124025291,100,6.92208077452317E-6,,,,,,,,,,,,,,,,,,,,,2.49392056465149,2.49657440185547,49999.63671875,49999.63671875,50.93325919864,5.38967782636712,2.91332483291626,26,1,0,0,1,0.267562866210938,31.7693061828613,6,1,1,2.49657440185547,0,2.49524748325348,,,,,,,,,,,,,,,,,,,,,,,,,,,,,,,,,
,3866172178.77291,2.64160799980164,49999.63671875,0.0880422176268367,9.37548385925094E-6,1,2,12.9061126708984,4.98375084522585,36.4199988543987,114.432308266576,16.8234156355226,100,9.07979553620368E-6,,,,,,,,,,,,,,,,,,,,,2.63963937759399,2.64357662200928,49999.63671875,49999.63671875,50.9672600392265,5.39079500854096,2.97445058822632,26,1,0,0,1,0.2734375,30.7917900085449,6,1,1,2.63963937759399,0,2.64160799980164,,,,,,,,,,,,,,,,,,,,,,,,,,,,,,,,,
,3866172243.30945,2.40617263317108,49999.63671875,0.0884041997869263,1.33661185045543E-5,1,2,12.9061126708984,4.9837278622835,36.4199988543987,114.902584158861,16.8888238584721,100,6.30802430131375E-6,,,,,,,,,,,,,,,,,,,,,2.40531420707703,2.40703105926514,49999.63671875,49999.63671875,50.9320867558612,5.39079585206585,2.85500025749207,26,1,0,0,1,0.267868041992187,31.7693061828613,6,1,1,2.40703105926514,0,2.40617263317108,,,,,,,,,,,,,,,,,,,,,,,,,,,,,,,,,
,3866172313.80439,2.00893425941467,49999.63671875,0.08891386734937,6.87864049930176E-6,1,2,12.9061126708984,4.98355140067309,36.4199988543987,115.555877788946,17.0084424681355,100,2.41149865310776E-5,,,,,,,,,,,,,,,,,,,,,2.00457763671875,2.0132908821106,49999.63671875,49999.63671875,51.0520667335631,5.39187935961901,2.62607312202454,26,1,0,0,1,0.2679443359375,31.2805480957031,6,1,1,2.00457763671875,0,2.00893425941467,,,,,,,,,,,,,,,,,,,,,,,,,,,,,,,,,
,3866172377.52484,1.99964225292206,49999.63671875,0.0889326468530126,9.9177090539557E-6,1,2,12.9061126708984,4.98334660738119,36.4199988543987,115.572782483056,17.0166901869921,100,2.84580135419592E-5,,,,,,,,,,,,,,,,,,,,,1.99935007095337,1.99993443489075,49999.63671875,49999.63671875,51.0231464783516,5.3916703487485,2.58008742332458,26,1,0,0,1,0.268020629882813,31.2805480957031,5,1,1,1.99993443489075,0,1.99964225292206,,,,,,,,,,,,,,,,,,,,,,,,,,,,,,,,,
,3866172861.62808,28.0032558441162,26.1867980957031,0.000218844264868205,9.94582258727526E-8,1,5,12.9061126708984,4.99359869364296,36.4199988543987,0.285240992217274,0.041863500525302,1,-3.11867535925234E-8,,,,,,,,,,,,,,,,,,,,,28.0032558441162,28.0032558441162,26.1867980957031,26.1867980957031,50.142641951438,5.38660569469338,5.99574995040894,65,1,0,0,1,0.273666381835938,30.7917900085449,2,1,1,28.0032558441162,0,28.0032558441162,,,,,,,,,,,,,,,,,,,,,,,,,,,,,,,,,
,3866173046.80772,57.0078773498535,26.1867980957031,0.000157127736439805,3.64686895977798E-8,1,5,12.9061126708984,4.99417132131885,36.4199988543987,0.204847858231115,0.029959711520934,1,-1.01134547762182E-7,,,,,,,,,,,,,,,,,,,,,57.0078773498535,57.0078773498535,26.1867980957031,26.1867980957031,50.259495415063,5.38477464540853,6.58908796310425,65,1,0,0,1,0.270919799804687,30.7917900085449,2,1,1,57.0078773498535,0,57.0078773498535,,,,,,,,,,,,,,,,,,,,,,,,,,,,,,,,,
,3866173228.15766,86.0229873657227,26.1867980957031,0.000126201422098153,2.35096802771927E-8,1,5,12.9061126708984,4.99428638230652,36.4199988543987,0.164539074362818,0.024032280003247,1,-1.05358558361075E-7,,,,,,,,,,,,,,,,,,,,,86.0229873657227,86.0229873657227,26.1867980957031,26.1867980957031,50.0801116698995,5.38414711796821,6.8252329826355,65,1,0,0,1,0.282211303710938,29.3255138397217,2,1,1,86.0229873657227,0,86.0229873657227,,,,,,,,,,,,,,,,,,,,,,,,,,,,,,,,,
,3866173403.79079,115.027519226074,26.1867980957031,0.000105062994944217,1.89769329267236E-8,1,5,12.9061126708984,4.99494985469012,36.4199988543987,0.137008623364025,0.0199839524489806,1,-1.08193873434924E-7,,,,,,,,,,,,,,,,,,,,,115.027519226074,115.027519226074,26.1867980957031,26.1867980957031,50.2219772461399,5.38171367956887,6.94467878341675,65,1,0,0,1,0.26947021484375,31.2805480957031,2,1,1,115.027519226074,0,115.027519226074,,,,,,,,,,,,,,,,,,,,,,,,,,,,,,,,,
,3866173579.00322,144.032348632812,26.1867980957031,8.87435094351483E-5,1.64064865922848E-8,1,5,12.9061126708984,4.99529628542394,36.4199988543987,0.11573715365591,0.0168890136177355,1,-8.56082903115762E-8,,,,,,,,,,,,,,,,,,,,,144.032348632812,144.032348632812,26.1867980957031,26.1867980957031,50.1270093810534,5.38085729365451,7.02169179916382,65,1,0,0,1,0.289154052734375,30.7917900085449,2,1,1,144.032348632812,0,144.032348632812,,,,,,,,,,,,,,,,,,,,,,,,,,,,,,,,,
,3866173754.05402,173.014938354492,26.1867980957031,7.31145855032557E-5,1.72102869746193E-8,1,5,12.9061126708984,4.99536599129285,36.4199988543987,0.0953595993505947,0.0138914368141556,1,-8.85273604792988E-8,,,,,,,,,,,,,,,,,,,,,173.014938354492,173.014938354492,26.1867980957031,26.1867980957031,50.1148941390053,5.38088876557706,7.0936164855957,65,1,0,0,1,0.289688110351562,31.2805480957031,2,1,1,173.014938354492,0,173.014938354492,,,,,,,,,,,,,,,,,,,,,,,,,,,,,,,,,
,3866173930.04679,202.07942199707,26.1867980957031,5.62356643773514E-5,1.41472317280862E-8,1,5,12.9061126708984,4.99532276012839,36.4199988543987,0.0733441929708706,0.0106857946698445,1,-6.701263384004E-8,,,,,,,,,,,,,,,,,,,,,202.07942199707,202.07942199707,26.1867980957031,26.1867980957031,50.1305267093899,5.38005685875566,7.16509294509888,65,1,0,0,1,0.280075073242187,30.7917900085449,2,1,1,202.07942199707,0,202.07942199707,,,,,,,,,,,,,,,,,,,,,,,,,,,,,,,,,
,3866174105.09936,231.145889282227,26.1867980957031,4.75696601381136E-5,1.11244436358879E-8,1,5,12.9061126708984,4.99521845846951,36.4199988543987,0.0620409722765293,0.00903167997815303,1,-6.21709712678122E-8,,,,,,,,,,,,,,,,,,,,,231.145889282227,231.145889282227,26.1867980957031,26.1867980957031,50.0805024841591,5.37907836518308,7.30757617950439,65,1,0,0,1,0.279006958007813,30.7917900085449,2,1,1,231.145889282227,0,231.145889282227,,,,,,,,,,,,,,,,,,,,,,,,,,,,,,,,,
,3866174278.75407,260.011352539062,26.1867980957031,4.12006777208341E-5,1.7350784537402E-8,1,5,12.9061126708984,4.99493866194973,36.4199988543987,0.0537295518987825,0.00782653785680054,1,-5.02415123588703E-8,,,,,,,,,,,,,,,,,,,,,260.011352539062,260.011352539062,26.1867980957031,26.1867980957031,50.1234920527168,5.38239191101657,7.54759359359741,65,1,0,0,1,0.28076171875,31.2805480957031,2,1,1,260.011352539062,0,260.011352539062,,,,,,,,,,,,,,,,,,,,,,,,,,,,,,,,,
,3866174453.91213,289.029876708984,26.1867980957031,3.53584863936723E-5,9.03698164859971E-9,1,5,12.9061126708984,4.99501352984008,36.4199988543987,0.0461129517973948,0.00670874113359182,1,-4.93656648896409E-8,,,,,,,,,,,,,,,,,,,,,289.029876708984,289.029876708984,26.1867980957031,26.1867980957031,50.1614010358995,5.38153568268324,7.42954778671265,65,1,0,0,1,0.279083251953125,32.2580642700195,2,1,1,289.029876708984,0,289.029876708984,,,,,,,,,,,,,,,,,,,,,,,,,,,,,,,,,
,3866176108.2001,1.9998465180397,43162.876953125,0.0839547993868441,1.43198238426654E-5,1,2,12.9061126708984,4.99392746276991,36.4199988543987,109.440925296651,16.0317126490564,1000,-3.4813050793801E-5,,,,,,,,,,,,,,,,,,,,,1.99981915950775,1.99987387657166,43093.19140625,43232.5625,50.8183598063131,5.38913631226827,2.61638617515564,26,1,0,0,1,0.272064208984375,30.7917900085449,1,6,1,1.99987387657166,0,1.9998465180397,,,,,,,,,,,,,,,,,,,,,,,,,,,,,,,,,
,3866176170.39294,1.99979454278946,36958.185546875,0.0791894212620337,1.04935800374741E-5,1,2,12.9061126708984,4.99404804914836,36.4199988543987,103.231143897925,15.1309211127989,1000,-2.61810738928078E-5,,,,,,,,,,,,,,,,,,,,,1.99977648258209,1.99981260299683,36863.3671875,37053.00390625,50.7261276410438,5.38836563951289,2.61293339729309,26,1,0,0,1,0.270462036132813,30.7917900085449,1,6,1,1.99977648258209,0,1.99979454278946,,,,,,,,,,,,,,,,,,,,,,,,,,,,,,,,,
,3866176234.86205,1.99974596500397,30517.9921875,0.073334948826867,1.30117278492889E-5,1,2,12.9061126708984,4.99413475199938,36.4199988543987,95.603670300606,13.998505205271,1000,-3.50837136449316E-5,,,,,,,,,,,,,,,,,,,,,1.99970138072968,1.99979054927826,30423.205078125,30612.779296875,50.50649002714,5.38813410104136,2.61913323402405,26,1,0,0,1,0.271835327148438,30.7917900085449,1,6,1,1.99979054927826,0,1.99974596500397,,,,,,,,,,,,,,,,,,,,,,,,,,,,,,,,,
,3866176311.418,2.00001931190491,22871.2548828125,0.0645787485351418,1.65433407268899E-5,1,2,12.9061126708984,4.99399639236443,36.4199988543987,84.1747304064651,12.3986295302073,100,2.43605920730964E-5,,,,,,,,,,,,,,,,,,,,,1.99999928474426,2.00003933906555,22776.548828125,22965.9609375,50.4345802033707,5.38790810136304,2.61350774765015,26,1,0,0,1,0.271530151367187,31.2805480957031,1,6,1,2.00003933906555,0,2.00001931190491,,,,,,,,,,,,,,,,,,,,,,,,,,,,,,,,,
,3866176392.34894,1.99990177154541,14794.2060546875,0.0518705964822672,2.1188514430849E-5,1,2,12.9061126708984,4.99402721779577,36.4199988543987,67.6117649164513,9.95337673399231,100,1.53702751169438E-5,,,,,,,,,,,,,,,,,,,,,1.9998996257782,1.99990391731262,14739.3193359375,14849.0927734375,50.4025334340823,5.38728815922805,2.61552166938782,26,1,0,0,1,0.27191162109375,31.2805480957031,1,6,1,1.9998996257782,0,1.99990177154541,,,,,,,,,,,,,,,,,,,,,,,,,,,,,,,,,
,3866176488.6936,2.00023686885834,5168.4140625,0.0270582213876243,3.80595463706657E-5,1,2,12.9061126708984,4.99389286310151,36.4199988543987,35.270121019521,5.1792227204859,100,-1.76052502083377E-6,,,,,,,,,,,,,,,,,,,,,2.00013327598572,2.00034046173096,5078.5341796875,5258.2939453125,50.1293542666111,5.38574275279672,2.62113070487976,26,1,0,0,1,0.270767211914062,31.2805480957031,1,6,1,2.00034046173096,0,2.00023686885834,,,,,,,,,,,,,,,,,,,,,,,,,,,,,,,,,
,3866176585.37426,2.00030291080475,-4497.0908203125,-0.0215436195083252,4.76800939544395E-5,1,2,12.9061126708984,4.99386937494961,36.4199988543987,-28.0804468262186,-4.13222433563677,100,-5.18110095957539E-6,,,,,,,,,,,,,,,,,,,,,2.00000190734863,2.00060391426086,-4587.02734375,-4407.154296875,50.1899304768515,5.38690599300532,2.61560273170471,25,1,68,0,0,0.272750854492187,31.2805480957031,1,6,1,2.00000190734863,0,2.00030291080475,,,,,,,,,,,,,,,,,,,,,,,,,,,,,,,,,
,3866176649.87319,1.99976485967636,-10941.46875,-0.0422744520275685,2.68568361906266E-5,1,2,12.9061126708984,4.99393301791757,36.4199988543987,-55.1048975157504,-8.09219322273353,100,2.49298911705379E-6,,,,,,,,,,,,,,,,,,,,,1.99958896636963,1.99994075298309,-11036.576171875,-10846.361328125,50.2204139891015,5.38672414684713,2.60805511474609,26,1,0,0,1,0.27191162109375,31.2805480957031,1,6,1,1.99994075298309,0,1.99976485967636,,,,,,,,,,,,,,,,,,,,,,,,,,,,,,,,,
,3866176722.60537,1.9997895359993,-18216.7978515625,-0.0569716974562617,1.85026270877333E-5,1,2,12.9061126708984,4.99397819087158,36.4199988543987,-74.2586439484716,-10.9404460662494,100,-2.33080591807651E-5,,,,,,,,,,,,,,,,,,,,,1.99970352649689,1.99987554550171,-18286.74609375,-18146.849609375,50.3767396929476,5.3870922110458,2.58422517776489,26,1,0,0,1,0.269393920898438,31.7693061828613,1,6,1,1.99970352649689,0,1.9997895359993,,,,,,,,,,,,,,,,,,,,,,,,,,,,,,,,,
,3866176813.01846,2.00009828805923,-27265.748046875,-0.0695034462288639,1.4506427858148E-5,1,2,12.9061126708984,4.99389088729078,36.4199988543987,-90.5868311300281,-13.3728662095795,100,-4.85642481797781E-5,,,,,,,,,,,,,,,,,,,,,1.99998939037323,2.00020718574524,-27360.91796875,-27170.578125,50.55729588089,5.38847424089784,2.56888651847839,26,1,0,0,1,0.271835327148438,31.2805480957031,1,6,1,2.00020718574524,0,2.00009828805923,,,,,,,,,,,,,,,,,,,,,,,,,,,,,,,,,
,3866176913.03273,1.99716800451279,-37283.826171875,-0.0793863185746886,1.32739898183294E-5,1,2,12.9061126708984,4.99385022860168,36.4199988543987,-103.469775849626,-15.2513878397098,100,-3.79579369005408E-5,,,,,,,,,,,,,,,,,,,,,1.9961348772049,1.99820113182068,-37449.1640625,-37118.48828125,50.7667723240438,5.38958739620358,2.55621671676636,26,1,0,0,1,0.272903442382813,31.7693061828613,1,6,1,1.9961348772049,0,1.99716800451279,,,,,,,,,,,,,,,,,,,,,,,,,,,,,,,,,
,3866177000.38571,1.99983537197113,-46034.3671875,-0.0858850962263753,1.35963114623828E-5,1,2,12.9061126708984,4.9937142959489,36.4199988543987,-111.932920955024,-16.5189922450357,100,-5.6190635165748E-5,,,,,,,,,,,,,,,,,,,,,1.99981606006622,1.99985468387604,-46124.515625,-45944.21875,50.8187506205727,5.39023907882988,2.51339721679687,26,1,0,0,1,0.27313232421875,30.7917900085449,1,6,1,1.99981606006622,0,1.99983537197113,,,,,,,,,,,,,,,,,,,,,,,,,,,,,,,,,
,3866177081.20528,2.0029069185257,-46572.845703125,-0.086342909295836,1.51475061387418E-5,1,2,12.9061126708984,4.993694003823,36.4199988543987,-112.546761266527,-16.4856561086123,1000,3.65710945057075E-5,,,,,,,,,,,,,,,,,,,,,1.9972243309021,2.00858950614929,-46647.6640625,-46498.02734375,50.9141092999188,5.39004295043618,2.50625944137573,26,1,0,0,1,0.27191162109375,30.7917900085449,6,6,1,2.00858950614929,0,2.0029069185257,,,,,,,,,,,,,,,,,,,,,,,,,,,,,,,,,
,3866177143.42275,1.99989449977875,-40364.857421875,-0.0819388204004242,1.16729850962221E-5,1,2,12.9061126708984,4.99366971385524,36.4199988543987,-106.804796294536,-15.6485382035887,1000,3.17350651850377E-5,,,,,,,,,,,,,,,,,,,,,1.99989259243011,1.99989640712738,-40460.01953125,-40269.6953125,50.7800600088708,5.39017606244413,2.48900842666626,26,1,0,0,1,0.273208618164062,31.2805480957031,5,6,1,1.99989259243011,0,1.99989449977875,,,,,,,,,,,,,,,,,,,,,,,,,,,,,,,,,
,3866177205.87274,1.99998247623444,-34131.1328125,-0.0768020795452796,1.28088075547016E-5,1,2,12.9061126708984,4.99369608651512,36.4199988543987,-100.108043141912,-14.6806202802455,1000,1.97873883488072E-5,,,,,,,,,,,,,,,,,,,,,1.9998722076416,2.00009274482727,-34220.91796875,-34041.34765625,50.7026787854669,5.38930603691189,2.493896484375,26,1,0,0,1,0.271148681640625,31.7693061828613,5,6,1,2.00009274482727,0,1.99998247623444,,,,,,,,,,,,,,,,,,,,,,,,,,,,,,,,,
,3866177271.59754,1.99979448318481,-27569.021484375,-0.0701914178502207,1.45767353708222E-5,1,2,12.9061126708984,4.9936478131286,36.4199988543987,-91.4904324869275,-13.4145814555832,1000,1.98007544013483E-5,,,,,,,,,,,,,,,,,,,,,1.99964845180511,1.99994051456451,-27733.6640625,-27404.37890625,50.5580775094092,5.38896880332087,2.48660469055176,26,1,0,0,1,0.270462036132813,33.2355842590332,1,6,1,1.99964845180511,0,1.99979448318481,,,,,,,,,,,,,,,,,,,,,,,,,,,,,,,,,
,3866177358.96694,2.00016021728516,-18849.2998046875,-0.0588768798470672,1.79592974774489E-5,1,2,12.9061126708984,4.99351246702463,36.4199988543987,-76.7306627983898,-11.3131154777453,100,-3.04481690692714E-5,,,,,,,,,,,,,,,,,,,,,2.0001163482666,2.00020408630371,-18939.248046875,-18759.3515625,50.3736131788707,5.38846854408464,2.48520994186401,26,1,0,0,1,0.271148681640625,32.2580642700195,5,6,1,2.0001163482666,0,2.00016021728516,,,,,,,,,,,,,,,,,,,,,,,,,,,,,,,,,
,3866177440.84356,2.00005781650543,-10676.373046875,-0.0428568246413057,2.6293364205685E-5,1,2,12.9061126708984,4.99339382131009,36.4300012588501,-55.8521063701831,-8.22596413155033,100,-1.5530756959454E-5,,,,,,,,,,,,,,,,,,,,,1.99988269805908,2.00023293495178,-10841.322265625,-10511.423828125,50.2512883156111,5.38831015073513,2.48956370353699,26,1,0,0,1,0.271682739257813,31.2805480957031,5,6,1,2.00023293495178,0,2.00005781650543,,,,,,,,,,,,,,,,,,,,,,,,,,,,,,,,,
,3866177530.20942,1.99985402822494,-1743.81005859375,-0.0131434859907576,5.22414419711664E-5,1,2,12.9061126708984,4.99335524151491,36.4199988543987,-17.1323093385369,-2.49844785380867,100,1.38770404582906E-5,,,,,,,,,,,,,,,,,,,,,1.99923551082611,2.00047254562378,-1838.76696777344,-1648.85314941406,50.1645275499765,5.38845288884846,2.48910617828369,26,1,0,0,1,0.2703857421875,31.7693061828613,1,6,1,2.00047254562378,0,1.99985402822494,,,,,,,,,,,,,,,,,,,,,,,,,,,,,,,,,
,3866177611.14451,1.99995690584183,6348.2490234375,0.0286431437005765,3.99374705729125E-5,1,2,12.9061126708984,4.99331582285153,36.4199988543987,37.3277711228207,5.49688663480436,100,9.78541349268617E-6,,,,,,,,,,,,,,,,,,,,,1.99979078769684,2.00012302398682,6288.42919921875,6408.06884765625,50.1739070922072,5.38837705054612,2.48066306114197,25,1,68,0,0,0.274200439453125,31.2805480957031,1,6,1,2.00012302398682,0,1.99995690584183,,,,,,,,,,,,,,,,,,,,,,,,,,,,,,,,,
,3866177671.20927,1.99986976385117,12354.24609375,0.0457100084812394,2.52434204912291E-5,1,2,12.9061126708984,4.99319066682963,36.4199988543987,59.5671083074254,8.77270374041117,100,1.62565761305844E-5,,,,,,,,,,,,,,,,,,,,,1.9998060464859,1.99993348121643,12259.14453125,12449.34765625,50.2454261017169,5.38981538255043,2.48163890838623,26,1,0,0,1,0.272750854492187,31.2805480957031,1,6,1,1.99993348121643,0,1.99986976385117,,,,,,,,,,,,,,,,,,,,,,,,,,,,,,,,,
,3866177735.72996,2.00019657611847,18810.7529296875,0.058048721279685,1.86523548932959E-5,1,2,12.9061126708984,4.99316330199526,36.4199988543987,75.6440879290651,11.1519902302586,100,2.93278493988654E-5,,,,,,,,,,,,,,,,,,,,,2.00009202957153,2.00030112266541,18720.603515625,18900.90234375,50.2352649309669,5.38951628328981,2.47134566307068,26,1,0,0,1,0.2740478515625,31.2805480957031,1,6,1,2.00030112266541,0,2.00019657611847,,,,,,,,,,,,,,,,,,,,,,,,,,,,,,,,,
,3866177819.61902,1.99987351894379,27204.650390625,0.0693371112687045,1.48501728418987E-5,1,2,12.9061126708984,4.99324602963923,36.4199988543987,90.3539436558466,13.3366182575708,100,4.70451186643616E-5,,,,,,,,,,,,,,,,,,,,,1.99987351894379,1.99987351894379,27204.650390625,27204.650390625,50.4978921134284,5.39049051499095,2.45893096923828,26,1,0,0,1,0.272369384765625,30.7917900085449,1,6,1,1.99987351894379,0,1.99987351894379,,,,,,,,,,,,,,,,,,,,,,,,,,,,,,,,,
,3866177894.83732,1.9997301697731,34735.083984375,0.077148851493622,1.62151279300727E-5,1,2,12.9061126708984,4.99336354609363,36.4199988543987,100.537791350998,14.8330802957362,100,4.73013965789145E-5,,,,,,,,,,,,,,,,,,,,,1.99962651729584,1.99983382225037,34639.93359375,34830.234375,50.8648667032073,5.39109386400798,2.45963311195374,26,1,0,0,1,0.274734497070313,31.7693061828613,1,6,1,1.99962651729584,0,1.9997301697731,,,,,,,,,,,,,,,,,,,,,,,,,,,,,,,,,
,3866177983.51544,2.0001277923584,43628.328125,0.0842315629490015,1.1625384973132E-5,1,2,12.9061126708984,4.99339575692908,36.4199988543987,109.769486015997,16.1898842967089,100,4.77267906654078E-5,,,,,,,,,,,,,,,,,,,,,2.00002574920654,2.00022983551025,43528,43728.65625,50.9668692249669,5.39139971748122,2.45501255989075,26,1,0,0,1,0.2703857421875,31.2805480957031,1,6,1,2.00002574920654,0,2.0001277923584,,,,,,,,,,,,,,,,,,,,,,,,,,,,,,,,,
,3866178418.09869,5.03385734558105,26.39990234375,0.000856212721910602,1.2345855628782E-5,1,5,12.9061126708984,4.99316748158992,36.4199988543987,1.11590261773729,0.163410520328748,100,-3.96439594988773E-7,,,,,,,,,,,,,,,,,,,,,5.03385734558105,5.03385734558105,26.39990234375,26.39990234375,50.1739070922072,5.3881020554829,3.67690467834473,65,1,0,0,1,0.271148681640625,30.3030319213867,6,1,1,5.03385734558105,0,5.03385734558105,,,,,,,,,,,,,,,,,,,,,,,,,,,,,,,,,
,3866178615.05758,35.0650329589844,26.39990234375,0.00015011332363187,5.02407959116593E-8,1,5,12.9061126708984,4.9938044590379,36.4199988543987,0.195675907744084,0.0286675285230912,1,-5.96325564222094E-8,,,,,,,,,,,,,,,,,,,,,35.0650329589844,35.0650329589844,26.39990234375,26.39990234375,50.188367219813,5.38559246732791,6.17309331893921,65,1,0,0,1,0.27191162109375,31.2805480957031,2,1,1,35.0650329589844,0,35.0650329589844,,,,,,,,,,,,,,,,,,,,,,,,,,,,,,,,,
,3866178798.91747,64.0899963378906,26.39990234375,0.000115053640075988,2.4990238134224E-8,1,5,12.9061126708984,4.9939891469978,36.4199988543987,0.149991797761617,0.0219109154816751,1,-9.35100496545037E-8,,,,,,,,,,,,,,,,,,,,,64.0899963378906,64.0899963378906,26.39990234375,26.39990234375,50.1008248256591,5.38498676668989,6.65520286560059,65,1,0,0,1,0.272293090820313,30.7917900085449,2,1,1,64.0899963378906,0,64.0899963378906,,,,,,,,,,,,,,,,,,,,,,,,,,,,,,,,,
,3866178979.16184,93.0285339355469,26.39990234375,9.57297306284728E-5,1.82058908619831E-8,1,5,12.9061126708984,4.99419201406476,36.4199988543987,0.124811037758863,0.0182039724375227,1,-9.92218483239554E-8,,,,,,,,,,,,,,,,,,,,,93.0285339355469,93.0285339355469,26.39990234375,26.39990234375,50.1699989496111,5.38519459630295,6.84726762771606,65,1,0,0,1,0.271148681640625,30.7917900085449,2,1,1,93.0285339355469,0,93.0285339355469,,,,,,,,,,,,,,,,,,,,,,,,,,,,,,,,,
,3866179154.84509,122.031265258789,26.39990234375,8.18014159165204E-5,1.4414349891451E-8,1,5,12.9061126708984,4.99426230955064,36.4199988543987,0.10665343634882,0.0155568351619788,1,-8.3891745342594E-8,,,,,,,,,,,,,,,,,,,,,122.031265258789,122.031265258789,26.39990234375,26.39990234375,50.1442052084765,5.38523945734043,6.94429206848145,65,1,0,0,1,0.270919799804687,30.3030319213867,2,1,1,122.077911376953,0,122.031265258789,,,,,,,,,,,,,,,,,,,,,,,,,,,,,,,,,
,3866179329.82398,151.027114868164,26.39990234375,7.11077193296554E-5,1.13194272611895E-8,1,5,12.9061126708984,4.99423945951112,36.4199988543987,0.0927121904738387,0.0135101864817944,1,-8.27861948549905E-8,,,,,,,,,,,,,,,,,,,,,151.027114868164,151.027114868164,26.39990234375,26.39990234375,50.1215379814188,5.38578101520318,7.01871204376221,65,1,0,0,1,0.271377563476562,31.2805480957031,2,1,1,151.027114868164,0,151.027114868164,,,,,,,,,,,,,,,,,,,,,,,,,,,,,,,,,
,3866179504.62522,180.007095336914,26.39990234375,6.17375115864908E-5,1.36497937826795E-8,1,5,12.9061126708984,4.99411740385253,36.4199988543987,0.0804896954166841,0.011747202065143,1,-5.82834312044987E-8,,,,,,,,,,,,,,,,,,,,,180.007095336914,180.007095336914,26.39990234375,26.39990234375,50.1352164805053,5.38596523319807,7.08641242980957,65,1,0,0,1,0.27069091796875,31.2805480957031,2,1,1,180.007095336914,0,180.007095336914,,,,,,,,,,,,,,,,,,,,,,,,,,,,,,,,,
,3866179680.06446,209.079742431641,26.39990234375,5.06011664706677E-5,1.42597374867332E-8,1,5,12.9061126708984,4.99402787603696,36.4199988543987,0.0659695329949655,0.00962524979475424,1,-4.98603684556346E-8,,,,,,,,,,,,,,,,,,,,,209.079742431641,209.079742431641,26.39990234375,26.39990234375,50.2712198428515,5.38573649717238,7.16186380386353,65,1,0,0,1,0.271759033203125,31.2805480957031,2,1,1,209.079742431641,0,209.079742431641,,,,,,,,,,,,,,,,,,,,,,,,,,,,,,,,,
,3866179854.59021,238.028930664062,26.39990234375,4.36971553299614E-5,1.13571627229078E-8,1,5,12.9061126708984,4.99392279944818,36.4199988543987,0.0569676723442378,0.00830705742438559,1,-4.66480531816989E-8,,,,,,,,,,,,,,,,,,,,,238.028930664062,238.028930664062,26.39990234375,26.39990234375,50.1434235799572,5.38687944721486,7.35806846618652,65,1,0,0,1,0.27191162109375,31.7693061828613,2,1,1,238.028930664062,0,238.028930664062,,,,,,,,,,,,,,,,,,,,,,,,,,,,,,,,,
,3866180029.46574,267.072052001953,26.39990234375,3.8223993172141E-5,8.66269008213085E-9,1,5,12.9061126708984,4.99367177379147,36.4199988543987,0.0498282940411238,0.00726976388807712,1,-3.79700897709898E-8,,,,,,,,,,,,,,,,,,,,,267.072052001953,267.072052001953,26.39990234375,26.39990234375,50.2024365331592,5.38821301673771,7.68553590774536,65,1,0,0,1,0.27313232421875,29.8142719268799,2,1,1,267.072052001953,0,267.072052001953,,,,,,,,,,,,,,,,,,,,,,,,,,,,,,,,,
,3866180204.18735,296.025390625,26.39990234375,3.3343383405558E-5,8.21582606521064E-9,1,5,12.9061126708984,4.9937711812092,36.4199988543987,0.04346696740136,0.00634334846010589,1,-3.18610849600852E-8,,,,,,,,,,,,,,,,,,,,,296.025390625,296.025390625,26.39990234375,26.39990234375,50.1516306794092,5.38754595548745,7.46082592010498,65,1,0,0,1,0.270919799804687,31.7693061828613,2,1,1,296.025390625,0,296.025390625,,,,,,,,,,,,,,,,,,,,,,,,,,,,,,,,,
,3866180974.5897,276.965942382813,26.2996196746826,4.16539296246825E-5,8.15867496944229E-9,1,5,12.9061126708984,4.99348778317188,36.4199988543987,0.0542958360300783,0.00792762690781708,1,-3.68213039363035E-8,,,,,,,,,,,,,,,,,,,,,276.965942382813,276.965942382813,26.2996196746826,26.2996196746826,50.1227104241976,5.38861203994748,7.8832688331604,65,1,0,0,1,0.27191162109375,30.7917900085449,2,1,1,276.965942382813,0,276.965942382813,,,,,,,,,,,,,,,,,,,,,,,,,,,,,,,,,
,3866181149.80863,247.941650390625,26.2996196746826,4.35203228197882E-5,7.55270794418863E-9,1,5,12.9061126708984,4.99361288619599,36.4199988543987,0.0567314252241353,0.0082779911334508,1,-4.24155567649479E-8,,,,,,,,,,,,,,,,,,,,,247.941650390625,247.941650390625,26.2996196746826,26.2996196746826,50.1406878801399,5.38786630637097,7.7449688911438,65,1,0,0,1,0.273818969726562,31.2805480957031,2,1,1,247.941650390625,0,247.941650390625,,,,,,,,,,,,,,,,,,,,,,,,,,,,,,,,,
,3866181323.02754,218.980377197266,26.2996196746826,4.50440549383095E-5,9.00885994857337E-9,1,5,12.9061126708984,4.99342130103663,36.4199988543987,0.0587156162077044,0.00856006587252467,1,-4.94964080937952E-8,,,,,,,,,,,,,,,,,,,,,218.980377197266,218.980377197266,26.2996196746826,26.2996196746826,50.0973074973226,5.38850676161539,7.64479970932007,65,1,0,0,1,0.271530151367187,31.2805480957031,2,1,1,218.980377197266,0,218.980377197266,,,,,,,,,,,,,,,,,,,,,,,,,,,,,,,,,
,3866181497.73839,189.967514038086,26.2996196746826,4.65900287344282E-5,8.11512820166093E-9,1,5,12.9061126708984,4.99365680829422,36.4199988543987,0.0607325429332064,0.0088700371005266,1,-3.92322430433076E-8,,,,,,,,,,,,,,,,,,,,,189.967514038086,189.967514038086,26.2996196746826,26.2996196746826,50.1793784918418,5.38738292533784,7.57462167739868,65,1,0,0,1,0.272903442382813,31.2805480957031,2,1,1,189.967514038086,0,189.967514038086,,,,,,,,,,,,,,,,,,,,,,,,,,,,,,,,,
,3866181671.82074,160.987991333008,26.2996196746826,4.84579077246722E-5,7.96582187201578E-9,1,5,12.9061126708984,4.99335997098254,36.4199988543987,0.0631617063505823,0.00922793989687928,1,-3.84603314317934E-8,,,,,,,,,,,,,,,,,,,,,160.987991333008,160.987991333008,26.2996196746826,26.2996196746826,50.2016549046399,5.38838731733375,7.49843883514404,65,1,0,0,1,0.271682739257813,31.7693061828613,2,1,1,160.987991333008,0,160.987991333008,,,,,,,,,,,,,,,,,,,,,,,,,,,,,,,,,
,3866181846.42044,131.974990844727,26.2996196746826,5.04974242372862E-5,7.74601370067817E-9,1,5,12.9061126708984,4.99337335649736,36.4199988543987,0.0658220724373353,0.00960450412432065,1,-4.91801171273674E-8,,,,,,,,,,,,,,,,,,,,,131.974990844727,131.974990844727,26.2996196746826,26.2996196746826,50.0875371408322,5.3887338282971,7.42039775848389,65,1,0,0,1,0.2728271484375,32.2580642700195,2,1,1,131.974990844727,0,131.974990844727,,,,,,,,,,,,,,,,,,,,,,,,,,,,,,,,,
,3866182020.42529,102.973976135254,26.2996196746826,5.13427345345216E-5,6.48311725138559E-9,1,5,12.9061126708984,4.99326907207008,36.4199988543987,0.0669212462499817,0.00976979930170554,1,-4.631647419631E-8,,,,,,,,,,,,,,,,,,,,,102.973976135254,102.973976135254,26.2996196746826,26.2996196746826,50.1504582366303,5.38898238278549,7.32788467407227,65,1,0,0,1,0.270462036132813,31.7693061828613,2,1,1,102.973976135254,0,102.973976135254,,,,,,,,,,,,,,,,,,,,,,,,,,,,,,,,,
,3866182192.01573,73.9806137084961,26.2996196746826,5.32267127115886E-5,6.59338582168942E-9,1,5,12.9061126708984,4.99316591888365,36.4199988543987,0.0693747828579301,0.0101284892391313,1,-4.76408916328162E-8,,,,,,,,,,,,,,,,,,,,,73.9806137084961,73.9806137084961,26.2996196746826,26.2996196746826,50.2313567883707,5.38995106362883,7.21122026443481,65,1,0,0,1,0.27130126953125,31.7693061828613,2,1,1,73.9806137084961,0,73.9806137084961,,,,,,,,,,,,,,,,,,,,,,,,,,,,,,,,,
,3866182361.54277,44.9456825256348,26.2996196746826,5.50734123797042E-5,6.71154306304625E-9,1,5,12.9061126708984,4.99323462050035,36.4199988543987,0.0717820843963915,0.010487180020074,1,-4.38605252051038E-8,,,,,,,,,,,,,,,,,,,,,44.9456825256348,44.9456825256348,26.2996196746826,26.2996196746826,50.2684841430342,5.39015147685451,6.97590494155884,65,1,0,0,1,0.271148681640625,31.7693061828613,2,1,1,44.9456825256348,0,44.9456825256348,,,,,,,,,,,,,,,,,,,,,,,,,,,,,,,,,
,3866182533.94486,15.8351449966431,26.2996196746826,5.60282683337361E-5,6.17962273096472E-9,1,5,12.9061126708984,4.99241278613795,36.4199988543987,0.0730049361211196,0.0106994837479013,1,-1.93387038967771E-8,,,,,,,,,,,,,,,,,,,,,15.8351449966431,15.8351449966431,26.2996196746826,26.2996196746826,50.2829442706399,5.39184703404594,6.08865165710449,65,1,0,0,1,0.274505615234375,31.7693061828613,2,1,1,15.8351449966431,0,15.8351449966431,,,,,,,,,,,,,,,,,,,,,,,,,,,,,,,,,
,3866183123.19533,15.0288190841675,26.2996196746826,5.61266202381859E-5,6.54730086175869E-9,1,5,12.9061126708984,4.99137430483651,36.4199988543987,0.0731101071655922,0.0107263141082279,1,-1.07925694938462E-8,,,,,,,,,,,,,,,,,,,,,15.0288190841675,15.0288190841675,26.2996196746826,26.2996196746826,50.0152365028034,5.39655063624377,5.3797025680542,65,1,0,0,1,0.27557373046875,31.7693061828613,6,1,1,15.0515518188477,0,15.0288190841675,,,,,,,,,,,,,,,,,,,,,,,,,,,,,,,,,
,3866183308.8077,44.0381240844727,26.2996196746826,5.48713713800877E-5,5.28873518618174E-9,1,5,12.9061126708984,4.99233072120605,36.4199988543987,0.0714995504244857,0.0104531174579367,1,-3.82784058516039E-8,,,,,,,,,,,,,,,,,,,,,44.0381240844727,44.0381240844727,26.2996196746826,26.2996196746826,50.1316991521688,5.39281714616794,6.40616369247437,65,1,0,0,1,0.273666381835938,31.2805480957031,2,1,1,44.0381240844727,0,44.0381240844727,,,,,,,,,,,,,,,,,,,,,,,,,,,,,,,,,
,3866183492.08761,73.0247192382813,26.2996196746826,5.31540210343301E-5,7.07618913701245E-9,1,5,12.9061126708984,4.99203239137771,36.4199988543987,0.0692572049870459,0.0101167012127465,1,-4.3534500851058E-8,,,,,,,,,,,,,,,,,,,,,73.0247192382813,73.0247192382813,26.2996196746826,26.2996196746826,50.1270093810534,5.39451296806308,6.78352165222168,65,1,0,0,1,0.273895263671875,31.2805480957031,2,1,1,73.0247192382813,0,73.0247192382813,,,,,,,,,,,,,,,,,,,,,,,,,,,,,,,,,
,3866183671.02372,102.156410217285,26.2996196746826,5.07027992547956E-5,7.82258066395198E-9,1,5,12.9061126708984,4.99247140305017,36.4199988543987,0.0660718811000606,0.00964894723811676,1,-4.33751282212906E-8,,,,,,,,,,,,,,,,,,,,,102.156410217285,102.156410217285,26.2996196746826,26.2996196746826,50.1254461240149,5.39315050553252,6.94059181213379,65,1,0,0,1,0.272903442382813,31.7693061828613,2,1,1,102.156410217285,0,102.156410217285,,,,,,,,,,,,,,,,,,,,,,,,,,,,,,,,,
,3866183845.30287,131.015029907227,26.2996196746826,4.84902633547563E-5,6.4783887497439E-9,1,5,12.9061126708984,4.99309661299361,36.4199988543987,0.06320230431538,0.0092123200137108,1,-5.46758751427724E-8,,,,,,,,,,,,,,,,,,,,,131.015029907227,131.015029907227,26.2996196746826,26.2996196746826,50.1821141916592,5.39154093843805,7.02849674224854,65,1,0,0,1,0.273361206054687,31.2805480957031,2,1,1,131.015029907227,0,131.015029907227,,,,,,,,,,,,,,,,,,,,,,,,,,,,,,,,,
,3866184021.87789,160.102584838867,26.2996196746826,4.60968675259202E-5,7.32609609121383E-9,1,5,12.9061126708984,4.99323653638341,36.4199988543987,0.0600841191666996,0.00876469704798624,1,-4.68076761051126E-8,,,,,,,,,,,,,,,,,,,,,160.102584838867,160.102584838867,26.2996196746826,26.2996196746826,50.0980891258418,5.39108335506718,7.09368753433228,65,1,0,0,1,0.270462036132813,31.7693061828613,2,1,1,160.102584838867,0,160.102584838867,,,,,,,,,,,,,,,,,,,,,,,,,,,,,,,,,
,3866184196.16257,189.09619140625,26.2996196746826,4.36666311679493E-5,6.37898201914065E-9,1,5,12.9061126708984,4.99306981129512,36.4199988543987,0.056913269075235,0.00830589089220903,1,-4.1531992134025E-8,,,,,,,,,,,,,,,,,,,,,189.09619140625,189.09619140625,26.2996196746826,26.2996196746826,50.2106436326111,5.39032030145849,7.14627742767334,65,1,0,0,1,0.271987915039062,31.7693061828613,2,1,1,189.09619140625,0,189.09619140625,,,,,,,,,,,,,,,,,,,,,,,,,,,,,,,,,
,3866184370.85517,218.003860473633,26.2996196746826,4.16442749754767E-5,7.35866460972476E-9,1,5,12.9061126708984,4.99288966457779,36.4199988543987,0.054276836946015,0.00790604876022141,1,-5.09399289642939E-8,,,,,,,,,,,,,,,,,,,,,218.003860473633,218.003860473633,26.2996196746826,26.2996196746826,50.147722536813,5.39072078558614,7.24814510345459,65,1,0,0,1,0.27313232421875,31.2805480957031,2,1,1,218.003860473633,0,218.003860473633,,,,,,,,,,,,,,,,,,,,,,,,,,,,,,,,,
,3866184545.55806,247.044387817383,26.2996196746826,3.98592112814063E-5,7.67826880395189E-9,1,5,12.9061126708984,4.99314003272317,36.4199988543987,0.0519521692180373,0.00757972929536114,1,-3.951941907456E-8,,,,,,,,,,,,,,,,,,,,,247.044387817383,247.044387817383,26.2996196746826,26.2996196746826,50.2497250585726,5.39093847887084,7.400062084198,65,1,0,0,1,0.272903442382813,32.2580642700195,2,1,1,247.044387817383,0,247.044387817383,,,,,,,,,,,,,,,,,,,,,,,,,,,,,,,,,
,3866184720.98675,276.120513916016,26.2996196746826,3.77702880228102E-5,7.75070657521645E-9,1,5,12.9061126708984,4.99317501917038,36.4199988543987,0.0492309145378331,0.0071761189263009,1,-4.23945157422082E-8,,,,,,,,,,,,,,,,,,,,,276.120513916016,276.120513916016,26.2996196746826,26.2996196746826,50.1699989496111,5.39059179105081,7.47651863098145,65,1,0,0,1,0.27313232421875,31.7693061828613,2,1,1,276.120513916016,0,276.120513916016,,,,,,,,,,,,,,,,,,,,,,,,,,,,,,,,,
,3866185050.72353,300.007339477539,48594.87109375,0.00133082341526936,1.25285319709902E-6,1,2,12.9061126708984,4.99324474323555,36.4199988543987,1.7425483441904,0.199217670649888,10,-4.26491915132916E-5,,,,,,,,,,,,,,,,,,,,,300.006988525391,300.007690429687,48505.1484375,48684.59375,50.0496281576495,5.39080001894394,7.44361019134521,21,1,68,0,0,0.27191162109375,31.7693061828613,1,6,1,300.007690429687,0,300.007339477539,,,,,,,,,,,,,,,,,,,,,,,,,,,,,,,,,
,3866185137.35413,300.00471496582,39943.529296875,0.00113574388114608,1.66665255010983E-6,1,2,12.9061126708984,4.99319133021478,36.4199988543987,1.48420752544633,0.189657459583514,100,-2.13234120556347E-5,,,,,,,,,,,,,,,,,,,,,300.004577636719,300.004852294922,39848.57421875,40038.484375,49.9913968329668,5.39030379976808,7.48747396469116,26,1,0,0,1,0.273284912109375,31.2805480957031,1,6,1,300.004577636719,0,300.00471496582,,,,,,,,,,,,,,,,,,,,,,,,,,,,,,,,,
,3866185201.82854,300.004684448242,33509.3125,0.000993921936151161,1.88150572491506E-6,1,2,12.9061126708984,4.99318044900556,36.4300012588501,1.29832269060513,0.169689141572572,100,-1.58101007417024E-5,,,,,,,,,,,,,,,,,,,,,300.004333496094,300.005035400391,33419.37109375,33599.25390625,50.1309175236495,5.3909026141832,7.54936408996582,26,1,0,0,1,0.272064208984375,31.7693061828613,1,6,1,300.004333496094,0,300.004684448242,,,,,,,,,,,,,,,,,,,,,,,,,,,,,,,,,
,3866185265.58146,300.002395629883,27144.404296875,0.000852823375307219,1.64670349364674E-6,1,2,12.9061126708984,4.99313256281582,36.4199988543987,1.11355962661913,0.148568098292434,100,-1.128649693946E-5,,,,,,,,,,,,,,,,,,,,,300.001953125,300.002838134766,26979.650390625,27309.158203125,50.0949626117649,5.3910784712395,7.63268232345581,26,1,0,0,1,0.272293090820313,31.7693061828613,1,6,1,300.001953125,0,300.002395629883,,,,,,,,,,,,,,,,,,,,,,,,,,,,,,,,,
,3866185328.98429,300.003433227539,20810.1005859375,0.000713407345206831,1.1691727683779E-6,1,2,12.9061126708984,4.99313572046934,36.4199988543987,0.931647040657828,0.123418488268484,100,-1.01032006519805E-5,,,,,,,,,,,,,,,,,,,,,300.003387451172,300.003479003906,20740.24609375,20879.955078125,50.1582745218226,5.39117123138249,7.75434637069702,26,1,0,0,1,0.272064208984375,33.2355842590332,1,6,1,300.003479003906,0,300.003433227539,,,,,,,,,,,,,,,,,,,,,,,,,,,,,,,,,
,3866185391.20847,300.001312255859,14600.10546875,0.000572820429800551,1.03171386280387E-6,1,2,12.9061126708984,4.9931249486234,36.4199988543987,0.748290702204733,0.0974629932912742,100,-9.36595021768747E-6,,,,,,,,,,,,,,,,,,,,,300.0009765625,300.001647949219,14510.20703125,14690.00390625,50.2329200454092,5.39125915321579,7.88241624832153,26,1,0,0,1,0.270919799804687,32.2580642700195,1,6,1,300.001647949219,0,300.001312255859,,,,,,,,,,,,,,,,,,,,,,,,,,,,,,,,,
,3866185453.98267,300.001541137695,8326.59326171875,0.000425731859763378,9.72808314146969E-7,1,2,12.9061126708984,4.9930882978785,36.4300012588501,0.556820800478708,0.0677963993460166,100,-1.0520976061366E-5,,,,,,,,,,,,,,,,,,,,,300.001495361328,300.001586914063,8266.6416015625,8386.544921875,50.1938386194476,5.39134521660182,8.02931499481201,26,1,0,0,1,0.272369384765625,31.7693061828613,1,6,1,300.001586914063,0,300.001541137695,,,,,,,,,,,,,,,,,,,,,,,,,,,,,,,,,
,3866185518.28862,300.000366210937,1900.64892578125,0.000233892786722978,1.06240789534812E-6,1,2,12.9061126708984,4.99311029646546,36.4199988543987,0.308894330181944,0.0169576429139714,100,-2.13490126255286E-5,,,,,,,,,,,,,,,,,,,,,300.000305175781,300.000427246094,1820.66577148438,1980.63208007813,50.3177267397457,5.39128292109442,8.06843948364258,26,1,0,0,1,0.273284912109375,31.7693061828613,1,6,1,300.000305175781,0,300.000366210937,,,,,,,,,,,,,,,,,,,,,,,,,,,,,,,,,
,3866185580.56352,300.001266479492,-4321.65551757812,-0.000288699097032432,2.47765928011473E-6,1,2,12.9061126708984,4.99301362068067,36.4199988543987,-0.375108938755442,-0.062832794528869,100,-5.80281729260211E-6,,,,,,,,,,,,,,,,,,,,,300.0009765625,300.001556396484,-4416.63134765625,-4226.6796875,50.2438628446784,5.39105888137659,8.01095676422119,26,1,0,0,1,0.271072387695313,31.7693061828613,1,6,1,300.0009765625,0,300.001266479492,,,,,,,,,,,,,,,,,,,,,,,,,,,,,,,,,
,3866185659.21763,300.00080871582,-12191.3461914062,-0.000506574841470044,9.98044024576955E-7,1,2,12.9061126708984,4.99313742688002,36.4199988543987,-0.660375876970239,-0.0955768542734006,10,1.08132231322475E-6,,,,,,,,,,,,,,,,,,,,,300.000549316406,300.001068115234,-12276.318359375,-12106.3740234375,50.1188022816015,5.39155341471742,7.96463012695313,26,1,0,0,1,0.270767211914062,31.7693061828613,1,6,1,300.001068115234,0,300.00080871582,,,,,,,,,,,,,,,,,,,,,,,,,,,,,,,,,
,3866185767.93591,300.001159667969,-23056.9365234375,-0.000760299615951693,1.46500060675368E-6,1,2,12.9061126708984,4.9931108760966,36.4199988543987,-0.992230820201385,-0.135930217420351,100,7.39068948474327E-6,,,,,,,,,,,,,,,,,,,,,300.001129150391,300.001190185547,-23146.810546875,-22967.0625,50.1215379814188,5.39135339793278,7.92364072799683,26,1,0,0,1,0.272216796875,31.2805480957031,1,6,1,300.001190185547,0,300.001159667969,,,,,,,,,,,,,,,,,,,,,,,,,,,,,,,,,
,3866185831.74612,300.001724243164,-29449.1044921875,-0.000904403619076617,1.9024937522143E-6,1,2,12.9061126708984,4.99317141374172,36.4199988543987,-1.17967005200137,-0.166080966424004,100,5.42722458224748E-6,,,,,,,,,,,,,,,,,,,,,300.001586914063,300.001861572266,-29604.408203125,-29293.80078125,50.2028273474188,5.39172579669931,7.90660095214844,26,1,0,0,1,0.27130126953125,31.7693061828613,1,6,1,300.001586914063,0,300.001724243164,,,,,,,,,,,,,,,,,,,,,,,,,,,,,,,,,
,3866185894.95033,299.999938964844,-35785.2265625,-0.00104348494137517,1.41679298135425E-6,1,2,12.9061126708984,4.99308962170133,36.4199988543987,-1.36081117993224,-0.193250845346616,100,5.0080153648356E-6,,,,,,,,,,,,,,,,,,,,,299.999847412109,300.000030517578,-35865.22265625,-35705.23046875,50.1231012384572,5.39109852279365,7.88144397735596,26,1,0,0,1,0.273284912109375,31.7693061828613,1,6,1,300.000030517578,0,299.999938964844,,,,,,,,,,,,,,,,,,,,,,,,,,,,,,,,,
,3866185957.28967,299.999328613281,-42027.048828125,-0.00118231406747534,1.88414983976499E-6,1,2,12.9061126708984,4.99292322535521,36.4199988543987,-1.54158157682556,-0.22034634345953,100,4.60385661479118E-6,,,,,,,,,,,,,,,,,,,,,299.999176025391,299.999481201172,-42117.16015625,-41936.9375,50.0183630168803,5.39095787987556,7.86966323852539,26,1,0,0,1,0.272293090820313,31.7693061828613,1,6,1,299.999481201172,0,299.999328613281,,,,,,,,,,,,,,,,,,,,,,,,,,,,,,,,,
,3866186019.7278,300.001541137695,-48282.970703125,-0.00131873545488916,1.72353303675505E-6,1,2,12.9061126708984,4.99300170292242,36.4199988543987,-1.72000746015869,-0.242288032717287,100,7.81197325046046E-6,,,,,,,,,,,,,,,,,,,,,300.001373291016,300.001708984375,-48378.24609375,-48187.6953125,50.005466146313,5.39071625711122,7.86253833770752,26,1,0,0,1,0.272369384765625,31.7693061828613,1,6,1,300.001373291016,0,300.001541137695,,,,,,,,,,,,,,,,,,,,,,,,,,,,,,,,,
,3866186092.61982,300.000396728516,-45081.1328125,-0.00126288093825552,1.75588196431516E-6,1,2,12.9061126708984,4.99305423475869,36.4199988543987,-1.65209605204547,-0.198577074770528,100,3.31510846613192E-5,,,,,,,,,,,,,,,,,,,,,300.000366210937,300.000427246094,-45200.734375,-44961.53125,50.0750310845245,5.39087234589481,7.85014963150024,26,1,0,0,1,0.273208618164062,31.2805480957031,1,6,1,300.000366210937,0,300.000396728516,,,,,,,,,,,,,,,,,,,,,,,,,,,,,,,,,
,3866186156.8398,300.001007080078,-38668.318359375,-0.00111870565205649,1.70000776378828E-6,1,2,12.9061126708984,4.99306093009481,36.4199988543987,-1.46201214084671,-0.185961490023545,100,2.16511102050113E-5,,,,,,,,,,,,,,,,,,,,,300.000823974609,300.001190185547,-38773.109375,-38563.52734375,50.081674926938,5.39081288320067,7.8393726348877,26,1,0,0,1,0.27130126953125,31.2805480957031,1,6,1,300.000823974609,0,300.001007080078,,,,,,,,,,,,,,,,,,,,,,,,,,,,,,,,,
,3866186219.1591,300.001083374023,-32449.7685546875,-0.000978401268269028,1.81877623985634E-6,1,2,12.9061126708984,4.99300634271875,36.4199988543987,-1.27782889397927,-0.168101440232298,100,1.47419304168905E-5,,,,,,,,,,,,,,,,,,,,,300.000885009766,300.001281738281,-32544.525390625,-32355.01171875,50.1465500940341,5.39116397538981,7.82989692687988,26,1,0,0,1,0.27191162109375,31.7693061828613,1,6,1,300.001281738281,0,300.001083374023,,,,,,,,,,,,,,,,,,,,,,,,,,,,,,,,,
,3866186283.63084,300.002197265625,-26012.365234375,-0.000835629229745332,1.54076335826767E-6,1,2,12.9061126708984,4.99305987400266,36.4300012588501,-1.09107266334738,-0.145663185995152,100,1.09872687755196E-5,,,,,,,,,,,,,,,,,,,,,300.002197265625,300.002197265625,-26107.171875,-25917.55859375,50.2215864318803,5.39167450353382,7.82243728637695,24,1,68,0,0,0.272216796875,31.7693061828613,1,6,1,300.002197265625,0,300.002197265625,,,,,,,,,,,,,,,,,,,,,,,,,,,,,,,,,
,3866186346.35053,299.999053955078,-19752.8564453125,-0.000693409523526285,1.44027677493887E-6,1,2,12.9061126708984,4.99296434031686,36.4199988543987,-0.905827244451279,-0.117644336137683,100,1.15917034461512E-5,,,,,,,,,,,,,,,,,,,,,299.9990234375,299.999084472656,-19867.783203125,-19637.9296875,50.1742979064668,5.39182228447062,7.82267618179321,26,1,0,0,1,0.272445678710938,31.7693061828613,1,6,1,299.999084472656,0,299.999053955078,,,,,,,,,,,,,,,,,,,,,,,,,,,,,,,,,
,3866186410.59262,299.999221801758,-13339.7802734375,-0.000545995279138084,1.14012070854784E-6,1,2,12.9061126708984,4.99295129573826,36.4199988543987,-0.713201245794084,-0.0929776712725824,100,8.8633465721195E-6,,,,,,,,,,,,,,,,,,,,,299.999053955078,299.999389648438,-13439.7578125,-13239.802734375,50.1277910095726,5.3919250388411,7.81480646133423,26,1,0,0,1,0.272064208984375,31.2805480957031,1,6,1,299.999053955078,0,299.999221801758,,,,,,,,,,,,,,,,,,,,,,,,,,,,,,,,,
,3866186475.01424,300.000579833984,-6900.02758789063,-0.000389251802559888,8.26605185727851E-7,1,2,12.9061126708984,4.99296834806571,36.4199988543987,-0.509286322155717,-0.0606544840439389,100,1.0640450261881E-5,,,,,,,,,,,,,,,,,,,,,300.000366210937,300.000793457031,-6995.072265625,-6804.98291015625,50.1821141916592,5.39196015703338,7.80801153182983,26,1,0,0,1,0.272445678710938,31.2805480957031,1,6,1,300.000366210937,0,300.000579833984,,,,,,,,,,,,,,,,,,,,,,,,,,,,,,,,,
,3866186537.88763,300.000045776367,-620.347625732422,-0.000152243838890514,2.01590509160117E-6,1,2,12.9061126708984,4.99293539714359,36.4199988543987,-0.20405537625237,0.00939633731446554,100,2.95768943958018E-5,,,,,,,,,,,,,,,,,,,,,299.999877929687,300.000213623047,-670.314392089844,-570.380859375,50.096916683063,5.39214664882821,7.81856250762939,25,1,64,0,0,0.273361206054687,31.7693061828613,1,6,1,299.999877929687,0,300.000045776367,,,,,,,,,,,,,,,,,,,,,,,,,,,,,,,,,
,3866186600.20393,299.999877929687,5612.994140625,0.000328294747560386,2.64378648684433E-6,1,2,12.9061126708984,4.9929605059036,36.4199988543987,0.427065285111543,0.0679385372951433,100,3.90454408898777E-6,,,,,,,,,,,,,,,,,,,,,299.999786376953,299.999969482422,5498.0869140625,5727.9013671875,50.2004824618611,5.39205487222162,7.80143070220947,26,1,0,0,1,0.272216796875,31.7693061828613,1,6,1,299.999969482422,0,299.999877929687,,,,,,,,,,,,,,,,,,,,,,,,,,,,,,,,,
,3866186691.96625,299.999404907227,14788.9912109375,0.000575574572405378,1.17320135100905E-6,1,2,12.9061126708984,4.99290402899945,36.4199988543987,0.750502041408819,0.10704542355487,10,-2.41244595081389E-6,,,,,,,,,,,,,,,,,,,,,299.999389648438,299.999420166016,14619.0283203125,14958.9541015625,50.1723438351688,5.39182680531772,7.80132389068604,26,1,0,0,1,0.272598266601562,31.7693061828613,1,6,1,299.999389648438,0,299.999404907227,,,,,,,,,,,,,,,,,,,,,,,,,,,,,,,,,
,3866186787.50752,300.001235961914,24346.26953125,0.000790103166799214,1.40542856294741E-6,1,2,12.9061126708984,4.99293917387314,36.4199988543987,1.03039725913998,0.145873852796273,100,-4.13353939374109E-6,,,,,,,,,,,,,,,,,,,,,300.001037597656,300.001434326172,24231.13671875,24461.40234375,50.1711713923899,5.39243110861585,7.79922008514404,26,1,0,0,1,0.272293090820313,31.7693061828613,1,6,1,300.001434326172,0,300.001235961914,,,,,,,,,,,,,,,,,,,,,,,,,,,,,,,,,
,3866186849.72145,299.999862670898,30575.51953125,0.000932070043133967,2.45177149899314E-6,1,2,12.9061126708984,4.99293604990722,36.4199988543987,1.21616200172695,0.167846966310273,100,-8.12809831561733E-6,,,,,,,,,,,,,,,,,,,,,299.99951171875,300.000213623047,30480.34375,30670.6953125,50.1395154373611,5.39187662787485,7.79781150817871,26,1,0,0,1,0.27191162109375,31.7693061828613,1,6,1,300.000213623047,0,299.999862670898,,,,,,,,,,,,,,,,,,,,,,,,,,,,,,,,,
,3866186913.487,299.99951171875,36969.517578125,0.00107711877030061,1.55645930166141E-6,1,2,12.9061126708984,4.99293555670686,36.4199988543987,1.40495056561147,0.197168916831225,100,-6.93610684296784E-6,,,,,,,,,,,,,,,,,,,,,299.99951171875,299.99951171875,36804.2109375,37134.82421875,50.112158439188,5.39251540880198,7.79373359680176,26,1,0,0,1,0.272064208984375,33.2355842590332,1,6,1,299.99951171875,0,299.99951171875,,,,,,,,,,,,,,,,,,,,,,,,,,,,,,,,,
,3866186984.94388,300.001205444336,44128.880859375,0.00123030714902721,1.52320980204961E-6,1,2,12.9061126708984,4.99291989383091,36.4199988543987,1.60416792394489,0.229214293045919,100,-4.84924768015786E-6,,,,,,,,,,,,,,,,,,,,,300.000793457031,300.001617431641,44018.66796875,44239.09375,50.0656515422938,5.39183401168901,7.79096794128418,26,1,0,0,1,0.271682739257813,32.2580642700195,1,6,1,300.001617431641,0,300.001205444336,,,,,,,,,,,,,,,,,,,,,,,,,,,,,,,,,
,3866187047.15688,300.000701904297,50000.43359375,0.00135762015093447,4.23970107228933E-7,1,2,12.9061126708984,4.99289638266366,36.4199988543987,1.76933749519203,0.258507364197996,100,-1.07245427462021E-6,,,,,,,,,,,,,,,,,,,,,300.000579833984,300.000823974609,50000.4140625,50000.453125,50.0066385890918,5.392294710658,7.78478193283081,26,1,0,0,1,0.272750854492187,32.2580642700195,1,4,1,300.000579833984,0,300.000701904297,,,,,,,,,,,,,,,,,,,,,,,,,,,,,,,,,