File: LT data/Sherwood/K1/305_SH_FULL_SEQUENCE_2.dat
[Header]
; MPMS3 Data File (default extension .dat)
; Copyright (c) 2007, Quantum Design, Inc. All rights reserved.
TITLE,
FILEOPENTIME,3873084673.75024,09/23/2022,11:02 am
BYAPP,MPMS3 w/ AC,1.0,1.1
INFO,MPMS3 Measurement Release 1.1.16 Build 424, MultiVu Release 2.3.4.19,APPNAME
INFO,Linear Motor Servo Controller,MOTOR_MODULE_NAME
INFO,3101-100 N0,MOTOR_HW_VERSION
INFO,MMC1047,MOTOR_SERIAL_NUMBER
INFO,01.04.28,MOTOR_SOFTWARE_VERSION
INFO,Quantum Design Squid Module,SQUID_MODULE_NAME
INFO,3101-501 B0,SQUID_HW_VERSION
INFO,SQM278,SQUID_SERIAL_NUMBER
INFO,01.03.04,SQUID_SOFTWARE_VERSION
INFO,Quantum Design VSM Oven,OVEN_MODULE_NAME
INFO,3101-201 A3,OVEN_HW_VERSION
INFO,OVB323,OVEN_SERIAL_NUMBER
INFO,01.07.07,OVEN_SOFTWARE_VERSION
INFO,SQUID AC,AC_MODULE_NAME
INFO,3101-401 G0,AC_HW_VERSION
INFO,SAC258,AC_SERIAL_NUMBER
INFO,SQUID AC 00.95.07,AC_SOFTWARE_VERSION
INFO,TCI127,COIL_SERIAL_NUMBER
INFO,0,MOMENT_UNITS
INFO,sndst,SAMPLE_MATERIAL
INFO,,SAMPLE_COMMENT
INFO,,SAMPLE_MASS
INFO,,SAMPLE_VOLUME
INFO,,SAMPLE_MOLECULAR_WEIGHT
INFO,,SAMPLE_SIZE
INFO,,SAMPLE_SHAPE
INFO,Straw,SAMPLE_HOLDER
INFO,Standard,SAMPLE_HOLDER_DETAIL
INFO,61.94,SAMPLE_OFFSET
DATATYPE,COMMENT,1
DATATYPE,TIME,2
STARTUPAXIS,X,2
STARTUPAXIS,Y1,5
FIELDGROUP, VSM,2,3,4,5,6,8,9,10,11,14,15
FIELDGROUP, DC, 2,3,4,14,56,57,58,59,60,61,62,63,64,65,66,67,68,69
FIELDGROUP, AC, 2,3,4,11,16,17,18,19,20,21,22,23,24,25,26,27,28,29,30
STARTUPGROUP, All
[Data]
Comment,Time Stamp (sec),Temperature (K),Magnetic Field (Oe),Moment (emu),M. Std. Err. (emu),Transport Action,Averaging Time (sec),Frequency (Hz),Peak Amplitude (mm),Center Position (mm),Lockin Signal' (V),Lockin Signal (V),Range,M. Quad. Signal (emu),AC Moment (emu),AC M. Std Err. (emu),AC Phase (deg),AC Phase Std. Err. (deg),AC Susceptibility (emu/Oe),AC Suscept. Std Err. (emu/Oe),AC X' (emu/Oe),AC X' Std Err. (emu/Oe),AC X'' (emu/Oe),AC X'' Std Err. (emu/Oe),AC Drive (Oe),AC Frequency (Hz),AC Averaging Time (sec),AC Cycles,AC Range,AC Measure Type,AC Signal' (V),AC Signal'' (V),AC Trim Coil Ratio,AC Trim Coil Phase,Min. Temperature (K),Max. Temperature (K),Min. Field (Oe),Max. Field (Oe),Mass (grams),Motor Lag (deg),Pressure (Torr),Measure Count,Measurement Number,SQUID Status (code),Motor Status (code),Measure Status (code),Motor Current (amps),Motor Temp. (C),Temp. Status (code),Field Status (code),Chamber Status (code),Chamber Temp (K),Redirection State,Evercool Status,Average Temp (K),Rotation Angle (deg),Rotator state,DC Moment Fixed Ctr (emu),DC Moment Err Fixed Ctr (emu),DC Moment Free Ctr (emu),DC Moment Err Free Ctr (emu),DC Fixed Fit,DC Free Fit,DC Calculated Center (mm),DC Calculated Center Err (mm),DC Scan Length (mm),DC Scan Time (s),DC Number of Points,DC Squid Drift,DC Min V (V),DC Max V (V),DC Scans per Measure,Map 01,Map 02,Map 03,Map 04,Map 05,Map 06,Map 07,Map 08,Map 09,Map 10,Map 11,Map 12,Map 13,Map 14,Map 15,Map 16
"FC",3873084922.74018
,3873085802.3833,86.3443870544434,49999.55859375,0.0123635019444869,6.59365540665008E-6,1,2,13.1008939743042,4.97686356124416,36.5700013935566,14.2697451670897,2.12966019757625,10,3.25453216227916E-5,,,,,,,,,,,,,,,,,,,,,86.0806198120117,86.608154296875,49999.55859375,49999.55859375,52.5477129051113,5.75156640227821,7.44562578201294,24,1,68,0,0,0.296478271484375,31.7693061828613,2,1,1,86.0806198120117,0,2084573184,86.3443870544434,,,,,,,,,,,,,,,,,,,,,,,,,,,,,,,,,
,3873085930.23741,64.9043388366699,49999.55859375,0.0173494355422314,1.34850336180211E-5,1,2,13.1008939743042,4.97837888092611,36.5099981427193,20.039406825773,2.94593479151383,100,7.71032390023044E-6,,,,,,,,,,,,,,,,,,,,,64.7873077392578,65.021369934082,49999.55859375,49999.55859375,52.6356461135248,5.74427079153992,7.25471687316895,25,1,64,0,0,0.292205810546875,32.7468223571777,2,1,1,64.7873077392578,0,2084573184,64.9043388366699,,,,,,,,,,,,,,,,,,,,,,,,,,,,,,,,,
,3873086067.0319,41.5114326477051,49999.55859375,0.0278204179903152,1.26987600579784E-5,1,2,13.1008939743042,4.97984298047184,36.4600010216236,32.1489706938222,4.71335131346119,1000,1.54189656224752E-6,,,,,,,,,,,,,,,,,,,,,41.3143577575684,41.7085075378418,49999.55859375,49999.55859375,52.6383818133421,5.73873306401378,6.9211254119873,26,1,0,0,1,0.290679931640625,32.7468223571777,2,1,1,41.3143577575684,0,2084573184,41.5114326477051,,,,,,,,,,,,,,,,,,,,,,,,,,,,,,,,,
,3873086207.21384,18.0329074859619,49999.55859375,0.0514422577261816,0.00011574964243265,1,2,13.1008939743042,4.977063372129,36.4199988543987,59.400248926641,8.70387345959139,1000,-1.20136444815079E-6,,,,,,,,,,,,,,,,,,,,,18.0329074859619,18.0329074859619,49999.55859375,49999.55859375,52.8896753822748,5.75112403483853,5.96902322769165,26,1,0,0,1,0.295944213867188,33.7243423461914,2,1,1,18.0329074859619,0,2084573184,18.0329074859619,,,,,,,,,,,,,,,,,,,,,,,,,,,,,,,,,
,3873086331.04534,2.40600478649139,49999.55859375,0.0863033979430772,4.63740096149351E-5,1,2,13.1008939743042,4.97732314218894,36.4199988543987,99.6345306064078,14.7881895091421,100,0.000158056601587607,,,,,,,,,,,,,,,,,,,,,2.4054594039917,2.40655016899109,49999.55859375,49999.55859375,53.6779477439191,5.75315234608429,2.79822731018066,26,1,0,0,1,0.297317504882812,33.7243423461914,6,1,1,2.40655016899109,0,2084573184,2.40600478649139,,,,,,,,,,,,,,,,,,,,,,,,,,,,,,,,,
,3873086420.29815,2.45782339572906,49999.55859375,0.08620424108268,2.57627692253106E-5,1,2,13.1008939743042,4.97671192286851,36.4199988543987,99.5157610688353,14.6809549644581,100,8.19177809512232E-5,,,,,,,,,,,,,,,,,,,,,2.45727801322937,2.45836877822876,49999.55859375,49999.55859375,53.592750235323,5.75477514917317,2.80294609069824,26,1,0,0,1,0.298004150390625,33.7243423461914,6,1,1,2.45836877822876,0,2084573184,2.45782339572906,,,,,,,,,,,,,,,,,,,,,,,,,,,,,,,,,
,3873086483.75869,2.50447714328766,49999.55859375,0.0861275357080472,1.35368035606479E-5,1,2,13.1008939743042,4.97637337683955,36.4199988543987,99.416509047514,14.6747518854223,100,8.90000217795945E-5,,,,,,,,,,,,,,,,,,,,,2.5043363571167,2.50461792945862,49999.55859375,49999.55859375,53.4989548130153,5.75639536312721,2.83040165901184,26,1,0,0,1,0.296783447265625,33.7243423461914,6,1,1,2.5043363571167,0,2084573184,2.50447714328766,,,,,,,,,,,,,,,,,,,,,,,,,,,,,,,,,
,3873086563.16074,2.54785215854645,49999.55859375,0.0860632692652104,1.99835962513739E-5,1,2,13.1008939743042,4.97627194314068,36.4199988543987,99.3410379086698,14.6527865481069,100,7.97551759573189E-5,,,,,,,,,,,,,,,,,,,,,2.54747700691223,2.54822731018066,49999.55859375,49999.55859375,53.5255301826691,5.75685245394881,2.86778140068054,26,1,0,0,1,0.29693603515625,34.2131004333496,6,1,1,2.54822731018066,0,2084573984,2.54785215854645,,,,,,,,,,,,,,,,,,,,,,,,,,,,,,,,,
,3873086626.68434,2.56913435459137,49999.55859375,0.0860218340607042,2.05129825755178E-5,1,2,13.1008939743042,4.97612637921342,36.4199988543987,99.2897307367502,14.6410594556416,100,7.61899878207019E-5,,,,,,,,,,,,,,,,,,,,,2.56886601448059,2.56940269470215,49999.55859375,49999.55859375,53.4497122163037,5.7577429300079,2.87816286087036,26,1,0,0,1,0.297317504882812,33.2355842590332,6,1,1,2.56940269470215,0,2084573984,2.56913435459137,,,,,,,,,,,,,,,,,,,,,,,,,,,,,,,,,
,3873086690.23033,2.5250039100647,49999.55859375,0.086087591161259,3.01459111360934E-5,1,2,13.1008939743042,4.97599488787159,36.4199988543987,99.3570886672664,14.6848470400817,100,0.000104956244680137,,,,,,,,,,,,,,,,,,,,,2.52313709259033,2.52687072753906,49999.55859375,49999.55859375,53.5595310232557,5.75843432288861,2.86947011947632,26,1,0,0,1,0.2972412109375,33.2355842590332,6,1,1,2.52687072753906,0,2084574048,2.5250039100647,,,,,,,,,,,,,,,,,,,,,,,,,,,,,,,,,
,3873086753.67111,2.51155126094818,49999.55859375,0.0861132939585542,2.83174638805648E-5,1,2,13.1008939743042,4.97575769968769,36.4300012588501,99.376587208031,14.712250524682,100,0.000125781477092011,,,,,,,,,,,,,,,,,,,,,2.50970244407654,2.51340007781982,49999.55859375,49999.55859375,53.4755059574383,5.75904121079817,2.85719680786133,26,1,0,0,1,0.296478271484375,32.7468223571777,6,1,1,2.50970244407654,0,2084574240,2.51155126094818,,,,,,,,,,,,,,,,,,,,,,,,,,,,,,,,,
,3873086837.02297,2.43254041671753,49999.55859375,0.086216550782447,5.79581982703001E-5,1,2,13.1008939743042,4.98629087364717,36.4199988543987,99.7922123267142,14.7672722546018,100,0.000120428756218209,,,,,,,,,,,,,,,,,,,,,2.43194150924683,2.43313932418823,49999.55859375,49999.55859375,53.6756028583615,5.76036101784201,2.82733130455017,26,1,0,0,1,0.298843383789063,33.2355842590332,6,1,1,2.43194150924683,0,2084574176,2.43254041671753,,,,,,,,,,,,,,,,,,,,,,,,,,,,,,,,,
,3873086941.25394,2.31246733665466,49999.55859375,0.0864569448742117,9.90908556907411E-5,1,2,13.1008939743042,4.98718145122801,36.4199988543987,100.06929529025,14.9910285543811,1000,0.000275234576983854,,,,,,,,,,,,,,,,,,,,,2.31246733665466,2.31246733665466,49999.55859375,49999.55859375,53.6052562916307,5.75595166614233,2.76544737815857,26,1,0,0,1,0.294113159179687,33.2355842590332,6,1,1,2.31246733665466,0,2084573984,2.31246733665466,,,,,,,,,,,,,,,,,,,,,,,,,,,,,,,,,
,3873087069.30586,2.09196674823761,49999.55859375,0.0865926633449819,0.000150289152719824,1,2,13.1008939743042,4.98767263978758,36.4199988543987,100.257504763926,14.8986674199188,1000,0.000173808871110878,,,,,,,,,,,,,,,,,,,,,2.09022307395935,2.09371042251587,49999.55859375,49999.55859375,53.4852763139287,5.75523632120934,2.63029646873474,26,1,0,0,1,0.298080444335937,34.2131004333496,2,1,1,2.09022307395935,0,2084574176,2.09196674823761,,,,,,,,,,,,,,,,,,,,,,,,,,,,,,,,,
,3873087495.21554,6.01649188995361,26.2547473907471,0.000415762399952104,1.00630866026686E-6,1,2,13.1008939743042,2.0022812220143,36.4199988543987,0.100835357554447,0.0163052580016445,10,6.15245730023075E-6,,,,,,,,,,,,,,,,,,,,,6.01649188995361,6.01649188995361,26.2547473907471,26.2547473907471,52.7270966502748,5.81748807036376,4.00146961212158,26,1,0,0,1,0.130996704101562,31.2805480957031,6,1,1,6.01649188995361,0,2084574368,6.01649188995361,,,,,,,,,,,,,,,,,,,,,,,,,,,,,,,,,
,3873087702.70467,38.0110473632812,26.2547473907471,0.000216347655196308,1.1724082523604E-7,1,2,13.1008939743042,2.00388111526626,36.4199988543987,0.0525412667340168,0.00856050539040115,1,3.46030229538215E-6,,,,,,,,,,,,,,,,,,,,,38.0110473632812,38.0110473632812,26.2547473907471,26.2547473907471,52.7286599073133,5.79790951049467,6.23397493362427,26,1,0,0,1,0.1385498046875,31.2805480957031,2,1,1,38.0110473632812,0,2084574304,38.0110473632812,,,,,,,,,,,,,,,,,,,,,,,,,,,,,,,,,
,3873087906.38131,70.0303573608398,26.2547473907471,0.000191434334511208,1.29330219890627E-7,1,2,13.1008939743042,1.99864995165094,36.4499986171722,0.0462679617227736,0.00749173951206701,1,2.87368909792481E-6,,,,,,,,,,,,,,,,,,,,,70.0303573608398,70.0303573608398,26.2547473907471,26.2547473907471,52.822455329621,5.85112612965904,6.66463375091553,26,1,0,0,1,0.138397216796875,31.2805480957031,2,1,1,70.0303573608398,0,2084574240,70.0303573608398,,,,,,,,,,,,,,,,,,,,,,,,,,,,,,,,,
,3873088103.21792,102.006050109863,26.2547473907471,0.000182194826721948,1.14116906326693E-7,1,2,13.1008939743042,1.99678239091036,36.5099981427193,0.0439129396504994,0.00741763170926612,1,3.97611475153252E-6,,,,,,,,,,,,,,,,,,,,,102.006050109863,102.006050109863,26.2547473907471,26.2547473907471,52.7822014608806,5.8718386606722,6.85385036468506,26,1,0,0,1,0.145263671875,31.2805480957031,2,1,1,102.006050109863,0,2084574304,102.006050109863,,,,,,,,,,,,,,,,,,,,,,,,,,,,,,,,,
,3873088296.84348,134.024719238281,26.2547473907471,0.000165845186921859,1.85145486016182E-6,1,2,13.1008939743042,1.99898718697563,36.6000011563301,0.04003589154876,0.0069032865070041,1,4.18537267563185E-6,,,,,,,,,,,,,,,,,,,,,134.024719238281,134.024719238281,26.2547473907471,26.2547473907471,52.6583133405825,5.84351950444072,6.96298885345459,26,1,0,0,1,0.138397216796875,30.7917900085449,2,1,1,134.024719238281,0,2084574336,134.024719238281,,,,,,,,,,,,,,,,,,,,,,,,,,,,,,,,,
,3873088490.26985,166.078720092773,26.2547473907471,0.00015696298227134,2.03188721754742E-7,1,2,13.1008939743042,1.99771051343182,36.6999991238117,0.0378903254769733,0.00622211908492495,1,2.70695062587733E-6,,,,,,,,,,,,,,,,,,,,,166.078720092773,166.078720092773,26.2547473907471,26.2547473907471,52.7239701361979,5.85566804002786,7.07146167755127,26,1,0,0,1,0.143051147460938,32.2580642700195,2,1,1,166.078720092773,0,2084574272,166.078720092773,,,,,,,,,,,,,,,,,,,,,,,,,,,,,,,,,
,3873088683.003,198.001754760742,26.2547473907471,0.000149079046765055,1.35116482081562E-7,1,2,13.1008939743042,1.99473962340679,36.8199981749058,0.0359114650147736,0.00571792979957396,1,1.84574155142573E-6,,,,,,,,,,,,,,,,,,,,,198.001754760742,198.001754760742,26.2547473907471,26.2547473907471,52.9213313373037,5.88774665327051,7.21613788604736,24,1,64,0,0,0.143814086914062,31.2805480957031,2,1,1,198.001754760742,0,2084574624,198.001754760742,,,,,,,,,,,,,,,,,,,,,,,,,,,,,,,,,
,3873088875.95804,230.064910888672,26.2547473907471,0.000142530826702941,1.33711843604761E-7,1,2,13.1008939743042,1.99490033728417,36.9700007140636,0.0343006484378996,0.00573145155481741,1,2.85780816398284E-6,,,,,,,,,,,,,,,,,,,,,230.064910888672,230.064910888672,26.2547473907471,26.2547473907471,53.0295868872172,5.88731453126386,7.48540925979614,24,1,64,0,0,0.13519287109375,30.7917900085449,2,1,1,230.064910888672,0,2084574432,230.064910888672,,,,,,,,,,,,,,,,,,,,,,,,,,,,,,,,,
,3873089069.09288,262.075439453125,26.2547473907471,0.00013262851517712,1.41042637244391E-7,1,2,13.1008939743042,1.9943402389342,37.1499992907047,0.0318864188137258,0.00542740793384888,1,3.06130165312042E-6,,,,,,,,,,,,,,,,,,,,,262.075439453125,262.075439453125,26.2547473907471,26.2547473907471,53.2328103022172,5.88117899572182,7.96750640869141,25,1,64,0,0,0.142288208007812,30.7917900085449,2,1,1,262.075439453125,0,2084574624,262.075439453125,,,,,,,,,,,,,,,,,,,,,,,,,,,,,,,,,
,3873089261.58977,294.016723632812,26.2547473907471,0.000116498472022728,9.56018281913957E-8,1,2,13.1008939743042,1.99783041259445,37.3199991881847,0.0281507952078446,0.00444620655385509,1,1.29682863775946E-6,,,,,,,,,,,,,,,,,,,,,294.016723632812,294.016723632812,26.2547473907471,26.2547473907471,52.9611943917845,5.8486112171059,7.89284658432007,26,1,0,0,1,0.141525268554688,30.7917900085449,2,1,1,294.016723632812,0,2084574336,294.016723632812,,,,,,,,,,,,,,,,,,,,,,,,,,,,,,,,,
,3873091099.8893,1.99871623516083,39426.6640625,0.0762438690101529,1.90765054203651E-5,1,2,13.1008939743042,2.00098503262633,36.4100001752377,18.5203808114139,2.63481560837373,100,-0.000320208820805814,,,,,,,,,,,,,,,,,,,,,1.99836611747742,1.99906635284424,39336.65625,39516.671875,53.4672988579864,5.83113703581773,2.52773427963257,24,1,68,0,0,0.132675170898438,30.7917900085449,1,6,1,1.99836611747742,0,2084573440,1.99871623516083,,,,,,,,,,,,,,,,,,,,,,,,,,,,,,,,,
,3873091177.27358,1.99977278709412,31697.61328125,0.0705444181885385,2.19735081659003E-5,1,2,13.1008939743042,2.00058011806766,36.4100001752377,17.1285628396427,2.44236040652158,1000,-0.000273857238645131,,,,,,,,,,,,,,,,,,,,,1.99956786632538,1.99997770786285,31608.044921875,31787.181640625,53.2871334843037,5.83603806925298,2.51923418045044,26,1,0,0,1,0.134506225585938,31.7693061828613,1,6,1,1.99997770786285,0,2084573184,1.99977278709412,,,,,,,,,,,,,,,,,,,,,,,,,,,,,,,,,
,3873091240.78767,2.00009763240814,25356.4931640625,0.0644711062031928,2.15717897284805E-5,1,2,13.1008939743042,2.00043702151673,36.4100001752377,15.6499119725711,2.24473441687729,1000,-0.000196931641806378,,,,,,,,,,,,,,,,,,,,,2.00001430511475,2.00018095970154,25266.74609375,25446.240234375,53.2144420320153,5.83589840590509,2.51289057731628,26,1,0,0,1,0.13397216796875,31.2805480957031,1,6,1,2.00018095970154,0,2084573760,2.00009763240814,,,,,,,,,,,,,,,,,,,,,,,,,,,,,,,,,
,3873091360.03516,2.000035405159,13448.4443359375,0.0472133175484467,2.38243556981444E-5,1,2,13.1008939743042,1.9999851480181,36.4100001752377,11.4552751032445,1.6467357293085,1000,-0.000129451711267118,,,,,,,,,,,,,,,,,,,,,1.99996376037598,2.00010704994202,13373.4931640625,13523.3955078125,52.8951467819094,5.83989579116815,2.5040295124054,26,1,0,0,1,0.135726928710938,31.2805480957031,1,6,1,1.99996376037598,0,2084573664,2.000035405159,,,,,,,,,,,,,,,,,,,,,,,,,,,,,,,,,
,3873091427.36682,1.99996423721313,6717.67431640625,0.0306894683418215,3.63148001088015E-5,1,2,13.1008939743042,1.99942003523951,36.4100001752377,7.44060778852602,1.08028967877349,100,-4.10103027148041E-5,,,,,,,,,,,,,,,,,,,,,1.99988889694214,2.00003957748413,6627.5810546875,6807.767578125,52.8302716148133,5.84563720019739,2.49800491333008,26,1,0,0,1,0.137252807617188,31.2805480957031,1,6,1,2.00003957748413,0,2084573728,1.99996423721313,,,,,,,,,,,,,,,,,,,,,,,,,,,,,,,,,
,3873091490.83844,1.99988543987274,370.786514282227,0.00457389712575718,8.76971652420043E-5,1,2,13.1008939743042,1.99934420044368,36.4100001752377,1.12478438175359,0.0522898567272683,100,-0.00045458674729135,,,,,,,,,,,,,,,,,,,,,1.99980413913727,1.99996674060822,280.681060791016,460.891967773438,52.763442376419,5.84661519355084,2.49741864204407,24,1,68,0,0,0.137863159179688,31.2805480957031,1,6,1,1.99980413913727,0,2084573600,1.99988543987274,,,,,,,,,,,,,,,,,,,,,,,,,,,,,,,,,
,3873091572.21986,1.99994021654129,-7764.27905273437,-0.0326754887238261,3.35357957260655E-5,1,2,13.1008939743042,1.99992472368861,36.4100001752377,-7.91975696889695,-1.19269284112686,100,-0.000129288002975676,,,,,,,,,,,,,,,,,,,,,1.99992895126343,1.99995148181915,-7859.45263671875,-7669.10546875,52.7763392469864,5.84351147788262,2.49298167228699,26,1,0,0,1,0.136489868164062,30.7917900085449,1,6,1,1.99992895126343,0,2084573184,1.99994021654129,,,,,,,,,,,,,,,,,,,,,,,,,,,,,,,,,
,3873091635.70301,2.00010871887207,-14111.0361328125,-0.0479334554537378,3.0316158190449E-5,1,2,13.1008939743042,1.99981972471676,36.4100001752377,-11.6224544828767,-1.71064786907851,100,-2.96372325264969E-5,,,,,,,,,,,,,,,,,,,,,2.0000786781311,2.00013875961304,-14201.197265625,-14020.875,52.8447317424191,5.84320222981939,2.48987579345703,26,1,0,0,1,0.136642456054688,29.8142719268799,1,6,1,2.00013875961304,0,2084573856,2.00010871887207,,,,,,,,,,,,,,,,,,,,,,,,,,,,,,,,,
,3873091699.22758,1.99994248151779,-20473.2216796875,-0.0582778238810904,1.99823366978192E-5,1,2,13.1008939743042,1.99956393641512,36.4100001752377,-14.1272333679327,-2.07932998114572,100,-3.61013829865142E-5,,,,,,,,,,,,,,,,,,,,,1.99979841709137,2.00008654594421,-20563.3515625,-20383.091796875,52.9725280053133,5.84425704647997,2.48445677757263,24,1,68,0,0,0.135879516601562,30.7917900085449,1,6,1,1.99979841709137,0,2084574048,1.99994248151779,,,,,,,,,,,,,,,,,,,,,,,,,,,,,,,,,
,3873091780.60164,2.00004237890244,-28610.4560546875,-0.067556683394774,1.7306515275695E-5,1,2,13.1008939743042,1.99904798330818,36.4100001752377,-16.3691753980126,-2.40483658749237,100,-2.37687416671806E-5,,,,,,,,,,,,,,,,,,,,,1.99975979328156,2.00032496452332,-28700.791015625,-28520.12109375,53.1714524634575,5.8502391099474,2.48406910896301,26,1,0,0,1,0.13824462890625,32.2580642700195,1,6,1,2.00032496452332,0,2084574080,2.00004237890244,,,,,,,,,,,,,,,,,,,,,,,,,,,,,,,,,
,3873091877.90284,1.99980938434601,-38365.591796875,-0.0752579129331236,4.44093996902499E-5,1,2,13.1008939743042,1.99857143842823,36.4100001752377,-18.227033192811,-2.67733564840571,100,-2.46858655992218E-5,,,,,,,,,,,,,,,,,,,,,1.99975109100342,1.9998676776886,-38460.8828125,-38270.30078125,53.3867911205057,5.85504087865673,2.48182129859924,26,1,0,0,1,0.135726928710938,31.7693061828613,1,6,1,1.99975109100342,0,2084573888,1.99980938434601,,,,,,,,,,,,,,,,,,,,,,,,,,,,,,,,,
,3873091991.00997,2.00004523992538,-49698.96875,-0.0821100120079457,0.000546647592673137,1,2,13.1008939743042,1.99791852452867,36.4100001752377,-19.8817971407877,-2.86789111508272,100,0.000185427478735976,,,,,,,,,,,,,,,,,,,,,1.99990379810333,2.00018668174744,-49793.796875,-49604.140625,53.7213281267365,5.85830855586647,2.48174405097961,26,1,0,0,1,0.142059326171875,30.7917900085449,1,6,1,2.00018668174744,0,2084573952,2.00004523992538,,,,,,,,,,,,,,,,,,,,,,,,,,,,,,,,,
,3873092070.34243,1.99957942962646,-43023.62109375,-0.0785213843251944,1.93892800217425E-5,1,2,13.1008939743042,1.99756555268001,36.4100001752377,-19.0156296356163,-2.67931167493134,1000,0.000434870157128126,,,,,,,,,,,,,,,,,,,,,1.99926090240479,1.99989795684814,-43113.59765625,-42933.64453125,53.482931428371,5.86046959997278,2.47699093818665,26,1,0,0,1,0.141372680664062,30.7917900085449,1,6,1,1.99926090240479,0,2084574016,1.99957942962646,,,,,,,,,,,,,,,,,,,,,,,,,,,,,,,,,
,3873092133.83601,1.99983060359955,-36684.419921875,-0.0744652565134679,2.11667064999737E-5,1,2,13.1008939743042,1.99743998985024,36.4100001752377,-18.0286145968292,-2.55827281456475,1000,0.000339385009241639,,,,,,,,,,,,,,,,,,,,,1.99980545043945,1.99985575675964,-36774.4453125,-36594.39453125,53.2871334843037,5.85900284130274,2.47592902183533,26,1,0,0,1,0.142593383789062,30.7917900085449,1,6,1,1.99985575675964,0,2084574144,1.99983060359955,,,,,,,,,,,,,,,,,,,,,,,,,,,,,,,,,
,3873092197.34931,1.99982225894928,-30344.734375,-0.0694215993089307,2.10853758755389E-5,1,2,13.1008939743042,1.99801822351793,36.4100001752377,-16.8141905024936,-2.40361316188598,1000,0.0002449004298494,,,,,,,,,,,,,,,,,,,,,1.99980366230011,1.99984085559845,-30434.7421875,-30254.7265625,53.1315894089768,5.85251050961436,2.47722864151001,26,1,0,0,1,0.141220092773438,31.2805480957031,1,6,1,1.99984085559845,0,2084574144,1.99982225894928,,,,,,,,,,,,,,,,,,,,,,,,,,,,,,,,,
,3873092260.90465,2.00005960464478,-23999.28125,-0.0632063815797363,0.000161617017529839,1,2,13.1008939743042,1.99786777468693,36.4100001752377,-15.3065892370197,-2.18856149446051,1000,0.000221104692632992,,,,,,,,,,,,,,,,,,,,,2.00000596046448,2.00011324882507,-24084.26953125,-23914.29296875,52.9463434499191,5.85420414395111,2.47314834594727,26,1,0,0,1,0.141143798828125,30.7917900085449,1,6,1,2.00000596046448,0,2084573984,2.00005960464478,,,,,,,,,,,,,,,,,,,,,,,,,,,,,,,,,
,3873092357.33466,1.99993336200714,-14369.4189453125,-0.0492153060947358,2.18674643874218E-5,1,2,13.1008939743042,1.99782716519209,36.4100001752377,-11.9169228665283,-1.71094274995057,1000,0.000143666707146652,,,,,,,,,,,,,,,,,,,,,1.99993336200714,1.99993336200714,-14369.4189453125,-14369.4189453125,52.8627091983614,5.8558168198338,2.47266507148743,26,1,0,0,1,0.141448974609375,30.3030319213867,1,6,1,1.99993336200714,0,2084573888,1.99993336200714,,,,,,,,,,,,,,,,,,,,,,,,,,,,,,,,,
,3873092449.3798,1.99995869398117,-5176.37573242188,-0.0257056302597769,3.8598961792021E-5,1,2,13.1008939743042,1.99756405082051,36.4100001752377,-6.22466616914103,-0.880486011433885,100,0.000128485973383463,,,,,,,,,,,,,,,,,,,,,1.99994874000549,1.99996864795685,-5266.388671875,-5086.36279296875,52.7091191943325,5.85927958756741,2.47453045845032,26,1,0,0,1,0.14251708984375,30.3030319213867,1,6,1,1.99996864795685,0,2084573824,1.99995869398117,,,,,,,,,,,,,,,,,,,,,,,,,,,,,,,,,
,3873092522.82744,2.0001049041748,2171.58520507813,0.01128665859701,5.5046985657587E-5,1,2,13.1008939743042,1.99747711420509,36.4100001752377,2.72063704607786,0.46996885391407,100,0.000288289261583344,,,,,,,,,,,,,,,,,,,,,2.00006937980652,2.00014042854309,2081.51684570313,2261.65356445313,52.7251425789767,5.86237820527096,2.47227621078491,24,1,68,0,0,0.138015747070312,30.7917900085449,1,6,1,2.00014042854309,0,2084573440,2.0001049041748,,,,,,,,,,,,,,,,,,,,,,,,,,,,,,,,,
,3873092594.25731,2.00006723403931,9312.017578125,0.0373047309026182,3.2088854659056E-5,1,2,13.1008939743042,1.99716767880766,36.4100001752377,9.01877736994613,1.35397574376673,100,0.000130508935664392,,,,,,,,,,,,,,,,,,,,,2.00003004074097,2.00010442733765,9221.9306640625,9402.1044921875,52.7415567778806,5.86491711829288,2.47045803070068,25,1,68,0,0,0.140762329101562,30.7917900085449,1,6,1,2.00003004074097,0,2084573472,2.00006723403931,,,,,,,,,,,,,,,,,,,,,,,,,,,,,,,,,
,3873092657.79302,2.00000864267349,15669.7524414062,0.051115594435532,2.33681801031193E-5,1,2,13.1008939743042,1.9972493396174,36.4100001752377,12.3630264144763,1.82548125107085,100,5.52066103617684E-5,,,,,,,,,,,,,,,,,,,,,1.9999486207962,2.00006866455078,15584.6904296875,15754.814453125,52.9248486656402,5.86516593630493,2.47011303901672,26,1,0,0,1,0.143890380859375,30.3030319213867,1,6,1,2.00006866455078,0,2084573664,2.00000864267349,,,,,,,,,,,,,,,,,,,,,,,,,,,,,,,,,
,3873092721.29131,1.99997544288635,22017.4296875,0.0606644508316385,1.87795413564692E-5,1,2,13.1008939743042,1.99666085762895,36.4100001752377,14.664595043383,2.16368718558112,100,5.88976500958248E-5,,,,,,,,,,,,,,,,,,,,,1.99981427192688,2.00013661384583,21927.3359375,22107.5234375,52.9791718477267,5.87073022809476,2.47054266929626,26,1,0,0,1,0.144119262695313,31.2805480957031,1,6,1,2.00013661384583,0,2084573632,1.99997544288635,,,,,,,,,,,,,,,,,,,,,,,,,,,,,,,,,
,3873092812.5655,1.99992156028748,31161.1533203125,0.0701926494522886,2.22161194900661E-5,1,2,13.1008939743042,1.9968561526889,36.4100001752377,16.971490230757,2.50077688888673,100,5.48668620565232E-5,,,,,,,,,,,,,,,,,,,,,1.99982833862305,2.0000147819519,31070.82421875,31251.482421875,53.2226491314672,5.87075234539868,2.46950769424438,26,1,0,0,1,0.138473510742188,31.7693061828613,1,6,1,2.0000147819519,0,2084574048,1.99992156028748,,,,,,,,,,,,,,,,,,,,,,,,,,,,,,,,,
,3873092915.79186,1.99995225667954,41510.015625,0.0772971758011875,0.000425676721961135,1,2,13.1008939743042,1.99756934786165,36.4100001752377,18.6935285239293,2.8129135723644,1000,0.000296630647436998,,,,,,,,,,,,,,,,,,,,,1.99974429607391,2.00016021728516,41424.7109375,41595.3203125,53.4731610718807,5.86350509610008,2.46933794021606,26,1,0,0,1,0.144119262695313,31.2805480957031,1,6,1,1.99974429607391,0,2084574240,1.99995225667954,,,,,,,,,,,,,,,,,,,,,,,,,,,,,,,,,
,3873093377.62707,4.56676387786865,26.4278011322021,0.000502318871408426,2.60882385684982E-5,1,2,13.1008939743042,1.99640662722126,36.4100001752377,0.122270951153214,0.0119530992317309,10,-2.41639467291217E-5,,,,,,,,,,,,,,,,,,,,,4.56676387786865,4.56676387786865,26.4278011322021,26.4278011322021,52.7349129354671,5.87114985709546,3.52937459945679,26,1,0,0,1,0.140228271484375,30.3030319213867,6,1,1,4.56676387786865,0,2084574336,4.56676387786865,,,,,,,,,,,,,,,,,,,,,,,,,,,,,,,,,
,3873093583.78605,36.0329208374023,26.4278011322021,0.00019603432618568,2.11205187517094E-6,1,2,13.1008939743042,1.99867213159048,36.4199988543987,0.0474667180073104,0.0070852163836142,1,5.20636260356667E-7,,,,,,,,,,,,,,,,,,,,,36.0329208374023,36.0329208374023,26.4278011322021,26.4278011322021,52.6993488378421,5.84640063045695,6.15963077545166,26,1,0,0,1,0.135040283203125,30.7917900085449,2,1,1,36.0329208374023,0,2084574304,36.0329208374023,,,,,,,,,,,,,,,,,,,,,,,,,,,,,,,,,
,3873093786.6261,68.0039367675781,26.4278011322021,0.000181142730380438,1.13137152571619E-7,1,2,13.1008939743042,1.99531958650446,36.4499986171722,0.0436360860244651,0.00710991978325575,1,2.89855595086114E-6,,,,,,,,,,,,,,,,,,,,,68.0039367675781,68.0039367675781,26.4278011322021,26.4278011322021,52.6153237720248,5.88335412998048,6.59427833557129,26,1,0,0,1,0.147018432617187,32.7468223571777,2,1,1,68.0039367675781,0,2084574304,68.0039367675781,,,,,,,,,,,,,,,,,,,,,,,,,,,,,,,,,
,3873093984.34252,100.031593322754,26.4278011322021,0.000166029790511096,1.3975313333725E-7,1,2,13.1008939743042,1.99445002885999,36.5099981427193,0.0399717730656415,0.00644773425049702,1,2.39304654476351E-6,,,,,,,,,,,,,,,,,,,,,100.031593322754,100.031593322754,26.4278011322021,26.4278011322021,52.6637847402171,5.89046754690624,6.79193782806397,26,1,0,0,1,0.142059326171875,30.7917900085449,2,1,1,100.031593322754,0,2084574368,100.031593322754,,,,,,,,,,,,,,,,,,,,,,,,,,,,,,,,,
,3873094177.76416,132.01301574707,26.4278011322021,0.000156540480653742,1.15501402113438E-7,1,2,13.1008939743042,1.99473695532222,36.5899987518787,0.0377252707909523,0.00589133411293816,1,1.47085331753809E-6,,,,,,,,,,,,,,,,,,,,,132.01301574707,132.01301574707,26.4278011322021,26.4278011322021,52.6614398546594,5.88613540378844,6.90115594863892,26,1,0,0,1,0.149002075195313,30.7917900085449,2,1,1,132.01301574707,0,2084574400,132.01301574707,,,,,,,,,,,,,,,,,,,,,,,,,,,,,,,,,
,3873094370.67482,164.01643371582,26.4278011322021,0.000146929156398857,8.34307585200333E-8,1,2,13.1008939743042,1.99355066533157,36.6900004446506,0.0353607505309885,0.00558034941013569,1,1.61686096424366E-6,,,,,,,,,,,,,,,,,,,,,164.01643371582,164.01643371582,26.4278011322021,26.4278011322021,52.6891876670921,5.89765508274956,6.98985719680786,25,1,64,0,0,0.145187377929687,30.7917900085449,2,1,1,164.01643371582,0,2084574432,164.01643371582,,,,,,,,,,,,,,,,,,,,,,,,,,,,,,,,,
,3873094564.29129,196.077087402344,26.4278011322021,0.000138815834306864,1.46246174989916E-7,1,2,13.1008939743042,1.99048042695085,36.8099994957447,0.0333122894340989,0.00524587346037115,1,1.48201644042765E-6,,,,,,,,,,,,,,,,,,,,,196.077087402344,196.077087402344,26.4278011322021,26.4278011322021,52.9424353073229,5.92235927376967,7.12066888809204,25,1,64,0,0,0.135650634765625,31.2805480957031,2,1,1,196.077087402344,0,2084574432,196.077087402344,,,,,,,,,,,,,,,,,,,,,,,,,,,,,,,,,
,3873094757.14641,228.012817382813,26.4278011322021,0.000131088977600133,1.26563218944488E-7,1,2,13.1008939743042,1.99135209077432,36.9599983096123,0.0314671454895291,0.00507410098763322,1,1.88222074128259E-6,,,,,,,,,,,,,,,,,,,,,228.012817382813,228.012817382813,26.4278011322021,26.4278011322021,52.8634908268806,5.91244554343081,7.39683389663696,26,1,0,0,1,0.133819580078125,30.7917900085449,2,1,1,228.012817382813,0,2084573184,228.012817382813,,,,,,,,,,,,,,,,,,,,,,,,,,,,,,,,,
,3873094950.23236,260.095916748047,26.4278011322021,0.00012521562172691,1.09648700400227E-7,1,2,13.1008939743042,1.99285910374621,37.1400006115437,0.0300912806098794,0.00491605416847627,1,2.05667026322134E-6,,,,,,,,,,,,,,,,,,,,,260.095916748047,260.095916748047,26.4278011322021,26.4278011322021,53.0034023318229,5.89697014853802,7.89285469055176,26,1,0,0,1,0.134353637695312,28.8367557525635,2,1,1,260.095916748047,0,2084574368,260.095916748047,,,,,,,,,,,,,,,,,,,,,,,,,,,,,,,,,
,3873095142.42298,292.046936035156,26.4278011322021,0.000115325067895154,1.2838844082035E-7,1,2,13.1008939743042,1.99519156812775,37.3100005090237,0.0277772084272955,0.00452913945734833,1,1.85837154760549E-6,,,,,,,,,,,,,,,,,,,,,292.046936035156,292.046936035156,26.4278011322021,26.4278011322021,52.9486883354768,5.87231475941732,7.88859367370605,24,1,64,0,0,0.135574340820312,30.7917900085449,2,1,1,292.046936035156,0,2084574336,292.046936035156,,,,,,,,,,,,,,,,,,,,,,,,,,,,,,,,,
,3873095911.62461,278.972106933594,26.1187763214111,0.00018114835748033,1.42719311037817E-7,1,2,13.1008939743042,1.98461343015272,37.2299998998642,0.0431345880787509,0.00744722792002451,1,4.61091658381197E-6,,,,,,,,,,,,,,,,,,,,,278.972106933594,278.972106933594,26.1187763214111,26.1187763214111,52.8423868568614,5.87314892595462,8.89957523345947,26,1,0,0,1,0.138397216796875,30.7917900085449,2,1,1,278.972106933594,0,2084573184,278.972106933594,,,,,,,,,,,,,,,,,,,,,,,,,,,,,,,,,
,3873096100.29167,246.95085144043,26.1187763214111,0.000156287863146399,1.4774748592363E-6,1,2,13.1008939743042,1.98137149186156,37.0899997651577,0.0371556801806862,0.00602276245439898,1,2.37269842340251E-6,,,,,,,,,,,,,,,,,,,,,246.95085144043,246.95085144043,26.1187763214111,26.1187763214111,52.979953476246,5.90866401874751,8.56545066833496,26,1,0,0,1,0.137786865234375,31.2805480957031,2,1,1,246.95085144043,0,2084574112,246.95085144043,,,,,,,,,,,,,,,,,,,,,,,,,,,,,,,,,
,3873096291.6171,214.98991394043,26.1187763214111,0.000145926147505359,2.18320890862651E-7,1,2,13.1008939743042,1.97984129475871,36.9599983096123,0.0346276179931418,0.00570976497395374,1,2.612767310908E-6,,,,,,,,,,,,,,,,,,,,,214.98991394043,214.98991394043,26.1187763214111,26.1187763214111,52.908825280996,5.9314412848318,8.26308441162109,25,1,64,0,0,0.141754150390625,30.7917900085449,2,1,1,214.98991394043,0,2084573184,214.98991394043,,,,,,,,,,,,,,,,,,,,,,,,,,,,,,,,,
,3873096482.36328,182.998321533203,26.1187763214111,0.000142027054425502,1.22130330942719E-7,1,2,13.1008939743042,1.99143207460588,36.8600003421307,0.0340392222901441,0.00588097881154829,1,3.6316491990417E-6,,,,,,,,,,,,,,,,,,,,,182.998321533203,182.998321533203,26.1187763214111,26.1187763214111,52.8017421738614,5.9197789409448,8.02496242523193,26,1,0,0,1,0.134353637695312,31.2805480957031,2,1,1,182.998321533203,0,2084574048,182.998321533203,,,,,,,,,,,,,,,,,,,,,,,,,,,,,,,,,
,3873096674.30369,150.983978271484,26.1187763214111,0.000138064516051663,9.07878145167426E-8,1,2,13.1008939743042,1.99385663457084,36.7499999701977,0.0332324332675159,0.00527640057925959,1,1.64871939519488E-6,,,,,,,,,,,,,,,,,,,,,150.983978271484,150.983978271484,26.1187763214111,26.1187763214111,52.634473670746,5.89839084838423,7.82994699478149,26,1,0,0,1,0.150833129882813,31.2805480957031,2,1,1,150.983978271484,0,2084573952,150.983978271484,,,,,,,,,,,,,,,,,,,,,,,,,,,,,,,,,
,3873096866.53883,118.993202209473,26.1187763214111,0.00013695355868179,8.18872973880655E-8,1,2,13.1008939743042,1.99637680461831,36.6499982774258,0.0330597613243623,0.00513919989689554,1,1.19156487066065E-6,,,,,,,,,,,,,,,,,,,,,118.993202209473,118.993202209473,26.1187763214111,26.1187763214111,52.8134666016498,5.86964933046697,7.65526247024536,26,1,0,0,1,0.140304565429688,31.2805480957031,2,1,1,118.993202209473,0,2084573952,118.993202209473,,,,,,,,,,,,,,,,,,,,,,,,,,,,,,,,,
,3873097058.60968,86.9623641967773,26.1187763214111,0.000136882757340522,8.21884819959641E-8,1,2,13.1008939743042,1.99628031819758,36.5700013935566,0.0330533351845124,0.00504265097361602,1,8.04397896183358E-7,,,,,,,,,,,,,,,,,,,,,86.9623641967773,86.9623641967773,26.1187763214111,26.1187763214111,52.5438047625152,5.87064815064004,7.46372699737549,26,1,0,0,1,0.13824462890625,31.7693061828613,2,1,1,86.9623641967773,0,2084573888,86.9623641967773,,,,,,,,,,,,,,,,,,,,,,,,,,,,,,,,,
,3873097245.09744,54.9988250732422,26.1187763214111,0.000137610303107605,9.45797002428427E-8,1,2,13.1008939743042,1.99835095598196,36.5099981427193,0.0332986343844712,0.00505025543057175,1,6.88227780731644E-7,,,,,,,,,,,,,,,,,,,,,54.9988250732422,54.9988250732422,26.1187763214111,26.1187763214111,52.6125880722075,5.84820549580553,7.19213771820068,26,1,0,0,1,0.139846801757812,29.8142719268799,2,1,1,54.9988250732422,0,2084573184,54.9988250732422,,,,,,,,,,,,,,,,,,,,,,,,,,,,,,,,,
,3873097432.62587,22.9735622406006,26.1187763214111,0.000136228626617882,6.63006180150483E-8,1,2,13.1008939743042,1.99910383377779,36.4499986171722,0.0330047501513649,0.004887695360244,1,2.05011189928627E-7,,,,,,,,,,,,,,,,,,,,,22.9735622406006,22.9735622406006,26.1187763214111,26.1187763214111,52.7962707742267,5.84440603370627,6.50406169891357,26,1,0,0,1,0.1373291015625,30.7917900085449,2,1,1,22.9735622406006,0,2084573856,22.9735622406006,,,,,,,,,,,,,,,,,,,,,,,,,,,,,,,,,
,3873098508.20841,11.03102684021,26.1187763214111,0.000136734978530655,8.59343966185452E-8,1,2,13.1008939743042,1.99458739966133,36.4100001752377,0.0329710150071917,0.00498537063921413,1,6.22240803713679E-7,,,,,,,,,,,,,,,,,,,,,11.03102684021,11.03102684021,26.1187763214111,26.1187763214111,52.7446832919575,5.89514593475431,4.88186693191528,26,1,0,0,1,0.148544311523438,31.2805480957031,6,1,1,11.03102684021,0,2084574304,11.03102684021,,,,,,,,,,,,,,,,,,,,,,,,,,,,,,,,,
,3873098714.37486,43.0024833679199,26.1187763214111,0.000133533337048719,1.39651219018404E-7,1,2,13.1008939743042,1.99819400772585,36.4199988543987,0.0322817300678063,0.00507431584201979,1,1.38819798737759E-6,,,,,,,,,,,,,,,,,,,,,43.0024833679199,43.0024833679199,26.1187763214111,26.1187763214111,52.731004792871,5.85079724098064,6.33714914321899,26,1,0,0,1,0.140914916992188,30.7917900085449,2,1,1,43.0024833679199,0,2084574368,43.0024833679199,,,,,,,,,,,,,,,,,,,,,,,,,,,,,,,,,
,3873098916.30713,75.0045852661133,26.1187763214111,0.000130497891767716,1.21399622021329E-7,1,2,13.1008939743042,1.99287311472203,36.4600010216236,0.0314295587817984,0.00465645717805419,1,2.04646748883252E-7,,,,,,,,,,,,,,,,,,,,,75.0045852661133,75.0045852661133,26.1187763214111,26.1187763214111,52.7087283800729,5.90633365528122,6.70671796798706,26,1,0,0,1,0.135345458984375,31.7693061828613,2,1,1,75.0045852661133,0,2084574336,75.0045852661133,,,,,,,,,,,,,,,,,,,,,,,,,,,,,,,,,
,3873099112.18376,107.004089355469,26.1187763214111,0.000128220833917086,1.28314181195507E-7,1,2,13.1008939743042,1.99166158696248,36.5299992263317,0.0308246447590621,0.00471268447381142,1,7.94328094344242E-7,,,,,,,,,,,,,,,,,,,,,107.004089355469,107.004089355469,26.1187763214111,26.1187763214111,52.6993488378421,5.91811688509931,6.87467575073242,24,1,64,0,0,0.132598876953125,30.7917900085449,2,1,1,107.004089355469,0,2084574432,107.004089355469,,,,,,,,,,,,,,,,,,,,,,,,,,,,,,,,,
,3873099305.48467,139.023544311523,26.1187763214111,0.000125661554602002,1.42140113434164E-7,1,2,13.1008939743042,1.99323318751157,36.6099998354912,0.0302463916146859,0.00468148370269584,1,1.01066099515573E-6,,,,,,,,,,,,,,,,,,,,,139.023544311523,139.023544311523,26.1187763214111,26.1187763214111,52.6571408978036,5.90495069553123,6.97588205337524,26,1,0,0,1,0.139236450195312,31.2805480957031,2,1,1,139.023544311523,0,2084574272,139.023544311523,,,,,,,,,,,,,,,,,,,,,,,,,,,,,,,,,
,3873099499.45405,171.026107788086,26.1187763214111,0.000123840640345809,1.37897278274154E-7,1,2,13.1008939743042,1.99206738596903,36.7100015282631,0.0297847897381903,0.00454215770672656,1,7.20276114763796E-7,,,,,,,,,,,,,,,,,,,,,171.026107788086,171.026107788086,26.1187763214111,26.1187763214111,52.8435592996402,5.91362413371292,7.06694507598877,26,1,0,0,1,0.133285522460938,33.2355842590332,2,1,1,171.026107788086,0,2084574496,171.026107788086,,,,,,,,,,,,,,,,,,,,,,,,,,,,,,,,,
,3873099691.82574,203.019226074219,26.1187763214111,0.000120993234839081,1.01150096918293E-7,1,2,13.1008939743042,1.99101336829912,36.8399992585182,0.0290533623292701,0.00455212261007317,1,1.19795321116759E-6,,,,,,,,,,,,,,,,,,,,,203.019226074219,203.019226074219,26.1187763214111,26.1187763214111,52.8611459413229,5.92999382055307,7.19981813430786,26,1,0,0,1,0.136184692382812,31.7693061828613,2,1,1,203.019226074219,0,2084574368,203.019226074219,,,,,,,,,,,,,,,,,,,,,,,,,,,,,,,,,
,3873099884.66903,235.005401611328,26.1187763214111,0.000119949393015509,8.54475878476045E-8,1,2,13.1008939743042,1.99070769707705,36.9900017976761,0.0287835524008751,0.00458506358251081,1,1.49346668225849E-6,,,,,,,,,,,,,,,,,,,,,235.005401611328,235.005401611328,26.1187763214111,26.1187763214111,52.832616500371,5.9226021598853,7.47655439376831,24,1,64,0,0,0.135955810546875,32.2580642700195,2,1,1,235.005401611328,0,2084574368,235.005401611328,,,,,,,,,,,,,,,,,,,,,,,,,,,,,,,,,
,3873100078.05304,267.106384277344,26.1187763214111,0.000118766432162744,9.34175342337463E-8,1,2,13.1008939743042,1.99199240180778,37.1600016951561,0.0285221512704858,0.00463009186526198,1,1.83059492865849E-6,,,,,,,,,,,,,,,,,,,,,267.106384277344,267.106384277344,26.1187763214111,26.1187763214111,52.9948044181114,5.90774176866051,7.95641946792602,26,1,0,0,1,0.143051147460938,31.2805480957031,2,1,1,267.106384277344,0,2084574336,267.106384277344,,,,,,,,,,,,,,,,,,,,,,,,,,,,,,,,,
,3873100281.49593,299.011138916016,26.1187763214111,0.000113802199190448,1.06371957682893E-7,1,2,13.1008939743042,1.99480361104197,37.3400002717972,0.0274072880122688,0.00442006673129978,1,1.63652424236545E-6,,,,,,,,,,,,,,,,,,,,,299.011138916016,299.011138916016,26.1187763214111,26.1187763214111,52.9471250784383,5.88924636006599,7.68605709075928,26,1,0,0,1,0.145950317382813,31.2805480957031,6,1,1,299.011138916016,0,2084574304,299.011138916016,,,,,,,,,,,,,,,,,,,,,,,,,,,,,,,,,
,3873100594.07197,300.004516601562,41782.59765625,0.00193779131712971,1.39750492278162E-5,1,2,13.1008939743042,1.98337450507586,37.3499989509583,0.473903395152761,-0.00932353915421197,100,-0.000323044704194362,,,,,,,,,,,,,,,,,,,,,300.004119873047,300.004913330078,41692.71484375,41872.48046875,52.8709162978133,5.89098216232199,7.69758605957031,25,1,68,0,0,0.13824462890625,31.2805480957031,1,6,1,300.004119873047,0,2084573184,300.004516601562,,,,,,,,,,,,,,,,,,,,,,,,,,,,,,,,,
,3873100657.57195,300.002227783203,35441.705078125,0.00172652234198102,1.30922639964004E-5,1,2,13.1008939743042,1.98297161908753,37.3600013554096,0.421159194123705,-0.00206809286196555,100,-0.000261693573052608,,,,,,,,,,,,,,,,,,,,,300.002014160156,300.00244140625,35351.7734375,35531.63671875,52.8838131683806,5.89135786260597,7.79899263381958,25,1,68,0,0,0.139694213867188,31.2805480957031,1,6,1,300.002014160156,0,2084573856,300.002227783203,,,,,,,,,,,,,,,,,,,,,,,,,,,,,,,,,
,3873100729.05487,300.001876831055,28301.4326171875,0.00147959901151839,2.08121478633652E-5,1,2,13.1008939743042,1.98294953111097,37.3600013554096,0.360880555321641,-0.00151453409177053,100,-0.000223186631408908,,,,,,,,,,,,,,,,,,,,,300.001861572266,300.001892089844,28211.53125,28391.333984375,52.9459526356594,5.8921863893952,7.96625995635986,25,1,68,0,0,0.139007568359375,31.7693061828613,1,6,1,300.001892089844,0,2084574112,300.001876831055,,,,,,,,,,,,,,,,,,,,,,,,,,,,,,,,,
,3873100792.52065,300.002410888672,21966.033203125,0.00125932930753642,3.06024282338162E-5,1,2,13.1008939743042,1.98286666599524,37.3600013554096,0.307634282701243,-0.00471984126111937,100,-0.00020433916713236,,,,,,,,,,,,,,,,,,,,,300.002288818359,300.002532958984,21871.119140625,22060.947265625,52.8959284104287,5.88958700247507,8.16300106048584,25,1,68,0,0,0.14068603515625,31.2805480957031,1,6,1,300.002288818359,0,2084573856,300.002410888672,,,,,,,,,,,,,,,,,,,,,,,,,,,,,,,,,
,3873100856.06254,300.000823974609,15620.0043945313,0.00100071648092981,4.48387498708097E-5,1,2,13.1008939743042,1.98298541212873,37.3600013554096,0.242803984235645,0.00773315443009581,100,-0.000114252620009877,,,,,,,,,,,,,,,,,,,,,300.000732421875,300.000915527344,15530.078125,15709.9306640625,52.9916779040345,5.88985072648375,8.39845275878906,24,1,68,0,0,0.140151977539062,31.7693061828613,1,6,1,300.000915527344,0,2084573824,300.000823974609,,,,,,,,,,,,,,,,,,,,,,,,,,,,,,,,,
,3873100919.56904,300.000335693359,9275.67626953125,0.000863761199398777,1.38694585743158E-5,1,2,13.1008939743042,1.982639021749,37.3499989509583,0.211443923989115,-0.00655720404521049,100,-0.000154073693764343,,,,,,,,,,,,,,,,,,,,,300.000213623047,300.000457763672,9185.7255859375,9365.626953125,53.0940712400537,5.89158297836957,8.65249347686768,25,1,68,0,0,0.133285522460938,31.7693061828613,1,6,1,300.000457763672,0,2084573888,300.000335693359,,,,,,,,,,,,,,,,,,,,,,,,,,,,,,,,,
,3873100990.98369,300.00163269043,2139.63208007813,0.000591397595290845,2.52772646179493E-5,1,2,13.1008939743042,1.9826550335582,37.3499989509583,0.152237653422786,-0.055424093482574,100,-0.000318997066287309,,,,,,,,,,,,,,,,,,,,,300.001281738281,300.001983642578,2049.60083007813,2229.66333007813,53.0061380316402,5.88989148061971,8.92068576812744,25,1,68,0,0,0.133132934570312,32.2580642700195,1,6,1,300.001281738281,0,2084573664,300.00163269043,,,,,,,,,,,,,,,,,,,,,,,,,,,,,,,,,
,3873101064.40786,300.001541137695,-5204.52172851562,-0.000380306226984313,1.23755249787179E-5,1,2,13.1008939743042,1.98255211165915,37.3499989509583,-0.0851952823998969,-0.0509763590546505,100,-0.000157967959379646,,,,,,,,,,,,,,,,,,,,,300.001525878906,300.001556396484,-5299.54052734375,-5109.5029296875,53.0190349022075,5.89154257675667,9.19928550720215,26,1,0,0,1,0.139541625976562,30.7917900085449,1,6,1,300.001525878906,0,2084573184,300.001541137695,,,,,,,,,,,,,,,,,,,,,,,,,,,,,,,,,
,3873101137.8541,300.000076293945,-12551.3950195313,-0.000819335834907512,5.82680016397457E-6,1,2,13.1008939743042,1.98220447068162,37.3499989509583,-0.19345725913069,-0.0417392157210491,100,-5.49611017242385E-5,,,,,,,,,,,,,,,,,,,,,299.999938964844,300.000213623047,-12641.462890625,-12461.3271484375,53.2031084184864,5.89356242669676,9.47160339355469,26,1,0,0,1,0.135269165039062,31.2805480957031,1,6,1,300.000213623047,0,2084573440,300.000076293945,,,,,,,,,,,,,,,,,,,,,,,,,,,,,,,,,
,3873101237.0853,300.000350952148,-22474.515625,-0.00117662657060711,5.58353064683772E-6,1,2,13.1008939743042,1.9816231234448,37.3499989509583,-0.279796928093467,-0.045355220329683,100,-1.78689789661844E-5,,,,,,,,,,,,,,,,,,,,,300.000213623047,300.00048828125,-22564.595703125,-22384.435546875,53.061242842246,5.89967137140044,9.3871603012085,26,1,0,0,1,0.1312255859375,31.7693061828613,1,6,1,300.00048828125,0,2084573984,300.000350952148,,,,,,,,,,,,,,,,,,,,,,,,,,,,,,,,,
,3873101300.61422,300.000930786133,-28836.5263671875,-0.0013772626497116,7.21642494181039E-6,1,2,13.1008939743042,1.98162905248136,37.3499989509583,-0.327819377050744,-0.0509730363655581,100,-1.20358785452572E-5,,,,,,,,,,,,,,,,,,,,,300.000915527344,300.000946044922,-28931.7421875,-28741.310546875,53.1038415965441,5.90179942909395,9.31291961669922,26,1,0,0,1,0.138092041015625,33.2355842590332,1,6,1,300.000946044922,0,2084573728,300.000930786133,,,,,,,,,,,,,,,,,,,,,,,,,,,,,,,,,
,3873101364.07901,300.000503540039,-35194.904296875,-0.00182494016643708,0.000402800137670342,1,2,13.1008939743042,1.98196891956096,37.3499989509583,-0.421952253057971,-0.153305865935189,100,-0.000375596837900601,,,,,,,,,,,,,,,,,,,,,300.00048828125,300.000518798828,-35285.14453125,-35104.6640625,53.0803927409672,5.89706854480386,9.25216579437256,26,1,0,0,1,0.13153076171875,31.7693061828613,1,6,1,300.00048828125,0,2084573984,300.000503540039,,,,,,,,,,,,,,,,,,,,,,,,,,,,,,,,,
,3873101441.52134,300.000869750977,-42955.431640625,-0.00180598394299439,9.63349176104522E-6,1,2,13.1008939743042,1.98168966182527,37.3499989509583,-0.42913941185408,-0.0719629468652867,1000,-3.72595793894876E-5,,,,,,,,,,,,,,,,,,,,,300.000610351562,300.001129150391,-43040.69140625,-42870.171875,53.0655417991018,5.89991306591004,9.19297885894775,26,1,0,0,1,0.136642456054688,31.7693061828613,1,6,1,300.000610351562,0,2084574176,300.000869750977,,,,,,,,,,,,,,,,,,,,,,,,,,,,,,,,,
,3873101528.82889,299.999740600586,-49143.474609375,-0.00231962344353525,1.51590506181585E-5,1,2,13.1008939743042,1.98170792586903,37.3499989509583,-0.575967394040733,0.0765645327231268,100,0.000661181196283334,,,,,,,,,,,,,,,,,,,,,299.999694824219,299.999786376953,-49233.36328125,-49053.5859375,53.0108278027556,5.9034460535974,9.13362693786621,23,1,68,0,0,0.13671875,31.2805480957031,1,6,1,299.999694824219,0,2084574496,299.999740600586,,,,,,,,,,,,,,,,,,,,,,,,,,,,,,,,,
,3873101592.30847,300.000946044922,-42803.662109375,-0.00203262947625631,1.31776361297591E-5,1,2,13.1008939743042,1.98189157581787,37.3499989509583,-0.500277829613894,0.0362811022755592,100,0.000450081921694538,,,,,,,,,,,,,,,,,,,,,300.000701904297,300.001190185547,-42893.5703125,-42713.75390625,53.1097038104383,5.90158266576063,9.0966739654541,24,1,68,0,0,0.142593383789062,30.7917900085449,1,6,1,300.001190185547,0,2084573824,300.000946044922,,,,,,,,,,,,,,,,,,,,,,,,,,,,,,,,,
,3873101663.76003,299.999969482422,-35675.42578125,-0.00172399644583342,6.07010950788682E-5,1,2,13.1008939743042,1.98264776449293,37.3499989509583,-0.424301068546539,0.0285962825017799,100,0.000372527337920589,,,,,,,,,,,,,,,,,,,,,299.999938964844,300,-35765.40625,-35585.4453125,53.0784386696691,5.89651287801923,9.06065940856934,24,1,68,0,0,0.1416015625,31.2805480957031,1,6,1,300,0,2084573920,299.999969482422,,,,,,,,,,,,,,,,,,,,,,,,,,,,,,,,,
,3873101727.26754,299.99967956543,-29336.2197265625,-0.00151471928862653,2.36898458919886E-5,1,2,13.1008939743042,1.98267348849266,37.3499989509583,-0.370010854931016,0.00606640134592319,100,0.000247415408046655,,,,,,,,,,,,,,,,,,,,,299.999542236328,299.999816894531,-29426.169921875,-29246.26953125,53.1718432777172,5.89244211011355,9.03307437896729,25,1,68,0,0,0.142822265625,31.7693061828613,1,6,1,299.999542236328,0,2084573984,299.99967956543,,,,,,,,,,,,,,,,,,,,,,,,,,,,,,,,,
,3873101806.72251,300.000396728516,-21403.3310546875,-0.00125994573021509,1.23884747861224E-5,1,2,13.1008939743042,1.98252210624664,37.3499989509583,-0.307324769993242,0.00227348607229119,100,0.000194180127753374,,,,,,,,,,,,,,,,,,,,,300.000396728516,300.000396728516,-21488.251953125,-21318.41015625,53.2550867150153,5.89421453652534,9.00207328796387,24,1,68,0,0,0.13702392578125,31.7693061828613,1,6,1,300.000396728516,0,2084574016,300.000396728516,,,,,,,,,,,,,,,,,,,,,,,,,,,,,,,,,
,3873101897.08141,299.999786376953,-12381.931640625,-0.000958497282048585,1.46999970088404E-5,1,2,13.1008939743042,1.98286288714432,37.3499989509583,-0.234135054458,0.00352503477384847,100,0.000155243996927992,,,,,,,,,,,,,,,,,,,,,299.999786376953,299.999786376953,-12381.931640625,-12381.931640625,53.2429714729672,5.89094533170511,8.97648906707764,26,1,0,0,1,0.141448974609375,31.2805480957031,1,6,1,299.999786376953,0,2084573952,299.999786376953,,,,,,,,,,,,,,,,,,,,,,,,,,,,,,,,,
,3873101959.4792,299.999984741211,-6145.54541015625,-0.000780537137109136,3.59564169104751E-5,1,2,13.1008939743042,1.98208063610721,37.3499989509583,-0.193630834814656,0.0240848397377282,100,0.00021540413700031,,,,,,,,,,,,,,,,,,,,,299.999816894531,300.000152587891,-6235.5146484375,-6055.576171875,53.3449739947268,5.89979094235453,8.95570945739746,26,1,0,0,1,0.132675170898438,31.7693061828613,1,6,1,299.999816894531,0,2084573184,299.999984741211,,,,,,,,,,,,,,,,,,,,,,,,,,,,,,,,,
,3873102042.81936,300.001068115234,2191.73376464844,8.03729969966402E-5,2.07091100149869E-5,1,2,13.1008939743042,1.98185559362587,37.3499989509583,0.0123664568900297,0.0491583221216476,100,0.000194439972127443,,,,,,,,,,,,,,,,,,,,,300.001068115234,300.001068115234,2101.640625,2281.82690429687,53.2425806587076,5.90190977127692,8.93698215484619,25,1,68,0,0,0.137786865234375,31.7693061828613,1,6,1,300.001068115234,0,2084573632,300.001068115234,,,,,,,,,,,,,,,,,,,,,,,,,,,,,,,,,
,3873102106.32333,299.999496459961,8542.21826171875,0.000622221488827319,8.31672985435791E-6,1,2,13.1008939743042,1.98154600759197,37.3499989509583,0.144851455524894,0.0451309517605122,100,9.81917298021023E-5,,,,,,,,,,,,,,,,,,,,,299.999359130859,299.999633789063,8452.0634765625,8632.373046875,53.2926048839383,5.90548780247713,8.92003440856934,26,1,0,0,1,0.139694213867188,31.7693061828613,1,6,1,299.999359130859,0,2084573376,299.999496459961,,,,,,,,,,,,,,,,,,,,,,,,,,,,,,,,,
,3873102173.78149,299.998886108398,15289.7880859375,0.000942912642604406,5.63769247063795E-6,1,2,13.1008939743042,1.9806315653929,37.3499989509583,0.223077056433868,0.0426632016068174,10,4.09950549442686E-5,,,,,,,,,,,,,,,,,,,,,299.998687744141,299.999084472656,15195.083984375,15384.4921875,53.4368153457364,5.9166322022505,8.90539932250977,26,1,0,0,1,0.133895874023438,31.7693061828613,1,6,1,299.998687744141,0,2084573920,299.998886108398,,,,,,,,,,,,,,,,,,,,,,,,,,,,,,,,,
,3873102245.26133,300.000640869141,22438.1298828125,0.00118728338327326,5.66018170758945E-6,1,2,13.1008939743042,1.98098643904027,37.3499989509583,0.281670826563131,0.0490689551338417,10,3.20153361885382E-5,,,,,,,,,,,,,,,,,,,,,300.00048828125,300.000793457031,22348.04296875,22528.216796875,53.2836161559672,5.91054279042157,8.89420032501221,24,1,68,0,0,0.13336181640625,31.7693061828613,1,6,1,300.000793457031,0,2084573856,300.000640869141,,,,,,,,,,,,,,,,,,,,,,,,,,,,,,,,,
,3873102338.5118,300.000228881836,31782.287109375,0.0014929308443735,6.6328196949687E-6,1,2,13.1008939743042,1.98118531849051,37.3499989509583,0.354770385363486,0.0581621385686979,100,2.53528578867131E-5,,,,,,,,,,,,,,,,,,,,,300.000183105469,300.000274658203,31692.013671875,31872.560546875,53.3375485237941,5.90921863758437,8.87878608703613,26,1,0,0,1,0.137176513671875,31.7693061828613,1,6,1,300.000274658203,0,2084573984,300.000228881836,,,,,,,,,,,,,,,,,,,,,,,,,,,,,,,,,
,3873102409.94884,299.999618530273,38938.880859375,0.00175186466951953,4.8505495802016E-5,1,2,13.1008939743042,1.98061016136562,37.3499989509583,0.415701661391421,0.0707421141890164,100,4.03757708406677E-5,,,,,,,,,,,,,,,,,,,,,299.999603271484,299.999633789063,38849.00390625,39028.7578125,53.254305086496,5.91711414358171,8.86881351470947,26,1,0,0,1,0.134048461914062,31.7693061828613,1,6,1,299.999603271484,0,2084574080,299.999618530273,,,,,,,,,,,,,,,,,,,,,,,,,,,,,,,,,
,3873102491.36475,300.000778198242,47102.966796875,0.00194839736805877,1.22550496810402E-5,1,2,13.1008939743042,1.98204171830451,37.3499989509583,0.462788256601807,0.0800358860018207,100,5.01466007352066E-5,,,,,,,,,,,,,,,,,,,,,300.000732421875,300.000823974609,47017.85546875,47188.078125,53.198418647371,5.89839152950651,8.85301303863525,26,1,0,0,1,0.13153076171875,31.7693061828613,1,6,1,300.000823974609,0,2084574144,300.000778198242,,,,,,,,,,,,,,,,,,,,,,,,,,,,,,,,,
,3873102525.21005,300.000213623047,50000.2890625,0.00200225645432428,5.16435213852376E-6,1,2,13.1008939743042,1.98166720052069,37.3499989509583,0.47389317123997,0.0925723111643752,100,9.49734914849176E-5,,,,,,,,,,,,,,,,,,,,,300.000030517578,300.000396728516,50000.2890625,50000.2890625,53.2077981896018,5.90194399282132,8.84941005706787,26,1,0,0,1,0.142593383789062,31.2805480957031,1,4,1,300.000396728516,0,2084574112,300.000213623047,,,,,,,,,,,,,,,,,,,,,,,,,,,,,,,,,