File: LT data/Sherwood/D2/224-FC-ZFC-RTSIRM-contsweepwithloop.dat
[Header]
; MPMS3 Data File (default extension .dat)
; Copyright (c) 2007, Quantum Design, Inc. All rights reserved.
TITLE,
FILEOPENTIME,3865685509.89007,06/29/2022,6:29 pm
BYAPP,MPMS3 w/ AC,1.0,1.1
INFO,MPMS3 Measurement Release 1.1.16 Build 424, MultiVu Release 2.3.4.19,APPNAME
INFO,Linear Motor Servo Controller,MOTOR_MODULE_NAME
INFO,3101-100 N2,MOTOR_HW_VERSION
INFO,,MOTOR_SERIAL_NUMBER
INFO,01.04.28,MOTOR_SOFTWARE_VERSION
INFO,Quantum Design Squid Module,SQUID_MODULE_NAME
INFO,3101-501 B0,SQUID_HW_VERSION
INFO,SQM327,SQUID_SERIAL_NUMBER
INFO,01.03.04,SQUID_SOFTWARE_VERSION
INFO,Quantum Design VSM Oven,OVEN_MODULE_NAME
INFO,3101-201 A3,OVEN_HW_VERSION
INFO,OVB365,OVEN_SERIAL_NUMBER
INFO,01.07.07,OVEN_SOFTWARE_VERSION
INFO,SQUID AC,AC_MODULE_NAME
INFO,3101-401 G0,AC_HW_VERSION
INFO,SAC220,AC_SERIAL_NUMBER
INFO,SQUID AC 00.95.07,AC_SOFTWARE_VERSION
INFO,TCI344,COIL_SERIAL_NUMBER
INFO,0,MOMENT_UNITS
INFO,Sndst,SAMPLE_MATERIAL
INFO,,SAMPLE_COMMENT
INFO,170.11,SAMPLE_MASS
INFO,,SAMPLE_VOLUME
INFO,,SAMPLE_MOLECULAR_WEIGHT
INFO,,SAMPLE_SIZE
INFO,,SAMPLE_SHAPE
INFO,Straw,SAMPLE_HOLDER
INFO,Standard,SAMPLE_HOLDER_DETAIL
INFO,61.01,SAMPLE_OFFSET
DATATYPE,COMMENT,1
DATATYPE,TIME,2
STARTUPAXIS,X,2
STARTUPAXIS,Y1,5
FIELDGROUP, VSM,2,3,4,5,6,8,9,10,11,14,15
FIELDGROUP, DC, 2,3,4,14,56,57,58,59,60,61,62,63,64,65,66,67,68,69
FIELDGROUP, AC, 2,3,4,11,16,17,18,19,20,21,22,23,24,25,26,27,28,29,30
STARTUPGROUP, All
[Data]
Comment,Time Stamp (sec),Temperature (K),Magnetic Field (Oe),Moment (emu),M. Std. Err. (emu),Transport Action,Averaging Time (sec),Frequency (Hz),Peak Amplitude (mm),Center Position (mm),Lockin Signal' (V),Lockin Signal (V),Range,M. Quad. Signal (emu),AC Moment (emu),AC M. Std Err. (emu),AC Phase (deg),AC Phase Std. Err. (deg),AC Susceptibility (emu/Oe),AC Suscept. Std Err. (emu/Oe),AC X' (emu/Oe),AC X' Std Err. (emu/Oe),AC X'' (emu/Oe),AC X'' Std Err. (emu/Oe),AC Drive (Oe),AC Frequency (Hz),AC Averaging Time (sec),AC Cycles,AC Range,AC Measure Type,AC Signal' (V),AC Signal'' (V),AC Trim Coil Ratio,AC Trim Coil Phase,Min. Temperature (K),Max. Temperature (K),Min. Field (Oe),Max. Field (Oe),Mass (grams),Motor Lag (deg),Pressure (Torr),Measure Count,Measurement Number,SQUID Status (code),Motor Status (code),Measure Status (code),Motor Current (amps),Motor Temp. (C),Temp. Status (code),Field Status (code),Chamber Status (code),Chamber Temp (K),Redirection State,Average Temp (K),Rotation Angle (deg),Rotator state,DC Moment Fixed Ctr (emu),DC Moment Err Fixed Ctr (emu),DC Moment Free Ctr (emu),DC Moment Err Free Ctr (emu),DC Fixed Fit,DC Free Fit,DC Calculated Center (mm),DC Calculated Center Err (mm),DC Scan Length (mm),DC Scan Time (s),DC Number of Points,DC Squid Drift,DC Min V (V),DC Max V (V),DC Scans per Measure,Map 01,Map 02,Map 03,Map 04,Map 05,Map 06,Map 07,Map 08,Map 09,Map 10,Map 11,Map 12,Map 13,Map 14,Map 15,Map 16
,3865687465.54462,1.99952292442322,26.2620124816895,0.00481113141446575,3.3491484591245E-7,1,5,12.9061126708984,4.99618693192953,41.6800007224083,6.27591223992546,0.917332646064617,100,-3.50297003980475E-6,,,,,,,,,,,,,,,,,,,,,1.99952292442322,1.99952292442322,26.2620124816895,26.2620124816895,49.7447930351495,5.36050216405349,2.62839579582214,65,1,0,0,1,0.266952514648438,30.3030319213867,1,1,1,1.99952292442322,0,1.99952292442322,,,,,,,,,,,,,,,,,,,,,,,,,,,,,,,,,
,3865687640.01496,28.0447959899902,26.2620124816895,0.00085399019431696,1.40394406667552E-7,1,5,12.9061126708984,4.99557700242256,41.6800007224083,1.1136397308816,0.163909620978463,1,2.27997972875331E-7,,,,,,,,,,,,,,,,,,,,,28.0447959899902,28.0447959899902,26.2620124816895,26.2620124816895,49.7823112040726,5.36211057483193,6.08451128005981,65,1,0,0,1,0.268173217773438,30.7917900085449,2,1,1,28.0447959899902,0,28.0447959899902,,,,,,,,,,,,,,,,,,,,,,,,,,,,,,,,,
,3865687812.23026,55.002384185791,26.2620124816895,0.000748724372281715,8.42133989088835E-8,1,5,12.9061126708984,4.99538182449576,41.7100004851818,0.976364938101896,0.14335858070612,1,-6.01439485977153E-8,,,,,,,,,,,,,,,,,,,,,55.002384185791,55.002384185791,26.2620124816895,26.2620124816895,49.7850469038899,5.3613188658749,6.65092468261719,65,1,0,0,1,0.28839111328125,31.7693061828613,2,1,1,55.002384185791,0,55.002384185791,,,,,,,,,,,,,,,,,,,,,,,,,,,,,,,,,
,3865687981.79451,82.00390625,26.2620124816895,0.000691371237781568,8.53126058080043E-8,1,5,12.9061126708984,4.99528675769432,41.7499989271164,0.901580987144465,0.132164226383887,1,-2.16115821949084E-7,,,,,,,,,,,,,,,,,,,,,82.00390625,82.00390625,26.2620124816895,26.2620124816895,49.819438558736,5.36415723025752,6.89574909210205,64,1,64,0,0,0.268173217773438,31.2805480957031,2,1,1,82.00390625,0,82.00390625,,,,,,,,,,,,,,,,,,,,,,,,,,,,,,,,,
,3865688146.05069,109.003089904785,26.2620124816895,0.000648081790002784,5.54142647885433E-8,1,5,12.9061126708984,4.99513193703376,41.7999997735023,0.845096133863457,0.12386060381411,1,-2.20163281463984E-7,,,,,,,,,,,,,,,,,,,,,109.003089904785,109.003089904785,26.2620124816895,26.2620124816895,49.8882218684284,5.36490251439142,7.02664470672607,65,1,0,0,1,0.279159545898438,31.7693061828613,2,1,1,109.003089904785,0,109.003089904785,,,,,,,,,,,,,,,,,,,,,,,,,,,,,,,,,
,3865688310.20586,136.015747070312,26.2620124816895,0.000609618234792664,5.44797471728387E-8,1,5,12.9061126708984,4.99499541443032,41.8700017035007,0.794920267187275,0.116430702025753,1,-2.64102995688655E-7,,,,,,,,,,,,,,,,,,,,,136.015747070312,136.015747070312,26.2620124816895,26.2620124816895,49.8534393993226,5.36530881099893,7.11559200286865,65,1,0,0,1,0.2777099609375,33.2355842590332,2,1,1,136.015747070312,0,136.015747070312,,,,,,,,,,,,,,,,,,,,,,,,,,,,,,,,,
,3865688472.87263,163.044097900391,26.2620124816895,0.000577877636637642,5.6626801652335E-8,1,5,12.9061126708984,4.99490205299949,41.9600009918213,0.753515832582762,0.110339067845997,1,-2.70768595617981E-7,,,,,,,,,,,,,,,,,,,,,163.044097900391,163.044097900391,26.2620124816895,26.2620124816895,49.8014611027937,5.36613148159936,7.18425559997559,64,1,64,0,0,0.278396606445313,31.7693061828613,2,1,1,163.044097900391,0,163.044097900391,,,,,,,,,,,,,,,,,,,,,,,,,,,,,,,,,
,3865688635.99411,190.151916503906,26.2620124816895,0.000545278066956123,2.84869929040669E-8,1,5,12.9061126708984,4.99477611265992,42.0599989593029,0.710983344956927,0.104108011668195,1,-2.57690445739972E-7,,,,,,,,,,,,,,,,,,,,,190.151916503906,190.151916503906,26.2620124816895,26.2620124816895,49.832726243563,5.36484699933358,7.25597429275513,65,1,0,0,1,0.279541015625,31.7693061828613,2,1,1,190.151916503906,0,190.151916503906,,,,,,,,,,,,,,,,,,,,,,,,,,,,,,,,,
,3865688798.11236,217.005157470703,26.2620124816895,0.000507094727309516,3.37554831117834E-8,1,5,12.9061126708984,4.99477367645084,42.1699993312359,0.661204804550091,0.096757581129064,1,-2.8578332375267E-7,,,,,,,,,,,,,,,,,,,,,217.005157470703,217.005157470703,26.2620124816895,26.2620124816895,49.8241283298514,5.36753238671265,7.35535526275635,65,1,0,0,1,0.2691650390625,30.7917900085449,2,1,1,217.005157470703,0,217.005157470703,,,,,,,,,,,,,,,,,,,,,,,,,,,,,,,,,
,3865688961.22453,244.006729125977,26.2620124816895,0.000486084101330706,1.55173655447531E-8,1,5,12.9061126708984,4.99500112940358,42.3099994659424,0.633845966018737,0.0927775505592359,1,-2.56274301198877E-7,,,,,,,,,,,,,,,,,,,,,244.006729125977,244.006729125977,26.2620124816895,26.2620124816895,49.8510945137649,5.36659161243763,7.51335144042969,65,1,0,0,1,0.2685546875,31.7693061828613,2,1,1,244.006729125977,0,244.006729125977,,,,,,,,,,,,,,,,,,,,,,,,,,,,,,,,,
,3865689124.09011,271.013641357422,26.2620124816895,0.000468082970823793,3.92072318395086E-8,1,5,12.9061126708984,4.99477242404347,42.4499996006489,0.610314131300541,0.0894684743351771,1,-1.45168547876109E-7,,,,,,,,,,,,,,,,,,,,,271.013641357422,271.013641357422,26.2620124816895,26.2620124816895,49.7741041046207,5.36825653614066,7.77055501937866,64,1,64,0,0,0.279541015625,31.7693061828613,2,1,1,271.013641357422,0,271.013641357422,,,,,,,,,,,,,,,,,,,,,,,,,,,,,,,,,
,3865689287.97854,298.006042480469,26.2620124816895,0.000447858289346845,2.5933065878546E-8,1,5,12.9061126708984,4.99456269613822,42.6100008189678,0.583886007534192,0.0857584741712706,1,-1.55984887772411E-8,,,,,,,,,,,,,,,,,,,,,298.006042480469,298.006042480469,26.2620124816895,26.2620124816895,49.7455746636687,5.36820378732727,7.64419412612915,65,1,0,0,1,0.279617309570313,30.3030319213867,6,1,1,298.006042480469,0,298.006042480469,,,,,,,,,,,,,,,,,,,,,,,,,,,,,,,,,
,3865690888.06014,1.99998223781586,41840.388671875,0.18108850513756,3.09111209979238E-5,1,2,12.9061126708984,4.99492466356596,41.6800007224083,236.120380599346,34.6386344779511,1000,-3.75642298345798E-5,,,,,,,,,,,,,,,,,,,,,1.99997913837433,1.99998533725739,41735.46484375,41945.3125,50.4326261320726,5.36976873488931,2.60731816291809,26,1,0,0,1,0.278549194335938,31.2805480957031,1,6,1,1.99997913837433,0,1.99998223781586,,,,,,,,,,,,,,,,,,,,,,,,,,,,,,,,,
,3865690947.67819,1.99992680549622,35889.94140625,0.170495519872306,2.66508772943567E-5,1,2,12.9061126708984,4.99492677328784,41.6800007224083,222.308049178669,32.614627890598,1000,-3.36781848524103E-5,,,,,,,,,,,,,,,,,,,,,1.99982595443726,2.00002765655518,35725.38671875,36054.49609375,50.3427388523611,5.36780482951191,2.60364937782288,26,1,0,0,1,0.27923583984375,31.7693061828613,1,6,1,2.00002765655518,0,1.99992680549622,,,,,,,,,,,,,,,,,,,,,,,,,,,,,,,,,
,3865691009.00785,1.99979043006897,29764.8505859375,0.157980565470193,3.08306668727365E-5,1,2,12.9061126708984,4.99487534984244,41.6800007224083,205.990044075009,30.1987966863595,1000,-4.75959774866393E-5,,,,,,,,,,,,,,,,,,,,,1.99975538253784,1.9998254776001,29684.82421875,29844.876953125,50.1684356925726,5.36807554490246,2.60241222381592,26,1,0,0,1,0.278778076171875,31.2805480957031,1,6,1,1.99975538253784,0,1.99979043006897,,,,,,,,,,,,,,,,,,,,,,,,,,,,,,,,,
,3865691066.5576,1.99997460842133,24019.5810546875,0.143329252448081,3.22323867482071E-5,1,2,12.9061126708984,4.9948325353811,41.6800007224083,186.883446499466,27.401742826302,1000,-4.01529581688928E-5,,,,,,,,,,,,,,,,,,,,,1.99991297721863,2.00003623962402,23854.93359375,24184.228515625,50.0316507017072,5.36776012665814,2.60403919219971,26,1,0,0,1,0.289230346679687,31.7693061828613,1,6,1,1.99991297721863,0,1.99997460842133,,,,,,,,,,,,,,,,,,,,,,,,,,,,,,,,,
,3865691123.64296,1.99993014335632,18318.75,0.125742882546272,3.9156487393826E-5,1,2,12.9061126708984,4.99483203045234,41.6800007224083,163.956631226279,24.0148058995327,1000,-5.42199404791985E-5,,,,,,,,,,,,,,,,,,,,,1.99983310699463,2.00002717971802,18223.529296875,18413.970703125,49.9511429642264,5.36693830373433,2.60660600662231,26,1,0,0,1,0.289459228515625,31.2805480957031,1,6,1,1.99983310699463,0,1.99993014335632,,,,,,,,,,,,,,,,,,,,,,,,,,,,,,,,,
,3865691184.09052,2.00000166893005,12283.3071289062,0.101064074190621,5.21252652436242E-5,1,2,12.9061126708984,4.99479385645411,41.6800007224083,131.775632311549,19.3067545368531,1000,-3.94377863606168E-5,,,,,,,,,,,,,,,,,,,,,1.99999856948853,2.00000476837158,12193.2578125,12373.3564453125,49.9030728102937,5.36689703336077,2.61217617988586,26,1,0,0,1,0.269241333007813,31.7693061828613,1,6,1,2.00000476837158,0,2.00000166893005,,,,,,,,,,,,,,,,,,,,,,,,,,,,,,,,,
,3865691250.59128,2.00005102157593,5638.322265625,0.0620245488977208,8.43124194893943E-5,1,2,12.9061126708984,4.99480107609189,41.6800007224083,80.8655884685417,11.8983664504696,100,1.37586787319534E-5,,,,,,,,,,,,,,,,,,,,,1.99994707107544,2.00015497207642,5548.4296875,5728.21484375,49.849922070986,5.36684289814127,2.60390210151672,24,1,68,0,0,0.28961181640625,30.7917900085449,1,6,1,2.00015497207642,0,2.00005102157593,,,,,,,,,,,,,,,,,,,,,,,,,,,,,,,,,
,3865691319.44168,1.99992960691452,-1242.77612304688,-0.012126372409837,0.00124694143825929,1,2,12.9061126708984,4.99472521416786,41.6800007224083,-15.5907259737387,-3.81625757993968,100,-0.00114556991337465,,,,,,,,,,,,,,,,,,,,,1.99976718425751,2.00009202957153,-1297.81982421875,-1187.732421875,49.807323316688,5.36693666932373,2.60639715194702,26,1,0,0,1,0.279006958007813,31.7693061828613,1,6,1,2.00009202957153,0,1.99992960691452,,,,,,,,,,,,,,,,,,,,,,,,,,,,,,,,,
,3865691377.51442,1.99996268749237,-7050.64208984375,-0.0677401935147705,7.68819678452897E-5,1,2,12.9061126708984,4.99476876198244,41.6800007224083,-88.3159038379695,-12.9998379528342,100,-1.89681904920985E-5,,,,,,,,,,,,,,,,,,,,,1.99981641769409,2.00010895729065,-7145.58642578125,-6955.69775390625,49.8167028589187,5.36710778088286,2.58801436424255,26,1,0,0,1,0.289840698242188,31.2805480957031,1,6,1,1.99981641769409,0,1.99996268749237,,,,,,,,,,,,,,,,,,,,,,,,,,,,,,,,,
,3865691439.93506,2.0001425743103,-13291.724609375,-0.103633334034849,5.09025317969729E-5,1,2,12.9061126708984,4.99476202920947,41.6800007224083,-135.109440523047,-19.8994736416408,100,-3.78525302986453E-5,,,,,,,,,,,,,,,,,,,,,2.00008869171143,2.00019645690918,-13386.8564453125,-13196.5927734375,49.8933024538034,5.36768915674072,2.58124256134033,26,1,0,0,1,0.278778076171875,30.7917900085449,1,6,1,2.00019645690918,0,2.0001425743103,,,,,,,,,,,,,,,,,,,,,,,,,,,,,,,,,
,3865691550.1232,2.00016379356384,-24307.015625,-0.142916758043447,3.49689627331746E-5,1,2,12.9061126708984,4.99488164934452,41.6800007224083,-186.353950232542,-27.2839427916218,1000,7.01913201616191E-5,,,,,,,,,,,,,,,,,,,,,2.00016379356384,2.00016379356384,-24307.015625,-24307.015625,50.0812841126784,5.36749979877951,2.55523324012756,26,1,0,0,1,0.289306640625,31.2805480957031,1,6,1,2.00016379356384,0,2.00016379356384,,,,,,,,,,,,,,,,,,,,,,,,,,,,,,,,,
,3865691611.25486,1.99991154670715,-30435.7802734375,-0.158691637269671,3.14086132180384E-5,1,2,12.9061126708984,4.99487846488945,41.6800007224083,-206.920296833072,-30.3149472285892,1000,6.29969138636522E-5,,,,,,,,,,,,,,,,,,,,,1.99990034103394,1.99992275238037,-30525.9609375,-30345.599609375,50.1293542666111,5.36863118664137,2.54978227615356,26,1,0,0,1,0.27923583984375,31.2805480957031,1,6,1,1.99990034103394,0,1.99991154670715,,,,,,,,,,,,,,,,,,,,,,,,,,,,,,,,,
,3865691672.03444,2.00006568431854,-36521.666015625,-0.171184984839318,3.26429375516918E-5,1,2,12.9061126708984,4.99486487098042,41.6800007224083,-223.197966523562,-32.7812998757412,1000,6.70122480571213E-6,,,,,,,,,,,,,,,,,,,,,2.00000214576721,2.00012922286987,-36576.6796875,-36466.65234375,50.3360950099476,5.36931025581619,2.54378795623779,26,1,0,0,1,0.289154052734375,31.7693061828613,1,6,1,2.00012922286987,0,2.00006568431854,,,,,,,,,,,,,,,,,,,,,,,,,,,,,,,,,
,3865691732.34357,1.99842059612274,-42563.037109375,-0.18178238214882,2.62695410341664E-5,1,2,12.9061126708984,4.99485800722546,41.6800007224083,-237.028024179255,-34.720776861046,1000,7.60045037275161E-5,,,,,,,,,,,,,,,,,,,,,1.9977320432663,1.99910914897919,-42678.17578125,-42447.8984375,50.4013609913034,5.36952470653327,2.52568960189819,26,1,0,0,1,0.2801513671875,31.7693061828613,1,6,1,1.99910914897919,0,1.99842059612274,,,,,,,,,,,,,,,,,,,,,,,,,,,,,,,,,
,3865691792.50999,1.99950981140137,-48588.55859375,-0.190886747830173,2.19736917238699E-5,1,2,12.9061126708984,4.99476646962548,41.6800007224083,-248.885127764822,-36.5117652469753,1000,3.91803799225713E-5,,,,,,,,,,,,,,,,,,,,,1.99930965900421,1.99970996379852,-48678.55078125,-48498.56640625,50.50649002714,5.37121219543068,2.5090491771698,26,1,0,0,1,0.279617309570313,31.7693061828613,1,6,1,1.99930965900421,0,1.99950981140137,,,,,,,,,,,,,,,,,,,,,,,,,,,,,,,,,
,3865691851.15253,1.99959832429886,-46093.88671875,-0.187395739334967,2.52576014918642E-5,1,2,12.9061126708984,4.99472322052722,41.6800007224083,-244.32517018664,-35.8795746922414,1000,1.08629890840005E-5,,,,,,,,,,,,,,,,,,,,,1.999307513237,1.99988913536072,-46208.6171875,-45979.15625,50.5377551679092,5.3716035928768,2.49459409713745,26,1,0,0,1,0.268936157226562,31.7693061828613,1,6,1,1.99988913536072,0,1.99959832429886,,,,,,,,,,,,,,,,,,,,,,,,,,,,,,,,,
,3865691908.64929,2.00004535913467,-40355.099609375,-0.17821059145815,3.31785151215871E-5,1,2,12.9061126708984,4.99457773333774,41.6800007224083,-232.352569008342,-34.0350442209009,1000,7.51523422397613E-5,,,,,,,,,,,,,,,,,,,,,1.99985778331757,2.00023293495178,-40520.06640625,-40190.1328125,50.3861192351784,5.37150023425653,2.4913055896759,26,1,0,0,1,0.269851684570313,31.2805480957031,5,6,1,2.00023293495178,0,2.00004535913467,,,,,,,,,,,,,,,,,,,,,,,,,,,,,,,,,
,3865691965.73996,1.99993145465851,-34655.578125,-0.167984309452655,2.38186393790742E-5,1,2,12.9061126708984,4.994616965621,41.6800007224083,-219.02208704694,-32.0808343608747,1000,7.20101418939073E-5,,,,,,,,,,,,,,,,,,,,,1.99981498718262,2.0000479221344,-34750.3359375,-34560.8203125,50.3267154677169,5.37003424322243,2.48043322563171,26,1,0,0,1,0.269775390625,31.2805480957031,1,6,1,2.0000479221344,0,1.99993145465851,,,,,,,,,,,,,,,,,,,,,,,,,,,,,,,,,
,3865692025.53736,2.00021255016327,-28681.9599609375,-0.155007666396324,3.02047390661038E-5,1,2,12.9061126708984,4.99453438793588,41.6800007224083,-202.086878436676,-29.6785505212931,1000,7.67741220907679E-6,,,,,,,,,,,,,,,,,,,,,2.00007033348083,2.0003547668457,-28841.58203125,-28522.337890625,50.1485041653322,5.37041894933988,2.47577714920044,26,1,0,0,1,0.2801513671875,32.7468223571777,1,6,1,2.00007033348083,0,2.00021255016327,,,,,,,,,,,,,,,,,,,,,,,,,,,,,,,,,
,3865692082.62002,1.99991434812546,-22987.15234375,-0.140365823138904,3.85800330267073E-5,1,2,12.9061126708984,4.9943637519448,41.6800007224083,-182.994067275296,-26.8408777335153,1000,3.22535876866643E-5,,,,,,,,,,,,,,,,,,,,,1.99925982952118,2.00056886672974,-23071.861328125,-22902.443359375,50.0586168856207,5.36993505557159,2.47347569465637,26,1,0,0,1,0.270156860351562,30.3030319213867,1,6,1,2.00056886672974,0,1.99991434812546,,,,,,,,,,,,,,,,,,,,,,,,,,,,,,,,,
,3865692141.13163,2.00000703334808,-17142.55078125,-0.121319381105312,4.14127456048571E-5,1,2,12.9061126708984,4.9943684197216,41.6800007224083,-158.162165607768,-23.2082148305743,1000,2.067857382304E-5,,,,,,,,,,,,,,,,,,,,,1.99978280067444,2.00023126602173,-17222.388671875,-17062.712890625,49.9753734483226,5.36980330684286,2.48158931732178,26,1,0,0,1,0.279083251953125,30.7917900085449,1,6,1,1.99978280067444,0,2.00000703334808,,,,,,,,,,,,,,,,,,,,,,,,,,,,,,,,,
,3865692198.7554,1.99967217445374,-11391.9028320312,-0.0961603236701373,5.41368840351731E-5,1,2,12.9061126708984,4.9944633403123,41.6800007224083,-125.370877722165,-18.3628829463936,1000,4.16511954525544E-5,,,,,,,,,,,,,,,,,,,,,1.99953699111938,1.99980735778809,-11551.900390625,-11231.9052734375,49.8983830391784,5.36922981525283,2.48540258407593,26,1,0,0,1,0.270004272460938,31.2805480957031,5,6,1,1.99980735778809,0,1.99967217445374,,,,,,,,,,,,,,,,,,,,,,,,,,,,,,,,,
,3865692259.98284,1.99985665082932,-5276.4267578125,-0.0592167960323111,8.02739442379555E-5,1,2,12.9061126708984,4.99437147459173,41.6800007224083,-77.1940531162761,-11.3690506852947,100,-2.13238386070522E-5,,,,,,,,,,,,,,,,,,,,,1.99972772598267,1.99998557567596,-5356.3095703125,-5196.5439453125,49.8514853280245,5.3690654775931,2.47889113426209,26,1,0,0,1,0.270309448242187,31.2805480957031,1,6,1,1.99972772598267,0,1.99985665082932,,,,,,,,,,,,,,,,,,,,,,,,,,,,,,,,,
,3865692351.81686,1.99986445903778,3903.88244628906,0.0428523360400682,0.000102436552921797,1,2,12.9061126708984,4.99427011414528,41.6800007224083,55.8596239132151,8.22969034696641,100,1.74956261302362E-5,,,,,,,,,,,,,,,,,,,,,1.99981379508972,1.99991512298584,3738.9833984375,4068.78149414063,49.8370252004187,5.36990519395834,2.47729468345642,26,1,0,0,1,0.269775390625,31.2805480957031,5,6,1,1.99991512298584,0,1.99986445903778,,,,,,,,,,,,,,,,,,,,,,,,,,,,,,,,,
,3865692408.94611,1.99978119134903,9618.82861328125,0.0847570536848445,6.3448909644521E-5,1,2,12.9061126708984,4.99422784669583,41.6800007224083,110.485437407056,16.2584349026039,100,2.02098075088736E-5,,,,,,,,,,,,,,,,,,,,,1.99975061416626,1.9998117685318,9528.7236328125,9708.93359375,49.8170936731783,5.36953971117467,2.47125577926636,26,1,0,0,1,0.280075073242187,31.2805480957031,1,6,1,1.99975061416626,0,1.99978119134903,,,,,,,,,,,,,,,,,,,,,,,,,,,,,,,,,
,3865692477.59029,1.99992704391479,16479.48828125,0.117655027757797,4.52647723949734E-5,1,2,12.9061126708984,4.99423339632715,41.6800007224083,153.361548058942,22.6264715468163,100,7.20716541793859E-5,,,,,,,,,,,,,,,,,,,,,1.99991059303284,1.99994349479675,16399.517578125,16559.458984375,49.9777183338803,5.37027549456829,2.46285533905029,26,1,0,0,1,0.27191162109375,31.2805480957031,1,6,1,1.99991059303284,0,1.99992704391479,,,,,,,,,,,,,,,,,,,,,,,,,,,,,,,,,
,3865692571.45125,1.99982112646103,25871.9609375,0.148083896984945,3.38681805590291E-5,1,2,12.9061126708984,4.99420676607748,41.6800007224083,193.047224982699,28.3177961417962,1000,-3.22554301241728E-5,,,,,,,,,,,,,,,,,,,,,1.9997740983963,1.99986815452576,25711.826171875,26032.095703125,50.1383429945822,5.37193508468373,2.44582581520081,26,1,0,0,1,0.270309448242187,31.7693061828613,1,6,1,1.99986815452576,0,1.99982112646103,,,,,,,,,,,,,,,,,,,,,,,,,,,,,,,,,
,3865692630.72332,2.00005143880844,31813.62109375,0.162042726535835,2.10912813181667E-5,1,2,12.9061126708984,4.99426113184085,41.6800007224083,211.251180389982,30.9636011774708,1000,-5.36969693856724E-5,,,,,,,,,,,,,,,,,,,,,1.99978268146515,2.00032019615173,31703.453125,31923.7890625,50.2215864318803,5.37237403722472,2.43947863578796,26,1,0,0,1,0.269775390625,31.7693061828613,1,6,1,1.99978268146515,0,2.00005143880844,,,,,,,,,,,,,,,,,,,,,,,,,,,,,,,,,
,3865692690.35095,1.99982643127441,37781.24609375,0.174016764651286,2.46922391585128E-5,1,2,12.9061126708984,4.99417214460588,41.6800007224083,226.86086908483,33.216137546988,1000,-8.42588026703074E-5,,,,,,,,,,,,,,,,,,,,,1.99965381622314,1.99999904632568,37625.95703125,37936.53515625,50.3235889536399,5.37261943111285,2.44364094734192,26,1,0,0,1,0.269317626953125,30.7917900085449,1,6,1,1.99965381622314,0,1.99982643127441,,,,,,,,,,,,,,,,,,,,,,,,,,,,,,,,,
,3865692749.50657,1.99988788366318,43713.458984375,0.183881092164078,2.0276950332779E-5,1,2,12.9061126708984,4.99419295640111,41.6800007224083,239.71676032333,35.1357331306747,1000,-6.10369827872593E-5,,,,,,,,,,,,,,,,,,,,,1.99971854686737,2.00005722045898,43628.28515625,43798.6328125,50.4631096443226,5.37334699579644,2.43520402908325,26,1,0,0,1,0.269927978515625,31.2805480957031,1,6,1,2.00005722045898,0,1.99988788366318,,,,,,,,,,,,,,,,,,,,,,,,,,,,,,,,,
,3865692809.83461,2.00007915496826,49756.189453125,0.192722499946072,1.61205820297234E-5,1,2,12.9061126708984,4.99423205806154,41.6800007224083,251.238952159851,36.8709838769695,1000,-2.91121624970015E-5,,,,,,,,,,,,,,,,,,,,,1.99994730949402,2.0002110004425,49661.0390625,49851.33984375,50.6155272055727,5.37396861969727,2.43516325950623,24,1,68,0,0,0.27008056640625,31.2805480957031,1,6,1,1.99994730949402,0,2.00007915496826,,,,,,,,,,,,,,,,,,,,,,,,,,,,,,,,,
,3865693318.02191,26.0230274200439,26.4625797271729,0.0007260170338859,8.79895684871219E-8,1,5,12.9061126708984,5.00413588239904,41.6800007224083,0.949061058412948,0.139470643600364,1,3.23340092541585E-8,,,,,,,,,,,,,,,,,,,,,26.0230274200439,26.0230274200439,26.4625797271729,26.4625797271729,49.8319446150437,5.36875069522598,5.98175239562988,65,1,0,0,1,0.269393920898438,30.7917900085449,2,1,1,26.0230274200439,0,26.0230274200439,,,,,,,,,,,,,,,,,,,,,,,,,,,,,,,,,
,3865693490.69471,53.0017356872559,26.4625797271729,0.000660427610234507,6.50573265798053E-8,1,5,12.9061126708984,5.00411951240369,41.7000018060207,0.863360143488453,0.126580252874705,1,-1.92303062146707E-7,,,,,,,,,,,,,,,,,,,,,53.0017356872559,53.0017356872559,26.4625797271729,26.4625797271729,49.8338986863418,5.3689736060331,6.62532615661621,65,1,0,0,1,0.269851684570313,31.2805480957031,2,1,1,53.0017356872559,0,53.0017356872559,,,,,,,,,,,,,,,,,,,,,,,,,,,,,,,,,
,3865693660.37371,80.0015335083008,26.4625797271729,0.000617682391216719,4.34921631980115E-8,1,5,12.9061126708984,5.00396603560526,41.7400002479553,0.807457730840541,0.118300899137667,1,-2.42242681081821E-7,,,,,,,,,,,,,,,,,,,,,80.0015335083008,80.0015335083008,26.4625797271729,26.4625797271729,49.8847045400918,5.36964739187764,6.89741516113281,65,1,0,0,1,0.2691650390625,30.7917900085449,2,1,1,80.0015335083008,0,80.0015335083008,,,,,,,,,,,,,,,,,,,,,,,,,,,,,,,,,
,3865693825.59211,107.135139465332,26.4625797271729,0.000581056455911726,3.77639728372113E-8,1,5,12.9061126708984,5.00379867312487,41.8099984526634,0.759547702324828,0.11125146065291,1,-2.50439813632604E-7,,,,,,,,,,,,,,,,,,,,,107.135139465332,107.135139465332,26.4625797271729,26.4625797271729,49.7995070314957,5.37020489135102,7.04389905929565,65,1,0,0,1,0.270309448242187,31.7693061828613,2,1,1,107.135139465332,0,107.135139465332,,,,,,,,,,,,,,,,,,,,,,,,,,,,,,,,,
,3865693988.3614,134.038360595703,26.4625797271729,0.000547196731465569,2.825562145584E-8,1,5,12.9061126708984,5.00385177245785,41.8599992990494,0.715303585126208,0.104728238207053,1,-2.67867767036081E-7,,,,,,,,,,,,,,,,,,,,,134.038360595703,134.038360595703,26.4625797271729,26.4625797271729,49.8217834442937,5.37037223885055,7.14575624465942,65,1,0,0,1,0.270233154296875,31.2805480957031,2,1,1,134.038360595703,0,134.038360595703,,,,,,,,,,,,,,,,,,,,,,,,,,,,,,,,,
,3865694151.32717,161.013168334961,26.4625797271729,0.0005196661318664,3.21968522168828E-8,1,5,12.9061126708984,5.00377711101889,41.9499985873699,0.67931091333071,0.0993895589030939,1,-3.06038170964981E-7,,,,,,,,,,,,,,,,,,,,,161.013168334961,161.013168334961,26.4625797271729,26.4625797271729,49.8401517144957,5.370553718858,7.22535705566406,65,1,0,0,1,0.27069091796875,31.2805480957031,2,1,1,161.013168334961,0,161.013168334961,,,,,,,,,,,,,,,,,,,,,,,,,,,,,,,,,
,3865694314.73811,188.142166137695,26.4625797271729,0.000491113494230249,3.87226519087663E-8,1,5,12.9061126708984,5.00381852090458,42.0500002801418,0.64200893902233,0.0938291526542208,1,-3.66198271694892E-7,,,,,,,,,,,,,,,,,,,,,188.142166137695,188.142166137695,26.4625797271729,26.4625797271729,49.809277387986,5.37069731504302,7.28359699249268,64,1,64,0,0,0.269317626953125,32.2580642700195,2,1,1,188.142166137695,0,188.142166137695,,,,,,,,,,,,,,,,,,,,,,,,,,,,,,,,,
,3865694477.24444,215.024688720703,26.4625797271729,0.000448452268754848,5.10080993984098E-8,1,5,12.9061126708984,5.00378665368792,42.1600006520748,0.586219609347384,0.0857808892324472,1,-2.55515354777137E-7,,,,,,,,,,,,,,,,,,,,,215.024688720703,215.024688720703,26.4625797271729,26.4625797271729,49.8436690428322,5.37113264386324,7.38521862030029,63,1,64,0,0,0.271377563476562,31.2805480957031,2,1,1,215.024688720703,0,215.024688720703,,,,,,,,,,,,,,,,,,,,,,,,,,,,,,,,,
,3865694640.55855,242.085815429687,26.4625797271729,0.000426736694921724,2.97702214311754E-8,1,5,12.9061126708984,5.00390621224095,42.3000007867813,0.557852719047018,0.0816217269951919,1,-2.49332694340571E-7,,,,,,,,,,,,,,,,,,,,,242.085815429687,242.085815429687,26.4625797271729,26.4625797271729,49.7776214329572,5.37116948108118,7.63068437576294,63,1,64,0,0,0.269622802734375,31.7693061828613,2,1,1,242.085815429687,0,242.085815429687,,,,,,,,,,,,,,,,,,,,,,,,,,,,,,,,,
,3865694802.577,269.114074707031,26.4625797271729,0.000413686548079054,3.72275598698022E-8,1,5,12.9061126708984,5.00400309140229,42.4400009214878,0.540809321998801,0.0791155940475747,1,-2.51026764123364E-7,,,,,,,,,,,,,,,,,,,,,269.114074707031,269.114074707031,26.4625797271729,26.4625797271729,49.8139671591014,5.3703690809774,8.005690574646,64,1,64,0,0,0.270919799804687,31.7693061828613,2,1,1,269.114074707031,0,269.114074707031,,,,,,,,,,,,,,,,,,,,,,,,,,,,,,,,,
,3865694965.58411,296.076995849609,26.4625797271729,0.000399942097065814,2.45227410228997E-8,1,5,12.9061126708984,5.00400395345968,42.6100008189678,0.522833281678118,0.076542517843551,1,-2.0025423265296E-7,,,,,,,,,,,,,,,,,,,,,296.076995849609,296.076995849609,26.4625797271729,26.4625797271729,49.7444022208899,5.36913223152185,7.78062295913696,63,1,64,0,0,0.268478393554687,31.2805480957031,2,1,1,296.076995849609,0,296.076995849609,,,,,,,,,,,,,,,,,,,,,,,,,,,,,,,,,
,3865695723.99918,278.985473632813,26.0865154266357,0.00051087210425973,5.09927990734773E-8,1,5,12.9061126708984,5.00358518779522,42.5000004470348,0.667787771454388,0.0976457751334888,1,-3.44181316682767E-7,,,,,,,,,,,,,,,,,,,,,278.985473632813,278.985473632813,26.0865154266357,26.0865154266357,49.7932540033418,5.37027804682635,8.36906147003174,63,1,64,0,0,0.269622802734375,31.2805480957031,2,1,1,278.985473632813,0,278.985473632813,,,,,,,,,,,,,,,,,,,,,,,,,,,,,,,,,
,3865695886.4613,251.998931884766,26.0865154266357,0.000489709562422826,4.76857320062098E-8,1,5,12.9061126708984,5.00341672831528,42.3800013959408,0.639980625441843,0.0943745438688154,1,2.65420205942749E-7,,,,,,,,,,,,,,,,,,,,,251.998931884766,251.998931884766,26.0865154266357,26.0865154266357,49.8112314592841,5.37186856355521,8.1671314239502,63,1,64,0,0,0.270004272460938,31.7693061828613,2,1,1,251.998931884766,0,251.998931884766,,,,,,,,,,,,,,,,,,,,,,,,,,,,,,,,,
,3865696047.21246,225,26.0865154266357,0.000443679994969076,6.61777110704326E-8,1,5,12.9061126708984,5.00347591816987,42.2599986195564,0.579773906196267,0.0859289716730435,1,5.64589528093502E-7,,,,,,,,,,,,,,,,,,,,,225,225,26.0865154266357,26.0865154266357,49.7741041046207,5.3717277038891,8.03002166748047,64,1,64,0,0,0.271682739257813,31.2805480957031,2,1,1,225,0,225,,,,,,,,,,,,,,,,,,,,,,,,,,,,,,,,,
,3865696197.36277,199.990692138672,26.0865154266357,0.000416226980222727,2.37904828529004E-8,1,5,12.9061126708984,5.00362425286414,42.1800017356873,0.54404793790053,0.0797619285161748,1,-1.23326944862561E-7,,,,,,,,,,,,,,,,,,,,,199.990692138672,199.990692138672,26.0865154266357,26.0865154266357,49.7479195492264,5.37124441610301,7.92556619644165,64,1,64,0,0,0.2740478515625,32.2580642700195,2,1,1,199.990692138672,0,199.990692138672,,,,,,,,,,,,,,,,,,,,,,,,,,,,,,,,,
,3865696359.48814,172.79753112793,26.0865154266357,0.000412778413011079,4.09564751997537E-8,1,5,12.9061126708984,5.0039193387674,42.0800000429153,0.539613315679005,0.0789139824037717,1,-2.70432110024093E-7,,,,,,,,,,,,,,,,,,,,,172.79753112793,172.79753112793,26.0865154266357,26.0865154266357,49.8909575682457,5.36932645504493,7.83415365219116,65,1,0,0,1,0.269317626953125,31.2805480957031,2,1,1,172.79753112793,0,172.79753112793,,,,,,,,,,,,,,,,,,,,,,,,,,,,,,,,,
,3865696521.05052,145.941467285156,26.0865154266357,0.000408694244451617,2.72559508012331E-8,1,5,12.9061126708984,5.00376997439875,41.9999994337559,0.534260758120344,0.078069481340599,1,-3.13992927957447E-7,,,,,,,,,,,,,,,,,,,,,145.941467285156,145.941467285156,26.0865154266357,26.0865154266357,49.8088865737264,5.36886749938949,7.74245071411133,65,1,0,0,1,0.270233154296875,30.7917900085449,2,1,1,145.941467285156,0,145.941467285156,,,,,,,,,,,,,,,,,,,,,,,,,,,,,,,,,
,3865696683.2155,118.984397888184,26.0865154266357,0.000404761784276379,3.96827046879506E-8,1,5,12.9061126708984,5.00381731299509,41.9399999082088,0.529132702423037,0.0772811975565779,1,-3.40137006397006E-7,,,,,,,,,,,,,,,,,,,,,118.984397888184,118.984397888184,26.0865154266357,26.0865154266357,49.6916422958418,5.36897490976314,7.64165687561035,63,1,64,0,0,0.270309448242187,31.2805480957031,2,1,1,118.984397888184,0,118.984397888184,,,,,,,,,,,,,,,,,,,,,,,,,,,,,,,,,
,3865696845.38977,91.8270568847656,26.0865154266357,0.000401221646236162,1.87694557800462E-8,1,5,12.9061126708984,5.00339431840292,41.8500006198883,0.524441265668967,0.0766061824859577,1,-3.2953556702498E-7,,,,,,,,,,,,,,,,,,,,,91.8270568847656,91.8270568847656,26.0865154266357,26.0865154266357,49.8350711291207,5.37018906408173,7.53019666671753,65,1,0,0,1,0.269927978515625,31.2805480957031,2,1,1,91.8270568847656,0,91.8270568847656,,,,,,,,,,,,,,,,,,,,,,,,,,,,,,,,,
,3865697004.98519,64.870849609375,26.0865154266357,0.000397963686048834,2.62279745146929E-8,1,5,12.9061126708984,5.00361791085428,41.7900010943413,0.520213172644997,0.0760032793817485,1,-3.15846998662231E-7,,,,,,,,,,,,,,,,,,,,,64.870849609375,64.870849609375,26.0865154266357,26.0865154266357,49.758471534236,5.36977186092479,7.33846378326416,64,1,64,0,0,0.269393920898438,32.7468223571777,2,1,1,64.870849609375,0,64.870849609375,,,,,,,,,,,,,,,,,,,,,,,,,,,,,,,,,
,3865697162.2338,37.8832092285156,26.0865154266357,0.000395562512362909,2.37925509057994E-8,1,5,12.9061126708984,5.00359069206015,41.7300015687943,0.517040032481815,0.0757511835175814,1,-1.55523124639931E-7,,,,,,,,,,,,,,,,,,,,,37.8832092285156,37.8832092285156,26.0865154266357,26.0865154266357,49.751436877563,5.36972334903844,7.02162408828735,65,1,0,0,1,0.270462036132813,31.7693061828613,2,1,1,37.8832092285156,0,37.8832092285156,,,,,,,,,,,,,,,,,,,,,,,,,,,,,,,,,
,3865697324.31032,10.8107399940491,26.0865154266357,0.000392870749055301,1.80337896488042E-8,1,5,12.9061126708984,5.00341552806993,41.6899994015694,0.513490407343347,0.0752732475901373,1,-1.22918485688222E-7,,,,,,,,,,,,,,,,,,,,,10.8033695220947,10.8181104660034,26.0865154266357,26.0865154266357,49.804196802611,5.36991394609653,5.64757394790649,65,1,0,0,1,0.2716064453125,31.7693061828613,2,1,1,10.8033695220947,0,10.8107399940491,,,,,,,,,,,,,,,,,,,,,,,,,,,,,,,,,
,3865697899.34238,18.0055408477783,26.0865154266357,0.000393653215756159,2.83441941203684E-8,1,5,12.9061126708984,5.00362007696596,41.6899994015694,0.514526928656963,0.07553381155957,1,-4.18120298389576E-8,,,,,,,,,,,,,,,,,,,,,18.0055408477783,18.0055408477783,26.0865154266357,26.0865154266357,49.7846560896303,5.36986070539976,5.66337633132935,65,1,0,0,1,0.270309448242187,31.7693061828613,2,1,1,18.0055408477783,0,18.0055408477783,,,,,,,,,,,,,,,,,,,,,,,,,,,,,,,,,
,3865698073.75916,45.0818977355957,26.0865154266357,0.000396061211479633,1.32124439574831E-8,1,5,12.9061126708984,5.0034071046085,41.7100004851818,0.517684729071348,0.0757105116888292,1,-2.56930358612281E-7,,,,,,,,,,,,,,,,,,,,,45.0818977355957,45.0818977355957,26.0865154266357,26.0865154266357,49.7338502358803,5.36923779373112,6.51010179519653,65,1,0,0,1,0.271835327148438,32.7468223571777,2,1,1,45.1019821166992,0,45.0818977355957,,,,,,,,,,,,,,,,,,,,,,,,,,,,,,,,,
,3865698243.98847,72.0002746582031,26.0865154266357,0.000397458109489881,1.24049219722397E-8,1,5,12.9061126708984,5.00319122714982,41.7400002479553,0.519480559743781,0.0759638010424823,1,-2.64838885191786E-7,,,,,,,,,,,,,,,,,,,,,72.0002746582031,72.0002746582031,26.0865154266357,26.0865154266357,49.809277387986,5.37187829140374,6.88048934936523,65,1,0,0,1,0.272750854492187,31.7693061828613,2,1,1,72.0002746582031,0,72.0002746582031,,,,,,,,,,,,,,,,,,,,,,,,,,,,,,,,,
,3865698410.36354,99.0061492919922,26.0865154266357,0.000398582146899439,2.27312943034649E-8,1,5,12.9061126708984,5.00307980208678,41.7799986898899,0.520935054339699,0.0761652976419169,1,-2.73973873987743E-7,,,,,,,,,,,,,,,,,,,,,99.0061492919922,99.0061492919922,26.0865154266357,26.0865154266357,49.844841485611,5.37242370290352,7.04624509811401,65,1,0,0,1,0.271759033203125,30.7917900085449,2,1,1,99.0061492919922,0,99.0061492919922,,,,,,,,,,,,,,,,,,,,,,,,,,,,,,,,,
,3865698573.88825,126.166007995605,26.0865154266357,0.000399780801971806,2.10700811117167E-8,1,5,12.9061126708984,5.00327458794506,41.8500006198883,0.522526043072342,0.0764263758951405,1,-2.53477895350535E-7,,,,,,,,,,,,,,,,,,,,,126.166007995605,126.166007995605,26.0865154266357,26.0865154266357,49.8374160146784,5.37158970704743,7.12769889831543,64,1,64,0,0,0.270156860351562,31.2805480957031,2,1,1,126.166007995605,0,126.166007995605,,,,,,,,,,,,,,,,,,,,,,,,,,,,,,,,,
,3865698736.90895,153.017532348633,26.0865154266357,0.000400632592023791,2.97246565367747E-8,1,5,12.9061126708984,5.00311965294014,41.9199988245964,0.523613388795666,0.0766081708856551,1,-2.369712590909E-7,,,,,,,,,,,,,,,,,,,,,153.017532348633,153.017532348633,26.0865154266357,26.0865154266357,49.7752765473995,5.3723190801919,7.19689702987671,63,1,64,0,0,0.270462036132813,31.7693061828613,2,1,1,153.017532348633,0,153.017532348633,,,,,,,,,,,,,,,,,,,,,,,,,,,,,,,,,
,3865698899.66818,180.015899658203,26.0865154266357,0.000400381427137342,1.69651492229373E-8,1,5,12.9061126708984,5.0032324234179,42.0200005173683,0.523296171272997,0.076599749917827,1,-2.08365369655104E-7,,,,,,,,,,,,,,,,,,,,,180.015899658203,180.015899658203,26.0865154266357,26.0865154266357,49.8421057857937,5.37269571524274,7.27253150939941,64,1,64,0,0,0.270462036132813,31.7693061828613,2,1,1,180.048828125,0,180.015899658203,,,,,,,,,,,,,,,,,,,,,,,,,,,,,,,,,
,3865699063.24003,207.122055053711,26.0865154266357,0.000399310668788,2.18691747443887E-8,1,5,12.9061126708984,5.0034407838659,42.1300008893013,0.521942022436183,0.0762979050734805,1,-2.85425727636706E-7,,,,,,,,,,,,,,,,,,,,,207.122055053711,207.122055053711,26.0865154266357,26.0865154266357,49.8917391967649,5.37147348671521,7.33876466751099,64,1,64,0,0,0.27099609375,31.2805480957031,2,1,1,207.122055053711,0,207.122055053711,,,,,,,,,,,,,,,,,,,,,,,,,,,,,,,,,
,3865699225.3731,234.070861816406,26.0865154266357,0.000398326061563823,2.55749144271496E-8,1,5,12.9061126708984,5.00357676926784,42.2599986195564,0.520669262945323,0.0761506387187849,1,-2.55670200787372E-7,,,,,,,,,,,,,,,,,,,,,234.070861816406,234.070861816406,26.0865154266357,26.0865154266357,49.7670694479476,5.37176102112864,7.47534370422363,63,1,64,0,0,0.268478393554687,31.7693061828613,2,1,1,234.070861816406,0,234.070861816406,,,,,,,,,,,,,,,,,,,,,,,,,,,,,,,,,
,3865699388.23545,261.017517089844,26.0865154266357,0.000398008948807594,2.02764411818001E-8,1,5,12.9061126708984,5.0035719952779,42.3999987542629,0.520254084852621,0.0760897184768287,1,-2.55615145772778E-7,,,,,,,,,,,,,,,,,,,,,261.017517089844,261.017517089844,26.0865154266357,26.0865154266357,49.736195121438,5.37158792057203,7.7505669593811,64,1,64,0,0,0.2703857421875,32.2580642700195,2,1,1,261.017517089844,0,261.017517089844,,,,,,,,,,,,,,,,,,,,,,,,,,,,,,,,,
,3865699550.72909,288.016296386719,26.0865154266357,0.00039621922274121,2.87868885773657E-8,1,5,12.9061126708984,5.00361542024371,42.5699986517429,0.517929127345048,0.0756928287057274,1,-2.97048708235583E-7,,,,,,,,,,,,,,,,,,,,,288.016296386719,288.016296386719,26.0865154266357,26.0865154266357,49.7487011777457,5.37191855262458,7.69385385513306,64,1,64,0,0,0.2703857421875,31.2805480957031,2,1,1,288.016296386719,0,288.016296386719,,,,,,,,,,,,,,,,,,,,,,,,,,,,,,,,,
,3865699856.19132,300.005523681641,44111.59375,0.00889743556810846,2.33757345980088E-6,1,2,12.9061126708984,5.00337625198034,42.6100008189678,11.634272971632,1.66888343504815,100,-3.01977676212796E-5,,,,,,,,,,,,,,,,,,,,,300.005523681641,300.005523681641,44111.59375,44111.59375,49.7018034665918,5.37195533955856,7.68027305603027,26,1,0,0,1,0.27191162109375,31.7693061828613,1,6,1,300.005523681641,0,300.005523681641,,,,,,,,,,,,,,,,,,,,,,,,,,,,,,,,,
,3865699925.08876,300.00471496582,37238.44921875,0.00773680185292597,2.44561821244726E-6,1,2,12.9061126708984,5.00334697632435,42.6100008189678,10.11545680284,1.45859521942601,100,-2.05791882773135E-5,,,,,,,,,,,,,,,,,,,,,300.004638671875,300.004791259766,37183.51171875,37293.38671875,49.7057116091879,5.37171469197144,7.72220659255981,26,1,0,0,1,0.2716064453125,31.7693061828613,1,6,1,300.004791259766,0,300.00471496582,,,,,,,,,,,,,,,,,,,,,,,,,,,,,,,,,
,3865700007.6554,300.003051757812,28996.2900390625,0.00637427952767145,2.23056284125127E-6,1,2,12.9061126708984,5.0033960682694,42.6100008189678,8.33446809229483,1.19954590672256,100,-1.86334978770313E-5,,,,,,,,,,,,,,,,,,,,,300.002960205078,300.003143310547,28936.388671875,29056.19140625,49.783874461111,5.37156893702431,7.80876111984253,24,1,68,0,0,0.272293090820313,31.2805480957031,1,6,1,300.003143310547,0,300.003051757812,,,,,,,,,,,,,,,,,,,,,,,,,,,,,,,,,
,3865700068.04733,300.002365112305,22961.5791015625,0.00536640462174467,2.26399732409553E-6,1,2,12.9061126708984,5.00344745547282,42.6100008189678,7.0160408580392,1.01476842236781,100,-1.19570447394983E-5,,,,,,,,,,,,,,,,,,,,,300.002227783203,300.002502441406,22846.947265625,23076.2109375,49.7729316618418,5.37181936620603,7.91432762145996,26,1,0,0,1,0.27069091796875,31.2805480957031,1,6,1,300.002227783203,0,300.002365112305,,,,,,,,,,,,,,,,,,,,,,,,,,,,,,,,,
,3865700126.57005,300.00146484375,17120.7509765625,0.00437869689375908,2.20607469149693E-6,1,2,12.9061126708984,5.00334881137097,42.6100008189678,5.7248720759517,0.825802677946331,100,-1.1417290362472E-5,,,,,,,,,,,,,,,,,,,,,300.001434326172,300.001495361328,17065.857421875,17175.64453125,49.7334594216207,5.37246307568894,8.03350925445557,26,1,0,0,1,0.271224975585938,31.2805480957031,1,6,1,300.001434326172,0,300.00146484375,,,,,,,,,,,,,,,,,,,,,,,,,,,,,,,,,
,3865700187.00426,300.002029418945,11089.4448242187,0.00333156486202908,2.09988981205769E-6,1,2,12.9061126708984,5.00328815559037,42.6100008189678,4.35617951600629,0.625306224056834,100,-1.09834614383088E-5,,,,,,,,,,,,,,,,,,,,,300.001892089844,300.002166748047,10974.349609375,11204.5400390625,49.8100590165053,5.3726003847016,8.20016670227051,25,1,68,0,0,0.272064208984375,32.2580642700195,1,6,1,300.001892089844,0,300.002029418945,,,,,,,,,,,,,,,,,,,,,,,,,,,,,,,,,
,3865700249.32296,300.000930786133,4858.91723632812,0.00218176166011592,2.47072994606009E-6,1,2,12.9061126708984,5.00348281990262,42.6100008189678,2.85439828181035,0.399406830580003,100,-1.49308154237152E-5,,,,,,,,,,,,,,,,,,,,,300.000762939453,300.001098632812,4739.0458984375,4978.78857421875,49.804196802611,5.37233487209988,8.36805629730225,26,1,0,0,1,0.270919799804687,31.2805480957031,1,6,1,300.000762939453,0,300.000930786133,,,,,,,,,,,,,,,,,,,,,,,,,,,,,,,,,
,3865700319.26691,300.002136230469,-2132.45031738281,-0.000760130406249396,4.28275321054618E-6,1,2,12.9061126708984,5.00345349307412,42.6100008189678,-0.991947175903257,-0.156327413267966,100,-7.93861771708296E-6,,,,,,,,,,,,,,,,,,,,,300.002136230469,300.002136230469,-2137.439453125,-2127.46118164062,49.6955504384379,5.37220466176997,8.57723236083984,26,1,0,0,1,0.269775390625,32.2580642700195,1,6,1,300.002136230469,0,300.002136230469,,,,,,,,,,,,,,,,,,,,,,,,,,,,,,,,,
,3865700382.04331,300.000625610352,-8405.85595703125,-0.0025642193541195,2.55433133210245E-6,1,2,12.9061126708984,5.00336946886452,42.6100008189678,-3.35128332719968,-0.492399797650202,10,-4.46195398557817E-8,,,,,,,,,,,,,,,,,,,,,300.000213623047,300.001037597656,-8495.85546875,-8315.8564453125,49.7354134929187,5.37194584731953,8.67571640014648,26,1,0,0,1,0.271453857421875,31.7693061828613,1,6,1,300.001037597656,0,300.000625610352,,,,,,,,,,,,,,,,,,,,,,,,,,,,,,,,,
,3865700484.8247,300.000732421875,-18686.6630859375,-0.00456514206495275,2.4875817993718E-6,1,2,12.9061126708984,5.00338204461186,42.6100008189678,-5.96829081518472,-0.863710730997517,100,9.80900251030377E-6,,,,,,,,,,,,,,,,,,,,,300.000366210937,300.001098632812,-18816.61328125,-18556.712890625,49.7213441795726,5.37184420998458,8.58383750915527,26,1,0,0,1,0.2703857421875,31.7693061828613,1,6,1,300.001098632812,0,300.000732421875,,,,,,,,,,,,,,,,,,,,,,,,,,,,,,,,,
,3865700545.20939,300.001190185547,-24726.9697265625,-0.00561467568057465,2.45326855608189E-6,1,2,12.9061126708984,5.00331947383909,42.6100008189678,-7.33965537950292,-1.06652682936822,100,8.79981815099366E-6,,,,,,,,,,,,,,,,,,,,,300.001037597656,300.001342773438,-24816.849609375,-24637.08984375,49.6842168249091,5.3718649677903,8.5401782989502,26,1,0,0,1,0.271224975585938,32.2580642700195,1,6,1,300.001342773438,0,300.001190185547,,,,,,,,,,,,,,,,,,,,,,,,,,,,,,,,,
,3865700603.98109,300.000625610352,-30615.9208984375,-0.00660838837507215,3.03774987478366E-6,1,2,12.9061126708984,5.00335522221144,42.6100008189678,-8.63865931312484,-1.25591438388044,100,9.88601535120362E-6,,,,,,,,,,,,,,,,,,,,,300.000274658203,300.0009765625,-30736.091796875,-30495.75,49.6588138980341,5.3714356977806,8.50642776489258,26,1,0,0,1,0.270919799804687,31.2805480957031,1,6,1,300.000274658203,0,300.000625610352,,,,,,,,,,,,,,,,,,,,,,,,,,,,,,,,,
,3865700691.58171,300.001602172852,-39391.984375,-0.0080952335637622,3.06306492164052E-6,1,2,12.9061126708984,5.00320418944621,42.6199994981289,-10.5813744251393,-1.54169577228038,100,9.60535695573626E-6,,,,,,,,,,,,,,,,,,,,,300.00146484375,300.001739501953,-39562.09765625,-39221.87109375,49.7033667236303,5.37199870918301,8.46917247772217,26,1,0,0,1,0.270538330078125,31.7693061828613,1,6,1,300.001739501953,0,300.001602172852,,,,,,,,,,,,,,,,,,,,,,,,,,,,,,,,,
,3865700759.88935,300.001403808594,-46234.19140625,-0.00920092692584321,2.11028463629417E-6,1,2,12.9061126708984,5.00327843991373,42.6100008189678,-12.0272343120911,-1.74995517621931,100,1.27159302836422E-5,,,,,,,,,,,,,,,,,,,,,300.001403808594,300.001403808594,-46234.19140625,-46234.19140625,49.641618070611,5.37182551313903,8.44551372528076,26,1,0,0,1,0.269927978515625,31.7693061828613,1,6,1,300.001403808594,0,300.001403808594,,,,,,,,,,,,,,,,,,,,,,,,,,,,,,,,,
,3865700829.55972,300.000076293945,-47301.4375,-0.00942141359518831,2.29404126557015E-6,1,2,12.9061126708984,5.00322252380761,42.6100008189678,-12.3206574551127,-1.75509960096259,100,4.11505045209077E-5,,,,,,,,,,,,,,,,,,,,,299.999908447266,300.000244140625,-47416.359375,-47186.515625,49.6724923971206,5.37149013993855,8.43123149871826,25,1,68,0,0,0.272064208984375,31.7693061828613,1,6,1,299.999908447266,0,300.000076293945,,,,,,,,,,,,,,,,,,,,,,,,,,,,,,,,,
,3865700897.98128,299.998886108398,-40475.013671875,-0.00828828071973352,2.81430453468657E-6,1,2,12.9061126708984,5.00316593185189,42.6100008189678,-10.8370039643355,-1.55522350283156,100,2.76022264726913E-5,,,,,,,,,,,,,,,,,,,,,299.998840332031,299.998931884766,-40550.21484375,-40399.8125,49.6814811250918,5.37188907637253,8.40855026245117,25,1,68,0,0,0.270156860351562,31.2805480957031,1,6,1,299.998840332031,0,299.998886108398,,,,,,,,,,,,,,,,,,,,,,,,,,,,,,,,,
,3865700964.3344,300.000854492188,-33847.498046875,-0.00718487185346752,2.39386968303781E-6,1,2,12.9061126708984,5.00320528719414,42.6100008189678,-9.39342759089114,-1.3547447514012,100,1.89145508416235E-5,,,,,,,,,,,,,,,,,,,,,300.000640869141,300.001068115234,-33952.2578125,-33742.73828125,49.7623796768322,5.37236569037686,8.39682483673096,26,1,0,0,1,0.271072387695313,30.7917900085449,1,6,1,300.000640869141,0,300.000854492188,,,,,,,,,,,,,,,,,,,,,,,,,,,,,,,,,
,3865701042.81784,299.999740600586,-26017.2490234375,-0.00587491142686295,2.32978379112728E-6,1,2,12.9061126708984,5.00337104179506,42.6100008189678,-7.68120768088239,-1.10743760525767,100,1.57404700079275E-5,,,,,,,,,,,,,,,,,,,,,299.999420166016,300.000061035156,-26107.0234375,-25927.474609375,49.7193901082745,5.3711458080402,8.39136981964111,26,1,0,0,1,0.2703857421875,31.7693061828613,1,6,1,299.999420166016,0,299.999740600586,,,,,,,,,,,,,,,,,,,,,,,,,,,,,,,,,
,3865701099.29619,300.000411987305,-20376.6953125,-0.00492653288639518,2.63643962905498E-6,1,2,12.9061126708984,5.00329281744811,42.6100008189678,-6.44104791303388,-0.929002232091619,100,1.29263335514571E-5,,,,,,,,,,,,,,,,,,,,,300.000183105469,300.000640869141,-20476.4609375,-20276.9296875,49.7623796768322,5.37165166214926,8.39621067047119,26,1,0,0,1,0.2716064453125,31.2805480957031,1,6,1,300.000640869141,0,300.000411987305,,,,,,,,,,,,,,,,,,,,,,,,,,,,,,,,,
,3865701157.92104,299.999664306641,-14522.4350585938,-0.00392546141378075,2.19632503623888E-6,1,2,12.9061126708984,5.00330467868658,42.6199994981289,-5.13272782254877,-0.736938272468115,100,1.28194916570229E-5,,,,,,,,,,,,,,,,,,,,,299.999450683594,299.999877929687,-14587.275390625,-14457.5947265625,49.7291604647649,5.37187130140941,8.38085842132568,26,1,0,0,1,0.27099609375,31.7693061828613,1,6,1,299.999450683594,0,299.999664306641,,,,,,,,,,,,,,,,,,,,,,,,,,,,,,,,,
,3865701214.06328,300.001190185547,-8918.52294921875,-0.00292565405454718,2.30946130346559E-6,1,2,12.9061126708984,5.00306787138805,42.6100008189678,-3.82540456938058,-0.5476671871721,100,1.07312500863496E-5,,,,,,,,,,,,,,,,,,,,,300.001098632812,300.001281738281,-9013.4111328125,-8823.634765625,49.7772306186976,5.37301212353818,8.37905502319336,24,1,68,0,0,0.271835327148438,31.7693061828613,1,6,1,300.001098632812,0,300.001190185547,,,,,,,,,,,,,,,,,,,,,,,,,,,,,,,,,
,3865701270.50173,299.999450683594,-3278.02563476562,-0.0018405193116898,2.48762237969234E-6,1,2,12.9061126708984,5.00310508914769,42.6100008189678,-2.40867185692476,-0.330262494446019,100,1.76755372016244E-5,,,,,,,,,,,,,,,,,,,,,299.999114990234,299.999786376953,-3368.13134765625,-3187.919921875,49.771759219063,5.37334500702925,8.36489486694336,26,1,0,0,1,0.2703857421875,32.2580642700195,1,6,1,299.999786376953,0,299.999450683594,,,,,,,,,,,,,,,,,,,,,,,,,,,,,,,,,
,3865701339.3178,299.999984741211,3603.64331054687,0.00130491637942837,3.5178604209314E-6,1,2,12.9061126708984,5.00305601466421,42.6100008189678,1.70385009286686,0.260420747484389,100,7.57022104460076E-6,,,,,,,,,,,,,,,,,,,,,299.999938964844,300.000030517578,3548.22998046875,3659.056640625,49.8061508739091,5.37290971130536,8.35816478729248,26,1,0,0,1,0.271224975585938,31.2805480957031,1,6,1,300.000030517578,0,299.999984741211,,,,,,,,,,,,,,,,,,,,,,,,,,,,,,,,,
,3865701399.74522,300.000183105469,9648.70703125,0.00284744837284038,2.4722457194168E-6,1,2,12.9061126708984,5.0030013033077,42.6100008189678,3.72118158790072,0.545928223372734,10,-5.64867348344097E-7,,,,,,,,,,,,,,,,,,,,,300.000152587891,300.000213623047,9528.5849609375,9768.8291015625,49.672101582861,5.37324597472184,8.34419727325439,26,1,0,0,1,0.273056030273438,32.2580642700195,1,6,1,300.000213623047,0,300.000183105469,,,,,,,,,,,,,,,,,,,,,,,,,,,,,,,,,
,3865701494.08305,300.000839233398,19080.51171875,0.00465476052585473,2.89291886871378E-6,1,2,12.9061126708984,5.00307004696109,42.6100008189678,6.08477681908262,0.881586949224193,100,-9.2382290759645E-6,,,,,,,,,,,,,,,,,,,,,300.000610351562,300.001068115234,18990.53125,19170.4921875,49.7983345887168,5.37298544098929,8.33767318725586,26,1,0,0,1,0.27099609375,31.2805480957031,1,6,1,300.000610351562,0,300.000839233398,,,,,,,,,,,,,,,,,,,,,,,,,,,,,,,,,
,3865701554.54826,300.000671386719,25126.24609375,0.00570182609481659,2.58305801005757E-6,1,2,12.9061126708984,5.00301083661048,42.6199994981289,7.4533521359344,1.08016313627382,100,-1.10979193838521E-5,,,,,,,,,,,,,,,,,,,,,300.000457763672,300.000885009766,25031.169921875,25221.322265625,49.7334594216207,5.37335706067015,8.3255558013916,26,1,0,0,1,0.272598266601562,31.7693061828613,1,6,1,300.000427246094,0,300.000671386719,,,,,,,,,,,,,,,,,,,,,,,,,,,,,,,,,
,3865701624.43506,299.998779296875,32128.8134765625,0.00686617523788719,2.68474936139683E-6,1,2,12.9061126708984,5.00309825490097,42.6199994981289,8.97465613373115,1.30715207552427,100,-8.48147679249952E-6,,,,,,,,,,,,,,,,,,,,,299.998779296875,299.998779296875,32123.76953125,32133.857421875,49.6920331101014,5.37251284127188,8.32567977905273,26,1,0,0,1,0.271530151367187,31.2805480957031,1,6,1,299.998779296875,0,299.998779296875,,,,,,,,,,,,,,,,,,,,,,,,,,,,,,,,,
,3865701699.57429,300.001205444336,39654.8359375,0.0081465557463803,2.46537230507246E-6,1,2,12.9061126708984,5.00311042516359,42.6100008189678,10.649118094169,1.54503622610631,100,-1.45580884703138E-5,,,,,,,,,,,,,,,,,,,,,300.000915527344,300.001495361328,39569.6953125,39739.9765625,49.6865617104668,5.37207020189065,8.31476593017578,26,1,0,0,1,0.270538330078125,32.7468223571777,1,6,1,300.001495361328,0,300.001205444336,,,,,,,,,,,,,,,,,,,,,,,,,,,,,,,,,
,3865701768.22719,299.999862670898,46539.087890625,0.00928605562870202,2.58207757800256E-6,1,2,12.9061126708984,5.00314884268609,42.6199994981289,12.1376254651579,1.76912448391401,100,-1.050554133966E-5,,,,,,,,,,,,,,,,,,,,,299.999633789063,300.000091552734,46433.95703125,46644.21875,49.6658485547072,5.372490925049,8.30747890472412,26,1,0,0,1,0.27008056640625,31.2805480957031,1,6,1,299.999633789063,0,299.999862670898,,,,,,,,,,,,,,,,,,,,,,,,,,,,,,,,,
,3865701805.0136,299.999710083008,50000.17578125,0.00986093316905808,1.14584933994261E-6,1,2,12.9061126708984,5.00309124740999,42.6199994981289,12.8882241441038,1.88273495406503,100,-8.00444936056422E-6,,,,,,,,,,,,,,,,,,,,,299.999481201172,299.999938964844,50000.1640625,50000.1875,49.6892974102841,5.37183443710913,8.30348777770996,26,1,0,0,1,0.271072387695313,31.7693061828613,1,4,1,299.999481201172,0,299.999710083008,,,,,,,,,,,,,,,,,,,,,,,,,,,,,,,,,