File: LT data/Sherwood/D2/228-AC.dat
[Header]
; MPMS3 Data File (default extension .dat)
; Copyright (c) 2007, Quantum Design, Inc. All rights reserved.
TITLE,
FILEOPENTIME,3865760958.18592,06/30/2022,3:27 pm
BYAPP,MPMS3 w/ AC,1.0,1.1
INFO,MPMS3 Measurement Release 1.1.16 Build 424, MultiVu Release 2.3.4.19,APPNAME
INFO,Linear Motor Servo Controller,MOTOR_MODULE_NAME
INFO,3101-100 N2,MOTOR_HW_VERSION
INFO,,MOTOR_SERIAL_NUMBER
INFO,01.04.28,MOTOR_SOFTWARE_VERSION
INFO,Quantum Design Squid Module,SQUID_MODULE_NAME
INFO,3101-501 B0,SQUID_HW_VERSION
INFO,SQM327,SQUID_SERIAL_NUMBER
INFO,01.03.04,SQUID_SOFTWARE_VERSION
INFO,Quantum Design VSM Oven,OVEN_MODULE_NAME
INFO,3101-201 A3,OVEN_HW_VERSION
INFO,OVB365,OVEN_SERIAL_NUMBER
INFO,01.07.07,OVEN_SOFTWARE_VERSION
INFO,SQUID AC,AC_MODULE_NAME
INFO,3101-401 G0,AC_HW_VERSION
INFO,SAC220,AC_SERIAL_NUMBER
INFO,SQUID AC 00.95.07,AC_SOFTWARE_VERSION
INFO,TCI344,COIL_SERIAL_NUMBER
INFO,0,MOMENT_UNITS
INFO,sndst,SAMPLE_MATERIAL
INFO,,SAMPLE_COMMENT
INFO,342.13,SAMPLE_MASS
INFO,,SAMPLE_VOLUME
INFO,,SAMPLE_MOLECULAR_WEIGHT
INFO,,SAMPLE_SIZE
INFO,,SAMPLE_SHAPE
INFO,Straw,SAMPLE_HOLDER
INFO,Standard,SAMPLE_HOLDER_DETAIL
INFO,54.97,SAMPLE_OFFSET
DATATYPE,COMMENT,1
DATATYPE,TIME,2
STARTUPAXIS,X,2
STARTUPAXIS,Y1,5
FIELDGROUP, VSM,2,3,4,5,6,8,9,10,11,14,15
FIELDGROUP, DC, 2,3,4,14,56,57,58,59,60,61,62,63,64,65,66,67,68,69
FIELDGROUP, AC, 2,3,4,11,16,17,18,19,20,21,22,23,24,25,26,27,28,29,30
STARTUPGROUP, All
[Data]
Comment,Time Stamp (sec),Temperature (K),Magnetic Field (Oe),Moment (emu),M. Std. Err. (emu),Transport Action,Averaging Time (sec),Frequency (Hz),Peak Amplitude (mm),Center Position (mm),Lockin Signal' (V),Lockin Signal (V),Range,M. Quad. Signal (emu),AC Moment (emu),AC M. Std Err. (emu),AC Phase (deg),AC Phase Std. Err. (deg),AC Susceptibility (emu/Oe),AC Suscept. Std Err. (emu/Oe),AC X' (emu/Oe),AC X' Std Err. (emu/Oe),AC X'' (emu/Oe),AC X'' Std Err. (emu/Oe),AC Drive (Oe),AC Frequency (Hz),AC Averaging Time (sec),AC Cycles,AC Range,AC Measure Type,AC Signal' (V),AC Signal'' (V),AC Trim Coil Ratio,AC Trim Coil Phase,Min. Temperature (K),Max. Temperature (K),Min. Field (Oe),Max. Field (Oe),Mass (grams),Motor Lag (deg),Pressure (Torr),Measure Count,Measurement Number,SQUID Status (code),Motor Status (code),Measure Status (code),Motor Current (amps),Motor Temp. (C),Temp. Status (code),Field Status (code),Chamber Status (code),Chamber Temp (K),Redirection State,Average Temp (K),Rotation Angle (deg),Rotator state,DC Moment Fixed Ctr (emu),DC Moment Err Fixed Ctr (emu),DC Moment Free Ctr (emu),DC Moment Err Free Ctr (emu),DC Fixed Fit,DC Free Fit,DC Calculated Center (mm),DC Calculated Center Err (mm),DC Scan Length (mm),DC Scan Time (s),DC Number of Points,DC Squid Drift,DC Min V (V),DC Max V (V),DC Scans per Measure,Map 01,Map 02,Map 03,Map 04,Map 05,Map 06,Map 07,Map 08,Map 09,Map 10,Map 11,Map 12,Map 13,Map 14,Map 15,Map 16
,3865762600.62918,1.99989974498749,25.0585975646973,,,5,,,,39.5999997854233,,,,,0.00031090458554836,3.85344945661357E-8,1.967907359153,8.68036885276525E-5,0.000103634850040913,1.28448300584575E-8,0.000103573728095594,9.16905674750666E-9,3.55879071910232E-6,8.99544649206781E-9,3.00000034183117,1.00057637691498,19.98847910208,20,1,3,1.09307497336268,0.0508685870449157,0.00126359087880701,195.232986450195,1.99767291545868,2.001469373703,25.0585975646973,25.0585975646973,,,2.40947198867798,,1,,,,,,1,1,1,1.9999680519104,0,1.99996256732172,,,,,,,,,,,,,,,,,,,,,,,,,,,,,,,,,
,3865762762.87621,1.99994778633118,25.0585975646973,,,5,,,,39.5999997854233,,,,,0.000279021017223555,5.54882578380573E-9,2.30478937462105,1.86666810929257E-5,9.30012922148776E-5,1.84949497103905E-9,9.29260576098499E-5,6.14371531115996E-10,3.74007629974539E-6,1.74447105727006E-9,3.00018430473936,100.057640075684,10,1000,1,3,0.966783222437171,0.155302503572182,0.0131124872714281,196.729888916016,1.99854290485382,2.00202298164368,25.0585975646973,25.0585975646973,,,2.38847374916077,,1,,,,,,1,1,1,1.9999668598175,0,1.9999706586202,,,,,,,,,,,,,,,,,,,,,,,,,,,,,,,,,
,3865763094.397,11.9248986244202,25.0585975646973,,,5,,,,39.5999997854233,,,,,0.000165134041998978,1.16626486922661E-8,0.0180522452154142,3.72064160915606E-5,5.50448740642785E-5,3.88756322288584E-9,5.50448713321314E-5,3.30504818055278E-9,1.73430496358392E-8,2.04690115446723E-9,2.99998945962058,10.005763053894,10,100,1,3,0.578022983769054,0.0569766976429365,0.00395644968375564,247.203941345215,11.9206142425537,11.9343004226685,25.0585975646973,25.0585975646973,,,5.21473407745361,,1,,,,,,1,1,1,11.9228296279907,0,11.9299598446599,,,,,,,,,,,,,,,,,,,,,,,,,,,,,,,,,
,3865763375.77898,21.8671283721924,25.0585975646973,,,5,,,,39.5999997854233,,,,,8.38036028592748E-5,5.66847670419317E-8,0.020458979848569,0.000588674426498441,2.79345335092797E-5,1.88949218216495E-8,2.7934531728402E-5,9.30591001327559E-9,9.97476691751889E-9,1.64443944695773E-8,3.00000008346069,1.00057637691498,19.98847910208,20,1,3,0.294931589695556,0.00369011028242815,0.000490242789965123,229.794464111328,21.866662979126,21.8685913085938,25.0585975646973,25.0585975646973,,,5.89039373397827,,1,,,,,,1,1,1,21.8671207427979,0,21.8672216887115,,,,,,,,,,,,,,,,,,,,,,,,,,,,,,,,,
,3865763542.99127,21.8668584823608,25.0585975646973,,,5,,,,39.5999997854233,,,,,8.36840326908185E-5,5.16615730147393E-9,0.068015017246025,4.39035223720211E-5,2.78934360435976E-5,1.72197578972121E-9,2.78934163902593E-5,1.21109167241705E-9,3.31118994122235E-8,1.22411501967261E-9,3.00013352818993,100.057640075684,10,1000,1,3,0.29156606558046,0.0351354618439164,0.0125240609049797,197.680114746094,21.8663902282715,21.8673191070557,25.0585975646973,25.0585975646973,,,5.88849592208862,,1,,,,,,1,1,1,21.8669567108154,0,21.8667898178101,,,,,,,,,,,,,,,,,,,,,,,,,,,,,,,,,
,3865763870.87239,31.8000993728638,25.0585975646973,,,5,,,,39.6099984645844,,,,,5.24962410891316E-5,1.16135349838784E-8,-0.0109241393544917,0.000125616695016184,1.7498692493633E-5,3.87116626315956E-9,1.74986921755761E-5,3.18712177133323E-9,-3.33633918219109E-9,2.19731268865369E-9,3.00000934974043,10.005763053894,10,100,1,3,0.183764241191733,0.0180083207756992,0.00382403749972582,252.432159423828,31.7998676300049,31.8024959564209,25.0585975646973,25.0585975646973,,,6.22070121765137,,1,,,,,,1,1,1,31.8002090454102,0,31.8005856208082,,,,,,,,,,,,,,,,,,,,,,,,,,,,,,,,,
,3865764168.54472,41.7336444854736,25.0585975646973,,,5,,,,39.6200008690357,,,,,3.7395009629291E-5,5.08971622897912E-8,0.196641147692396,0.000838596257284095,1.24650029675163E-5,1.69657204335486E-8,1.24649295557793E-5,1.33631922518596E-8,4.27802483608281E-8,1.04527873157913E-8,3.00000005830259,1.00057637691498,19.98847910208,20,1,3,0.131599290606142,0.00205012347560031,0.000309034832753241,235.051803588867,41.7323951721191,41.7340316772461,25.0585975646973,25.0585975646973,,,6.42423439025879,,1,,,,,,1,1,1,41.7335968017578,0,41.7333783721924,,,,,,,,,,,,,,,,,,,,,,,,,,,,,,,,,
,3865764333.45099,41.7331390380859,25.0585975646973,,,5,,,,39.6200008690357,,,,,3.72687404746534E-5,4.55013739597241E-9,0.117066215100299,0.000109320960051105,1.24240816420527E-5,1.51685508472081E-9,1.24240557090958E-5,6.75122736542523E-10,2.53847528445316E-8,1.35832935573326E-9,2.99971793074082,100.057640075684,10,1000,1,3,0.129849442435967,0.0156446717542328,0.0123559180647135,197.637756347656,41.7328834533691,41.734058380127,25.0585975646973,25.0585975646973,,,6.45462226867676,,1,,,,,,1,1,1,41.7333831787109,0,41.7333974254375,,,,,,,,,,,,,,,,,,,,,,,,,,,,,,,,,
,3865764671.24564,51.6663417816162,25.0585975646973,,,5,,,,39.6299995481968,,,,,2.89836041751503E-5,1.54832380599911E-8,0.00890396053957154,0.000352511287920951,9.66121520423463E-6,5.16108673207115E-9,9.66121508757436E-6,3.87864274068828E-9,1.50138595421197E-9,3.40484166240766E-9,2.99999571093774,10.005763053894,10,100,1,3,0.101454965376689,0.00997082535068554,0.00378542044200003,253.551918029785,51.665885925293,51.6675491333008,25.0585975646973,25.0585975646973,,,6.60233640670776,,1,,,,,,1,1,1,51.6666374206543,0,51.6666376365806,,,,,,,,,,,,,,,,,,,,,,,,,,,,,,,,,
,3865764966.04123,61.5994625091553,25.0585975646973,,,5,,,,39.6399982273579,,,,,2.38164829871522E-5,5.77490664743208E-8,0.00291418771275742,0.00164266654278743,7.93882758974732E-6,1.92496886486475E-8,7.9388275794786E-6,1.41593393839826E-8,4.0378600312932E-10,1.30408443468615E-8,3.00000002744866,1.00057637691498,19.98847910208,20,1,3,0.0838181244034955,0.00102202517326491,0.000265587586909533,245.904556274414,61.5904769897461,61.601016998291,25.0585975646973,25.0585975646973,,,6.70085573196411,,1,,,,,,1,1,1,61.6002426147461,0,61.5987487792969,,,,,,,,,,,,,,,,,,,,,,,,,,,,,,,,,
,3865765130.02014,61.5996780395508,25.0585975646973,,,5,,,,39.6399982273579,,,,,2.37145669267074E-5,3.30667689894549E-9,0.152682417273794,0.000119283201583643,7.90498350745619E-6,1.10224346206434E-9,7.90495543997082E-6,5.70726926537903E-10,2.10652612149462E-8,9.42980076665562E-10,2.99995147419842,100.057640075684,10,1000,1,3,0.082622053168065,0.00997873057816904,0.0123087391257286,197.620346069336,61.599235534668,61.6008338928223,25.0585975646973,25.0585975646973,,,6.70767784118652,,1,,,,,,1,1,1,61.5997657775879,0,61.6000912189484,,,,,,,,,,,,,,,,,,,,,,,,,,,,,,,,,
,3865765467.85864,71.532886505127,25.0585975646973,,,5,,,,39.6500006318092,,,,,2.02527408707906E-5,1.25164264890866E-8,0.0518469357805147,0.000264120576057721,6.75093629878561E-6,4.17215617655598E-9,6.75093353480553E-6,3.77294507664454E-9,6.10891964378627E-9,1.78094711044374E-9,2.99998992353605,10.005763053894,10,100,1,3,0.0708881061460427,0.00701915386000177,0.00378924305550754,254.002517700195,71.5322494506836,71.5349273681641,25.0585975646973,25.0585975646973,,,6.78414630889893,,1,,,,,,1,1,1,71.5330123901367,0,71.5336116574845,,,,,,,,,,,,,,,,,,,,,,,,,,,,,,,,,
,3865765776.86352,81.4647216796875,25.0585975646973,,,5,,,,39.6700017154217,,,,,1.77560313175498E-5,6.85848362121956E-8,0.175456282062471,0.00322269398148842,5.91867712284063E-6,2.28616121363605E-8,5.91864937131305E-6,1.26022001644079E-8,1.81246763455631E-8,1.90745343452883E-8,2.99999999138792,1.00057637691498,19.98847910208,20,1,3,0.0624868025641973,0.00095006543166926,0.000394360948121175,244.311965942383,81.4384841918945,81.467399597168,25.0585975646973,25.0585975646973,,,6.83019638061523,,1,,,,,,1,1,1,81.4662551879883,0,81.4617018606148,,,,,,,,,,,,,,,,,,,,,,,,,,,,,,,,,
,3865765942.85898,81.4665603637695,25.0585975646973,,,5,,,,39.6599993109703,,,,,1.7645361358884E-5,2.90690148171287E-9,0.1805654761942,0.000125492821913576,5.88196030443107E-6,9.68995691081066E-10,5.88193109548381E-6,6.27950728889047E-10,1.8536744142549E-8,7.37990874890325E-10,2.99991166985455,100.057640075684,10,1000,1,3,0.0614741393465678,0.00744804170448564,0.012306172400713,197.622680664062,81.4655151367187,81.4679107666016,25.0585975646973,25.0585975646973,,,6.83524799346924,,1,,,,,,1,1,1,81.4665603637695,0,81.4667339714206,,,,,,,,,,,,,,,,,,,,,,,,,,,,,,,,,
,3865766292.44019,91.39990234375,25.0585975646973,,,5,,,,39.6899990737438,,,,,1.57758001950139E-5,8.62934554801593E-9,0.0799956859014399,0.000390953681312402,5.25861289302086E-6,2.87645553291624E-9,5.25860776760624E-6,2.01219388220417E-9,7.34201039189888E-9,2.05549804506464E-9,2.99999268171103,10.005763053894,10,100,1,3,0.0552153889449722,0.00549423706022213,0.00378106371499598,254.215293884277,91.3989715576172,91.4015960693359,25.0585975646973,25.0585975646973,,,6.87964773178101,,1,,,,,,1,1,1,91.3998718261719,0,91.4002478672908,,,,,,,,,,,,,,,,,,,,,,,,,,,,,,,,,
,3865766597.83368,101.327884674072,25.0585975646973,,,5,,,,39.7000014781952,,,,,1.43348867271682E-5,5.73400339172755E-8,-0.2245062851932,0.00283641809275277,4.77829528311578E-6,1.9113343468654E-8,4.77825860101703E-6,1.34770050548542E-8,-1.87230994597358E-8,1.35532370045748E-8,3.00000018371005,1.00057637691498,19.98847910208,20,1,3,0.0504512788004441,0.000414810114778611,0.000326991459587589,246.668434143066,101.288444519043,101.333511352539,25.0585975646973,25.0585975646973,,,6.93875503540039,,1,,,,,,1,1,1,101.330955505371,0,101.323812637329,,,,,,,,,,,,,,,,,,,,,,,,,,,,,,,,,
,3865766760.33926,101.333160400391,25.0585975646973,,,5,,,,39.7100001573563,,,,,1.42173332398219E-5,3.45982617535905E-9,0.245609321020413,0.000206531176164384,4.73954206164009E-6,1.15338027233883E-9,4.73949851545188E-6,6.09777047418261E-10,2.03168916189117E-8,9.79008684875805E-10,2.99972720041692,100.057640075684,10,1000,1,3,0.0495249856083572,0.0060542856328024,0.0123072741553187,197.636734008789,101.331069946289,101.334838867187,25.0585975646973,25.0585975646973,,,6.93944692611694,,1,,,,,,1,1,1,101.332901000977,0,101.333268997517,,,,,,,,,,,,,,,,,,,,,,,,,,,,,,,,,
,3865767113.60759,111.266292572021,25.0585975646973,,,5,,,,39.7300012409687,,,,,1.30608584393759E-5,1.04720872611805E-8,0.0881849109009272,0.000382456231852764,4.35363381604637E-6,3.49070724841594E-9,4.35362865942657E-6,3.06893571760111E-9,6.70074937189665E-9,1.66333119232934E-9,2.99999012118036,10.005763053894,10,100,1,3,0.0457124513475027,0.00455500623883261,0.00378800625912845,254.349555969238,111.264976501465,111.268478393555,25.0585975646973,25.0585975646973,,,6.97225666046143,,1,,,,,,1,1,1,111.265991210938,0,111.26676104619,,,,,,,,,,,,,,,,,,,,,,,,,,,,,,,,,
,3865767417.62269,121.188526153564,25.0585975646973,,,5,,,,39.7499985992908,,,,,1.20606964701106E-5,5.67215090426428E-8,0.133542382389387,0.0030442533267388,4.02023230952339E-6,1.89071703995935E-8,4.02022138974231E-6,1.44118442743514E-8,9.37016511251659E-9,1.22384573019278E-8,2.99999988596191,1.00057637691498,19.98847910208,20,1,3,0.0424443130408362,0.000614233240481654,0.000225141731789336,268.333946228027,121.14665222168,121.198959350586,25.0585975646973,25.0585975646973,,,6.99661684036255,,1,,,,,,1,1,1,121.193862915039,0,121.186015170553,,,,,,,,,,,,,,,,,,,,,,,,,,,,,,,,,
,3865767578.45882,121.199779510498,25.0585975646973,,,5,,,,39.7499985992908,,,,,1.19966243697524E-5,6.16990296181692E-9,0.262621514578766,0.000498237612006931,3.99928303171615E-6,2.05684428069151E-9,3.99924102035788E-6,5.06175773758552E-10,1.83310899728758E-8,1.99358834293174E-9,2.99969376376057,100.057640075684,10,1000,1,3,0.0417881450965508,0.00511921295134606,0.0122922230511904,197.645690917969,121.197402954102,121.20231628418,25.0585975646973,25.0585975646973,,,6.99666404724121,,1,,,,,,1,1,1,121.199546813965,0,121.199784538963,,,,,,,,,,,,,,,,,,,,,,,,,,,,,,,,,
,3865767924.45515,131.132698059082,25.0585975646973,,,5,,,,39.7799983620644,,,,,1.12192898765129E-5,1.67951134414725E-8,0.17215695024053,0.000506312877599209,3.7397491401386E-6,5.59834996177128E-9,3.73973225844534E-6,5.27092577840286E-9,1.12368283202547E-8,1.88649509223656E-9,3.0000113526591,10.005763053894,10,100,1,3,0.0392612794881445,0.00397014638266932,0.00378134031780064,254.284851074219,131.130508422852,131.135726928711,25.0585975646973,25.0585975646973,,,7.02204275131226,,1,,,,,,1,1,1,131.132583618164,0,131.133254141178,,,,,,,,,,,,,,,,,,,,,,,,,,,,,,,,,
,3865768227.19723,141.053489685059,25.0585975646973,,,5,,,,39.8100018501282,,,,,1.05426938115952E-5,4.50448240591426E-8,0.0388583185587363,0.00313243024438499,3.51423117901201E-6,1.50149409620194E-8,3.51423037080416E-6,1.02112811676493E-8,2.38337108483495E-9,1.10080965206587E-8,3.0000000781278,1.00057637691498,19.98847910208,20,1,3,0.0371029558776111,0.000475596619873042,3.58441320713609E-5,247.133140563965,141.004898071289,141.066299438477,25.0585975646973,25.0585975646973,,,7.04085063934326,,1,,,,,,1,1,1,141.059494018555,0,141.050579229991,,,,,,,,,,,,,,,,,,,,,,,,,,,,,,,,,
,3865768388.65897,141.066482543945,25.0585975646973,,,5,,,,39.8100018501282,,,,,1.04158870444693E-5,3.4043761061933E-9,0.301375573169124,0.000174409630939388,3.47221390977098E-6,1.13487425694511E-9,3.47216587604132E-6,9.60615689723515E-10,1.82637471854633E-8,6.0428228149908E-10,2.99978265024471,100.057640075684,10,1000,1,3,0.0362791928225479,0.0044679381221667,0.0122821042314172,197.658660888672,141.063583374023,141.069290161133,25.0585975646973,25.0585975646973,,,7.0435209274292,,1,,,,,,1,1,1,141.066101074219,0,141.066623521888,,,,,,,,,,,,,,,,,,,,,,,,,,,,,,,,,
,3865768745.1226,150.999771118164,25.0585975646973,,,5,,,,39.8400016129017,,,,,9.85234885119517E-6,1.24940770065193E-8,0.18055605310943,0.000784070999149134,3.28410463985392E-6,4.16467756953456E-9,3.28408833317681E-6,3.27432604390834E-9,1.03491739773187E-8,2.57358275879519E-9,3.00001063657746,10.005763053894,10,100,1,3,0.034477247004884,0.00349136962097975,0.00378724350593984,254.498245239258,150.996612548828,151.003341674805,25.0585975646973,25.0585975646973,,,7.06537342071533,,1,,,,,,1,1,1,150.999450683594,0,150.999893188477,,,,,,,,,,,,,,,,,,,,,,,,,,,,,,,,,
,3865769053.07603,160.91845703125,25.0585975646973,,,5,,,,39.8700013756752,,,,,9.3511750910101E-6,5.96915481968378E-8,0.216008295846616,0.00366586490786167,3.11705833450463E-6,1.98971825461071E-8,3.11703618265389E-6,1.62893335071775E-8,1.17514565578401E-8,1.1426088007934E-8,3.00000002807013,1.00057637691498,19.98847910208,20,1,3,0.0329081765886016,0.000523584635541852,0.000206557233468629,260.070289611816,160.865142822266,160.934478759766,25.0585975646973,25.0585975646973,,,7.08064889907837,,1,,,,,,1,1,1,160.9248046875,0,160.915417194366,,,,,,,,,,,,,,,,,,,,,,,,,,,,,,,,,
,3865769213.66505,160.932838439941,25.0585975646973,,,5,,,,39.8700013756752,,,,,9.23710638693984E-6,4.18482490800168E-9,0.297757651078947,0.00038212302507878,3.07897370471258E-6,1.39491365702805E-9,3.07893212747783E-6,7.48989137835683E-10,1.60008967360228E-8,1.17677499207263E-9,3.00006017355777,100.057640075684,10,1000,1,3,0.032173931452628,0.00395927305589419,0.0122719556093216,197.675888061523,160.929458618164,160.936981201172,25.0585975646973,25.0585975646973,,,7.08170890808105,,1,,,,,,1,1,1,160.932052612305,0,160.933088551397,,,,,,,,,,,,,,,,,,,,,,,,,,,,,,,,,
,3865769569.65742,170.865631103516,25.0585975646973,,,5,,,,39.9099998176098,,,,,8.81007627185459E-6,1.34362016595311E-8,0.252816590159524,0.000809307050766233,2.93670093181606E-6,4.4787473701754E-9,2.93667234308396E-6,3.79800119116522E-9,1.29580976639595E-8,2.37368173051078E-9,2.9999909682347,10.005763053894,10,100,1,3,0.0308259738057204,0.00316080823443121,0.0037802483420819,254.548156738281,170.862854003906,170.869689941406,25.0585975646973,25.0585975646973,,,7.10407447814941,,1,,,,,,1,1,1,170.865203857422,0,170.866566783977,,,,,,,,,,,,,,,,,,,,,,,,,,,,,,,,,
,3865769878.35615,180.785530090332,25.0585975646973,,,5,,,,39.9399995803833,,,,,8.44650580242012E-6,5.6991860614548E-8,0.0877623466048076,0.00572803047257577,2.81550195088296E-6,1.8997286984487E-8,2.81549864797143E-6,1.00399918725754E-8,4.31262064249811E-9,1.61274758089906E-8,2.99999998215993,1.00057637691498,19.98847910208,20,1,3,0.0297254949860713,0.000406388577694194,1.53838936967077E-5,270.216468811035,180.730514526367,180.800674438477,25.0585975646973,25.0585975646973,,,7.12461566925049,,1,,,,,,1,1,1,180.792556762695,0,180.781986395518,,,,,,,,,,,,,,,,,,,,,,,,,,,,,,,,,
,3865770045.14898,180.799270629883,25.0585975646973,,,5,,,,39.9399995803833,,,,,8.3307355665648E-6,4.07864773857814E-9,0.30793987074326,0.000452374566133717,2.77680079373716E-6,1.35949487141484E-9,2.77676068857606E-6,5.18474490818597E-10,1.49240235163329E-8,1.25674599970465E-9,3.00011998892902,100.057640075684,10,1000,1,3,0.0290165462012217,0.00357512174979259,0.0122703202068806,197.679443359375,180.795059204102,180.804412841797,25.0585975646973,25.0585975646973,,,7.12808847427368,,1,,,,,,1,1,1,180.797958374023,0,180.800231933594,,,,,,,,,,,,,,,,,,,,,,,,,,,,,,,,,
,3865770399.76854,190.733367919922,25.0585975646973,,,5,,,,39.9800017476082,,,,,8.00042469977731E-6,1.16121020797011E-8,0.193160981777341,0.00104956702586662,2.66681587574607E-6,3.87071178581217E-9,2.66680072073812E-6,2.67405711740753E-9,8.9906063128981E-9,2.79854038056758E-9,2.99999140268322,10.005763053894,10,100,1,3,0.0279960301204762,0.00284110308510973,0.00378324813209474,254.572425842285,190.728942871094,190.738006591797,25.0585975646973,25.0585975646973,,,7.15319776535034,,1,,,,,,1,1,1,190.733016967773,0,190.733997486256,,,,,,,,,,,,,,,,,,,,,,,,,,,,,,,,,
,3865770705.45654,200.645263671875,25.0585975646973,,,5,,,,40.0200001895428,,,,,7.70716851649425E-6,4.40990167156924E-8,0.445556000606086,0.00402844351908976,2.56905625159976E-6,1.46996726930768E-8,2.56897857311265E-6,1.04390105715021E-8,1.99778570392762E-8,1.03492722242511E-8,2.99999990724025,1.00057637691498,19.98847910208,20,1,3,0.0271207266051015,0.000540179004946234,0.000266027287580073,247.589263916016,200.585144042969,200.66667175293,25.0585975646973,25.0585975646973,,,7.177894115448,,1,,,,,,1,1,1,200.654205322266,0,200.643404068485,,,,,,,,,,,,,,,,,,,,,,,,,,,,,,,,,
,3865770873.07554,200.666290283203,25.0585975646973,,,5,,,,40.0200001895428,,,,,7.60305072500513E-6,4.59212325396023E-9,0.427470421969716,0.00056913270033184,2.5340941242647E-6,1.53055306042984E-9,2.53402359690808E-6,5.09343350769433E-10,1.89061086932496E-8,1.4433163277044E-9,3.00030320586898,100.057640075684,10,1000,1,3,0.0264753542879204,0.0033173846180691,0.0122650591656566,197.697357177734,200.661407470703,200.671279907227,25.0585975646973,25.0585975646973,,,7.17568254470825,,1,,,,,,1,1,1,200.66552734375,0,200.666674555564,,,,,,,,,,,,,,,,,,,,,,,,,,,,,,,,,
,3865771220.93062,210.600387573242,25.0585975646973,,,5,,,,40.0700010359287,,,,,7.36472356617659E-6,1.50598686698686E-8,0.359628023253075,0.00152070495713165,2.45490206158212E-6,5.01994437572757E-9,2.45485370400467E-6,3.35635894914081E-9,1.54085656267955E-8,3.732920591162E-9,3.00000708029477,10.005763053894,10,100,1,3,0.0257638111169443,0.0026901514050482,0.00378654827363789,254.598762512207,210.595642089844,210.606079101562,25.0585975646973,25.0585975646973,,,7.1993818283081,,1,,,,,,1,1,1,210.599609375,0,210.601210417571,,,,,,,,,,,,,,,,,,,,,,,,,,,,,,,,,
,3865771540.05411,220.518814086914,25.0585975646973,,,5,,,,40.1099994778633,,,,,7.11845783602892E-6,3.77937646734257E-8,0.595586978496182,0.00393914045022785,2.3728191864539E-6,1.25979210681756E-8,2.37269099004421E-6,8.44618069607708E-9,2.46649015161649E-8,9.34717320312388E-9,3.00000011659852,1.00057637691498,19.98847910208,20,1,3,0.025047722638639,0.000564501273798444,0.000372654874809086,249.533027648926,220.456405639648,220.534942626953,25.0585975646973,25.0585975646973,,,7.23754262924194,,1,,,,,,1,1,1,220.526214599609,0,220.51324107346,,,,,,,,,,,,,,,,,,,,,,,,,,,,,,,,,
,3865771706.6125,220.53352355957,25.0585975646973,,,5,,,,40.1000007987022,,,,,7.04348906194854E-6,3.29361514799511E-9,0.409714255023096,0.000392263319433551,2.34763218182518E-6,1.09777936019697E-9,2.34757215918534E-6,5.97126355088135E-10,1.67874524306647E-8,9.21172969497923E-10,3.000252388972,100.057640075684,10,1000,1,3,0.0245280664441387,0.00306502685289223,0.0122648850083351,197.710327148438,220.527053833008,220.539520263672,25.0585975646973,25.0585975646973,,,7.24677610397339,,1,,,,,,1,1,1,220.532272338867,0,220.533672722018,,,,,,,,,,,,,,,,,,,,,,,,,,,,,,,,,
,3865772053.47136,230.467079162598,25.0585975646973,,,5,,,,40.1600003242493,,,,,6.84064822235916E-6,1.17142812239228E-8,0.226154811741718,0.00143734101968369,2.28021546260251E-6,3.90475936078044E-9,2.28019769979021E-6,2.12189684509889E-9,9.00032016334633E-9,3.27791083532817E-9,3.00000080455187,10.005763053894,10,100,1,3,0.0239362168674406,0.00244290555842982,0.00378293916583061,254.640769958496,230.460830688477,230.472869873047,25.0585975646973,25.0585975646973,,,7.2992000579834,,1,,,,,,1,1,1,230.465866088867,0,230.467538221827,,,,,,,,,,,,,,,,,,,,,,,,,,,,,,,,,
,3865772363.2358,240.37735748291,25.0585975646973,,,5,,,,40.1999987661839,,,,,6.70203822536025E-6,9.96088897507283E-8,0.228738008268433,0.00757179667893337,2.23401271868859E-6,3.3202962906947E-8,2.23399491596396E-6,2.85720670703106E-8,8.91867196283083E-9,1.69137142322368E-8,3.00000003101794,1.00057637691498,19.98847910208,20,1,3,0.0235853862865612,0.000380471044191275,0.000182922667590901,265.87353515625,240.319564819336,240.400970458984,25.0585975646973,25.0585975646973,,,7.36318778991699,,1,,,,,,1,1,1,240.386199951172,0,240.37667879851,,,,,,,,,,,,,,,,,,,,,,,,,,,,,,,,,
,3865772529.16131,240.398094177246,25.0585975646973,,,5,,,,40.2100011706352,,,,,6.55709959607958E-6,5.02140498113498E-9,0.403148535317335,0.000726064402968493,2.18556749374506E-6,1.67370029063761E-9,2.1855133912439E-6,5.28682947515098E-10,1.53781146005577E-8,1.588007243021E-9,3.00018169873295,100.057640075684,10,1000,1,3,0.0228349015742484,0.00285021485341345,0.012261874973774,197.716171264648,240.392211914062,240.407211303711,25.0585975646973,25.0585975646973,,,7.37573385238647,,1,,,,,,1,1,1,240.397018432617,0,240.399534264389,,,,,,,,,,,,,,,,,,,,,,,,,,,,,,,,,
,3865772876.36031,250.332893371582,25.0585975646973,,,5,,,,40.2599982917309,,,,,6.40426224534993E-6,1.76954960755361E-8,0.432926575107219,0.00201821790140602,2.13476209011071E-6,5.89852081950361E-9,2.13470115036376E-6,4.02922326139011E-9,1.61300963881169E-8,4.30788901528235E-9,2.99998874582684,10.005763053894,10,100,1,3,0.0224008608207835,0.00236786694821608,0.00378396920859814,254.666320800781,250.326080322266,250.339996337891,25.0585975646973,25.0585975646973,,,7.49722576141357,,1,,,,,,1,1,1,250.331558227539,0,250.333657441316,,,,,,,,,,,,,,,,,,,,,,,,,,,,,,,,,
,3865773185.24571,260.245880126953,25.0585975646973,,,5,,,,40.3099991381168,,,,,6.30942518432451E-6,4.1406915341598E-8,0.246213617465976,0.00460077231993493,2.10314174407623E-6,1.38023052186597E-8,2.10312232552823E-6,9.84264212338241E-9,9.03767341239937E-9,9.67605422577089E-9,2.99999997722257,1.00057637691498,19.98847910208,20,1,3,0.0222036173026543,0.000364949508244764,6.52261369396001E-5,254.196098327637,260.185028076172,260.266632080078,25.0585975646973,25.0585975646973,,,7.69860792160034,,1,,,,,,1,1,1,260.255798339844,0,260.243193626404,,,,,,,,,,,,,,,,,,,,,,,,,,,,,,,,,
,3865773351.53259,260.264465332031,25.0585975646973,,,5,,,,40.3099991381168,,,,,6.14753091735073E-6,2.83929207116622E-9,0.502350744698188,0.00036699295502065,2.04911907374838E-6,9.46403949356067E-10,2.0490403141933E-6,5.74442918066193E-10,1.79657788598004E-8,7.52127495335969E-10,3.00008476623336,100.057640075684,10,1000,1,3,0.0214042858030734,0.00270876568065791,0.01226313598454,197.722351074219,260.257598876953,260.272766113281,25.0585975646973,25.0585975646973,,,7.644775390625,,1,,,,,,1,1,1,260.263397216797,0,260.265471789302,,,,,,,,,,,,,,,,,,,,,,,,,,,,,,,,,
,3865773706.34604,270.200271606445,25.0585975646973,,,5,,,,40.3599999845028,,,,,6.03714797375737E-6,1.30210872057891E-8,0.463338545722467,0.0013501073253119,2.0123902352965E-6,4.34037874502614E-9,2.01232443445668E-6,3.38671567377105E-9,1.62735861220781E-8,2.71459842247581E-9,2.99998870391452,10.005763053894,10,100,1,3,0.0211155876352362,0.0022432906391748,0.00378227839246392,254.66902923584,270.1943359375,270.206909179687,25.0585975646973,25.0585975646973,,,7.81862258911133,,1,,,,,,1,1,1,270.198883056641,0,270.200523659035,,,,,,,,,,,,,,,,,,,,,,,,,,,,,,,,,
,3865774020.69861,280.1142578125,25.0585975646973,,,5,,,,40.4199995100498,,,,,5.96303619094414E-6,6.42857601258198E-8,0.708153092323316,0.00831371644254883,1.98767862515988E-6,2.14285855749629E-8,1.9875268084098E-6,1.36407340295243E-8,2.45662933680432E-8,1.65261808921265E-8,3.00000015871001,1.00057637691498,19.98847910208,20,1,3,0.0209811706127179,0.000514081431583288,0.000347194407368079,286.713401794434,280.053253173828,280.134124755859,25.0585975646973,25.0585975646973,,,7.91519975662231,,1,,,,,,1,1,1,280.121673583984,0,280.110732396444,,,,,,,,,,,,,,,,,,,,,,,,,,,,,,,,,
,3865774183.42831,280.13346862793,25.0585975646973,,,5,,,,40.4199995100498,,,,,5.80593919081151E-6,3.80212435898038E-9,0.49727121405047,0.000496281677655858,1.93533143491976E-6,1.26738681711552E-9,1.93525854558218E-6,8.27017305067718E-10,1.67965692841195E-8,9.6037061664585E-10,2.99997152221746,100.057640075684,10,1000,1,3,0.020215616229186,0.00255602764172873,0.0122602330520749,197.728897094727,280.126739501953,280.141021728516,25.0585975646973,25.0585975646973,,,7.93185806274414,,1,,,,,,1,1,1,280.131134033203,0,280.134041164232,,,,,,,,,,,,,,,,,,,,,,,,,,,,,,,,,
,3865774538.00148,290.066253662109,25.0585975646973,,,5,,,,40.4799990355968,,,,,5.73198572188385E-6,1.75950507156017E-8,0.455444560628359,0.00201275196705842,1.91066560161193E-6,5.86502824537197E-9,1.91060523758878E-6,4.43025482181631E-9,1.51877345705811E-8,3.84335771595416E-9,2.99999419942875,10.005763053894,10,100,1,3,0.0200485521217201,0.00212708915540838,0.00378101435489953,254.687454223633,290.057464599609,290.074798583984,25.0585975646973,25.0585975646973,,,8.11910438537598,,1,,,,,,1,1,1,290.063690185547,0,290.067683381854,,,,,,,,,,,,,,,,,,,,,,,,,,,,,,,,,
,3865774846.55063,299.976303100586,25.0585975646973,,,5,,,,40.5399985611439,,,,,5.7407620334429E-6,6.77142698408746E-8,1.14460501220321,0.00604550879323528,1.91358729619839E-6,2.25714227107819E-8,1.91320546636153E-6,1.93869062911508E-8,3.82254320604997E-8,1.15592814502866E-8,3.00000007569434,1.00057637691498,19.98847910208,20,1,3,0.0201947346504852,0.00064876534391641,0.000167335703736171,235.797096252441,299.91796875,299.998077392578,25.0585975646973,25.0585975646973,,,8.15481472015381,,1,,,,,,1,1,1,299.985717773438,0,299.97503366778,,,,,,,,,,,,,,,,,,,,,,,,,,,,,,,,,
,3865775008.6617,299.997634887695,25.0585975646973,,,5,,,,40.5399985611439,,,,,5.54240331717067E-6,3.372145000417E-9,0.609914656699756,0.000413811752650074,1.84761862871544E-6,1.12414011845688E-9,1.84751394693257E-6,8.24701720491194E-10,1.96675638035342E-8,7.63909731671958E-10,2.99975505281847,100.057640075684,10,1000,1,3,0.0192938041810747,0.00247756427007697,0.0122568709775805,197.743499755859,299.990478515625,300.007385253906,25.0585975646973,25.0585975646973,,,8.16282367706299,,1,,,,,,1,1,1,299.995483398438,0,299.998901367188,,,,,,,,,,,,,,,,,,,,,,,,,,,,,,,,,