File: LT data/Sherwood/D2/228-FC-ZFC-RTSIRM-contsweepwithloop.dat
[Header]
; MPMS3 Data File (default extension .dat)
; Copyright (c) 2007, Quantum Design, Inc. All rights reserved.
TITLE,
FILEOPENTIME,3865506943.51374,06/27/2022,4:53 pm
BYAPP,MPMS3 w/ AC,1.0,1.1
INFO,MPMS3 Measurement Release 1.1.16 Build 424, MultiVu Release 2.3.4.19,APPNAME
INFO,Linear Motor Servo Controller,MOTOR_MODULE_NAME
INFO,3101-100 N2,MOTOR_HW_VERSION
INFO,,MOTOR_SERIAL_NUMBER
INFO,01.04.28,MOTOR_SOFTWARE_VERSION
INFO,Quantum Design Squid Module,SQUID_MODULE_NAME
INFO,3101-501 B0,SQUID_HW_VERSION
INFO,SQM327,SQUID_SERIAL_NUMBER
INFO,01.03.04,SQUID_SOFTWARE_VERSION
INFO,Quantum Design VSM Oven,OVEN_MODULE_NAME
INFO,3101-201 A3,OVEN_HW_VERSION
INFO,OVB365,OVEN_SERIAL_NUMBER
INFO,01.07.07,OVEN_SOFTWARE_VERSION
INFO,SQUID AC,AC_MODULE_NAME
INFO,3101-401 G0,AC_HW_VERSION
INFO,SAC220,AC_SERIAL_NUMBER
INFO,SQUID AC 00.95.07,AC_SOFTWARE_VERSION
INFO,TCI344,COIL_SERIAL_NUMBER
INFO,0,MOMENT_UNITS
INFO,oil stained sst,SAMPLE_MATERIAL
INFO,,SAMPLE_COMMENT
INFO,,SAMPLE_MASS
INFO,,SAMPLE_VOLUME
INFO,,SAMPLE_MOLECULAR_WEIGHT
INFO,,SAMPLE_SIZE
INFO,,SAMPLE_SHAPE
INFO,Straw,SAMPLE_HOLDER
INFO,Standard,SAMPLE_HOLDER_DETAIL
INFO,57.72,SAMPLE_OFFSET
DATATYPE,COMMENT,1
DATATYPE,TIME,2
STARTUPAXIS,X,2
STARTUPAXIS,Y1,5
FIELDGROUP, VSM,2,3,4,5,6,8,9,10,11,14,15
FIELDGROUP, DC, 2,3,4,14,56,57,58,59,60,61,62,63,64,65,66,67,68,69
FIELDGROUP, AC, 2,3,4,11,16,17,18,19,20,21,22,23,24,25,26,27,28,29,30
STARTUPGROUP, All
[Data]
Comment,Time Stamp (sec),Temperature (K),Magnetic Field (Oe),Moment (emu),M. Std. Err. (emu),Transport Action,Averaging Time (sec),Frequency (Hz),Peak Amplitude (mm),Center Position (mm),Lockin Signal' (V),Lockin Signal (V),Range,M. Quad. Signal (emu),AC Moment (emu),AC M. Std Err. (emu),AC Phase (deg),AC Phase Std. Err. (deg),AC Susceptibility (emu/Oe),AC Suscept. Std Err. (emu/Oe),AC X' (emu/Oe),AC X' Std Err. (emu/Oe),AC X'' (emu/Oe),AC X'' Std Err. (emu/Oe),AC Drive (Oe),AC Frequency (Hz),AC Averaging Time (sec),AC Cycles,AC Range,AC Measure Type,AC Signal' (V),AC Signal'' (V),AC Trim Coil Ratio,AC Trim Coil Phase,Min. Temperature (K),Max. Temperature (K),Min. Field (Oe),Max. Field (Oe),Mass (grams),Motor Lag (deg),Pressure (Torr),Measure Count,Measurement Number,SQUID Status (code),Motor Status (code),Measure Status (code),Motor Current (amps),Motor Temp. (C),Temp. Status (code),Field Status (code),Chamber Status (code),Chamber Temp (K),Redirection State,Average Temp (K),Rotation Angle (deg),Rotator state,DC Moment Fixed Ctr (emu),DC Moment Err Fixed Ctr (emu),DC Moment Free Ctr (emu),DC Moment Err Free Ctr (emu),DC Fixed Fit,DC Free Fit,DC Calculated Center (mm),DC Calculated Center Err (mm),DC Scan Length (mm),DC Scan Time (s),DC Number of Points,DC Squid Drift,DC Min V (V),DC Max V (V),DC Scans per Measure,Map 01,Map 02,Map 03,Map 04,Map 05,Map 06,Map 07,Map 08,Map 09,Map 10,Map 11,Map 12,Map 13,Map 14,Map 15,Map 16
,3865509085.81241,1.99998533725739,25.2842388153076,0.022162003395994,1.07106337154827E-6,1,5,12.9061126708984,4.97541780289132,39.6299995481968,28.7396208381394,4.20850998196587,100,-1.03080879616227E-5,,,,,,,,,,,,,,,,,,,,,1.99998533725739,1.99998533725739,25.2842388153076,25.2842388153076,50.3134277828899,5.39749124237694,2.43518948554993,65,1,0,0,1,0.279769897460938,30.7917900085449,1,1,1,1.99998533725739,0,1.99998533725739,,,,,,,,,,,,,,,,,,,,,,,,,,,,,,,,,
,3865509266.77367,29.0846538543701,25.2842388153076,0.000737198627373733,5.22245752357858E-8,1,5,12.9061126708984,4.97503480441809,39.6299995481968,0.955748678289806,0.140962488184502,1,4.17152533714528E-7,,,,,,,,,,,,,,,,,,,,,29.0846538543701,29.0846538543701,25.2842388153076,25.2842388153076,50.2567597152457,5.39780388185548,5.97834539413452,65,1,0,0,1,0.270309448242187,31.7693061828613,2,1,1,29.0846538543701,0,29.0846538543701,,,,,,,,,,,,,,,,,,,,,,,,,,,,,,,,,
,3865509445.42722,57.0470199584961,25.2842388153076,0.000714931358788927,4.08600800940219E-8,1,5,12.9061126708984,4.98612014709083,39.6599993109703,0.929901124892694,0.136341568851611,1,-2.04026541820258E-7,,,,,,,,,,,,,,,,,,,,,57.0470199584961,57.0470199584961,25.2842388153076,25.2842388153076,50.2516791298707,5.39603044725818,6.52201747894287,65,1,0,0,1,0.269699096679687,31.2805480957031,2,1,1,57.0470199584961,0,57.0470199584961,,,,,,,,,,,,,,,,,,,,,,,,,,,,,,,,,
,3865509620.69926,85.008918762207,25.2842388153076,0.000689483845076177,3.3580635996416E-8,1,5,12.9061126708984,4.98531015020498,39.7100001573563,0.896613677843865,0.131347068909266,1,-2.82520442474363E-7,,,,,,,,,,,,,,,,,,,,,85.008918762207,85.008918762207,25.2842388153076,25.2842388153076,50.2204139891015,5.39887597539092,6.76355266571045,64,1,64,0,0,0.267105102539062,31.2805480957031,2,1,1,85.008918762207,0,85.008918762207,,,,,,,,,,,,,,,,,,,,,,,,,,,,,,,,,
,3865509791.15171,113.077136993408,25.2842388153076,0.000663548845946904,4.26785648726428E-8,1,5,12.9061126708984,4.98484579563208,39.7600010037422,0.862786705781204,0.126307330793244,1,-3.35398918573121E-7,,,,,,,,,,,,,,,,,,,,,113.017883300781,113.136390686035,25.2842388153076,25.2842388153076,50.2684841430342,5.40158384822356,6.88678026199341,65,1,0,0,1,0.270309448242187,31.7693061828613,2,1,1,113.136390686035,0,113.077136993408,,,,,,,,,,,,,,,,,,,,,,,,,,,,,,,,,
,3865509959.6083,141.000366210938,25.2842388153076,0.000638933644847537,5.45667232742582E-8,1,5,12.9061126708984,4.98445130866109,39.8400016129017,0.830652423974201,0.121851544273542,1,-1.35830914302147E-7,,,,,,,,,,,,,,,,,,,,,141.000366210938,141.000366210938,25.2842388153076,25.2842388153076,50.2004824618611,5.40422520640702,6.96992635726929,63,1,64,0,0,0.273666381835938,31.7693061828613,2,1,1,141.000366210938,0,141.000366210938,,,,,,,,,,,,,,,,,,,,,,,,,,,,,,,,,
,3865510129.39915,169.023086547852,25.2842388153076,0.000616539610709166,3.73645036932087E-8,1,5,12.9061126708984,4.98349032819637,39.9300009012222,0.801333459243842,0.117469004111118,1,-1.92553792844544E-7,,,,,,,,,,,,,,,,,,,,,169.023086547852,169.023086547852,25.2842388153076,25.2842388153076,50.1438143942168,5.40763729109102,7.03798246383667,64,1,64,0,0,0.268402099609375,31.7693061828613,2,1,1,169.023086547852,0,169.023086547852,,,,,,,,,,,,,,,,,,,,,,,,,,,,,,,,,
,3865510298.97741,197.213607788086,25.2842388153076,0.000594121427139417,5.08556649372014E-8,1,5,12.9061126708984,4.9826301702955,40.0400012731552,0.772005902245193,0.113188921896014,1,-1.71162218818159E-7,,,,,,,,,,,,,,,,,,,,,197.213607788086,197.213607788086,25.2842388153076,25.2842388153076,50.2551964582072,5.41014709009735,7.11398792266846,65,1,0,0,1,0.271835327148438,31.2805480957031,2,1,1,197.213607788086,0,197.213607788086,,,,,,,,,,,,,,,,,,,,,,,,,,,,,,,,,
,3865510467.15477,225.012405395508,25.2842388153076,0.000573042080811367,2.21763919474716E-8,1,5,12.9061126708984,4.9826931927505,40.1600003242493,0.744607627226163,0.109316841035144,1,-5.58785466829515E-8,,,,,,,,,,,,,,,,,,,,,225.012405395508,225.012405395508,25.2842388153076,25.2842388153076,50.1793784918418,5.41035521721777,7.25403499603271,64,1,64,0,0,0.27191162109375,32.2580642700195,2,1,1,225.012405395508,0,225.012405395508,,,,,,,,,,,,,,,,,,,,,,,,,,,,,,,,,
,3865510635.65497,253.012832641602,25.2842388153076,0.000554156108509559,3.95864556058454E-8,1,5,12.9061126708984,4.9828985662623,40.3000004589558,0.720131678919541,0.105565860710788,1,-1.72783659415792E-7,,,,,,,,,,,,,,,,,,,,,253.012832641602,253.012832641602,25.2842388153076,25.2842388153076,50.0926177262072,5.41005170282467,7.50912189483643,64,1,64,0,0,0.271224975585938,31.2805480957031,2,1,1,253.012832641602,0,253.012832641602,,,,,,,,,,,,,,,,,,,,,,,,,,,,,,,,,
,3865510803.86916,281.019653320313,25.2842388153076,0.000533529246120743,4.35126044997972E-8,1,5,12.9061126708984,4.9834279801531,40.4600016772747,0.693438186134206,0.101598423716334,1,-2.0730688580074E-7,,,,,,,,,,,,,,,,,,,,,281.019653320313,281.019653320313,25.2842388153076,25.2842388153076,50.2559780867265,5.40849985315984,7.62925910949707,64,1,64,0,0,0.270843505859375,31.7693061828613,2,1,1,281.019653320313,0,281.019653320313,,,,,,,,,,,,,,,,,,,,,,,,,,,,,,,,,
,3865512456.12908,1.99993139505386,46417.3984375,1.3814351369661,0.0068902290265293,1,2,12.9061126708984,4.97556131452572,39.6299995481968,1791.85083856454,260.047195526299,1000,-0.00241201709033746,,,,,,,,,,,,,,,,,,,,,1.9998676776886,1.99999511241913,46327.46875,46507.328125,51.0364341631785,5.39986255597,2.42344903945923,26,1,0,0,1,0.268630981445313,31.2805480957031,1,6,1,1.9998676776886,0,1.99993139505386,,,,,,,,,,,,,,,,,,,,,,,,,,,,,,,,,
,3865512518.95016,1.99977737665176,40142.791015625,1.31228718978219,0.00850857167646732,1,2,12.9061126708984,4.97561565163879,39.6299995481968,1700.80207592877,256.451918373523,1000,0.00497102912288956,,,,,,,,,,,,,,,,,,,,,1.99972784519196,1.99982690811157,40087.91796875,40197.6640625,50.9371673412362,5.39918844315692,2.41779160499573,25,1,68,0,0,0.26947021484375,31.2805480957031,1,6,1,1.99972784519196,0,1.99977737665176,,,,,,,,,,,,,,,,,,,,,,,,,,,,,,,,,
,3865512582.3067,2.00004816055298,33818.26953125,1.23438859296143,0.000242286129790413,1,2,12.9061126708984,4.97561593950982,39.6299995481968,1600.59003362724,236.130168696516,1000,0.000744252744910853,,,,,,,,,,,,,,,,,,,,,1.99992275238037,2.00017356872559,33648.71875,33987.8203125,50.6913451719381,5.39869829360893,2.41032457351685,26,1,0,0,1,0.289382934570313,30.3030319213867,1,6,1,2.00017356872559,0,2.00004816055298,,,,,,,,,,,,,,,,,,,,,,,,,,,,,,,,,
,3865512639.44001,1.9999395608902,28112.58203125,1.14364151929153,0.000230630261781039,1,2,12.9061126708984,4.97559306346936,39.6299995481968,1482.92431631695,218.684062519551,1000,0.000623689648451663,,,,,,,,,,,,,,,,,,,,,1.99984836578369,2.0000307559967,28017.806640625,28207.357421875,50.5889518359188,5.39812855763738,2.41680860519409,26,1,0,0,1,0.269241333007813,31.2805480957031,1,6,1,1.99984836578369,0,1.9999395608902,,,,,,,,,,,,,,,,,,,,,,,,,,,,,,,,,
,3865512695.95364,1.99996548891068,22472.052734375,1.03268038823348,0.000276605713511101,1,2,12.9061126708984,4.97555123064521,39.6299995481968,1339.01675118913,197.544917487296,1000,0.000625548214319703,,,,,,,,,,,,,,,,,,,,,1.99995052814484,1.99998044967651,22367.09765625,22577.0078125,50.56745705164,5.39670765636913,2.40806341171265,26,1,0,0,1,0.287933349609375,31.2805480957031,1,6,1,1.99998044967651,0,1.99996548891068,,,,,,,,,,,,,,,,,,,,,,,,,,,,,,,,,
,3865512755.54522,1.9998065829277,16526.1645507813,0.880428816932224,0.000332982354742106,1,2,12.9061126708984,4.9755856321708,39.6299995481968,1141.70629473465,167.780522698644,1000,3.87724513592653E-5,,,,,,,,,,,,,,,,,,,,,1.99977791309357,1.99983525276184,16356.4951171875,16695.833984375,50.3872916779572,5.39669746478082,2.41270542144775,26,1,0,0,1,0.278701782226562,31.7693061828613,1,6,1,1.99977791309357,0,1.9998065829277,,,,,,,,,,,,,,,,,,,,,,,,,,,,,,,,,
,3865512818.74392,1.99962019920349,10209.4233398438,0.665365891541281,0.000448626839422204,1,2,12.9061126708984,4.97550386966759,39.6299995481968,862.736640420975,127.231793129916,1000,0.000367118581571406,,,,,,,,,,,,,,,,,,,,,1.9995219707489,1.99971842765808,10114.5478515625,10304.298828125,50.2884156702746,5.39618901443368,2.41962337493896,26,1,0,0,1,0.269241333007813,31.7693061828613,1,6,1,1.99971842765808,0,1.99962019920349,,,,,,,,,,,,,,,,,,,,,,,,,,,,,,,,,
,3865512877.22293,2.00000238418579,4369.16528320313,0.374441939619487,0.000655789162061606,1,2,12.9061126708984,4.97557648208853,39.6299995481968,485.53217584458,71.5500352289672,1000,0.00016609951197964,,,,,,,,,,,,,,,,,,,,,1.99997067451477,2.00003409385681,4269.33837890625,4468.9921875,50.3079563832553,5.39569878699502,2.41074514389038,26,1,0,0,1,0.279998779296875,31.2805480957031,1,6,1,2.00003409385681,0,2.00000238418579,,,,,,,,,,,,,,,,,,,,,,,,,,,,,,,,,
,3865512945.70361,1.99992436170578,-2477.89916992187,-0.204950843269072,0.000878039514468889,1,2,12.9061126708984,4.97558323810602,39.6299995481968,-265.767587159756,-39.088248541312,1000,-3.32735112643932E-5,,,,,,,,,,,,,,,,,,,,,1.99987375736237,1.99997496604919,-2567.82299804687,-2387.97534179687,50.3263246534572,5.39582174023314,2.40516352653503,26,1,0,0,1,0.268707275390625,31.2805480957031,1,6,1,1.99997496604919,0,1.99992436170578,,,,,,,,,,,,,,,,,,,,,,,,,,,,,,,,,
,3865513004.09977,2.00010055303574,-8316.48388671875,-0.568838168203413,0.000526564940597597,1,2,12.9061126708984,4.97548324226208,39.6299995481968,-737.619831652186,-108.441491156589,1000,-5.81704424265849E-5,,,,,,,,,,,,,,,,,,,,,1.99997460842133,2.00022649765015,-8416.3173828125,-8216.650390625,50.2966227697265,5.39595153357352,2.39498019218445,26,1,0,0,1,0.280075073242187,30.7917900085449,1,6,1,2.00022649765015,0,2.00010055303574,,,,,,,,,,,,,,,,,,,,,,,,,,,,,,,,,
,3865513066.56176,1.99990880489349,-14561.9975585938,-0.816731487768285,0.000360554645634379,1,2,12.9061126708984,4.97548174610097,39.6299995481968,-1059.00979534167,-156.080684396363,1000,-0.000377851636024313,,,,,,,,,,,,,,,,,,,,,1.99985194206238,1.99996566772461,-14646.9453125,-14477.0498046875,50.3845559781399,5.3963530362524,2.37530374526978,26,1,0,0,1,0.269546508789062,32.2580642700195,1,6,1,1.99996566772461,0,1.99990880489349,,,,,,,,,,,,,,,,,,,,,,,,,,,,,,,,,
,3865513126.27222,2.00033628940582,-20532.298828125,-0.986344206915555,0.000261775237426148,1,2,12.9061126708984,4.97549270453096,39.6299995481968,-1278.85918949124,-189.052052356661,1000,-0.000885944690897094,,,,,,,,,,,,,,,,,,,,,2.00027012825012,2.00040245056152,-20697.38671875,-20367.2109375,50.5060992128803,5.39728013200019,2.36602544784546,26,1,0,0,1,0.289459228515625,30.7917900085449,1,6,1,2.00027012825012,0,2.00033628940582,,,,,,,,,,,,,,,,,,,,,,,,,,,,,,,,,
,3865513189.78738,1.99997240304947,-26889.919921875,-1.11881305982935,0.000229390314209935,1,2,12.9061126708984,4.97573858714362,39.6299995481968,-1450.73282625047,-214.332593365194,1000,-0.00090884584915992,,,,,,,,,,,,,,,,,,,,,1.99981510639191,2.00012969970703,-26940,-26839.83984375,50.6159180198323,5.39677616065775,2.35536861419678,26,1,0,0,1,0.2685546875,31.2805480957031,1,6,1,2.00012969970703,0,1.99997240304947,,,,,,,,,,,,,,,,,,,,,,,,,,,,,,,,,
,3865513253.22258,2.00011777877808,-33241.4765625,-1.22676792559337,0.000186111511924132,1,2,12.9061126708984,4.97563694908267,39.6299995481968,-1590.70045096779,-234.79339176962,1000,-0.000831894061368772,,,,,,,,,,,,,,,,,,,,,1.99982118606567,2.00041437149048,-33401.6796875,-33081.2734375,50.7347255547554,5.39752306306026,2.34081482887268,26,1,0,0,1,0.288772583007812,31.2805480957031,1,6,1,1.99982118606567,0,2.00011777877808,,,,,,,,,,,,,,,,,,,,,,,,,,,,,,,,,
,3865513312.54697,1.99992632865906,-39187.3359375,-1.30715617712461,0.000194392209473643,1,2,12.9061126708984,4.97566973043051,39.6299995481968,-1694.92050235912,-250.398255659557,1000,-0.00105365511666588,,,,,,,,,,,,,,,,,,,,,1.99990916252136,1.99994349479675,-39302.48828125,-39072.18359375,50.8410270333708,5.39836605763188,2.33658695220947,26,1,0,0,1,0.289077758789063,31.7693061828613,1,6,1,1.99994349479675,0,1.99992632865906,,,,,,,,,,,,,,,,,,,,,,,,,,,,,,,,,
,3865513372.73133,1.9976282119751,-45217.787109375,-1.37828196672905,0.000173920069024014,1,2,12.9061126708984,4.97564442715924,39.6299995481968,-1787.00846985648,-264.867318305018,1000,-0.00176346479830309,,,,,,,,,,,,,,,,,,,,,1.99684166908264,1.99841475486755,-45312.86328125,-45122.7109375,50.9547539829189,5.39837601193592,2.32500553131104,24,1,68,0,0,0.289154052734375,31.2805480957031,1,6,1,1.99841475486755,0,1.9976282119751,,,,,,,,,,,,,,,,,,,,,,,,,,,,,,,,,
,3865513437.40447,2.00012862682343,-48918.29296875,-1.41736561261711,0.00015615951972938,1,2,12.9061126708984,4.97569175372919,39.6299995481968,-1837.75439530442,-272.058332812999,1000,-0.00156407664318695,,,,,,,,,,,,,,,,,,,,,2.00000286102295,2.0002543926239,-49033.04296875,-48803.54296875,51.141563199015,5.39906528774027,2.29974865913391,24,1,68,0,0,0.268478393554687,30.7917900085449,1,6,1,2.00000286102295,0,2.00012862682343,,,,,,,,,,,,,,,,,,,,,,,,,,,,,,,,,
,3865513497.64347,2.00016134977341,-42910.474609375,-1.35311852980249,0.0002112554215338,1,2,12.9061126708984,4.97559449766379,39.6299995481968,-1754.52034514361,-258.923543219896,1000,-0.000879621967874908,,,,,,,,,,,,,,,,,,,,,1.99952876567841,2.00079393386841,-43005.2578125,-42815.69140625,50.9950078516592,5.39877023251247,2.28653454780579,26,1,0,0,1,0.2691650390625,31.7693061828613,5,6,1,1.99952876567841,0,2.00016134977341,,,,,,,,,,,,,,,,,,,,,,,,,,,,,,,,,
,3865513560.0955,2.00000804662704,-36676.779296875,-1.27566349835604,0.000212745234419058,1,2,12.9061126708984,4.97557295591616,39.6299995481968,-1654.09374577218,-243.995290448451,1000,-0.000747915657061584,,,,,,,,,,,,,,,,,,,,,1.99997341632843,2.00004267692566,-36766.890625,-36586.66796875,50.7405877686496,5.39801289640437,2.29609370231628,26,1,0,0,1,0.289306640625,31.2805480957031,5,6,1,2.00004267692566,0,2.00000804662704,,,,,,,,,,,,,,,,,,,,,,,,,,,,,,,,,
,3865513620.86709,2.00047248601913,-30613.0390625,-1.18679047033967,0.000213135144976269,1,2,12.9061126708984,4.97560762935335,39.6299995481968,-1538.83638764965,-227.236469405587,1000,-0.000879061393183916,,,,,,,,,,,,,,,,,,,,,1.99952280521393,2.00142216682434,-30677.966796875,-30548.111328125,50.6319414044765,5.39751049556772,2.27694725990295,26,1,0,0,1,0.278701782226562,32.7468223571777,5,6,1,1.99952280521393,0,2.00047248601913,,,,,,,,,,,,,,,,,,,,,,,,,,,,,,,,,
,3865513681.03913,2.0002549290657,-24604.220703125,-1.07775840373959,0.000245060282775885,1,2,12.9061126708984,4.97557457852132,39.6299995481968,-1397.52255444735,-205.852697269082,1000,-0.000408625692923146,,,,,,,,,,,,,,,,,,,,,1.99999129772186,2.00051856040955,-24689.01171875,-24519.4296875,50.5158695693707,5.3970431727578,2.28852820396423,26,1,0,0,1,0.289230346679687,31.7693061828613,5,6,1,2.00051856040955,0,2.0002549290657,,,,,,,,,,,,,,,,,,,,,,,,,,,,,,,,,
,3865513741.39838,1.99984329938889,-18579.8662109375,-0.939336443239066,0.000303747474608745,1,2,12.9061126708984,4.97558170900723,39.6299995481968,-1217.94277448484,-180.036157042838,1000,-0.000835643869036109,,,,,,,,,,,,,,,,,,,,,1.9997661113739,1.99992048740387,-18669.658203125,-18490.07421875,50.3618887510822,5.39680307837634,2.28551244735718,26,1,0,0,1,0.279312133789062,31.7693061828613,1,6,1,1.99992048740387,0,1.99984329938889,,,,,,,,,,,,,,,,,,,,,,,,,,,,,,,,,
,3865513797.96743,2.00004023313522,-12930.142578125,-0.769320055641854,0.000385496536491747,1,2,12.9061126708984,4.97554969295086,39.6299995481968,-997.600262623786,-146.702830427099,1000,-0.000109021927130685,,,,,,,,,,,,,,,,,,,,,1.99985039234161,2.00023007392883,-13039.998046875,-12820.287109375,50.3583714227457,5.39570276026571,2.28391051292419,26,1,0,0,1,0.268020629882813,30.7917900085449,5,6,1,1.99985039234161,0,2.00004023313522,,,,,,,,,,,,,,,,,,,,,,,,,,,,,,,,,
,3865513854.45529,2.00017082691193,-7284.37426757812,-0.535200547031959,0.000529035893789187,1,2,12.9061126708984,4.97555410446046,39.6299995481968,-694.039512440036,-101.866844381642,1000,7.18334361592998E-5,,,,,,,,,,,,,,,,,,,,,1.99999809265137,2.00034356117249,-7354.29150390625,-7214.45703125,50.3505551375534,5.39478067669582,2.28915476799011,26,1,0,0,1,0.279464721679687,31.2805480957031,5,6,1,1.99999809265137,0,2.00017082691193,,,,,,,,,,,,,,,,,,,,,,,,,,,,,,,,,
,3865513916.85116,1.99991351366043,-1054.34771728516,-0.135879000564471,0.000956429388769909,1,2,12.9061126708984,4.97559385087818,39.6299995481968,-176.198294827556,-25.9266739210987,1000,-3.11110441250053E-5,,,,,,,,,,,,,,,,,,,,,1.99973428249359,2.00009274482727,-1129.29162597656,-979.40380859375,50.2845075276784,5.39466299621741,2.28914260864258,26,1,0,0,1,0.289535522460937,31.2805480957031,1,6,1,2.00009274482727,0,1.99991351366043,,,,,,,,,,,,,,,,,,,,,,,,,,,,,,,,,
,3865513979.35102,2.00001841783524,5198.5498046875,0.398036495313051,0.000673661743485554,1,2,12.9061126708984,4.97563540847663,39.6299995481968,516.151243668692,75.9521212874049,1000,9.34880176303346E-5,,,,,,,,,,,,,,,,,,,,,1.99994432926178,2.00009250640869,5078.6220703125,5318.4775390625,50.2153334037265,5.39540856709203,2.28417658805847,26,1,0,0,1,0.289306640625,30.7917900085449,1,6,1,1.99994432926178,0,2.00001841783524,,,,,,,,,,,,,,,,,,,,,,,,,,,,,,,,,
,3865514037.55112,2.0001380443573,11013.9750976562,0.689173147127713,0.000432440094548325,1,2,12.9061126708984,4.97564620828291,39.6299995481968,893.638424197735,131.813423160203,1000,0.000398670960176679,,,,,,,,,,,,,,,,,,,,,2.0000205039978,2.0002555847168,10918.8173828125,11109.1328125,50.2751279854476,5.39573256735007,2.27660059928894,26,1,0,0,1,0.289688110351562,31.2805480957031,1,6,1,1.99996793270111,0,2.0001380443573,,,,,,,,,,,,,,,,,,,,,,,,,,,,,,,,,
,3865514101.28109,2.00005495548248,17394.62890625,0.905759981549509,0.00029930240459203,1,2,12.9061126708984,4.97564165452844,39.6299995481968,1174.45828924443,173.393985539484,1000,0.000644032167337831,,,,,,,,,,,,,,,,,,,,,1.99984812736511,2.00026178359985,17229.7734375,17559.484375,50.4365342746688,5.39605327351556,2.26965475082397,26,1,0,0,1,0.279693603515625,31.7693061828613,1,6,1,2.00026178359985,0,2.00005495548248,,,,,,,,,,,,,,,,,,,,,,,,,,,,,,,,,
,3865514164.44849,1.99968111515045,23706.373046875,1.05750676167543,0.000264030878106331,1,2,12.9061126708984,4.97565918601496,39.6299995481968,1371.23407470309,202.40545053765,1000,0.000721737431475964,,,,,,,,,,,,,,,,,,,,,1.99835610389709,2.00100612640381,23611.390625,23801.35546875,50.5350194680919,5.39678911470258,2.2581160068512,26,1,0,0,1,0.268630981445313,32.7468223571777,1,6,1,1.99835610389709,0,1.99968111515045,,,,,,,,,,,,,,,,,,,,,,,,,,,,,,,,,
,3865514220.868,2.00011360645294,29358.685546875,1.16452513632101,0.000205925523959019,1,2,12.9061126708984,4.9756962531037,39.6299995481968,1510.0128803696,222.919650237211,1000,0.000816893895719086,,,,,,,,,,,,,,,,,,,,,2.000075340271,2.00015187263489,29268.466796875,29448.904296875,50.6628157309861,5.39727894865097,2.24922442436218,26,1,0,0,1,0.2691650390625,31.2805480957031,1,6,1,2.00015187263489,0,2.00011360645294,,,,,,,,,,,,,,,,,,,,,,,,,,,,,,,,,
,3865514277.33513,2.00010967254639,35020.53125,1.25225283858315,0.000204099768490431,1,2,12.9061126708984,4.97557503967423,39.6299995481968,1623.74506370113,239.477675044867,1000,0.000703332123371067,,,,,,,,,,,,,,,,,,,,,2.00008463859558,2.00013470649719,34920.37890625,35120.68359375,50.7718529094188,5.39879209763,2.25409770011902,26,1,0,0,1,0.268020629882813,30.7917900085449,1,6,1,2.00013470649719,0,2.00010967254639,,,,,,,,,,,,,,,,,,,,,,,,,,,,,,,,,
,3865514339.70623,1.99996215105057,41268.66015625,1.33332196407564,0.000160215932754832,1,2,12.9061126708984,4.97562430310362,39.6299995481968,1728.75307738306,255.904251971339,1000,0.00145797997935784,,,,,,,,,,,,,,,,,,,,,1.99978244304657,2.00014185905457,41173.6328125,41363.6875,50.8617401891304,5.39860852939839,2.24026131629944,26,1,0,0,1,0.268936157226562,31.7693061828613,1,6,1,1.99978244304657,0,1.99996215105057,,,,,,,,,,,,,,,,,,,,,,,,,,,,,,,,,
,3865514399.46308,1.99989432096481,47255.431640625,1.40074272845334,0.000210150012700916,1,2,12.9061126708984,4.97564351904722,39.6299995481968,1816.20048995327,268.700056181167,1000,0.00141934041298752,,,,,,,,,,,,,,,,,,,,,1.99987089633942,1.99991774559021,47094.9453125,47415.91796875,51.0989644447169,5.39984098574341,2.23519778251648,26,1,0,0,1,0.289077758789063,31.2805480957031,1,6,1,1.99991774559021,0,1.99989432096481,,,,,,,,,,,,,,,,,,,,,,,,,,,,,,,,,
,3865514860.37111,14.5101127624512,25.1714191436768,0.000644446367211834,5.29805492295157E-8,1,5,12.9061126708984,5.00634805570703,39.6299995481968,0.843003870086041,0.123522164614766,10,-2.42718777826852E-7,,,,,,,,,,,,,,,,,,,,,14.1516122817993,14.868613243103,25.1714191436768,25.1714191436768,50.2098620040919,5.39376731132337,5.11707973480225,65,1,0,0,1,0.2685546875,30.7917900085449,6,1,1,14.868613243103,0,14.5101127624512,,,,,,,,,,,,,,,,,,,,,,,,,,,,,,,,,
,3865515037.3811,42.0402221679687,25.1714191436768,0.00065269119568294,4.58439921572364E-8,1,5,12.9061126708984,5.00701444521159,39.6399982273579,0.853917585775902,0.125332460467281,1,-8.78292433699095E-8,,,,,,,,,,,,,,,,,,,,,42.0402221679687,42.0402221679687,25.1714191436768,25.1714191436768,50.2876340417553,5.39314802963129,6.23617696762085,64,1,64,0,0,0.267868041992187,30.7917900085449,2,1,1,42.0402221679687,0,42.0402221679687,,,,,,,,,,,,,,,,,,,,,,,,,,,,,,,,,
,3865515214.85269,70.0318832397461,25.1714191436768,0.000637498323628196,2.95884214843241E-8,1,5,12.9061126708984,5.00579147166071,39.6800003945827,0.833764757531289,0.12231190287999,1,-1.32682523829842E-7,,,,,,,,,,,,,,,,,,,,,70.0318832397461,70.0318832397461,25.1714191436768,25.1714191436768,50.2630127433996,5.39521442769879,6.61120796203613,65,1,0,0,1,0.270767211914062,31.2805480957031,2,1,1,70.0318832397461,0,70.0318832397461,,,,,,,,,,,,,,,,,,,,,,,,,,,,,,,,,
,3865515387.0764,98.0227661132813,25.1714191436768,0.000618891352920853,4.0194363107645E-8,1,5,12.9061126708984,5.00508301591511,39.7300012409687,0.809281725317199,0.118631694199834,1,-1.95131036440079E-7,,,,,,,,,,,,,,,,,,,,,98.0227661132813,98.0227661132813,25.1714191436768,25.1714191436768,50.2192415463226,5.40019570725097,6.77720737457275,63,1,64,0,0,0.266571044921875,31.2805480957031,2,1,1,98.0227661132813,0,98.0227661132813,,,,,,,,,,,,,,,,,,,,,,,,,,,,,,,,,
,3865515556.81495,126.019943237305,25.1714191436768,0.00059924985289579,2.98506446068994E-8,1,5,12.9061126708984,5.00481656975607,39.7900007665157,0.783538846821719,0.114862710106343,1,-1.85467676889781E-7,,,,,,,,,,,,,,,,,,,,,126.019943237305,126.019943237305,25.1714191436768,25.1714191436768,50.2454261017169,5.40162834001527,6.88905668258667,64,1,64,0,0,0.271148681640625,31.2805480957031,2,1,1,126.019943237305,0,126.019943237305,,,,,,,,,,,,,,,,,,,,,,,,,,,,,,,,,
,3865515725.38134,154.099090576172,25.1714191436768,0.000582405795267022,4.77192925201111E-8,1,5,12.9061126708984,5.00480450472065,39.8800000548363,0.761528092917825,0.111524980786711,1,-2.63412046884608E-7,,,,,,,,,,,,,,,,,,,,,154.099090576172,154.099090576172,25.1714191436768,25.1714191436768,50.2168966607649,5.40196525525343,6.95106792449951,65,1,0,0,1,0.269241333007813,31.7693061828613,2,1,1,154.099090576172,0,154.099090576172,,,,,,,,,,,,,,,,,,,,,,,,,,,,,,,,,
,3865515895.19418,182.136840820313,25.1714191436768,0.000565800721867189,4.9912867740378E-8,1,5,12.9061126708984,5.00379342530096,39.9800017476082,0.739600355610091,0.108359030222178,1,-2.21942485969801E-7,,,,,,,,,,,,,,,,,,,,,182.106185913086,182.167495727539,25.1714191436768,25.1714191436768,50.2161150322457,5.40625709415985,7.01514959335327,63,1,64,0,0,0.271453857421875,31.7693061828613,2,1,1,182.167495727539,0,182.136840820313,,,,,,,,,,,,,,,,,,,,,,,,,,,,,,,,,
,3865516063.65559,210.143844604492,25.1714191436768,0.000549839874818044,4.77377675232074E-8,1,5,12.9061126708984,5.00326271178958,40.0899983942509,0.718651379705794,0.105141437229744,1,-3.26804847141033E-7,,,,,,,,,,,,,,,,,,,,,210.143844604492,210.143844604492,25.1714191436768,25.1714191436768,50.2079079327938,5.40729814464024,7.11687564849854,63,1,64,0,0,0.270767211914062,31.7693061828613,2,1,1,210.143844604492,0,210.143844604492,,,,,,,,,,,,,,,,,,,,,,,,,,,,,,,,,
,3865516232.77533,238.124801635742,25.1714191436768,0.000535583449197414,4.52843483438752E-8,1,5,12.9061126708984,5.00235265018848,40.2299985289574,0.699827499085508,0.102472379199148,1,-2.546838472986E-7,,,,,,,,,,,,,,,,,,,,,238.124801635742,238.124801635742,25.1714191436768,25.1714191436768,50.1809417488803,5.40909193725673,7.34771919250488,65,1,0,0,1,0.277862548828125,31.7693061828613,2,1,1,238.124801635742,0,238.124801635742,,,,,,,,,,,,,,,,,,,,,,,,,,,,,,,,,
,3865516400.40697,266.024047851562,25.1714191436768,0.000522819116128579,2.15331896186529E-8,1,5,12.9061126708984,5.00322495311389,40.3699986636639,0.683323273973389,0.100002223148112,1,-2.88705054722407E-7,,,,,,,,,,,,,,,,,,,,,266.024047851562,266.024047851562,25.1714191436768,25.1714191436768,50.2575413437649,5.40782929988342,7.73091411590576,64,1,64,0,0,0.276107788085938,31.7693061828613,2,1,1,266.024047851562,0,266.024047851562,,,,,,,,,,,,,,,,,,,,,,,,,,,,,,,,,
,3865516569.4969,294.026916503906,25.1714191436768,0.000509963101493828,3.63779719426676E-8,1,5,12.9061126708984,5.00410418970313,40.5399985611439,0.666674312739645,0.097636130636595,1,-2.28861210372768E-7,,,,,,,,,,,,,,,,,,,,,294.026916503906,294.026916503906,25.1714191436768,25.1714191436768,50.2649668146976,5.40479783761243,7.59370803833008,63,1,64,0,0,0.27008056640625,31.7693061828613,2,1,1,294.026916503906,0,294.026916503906,,,,,,,,,,,,,,,,,,,,,,,,,,,,,,,,,
,3865517330.37543,280.969848632813,25.5098781585693,0.000565264597244039,2.91043320623812E-8,1,5,12.9061126708984,5.00487085155961,40.4499992728233,0.739123067248874,0.108283166208593,1,-2.26176793359687E-7,,,,,,,,,,,,,,,,,,,,,280.949645996094,280.990051269531,25.5098781585693,25.5098781585693,50.1320899664284,5.40176354847842,8.39834117889404,63,1,64,0,0,0.269317626953125,31.2805480957031,2,1,1,280.949645996094,0,280.969848632813,,,,,,,,,,,,,,,,,,,,,,,,,,,,,,,,,
,3865517497.3119,252.925003051758,25.5098781585693,0.0005642810573177,4.59114595091753E-8,1,5,12.9061126708984,5.00506757246399,40.3300002217293,0.737857227947148,0.108239382770565,1,-1.1972349398045E-7,,,,,,,,,,,,,,,,,,,,,252.925003051758,252.925003051758,25.5098781585693,25.5098781585693,50.2680933287745,5.40139948020198,8.14474678039551,65,1,0,0,1,0.27923583984375,30.7917900085449,2,1,1,252.925003051758,0,252.925003051758,,,,,,,,,,,,,,,,,,,,,,,,,,,,,,,,,
,3865517664.65435,224.978591918945,25.5098781585693,0.000561031781096139,4.89625409731741E-8,1,5,12.9061126708984,5.00482802689796,40.2100011706352,0.733591550405815,0.107389552201266,1,-2.86802251683317E-7,,,,,,,,,,,,,,,,,,,,,224.978591918945,224.978591918945,25.5098781585693,25.5098781585693,50.2559780867265,5.401971662366,7.98050594329834,65,1,0,0,1,0.270767211914062,31.2805480957031,2,1,1,224.978591918945,0,224.978591918945,,,,,,,,,,,,,,,,,,,,,,,,,,,,,,,,,
,3865517831.9923,196.971969604492,25.5098781585693,0.000556197749813759,3.41760464935268E-8,1,5,12.9061126708984,5.00570707099554,40.1099994778633,0.727412844649252,0.106739418005276,1,-9.39319695849769E-8,,,,,,,,,,,,,,,,,,,,,196.971969604492,196.971969604492,25.5098781585693,25.5098781585693,50.1836774486976,5.3989736175711,7.84646368026733,65,1,0,0,1,0.269546508789062,31.7693061828613,2,1,1,196.971969604492,0,196.971969604492,,,,,,,,,,,,,,,,,,,,,,,,,,,,,,,,,
,3865518000.65507,168.965103149414,25.5098781585693,0.000552517032257922,2.29175337849904E-8,1,5,12.9061126708984,5.00627681132289,40.0299988687038,0.722763263016335,0.105715642953503,1,-3.48887074356056E-7,,,,,,,,,,,,,,,,,,,,,168.965103149414,168.965103149414,25.5098781585693,25.5098781585693,50.2626219291399,5.39569741457263,7.72752141952515,64,1,64,0,0,0.268936157226562,31.2805480957031,2,1,1,168.965103149414,0,168.965103149414,,,,,,,,,,,,,,,,,,,,,,,,,,,,,,,,,
,3865518167.6435,140.967208862305,25.5098781585693,0.000550243661517174,3.62168480968657E-8,1,5,12.9061126708984,5.00662899309344,39.9399995803833,0.719852357770378,0.105344660327677,1,-3.06453354365212E-7,,,,,,,,,,,,,,,,,,,,,140.967208862305,140.967208862305,25.5098781585693,25.5098781585693,50.2712198428515,5.39432224419569,7.6248607635498,65,1,0,0,1,0.268020629882813,31.7693061828613,2,1,1,140.967208862305,0,140.967208862305,,,,,,,,,,,,,,,,,,,,,,,,,,,,,,,,,
,3865518335.34039,112.985458374023,25.5098781585693,0.000547146771589468,3.05836414188727E-8,1,5,12.9061126708984,5.00697154617689,39.8599989712238,0.715800857358119,0.105228209043196,1,5.17948745777515E-8,,,,,,,,,,,,,,,,,,,,,112.985458374023,112.985458374023,25.5098781585693,25.5098781585693,50.1574928933034,5.3931731362052,7.50553178787231,65,1,0,0,1,0.278167724609375,30.7917900085449,2,1,1,112.985458374023,0,112.985458374023,,,,,,,,,,,,,,,,,,,,,,,,,,,,,,,,,
,3865518503.89267,84.91796875,25.5098781585693,0.000544296868017162,4.16671771451565E-8,1,5,12.9061126708984,5.00719293670239,39.7799983620644,0.712144414553895,0.10449678422401,1,-9.35444639810572E-8,,,,,,,,,,,,,,,,,,,,,84.91796875,84.91796875,25.5098781585693,25.5098781585693,50.2665300717361,5.39202557068327,7.36189842224121,64,1,64,0,0,0.276641845703125,31.2805480957031,2,1,1,84.91796875,0,84.91796875,,,,,,,,,,,,,,,,,,,,,,,,,,,,,,,,,
,3865518668.52776,56.8913593292236,25.5098781585693,0.000538162809972012,2.20866982066507E-8,1,5,12.9061126708984,5.0071075545457,39.7199988365173,0.704119232374612,0.103199190677072,1,-1.82287548893675E-7,,,,,,,,,,,,,,,,,,,,,56.8759346008301,56.9067840576172,25.5098781585693,25.5098781585693,50.1942294337072,5.39195199938335,7.15585231781006,65,1,0,0,1,0.27679443359375,32.2580642700195,2,1,1,56.8759346008301,0,56.8913593292236,,,,,,,,,,,,,,,,,,,,,,,,,,,,,,,,,
,3865518830.85991,28.9750308990479,25.5098781585693,0.000523706075234751,3.35917695701979E-8,1,5,12.9061126708984,5.00721900108101,39.6800003945827,0.685167852520267,0.100823967478759,1,1.23677496350302E-7,,,,,,,,,,,,,,,,,,,,,28.9750308990479,28.9750308990479,25.5098781585693,25.5098781585693,50.2528515726495,5.39146923479095,6.69834852218628,64,1,64,0,0,0.276260375976562,31.7693061828613,2,1,1,28.9750308990479,0,28.9750308990479,,,,,,,,,,,,,,,,,,,,,,,,,,,,,,,,,
,3865519307.09748,1.99912774562836,25.5098781585693,0.000356748901323038,2.93184455078378E-8,1,5,12.9061126708984,5.00699168089325,39.6399982273579,0.466708654463902,0.068666586052587,1,7.62985441323569E-8,,,,,,,,,,,,,,,,,,,,,1.99912774562836,1.99912774562836,25.5098781585693,25.5098781585693,50.2262762029957,5.39329148679629,2.5127444267273,65,1,0,0,1,0.276565551757813,31.7693061828613,1,1,1,1.99912774562836,0,1.99912774562836,,,,,,,,,,,,,,,,,,,,,,,,,,,,,,,,,
,3865519489.02753,29.0192470550537,25.5098781585693,0.00052170969717099,1.73261154972901E-8,1,5,12.9061126708984,5.00695382432175,39.6399982273579,0.682554201421195,0.100100133886694,1,-1.30605941510602E-7,,,,,,,,,,,,,,,,,,,,,29.0192470550537,29.0192470550537,25.5098781585693,25.5098781585693,50.2868524132361,5.39189572526977,6.01836347579956,65,1,0,0,1,0.27740478515625,31.2805480957031,2,1,1,29.0192470550537,0,29.0192470550537,,,,,,,,,,,,,,,,,,,,,,,,,,,,,,,,,
,3865519667.82934,57.0971298217773,25.5098781585693,0.000536851276063477,5.25957297961145E-8,1,5,12.9061126708984,5.00680862788119,39.6599993109703,0.702362312706982,0.10281851618895,1,-2.74012161121515E-7,,,,,,,,,,,,,,,,,,,,,57.0971298217773,57.0971298217773,25.5098781585693,25.5098781585693,50.203608975938,5.39299014225228,6.52236318588257,65,1,0,0,1,0.286407470703125,30.7917900085449,2,1,1,57.0971298217773,0,57.0971298217773,,,,,,,,,,,,,,,,,,,,,,,,,,,,,,,,,
,3865519843.33162,85.0157852172852,25.5098781585693,0.000541547227612316,4.97929151582874E-8,1,5,12.9061126708984,5.00644408456569,39.7000014781952,0.708397621639711,0.103954029296549,1,-8.78093514935404E-8,,,,,,,,,,,,,,,,,,,,,85.0157852172852,85.0157852172852,25.5098781585693,25.5098781585693,50.2563689009861,5.39420243566559,6.78507995605469,65,1,0,0,1,0.268325805664062,31.2805480957031,2,1,1,85.0157852172852,0,85.0157852172852,,,,,,,,,,,,,,,,,,,,,,,,,,,,,,,,,
,3865520013.31143,113.044944763184,25.5098781585693,0.000543766625379936,3.52571563530685E-8,1,5,12.9061126708984,5.00570799285089,39.7600010037422,0.711150118045771,0.104388485100248,1,-6.53099250268209E-8,,,,,,,,,,,,,,,,,,,,,113.044944763184,113.044944763184,25.5098781585693,25.5098781585693,50.1997008333418,5.39682255747816,6.90720415115356,63,1,64,0,0,0.268478393554687,30.7917900085449,2,1,1,113.044944763184,0,113.044944763184,,,,,,,,,,,,,,,,,,,,,,,,,,,,,,,,,
,3865520182.31471,141.010696411133,25.5098781585693,0.000544684784622861,3.43263630093897E-8,1,5,12.9061126708984,5.00469990653681,39.8299992084503,0.712198164235437,0.104208689343115,1,-3.15218295284132E-7,,,,,,,,,,,,,,,,,,,,,141.010696411133,141.010696411133,25.5098781585693,25.5098781585693,50.1907121053707,5.40205895749391,6.99047231674194,64,1,64,0,0,0.27099609375,31.7693061828613,2,1,1,141.010696411133,0,141.010696411133,,,,,,,,,,,,,,,,,,,,,,,,,,,,,,,,,
,3865520351.29965,169.010360717773,25.5098781585693,0.000544490497225522,4.26543984386798E-8,1,5,12.9061126708984,5.00401643100143,39.9300009012222,0.711805177937208,0.104171245058131,1,-3.00084746312166E-7,,,,,,,,,,,,,,,,,,,,,169.010360717773,169.010360717773,25.5098781585693,25.5098781585693,50.1457684655149,5.40501664335803,7.06123304367065,64,1,64,0,0,0.270843505859375,31.7693061828613,2,1,1,169.010360717773,0,169.010360717773,,,,,,,,,,,,,,,,,,,,,,,,,,,,,,,,,
,3865520520.60545,197.036529541016,25.5098781585693,0.000544167871773844,5.01164192153858E-8,1,5,12.9061126708984,5.00412837208292,40.0400012731552,0.711382996217552,0.104267226481417,1,-1.81758470319236E-7,,,,,,,,,,,,,,,,,,,,,197.036529541016,197.036529541016,25.5098781585693,25.5098781585693,50.2067354900149,5.40430447107768,7.12932586669922,63,1,64,0,0,0.269699096679687,31.2805480957031,2,1,1,197.036529541016,0,197.036529541016,,,,,,,,,,,,,,,,,,,,,,,,,,,,,,,,,
,3865520689.4476,225.063827514648,25.5098781585693,0.000544367399101935,3.71143200344196E-8,1,5,12.9061126708984,5.00297111344373,40.1600003242493,0.711442975475375,0.104071017014291,1,-3.35390807784819E-7,,,,,,,,,,,,,,,,,,,,,225.063827514648,225.063827514648,25.5098781585693,25.5098781585693,50.1946202479669,5.4073674090122,7.26051139831543,63,1,64,0,0,0.272750854492187,31.2805480957031,2,1,1,225.063827514648,0,225.063827514648,,,,,,,,,,,,,,,,,,,,,,,,,,,,,,,,,
,3865520858.39883,253.101821899414,25.5098781585693,0.000544938480816569,3.83180811141727E-8,1,5,12.9061126708984,5.00271187104477,40.3000004589558,0.712142181940448,0.104141936333108,1,-3.59238360745223E-7,,,,,,,,,,,,,,,,,,,,,253.101821899414,253.101821899414,25.5098781585693,25.5098781585693,50.2043906044572,5.40874352039957,7.4791316986084,63,1,64,0,0,0.2728271484375,31.7693061828613,2,1,1,253.101821899414,0,253.101821899414,,,,,,,,,,,,,,,,,,,,,,,,,,,,,,,,,
,3865521019.68205,279.856948852539,25.5098781585693,0.00054446159199814,4.36740065790334E-8,1,5,12.9061126708984,5.00373183109695,40.4499992728233,0.711720506648941,0.104090902072433,1,-3.50961998614636E-7,,,,,,,,,,,,,,,,,,,,,279.44287109375,280.271026611328,25.5098781585693,25.5098781585693,50.2208048033611,5.40604858957439,7.59336948394775,65,1,0,0,1,0.270462036132813,31.2805480957031,2,1,1,280.271026611328,0,279.856948852539,,,,,,,,,,,,,,,,,,,,,,,,,,,,,,,,,
,3865521351.81592,300.006851196289,47120.75,0.0629030009451006,1.44431687522853E-5,1,2,12.9061126708984,5.00445297437903,40.5599996447563,82.2385871175279,12.0612361158525,100,-1.53591422626407E-5,,,,,,,,,,,,,,,,,,,,,300.006713867188,300.006988525391,47045.89453125,47195.60546875,50.0523638574668,5.40405605156301,7.51408338546753,25,1,64,0,0,0.2679443359375,31.7693061828613,1,6,1,300.006988525391,0,300.006851196289,,,,,,,,,,,,,,,,,,,,,,,,,,,,,,,,,
,3865521454.39903,300.004669189453,36878.24609375,0.0494782884155346,1.39921390058529E-5,1,2,12.9061126708984,5.00465991866147,40.5599996447563,64.6907489880046,9.48960641431453,100,-1.06115166097193E-5,,,,,,,,,,,,,,,,,,,,,300.004455566406,300.0048828125,36783.42578125,36973.06640625,50.1961835050053,5.40330620318198,7.57385873794556,26,1,0,0,1,0.2685546875,31.2805480957031,1,6,1,300.0048828125,0,300.004669189453,,,,,,,,,,,,,,,,,,,,,,,,,,,,,,,,,
,3865521541.13094,300.002471923828,28217.1962890625,0.0381531411069801,1.46409241776022E-5,1,2,12.9061126708984,5.00479876048714,40.5699983239174,49.8859643828199,7.31490800524467,100,-1.03965404093656E-5,,,,,,,,,,,,,,,,,,,,,300.002319335937,300.002624511719,28137.431640625,28296.9609375,50.2294027170726,5.40324119360893,7.69004631042481,26,1,0,0,1,0.27252197265625,31.2805480957031,1,6,1,300.002319335937,0,300.002471923828,,,,,,,,,,,,,,,,,,,,,,,,,,,,,,,,,
,3865521603.65092,300.002334594727,21977.3994140625,0.0299757924315039,1.47293735116307E-5,1,2,12.9061126708984,5.00484470435692,40.5599996447563,39.194321528057,5.74790160788193,100,-7.61657289479222E-6,,,,,,,,,,,,,,,,,,,,,300.002319335937,300.002349853516,21867.318359375,22087.48046875,50.1262277525342,5.40283092297449,7.80998849868774,26,1,0,0,1,0.270767211914062,31.2805480957031,1,6,1,300.002319335937,0,300.002334594727,,,,,,,,,,,,,,,,,,,,,,,,,,,,,,,,,
,3865521663.91015,300.001953125,15962.0009765625,0.0220403243983862,1.46570832364355E-5,1,2,12.9061126708984,5.00487869633029,40.5599996447563,28.8196213533538,4.22012400554814,100,-1.03270504463528E-5,,,,,,,,,,,,,,,,,,,,,300.001708984375,300.002197265625,15867.0439453125,16056.9580078125,50.1262277525342,5.4024233188013,7.95434808731079,26,1,0,0,1,0.270233154296875,31.7693061828613,1,6,1,300.001708984375,0,300.001953125,,,,,,,,,,,,,,,,,,,,,,,,,,,,,,,,,
,3865521722.78291,300.001922607422,10079.4736328125,0.014340875147444,1.4319104808312E-5,1,2,12.9061126708984,5.00492264493998,40.5599996447563,18.7530478010237,2.73987301092127,100,-1.13459089655492E-5,,,,,,,,,,,,,,,,,,,,,300.001739501953,300.002105712891,9954.7197265625,10204.2275390625,50.2669208859957,5.40246723840484,8.10802555084228,26,1,0,0,1,0.271072387695313,31.2805480957031,1,6,1,300.001739501953,0,300.001922607422,,,,,,,,,,,,,,,,,,,,,,,,,,,,,,,,,
,3865521785.08548,300.000625610352,3854.24182128906,0.00604065776043407,1.48067874418931E-5,1,2,12.9061126708984,5.00494499092681,40.5599996447563,7.90115394647093,1.14080021119083,100,-1.49473939507066E-5,,,,,,,,,,,,,,,,,,,,,300.000549316406,300.000701904297,3739.34716796875,3969.13647460937,50.2759096139669,5.40238924282561,8.27793788909912,26,1,0,0,1,0.2703857421875,31.7693061828613,1,6,1,300.000701904297,0,300.000625610352,,,,,,,,,,,,,,,,,,,,,,,,,,,,,,,,,
,3865521855.31788,300.001037597656,-3167.48083496094,-0.00433877208632646,1.57763931680273E-5,1,2,12.9061126708984,5.00494889463401,40.5599996447563,-5.67147616612598,-0.844068280994146,100,-8.13504446969341E-6,,,,,,,,,,,,,,,,,,,,,300.000915527344,300.001159667969,-3267.57104492188,-3067.390625,50.2063446757553,5.40216603516576,8.46364784240723,26,1,0,0,1,0.278778076171875,32.2580642700195,1,6,1,300.001159667969,0,300.001037597656,,,,,,,,,,,,,,,,,,,,,,,,,,,,,,,,,
,3865521917.74132,300.00129699707,-9406.62060546875,-0.0131659738612825,1.48366335309998E-5,1,2,12.9061126708984,5.00488772600563,40.5599996447563,-17.2153395179153,-2.52330238448692,100,4.35685371426831E-6,,,,,,,,,,,,,,,,,,,,,300.001251220703,300.001342773438,-9496.58203125,-9316.6591796875,50.1723438351688,5.40287858456367,8.66997051239014,26,1,0,0,1,0.269393920898438,31.2805480957031,1,6,1,300.001342773438,0,300.00129699707,,,,,,,,,,,,,,,,,,,,,,,,,,,,,,,,,
,3865521976.2929,300.000289916992,-15267.2993164062,-0.0210187057876087,1.48252898252985E-5,1,2,12.9061126708984,5.00486829807155,40.5699983239174,-27.4827306039413,-4.03101131457924,100,4.86841607758135E-6,,,,,,,,,,,,,,,,,,,,,300.000213623047,300.000366210937,-15347.3076171875,-15187.291015625,50.1406878801399,5.40301990753065,8.74699115753174,26,1,0,0,1,0.275955200195313,32.7468223571777,1,6,1,300.000213623047,0,300.000289916992,,,,,,,,,,,,,,,,,,,,,,,,,,,,,,,,,
,3865522034.60891,300.000595092773,-21097.2890625,-0.0287574439484547,1.49092900835478E-5,1,2,12.9061126708984,5.00477801829528,40.5599996447563,-37.5991374665887,-5.52406765913295,100,-2.56485588860514E-7,,,,,,,,,,,,,,,,,,,,,300.000427246094,300.000762939453,-21197.154296875,-20997.423828125,50.1614010358995,5.40299154518099,8.70844554901123,26,1,0,0,1,0.271072387695313,31.7693061828613,1,6,1,300.000762939453,0,300.000595092773,,,,,,,,,,,,,,,,,,,,,,,,,,,,,,,,,
,3865522099.07631,300.002014160156,-27546.4384765625,-0.0372453507709711,1.49071556391534E-5,1,2,12.9061126708984,5.00487466465111,40.5599996447563,-48.6967395938696,-7.16351029194718,100,-7.0568415494409E-6,,,,,,,,,,,,,,,,,,,,,300.001892089844,300.002136230469,-27641.615234375,-27451.26171875,50.127400195313,5.40251507194888,8.65511989593506,26,1,0,0,1,0.266952514648438,32.2580642700195,1,6,1,300.002136230469,0,300.002014160156,,,,,,,,,,,,,,,,,,,,,,,,,,,,,,,,,
,3865522189.15903,300.000732421875,-36572.271484375,-0.0489023773782689,1.47427768308238E-5,1,2,12.9061126708984,5.00489794870853,40.5699983239174,-63.940383427352,-9.390950944028,100,1.94026203340038E-6,,,,,,,,,,,,,,,,,,,,,300.000732421875,300.000732421875,-36577.27734375,-36567.265625,50.0988707543611,5.40214476698545,8.59997367858887,26,1,0,0,1,0.271377563476562,31.7693061828613,1,6,1,300.000732421875,0,300.000732421875,,,,,,,,,,,,,,,,,,,,,,,,,,,,,,,,,
,3865522280.36826,300.001617431641,-45708.982421875,-0.0610611372392475,1.57759830373023E-5,1,2,12.9061126708984,5.00492328054835,40.5599996447563,-79.8334435313693,-11.7614308002193,100,-2.47232307375231E-5,,,,,,,,,,,,,,,,,,,,,300.001434326172,300.001800537109,-45804.09375,-45613.87109375,50.0113283602072,5.40179041182377,8.56355953216553,26,1,0,0,1,0.27008056640625,31.2805480957031,1,6,1,300.001434326172,0,300.001617431641,,,,,,,,,,,,,,,,,,,,,,,,,,,,,,,,,
,3865522360.9443,300.000411987305,-46921.81640625,-0.0626839401483542,1.43517817695033E-5,1,2,12.9061126708984,5.00492836335443,40.5699983239174,-81.9615573351796,-12.0312218797074,100,7.35814876534988E-6,,,,,,,,,,,,,,,,,,,,,300.000274658203,300.000549316406,-47016.53515625,-46827.09765625,49.9894427616688,5.40165194399569,8.53771114349365,26,1,0,0,1,0.267410278320313,31.2805480957031,1,6,1,300.000274658203,0,300.000411987305,,,,,,,,,,,,,,,,,,,,,,,,,,,,,,,,,
,3865522427.47744,300.000671386719,-40284.4296875,-0.0539930108975776,1.69760741093017E-5,1,2,12.9061126708984,5.0048239878559,40.5599996447563,-70.595917543364,-10.361943495372,100,7.0150390521709E-6,,,,,,,,,,,,,,,,,,,,,300.000061035156,300.001281738281,-40379.2421875,-40189.6171875,50.1770336062842,5.40194656248238,8.52115249633789,26,1,0,0,1,0.267562866210938,31.7693061828613,1,6,1,300.000061035156,0,300.000671386719,,,,,,,,,,,,,,,,,,,,,,,,,,,,,,,,,
,3865522544.27317,300.00032043457,-28626.6650390625,-0.0387065572128521,1.42749683153649E-5,1,2,12.9061126708984,5.00499264630176,40.5599996447563,-50.610367678238,-7.43463570225361,100,4.35401381296246E-7,,,,,,,,,,,,,,,,,,,,,300.000152587891,300.00048828125,-28721.439453125,-28531.890625,50.1727346494284,5.40166426322414,8.50091648101807,26,1,0,0,1,0.268936157226562,31.7693061828613,1,6,1,300.00048828125,0,300.00032043457,,,,,,,,,,,,,,,,,,,,,,,,,,,,,,,,,
,3865522610.86358,299.999114990234,-21978.345703125,-0.0299941436984709,1.53083554913762E-5,1,2,12.9061126708984,5.00499692880815,40.5599996447563,-39.219925881336,-5.75207153585072,100,7.31052903993549E-6,,,,,,,,,,,,,,,,,,,,,299.998931884766,299.999298095703,-22063.474609375,-21893.216796875,50.1887580340726,5.40206674378843,8.48482799530029,26,1,0,0,1,0.26885986328125,31.2805480957031,1,6,1,299.999298095703,0,299.999114990234,,,,,,,,,,,,,,,,,,,,,,,,,,,,,,,,,
,3865522667.53194,300.000366210937,-16318.349609375,-0.0225878484556991,1.45434977910055E-5,1,2,12.9061126708984,5.00488228297324,40.5699983239174,-29.5348025679685,-4.33029572377259,100,6.5060468366129E-6,,,,,,,,,,,,,,,,,,,,,300.000244140625,300.00048828125,-16373.2177734375,-16263.4814453125,50.1340440377265,5.4021617264733,8.48088073730469,25,1,68,0,0,0.269393920898438,31.2805480957031,1,6,1,300.000244140625,0,300.000366210937,,,,,,,,,,,,,,,,,,,,,,,,,,,,,,,,,
,3865522725.65713,300.001388549805,-10516.3754882813,-0.0148817222179835,1.41847024721045E-5,1,2,12.9061126708984,5.00496345941991,40.5599996447563,-19.4610545193727,-2.83957167122771,100,1.45763913066875E-5,,,,,,,,,,,,,,,,,,,,,300.001281738281,300.001495361328,-10601.466796875,-10431.2841796875,50.1981375763034,5.40213176232781,8.47381591796875,26,1,0,0,1,0.273666381835938,30.7917900085449,1,6,1,300.001281738281,0,300.001388549805,,,,,,,,,,,,,,,,,,,,,,,,,,,,,,,,,
,3865522784.09925,300.000244140625,-4676.59985351562,-0.00711500439301494,1.43277031995186E-5,1,2,12.9061126708984,5.00486935066287,40.5599996447563,-9.3054508241716,-1.34875085860183,100,1.37168637018146E-5,,,,,,,,,,,,,,,,,,,,,300.000061035156,300.000427246094,-4756.357421875,-4596.84228515625,50.1969651335245,5.40245159990288,8.46276092529297,26,1,0,0,1,0.269393920898438,30.7917900085449,1,6,1,300.000427246094,0,300.000244140625,,,,,,,,,,,,,,,,,,,,,,,,,,,,,,,,,
,3865522856.66463,299.999862670898,2574.31030273438,0.00346114938736641,1.60114027820515E-5,1,2,12.9061126708984,5.00490103363055,40.5599996447563,4.52395164868811,0.675158951329822,100,7.89153228548126E-6,,,,,,,,,,,,,,,,,,,,,299.999755859375,299.999969482422,2499.36645507813,2649.25415039062,50.1965743192649,5.40269214186899,8.4557523727417,26,1,0,0,1,0.267105102539062,31.2805480957031,1,6,1,299.999755859375,0,299.999862670898,,,,,,,,,,,,,,,,,,,,,,,,,,,,,,,,,
,3865522919.0303,299.999176025391,8809.17529296875,0.0123772882261794,1.49823201100121E-5,1,2,12.9061126708984,5.0049978614125,40.5599996447563,16.1838593790444,2.37713833792587,100,-3.35276807393963E-7,,,,,,,,,,,,,,,,,,,,,299.99853515625,299.999816894531,8719.1884765625,8899.162109375,50.2000916476015,5.40206367806026,8.45449638366699,26,1,0,0,1,0.267562866210938,31.2805480957031,1,6,1,299.998229980469,0,299.999176025391,,,,,,,,,,,,,,,,,,,,,,,,,,,,,,,,,
,3865522977.38795,299.999526977539,14649.8032226562,0.0202931892120209,2.53225835977691E-5,1,2,12.9061126708984,5.00493738981003,40.5599996447563,26.5364177495883,3.87959661602078,100,-1.41448278497712E-5,,,,,,,,,,,,,,,,,,,,,299.999267578125,299.999786376953,14559.7724609375,14739.833984375,50.1406878801399,5.40239678657391,8.44532871246338,26,1,0,0,1,0.271453857421875,31.2805480957031,1,6,1,299.999786376953,0,299.999526977539,,,,,,,,,,,,,,,,,,,,,,,,,,,,,,,,,
,3865523038.16846,300.00016784668,20731.3203125,0.0282904835567293,1.47291360709404E-5,1,2,12.9061126708984,5.00488383406288,40.5599996447563,36.9921553162063,5.4178225179593,100,-1.25252787659342E-5,,,,,,,,,,,,,,,,,,,,,300.000122070313,300.000213623047,20671.32421875,20791.31640625,50.1387338088418,5.40240747552884,8.43976497650146,26,1,0,0,1,0.27099609375,31.2805480957031,1,6,1,300.000213623047,0,300.00016784668,,,,,,,,,,,,,,,,,,,,,,,,,,,,,,,,,
,3865523098.50839,300.00016784668,26763.8486328125,0.0362536614210147,1.45434913061701E-5,1,2,12.9061126708984,5.00492766748973,40.5599996447563,47.4016094341915,6.96770722312041,100,2.91349819515722E-6,,,,,,,,,,,,,,,,,,,,,300,300.000335693359,26653.673828125,26874.0234375,50.152803122188,5.40214754909792,8.43665409088135,26,1,0,0,1,0.270309448242187,31.7693061828613,1,6,1,300,0,300.00016784668,,,,,,,,,,,,,,,,,,,,,,,,,,,,,,,,,
,3865523170.97694,300.000839233398,34024.04296875,0.0458041273045836,1.47338424408778E-5,1,2,12.9061126708984,5.00483119800504,40.5599996447563,59.8868106273677,8.80575247444003,100,5.78283281998366E-6,,,,,,,,,,,,,,,,,,,,,300.000579833984,300.001098632812,33908.91015625,34139.17578125,50.1813325631399,5.40293533477966,8.43371772766113,26,1,0,0,1,0.2685546875,31.2805480957031,1,6,1,300.000579833984,0,300.000839233398,,,,,,,,,,,,,,,,,,,,,,,,,,,,,,,,,
,3865523231.22566,299.999862670898,40066.47265625,0.0537598974649454,1.64323875571203E-5,1,2,12.9061126708984,5.00490736852323,40.5599996447563,70.2917415611922,10.3243801441676,100,-1.68187265858605E-6,,,,,,,,,,,,,,,,,,,,,299.999786376953,299.999938964844,39971.3359375,40161.609375,50.0687780563707,5.40229940642623,8.43293285369873,26,1,0,0,1,0.272064208984375,30.7917900085449,1,6,1,299.999786376953,0,299.999862670898,,,,,,,,,,,,,,,,,,,,,,,,,,,,,,,,,
,3865523301.73866,299.998641967773,47130.560546875,0.0630238688848001,1.50708542415429E-5,1,2,12.9061126708984,5.00495713729123,40.5599996447563,82.40261419399,12.1243039413024,100,1.38180946143076E-5,,,,,,,,,,,,,,,,,,,,,299.998504638672,299.998779296875,47035.37890625,47225.7421875,50.1094227393707,5.40148234913361,8.43106746673584,26,1,0,0,1,0.267486572265625,31.2805480957031,1,6,1,299.998504638672,0,299.998641967773,,,,,,,,,,,,,,,,,,,,,,,,,,,,,,,,,
,3865523340.20709,300.001388549805,50000.40234375,0.0667970626475254,8.3650413352429E-6,1,2,12.9061126708984,5.00486405846141,40.5599996447563,87.336138640767,12.8334255270207,100,2.08897230840799E-6,,,,,,,,,,,,,,,,,,,,,300.001220703125,300.001556396484,50000.40234375,50000.40234375,50.0590076998803,5.40215883800841,8.43225955963135,26,1,0,0,1,0.271072387695313,31.2805480957031,1,4,1,300.001556396484,0,300.001388549805,,,,,,,,,,,,,,,,,,,,,,,,,,,,,,,,,