File: LT data/Sherwood/D2/395-FC-ZFC-RTSIRM-contsweepwithloop-MsT-AC.dat
[Header]
; MPMS3 Data File (default extension .dat)
; Copyright (c) 2007, Quantum Design, Inc. All rights reserved.
TITLE,
FILEOPENTIME,3865946262.15927,07/02/2022,6:55 pm
BYAPP,MPMS3 w/ AC,1.0,1.1
INFO,MPMS3 Measurement Release 1.1.16 Build 424, MultiVu Release 2.3.4.19,APPNAME
INFO,Linear Motor Servo Controller,MOTOR_MODULE_NAME
INFO,3101-100 N2,MOTOR_HW_VERSION
INFO,,MOTOR_SERIAL_NUMBER
INFO,01.04.28,MOTOR_SOFTWARE_VERSION
INFO,Quantum Design Squid Module,SQUID_MODULE_NAME
INFO,3101-501 B0,SQUID_HW_VERSION
INFO,SQM327,SQUID_SERIAL_NUMBER
INFO,01.03.04,SQUID_SOFTWARE_VERSION
INFO,Quantum Design VSM Oven,OVEN_MODULE_NAME
INFO,3101-201 A3,OVEN_HW_VERSION
INFO,OVB365,OVEN_SERIAL_NUMBER
INFO,01.07.07,OVEN_SOFTWARE_VERSION
INFO,SQUID AC,AC_MODULE_NAME
INFO,3101-401 G0,AC_HW_VERSION
INFO,SAC220,AC_SERIAL_NUMBER
INFO,SQUID AC 00.95.07,AC_SOFTWARE_VERSION
INFO,TCI344,COIL_SERIAL_NUMBER
INFO,0,MOMENT_UNITS
INFO,sndst,SAMPLE_MATERIAL
INFO,,SAMPLE_COMMENT
INFO,139.6,SAMPLE_MASS
INFO,,SAMPLE_VOLUME
INFO,,SAMPLE_MOLECULAR_WEIGHT
INFO,,SAMPLE_SIZE
INFO,,SAMPLE_SHAPE
INFO,Straw,SAMPLE_HOLDER
INFO,Standard,SAMPLE_HOLDER_DETAIL
INFO,62.64,SAMPLE_OFFSET
DATATYPE,COMMENT,1
DATATYPE,TIME,2
STARTUPAXIS,X,2
STARTUPAXIS,Y1,5
FIELDGROUP, VSM,2,3,4,5,6,8,9,10,11,14,15
FIELDGROUP, DC, 2,3,4,14,56,57,58,59,60,61,62,63,64,65,66,67,68,69
FIELDGROUP, AC, 2,3,4,11,16,17,18,19,20,21,22,23,24,25,26,27,28,29,30
STARTUPGROUP, All
[Data]
Comment,Time Stamp (sec),Temperature (K),Magnetic Field (Oe),Moment (emu),M. Std. Err. (emu),Transport Action,Averaging Time (sec),Frequency (Hz),Peak Amplitude (mm),Center Position (mm),Lockin Signal' (V),Lockin Signal (V),Range,M. Quad. Signal (emu),AC Moment (emu),AC M. Std Err. (emu),AC Phase (deg),AC Phase Std. Err. (deg),AC Susceptibility (emu/Oe),AC Suscept. Std Err. (emu/Oe),AC X' (emu/Oe),AC X' Std Err. (emu/Oe),AC X'' (emu/Oe),AC X'' Std Err. (emu/Oe),AC Drive (Oe),AC Frequency (Hz),AC Averaging Time (sec),AC Cycles,AC Range,AC Measure Type,AC Signal' (V),AC Signal'' (V),AC Trim Coil Ratio,AC Trim Coil Phase,Min. Temperature (K),Max. Temperature (K),Min. Field (Oe),Max. Field (Oe),Mass (grams),Motor Lag (deg),Pressure (Torr),Measure Count,Measurement Number,SQUID Status (code),Motor Status (code),Measure Status (code),Motor Current (amps),Motor Temp. (C),Temp. Status (code),Field Status (code),Chamber Status (code),Chamber Temp (K),Redirection State,Average Temp (K),Rotation Angle (deg),Rotator state,DC Moment Fixed Ctr (emu),DC Moment Err Fixed Ctr (emu),DC Moment Free Ctr (emu),DC Moment Err Free Ctr (emu),DC Fixed Fit,DC Free Fit,DC Calculated Center (mm),DC Calculated Center Err (mm),DC Scan Length (mm),DC Scan Time (s),DC Number of Points,DC Squid Drift,DC Min V (V),DC Max V (V),DC Scans per Measure,Map 01,Map 02,Map 03,Map 04,Map 05,Map 06,Map 07,Map 08,Map 09,Map 10,Map 11,Map 12,Map 13,Map 14,Map 15,Map 16
,3865947337.57985,100.001113891602,49999.75,0.074766018486773,5.15557680064666E-5,1,2,12.9061126708984,4.98700012401072,41.2099994719028,97.2937322543467,14.1085190845691,100,-0.000139195853169033,,,,,,,,,,,,,,,,,,,,,100.001113891602,100.001113891602,49999.75,49999.75,49.707665680486,5.39715277089858,7.46804046630859,26,1,0,0,1,0.276260375976562,29.8142719268799,1,1,1,100.001113891602,0,100.001113891602,,,,,,,,,,,,,,,,,,,,,,,,,,,,,,,,,
,3865947428.59279,88.1490135192871,49999.75,0.0846731725345042,0.000324733455972776,1,2,12.9061126708984,4.98634536868182,41.1799997091293,110.088096070941,16.5032613679579,1000,0.000248432888506296,,,,,,,,,,,,,,,,,,,,,87.9064025878906,88.3916244506836,49999.75,49999.75,49.7698051477649,5.35539783298927,7.39057970046997,26,1,0,0,1,0.276336669921875,30.3030319213867,2,1,1,87.9064025878906,0,88.1490135192871,,,,,,,,,,,,,,,,,,,,,,,,,,,,,,,,,
,3865947524.22683,72.5184020996094,49999.75,0.10324288162679,3.42356212523007E-5,1,2,12.9061126708984,4.98621879829853,41.1400012671947,134.308676736016,19.5644081025944,1000,-0.000125688624400823,,,,,,,,,,,,,,,,,,,,,72.4133834838867,72.623420715332,49999.75,49999.75,49.7369767499572,5.35643808582168,7.32383251190186,26,1,0,0,1,0.268402099609375,30.7917900085449,2,1,1,72.4133834838867,0,72.5184020996094,,,,,,,,,,,,,,,,,,,,,,,,,,,,,,,,,
,3865947623.01624,55.6541557312012,49999.75,0.134589050317723,4.30260949340013E-5,1,2,12.9061126708984,4.98610752859462,41.0800017416477,175.081882267817,25.5005538826278,1000,-0.000166247046623346,,,,,,,,,,,,,,,,,,,,,55.483814239502,55.8244972229004,49999.75,49999.75,49.7272063934668,5.35659477332287,7.19322299957275,26,1,0,0,1,0.268478393554687,31.2805480957031,2,1,1,55.483814239502,0,55.6541557312012,,,,,,,,,,,,,,,,,,,,,,,,,,,,,,,,,
,3865947693.21987,43.7414989471436,49999.75,0.169600687440612,7.19156792286499E-5,1,2,12.9061126708984,4.98602563453309,41.0600006580353,220.619461540757,32.1516075907991,1000,-0.000195539938130737,,,,,,,,,,,,,,,,,,,,,43.548885345459,43.9341125488281,49999.75,49999.75,49.8018519170534,5.35682988579918,7.05010223388672,26,1,0,0,1,0.267257690429687,31.7693061828613,2,1,1,43.548885345459,0,43.7414989471436,,,,,,,,,,,,,,,,,,,,,,,,,,,,,,,,,
,3865947765.73659,31.4428071975708,49999.75,0.224837402824445,0.000189284390629986,1,2,12.9061126708984,4.98593727349043,41.0399995744228,292.470168784411,42.5870058714604,1000,-0.00028605693840011,,,,,,,,,,,,,,,,,,,,,31.2505989074707,31.6350154876709,49999.75,49999.75,49.842887414313,5.35732892420789,6.78382015228271,26,1,0,0,1,0.268936157226562,31.2805480957031,2,1,1,31.2505989074707,0,31.4428071975708,,,,,,,,,,,,,,,,,,,,,,,,,,,,,,,,,
,3865947836.44441,19.6794500350952,49999.75,0.310750809240167,0.000172607159505898,1,2,12.9061126708984,4.98598277796278,41.0199984908104,404.165835260264,59.3122186279029,1000,-4.82963217500734E-5,,,,,,,,,,,,,,,,,,,,,19.5721263885498,19.7867736816406,49999.75,49999.75,49.8858769828707,5.35744705811523,6.2904748916626,26,1,0,0,1,0.2679443359375,31.2805480957031,2,1,1,19.5721263885498,0,19.6794500350952,,,,,,,,,,,,,,,,,,,,,,,,,,,,,,,,,
,3865947906.7997,9.13636779785156,49999.75,0.437749212256435,0.000362159432904192,1,2,12.9061126708984,4.98607045126754,41.0000011324882,569.309348366985,83.8674765997646,1000,0.000172876529188448,,,,,,,,,,,,,,,,,,,,,8.99858570098877,9.27414989471436,49999.75,49999.75,50.066433170813,5.35903491949337,4.90396451950073,26,1,0,0,1,0.268478393554687,30.7917900085449,6,1,1,8.99858570098877,0,9.13636779785156,,,,,,,,,,,,,,,,,,,,,,,,,,,,,,,,,
,3865947975.42265,2.3977952003479,49999.75,0.535260918148275,7.06829960328113E-5,1,2,12.9061126708984,4.98619134589582,41.0000011324882,696.22666298598,102.035975432743,1000,-0.000186152579010324,,,,,,,,,,,,,,,,,,,,,2.39450073242187,2.40108966827393,49999.75,49999.75,50.5842620648034,5.36169927473307,2.85482549667358,26,1,0,0,1,0.268707275390625,31.7693061828613,6,1,1,2.39450073242187,0,2.3977952003479,,,,,,,,,,,,,,,,,,,,,,,,,,,,,,,,,
,3865948045.14811,2.26320326328278,49999.75,0.536319847999505,7.76079256737299E-5,1,2,12.9061126708984,4.98618605615476,41.0000011324882,697.595888405673,102.286086071782,1000,-0.000149308254407308,,,,,,,,,,,,,,,,,,,,,2.25753235816956,2.268874168396,49999.75,49999.75,50.6135731342746,5.36222436014912,2.73141932487488,26,1,0,0,1,0.267486572265625,31.2805480957031,6,1,1,2.25753235816956,0,2.26320326328278,,,,,,,,,,,,,,,,,,,,,,,,,,,,,,,,,
,3865948116.54101,2.10283482074738,49999.75,0.537779970726611,8.10180548981003E-5,1,2,12.9061126708984,4.98615244206889,41.0000011324882,699.49766829629,102.500909903563,1000,-0.000197904343971003,,,,,,,,,,,,,,,,,,,,,2.10028839111328,2.10538125038147,49999.75,49999.75,50.6467923463419,5.36221349248019,2.62070417404175,26,1,0,0,1,0.2685546875,31.7693061828613,2,1,1,2.10538125038147,0,2.10283482074738,,,,,,,,,,,,,,,,,,,,,,,,,,,,,,,,,
,3865948184.79175,2.09141874313354,49999.75,0.537809757725207,6.77853995051679E-5,1,2,12.9061126708984,4.98615103731316,41.0000011324882,699.537342341661,102.498334497176,1000,-0.000204229302418723,,,,,,,,,,,,,,,,,,,,,2.08817672729492,2.09466075897217,49999.75,49999.75,50.6495280461592,5.36221741535341,2.61800765991211,26,1,0,0,1,0.268630981445313,31.7693061828613,2,1,1,2.08817672729492,0,2.09141874313354,,,,,,,,,,,,,,,,,,,,,,,,,,,,,,,,,
,3865948251.23948,1.99968671798706,49999.75,0.538481211675322,6.91400486805281E-5,1,2,12.9061126708984,4.98618179402513,41.0000011324882,700.424236611885,102.576437850108,1000,-0.000243506616624147,,,,,,,,,,,,,,,,,,,,,1.99962770938873,1.99974572658539,49999.75,49999.75,50.684310515265,5.36264067875718,2.54461050033569,26,1,0,0,1,0.268096923828125,31.2805480957031,5,1,1,1.99962770938873,0,1.99968671798706,,,,,,,,,,,,,,,,,,,,,,,,,,,,,,,,,
,3865948769.57253,32.3532676696777,26.4876518249512,0.000543820287861103,3.83258528535394E-8,1,5,12.9061126708984,4.99597004503167,41.0000011324882,0.709293494401532,0.104046171940424,1,-1.17691432365168E-7,,,,,,,,,,,,,,,,,,,,,32.0644302368164,32.6421051025391,26.4876518249512,26.4876518249512,49.7756673616591,5.35781728692627,6.28262329101562,65,1,0,0,1,0.277481079101562,31.2805480957031,2,1,1,32.6421051025391,0,32.3532676696777,,,,,,,,,,,,,,,,,,,,,,,,,,,,,,,,,
,3865948971.12193,64.0117797851562,26.4876518249512,0.000523736477741748,5.22681729769461E-8,1,5,12.9061126708984,4.99576027264892,41.0399995744228,0.683084775945035,0.100018164983862,1,-2.51045241995625E-7,,,,,,,,,,,,,,,,,,,,,64.0117797851562,64.0117797851562,26.4876518249512,26.4876518249512,49.8135763448418,5.35898836720035,6.85697507858276,63,1,64,0,0,0.276947021484375,31.2805480957031,2,1,1,64.0117797851562,0,64.0117797851562,,,,,,,,,,,,,,,,,,,,,,,,,,,,,,,,,
,3865949169.61171,96.012580871582,26.4876518249512,0.000508270327293342,5.19632381425849E-8,1,5,12.9061126708984,4.99567682096725,41.0900004208088,0.662905395085858,0.0970084566046743,1,-2.84930200591949E-7,,,,,,,,,,,,,,,,,,,,,96.012580871582,96.012580871582,26.4876518249512,26.4876518249512,49.8612556845149,5.35944239725495,7.07565832138062,65,1,0,0,1,0.27801513671875,32.2580642700195,2,1,1,96.012580871582,0,96.012580871582,,,,,,,,,,,,,,,,,,,,,,,,,,,,,,,,,
,3865949363.68587,128.085311889648,26.4876518249512,0.000492935659063448,3.36511700346922E-8,1,5,12.9061126708984,4.99567133776514,41.1700010299683,0.642885550211213,0.0942095136560316,1,-1.78202300772696E-7,,,,,,,,,,,,,,,,,,,,,128.085311889648,128.085311889648,26.4876518249512,26.4876518249512,49.8424966000534,5.35970886640317,7.19950532913208,63,1,64,0,0,0.277557373046875,31.2805480957031,2,1,1,128.085311889648,0,128.085311889648,,,,,,,,,,,,,,,,,,,,,,,,,,,,,,,,,
,3865949556.46521,160.091735839844,26.4876518249512,0.000480537117217506,4.8063314572149E-8,1,5,12.9061126708984,4.99563019372281,41.2699989974499,0.626724543095532,0.0917273690168985,1,-2.5920634981912E-7,,,,,,,,,,,,,,,,,,,,,160.091735839844,160.091735839844,26.4876518249512,26.4876518249512,49.8202201872553,5.36018261816385,7.2925591468811,64,1,64,0,0,0.2777099609375,31.2805480957031,2,1,1,160.091735839844,0,160.091735839844,,,,,,,,,,,,,,,,,,,,,,,,,,,,,,,,,
,3865949749.31683,192.019607543945,26.4876518249512,0.000467811389120839,3.71772225324473E-8,1,5,12.9061126708984,4.99569394986585,41.3900017738342,0.61013783608423,0.0893033216717557,1,-2.49653016865684E-7,,,,,,,,,,,,,,,,,,,,,192.019607543945,192.019607543945,26.4876518249512,26.4876518249512,49.837806828938,5.36001410831639,7.36759567260742,64,1,64,0,0,0.268020629882813,31.2805480957031,2,1,1,192.019607543945,0,192.019607543945,,,,,,,,,,,,,,,,,,,,,,,,,,,,,,,,,
,3865949941.97453,224.017272949219,26.4876518249512,0.00045578622977303,3.85508574754881E-8,1,5,12.9061126708984,4.99562215520162,41.5299981832504,0.594448092925696,0.0869657590674698,1,-2.74103409170491E-7,,,,,,,,,,,,,,,,,,,,,224.017272949219,224.017272949219,26.4876518249512,26.4876518249512,49.8299905437457,5.36001961358325,7.49565601348877,63,1,64,0,0,0.277099609375,31.7693061828613,2,1,1,224.017272949219,0,224.017272949219,,,,,,,,,,,,,,,,,,,,,,,,,,,,,,,,,
,3865950134.90061,256.014984130859,26.4876518249512,0.000445671526338596,3.97859226196823E-8,1,5,12.9061126708984,4.99558281271851,41.6899994015694,0.581253300067084,0.0850112090866535,1,-2.86184120896524E-7,,,,,,,,,,,,,,,,,,,,,256.014984130859,256.014984130859,26.4876518249512,26.4876518249512,49.7705867762841,5.36094769695915,7.72328281402588,63,1,64,0,0,0.277786254882813,31.7693061828613,2,1,1,256.014984130859,0,256.014984130859,,,,,,,,,,,,,,,,,,,,,,,,,,,,,,,,,
,3865950328.06389,288.043212890625,26.4876518249512,0.00043544573102082,3.16321651128468E-8,1,5,12.9061126708984,4.99557306290929,41.8800003826618,0.567908438255696,0.0831055610420296,1,-2.45007360506825E-7,,,,,,,,,,,,,,,,,,,,,288.043212890625,288.043212890625,26.4876518249512,26.4876518249512,49.8061508739091,5.36098531229727,7.6605486869812,65,1,0,0,1,0.277252197265625,31.2805480957031,2,1,1,288.043212890625,0,288.043212890625,,,,,,,,,,,,,,,,,,,,,,,,,,,,,,,,,
,3865951970.23548,1.99999874830246,43008.0625,0.509342616321408,6.81804244809791E-5,1,2,12.9061126708984,4.97523908649439,41.0000011324882,660.410432084687,97.1957770755633,1000,0.000131547737354333,,,,,,,,,,,,,,,,,,,,,1.99997746944427,2.00002002716064,42853.5234375,43162.6015625,50.4838228000823,5.36228354631936,2.594402551651,26,1,0,0,1,0.2691650390625,30.7917900085449,1,6,1,1.99997746944427,0,1.99999874830246,,,,,,,,,,,,,,,,,,,,,,,,,,,,,,,,,
,3865952041.61533,1.99999111890793,35879.35546875,0.475968274509952,8.10413826777721E-5,1,2,12.9061126708984,4.97518646641616,41.0000011324882,617.123856288909,90.8558811192328,1000,0.000146177489834396,,,,,,,,,,,,,,,,,,,,,1.99998939037323,1.99999284744263,35814.46484375,35944.24609375,50.3689234077553,5.3618798791404,2.58590817451477,26,1,0,0,1,0.268096923828125,30.7917900085449,1,6,1,1.99999284744263,0,1.99999111890793,,,,,,,,,,,,,,,,,,,,,,,,,,,,,,,,,
,3865952111.92048,1.99994188547134,28860.779296875,0.434918571027505,8.04696341251927E-5,1,2,12.9061126708984,4.97515002142312,41.0000011324882,563.906543807538,82.936737060725,1000,6.99760508143732E-5,,,,,,,,,,,,,,,,,,,,,1.99990475177765,1.99997901916504,28765.81640625,28955.7421875,50.1875855912938,5.36122775690858,2.59554219245911,26,1,0,0,1,0.268096923828125,30.7917900085449,1,6,1,1.99997901916504,0,1.99994188547134,,,,,,,,,,,,,,,,,,,,,,,,,,,,,,,,,
,3865952182.40106,1.9997895359993,21822.4599609375,0.382159321670989,0.000104523199494337,1,2,12.9061126708984,4.97508203872581,41.0000011324882,495.50303943659,72.7887185369932,1000,-4.60879718635295E-6,,,,,,,,,,,,,,,,,,,,,1.99976742267609,1.99981164932251,21727.671875,21917.248046875,50.071513756188,5.36076069743403,2.59357810020447,26,1,0,0,1,0.268707275390625,30.7917900085449,1,6,1,1.99976742267609,0,1.9997895359993,,,,,,,,,,,,,,,,,,,,,,,,,,,,,,,,,
,3865952248.88315,1.99987363815308,15188.51953125,0.315372445764106,0.000124234559957624,1,2,12.9061126708984,4.97505715351121,41.0000011324882,408.897182160754,60.1216727936508,1000,3.78982621587895E-5,,,,,,,,,,,,,,,,,,,,,1.99982702732086,1.99992024898529,15098.5771484375,15278.4619140625,49.9374644651399,5.35988129742474,2.59325861930847,26,1,0,0,1,0.2691650390625,31.2805480957031,1,6,1,1.99982702732086,0,1.99987363815308,,,,,,,,,,,,,,,,,,,,,,,,,,,,,,,,,
,3865952320.73714,1.99979096651077,8006.51000976563,0.210268970916357,0.000191309095490352,1,2,12.9061126708984,4.97503229756043,41.0000011324882,272.648594736302,39.9106176154031,1000,-0.000109053572360713,,,,,,,,,,,,,,,,,,,,,1.99973452091217,1.99984741210938,7846.68798828125,8166.33203125,49.787000975188,5.35941691351945,2.59111857414246,26,1,0,0,1,0.278854370117187,31.7693061828613,1,6,1,1.99973452091217,0,1.99979096651077,,,,,,,,,,,,,,,,,,,,,,,,,,,,,,,,,
,3865952392.08616,2.00005674362183,880.523284912109,0.0422148115719559,0.000372882962429477,1,2,12.9061126708984,4.97497014920842,41.0000011324882,54.7383488319807,8.00705547530407,1000,-2.61281569044291E-5,,,,,,,,,,,,,,,,,,,,,2.0000319480896,2.00008153915405,800.646667480469,960.39990234375,49.8409333430149,5.35907796303122,2.59420418739319,26,1,0,0,1,0.269012451171875,31.2805480957031,1,6,1,2.00008153915405,0,2.00005674362183,,,,,,,,,,,,,,,,,,,,,,,,,,,,,,,,,
,3865952486.94336,1.999995470047,-8606.3623046875,-0.216398172370713,0.000193216713878332,1,2,12.9061126708984,4.97496636514648,41.0000011324882,-280.591052558136,-41.0720967813582,1000,0.000113098466624768,,,,,,,,,,,,,,,,,,,,,1.99986481666565,2.00012612342834,-8666.3759765625,-8546.3486328125,49.792081560563,5.35961294296274,2.57667994499207,26,1,0,0,1,0.2703857421875,30.7917900085449,1,6,1,1.99986481666565,0,1.999995470047,,,,,,,,,,,,,,,,,,,,,,,,,,,,,,,,,
,3865952553.06848,2.00024366378784,-15217.0815429687,-0.313383914108111,0.000127813312993987,1,2,12.9061126708984,4.97493356465139,41.0000011324882,-406.341748942335,-59.4885806996431,1000,0.000156640474142639,,,,,,,,,,,,,,,,,,,,,2.00012969970703,2.00035762786865,-15307.193359375,-15126.9697265625,49.9316022512457,5.36011343401949,2.5713107585907,26,1,0,0,1,0.269851684570313,31.2805480957031,1,6,1,2.00035762786865,0,2.00024366378784,,,,,,,,,,,,,,,,,,,,,,,,,,,,,,,,,
,3865952624.95914,2.00013446807861,-22407.7705078125,-0.386458866221795,0.000100327612786525,1,2,12.9061126708984,4.97499921474833,41.0000011324882,-501.049683720184,-73.7172223144491,1000,-8.11877757404218E-5,,,,,,,,,,,,,,,,,,,,,1.99998998641968,2.00027894973755,-22567.85546875,-22247.685546875,49.9917876472264,5.36105842399106,2.55783700942993,26,1,0,0,1,0.2783203125,30.7917900085449,1,6,1,1.99998998641968,0,2.00013446807861,,,,,,,,,,,,,,,,,,,,,,,,,,,,,,,,,
,3865952694.08088,2.00004541873932,-29329.5908203125,-0.437231560052556,9.77948607372062E-5,1,2,12.9061126708984,4.97501699010368,41.0000011324882,-566.860044947023,-83.5389948243074,1000,-0.00019708354719394,,,,,,,,,,,,,,,,,,,,,2.00002264976501,2.00006818771362,-29424.7734375,-29234.408203125,50.1485041653322,5.36200549883447,2.5410144329071,26,1,0,0,1,0.268402099609375,30.7917900085449,1,6,1,2.00006818771362,0,2.00004541873932,,,,,,,,,,,,,,,,,,,,,,,,,,,,,,,,,
,3865952765.96368,1.99926471710205,-36527.1171875,-0.479182356608489,9.53726268578678E-5,1,2,12.9061126708984,4.97502359057693,41.0000011324882,-621.306233530678,-91.1674976947577,1000,8.24376046843567E-5,,,,,,,,,,,,,,,,,,,,,1.99886989593506,1.99965953826904,-36687.33984375,-36366.89453125,50.2915421843515,5.36193389913772,2.52640914916992,26,1,0,0,1,0.268630981445313,31.7693061828613,1,6,1,1.99886989593506,0,1.99926471710205,,,,,,,,,,,,,,,,,,,,,,,,,,,,,,,,,
,3865952839.51645,1.99999499320984,-43895.92578125,-0.513117994654156,9.04176876352344E-5,1,2,12.9061126708984,4.97507422275891,41.0000011324882,-665.272234655921,-97.9273338517644,1000,-0.000144618323194834,,,,,,,,,,,,,,,,,,,,,1.99990773200989,2.00008225440979,-43951,-43840.8515625,50.4756157006303,5.36297506403858,2.49697017669678,26,1,0,0,1,0.269317626953125,31.7693061828613,1,6,1,2.00008225440979,0,1.99999499320984,,,,,,,,,,,,,,,,,,,,,,,,,,,,,,,,,
,3865952912.04452,1.99666482210159,-49502.583984375,-0.535881665948666,8.75067662239379E-5,1,2,12.9061126708984,4.97505696478671,41.0000011324882,-694.791579691871,-102.210084165,1000,-0.000103877370950612,,,,,,,,,,,,,,,,,,,,,1.99480748176575,1.99852216243744,-49552.46875,-49452.69921875,50.6225618622457,5.3637955663196,2.47993469238281,24,1,68,0,0,0.26824951171875,31.2805480957031,1,6,1,1.99480748176575,0,1.99666482210159,,,,,,,,,,,,,,,,,,,,,,,,,,,,,,,,,
,3865952982.52302,2.00016313791275,-42466.4765625,-0.507554127732787,6.31370475713425E-5,1,2,12.9061126708984,4.97502679031475,41.0000011324882,-658.049099084338,-96.8682177165238,1000,-0.000146161609509912,,,,,,,,,,,,,,,,,,,,,1.99994075298309,2.00038552284241,-42586.1796875,-42346.7734375,50.4713167437746,5.36326662389171,2.48152184486389,26,1,0,0,1,0.269241333007813,29.8142719268799,5,6,1,1.99994075298309,0,2.00016313791275,,,,,,,,,,,,,,,,,,,,,,,,,,,,,,,,,
,3865953050.65153,2.00511372089386,-35664.138671875,-0.474902900100832,0.000152691520322093,1,2,12.9061126708984,4.97498122975238,41.0000011324882,-615.741570119069,-90.4104593680552,1000,3.6783452085994E-5,,,,,,,,,,,,,,,,,,,,,2.00107622146606,2.00915122032166,-35758.93359375,-35569.34375,50.4083956479765,5.36231890823244,2.47299551963806,26,1,0,0,1,0.268478393554687,31.2805480957031,6,6,1,2.00915122032166,0,2.00511372089386,,,,,,,,,,,,,,,,,,,,,,,,,,,,,,,,,
,3865953122.46908,2.00005233287811,-28502.7900390625,-0.432102011666868,7.69042523653711E-5,1,2,12.9061126708984,4.97495020311183,41.0000011324882,-560.226956588152,-82.367932192967,1000,-4.86642019993568E-5,,,,,,,,,,,,,,,,,,,,,1.999587059021,2.00051760673523,-28672.3515625,-28333.228515625,50.2114252611303,5.36186154237241,2.46595001220703,26,1,0,0,1,0.269775390625,31.2805480957031,5,6,1,2.00051760673523,0,2.00005233287811,,,,,,,,,,,,,,,,,,,,,,,,,,,,,,,,,
,3865953191.78809,1.99993538856506,-21579.544921875,-0.380177969366717,0.000113316566100311,1,2,12.9061126708984,4.97495591913545,41.0000011324882,-492.932897506369,-72.296842684009,1000,9.08996029860924E-5,,,,,,,,,,,,,,,,,,,,,1.99992847442627,1.99994230270386,-21684.486328125,-21474.603515625,49.9652122775726,5.36079977979671,2.47233891487122,26,1,0,0,1,0.26885986328125,32.7468223571777,1,6,1,1.99992847442627,0,1.99993538856506,,,,,,,,,,,,,,,,,,,,,,,,,,,,,,,,,
,3865953258.39419,1.99992269277573,-14926.8388671875,-0.312665314930918,0.000134871575307095,1,2,12.9061126708984,4.97489548721594,41.0000011324882,-405.380528603742,-59.5223768736882,1000,2.45092432671282E-5,,,,,,,,,,,,,,,,,,,,,1.99988114833832,1.99996423721313,-14996.6123046875,-14857.0654296875,49.9167513093803,5.36002495765332,2.46217060089111,26,1,0,0,1,0.269317626953125,30.7917900085449,1,6,1,1.99988114833832,0,1.99992269277573,,,,,,,,,,,,,,,,,,,,,,,,,,,,,,,,,
,3865953328.66151,2.00003266334534,-7909.77954101562,-0.209774457415566,0.000193497928252373,1,2,12.9061126708984,4.97487353359312,41.0000011324882,-271.971007896397,-39.9793650278685,1000,-1.80034121584137E-5,,,,,,,,,,,,,,,,,,,,,1.99999022483826,2.00007510185242,-8004.82421875,-7814.73486328125,49.8292089152264,5.35974048110947,2.47108030319214,26,1,0,0,1,0.26885986328125,31.7693061828613,1,6,1,1.99999022483826,0,2.00003266334534,,,,,,,,,,,,,,,,,,,,,,,,,,,,,,,,,
,3865953399.4855,1.99990582466126,-835.200958251953,-0.0410310881263017,0.000375653960583896,1,2,12.9061126708984,4.97488693476824,41.0000011324882,-53.2021188879967,-7.78295043166155,1000,2.4932875886333E-5,,,,,,,,,,,,,,,,,,,,,1.99982345104218,1.99998819828033,-900.16650390625,-770.235412597656,49.6990677667745,5.35932782566039,2.46846342086792,26,1,0,0,1,0.269012451171875,31.2805480957031,1,6,1,1.99978280067444,0,1.99990582466126,,,,,,,,,,,,,,,,,,,,,,,,,,,,,,,,,
,3865953498.14942,2.00007832050323,9028.265625,0.224579009147891,0.000190715828743873,1,2,12.9061126708984,4.97489210400898,41.0000011324882,291.169131029115,42.7833590635687,1000,5.60578466913302E-6,,,,,,,,,,,,,,,,,,,,,1.99982047080994,2.00033617019653,8908.275390625,9148.255859375,49.8655546413707,5.36007997977261,2.46498131752014,26,1,0,0,1,0.268478393554687,31.2805480957031,1,6,1,1.99982047080994,0,2.00007832050323,,,,,,,,,,,,,,,,,,,,,,,,,,,,,,,,,
,3865953570.51016,2.00014424324036,16269.166015625,0.326118254162625,0.000132518444086622,1,2,12.9061126708984,4.9749227644917,41.0000011324882,422.808651787441,62.2016848429237,1000,6.52794995705075E-5,,,,,,,,,,,,,,,,,,,,,2.00005412101746,2.00023436546326,16169.1884765625,16369.1435546875,49.9652122775726,5.36084526336566,2.44921779632568,26,1,0,0,1,0.26947021484375,31.7693061828613,1,6,1,2.00005412101746,0,2.00014424324036,,,,,,,,,,,,,,,,,,,,,,,,,,,,,,,,,
,3865953640.92358,2.00132608413696,23310.8896484375,0.393971733027808,8.98123472489924E-5,1,2,12.9061126708984,4.97490119751112,41.0000011324882,510.778795317735,75.1296345145917,1000,6.8429870931364E-5,,,,,,,,,,,,,,,,,,,,,2.00079894065857,2.00185322761536,23220.74609375,23401.033203125,50.0699504991495,5.36143118795098,2.44091868400574,26,1,0,0,1,0.26947021484375,31.7693061828613,1,6,1,2.00185322761536,0,2.00132608413696,,,,,,,,,,,,,,,,,,,,,,,,,,,,,,,,,
,3865953709.7974,1.9999925494194,30204.962890625,0.443185133213977,0.000231542967637777,1,2,12.9061126708984,4.97489414712771,41.0000011324882,574.566883568531,84.6181347581671,1000,0.000157015568519859,,,,,,,,,,,,,,,,,,,,,1.99989426136017,2.00009083747864,30089.822265625,30320.103515625,50.2989676552842,5.36238788138827,2.43167877197266,26,1,0,0,1,0.268402099609375,31.2805480957031,1,6,1,1.99989426136017,0,1.9999925494194,,,,,,,,,,,,,,,,,,,,,,,,,,,,,,,,,
,3865953779.94621,1.99988782405853,37235.083984375,0.48294490475374,0.00010302767935179,1,2,12.9061126708984,4.97493500528734,41.0000011324882,626.159807338354,91.9439518581074,1000,-3.45647475534494E-5,,,,,,,,,,,,,,,,,,,,,1.99916362762451,2.00061202049255,37144.77734375,37325.390625,50.3337501243899,5.36346376945743,2.43498826026917,26,1,0,0,1,0.2777099609375,31.7693061828613,1,6,1,2.00061202049255,0,1.99988782405853,,,,,,,,,,,,,,,,,,,,,,,,,,,,,,,,,
,3865953852.51249,1.99994450807571,44509.654296875,0.516096294887408,0.000110502265007399,1,2,12.9061126708984,4.97493849429541,41.0000011324882,669.112639037566,98.4603465406282,1000,0.000121079587748907,,,,,,,,,,,,,,,,,,,,,1.99984157085419,2.00004744529724,44419.3671875,44599.94140625,50.5158695693707,5.36383300484458,2.42968416213989,26,1,0,0,1,0.278778076171875,31.2805480957031,1,6,1,1.99984157085419,0,1.99994450807571,,,,,,,,,,,,,,,,,,,,,,,,,,,,,,,,,
,3865954278.47737,5.50397896766663,26.4751167297363,0.000677836785503848,4.85120840041181E-6,1,5,12.9061126708984,4.99556984423669,41.0000011324882,0.884079354843831,0.129058267347421,100,-6.17511815864751E-7,,,,,,,,,,,,,,,,,,,,,5.21930599212646,5.78865194320679,26.4751167297363,26.4751167297363,49.7885642322264,5.35959663969637,3.92276477813721,65,1,0,0,1,0.27862548828125,30.3030319213867,6,1,1,5.78865194320679,0,5.50397896766663,,,,,,,,,,,,,,,,,,,,,,,,,,,,,,,,,
,3865954490.69931,38.0573387145996,26.4751167297363,0.000465177553437693,2.46593542571979E-8,1,5,12.9061126708984,4.99546505529624,41.0099998116493,0.606643483760986,0.0889325526306549,1,-1.42635732769687E-7,,,,,,,,,,,,,,,,,,,,,38.0573387145996,38.0573387145996,26.4751167297363,26.4751167297363,49.8026335455726,5.35949138755052,6.39574003219604,65,1,0,0,1,0.267791748046875,31.2805480957031,2,1,1,38.0573387145996,0,38.0573387145996,,,,,,,,,,,,,,,,,,,,,,,,,,,,,,,,,
,3865954693.2905,70.0610275268555,26.4751167297363,0.0004503212537725,3.67367010839667E-8,1,5,12.9061126708984,4.99534866149781,41.0499982535839,0.587258891779831,0.0860291775736637,1,-1.84351914849849E-7,,,,,,,,,,,,,,,,,,,,,70.0610275268555,70.0610275268555,26.4751167297363,26.4751167297363,49.809277387986,5.36077776952292,6.88165378570557,65,1,0,0,1,0.277786254882813,31.2805480957031,2,1,1,70.0610275268555,0,70.0610275268555,,,,,,,,,,,,,,,,,,,,,,,,,,,,,,,,,
,3865954890.77565,102.152854919434,26.4751167297363,0.000437751358470272,2.46563460732487E-8,1,5,12.9061126708984,4.99526157746688,41.0999990999699,0.570855790749991,0.0836046168916093,1,-1.95440611598877E-7,,,,,,,,,,,,,,,,,,,,,102.152854919434,102.152854919434,26.4751167297363,26.4751167297363,49.8616464987745,5.36055357111839,7.07395553588867,65,1,0,0,1,0.268936157226562,31.2805480957031,2,1,1,102.152854919434,0,102.152854919434,,,,,,,,,,,,,,,,,,,,,,,,,,,,,,,,,
,3865955084.22923,134.077392578125,26.4751167297363,0.000425094921646849,2.90596614402901E-8,1,5,12.9061126708984,4.9953107668107,41.1899983882904,0.554370614469232,0.08110701923137,1,-2.52297325265238E-7,,,,,,,,,,,,,,,,,,,,,134.077392578125,134.077392578125,26.4751167297363,26.4751167297363,49.8706352267457,5.36018510900553,7.19132900238037,64,1,64,0,0,0.278549194335938,31.2805480957031,2,1,1,134.077392578125,0,134.077392578125,,,,,,,,,,,,,,,,,,,,,,,,,,,,,,,,,
,3865955277.72951,166.121795654297,26.4751167297363,0.0004143899788265,2.42627669726773E-8,1,5,12.9061126708984,4.99523307011881,41.2900000810623,0.540387459933606,0.0791373260117016,1,-1.88805639976713E-7,,,,,,,,,,,,,,,,,,,,,166.121795654297,166.121795654297,26.4751167297363,26.4751167297363,49.7866101609283,5.36151813012329,7.27351474761963,65,1,0,0,1,0.278701782226562,31.2805480957031,2,1,1,166.121795654297,0,166.121795654297,,,,,,,,,,,,,,,,,,,,,,,,,,,,,,,,,
,3865955470.09393,198.005340576172,26.4751167297363,0.000404217917768127,3.59540392619246E-8,1,5,12.9061126708984,4.99513029727933,41.4099991321564,0.527124164359522,0.0770778887717334,1,-2.72075191191725E-7,,,,,,,,,,,,,,,,,,,,,198.005340576172,198.005340576172,26.4751167297363,26.4751167297363,49.8081049452072,5.36189348311793,7.34544467926025,65,1,0,0,1,0.288619995117188,32.2580642700195,2,1,1,198.005340576172,0,198.005340576172,,,,,,,,,,,,,,,,,,,,,,,,,,,,,,,,,
,3865955662.65018,230.043029785156,26.4751167297363,0.000394260801510568,3.33872288180966E-8,1,5,12.9061126708984,4.99515589777143,41.5600016713142,0.514138789584605,0.0752097038719153,1,-2.42413760109517E-7,,,,,,,,,,,,,,,,,,,,,230.043029785156,230.043029785156,26.4751167297363,26.4751167297363,49.8413241572745,5.36197853907771,7.51971864700317,64,1,64,0,0,0.268478393554687,31.2805480957031,2,1,1,230.043029785156,0,230.043029785156,,,,,,,,,,,,,,,,,,,,,,,,,,,,,,,,,
,3865955856.20351,262.043426513672,26.4751167297363,0.000386300338650631,2.75584593898429E-8,1,5,12.9061126708984,4.99517587613116,41.7300015687943,0.503755820380079,0.073724867028758,1,-2.11982739857964E-7,,,,,,,,,,,,,,,,,,,,,262.043426513672,262.043426513672,26.4751167297363,26.4751167297363,49.8053692453899,5.36184475814181,7.83724212646484,64,1,64,0,0,0.269012451171875,31.2805480957031,2,1,1,262.043426513672,0,262.043426513672,,,,,,,,,,,,,,,,,,,,,,,,,,,,,,,,,
,3865956049.01609,294.096862792969,26.4751167297363,0.00037836481014742,2.74892253264638E-8,1,5,12.9061126708984,4.99506006898642,41.9100001454353,0.49340551585394,0.0721122209235448,1,-2.81111092263837E-7,,,,,,,,,,,,,,,,,,,,,294.096862792969,294.096862792969,26.4751167297363,26.4751167297363,49.7604256055341,5.36267570370671,7.69493103027344,64,1,64,0,0,0.288162231445313,31.7693061828613,2,1,1,294.096862792969,0,294.096862792969,,,,,,,,,,,,,,,,,,,,,,,,,,,,,,,,,
,3865956824.18148,277.99365234375,26.5252590179443,0.000450774670140933,4.19572830077855E-8,1,5,12.9061126708984,5.00492237011814,41.8099984526634,0.589432347230434,0.0863226081600957,1,-2.03228717213247E-7,,,,,,,,,,,,,,,,,,,,,277.99365234375,277.99365234375,26.5252590179443,26.5252590179443,49.7401032640341,5.3647906649015,8.16943645477295,64,1,64,0,0,0.279083251953125,31.2805480957031,2,1,1,277.99365234375,0,277.99365234375,,,,,,,,,,,,,,,,,,,,,,,,,,,,,,,,,
,3865957019.58182,245.887649536133,26.5252590179443,0.000448018723144042,2.99808170867217E-8,1,5,12.9061126708984,5.00513811642462,41.6800007224083,0.585886478484029,0.085647092556698,1,-3.18942775657843E-7,,,,,,,,,,,,,,,,,,,,,245.887649536133,245.887649536133,26.5252590179443,26.5252590179443,49.7385400069956,5.36108040864196,7.98764610290527,64,1,64,0,0,0.268173217773438,31.7693061828613,2,1,1,245.887649536133,0,245.887649536133,,,,,,,,,,,,,,,,,,,,,,,,,,,,,,,,,
,3865957208.57949,213.974670410156,26.5252590179443,0.000445042263171684,2.33808651935841E-8,1,5,12.9061126708984,5.00508959606189,41.5499992668629,0.58197720326711,0.0851380701038394,1,-2.70067652054123E-7,,,,,,,,,,,,,,,,,,,,,213.974670410156,213.974670410156,26.5252590179443,26.5252590179443,49.7901274892649,5.36036120254628,7.88161325454712,65,1,0,0,1,0.268783569335938,31.7693061828613,2,1,1,213.974670410156,0,213.974670410156,,,,,,,,,,,,,,,,,,,,,,,,,,,,,,,,,
,3865957402.12078,181.965301513672,26.5252590179443,0.000441664508403346,3.22722152436358E-8,1,5,12.9061126708984,5.00518289341101,41.4399988949299,0.577591915425243,0.0843804029539051,1,-3.54966929707114E-7,,,,,,,,,,,,,,,,,,,,,181.965301513672,181.965301513672,26.5252590179443,26.5252590179443,49.7916907463033,5.36105081064862,7.78899002075195,65,1,0,0,1,0.268707275390625,31.7693061828613,2,1,1,181.965301513672,0,181.965301513672,,,,,,,,,,,,,,,,,,,,,,,,,,,,,,,,,
,3865957593.37548,149.965591430664,26.5252590179443,0.000438844926019688,2.81930280626458E-8,1,5,12.9061126708984,5.00496658251464,41.3299985229969,0.57386775052836,0.0838510658138415,1,-3.41674908328728E-7,,,,,,,,,,,,,,,,,,,,,149.965591430664,149.965591430664,26.5252590179443,26.5252590179443,49.7995070314957,5.36165532917244,7.70977210998535,65,1,0,0,1,0.2685546875,31.2805480957031,2,1,1,149.965591430664,0,149.965591430664,,,,,,,,,,,,,,,,,,,,,,,,,,,,,,,,,
,3865957785.9321,117.970367431641,26.5252590179443,0.00043646723672268,4.50909883994054E-8,1,5,12.9061126708984,5.00507571256162,41.2500016391277,0.57076876005402,0.0834479905452534,1,-3.02586180790402E-7,,,,,,,,,,,,,,,,,,,,,117.970367431641,117.970367431641,26.5252590179443,26.5252590179443,49.9030728102937,5.36053716610013,7.61444997787476,65,1,0,0,1,0.2685546875,31.7693061828613,2,1,1,117.970367431641,0,117.970367431641,,,,,,,,,,,,,,,,,,,,,,,,,,,,,,,,,
,3865957977.18677,85.9893951416016,26.5252590179443,0.000434051230484937,2.36441169020225E-8,1,5,12.9061126708984,5.00502321232815,41.1599986255169,0.567597632300255,0.0830078797547603,1,-2.83303906545097E-7,,,,,,,,,,,,,,,,,,,,,85.9893951416016,85.9893951416016,26.5252590179443,26.5252590179443,49.7197809225341,5.35985820070082,7.47261381149292,63,1,64,0,0,0.268936157226562,31.2805480957031,2,1,1,85.9893951416016,0,85.9893951416016,,,,,,,,,,,,,,,,,,,,,,,,,,,,,,,,,
,3865958165.0748,53.7697219848633,26.5252590179443,0.000432474167652559,3.69951182336294E-8,1,5,12.9061126708984,5.00506463698297,41.0800017416477,0.565531793679743,0.0827760148379415,1,-2.29677173739952E-7,,,,,,,,,,,,,,,,,,,,,53.7697219848633,53.7697219848633,26.5252590179443,26.5252590179443,49.7873917894476,5.35977019164006,7.25112819671631,65,1,0,0,1,0.2691650390625,31.7693061828613,2,1,1,53.7697219848633,0,53.7697219848633,,,,,,,,,,,,,,,,,,,,,,,,,,,,,,,,,
,3865958352.37329,21.9976711273193,26.5252590179443,0.000430350741942817,3.34657899004226E-8,1,5,12.9061126708984,5.00511472368392,41.0399995744228,0.562734784993438,0.0825624028556538,1,-8.19731923347994E-8,,,,,,,,,,,,,,,,,,,,,21.9976711273193,21.9976711273193,26.5252590179443,26.5252590179443,49.7928631890822,5.35927813865706,6.59858179092407,64,1,64,0,0,0.2685546875,30.3030319213867,2,1,1,21.9976711273193,0,21.9976711273193,,,,,,,,,,,,,,,,,,,,,,,,,,,,,,,,,
,3865958926.6924,12.0092391967773,26.5252590179443,0.000434175460617741,1.96917253429591E-8,1,5,12.9061126708984,5.00506501197823,41.0000011324882,0.567731740223068,0.0832707080178328,1,-1.01290527732621E-7,,,,,,,,,,,,,,,,,,,,,12.0092391967773,12.0092391967773,26.5252590179443,26.5252590179443,49.7678510764668,5.36040028738496,5.20535612106323,65,1,0,0,1,0.270462036132813,31.2805480957031,6,1,1,12.0092391967773,0,12.0092391967773,,,,,,,,,,,,,,,,,,,,,,,,,,,,,,,,,
,3865959133.67815,44.2212600708008,26.5252590179443,0.000432016242067608,2.37363194586062E-8,1,5,12.9061126708984,5.00500207099761,41.0199984908104,0.564929746163095,0.0826416702341956,1,-2.64041536306601E-7,,,,,,,,,,,,,,,,,,,,,44.2212600708008,44.2212600708008,26.5252590179443,26.5252590179443,49.7385400069956,5.36002516981166,6.57213115692139,65,1,0,0,1,0.268325805664062,31.2805480957031,2,1,1,44.2212600708008,0,44.2212600708008,,,,,,,,,,,,,,,,,,,,,,,,,,,,,,,,,
,3865959334.60049,76.1784591674805,26.5252590179443,0.000433064023218273,2.38612438474118E-8,1,5,12.9061126708984,5.00499281746596,41.0600006580353,0.566284952362072,0.0829335687895213,1,-1.94565628882152E-7,,,,,,,,,,,,,,,,,,,,,76.1784591674805,76.1784591674805,26.5252590179443,26.5252590179443,49.8104498307649,5.36088286784787,6.98853731155395,64,1,64,0,0,0.269622802734375,31.2805480957031,2,1,1,76.1784591674805,0,76.1784591674805,,,,,,,,,,,,,,,,,,,,,,,,,,,,,,,,,
,3865959530.6215,108.076080322266,26.5252590179443,0.000433869881003231,2.78804126090804E-8,1,5,12.9061126708984,5.00492733379769,41.1200001835823,0.5673529042188,0.0829190635175662,1,-3.22887504370903E-7,,,,,,,,,,,,,,,,,,,,,108.076080322266,108.076080322266,26.5252590179443,26.5252590179443,49.8159212303995,5.36089872931847,7.15927410125732,65,1,0,0,1,0.270233154296875,31.2805480957031,2,1,1,108.076080322266,0,108.076080322266,,,,,,,,,,,,,,,,,,,,,,,,,,,,,,,,,
,3865959724.3326,140.180709838867,26.5252590179443,0.000434362124026011,3.27683066650145E-8,1,5,12.9061126708984,5.00501230180689,41.2000007927418,0.568012283961777,0.0830001243021912,1,-3.34715236292686E-7,,,,,,,,,,,,,,,,,,,,,140.180709838867,140.180709838867,26.5252590179443,26.5252590179443,49.8061508739091,5.36074748647773,7.25492143630982,64,1,64,0,0,0.280227661132813,31.2805480957031,2,1,1,140.180709838867,0,140.180709838867,,,,,,,,,,,,,,,,,,,,,,,,,,,,,,,,,
,3865959917.00852,172.020355224609,26.5252590179443,0.000434857503803137,2.42808436650505E-8,1,5,12.9061126708984,5.00476479117347,41.3100011646748,0.568604919182159,0.0831967094053596,1,-2.52741909140921E-7,,,,,,,,,,,,,,,,,,,,,172.020355224609,172.020355224609,26.5252590179443,26.5252590179443,49.8186569302168,5.36262878982927,7.3401026725769,63,1,64,0,0,0.269851684570313,31.2805480957031,2,1,1,172.020355224609,0,172.020355224609,,,,,,,,,,,,,,,,,,,,,,,,,,,,,,,,,
,3865960109.66767,204.012054443359,26.5252590179443,0.000435196027901735,3.57026448322605E-8,1,5,12.9061126708984,5.00496225153985,41.4399988949299,0.569073108938215,0.0833060283313132,1,-2.22380344558459E-7,,,,,,,,,,,,,,,,,,,,,204.012054443359,204.012054443359,26.5252590179443,26.5252590179443,49.8104498307649,5.36188648740372,7.41358041763306,63,1,64,0,0,0.2691650390625,30.7917900085449,2,1,1,204.012054443359,0,204.012054443359,,,,,,,,,,,,,,,,,,,,,,,,,,,,,,,,,
,3865960302.82901,236.133499145508,26.5252590179443,0.000436184447633018,3.32018654444179E-8,1,5,12.9061126708984,5.0050116602317,41.5900014340878,0.570379251132206,0.0834570351412697,1,-2.52981291494242E-7,,,,,,,,,,,,,,,,,,,,,236.133499145508,236.133499145508,26.5252590179443,26.5252590179443,49.7850469038899,5.36166240990065,7.53913259506226,63,1,64,0,0,0.269393920898438,31.7693061828613,2,1,1,236.133499145508,0,236.133499145508,,,,,,,,,,,,,,,,,,,,,,,,,,,,,,,,,
,3865960495.14655,268.002777099609,26.5252590179443,0.000436964222901488,2.78033436291041E-8,1,5,12.9061126708984,5.00499613950109,41.7600013315678,0.571421238696396,0.0834371344588929,1,-3.82481809217962E-7,,,,,,,,,,,,,,,,,,,,,268.002777099609,268.002777099609,26.5252590179443,26.5252590179443,49.8870494256495,5.36152180085921,7.76564121246338,63,1,64,0,0,0.268707275390625,31.7693061828613,2,1,1,268.002777099609,0,268.002777099609,,,,,,,,,,,,,,,,,,,,,,,,,,,,,,,,,
,3865960770.05904,299.944915771484,26.5252590179443,0.000437167942800999,3.31660031280955E-8,1,5,12.9061126708984,5.00502834786665,41.9399999082088,0.571658715756038,0.0837087413726936,1,-2.05263215727489E-7,,,,,,,,,,,,,,,,,,,,,299.944915771484,299.944915771484,26.5252590179443,26.5252590179443,49.7502644347841,5.36194534129933,7.6490421295166,65,1,0,0,1,0.268630981445313,31.7693061828613,1,1,1,299.944915771484,0,299.944915771484,,,,,,,,,,,,,,,,,,,,,,,,,,,,,,,,,
,3865960951.9959,300.004165649414,41865.056640625,0.0207244012553841,5.4448894191438E-6,1,2,12.9061126708984,5.00486376110729,41.9399999082088,27.1029954579833,3.93975901306209,100,-3.14198823474565E-5,,,,,,,,,,,,,,,,,,,,,300.004058837891,300.004272460937,41765.171875,41964.94140625,49.7322869788418,5.36208243686181,7.71204233169556,26,1,0,0,1,0.279083251953125,31.2805480957031,1,6,1,300.004058837891,0,300.004165649414,,,,,,,,,,,,,,,,,,,,,,,,,,,,,,,,,
,3865961024.50836,300.003890991211,34626.7890625,0.0172811140348453,5.68561773011996E-6,1,2,12.9061126708984,5.00487436975599,41.9399999082088,22.5994549109771,3.28886112013052,100,-2.33929686647433E-5,,,,,,,,,,,,,,,,,,,,,300.002960205078,300.004821777344,34537.00390625,34716.57421875,49.7100105660437,5.36197440301933,7.78142881393433,26,1,0,0,1,0.2685546875,31.2805480957031,1,6,1,300.002960205078,0,300.003890991211,,,,,,,,,,,,,,,,,,,,,,,,,,,,,,,,,
,3865961097.00487,300.003005981445,27388.482421875,0.0138364437476911,6.17021342674345E-6,1,2,12.9061126708984,5.00482889138434,41.9399999082088,18.0950201911005,2.62931639045014,100,-2.17416467573591E-5,,,,,,,,,,,,,,,,,,,,,300.002990722656,300.003021240234,27298.615234375,27478.349609375,49.7549542058995,5.36279464147012,7.88207244873047,25,1,68,0,0,0.269699096679687,31.7693061828613,1,6,1,300.002990722656,0,300.003005981445,,,,,,,,,,,,,,,,,,,,,,,,,,,,,,,,,
,3865961165.75592,300.002960205078,20519.8701171875,0.0105710408810797,5.31219378269733E-6,1,2,12.9061126708984,5.0048082880541,41.9399999082088,13.8252337127528,2.00387987061285,100,-2.03628013748404E-5,,,,,,,,,,,,,,,,,,,,,300.0029296875,300.002990722656,20450.009765625,20589.73046875,49.715872779938,5.36291033523369,8.01819038391113,26,1,0,0,1,0.26947021484375,31.2805480957031,1,6,1,300.0029296875,0,300.002960205078,,,,,,,,,,,,,,,,,,,,,,,,,,,,,,,,,
,3865961236.1283,300.001541137695,13496.7817382812,0.00719556272449275,5.32839054335988E-6,1,2,12.9061126708984,5.0047983867218,41.9399999082088,9.4106600974177,1.36374473633968,100,-1.40634125360573E-5,,,,,,,,,,,,,,,,,,,,,300.00146484375,300.001617431641,13402.0126953125,13591.55078125,49.783874461111,5.36298779914393,8.17613220214844,26,1,0,0,1,0.268707275390625,30.7917900085449,1,6,1,300.00146484375,0,300.001541137695,,,,,,,,,,,,,,,,,,,,,,,,,,,,,,,,,
,3865961306.52681,299.999221801758,6462.29150390625,0.00378317966897663,5.31204151010124E-6,1,2,12.9061126708984,5.00476294678562,41.9399999082088,4.94896776181894,0.708732544419615,100,-1.37196978488398E-5,,,,,,,,,,,,,,,,,,,,,299.9990234375,299.999420166016,6367.4912109375,6557.091796875,49.7217349938322,5.36322155996899,8.33961296081543,26,1,0,0,1,0.27984619140625,32.2580642700195,1,6,1,299.9990234375,0,299.999221801758,,,,,,,,,,,,,,,,,,,,,,,,,,,,,,,,,
,3865961378.3566,300.000900268555,-713.725036621094,-4.33376999656741E-5,7.06380794216935E-6,1,2,12.9061126708984,5.00473215372306,41.9399999082088,-0.0550614028081301,-0.0192161624194986,100,-8.33073727944775E-6,,,,,,,,,,,,,,,,,,,,,300.000640869141,300.001159667969,-878.630432128906,-548.819641113281,49.7643337481303,5.36332113670171,8.39391326904297,26,1,0,0,1,0.270004272460938,31.2805480957031,1,6,1,300.000640869141,0,300.000900268555,,,,,,,,,,,,,,,,,,,,,,,,,,,,,,,,,
,3865961463.6503,300.002380371094,-9246.328125,-0.00485958052491864,5.75419486186028E-6,1,2,12.9061126708984,5.00471536981413,41.9399999082088,-6.35462872516185,-0.926357647022633,100,5.39578754903811E-6,,,,,,,,,,,,,,,,,,,,,300.002288818359,300.002471923828,-9336.3525390625,-9156.3037109375,49.7936448176014,5.36267607505847,8.31859302520752,26,1,0,0,1,0.279083251953125,31.7693061828613,1,6,1,300.002288818359,0,300.002380371094,,,,,,,,,,,,,,,,,,,,,,,,,,,,,,,,,
,3865961562.35006,300.001281738281,-19112.2646484375,-0.00981789271280115,5.38795997469139E-6,1,2,12.9061126708984,5.00474410674553,41.9399999082088,-12.8389034950356,-1.86858011595338,100,1.3173523761302E-5,,,,,,,,,,,,,,,,,,,,,300.001068115234,300.001495361328,-19207.220703125,-19017.30859375,49.763552119611,5.36261777782252,8.25768280029297,26,1,0,0,1,0.2691650390625,31.2805480957031,1,6,1,300.001495361328,0,300.001281738281,,,,,,,,,,,,,,,,,,,,,,,,,,,,,,,,,
,3865961628.83274,300.000946044922,-25762.7333984375,-0.0130240136415251,6.25596678569287E-6,1,2,12.9061126708984,5.00477970970965,41.9399999082088,-17.0305638323262,-2.48675885997635,100,1.13930738017303E-5,,,,,,,,,,,,,,,,,,,,,300.000823974609,300.001068115234,-25858.12890625,-25667.337890625,49.792081560563,5.3623454649356,8.23404788970947,26,1,0,0,1,0.26885986328125,30.7917900085449,1,6,1,300.001068115234,0,300.000946044922,,,,,,,,,,,,,,,,,,,,,,,,,,,,,,,,,
,3865961701.36395,299.999954223633,-33030.8984375,-0.0165026543721221,6.10921066852889E-6,1,2,12.9061126708984,5.00468367646235,41.9399999082088,-21.5795236345586,-3.14562206798469,100,1.84527577925453E-5,,,,,,,,,,,,,,,,,,,,,299.999694824219,300.000213623047,-33121.25,-32940.546875,49.7475287349668,5.36243221362995,8.22008895874023,26,1,0,0,1,0.279693603515625,31.2805480957031,1,6,1,300.000213623047,0,299.999954223633,,,,,,,,,,,,,,,,,,,,,,,,,,,,,,,,,
,3865961765.83982,299.999542236328,-39492.525390625,-0.0195760742040166,6.09624205330707E-6,1,2,12.9061126708984,5.00469654439759,41.9399999082088,-25.5975761042252,-3.73803802606695,100,1.68654126935456E-5,,,,,,,,,,,,,,,,,,,,,299.99951171875,299.999572753906,-39582.5546875,-39402.49609375,49.7815295755533,5.36219084020039,8.20346164703369,26,1,0,0,1,0.269012451171875,31.2805480957031,1,6,1,299.99951171875,0,299.999542236328,,,,,,,,,,,,,,,,,,,,,,,,,,,,,,,,,
,3865961855.8302,300.001266479492,-48508.7890625,-0.023893866531484,5.6043995784075E-6,1,2,12.9061126708984,5.00468351706132,41.9399999082088,-31.2418614962608,-4.57287669794324,100,1.26492775480881E-5,,,,,,,,,,,,,,,,,,,,,300.001190185547,300.001342773438,-48668.92578125,-48348.65234375,49.6509976128418,5.36206228020378,8.18715858459473,26,1,0,0,1,0.268707275390625,31.2805480957031,1,6,1,300.001190185547,0,300.001266479492,,,,,,,,,,,,,,,,,,,,,,,,,,,,,,,,,
,3865961927.12285,299.999938964844,-45100.556640625,-0.0222735725107664,6.28629100810056E-6,1,2,12.9061126708984,5.00472749359285,41.9399999082088,-29.129897507424,-4.22025494737975,100,4.43571464777632E-5,,,,,,,,,,,,,,,,,,,,,299.999786376953,300.000091552734,-45180.40234375,-45020.7109375,49.7189992940149,5.36211029256854,8.16837787628174,26,1,0,0,1,0.268325805664062,31.2805480957031,1,6,1,300.000091552734,0,299.999938964844,,,,,,,,,,,,,,,,,,,,,,,,,,,,,,,,,
,3865961993.47635,300.000106811523,-38478.3984375,-0.0191153255999426,5.93871111218724E-6,1,2,12.9061126708984,5.00465493882755,41.9499985873699,-24.9970460970207,-3.6348140259647,100,2.80959218586701E-5,,,,,,,,,,,,,,,,,,,,,299.999908447266,300.000305175781,-38573.21875,-38383.578125,49.7080564947457,5.36213993778432,8.15812492370605,25,1,68,0,0,0.269012451171875,31.7693061828613,1,6,1,299.999908447266,0,300.000106811523,,,,,,,,,,,,,,,,,,,,,,,,,,,,,,,,,
,3865962062.03908,299.999282836914,-31636.41796875,-0.0158636486050878,5.50586497655152E-6,1,2,12.9061126708984,5.00472208901568,41.9399999082088,-20.7460698694293,-3.01083256507748,100,2.76959629530036E-5,,,,,,,,,,,,,,,,,,,,,299.999267578125,299.999298095703,-31726.37890625,-31546.45703125,49.7479195492264,5.36215208217193,8.15641689300537,26,1,0,0,1,0.27252197265625,31.7693061828613,1,6,1,299.999298095703,0,299.999282836914,,,,,,,,,,,,,,,,,,,,,,,,,,,,,,,,,
,3865962132.48859,299.999069213867,-24609.1787109375,-0.0125066673645652,6.27387567211308E-6,1,2,12.9061126708984,5.0047779801675,41.9399999082088,-16.3558525130759,-2.37577261136614,100,2.02752852593456E-5,,,,,,,,,,,,,,,,,,,,,299.998809814453,299.999328613281,-24698.9765625,-24519.380859375,49.7334594216207,5.36213451727864,8.14657497406006,24,1,68,0,0,0.267562866210938,31.7693061828613,1,6,1,299.999328613281,0,299.999069213867,,,,,,,,,,,,,,,,,,,,,,,,,,,,,,,,,
,3865962203.24435,299.998825073242,-17541.4072265625,-0.00914014295302845,5.33511147666235E-6,1,2,12.9061126708984,5.00471455194109,41.9399999082088,-11.9531954142654,-1.73489625171387,100,1.58417235557198E-5,,,,,,,,,,,,,,,,,,,,,299.998809814453,299.998840332031,-17611.29296875,-17471.521484375,49.7815295755533,5.36240109048293,8.14482688903809,26,1,0,0,1,0.269851684570313,31.2805480957031,1,6,1,299.998809814453,0,299.998825073242,,,,,,,,,,,,,,,,,,,,,,,,,,,,,,,,,
,3865962271.49896,300,-10726.703125,-0.00584890080934253,5.35739815354781E-6,1,2,12.9061126708984,5.00487546231967,41.9399999082088,-7.64991028877975,-1.10645491996773,100,1.30272486650076E-5,,,,,,,,,,,,,,,,,,,,,299.999847412109,300.000152587891,-10821.5537109375,-10631.8525390625,49.7827020183322,5.36169874544858,8.13714027404785,26,1,0,0,1,0.279617309570313,31.2805480957031,1,6,1,299.999847412109,0,300,,,,,,,,,,,,,,,,,,,,,,,,,,,,,,,,,
,3865962338.14629,299.999099731445,-4067.61584472656,-0.00260493321112446,5.5077083076194E-6,1,2,12.9061126708984,5.00486448446,41.9399999082088,-3.40904704409194,-0.479126287548278,100,1.62460826908503E-5,,,,,,,,,,,,,,,,,,,,,299.999084472656,299.999114990234,-4177.640625,-3957.59106445313,49.7873917894476,5.36158649143968,8.12431907653809,26,1,0,0,1,0.278778076171875,30.7917900085449,1,6,1,299.999114990234,0,299.999099731445,,,,,,,,,,,,,,,,,,,,,,,,,,,,,,,,,
,3865962418.54148,300.001052856445,3968.90454101562,0.00191438066456312,6.50022560893305E-6,1,2,12.9061126708984,5.00485200356317,41.9399999082088,2.50187695700857,0.375546957835131,100,5.98472645688101E-6,,,,,,,,,,,,,,,,,,,,,300.000640869141,300.00146484375,3878.98071289063,4058.82836914063,49.8452322998707,5.36199192447718,8.12432098388672,26,1,0,0,1,0.271072387695313,32.2580642700195,1,6,1,300.00146484375,0,300.001052856445,,,,,,,,,,,,,,,,,,,,,,,,,,,,,,,,,
,3865962509.26106,300.000411987305,13039.345703125,0.00682408199603292,5.89561571581244E-6,1,2,12.9061126708984,5.00484748312371,41.9399999082088,8.92289181033895,1.30732939789075,10,-2.65113547035312E-6,,,,,,,,,,,,,,,,,,,,,300.000335693359,300.00048828125,12949.4033203125,13129.2880859375,49.7987254029764,5.36208313659199,8.11195850372314,26,1,0,0,1,0.269622802734375,31.7693061828613,1,6,1,300.00048828125,0,300.000411987305,,,,,,,,,,,,,,,,,,,,,,,,,,,,,,,,,
,3865962614.04582,299.99951171875,23526.451171875,0.0119560642215976,5.3912031172453E-6,1,2,12.9061126708984,5.00480956606359,41.9399999082088,15.6346282384896,2.28004689545156,100,-1.26161202470417E-5,,,,,,,,,,,,,,,,,,,,,299.999206542969,299.999816894531,23441.435546875,23611.466796875,49.7612072340533,5.36230687102378,8.10885715484619,26,1,0,0,1,0.26947021484375,31.7693061828613,1,6,1,299.999206542969,0,299.99951171875,,,,,,,,,,,,,,,,,,,,,,,,,,,,,,,,,
,3865962684.46345,299.999633789063,30575.890625,0.0153409204681074,5.8637366635334E-6,1,2,12.9061126708984,5.00479137539127,41.9399999082088,20.0599190054192,2.93161652840946,100,-1.15336267298648E-5,,,,,,,,,,,,,,,,,,,,,299.999542236328,299.999725341797,30480.7578125,30671.0234375,49.7240798793899,5.36242476804991,8.10775947570801,26,1,0,0,1,0.269317626953125,32.2580642700195,1,6,1,299.999725341797,0,299.999633789063,,,,,,,,,,,,,,,,,,,,,,,,,,,,,,,,,
,3865962771.358,300.000930786133,39284.642578125,0.0194813848493493,5.94867718697806E-6,1,2,12.9061126708984,5.00473133658436,41.9399999082088,25.4738344785008,3.72117853603573,100,-1.58773404014194E-5,,,,,,,,,,,,,,,,,,,,,300.000885009766,300.0009765625,39219.5390625,39349.74609375,49.6545149411783,5.36234535811008,8.09993171691895,26,1,0,0,1,0.279083251953125,30.7917900085449,1,6,1,300.000885009766,0,300.000930786133,,,,,,,,,,,,,,,,,,,,,,,,,,,,,,,,,
,3865962855.72652,300.000686645508,47736.859375,0.0235060620354104,5.96667986627166E-6,1,2,12.9061126708984,5.00474988729442,41.9399999082088,30.7364664786931,4.49125875552577,100,-1.8166793032054E-5,,,,,,,,,,,,,,,,,,,,,300.000366210937,300.001007080078,47646.33203125,47827.38671875,49.6580322695149,5.36186245635622,8.09321308135986,26,1,0,0,1,0.268020629882813,31.7693061828613,1,6,1,300.000366210937,0,300.000686645508,,,,,,,,,,,,,,,,,,,,,,,,,,,,,,,,,
,3865966769.16592,61.599573135376,24.8454933166504,,,5,,,,41.0399995744228,,,,,8.05154056466653E-6,4.64462717054014E-9,0.252601693892725,0.000523715486494834,2.68364542168188E-6,1.54809285769966E-9,2.68361934083515E-6,6.4802994372968E-10,1.18314331188403E-8,1.40593338678986E-9,3.00022517863798,100.057640075684,10,1000,1,3,0.0280457869076021,0.00343687688179282,0.0122638251632452,197.686828613281,61.5991554260254,61.6005668640137,24.8454933166504,24.8454933166504,,,6.86504459381103,,1,,,,,,1,1,1,61.599552154541,0,61.5999612808228,,,,,,,,,,,,,,,,,,,,,,,,,,,,,,,,,
,3865971216.61712,170.866271972656,24.8454933166504,,,5,,,,41.3100011646748,,,,,3.08285241232239E-6,1.69686556252033E-8,0.133042659982516,0.0031077196124686,1.02761526149996E-6,5.65620638143366E-9,1.02761249113536E-6,4.66994056863681E-9,2.38615385167163E-9,3.19128903654479E-9,3.00000644971203,10.005763053894,10,100,1,3,0.0107890201259804,0.00108348779485916,0.00378571450710297,254.817085266113,170.863510131836,170.869644165039,24.8454933166504,24.8454933166504,,,7.32252359390259,,1,,,,,,1,1,1,170.866149902344,0,170.866709007407,,,,,,,,,,,,,,,,,,,,,,,,,,,,,,,,,
,3865975678.4122,280.112243652344,24.8454933166504,,,5,,,,41.8200008571148,,,,,2.09029524982861E-6,5.98339728984663E-8,-0.14372149723809,0.0231198569996671,6.96765103574519E-7,1.99446582138543E-8,6.96762911504768E-7,1.17597875980475E-8,-1.74777304269413E-9,1.61089039638417E-8,2.99999991260334,1.00057637691498,19.98847910208,20,1,3,0.00735664991659809,7.08391336704488E-5,0.000418028328567743,254.723861694336,280.050933837891,280.133148193359,24.8454933166504,24.8454933166504,,,8.14598560333252,,1,,,,,,1,1,1,280.120727539062,0,280.109497706095,,,,,,,,,,,,,,,,,,,,,,,,,,,,,,,,,
,3865976693.02191,299.998153686523,24.8454933166504,,,5,,,,41.9499985873699,,,,,1.89669468304901E-6,3.83842674100638E-9,0.542908612055481,0.00140093274797761,6.32294921953406E-7,1.27960380672706E-9,6.32266536577778E-7,9.24017147715031E-10,5.99124795056508E-9,8.85199532828036E-10,2.99969937634384,100.057640075684,10,1000,1,3,0.00660362023117892,0.000840136940496338,0.0122918207198381,197.757934570313,299.992034912109,300.007537841797,24.8454933166504,24.8454933166504,,,8.21710300445557,,1,,,,,,1,1,1,299.996765136719,0,299.999276123047,,,,,,,,,,,,,,,,,,,,,,,,,,,,,,,,,