File: LT data/Sherwood/D2/398_SH_FULL_SEQUENCE_2.dat
[Header]
; MPMS3 Data File (default extension .dat)
; Copyright (c) 2007, Quantum Design, Inc. All rights reserved.
TITLE,
FILEOPENTIME,3873518420.73179,09/28/2022,11:31 am
BYAPP,MPMS3 w/ AC,1.0,1.1
INFO,MPMS3 Measurement Release 1.1.16 Build 424, MultiVu Release 2.3.4.19,APPNAME
INFO,Linear Motor Servo Controller,MOTOR_MODULE_NAME
INFO,3101-100 N0,MOTOR_HW_VERSION
INFO,MMC1047,MOTOR_SERIAL_NUMBER
INFO,01.04.28,MOTOR_SOFTWARE_VERSION
INFO,Quantum Design Squid Module,SQUID_MODULE_NAME
INFO,3101-501 B0,SQUID_HW_VERSION
INFO,SQM278,SQUID_SERIAL_NUMBER
INFO,01.03.04,SQUID_SOFTWARE_VERSION
INFO,Quantum Design VSM Oven,OVEN_MODULE_NAME
INFO,3101-201 A3,OVEN_HW_VERSION
INFO,OVB323,OVEN_SERIAL_NUMBER
INFO,01.07.07,OVEN_SOFTWARE_VERSION
INFO,SQUID AC,AC_MODULE_NAME
INFO,3101-401 G0,AC_HW_VERSION
INFO,SAC258,AC_SERIAL_NUMBER
INFO,SQUID AC 00.95.07,AC_SOFTWARE_VERSION
INFO,TCI127,COIL_SERIAL_NUMBER
INFO,0,MOMENT_UNITS
INFO,sndst,SAMPLE_MATERIAL
INFO,Thickness unknown, 11000 pulses,SAMPLE_COMMENT
INFO,,SAMPLE_MASS
INFO,,SAMPLE_VOLUME
INFO,,SAMPLE_MOLECULAR_WEIGHT
INFO,,SAMPLE_SIZE
INFO,,SAMPLE_SHAPE
INFO,Straw,SAMPLE_HOLDER
INFO,Standard,SAMPLE_HOLDER_DETAIL
INFO,66.39,SAMPLE_OFFSET
DATATYPE,COMMENT,1
DATATYPE,TIME,2
STARTUPAXIS,X,2
STARTUPAXIS,Y1,5
FIELDGROUP, VSM,2,3,4,5,6,8,9,10,11,14,15
FIELDGROUP, DC, 2,3,4,14,56,57,58,59,60,61,62,63,64,65,66,67,68,69
FIELDGROUP, AC, 2,3,4,11,16,17,18,19,20,21,22,23,24,25,26,27,28,29,30
STARTUPGROUP, All
[Data]
Comment,Time Stamp (sec),Temperature (K),Magnetic Field (Oe),Moment (emu),M. Std. Err. (emu),Transport Action,Averaging Time (sec),Frequency (Hz),Peak Amplitude (mm),Center Position (mm),Lockin Signal' (V),Lockin Signal (V),Range,M. Quad. Signal (emu),AC Moment (emu),AC M. Std Err. (emu),AC Phase (deg),AC Phase Std. Err. (deg),AC Susceptibility (emu/Oe),AC Suscept. Std Err. (emu/Oe),AC X' (emu/Oe),AC X' Std Err. (emu/Oe),AC X'' (emu/Oe),AC X'' Std Err. (emu/Oe),AC Drive (Oe),AC Frequency (Hz),AC Averaging Time (sec),AC Cycles,AC Range,AC Measure Type,AC Signal' (V),AC Signal'' (V),AC Trim Coil Ratio,AC Trim Coil Phase,Min. Temperature (K),Max. Temperature (K),Min. Field (Oe),Max. Field (Oe),Mass (grams),Motor Lag (deg),Pressure (Torr),Measure Count,Measurement Number,SQUID Status (code),Motor Status (code),Measure Status (code),Motor Current (amps),Motor Temp. (C),Temp. Status (code),Field Status (code),Chamber Status (code),Chamber Temp (K),Redirection State,Evercool Status,Average Temp (K),Rotation Angle (deg),Rotator state,DC Moment Fixed Ctr (emu),DC Moment Err Fixed Ctr (emu),DC Moment Free Ctr (emu),DC Moment Err Free Ctr (emu),DC Fixed Fit,DC Free Fit,DC Calculated Center (mm),DC Calculated Center Err (mm),DC Scan Length (mm),DC Scan Time (s),DC Number of Points,DC Squid Drift,DC Min V (V),DC Max V (V),DC Scans per Measure,Map 01,Map 02,Map 03,Map 04,Map 05,Map 06,Map 07,Map 08,Map 09,Map 10,Map 11,Map 12,Map 13,Map 14,Map 15,Map 16
"FC",3873518746.10065
,3873519580.92714,94.4184761047363,49999.6328125,0.00791952019957572,4.10187333513172E-6,1,2,13.1008939743042,1.98948247642663,31.4400009810925,1.90164818245924,0.278731083549798,10,1.57585041468719E-7,,,,,,,,,,,,,,,,,,,,,94.2842178344727,94.552734375,49999.6328125,49999.6328125,52.204577985169,5.82403105794351,7.57066631317139,24,1,64,0,0,0.130538940429688,30.7917900085449,2,1,1,94.2842178344727,0,2084573184,94.4184761047363,,,,,,,,,,,,,,,,,,,,,,,,,,,,,,,,,
,3873519651.30706,83.0897064208984,49999.6328125,0.00978922831837677,0.000443899120051149,1,2,13.1008939743042,1.98929926415369,31.3999988138676,2.36433665260634,0.247981952418347,100,-0.000401729679337927,,,,,,,,,,,,,,,,,,,,,83.0897064208984,83.0897064208984,49999.6328125,49999.6328125,52.2749245518998,5.82893648417116,7.49288034439087,26,1,0,0,1,0.135040283203125,31.2805480957031,2,1,1,83.0897064208984,0,2084573184,83.0897064208984,,,,,,,,,,,,,,,,,,,,,,,,,,,,,,,,,
,3873519747.44317,66.7756729125977,49999.6328125,0.0127792328819432,0.000379653622943517,1,2,13.1008939743042,1.98797540020818,31.360000371933,3.06200488027237,0.463858226793496,100,6.16996113367697E-5,,,,,,,,,,,,,,,,,,,,,66.607307434082,66.9440383911133,49999.6328125,49999.6328125,52.250303253544,5.83813256091852,7.35414695739746,26,1,0,0,1,0.133209228515625,31.2805480957031,2,1,1,66.607307434082,0,2084573184,66.7756729125977,,,,,,,,,,,,,,,,,,,,,,,,,,,,,,,,,
,3873519854.61537,48.521089553833,49999.6328125,0.0179700968857168,0.000815748723905721,1,2,13.1008939743042,1.98530509317638,31.3199982047081,4.27746308556658,0.76901133825575,100,0.000581799538243012,,,,,,,,,,,,,,,,,,,,,48.3356857299805,48.7064933776855,49999.6328125,49999.6328125,52.270625595044,5.86711527575875,7.13485240936279,26,1,0,0,1,0.13763427734375,30.7917900085449,2,1,1,48.3356857299805,0,2084573184,48.521089553833,,,,,,,,,,,,,,,,,,,,,,,,,,,,,,,,,
,3873519981.77642,26.9348545074463,49999.6328125,0.0297611502325957,0.00171814961114699,1,2,13.1008939743042,1.98256403732668,31.2799997627735,7.0386473591815,1.45397840416539,100,0.00173370774329333,,,,,,,,,,,,,,,,,,,,,26.7915935516357,27.0781154632568,49999.6328125,49999.6328125,52.3612945032748,5.89712860868534,6.61082172393799,26,1,0,0,1,0.1422119140625,30.7917900085449,2,1,1,26.7915935516357,0,2084573184,26.9348545074463,,,,,,,,,,,,,,,,,,,,,,,,,,,,,,,,,
,3873520088.88684,9.85416460037231,49999.6328125,0.0557996464401138,2.03187216820574E-5,1,2,13.1008939743042,1.98124721979347,31.2599986791611,13.2898542384739,1.97472826444279,100,0.000111190221017443,,,,,,,,,,,,,,,,,,,,,9.8165922164917,9.89173698425293,49999.6328125,49999.6328125,52.634473670746,5.91328594994313,4.43621444702148,24,1,68,0,0,0.137710571289062,31.2805480957031,6,1,1,9.8165922164917,0,2084573184,9.85416460037231,,,,,,,,,,,,,,,,,,,,,,,,,,,,,,,,,
,3873520166.21772,2.00087827444077,49999.6328125,0.0730779547046041,1.80075091324405E-5,1,2,13.1008939743042,1.98158420737089,31.2599986791611,17.4100172970789,2.59144125434618,100,0.000164105982536994,,,,,,,,,,,,,,,,,,,,,1.99974930286407,2.00200724601746,49999.6328125,49999.6328125,53.3586524938133,5.91060259990609,2.24288702011108,26,1,0,0,1,0.134963989257812,30.3030319213867,5,1,1,1.99974930286407,0,2084573184,2.00087827444077,,,,,,,,,,,,,,,,,,,,,,,,,,,,,,,,,
,3873520554.51498,9.00024318695068,26.4278011322021,0.000283180276324958,1.57501076972014E-7,1,2,13.1008939743042,1.98132240527484,31.2599986791611,0.0674520349848986,0.0100096332880156,10,5.10852307439453E-7,,,,,,,,,,,,,,,,,,,,,9.00024318695068,9.00024318695068,26.4278011322021,26.4278011322021,52.4492277116882,5.91162421530148,4.10862398147583,26,1,0,0,1,0.138015747070312,31.2805480957031,6,1,1,9.03803730010986,0,2084573184,9.00024318695068,,,,,,,,,,,,,,,,,,,,,,,,,,,,,,,,,
,3873520742.09584,38.0097160339355,26.4278011322021,0.000230106498213074,7.83600546945657E-8,1,2,13.1008939743042,1.98046153474833,31.2599986791611,0.0547666005489334,0.00811573624087668,1,3.68136355562564E-7,,,,,,,,,,,,,,,,,,,,,38.0097160339355,38.0097160339355,26.4278011322021,26.4278011322021,52.2549930246594,5.91965185123438,6.37568378448486,26,1,0,0,1,0.139923095703125,30.7917900085449,2,1,1,38.0097160339355,0,2084574048,38.0097160339355,,,,,,,,,,,,,,,,,,,,,,,,,,,,,,,,,
,3873520925.99321,67.0270843505859,26.4278011322021,0.000217343381893954,6.65803273447367E-8,1,2,13.1008939743042,1.98025072206108,31.2899984419346,0.0517224417324398,0.00763687319701135,1,2.33579919529941E-7,,,,,,,,,,,,,,,,,,,,,67.0270843505859,67.0270843505859,26.4278011322021,26.4278011322021,52.3206498202748,5.9222266155717,6.77401781082153,26,1,0,0,1,0.139236450195312,31.2805480957031,2,1,1,67.0270843505859,0,2084574144,67.0270843505859,,,,,,,,,,,,,,,,,,,,,,,,,,,,,,,,,
,3873521105.20917,96.0012741088867,26.4278011322021,0.00020705633230878,8.00628763663754E-8,1,2,13.1008939743042,1.98096911762917,31.3399992883205,0.0493083408791352,0.0072801534814119,1,2.21393522682243E-7,,,,,,,,,,,,,,,,,,,,,96.0012741088867,96.0012741088867,26.4278011322021,26.4278011322021,52.2886030509863,5.91480929658562,6.94985771179199,26,1,0,0,1,0.142135620117188,30.7917900085449,2,1,1,96.0012741088867,0,2084574112,96.0012741088867,,,,,,,,,,,,,,,,,,,,,,,,,,,,,,,,,
,3873521281.03593,125.022392272949,26.4278011322021,0.000197065205695562,6.86589690186495E-8,1,2,13.1008939743042,1.98053557635518,31.4100012183189,0.0469076576983316,0.00693902641546952,1,2.65485749630281E-7,,,,,,,,,,,,,,,,,,,,,125.022392272949,125.022392272949,26.4278011322021,26.4278011322021,52.2080953135055,5.92215233859015,7.05694103240967,26,1,0,0,1,0.139541625976562,30.7917900085449,2,1,1,125.022392272949,0,2084574176,125.022392272949,,,,,,,,,,,,,,,,,,,,,,,,,,,,,,,,,
,3873521456.99468,154.123306274414,26.4278011322021,0.000188262652716047,5.43463168887168E-8,1,2,13.1008939743042,1.97960864685719,31.5000005066395,0.0447759664043181,0.00660009686029034,1,1.56560158019993E-7,,,,,,,,,,,,,,,,,,,,,154.123306274414,154.123306274414,26.4278011322021,26.4278011322021,52.1975433284959,5.92986703677351,7.14192867279053,26,1,0,0,1,0.141143798828125,30.7917900085449,2,1,1,154.158996582031,0,2084574336,154.123306274414,,,,,,,,,,,,,,,,,,,,,,,,,,,,,,,,,
,3873521631.21284,183.057327270508,26.4278011322021,0.000178720591375757,6.25245860166993E-8,1,2,13.1008939743042,1.99011258902234,31.5999984741211,0.0429344673922273,0.00633479662234449,1,1.73646140264369E-7,,,,,,,,,,,,,,,,,,,,,183.057327270508,183.057327270508,26.4278011322021,26.4278011322021,52.0717011368997,5.92960016472825,7.22426652908325,26,1,0,0,1,0.137176513671875,30.7917900085449,2,1,1,183.057327270508,0,2084574304,183.057327270508,,,,,,,,,,,,,,,,,,,,,,,,,,,,,,,,,
,3873521806.05244,212.014633178711,26.4278011322021,0.000165001516668623,1.14681733606699E-7,1,2,13.1008939743042,1.98936856959579,31.7200012505054,0.0396059201731924,0.00587636422637965,1,2.9354971519893E-7,,,,,,,,,,,,,,,,,,,,,212.014633178711,212.014633178711,26.4278011322021,26.4278011322021,52.316350863419,5.94019609253213,7.35892009735107,25,1,64,0,0,0.138320922851562,30.7917900085449,2,1,1,212.014633178711,0,2084574240,212.014633178711,,,,,,,,,,,,,,,,,,,,,,,,,,,,,,,,,
,3873521980.88846,241.010955810547,26.4278011322021,0.00015732203387718,5.59140899012154E-8,1,2,13.1008939743042,1.98919669365591,31.8600013852119,0.0377506752203728,0.00564100964819196,1,4.42600269270962E-7,,,,,,,,,,,,,,,,,,,,,241.010955810547,241.010955810547,26.4278011322021,26.4278011322021,52.316350863419,5.94516884829471,7.6299147605896,26,1,0,0,1,0.140304565429688,31.2805480957031,2,1,1,241.010955810547,0,2084574336,241.010955810547,,,,,,,,,,,,,,,,,,,,,,,,,,,,,,,,,
,3873522155.58244,270.025543212891,26.4278011322021,0.000152357462540678,5.32857860117011E-8,1,2,13.1008939743042,1.99109902095451,32.0199988782406,0.0366184151222792,0.00552265005343261,1,6.35469307823071E-7,,,,,,,,,,,,,,,,,,,,,270.025543212891,270.025543212891,26.4278011322021,26.4278011322021,52.1862097149671,5.92466764507227,8.02395153045654,25,1,64,0,0,0.135421752929688,31.2805480957031,2,1,1,270.025543212891,0,2084574304,270.025543212891,,,,,,,,,,,,,,,,,,,,,,,,,,,,,,,,,
,3873522341.18145,299.007537841797,26.4278011322021,0.000146432467933337,6.01056676621055E-8,1,2,13.1008939743042,1.99036861211053,32.1800000965595,0.0351618598826855,0.00535902722324411,1,8.38936054244441E-7,,,,,,,,,,,,,,,,,,,,,299.007537841797,299.007537841797,26.4278011322021,26.4278011322021,52.049033909842,5.93113417979668,7.78032398223877,26,1,0,0,1,0.135269165039062,30.7917900085449,6,1,1,299.007537841797,0,2084574176,299.007537841797,,,,,,,,,,,,,,,,,,,,,,,,,,,,,,,,,
,3873523948.7895,1.99993240833282,40255.865234375,0.0687727961986808,1.88058949350686E-5,1,2,13.1008939743042,1.99220744136837,31.25,16.5649910683204,2.3705190874769,1000,-0.000232320931434763,,,,,,,,,,,,,,,,,,,,,1.99989247322083,1.99997234344482,40165.78515625,40345.9453125,53.0671050561402,5.91377778933873,2.25955843925476,26,1,0,0,1,0.142669677734375,31.2805480957031,1,6,1,1.99997234344482,0,2084573184,1.99993240833282,,,,,,,,,,,,,,,,,,,,,,,,,,,,,,,,,
,3873524006.3272,1.9998345375061,34508.578125,0.065365476245647,2.31757020819623E-5,1,2,13.1008939743042,1.9927841478219,31.25,15.752002436882,2.26061327471594,1000,-0.000194639681097249,,,,,,,,,,,,,,,,,,,,,1.99983191490173,1.99983716011047,34413.68359375,34603.47265625,53.0631969135441,5.90888626433031,2.25378370285034,26,1,0,0,1,0.142135620117188,28.8367557525635,1,6,1,1.99983716011047,0,2084573184,1.9998345375061,,,,,,,,,,,,,,,,,,,,,,,,,,,,,,,,,
,3873524063.89683,1.99953746795654,28761.755859375,0.0611418469101128,2.28992848170072E-5,1,2,13.1008939743042,1.99211438595569,31.25,14.7227254451645,2.12729184877742,1000,-0.000123504510063217,,,,,,,,,,,,,,,,,,,,,1.99952614307404,1.99954879283905,28671.8671875,28851.64453125,52.8517663990921,5.91529333972523,2.24982357025146,26,1,0,0,1,0.133819580078125,30.7917900085449,1,6,1,1.99952614307404,0,2084573184,1.99953746795654,,,,,,,,,,,,,,,,,,,,,,,,,,,,,,,,,
,3873524154.53845,1.99712955951691,19705.15234375,0.0521088375555174,2.26357786183126E-5,1,2,13.1008939743042,1.99191148708135,31.25,12.5442751994319,1.8188896001478,1000,-7.93693902287078E-5,,,,,,,,,,,,,,,,,,,,,1.99712955951691,1.99712955951691,19705.15234375,19705.15234375,52.8560653559479,5.91386325209598,2.23910665512085,26,1,0,0,1,0.141448974609375,30.7917900085449,1,6,1,1.99712955951691,0,2084573184,1.99712955951691,,,,,,,,,,,,,,,,,,,,,,,,,,,,,,,,,
,3873524268.29898,2.0000165104866,8346.87158203125,0.0316244283704362,3.00105487624168E-5,1,2,13.1008939743042,1.99198109778093,31.25,7.61584415349754,1.08810164396983,1000,-0.000113981323427714,,,,,,,,,,,,,,,,,,,,,1.99979341030121,2.000239610672,8256.8837890625,8436.859375,52.5269997493517,5.91259282704831,2.23228454589844,26,1,0,0,1,0.134353637695312,30.7917900085449,1,6,1,2.000239610672,0,2084573184,2.0000165104866,,,,,,,,,,,,,,,,,,,,,,,,,,,,,,,,,
,3873524347.71048,1.9998836517334,405.84846496582,0.00392453755069809,6.58110494728671E-5,1,2,13.1008939743042,1.99195131310886,31.25,0.957356455901113,0.0513038551460521,100,-0.000361997760385063,,,,,,,,,,,,,,,,,,,,,1.99987149238586,1.99989581108093,310.767730712891,500.92919921875,52.3624669460536,5.91400658200406,2.22569012641907,24,1,68,0,0,0.138397216796875,30.7917900085449,1,6,1,1.99987149238586,0,2084573184,1.9998836517334,,,,,,,,,,,,,,,,,,,,,,,,,,,,,,,,,
,3873524413.21052,1.99999034404755,-6143.88305664062,-0.0242608127128674,3.54514741971872E-5,1,2,13.1008939743042,1.99209102422875,31.25,-5.83387648941048,-0.898024515403566,100,-0.000175085986573275,,,,,,,,,,,,,,,,,,,,,1.9999532699585,2.0000274181366,-6228.90185546875,-6058.8642578125,52.1533813171594,5.91243387026059,2.22168660163879,26,1,0,0,1,0.135574340820312,30.3030319213867,1,6,1,1.9999532699585,0,2084573184,1.99999034404755,,,,,,,,,,,,,,,,,,,,,,,,,,,,,,,,,
,3873524478.77517,1.99991869926453,-12700.7900390625,-0.0404179513582491,2.68027665606819E-5,1,2,13.1008939743042,1.99168515563073,31.25,-9.72200517747892,-1.4500945673488,100,-0.000102950101550287,,,,,,,,,,,,,,,,,,,,,1.99988865852356,1.99994874000549,-12780.4384765625,-12621.1416015625,52.4980794941402,5.91694117643204,2.21548104286194,26,1,0,0,1,0.14251708984375,32.7468223571777,1,6,1,1.99994874000549,0,2084573184,1.99991869926453,,,,,,,,,,,,,,,,,,,,,,,,,,,,,,,,,
,3873524552.13491,2.00008153915405,-20042.787109375,-0.0517945172919679,0.000128179945220092,1,2,13.1008939743042,1.99193935932092,31.25,-12.4590400525952,-1.87551075818561,100,-0.000201744935512536,,,,,,,,,,,,,,,,,,,,,1.99992609024048,2.00023698806763,-20132.892578125,-19952.681640625,52.8423868568614,5.91471398458995,2.21358489990234,26,1,0,0,1,0.144882202148438,30.7917900085449,1,6,1,1.99992609024048,0,2084573184,2.00008153915405,,,,,,,,,,,,,,,,,,,,,,,,,,,,,,,,,
,3873524649.49712,2.00012290477753,-29788.927734375,-0.0615920265024541,2.11882298191137E-5,1,2,13.1008939743042,1.99232560202327,31.25,-14.8260098012675,-2.19864399680011,100,-0.000105090076764966,,,,,,,,,,,,,,,,,,,,,2.00010466575623,2.00014114379883,-29864.1328125,-29713.72265625,53.0741397128133,5.91194506570834,2.20937085151672,26,1,0,0,1,0.137481689453125,30.7917900085449,1,6,1,2.00010466575623,0,2084573184,2.00012290477753,,,,,,,,,,,,,,,,,,,,,,,,,,,,,,,,,
,3873524748.59569,2.00001168251038,-39718.865234375,-0.0681323860129387,2.18403098077076E-5,1,2,13.1008939743042,1.9929417284729,31.25,-16.4110209048736,-2.42640995838007,100,-8.66516984534032E-5,,,,,,,,,,,,,,,,,,,,,1.99996376037598,2.00005960464478,-39814.125,-39623.60546875,53.2234307599864,5.90441890886874,2.2061505317688,26,1,0,0,1,0.142974853515625,30.7917900085449,1,6,1,2.00005960464478,0,2084573184,2.00001168251038,,,,,,,,,,,,,,,,,,,,,,,,,,,,,,,,,
,3873524863.76718,1.99990028142929,-49553.61328125,-0.0731635197061788,3.21074841663277E-5,1,2,13.1008939743042,1.99224771405188,31.25,-17.6346006493142,-2.44444013564884,100,0.00056913454660835,,,,,,,,,,,,,,,,,,,,,1.999835729599,1.99996483325958,-49633.52734375,-49473.69921875,53.4317347603614,5.91391201389172,2.20393347740173,22,1,68,0,0,0.134506225585938,30.7917900085449,1,6,1,1.999835729599,0,2084573184,1.99990028142929,,,,,,,,,,,,,,,,,,,,,,,,,,,,,,,,,
,3873524935.13883,1.99995666742325,-42425.1484375,-0.0698338588190941,2.73541941016396E-5,1,2,13.1008939743042,1.99261742650386,31.25,-16.8324923676244,-2.37142163511128,1000,0.000387915629652225,,,,,,,,,,,,,,,,,,,,,1.99990236759186,2.00001096725464,-42515.0625,-42335.234375,53.3027660546883,5.91134538370362,2.20046281814575,26,1,0,0,1,0.132980346679688,30.7917900085449,1,6,1,1.99990236759186,0,2084573280,1.99995666742325,,,,,,,,,,,,,,,,,,,,,,,,,,,,,,,,,
,3873524992.76604,2.00006568431854,-36674.544921875,-0.066690804264097,3.19192958698209E-5,1,2,13.1008939743042,1.99282046681209,31.25,-16.0745261672585,-2.28888097517588,1000,0.000271846307533509,,,,,,,,,,,,,,,,,,,,,2.00001907348633,2.00011229515076,-36754.546875,-36594.54296875,53.0518633000152,5.90752266462953,2.19927883148193,26,1,0,0,1,0.146942138671875,35.6793746948242,1,6,1,2.00001907348633,0,2084573568,2.00006568431854,,,,,,,,,,,,,,,,,,,,,,,,,,,,,,,,,
,3873525050.22531,1.99992299079895,-30933.494140625,-0.0627074244842886,6.9790000787486E-5,1,2,13.1008939743042,1.99309421157669,31.25,-15.1174007111043,-2.15917556065098,1000,0.000228853011410499,,,,,,,,,,,,,,,,,,,,,1.99986445903778,1.99998152256012,-31023.359375,-30843.62890625,52.9623668345633,5.90456332421816,2.19675517082214,26,1,0,0,1,0.141220092773438,31.2805480957031,1,6,1,1.99986445903778,0,2084573760,1.99992299079895,,,,,,,,,,,,,,,,,,,,,,,,,,,,,,,,,
,3873525107.8092,2.00007724761963,-25187.6298828125,-0.0577866134678633,0.000321261903318537,1,2,13.1008939743042,1.99295407712866,31.25,-13.9390364720502,-1.92265025329069,1000,0.000488268023273517,,,,,,,,,,,,,,,,,,,,,2.00004196166992,2.00011253356934,-25272.53125,-25102.728515625,52.7149814082267,5.90458676753862,2.19542264938354,26,1,0,0,1,0.13336181640625,31.2805480957031,1,6,1,2.00011253356934,0,2084573664,2.00007724761963,,,,,,,,,,,,,,,,,,,,,,,,,,,,,,,,,
,3873525174.55923,1.99996340274811,-18523.20703125,-0.0505169757735233,2.38294859867589E-5,1,2,13.1008939743042,1.9927693384096,31.25,-12.1732694341691,-1.74923231409047,1000,0.000141427521437135,,,,,,,,,,,,,,,,,,,,,1.99996340274811,1.99996340274811,-18523.20703125,-18523.20703125,52.5269997493517,5.90470408237986,2.19391369819641,26,1,0,0,1,0.143280029296875,31.2805480957031,1,6,1,1.99996340274811,0,2084573824,1.99996340274811,,,,,,,,,,,,,,,,,,,,,,,,,,,,,,,,,
,3873525286.50296,2.00009715557098,-7339.77197265625,-0.0289650126290738,5.87354171836324E-5,1,2,13.1008939743042,1.99312203126539,31.25,-6.98452592418125,-0.987099225133176,100,0.000148314019761614,,,,,,,,,,,,,,,,,,,,,2.00004315376282,2.00015115737915,-7414.8154296875,-7264.728515625,52.4156176853613,5.90273521638025,2.19105434417725,26,1,0,0,1,0.146255493164062,31.2805480957031,1,6,1,2.00004315376282,0,2084573664,2.00009715557098,,,,,,,,,,,,,,,,,,,,,,,,,,,,,,,,,
,3873525353.93138,1.99989801645279,-603.624328613281,-0.00489028214229918,0.000133901413931153,1,2,13.1008939743042,1.99218042093204,31.25,-1.1906712765576,-0.081207377219963,100,0.000379362120162008,,,,,,,,,,,,,,,,,,,,,1.99989473819733,1.99990129470825,-688.692687988281,-518.555969238281,52.2565562816978,5.91063377258807,2.18980002403259,25,1,68,0,0,0.140838623046875,30.3030319213867,1,6,1,1.99989473819733,0,2084573504,1.99989801645279,,,,,,,,,,,,,,,,,,,,,,,,,,,,,,,,,
,3873525421.38446,1.99991881847382,6146.509765625,0.024404459832757,3.64460983316439E-5,1,2,13.1008939743042,1.99257476139226,31.25,5.87093179171478,0.905043704572188,100,0.000181463145263967,,,,,,,,,,,,,,,,,,,,,1.99990892410278,1.99992871284485,6061.4970703125,6231.5224609375,52.3964677866402,5.90741673979825,2.18954753875732,26,1,0,0,1,0.140838623046875,31.2805480957031,1,6,1,1.99992871284485,0,2084573184,1.99991881847382,,,,,,,,,,,,,,,,,,,,,,,,,,,,,,,,,
,3873525478.95221,1.99987906217575,11907.8940429688,0.0389619561081362,2.44985076903953E-5,1,2,13.1008939743042,1.99290834885961,31.25,9.3822904221508,1.40227096473968,100,0.000110805962880787,,,,,,,,,,,,,,,,,,,,,1.99986147880554,1.99989664554596,11822.8564453125,11992.931640625,52.4640786535536,5.90476795544582,2.18956303596497,26,1,0,0,1,0.136795043945312,30.3030319213867,1,6,1,1.99986147880554,0,2084573184,1.99987906217575,,,,,,,,,,,,,,,,,,,,,,,,,,,,,,,,,
,3873525536.46038,1.99985307455063,17655.5205078125,0.0488142684605044,2.29940557136303E-5,1,2,13.1008939743042,1.99232159716367,31.25,11.7502287386446,1.74225240305547,100,8.22138895473304E-5,,,,,,,,,,,,,,,,,,,,,1.99965584278107,2.00005030632019,17565.376953125,17745.6640625,52.4097554714671,5.90913467474696,2.1875901222229,26,1,0,0,1,0.143280029296875,30.7917900085449,1,6,1,1.99965584278107,0,2084573824,1.99985307455063,,,,,,,,,,,,,,,,,,,,,,,,,,,,,,,,,
,3873525601.9985,2.00013113021851,24218.546875,0.0567234057652916,2.38892998502241E-5,1,2,13.1008939743042,1.99206467922727,31.25,13.6505522153354,2.02521285185459,100,0.000100381431541412,,,,,,,,,,,,,,,,,,,,,2.0000581741333,2.00020408630371,24128.484375,24308.609375,52.6372093705633,5.91070868236863,2.18946671485901,26,1,0,0,1,0.1483154296875,30.7917900085449,1,6,1,2.0000581741333,0,2084573792,2.00013113021851,,,,,,,,,,,,,,,,,,,,,,,,,,,,,,,,,
,3873525675.3919,2.00002044439316,31567.4775390625,0.0630634646796083,1.95006008386943E-5,1,2,13.1008939743042,1.99212946339687,31.25,15.1782519042258,2.24474156019777,100,8.26426877342802E-5,,,,,,,,,,,,,,,,,,,,,1.99991381168365,2.00012707710266,31482.28515625,31652.669921875,52.8158114872075,5.91478781282562,2.18759107589722,26,1,0,0,1,0.138397216796875,30.7917900085449,1,6,1,1.99991381168365,0,2084573792,2.00002044439316,,,,,,,,,,,,,,,,,,,,,,,,,,,,,,,,,
,3873525733.00367,2.00009274482727,37340.337890625,0.0669042179178034,1.88584520468837E-5,1,2,13.1008939743042,1.99236309181383,31.25,16.1057014269501,2.38560878290468,100,0.000102736349461962,,,,,,,,,,,,,,,,,,,,,2.00003147125244,2.0001540184021,37245.1015625,37435.57421875,53.3281689815633,5.9107072780335,2.18684577941895,26,1,0,0,1,0.136337280273438,31.2805480957031,1,6,1,2.0001540184021,0,2084573984,2.00009274482727,,,,,,,,,,,,,,,,,,,,,,,,,,,,,,,,,
,3873525851.20558,1.99999463558197,49192.85546875,0.0723403476330676,0.000575168019224023,1,2,13.1008939743042,1.99310360535374,31.25,17.4439586688196,2.46281753592619,100,-0.000380489521555009,,,,,,,,,,,,,,,,,,,,,1.99999463558197,1.99999463558197,49192.85546875,49192.85546875,53.6830283292941,5.90360993309996,2.18799877166748,26,1,0,0,1,0.14190673828125,30.7917900085449,1,6,1,1.99999463558197,0,2084574048,1.99999463558197,,,,,,,,,,,,,,,,,,,,,,,,,,,,,,,,,
,3873526311.61759,23.0233173370361,26.5143280029297,0.000207715432240666,2.87740541847609E-7,1,2,13.1008939743042,1.99228700721358,31.2599986791611,0.0499905033192472,0.00746565484262708,1,5.66781500050035E-7,,,,,,,,,,,,,,,,,,,,,23.0233173370361,23.0233173370361,26.5143280029297,26.5143280029297,52.2260727694478,5.90714897992605,5.87831497192383,26,1,0,0,1,0.141448974609375,30.7917900085449,2,1,1,23.0233173370361,0,2084574304,23.0233173370361,,,,,,,,,,,,,,,,,,,,,,,,,,,,,,,,,
,3873526497.7584,52.0072479248047,26.5143280029297,0.000194403179184518,7.91845144815497E-7,1,2,13.1008939743042,1.99164555649182,31.2700010836124,0.0467833652117738,0.00681062580169225,1,-1.85614172269514E-7,,,,,,,,,,,,,,,,,,,,,52.0072479248047,52.0072479248047,26.5143280029297,26.5143280029297,52.3343283193613,5.91433204617308,6.61937236785889,26,1,0,0,1,0.138931274414062,29.8142719268799,2,1,1,52.0072479248047,0,2084574528,52.0072479248047,,,,,,,,,,,,,,,,,,,,,,,,,,,,,,,,,
,3873526680.51237,81.0020141601562,26.5143280029297,0.000186068102246831,5.76566618457021E-8,1,2,13.1008939743042,1.99192969377857,31.3199982047081,0.044770756229513,0.00664916573793617,1,3.57421330918148E-7,,,,,,,,,,,,,,,,,,,,,81.0020141601562,81.0020141601562,26.5143280029297,26.5143280029297,52.3022815500728,5.91126405870005,6.88372230529785,26,1,0,0,1,0.134811401367188,30.7917900085449,2,1,1,81.0020141601562,0,2084574592,81.0020141601562,,,,,,,,,,,,,,,,,,,,,,,,,,,,,,,,,
,3873526857.28431,110.119697570801,26.5143280029297,0.000178056539153333,7.18669654249255E-8,1,2,13.1008939743042,1.99208419039007,31.3800014555454,0.042849443363386,0.00636320093266721,1,3.39513290316484E-7,,,,,,,,,,,,,,,,,,,,,110.119697570801,110.119697570801,26.5143280029297,26.5143280029297,52.5156661358229,5.91482921421845,7.0297999382019,26,1,0,0,1,0.144805908203125,30.7917900085449,2,1,1,110.119697570801,0,2084574336,110.119697570801,,,,,,,,,,,,,,,,,,,,,,,,,,,,,,,,,
,3873527032.27946,139.019180297852,26.5143280029297,0.000169790670018802,6.15750113954051E-8,1,2,13.1008939743042,1.99168676195197,31.4499996602535,0.0408448898989356,0.00606491766729314,1,3.21294153313211E-7,,,,,,,,,,,,,,,,,,,,,139.019180297852,139.019180297852,26.5143280029297,26.5143280029297,52.2104401990632,5.91938254805681,7.1146388053894,26,1,0,0,1,0.136795043945312,31.2805480957031,2,1,1,139.019180297852,0,2084574240,139.019180297852,,,,,,,,,,,,,,,,,,,,,,,,,,,,,,,,,
,3873527207.73225,168.082122802734,26.5143280029297,0.000162492968394455,8.30099772067919E-8,1,2,13.1008939743042,1.99151998495641,31.5500013530254,0.0390823996807179,0.00580842676567628,1,3.28700011629702E-7,,,,,,,,,,,,,,,,,,,,,168.082122802734,168.082122802734,26.5143280029297,26.5143280029297,52.0943683639574,5.92092650609025,7.18335914611816,26,1,0,0,1,0.1397705078125,31.7693061828613,2,1,1,168.082122802734,0,2084574144,168.082122802734,,,,,,,,,,,,,,,,,,,,,,,,,,,,,,,,,
,3873527382.25173,197.062622070313,26.5143280029297,0.000153546733284432,7.39034922852769E-8,1,2,13.1008939743042,1.9915935742076,31.6600017249584,0.0369325799121633,0.00549366812045336,1,3.29914307724382E-7,,,,,,,,,,,,,,,,,,,,,197.040008544922,197.085235595703,26.5143280029297,26.5143280029297,52.3300293625055,5.92145902030731,7.28834056854248,26,1,0,0,1,0.13519287109375,30.7917900085449,2,1,1,197.085235595703,0,2084574304,197.062622070313,,,,,,,,,,,,,,,,,,,,,,,,,,,,,,,,,
,3873527557.19738,226.032440185547,26.5143280029297,0.000146250379216823,7.29139080028108E-8,1,2,13.1008939743042,1.99031254843468,31.7899994552135,0.0351309547372782,0.00525181292187868,1,4.20667005469127E-7,,,,,,,,,,,,,,,,,,,,,226.032440185547,226.032440185547,26.5143280029297,26.5143280029297,52.2065320564671,5.93409650788673,7.52927350997925,26,1,0,0,1,0.141754150390625,31.2805480957031,2,1,1,226.032440185547,0,2084574400,226.032440185547,,,,,,,,,,,,,,,,,,,,,,,,,,,,,,,,,
,3873527731.63239,255.023178100586,26.5143280029297,0.000141561134990791,7.14239799012582E-8,1,2,13.1008939743042,1.99003969641926,31.9399982690811,0.0339868251171478,0.00514271760010378,1,6.59480731464219E-7,,,,,,,,,,,,,,,,,,,,,255.023178100586,255.023178100586,26.5143280029297,26.5143280029297,52.1830832008901,5.93620144748636,7.98756217956543,24,1,64,0,0,0.138626098632812,30.7917900085449,2,1,1,255.023178100586,0,2084574304,255.023178100586,,,,,,,,,,,,,,,,,,,,,,,,,,,,,,,,,
,3873527905.96868,284.005523681641,26.5143280029297,0.00013665720706667,8.13112132778062E-8,1,2,13.1008939743042,1.99126719225812,32.0999994874001,0.0328423557757769,0.00500780082099,1,7.92243561935501E-7,,,,,,,,,,,,,,,,,,,,,284.005523681641,284.005523681641,26.5143280029297,26.5143280029297,52.138530375294,5.9226132410927,8.11443710327148,26,1,0,0,1,0.13580322265625,31.2805480957031,2,1,1,284.005523681641,0,2084574304,284.005523681641,,,,,,,,,,,,,,,,,,,,,,,,,,,,,,,,,
,3873528667.79216,290.957336425781,26.2547473907471,0.000163157118748358,7.07027460351521E-7,1,2,13.1008939743042,1.98132627642035,32.1299992501736,0.038830764238518,0.00598918814917098,1,1.2261668936515E-6,,,,,,,,,,,,,,,,,,,,,290.957336425781,290.957336425781,26.2547473907471,26.2547473907471,52.1924627431209,5.91595041290843,9.22860622406006,24,1,64,0,0,0.139694213867188,30.3030319213867,2,1,1,290.957336425781,0,2084573184,290.957336425781,,,,,,,,,,,,,,,,,,,,,,,,,,,,,,,,,
,3873528824.52966,261.962158203125,26.2547473907471,0.000160756417435159,5.4327549049885E-8,1,2,13.1008939743042,1.9808733846226,31.9899991154671,0.0382524697627913,0.00583261468979749,1,9.31460977504898E-7,,,,,,,,,,,,,,,,,,,,,261.962158203125,261.962158203125,26.2547473907471,26.2547473907471,52.0404359961305,5.92284131221025,9.00317478179932,26,1,0,0,1,0.1434326171875,30.7917900085449,2,1,1,261.962158203125,0,2084574176,261.962158203125,,,,,,,,,,,,,,,,,,,,,,,,,,,,,,,,,
,3873528999.30012,232.942939758301,26.2547473907471,0.000158811418619399,5.01624899020611E-8,1,2,13.1008939743042,1.98127475388076,31.870000064373,0.0378183963580653,0.00566727338092796,1,5.13101171921305E-7,,,,,,,,,,,,,,,,,,,,,232.922576904297,232.963302612305,26.2547473907471,26.2547473907471,52.1701863303228,5.91939778669905,8.62440586090088,26,1,0,0,1,0.143356323242188,31.2805480957031,2,1,1,232.922576904297,0,2084574048,232.942939758301,,,,,,,,,,,,,,,,,,,,,,,,,,,,,,,,,
,3873529172.49436,203.999130249023,26.2547473907471,0.000157979331698146,5.34015653486315E-8,1,2,13.1008939743042,1.98129794711125,31.75999969244,0.0376200397815011,0.00564482920043536,1,5.40314212260075E-7,,,,,,,,,,,,,,,,,,,,,203.999130249023,203.999130249023,26.2547473907471,26.2547473907471,52.1780026155151,5.91750956533011,8.35337829589844,26,1,0,0,1,0.13885498046875,31.2805480957031,2,1,1,203.999130249023,0,2084574112,203.999130249023,,,,,,,,,,,,,,,,,,,,,,,,,,,,,,,,,
,3873529346.70611,174.93994140625,26.2547473907471,0.00015743141791246,7.24723374486745E-8,1,2,13.1008939743042,1.98181232566828,31.6600017249584,0.0375138603821052,0.00558826472151184,1,3.71648183129165E-7,,,,,,,,,,,,,,,,,,,,,174.918273925781,174.961608886719,26.2547473907471,26.2547473907471,52.311270278044,5.9102485592675,8.14354515075684,26,1,0,0,1,0.143203735351562,32.7468223571777,2,1,1,174.918273925781,0,2084574208,174.93994140625,,,,,,,,,,,,,,,,,,,,,,,,,,,,,,,,,
,3873529519.25247,145.951599121094,26.2547473907471,0.00015675162776314,5.23873083344525E-8,1,2,13.1008939743042,1.98111191314283,31.580001115799,0.0373375906209796,0.00548698337858714,1,6.18258435921106E-8,,,,,,,,,,,,,,,,,,,,,145.951599121094,145.951599121094,26.2547473907471,26.2547473907471,52.2913387508036,5.91569510056626,7.96671915054321,26,1,0,0,1,0.140304565429688,31.7693061828613,2,1,1,145.951599121094,0,2084574144,145.951599121094,,,,,,,,,,,,,,,,,,,,,,,,,,,,,,,,,
,3873529693.87363,116.985618591309,26.2547473907471,0.000156469656717341,7.12471414106236E-8,1,2,13.1008939743042,1.9811279180581,31.4900018274784,0.0372645431887884,0.00552123882477328,1,2.46598038805403E-7,,,,,,,,,,,,,,,,,,,,,116.985618591309,116.985618591309,26.2547473907471,26.2547473907471,52.2123942703613,5.9136389799346,7.80896902084351,26,1,0,0,1,0.137786865234375,30.7917900085449,2,1,1,116.985618591309,0,2084573856,116.985618591309,,,,,,,,,,,,,,,,,,,,,,,,,,,,,,,,,
,3873529866.95456,87.9972763061523,26.2547473907471,0.000156253062573462,9.06013446054485E-8,1,2,13.1008939743042,1.98084399979489,31.41999989748,0.0372008511867362,0.00552566931894344,1,3.03248853559045E-7,,,,,,,,,,,,,,,,,,,,,87.9972763061523,87.9972763061523,26.2547473907471,26.2547473907471,52.2940744506209,5.91869025377323,7.64317274093628,26,1,0,0,1,0.143966674804688,31.2805480957031,2,1,1,87.9972763061523,0,2084573184,87.9972763061523,,,,,,,,,,,,,,,,,,,,,,,,,,,,,,,,,
,3873530036.50552,58.9790802001953,26.2547473907471,0.000155854762969392,7.23625533572149E-8,1,2,13.1008939743042,1.98281074522088,31.3500016927719,0.0371780090426311,0.00550798656317457,1,2.43860653695907E-7,,,,,,,,,,,,,,,,,,,,,58.9790802001953,58.9790802001953,26.2547473907471,26.2547473907471,52.3280752912075,5.89483434189896,7.41967535018921,26,1,0,0,1,0.144882202148438,31.2805480957031,2,1,1,58.9790802001953,0,2084573824,58.9790802001953,,,,,,,,,,,,,,,,,,,,,,,,,,,,,,,,,
,3873530206.5455,29.9629802703857,26.2547473907471,0.000156289987192472,6.00099835629741E-8,1,2,13.1008939743042,1.98153104709207,31.2899984419346,0.0372352582104712,0.00552295382960817,1,2.71179219353838E-7,,,,,,,,,,,,,,,,,,,,,29.9629802703857,29.9629802703857,26.2547473907471,26.2547473907471,52.3495700754863,5.90967967969664,6.96197128295898,26,1,0,0,1,0.14617919921875,30.7917900085449,2,1,1,29.9629802703857,0,2084574144,29.9629802703857,,,,,,,,,,,,,,,,,,,,,,,,,,,,,,,,,
,3873530553.78379,2.00004291534424,26.2547473907471,0.000168805937053498,5.99438231072823E-8,1,2,13.1008939743042,1.9808831970368,31.25,0.0401924657610411,0.00595952327804411,1,2.84425551755816E-7,,,,,,,,,,,,,,,,,,,,,2.00004291534424,2.00004291534424,26.2547473907471,26.2547473907471,52.3757546308805,5.91477861263719,2.29814076423645,26,1,0,0,1,0.1434326171875,32.2580642700195,1,1,1,2.00004291534424,0,2084574272,2.00004291534424,,,,,,,,,,,,,,,,,,,,,,,,,,,,,,,,,
,3873530742.48693,30.0301837921143,26.2547473907471,0.000156436679313597,5.01919992271278E-8,1,2,13.1008939743042,1.98134225691597,31.25,0.0372635154379817,0.00552682330453776,1,2.70111849376459E-7,,,,,,,,,,,,,,,,,,,,,30.0301837921143,30.0301837921143,26.2547473907471,26.2547473907471,52.4054565146113,5.90813029185639,6.314453125,26,1,0,0,1,0.144424438476562,31.2805480957031,2,1,1,30.0301837921143,0,2084574080,30.0301837921143,,,,,,,,,,,,,,,,,,,,,,,,,,,,,,,,,
,3873530927.26382,59.0057678222656,26.2547473907471,0.000155441485560322,5.62783730486582E-8,1,2,13.1008939743042,1.98104152379884,31.2799997627735,0.037015914965822,0.0054892635377525,1,2.64957022703087E-7,,,,,,,,,,,,,,,,,,,,,59.0057678222656,59.0057678222656,26.2547473907471,26.2547473907471,52.2901663080248,5.91103253606641,6.86180925369263,26,1,0,0,1,0.140228271484375,30.3030319213867,2,1,1,59.0057678222656,0,2084574208,59.0057678222656,,,,,,,,,,,,,,,,,,,,,,,,,,,,,,,,,
,3873531108.4724,88.025390625,26.2547473907471,0.000154762438408998,5.2520681587022E-8,1,2,13.1008939743042,1.98101402338356,31.3199982047081,0.0368544395734641,0.00545695377701442,1,2.29432010763115E-7,,,,,,,,,,,,,,,,,,,,,88.025390625,88.025390625,26.2547473907471,26.2547473907471,52.311270278044,5.91366128900193,7.08221197128296,26,1,0,0,1,0.14312744140625,31.2805480957031,2,1,1,88.025390625,0,2084574304,88.025390625,,,,,,,,,,,,,,,,,,,,,,,,,,,,,,,,,
,3873531284.57576,117.031318664551,26.2547473907471,0.000154013245798119,5.60402937589216E-8,1,2,13.1008939743042,1.99210929558681,31.3900001347065,0.0370660530242608,0.00549208013506603,1,2.43744283926977E-7,,,,,,,,,,,,,,,,,,,,,117.031318664551,117.031318664551,26.2547473907471,26.2547473907471,52.1729220301401,5.91048491813565,7.19177865982056,26,1,0,0,1,0.1397705078125,31.7693061828613,2,1,1,117.031318664551,0,2084574368,117.031318664551,,,,,,,,,,,,,,,,,,,,,,,,,,,,,,,,,
,3873531460.0406,146.01496887207,26.2547473907471,0.000153324886171142,5.1125553419588E-8,1,2,13.1008939743042,1.99234623972175,31.470000743866,0.0369130543918591,0.00543910578670224,1,1.19468994698827E-7,,,,,,,,,,,,,,,,,,,,,146.01496887207,146.01496887207,26.2547473907471,26.2547473907471,52.2377971972363,5.91141918695429,7.26198101043701,26,1,0,0,1,0.135955810546875,31.7693061828613,2,1,1,146.01496887207,0,2084574464,146.01496887207,,,,,,,,,,,,,,,,,,,,,,,,,,,,,,,,,
,3873531634.68629,175.002334594727,26.2547473907471,0.000152743457592269,5.20180706429703E-8,1,2,13.1008939743042,1.99148438465541,31.5699987113476,0.0367338710019656,0.00547581383410919,1,3.75796905533296E-7,,,,,,,,,,,,,,,,,,,,,175.002334594727,175.002334594727,26.2547473907471,26.2547473907471,52.3992034864575,5.91739974338707,7.32662105560303,24,1,64,0,0,0.135345458984375,31.2805480957031,2,1,1,175.002334594727,0,2084574336,175.002334594727,,,,,,,,,,,,,,,,,,,,,,,,,,,,,,,,,
,3873531809.51311,204.032409667969,26.2547473907471,0.000151989844219613,6.31415066389609E-8,1,2,13.1008939743042,1.99116091393593,31.6900014877319,0.0365406216795122,0.00545227020073489,1,3.95359928342111E-7,,,,,,,,,,,,,,,,,,,,,204.032409667969,204.032409667969,26.2547473907471,26.2547473907471,52.1092193058228,5.921823040282,7.42097043991089,25,1,64,0,0,0.136642456054688,30.7917900085449,2,1,1,204.032409667969,0,2084574464,204.032409667969,,,,,,,,,,,,,,,,,,,,,,,,,,,,,,,,,
,3873531984.76228,233.017730712891,26.2547473907471,0.000151444739884537,6.02158266269168E-8,1,2,13.1008939743042,1.99109012709304,31.8199992179871,0.0364057099983185,0.00544194730007266,1,4.33850284112264E-7,,,,,,,,,,,,,,,,,,,,,233.017730712891,233.017730712891,26.2547473907471,26.2547473907471,52.3261212199094,5.92868059890642,7.61835861206055,26,1,0,0,1,0.14404296875,31.2805480957031,2,1,1,233.017730712891,0,2084574432,233.017730712891,,,,,,,,,,,,,,,,,,,,,,,,,,,,,,,,,
,3873532159.05408,262.027709960938,26.2547473907471,0.000151007809699623,5.04686124426767E-8,1,2,13.1008939743042,1.99140320722126,31.9700017571449,0.0362992502305948,0.00551144192250254,1,7.80024012140119E-7,,,,,,,,,,,,,,,,,,,,,262.027709960938,262.027709960938,26.2547473907471,26.2547473907471,52.2983734074767,5.92526802685392,8.02187824249268,25,1,64,0,0,0.140914916992188,30.7917900085449,2,1,1,262.027709960938,0,2084574336,262.027709960938,,,,,,,,,,,,,,,,,,,,,,,,,,,,,,,,,
,3873532334.29953,291.023773193359,26.2547473907471,0.000149353749308856,1.33440978089394E-7,1,2,13.1008939743042,1.99115118753802,32.1400016546249,0.0358866801988176,0.00549311975950312,1,9.51747311769204E-7,,,,,,,,,,,,,,,,,,,,,291.023773193359,291.023773193359,26.2547473907471,26.2547473907471,52.2964193361786,5.92816490678174,7.85794734954834,24,1,64,0,0,0.144729614257813,30.7917900085449,2,1,1,291.023773193359,0,2084574400,291.023773193359,,,,,,,,,,,,,,,,,,,,,,,,,,,,,,,,,
,3873532694.88456,300.003723144531,42821.4375,0.000730840790836346,1.30559104377681E-5,1,2,13.1008939743042,2.00188283241187,32.1800000965595,0.193263473971885,-0.0810604668904853,100,-0.00044073482862405,,,,,,,,,,,,,,,,,,,,,300.003448486328,300.003997802734,42741.48046875,42901.39453125,52.1483007317844,5.92327808078346,7.9080958366394,25,1,68,0,0,0.139389038085938,30.7917900085449,1,6,1,300.003997802734,0,2084573184,300.003723144531,,,,,,,,,,,,,,,,,,,,,,,,,,,,,,,,,
,3873532752.3528,300.002334594727,37080.18359375,0.000671223244959727,1.32631703875675E-5,1,2,13.1008939743042,2.00158154690662,32.1800000965595,0.175039361581724,-0.0579941876345603,100,-0.000337129798735953,,,,,,,,,,,,,,,,,,,,,300.002014160156,300.002655029297,36990.62890625,37169.73828125,52.1064836060055,5.92612537638769,8.00318813323975,26,1,0,0,1,0.139236450195312,31.2805480957031,1,6,1,300.002655029297,0,2084573184,300.002334594727,,,,,,,,,,,,,,,,,,,,,,,,,,,,,,,,,
,3873532809.91212,300.003234863281,31338.1435546875,0.000633576377891571,9.26153475043276E-6,1,2,13.1008939743042,2.00174343923675,32.1800000965595,0.163666990181368,-0.0439669926982531,100,-0.000273835353979089,,,,,,,,,,,,,,,,,,,,,300.003173828125,300.003295898438,31248.23046875,31428.056640625,52.2053596136882,5.92456507654447,8.16054153442383,26,1,0,0,1,0.138778686523438,29.8142719268799,1,6,1,300.003295898438,0,2084574080,300.003234863281,,,,,,,,,,,,,,,,,,,,,,,,,,,,,,,,,
,3873532867.51345,300.001800537109,25580.943359375,0.000397927720554598,0.000260123316974511,1,2,13.1008939743042,2.00271166525934,32.1800000965595,0.112644511296105,-0.094213662998955,100,-0.000445777255452018,,,,,,,,,,,,,,,,,,,,,300.001800537109,300.001800537109,25496.029296875,25665.857421875,52.2190381127747,5.91592468584547,8.36128234863281,26,1,0,0,1,0.141525268554688,31.2805480957031,1,6,1,300.001800537109,0,2084573984,300.001800537109,,,,,,,,,,,,,,,,,,,,,,,,,,,,,,,,,
,3873532942.8808,300.001739501953,18056.826171875,0.00050723637035203,2.47463688088928E-5,1,2,13.1008939743042,2.00258513597479,32.1800000965595,0.131273644363839,-0.0361742837605228,100,-0.000223123921968787,,,,,,,,,,,,,,,,,,,,,300.001678466797,300.001800537109,17967.01171875,18146.640625,52.2213829983325,5.91484078929606,8.70359802246094,24,1,68,0,0,0.138778686523438,31.2805480957031,1,6,1,300.001678466797,0,2084573760,300.001739501953,,,,,,,,,,,,,,,,,,,,,,,,,,,,,,,,,
,3873533000.41301,300.000350952148,12314.52734375,0.000536373363388082,5.13373650296544E-5,1,2,13.1008939743042,2.00310750874601,32.1800000965595,0.137035221706137,-0.0256632771286258,100,-0.00018410954505358,,,,,,,,,,,,,,,,,,,,,299.999969482422,300.000732421875,12224.4775390625,12404.5771484375,52.2632001241113,5.91145324177203,9.02354526519775,26,1,0,0,1,0.13702392578125,30.3030319213867,1,6,1,300.000732421875,0,2084574080,300.000350952148,,,,,,,,,,,,,,,,,,,,,,,,,,,,,,,,,
,3873533058.02751,300.001663208008,6552.36450195313,0.000508184291298149,7.60833745025843E-5,1,2,13.1008939743042,2.00293046163571,32.1800000965595,0.130872916479558,-0.0315522734700049,100,-0.000204209877135975,,,,,,,,,,,,,,,,,,,,,300.001434326172,300.001892089844,6467.3828125,6637.34619140625,52.1701863303228,5.91448932891271,9.36593246459961,26,1,0,0,1,0.13702392578125,31.2805480957031,1,6,1,300.001892089844,0,2084573760,300.001663208008,,,,,,,,,,,,,,,,,,,,,,,,,,,,,,,,,
,3873533115.52999,300.000747680664,805.374298095703,0.000666113137784536,0.000196791184388227,1,2,13.1008939743042,2.00313103544962,32.1800000965595,0.179434458978972,-0.094981162779201,100,-0.000488082167719971,,,,,,,,,,,,,,,,,,,,,300.000549316406,300.000946044922,710.732360839844,900.016235351562,52.2608552385536,5.9127213374311,9.70883369445801,25,1,68,0,0,0.14007568359375,30.7917900085449,1,6,1,300.000946044922,0,2084573504,300.000747680664,,,,,,,,,,,,,,,,,,,,,,,,,,,,,,,,,
,3873533181.04642,300.000244140625,-5748.88134765625,-0.00014590464722409,1.69163497518944E-5,1,2,13.1008939743042,2.0034521229519,32.1800000965595,-0.0307127402690227,-0.0378866745048009,100,-0.000134319538286398,,,,,,,,,,,,,,,,,,,,,300.000030517578,300.000457763672,-5838.91259765625,-5658.85009765625,52.1525996886401,5.9088197570817,9.99647617340088,24,1,68,0,0,0.135650634765625,31.7693061828613,1,6,1,300.000030517578,0,2084573184,300.000244140625,,,,,,,,,,,,,,,,,,,,,,,,,,,,,,,,,
,3873533238.63718,299.999374389648,-11506.056640625,-0.000327229536808934,5.86573032941067E-6,1,2,13.1008939743042,2.0028632932234,32.1800000965595,-0.0786672840814209,-0.0178882510636513,100,-2.55995257264E-5,,,,,,,,,,,,,,,,,,,,,299.999328613281,299.999420166016,-11591.125,-11420.98828125,52.2573379102171,5.91526865379709,9.8900842666626,26,1,0,0,1,0.14434814453125,30.7917900085449,1,6,1,299.999298095703,0,2084573184,299.999374389648,,,,,,,,,,,,,,,,,,,,,,,,,,,,,,,,,
,3873533323.90212,300.000381469727,-20033.0400390625,-0.000434724850012309,5.21983188730948E-6,1,2,13.1008939743042,2.00297242799955,32.1800000965595,-0.106692366735174,-0.00894648685183773,10,2.69263461575329E-5,,,,,,,,,,,,,,,,,,,,,300.000061035156,300.000701904297,-20123.1640625,-19942.916015625,52.255383838919,5.91125081551436,9.74059677124023,25,1,68,0,0,0.138320922851562,30.3030319213867,1,6,1,300.000061035156,0,2084573952,300.000381469727,,,,,,,,,,,,,,,,,,,,,,,,,,,,,,,,,
,3873533393.39183,300.000030517578,-26987.9658203125,-0.00048810079018831,5.19027344910052E-6,1,2,13.1008939743042,2.00312508537535,32.1800000965595,-0.120047150379773,-0.00842447601528087,100,3.69000288345028E-5,,,,,,,,,,,,,,,,,,,,,299.999877929687,300.000183105469,-27078.201171875,-26897.73046875,52.2323257976017,5.91167371198895,9.64238739013672,26,1,0,0,1,0.143585205078125,30.7917900085449,1,6,1,299.999877929687,0,2084573792,300.000030517578,,,,,,,,,,,,,,,,,,,,,,,,,,,,,,,,,
,3873533450.96587,299.999908447266,-32754.7373046875,-0.000514141997047898,7.40138219744719E-6,1,2,13.1008939743042,2.00283510678726,32.1800000965595,-0.12665087231947,-0.00727738331570651,100,4.54238915876214E-5,,,,,,,,,,,,,,,,,,,,,299.999877929687,299.999938964844,-32839.94140625,-32669.533203125,52.1920719288613,5.91258153513362,9.5748176574707,26,1,0,0,1,0.1385498046875,31.2805480957031,1,6,1,299.999938964844,0,2084574016,299.999908447266,,,,,,,,,,,,,,,,,,,,,,,,,,,,,,,,,
,3873533508.45885,300.000183105469,-38521.60546875,-0.000551500744938337,9.21721138651921E-6,1,2,13.1008939743042,2.00261346149387,32.1800000965595,-0.136415438446502,-0.00377667189922192,100,6.52908948754353E-5,,,,,,,,,,,,,,,,,,,,,300.000183105469,300.000183105469,-38611.93359375,-38431.27734375,52.2229462553709,5.91289923047978,9.52284049987793,26,1,0,0,1,0.14862060546875,31.2805480957031,1,6,1,300.000183105469,0,2084574176,300.000183105469,,,,,,,,,,,,,,,,,,,,,,,,,,,,,,,,,
,3873533599.79044,300.00114440918,-47670.982421875,-0.000646469074833889,7.04878150643191E-5,1,2,13.1008939743042,2.00274510723327,32.1800000965595,-0.160640533067312,0.000447589338837727,100,9.65827268033957E-5,,,,,,,,,,,,,,,,,,,,,300.000946044922,300.001342773438,-47761.20703125,-47580.7578125,52.1862097149671,5.91377477731643,9.4514799118042,26,1,0,0,1,0.136642456054688,30.7917900085449,1,6,1,300.000946044922,0,2084573920,300.00114440918,,,,,,,,,,,,,,,,,,,,,,,,,,,,,,,,,
,3873533667.22444,300.000045776367,-46772.962890625,-0.000845404925158627,1.4130846814797E-5,1,2,13.1008939743042,2.0023711486606,32.1800000965595,-0.227967447865426,0.123187874434627,100,0.000630677926181425,,,,,,,,,,,,,,,,,,,,,300,300.000091552734,-46867.81640625,-46678.109375,52.174094472919,5.91664454225891,9.40064430236816,24,1,68,0,0,0.141830444335938,31.7693061828613,1,6,1,300,0,2084574016,300.000045776367,,,,,,,,,,,,,,,,,,,,,,,,,,,,,,,,,
,3873533724.88654,299.999481201172,-41017.05078125,-0.000776063183607422,1.59478194816527E-5,1,2,13.1008939743042,2.0024834550313,32.1800000965595,-0.206445496247524,0.0936771871390011,100,0.0004990710547506,,,,,,,,,,,,,,,,,,,,,299.999237060547,299.999725341797,-41096.96484375,-40937.13671875,52.2307625405632,5.91346965185749,9.36760330200195,24,1,68,0,0,0.1416015625,31.7693061828613,1,6,1,299.999725341797,0,2084573920,299.999481201172,,,,,,,,,,,,,,,,,,,,,,,,,,,,,,,,,
,3873533782.42638,300.000503540039,-35271.326171875,-0.000686175523549413,2.48151757714732E-5,1,2,13.1008939743042,2.00278826074222,32.1800000965595,-0.180884228712469,0.0712352284868449,100,0.000393499360295821,,,,,,,,,,,,,,,,,,,,,300.000457763672,300.000549316406,-35355.8515625,-35186.80078125,52.0935867354382,5.9113934669137,9.33619785308838,25,1,68,0,0,0.140228271484375,31.2805480957031,1,6,1,300.000549316406,0,2084574112,300.000503540039,,,,,,,,,,,,,,,,,,,,,,,,,,,,,,,,,
,3873533839.9131,300.000289916992,-29531.2578125,-0.000644132619939878,2.86470604540084E-5,1,2,13.1008939743042,2.00269680901222,32.1800000965595,-0.167999295802708,0.0546696957717523,100,0.000319235410503515,,,,,,,,,,,,,,,,,,,,,300.000152587891,300.000427246094,-29616.208984375,-29446.306640625,52.2127850846209,5.91135792579382,9.3021879196167,25,1,68,0,0,0.14556884765625,31.7693061828613,1,6,1,300.000152587891,0,2084573920,300.000289916992,,,,,,,,,,,,,,,,,,,,,,,,,,,,,,,,,
,3873533915.38316,300.001037597656,-21992.423828125,-0.000575463081306448,3.03952153774628E-5,1,2,13.1008939743042,2.00282288671705,32.1800000965595,-0.147822394238966,0.0332572573823317,100,0.000221094109049917,,,,,,,,,,,,,,,,,,,,,300.000854492188,300.001220703125,-22077.337890625,-21907.509765625,52.2374063829767,5.9101654951466,9.27186965942383,24,1,68,0,0,0.139617919921875,31.2805480957031,1,6,1,300.000854492188,0,2084573184,300.001037597656,,,,,,,,,,,,,,,,,,,,,,,,,,,,,,,,,
,3873533982.81843,300,-15263.5263671875,-0.000475679863743583,2.71155021356295E-5,1,2,13.1008939743042,2.00407644136483,32.1800000965595,-0.124038476761922,0.0391439237272908,100,0.000230486668947991,,,,,,,,,,,,,,,,,,,,,299.999969482422,300.000030517578,-15348.3974609375,-15178.6552734375,52.2565562816978,5.89620400950639,9.24441623687744,25,1,68,0,0,0.146026611328125,31.2805480957031,1,6,1,299.999969482422,0,2084573984,300,,,,,,,,,,,,,,,,,,,,,,,,,,,,,,,,,
,3873534050.29758,300.00065612793,-8518.880859375,-0.000461607737420182,8.60951666023138E-6,1,2,13.1008939743042,2.00292090418975,32.1800000965595,-0.119716595044257,0.0343893625688035,100,0.000209050513237846,,,,,,,,,,,,,,,,,,,,,300.000640869141,300.000671386719,-8603.8935546875,-8433.8681640625,52.1627608593901,5.90641734349331,9.2238826751709,26,1,0,0,1,0.144500732421875,31.2805480957031,1,6,1,300.000640869141,0,2084573824,300.00065612793,,,,,,,,,,,,,,,,,,,,,,,,,,,,,,,,,
,3873534107.83506,300.000244140625,-2767.29248046875,-0.000418119060685199,1.7336057527247E-5,1,2,13.1008939743042,2.00349001281532,32.1800000965595,-0.112037184659672,0.0553273477235523,100,0.000288646496619877,,,,,,,,,,,,,,,,,,,,,300,300.00048828125,-2856.921875,-2677.6630859375,52.1873821577459,5.90073907014031,9.21173667907715,26,1,0,0,1,0.152130126953125,30.7917900085449,1,6,1,300,0,2084573600,300.000244140625,,,,,,,,,,,,,,,,,,,,,,,,,,,,,,,,,
,3873534173.45789,299.99934387207,3791.80871582031,4.99803627623806E-5,2.15450430034088E-5,1,2,13.1008939743042,2.00321651129685,32.1800000965595,0.00576879328876263,0.0453845555656609,100,0.000179233025112921,,,,,,,,,,,,,,,,,,,,,299.999328613281,299.999359130859,3711.78369140625,3871.83374023438,52.2596827957748,5.90355281988169,9.19467449188232,25,1,68,0,0,0.140151977539062,31.2805480957031,1,6,1,299.999328613281,0,2084573184,299.99934387207,,,,,,,,,,,,,,,,,,,,,,,,,,,,,,,,,
,3873534238.82743,300.000381469727,10327.6586914062,0.000299110831729254,1.00096546739179E-5,1,2,13.1008939743042,2.00333646944519,32.1800000965595,0.0710066898578028,0.0227242262842038,100,4.95640159153443E-5,,,,,,,,,,,,,,,,,,,,,300.000335693359,300.000427246094,10232.4912109375,10422.826171875,52.1967616999767,5.90242385897838,9.17945766448975,26,1,0,0,1,0.147933959960938,31.2805480957031,1,6,1,300.000427246094,0,2084573184,300.000381469727,,,,,,,,,,,,,,,,,,,,,,,,,,,,,,,,,
,3873534300.30551,300.001068115234,16480.076171875,0.000403716023892379,5.52810644194738E-6,1,2,13.1008939743042,2.00321490592455,32.1800000965595,0.0985233436160714,0.0122774103483862,10,-8.69822117742062E-6,,,,,,,,,,,,,,,,,,,,,300.001007080078,300.001129150391,16385.001953125,16575.150390625,52.1951984429382,5.90324135394687,9.17502593994141,26,1,0,0,1,0.139999389648438,31.7693061828613,1,6,1,300.001129150391,0,2084574272,300.001068115234,,,,,,,,,,,,,,,,,,,,,,,,,,,,,,,,,
,3873534395.58708,300.00048828125,26010.056640625,0.000454345642842468,6.97436280152912E-5,1,2,13.1008939743042,2.00331374845707,32.1800000965595,0.113868399208938,-0.00650856719313067,100,-9.33374248224995E-5,,,,,,,,,,,,,,,,,,,,,300.000335693359,300.000640869141,25919.779296875,26100.333984375,52.1338406041786,5.90402875741768,9.15416622161865,26,1,0,0,1,0.139617919921875,31.2805480957031,1,6,1,300.000640869141,0,2084573952,300.00048828125,,,,,,,,,,,,,,,,,,,,,,,,,,,,,,,,,
,3873534461.20334,299.999481201172,32584.8974609375,0.000519985228079429,6.95141540742067E-6,1,2,13.1008939743042,2.00315377912869,32.1800000965595,0.128088025090892,0.00764099164950483,100,-4.47945142886031E-5,,,,,,,,,,,,,,,,,,,,,299.999420166016,299.999542236328,32504.7734375,32665.021484375,52.2272452122267,5.90496340353603,9.14312553405762,25,1,68,0,0,0.137176513671875,31.2805480957031,1,6,1,299.999420166016,0,2084574048,299.999481201172,,,,,,,,,,,,,,,,,,,,,,,,,,,,,,,,,
,3873534518.64547,300.000122070313,38347.69140625,0.000548880851414848,5.96828083486655E-6,1,2,13.1008939743042,2.00366890756045,32.1800000965595,0.13572930802854,0.00494739856743458,100,-6.01121030705764E-5,,,,,,,,,,,,,,,,,,,,,300.000091552734,300.000152587891,38257.40625,38437.9765625,52.209658570544,5.90172466659144,9.13799667358398,26,1,0,0,1,0.139083862304688,32.2580642700195,1,6,1,300.000091552734,0,2084573888,300.000122070313,,,,,,,,,,,,,,,,,,,,,,,,,,,,,,,,,
,3873534584.19548,299.99919128418,44918.380859375,0.0005634081674518,5.9412279749788E-6,1,2,13.1008939743042,2.00332607533025,32.1800000965595,0.139030489673099,0.00675554477838469,100,-5.48027389996447E-5,,,,,,,,,,,,,,,,,,,,,299.998962402344,299.999420166016,44833.12109375,45003.640625,52.1213345478709,5.90723825179678,9.11884498596191,26,1,0,0,1,0.139694213867188,31.2805480957031,1,6,1,299.999420166016,0,2084574016,299.99919128418,,,,,,,,,,,,,,,,,,,,,,,,,,,,,,,,,
,3873534639.86801,299.999160766602,50000.203125,0.000569972722354045,3.54727867856423E-6,1,2,13.1008939743042,2.00357478109138,32.1800000965595,0.138678509102138,0.0205167047627693,100,7.76159433646097E-7,,,,,,,,,,,,,,,,,,,,,299.999145507812,299.999176025391,50000.19140625,50000.21484375,51.965790472544,5.90558902463049,9.11185359954834,26,1,0,0,1,0.142288208007812,31.2805480957031,1,4,1,299.999145507812,0,2084574016,299.999160766602,,,,,,,,,,,,,,,,,,,,,,,,,,,,,,,,,