File: LT data/Sherwood/D2/D2 386 Full sequence.dat
[Header]
; MPMS3 Data File (default extension .dat)
; Copyright (c) 2007, Quantum Design, Inc. All rights reserved.
TITLE,
FILEOPENTIME,3869973568.13186,08/18/2022,10:50 am
BYAPP,MPMS3 w/ AC,1.0,1.1
INFO,MPMS3 Measurement Release 1.1.16 Build 424, MultiVu Release 2.3.4.19,APPNAME
INFO,Linear Motor Servo Controller,MOTOR_MODULE_NAME
INFO,3101-100 N0,MOTOR_HW_VERSION
INFO,MMC1047,MOTOR_SERIAL_NUMBER
INFO,01.04.28,MOTOR_SOFTWARE_VERSION
INFO,Quantum Design Squid Module,SQUID_MODULE_NAME
INFO,3101-501 B0,SQUID_HW_VERSION
INFO,SQM278,SQUID_SERIAL_NUMBER
INFO,01.03.04,SQUID_SOFTWARE_VERSION
INFO,Quantum Design VSM Oven,OVEN_MODULE_NAME
INFO,3101-201 A3,OVEN_HW_VERSION
INFO,OVB323,OVEN_SERIAL_NUMBER
INFO,01.07.07,OVEN_SOFTWARE_VERSION
INFO,SQUID AC,AC_MODULE_NAME
INFO,3101-401 G0,AC_HW_VERSION
INFO,SAC258,AC_SERIAL_NUMBER
INFO,SQUID AC 00.95.07,AC_SOFTWARE_VERSION
INFO,TCI127,COIL_SERIAL_NUMBER
INFO,0,MOMENT_UNITS
INFO,Sandstone,SAMPLE_MATERIAL
INFO,,SAMPLE_COMMENT
INFO,,SAMPLE_MASS
INFO,,SAMPLE_VOLUME
INFO,,SAMPLE_MOLECULAR_WEIGHT
INFO,,SAMPLE_SIZE
INFO,,SAMPLE_SHAPE
INFO,Straw,SAMPLE_HOLDER
INFO,Standard,SAMPLE_HOLDER_DETAIL
INFO,67.57,SAMPLE_OFFSET
DATATYPE,COMMENT,1
DATATYPE,TIME,2
STARTUPAXIS,X,2
STARTUPAXIS,Y1,5
FIELDGROUP, VSM,2,3,4,5,6,8,9,10,11,14,15
FIELDGROUP, DC, 2,3,4,14,56,57,58,59,60,61,62,63,64,65,66,67,68,69
FIELDGROUP, AC, 2,3,4,11,16,17,18,19,20,21,22,23,24,25,26,27,28,29,30
STARTUPGROUP, All
[Data]
Comment,Time Stamp (sec),Temperature (K),Magnetic Field (Oe),Moment (emu),M. Std. Err. (emu),Transport Action,Averaging Time (sec),Frequency (Hz),Peak Amplitude (mm),Center Position (mm),Lockin Signal' (V),Lockin Signal (V),Range,M. Quad. Signal (emu),AC Moment (emu),AC M. Std Err. (emu),AC Phase (deg),AC Phase Std. Err. (deg),AC Susceptibility (emu/Oe),AC Suscept. Std Err. (emu/Oe),AC X' (emu/Oe),AC X' Std Err. (emu/Oe),AC X'' (emu/Oe),AC X'' Std Err. (emu/Oe),AC Drive (Oe),AC Frequency (Hz),AC Averaging Time (sec),AC Cycles,AC Range,AC Measure Type,AC Signal' (V),AC Signal'' (V),AC Trim Coil Ratio,AC Trim Coil Phase,Min. Temperature (K),Max. Temperature (K),Min. Field (Oe),Max. Field (Oe),Mass (grams),Motor Lag (deg),Pressure (Torr),Measure Count,Measurement Number,SQUID Status (code),Motor Status (code),Measure Status (code),Motor Current (amps),Motor Temp. (C),Temp. Status (code),Field Status (code),Chamber Status (code),Chamber Temp (K),Redirection State,Evercool Status,Average Temp (K),Rotation Angle (deg),Rotator state,DC Moment Fixed Ctr (emu),DC Moment Err Fixed Ctr (emu),DC Moment Free Ctr (emu),DC Moment Err Free Ctr (emu),DC Fixed Fit,DC Free Fit,DC Calculated Center (mm),DC Calculated Center Err (mm),DC Scan Length (mm),DC Scan Time (s),DC Number of Points,DC Squid Drift,DC Min V (V),DC Max V (V),DC Scans per Measure,Map 01,Map 02,Map 03,Map 04,Map 05,Map 06,Map 07,Map 08,Map 09,Map 10,Map 11,Map 12,Map 13,Map 14,Map 15,Map 16
"FC",3869975029.41067
,3869975926.52755,88.431526184082,49999.7578125,0.0125754277118024,2.46587229516406E-5,1,2,14.0008964538574,4.98136737213615,39.4099988043308,14.5305592400965,2.18553021239228,100,6.5470971792382E-6,,,,,,,,,,,,,,,,,,,,,88.2688522338867,88.5942001342773,49999.7578125,49999.7578125,52.6774632393037,6.09518963600995,8.11257171630859,28,1,0,0,1,0.337066650390625,31.7693061828613,2,1,1,88.2688522338867,0,2084573184,88.431526184082,,,,,,,,,,,,,,,,,,,,,,,,,,,,,,,,,
,3869976052.65071,67.5708808898926,49999.7578125,0.0175601570284749,9.3228874459734E-5,1,2,14.0008964538574,4.98125371884902,39.3499992787838,20.292196156509,3.03460522095962,100,-5.69246941314895E-6,,,,,,,,,,,,,,,,,,,,,67.4297409057617,67.7120208740234,49999.7578125,49999.7578125,52.6481521698325,6.09415641546273,7.85576152801514,27,1,64,0,0,0.33782958984375,33.2355842590332,2,1,1,67.4297409057617,0,2084573184,67.5708808898926,,,,,,,,,,,,,,,,,,,,,,,,,,,,,,,,,
,3869976183.7486,45.1793670654297,49999.7578125,0.0269327151755095,1.03872491533641E-5,1,2,14.0008964538574,4.98109111567088,39.3100008368492,31.1199379620506,4.66469133818558,1000,4.50771232937258E-7,,,,,,,,,,,,,,,,,,,,,45.1793670654297,45.1793670654297,49999.7578125,49999.7578125,52.6946590667267,6.09461743110493,7.46331977844238,28,1,0,0,1,0.33721923828125,34.2131004333496,2,1,1,45.1793670654297,0,2084573664,45.1793670654297,,,,,,,,,,,,,,,,,,,,,,,,,,,,,,,,,
,3869976300.48057,25.4357481002808,49999.7578125,0.0431671592806457,0.000106716788139194,1,2,14.0008964538574,4.98115080253673,39.2800010740757,49.8587158393343,7.61316580477931,1000,0.000118919930420775,,,,,,,,,,,,,,,,,,,,,25.2650527954102,25.6064434051514,49999.7578125,49999.7578125,52.8322256861114,6.09474477008781,6.76325368881226,28,1,0,0,1,0.337295532226562,34.2131004333496,2,1,1,25.2650527954102,0,2084573792,25.4357481002808,,,,,,,,,,,,,,,,,,,,,,,,,,,,,,,,,
,3869976422.54,6.72626948356628,49999.7578125,0.0737814385935638,0.000603313364901727,1,2,14.0008964538574,4.98128979048557,39.2500013113022,85.3195933604287,12.3618122603533,100,-0.000360239626179268,,,,,,,,,,,,,,,,,,,,,6.59455490112305,6.85798406600952,49999.7578125,49999.7578125,53.2754090565153,6.09592407639899,4.5529990196228,28,1,0,0,1,0.338058471679687,34.2131004333496,6,1,1,6.59455490112305,0,2084575648,6.72626948356628,,,,,,,,,,,,,,,,,,,,,,,,,,,,,,,,,
,3869976492.50565,1.99928814172745,49999.7578125,0.0821731436466576,1.99605300886136E-5,1,2,14.0008964538574,4.98125717389923,39.2500013113022,94.9293872457565,14.3905812836766,100,0.000137845523953807,,,,,,,,,,,,,,,,,,,,,1.99869811534882,1.99987816810608,49999.7578125,49999.7578125,53.8608488174192,6.09685289328373,2.60950446128845,28,1,0,0,1,0.337142944335937,34.2131004333496,5,1,1,1.99869811534882,0,2084574592,1.99928814172745,,,,,,,,,,,,,,,,,,,,,,,,,,,,,,,,,
,3869976945.92278,20.4875478744507,26.2300281524658,0.000238707850030593,1.14468181141526E-7,1,5,14.0008964538574,4.99155790161996,39.2500013113022,0.276560665201423,0.0419441027374244,1,4.16957592630564E-7,,,,,,,,,,,,,,,,,,,,,20.0957489013672,20.8793468475342,26.2300281524658,26.2300281524658,52.6610490403998,6.09468834123557,5.86815595626831,70,1,0,0,1,0.339508056640625,32.7468223571777,2,1,1,20.8793468475342,0,2084574464,20.4875478744507,,,,,,,,,,,,,,,,,,,,,,,,,,,,,,,,,
,3869977142.3358,51.0101280212402,26.2300281524658,0.000184877211180512,4.30365811961465E-8,1,5,14.0008964538574,4.99151382479801,39.2699986696243,0.21420301819689,0.0324064126603664,1,2.55158176934092E-7,,,,,,,,,,,,,,,,,,,,,51.0101280212402,51.0101280212402,26.2300281524658,26.2300281524658,52.6016452729383,6.09696070343521,6.75626945495606,69,1,64,0,0,0.340423583984375,35.6793746948242,2,1,1,51.0101280212402,0,2084574592,51.0101280212402,,,,,,,,,,,,,,,,,,,,,,,,,,,,,,,,,
,3869977337.12302,82.0270767211914,26.2300281524658,0.000169368149647743,3.76055314926963E-8,1,5,14.0008964538574,4.99141408505369,39.3199995160103,0.196237026902155,0.0296292841890471,1,1.83897912181176E-7,,,,,,,,,,,,,,,,,,,,,82.0270767211914,82.0270767211914,26.2300281524658,26.2300281524658,52.6946590667267,6.09757979482799,7.06488084793091,69,1,64,0,0,0.338821411132812,34.2131004333496,2,1,1,82.0270767211914,0,2084574496,82.0270767211914,,,,,,,,,,,,,,,,,,,,,,,,,,,,,,,,,
,3869977525.30242,113.003517150879,26.2300281524658,0.00015818190712979,4.25077004259066E-8,1,5,14.0008964538574,4.99130161081803,39.3900014460087,0.183262009798409,0.027727423627567,1,2.20022453509985E-7,,,,,,,,,,,,,,,,,,,,,113.003517150879,113.003517150879,26.2300281524658,26.2300281524658,52.7591434195633,6.09925218961236,7.2149224281311,70,1,0,0,1,0.3399658203125,34.2131004333496,2,1,1,113.003517150879,0,2084574624,113.003517150879,,,,,,,,,,,,,,,,,,,,,,,,,,,,,,,,,
,3869977712.74021,144.056533813477,26.2300281524658,0.000147753471635324,2.7777114059307E-8,1,5,14.0008964538574,4.99114379640064,39.4599996507168,0.17118790602531,0.0257957742677461,1,1.17041431057188E-7,,,,,,,,,,,,,,,,,,,,,144.056533813477,144.056533813477,26.2300281524658,26.2300281524658,52.7224068791594,6.10141106548231,7.3315281867981,70,1,0,0,1,0.337753295898438,34.2131004333496,2,1,1,144.056533813477,0,2084574688,144.056533813477,,,,,,,,,,,,,,,,,,,,,,,,,,,,,,,,,
,3869977900.11302,175.010131835938,26.2300281524658,0.000129563953894259,2.54855345143726E-8,1,5,14.0008964538574,4.9907383661441,39.5700000226498,0.150099178841283,0.0225987432402438,1,8.63966739933711E-8,,,,,,,,,,,,,,,,,,,,,175.010131835938,175.010131835938,26.2300281524658,26.2300281524658,52.7325680499094,6.10252177885606,7.44624376296997,68,1,64,0,0,0.337982177734375,32.7468223571777,2,1,1,175.010131835938,0,2084574624,175.010131835938,,,,,,,,,,,,,,,,,,,,,,,,,,,,,,,,,
,3869978086.98599,206.031448364258,26.2300281524658,0.000116485239022816,5.88807711004805E-8,1,5,14.0008964538574,4.99071133220861,39.7000014781952,0.134942842053427,0.0203419891119422,1,9.89161455453529E-8,,,,,,,,,,,,,,,,,,,,,206.031448364258,206.031448364258,26.2300281524658,26.2300281524658,52.7579709767844,6.10276004152507,7.56172132492065,70,1,0,0,1,0.338211059570313,34.2131004333496,2,1,1,206.031448364258,0,2084574560,206.031448364258,,,,,,,,,,,,,,,,,,,,,,,,,,,,,,,,,
,3869978273.44636,237.030242919922,26.2300281524658,0.000106134709632095,6.8235620279678E-8,1,5,14.0008964538574,4.99033906769703,39.8400016129017,0.122909535778224,0.0187316335018014,1,2.61997817224502E-7,,,,,,,,,,,,,,,,,,,,,237.030242919922,237.030242919922,26.2300281524658,26.2300281524658,52.7493730630729,6.10459969928946,7.87085056304932,68,1,64,0,0,0.338668823242188,34.2131004333496,2,1,1,237.030242919922,0,2084574432,237.030242919922,,,,,,,,,,,,,,,,,,,,,,,,,,,,,,,,,
,3869978460.5219,268.027648925781,26.2300281524658,9.55240034576238E-5,2.57851282620661E-8,1,5,14.0008964538574,4.99022218189385,40.0100015103817,0.110616060726288,0.0168723723142788,1,2.47861910844238E-7,,,,,,,,,,,,,,,,,,,,,268.027648925781,268.027648925781,26.2300281524658,26.2300281524658,52.7720402901306,6.10564278756525,8.45828819274902,68,1,64,0,0,0.338211059570313,34.2131004333496,2,1,1,268.027648925781,0,2084574528,268.027648925781,,,,,,,,,,,,,,,,,,,,,,,,,,,,,,,,,
,3869978658.50774,299.004791259766,26.2300281524658,9.02999742912593E-5,1.38701216113948E-8,1,5,14.0008964538574,4.99019676993414,40.1800014078617,0.10455644583362,0.0160128142230507,1,2.88927237250639E-7,,,,,,,,,,,,,,,,,,,,,299.004791259766,299.004791259766,26.2300281524658,26.2300281524658,52.7638331906787,6.10620946842243,8.46909427642822,70,1,0,0,1,0.336990356445313,31.7693061828613,6,1,1,299.004791259766,0,2084574496,299.004791259766,,,,,,,,,,,,,,,,,,,,,,,,,,,,,,,,,
,3869980265.01294,2.00013244152069,41164.15625,0.0771427800141424,1.84838397015438E-5,1,2,14.0008964538574,4.98022307527963,39.2399989068508,89.1145683634306,13.3563385582213,1000,1.06931630488182E-7,,,,,,,,,,,,,,,,,,,,,2.00000023841858,2.0002646446228,41074.15625,41254.15625,53.4508846590826,6.10380143493427,2.64509105682373,28,1,0,0,1,0.339508056640625,33.2355842590332,1,6,1,1.99975788593292,0,2084574080,2.00013244152069,,,,,,,,,,,,,,,,,,,,,,,,,,,,,,,,,
,3869980327.02174,2.00038290023804,34973.080078125,0.0725497998351668,2.33009642422839E-5,1,2,14.0008964538574,4.98010038576832,39.2399989068508,83.8069526455832,12.5537126054278,1000,-5.93586347980816E-6,,,,,,,,,,,,,,,,,,,,,2.00034594535828,2.0004198551178,34883.15234375,35063.0078125,53.2777539420729,6.10463514129938,2.63629674911499,28,1,0,0,1,0.337982177734375,34.7018585205078,1,6,1,2.00034594535828,0,2084574144,2.00038290023804,,,,,,,,,,,,,,,,,,,,,,,,,,,,,,,,,
,3869980389.025,1.99878370761871,28781.51953125,0.0670920067015253,1.94684017297955E-5,1,2,14.0008964538574,4.97972058910274,39.2399989068508,77.4944234788187,11.6053393872921,1000,-7.85959843656708E-6,,,,,,,,,,,,,,,,,,,,,1.99866759777069,1.99889981746674,28691.6796875,28871.359375,53.1773146773518,6.10546184390784,2.6337890625,28,1,0,0,1,0.33843994140625,33.7243423461914,1,6,1,1.99866759777069,0,2084574304,1.99878370761871,,,,,,,,,,,,,,,,,,,,,,,,,,,,,,,,,
,3869980450.99101,1.99987655878067,22590.6279296875,0.0603098687044282,2.03837292403058E-5,1,2,14.0008964538574,4.9795106495479,39.2399989068508,69.6548295465925,10.4434879617437,1000,3.2520720164955E-6,,,,,,,,,,,,,,,,,,,,,1.99975025653839,2.00000286102295,22501.09765625,22680.158203125,53.1354975515729,6.10619546562089,2.62675070762634,28,1,0,0,1,0.338211059570313,34.7018585205078,1,6,1,1.99975025653839,0,2084574304,1.99987655878067,,,,,,,,,,,,,,,,,,,,,,,,,,,,,,,,,
,3869980512.95532,1.99966776371002,16404.0502929687,0.0515893746250447,2.13830540591831E-5,1,2,14.0008964538574,4.97954156301065,39.2399989068508,59.5821811158129,8.94310208047193,1000,1.11028376394389E-5,,,,,,,,,,,,,,,,,,,,,1.99863791465759,2.00069761276245,16309.1298828125,16498.970703125,52.9635392773421,6.10518764241873,2.61508655548096,28,1,0,0,1,0.338592529296875,33.7243423461914,1,6,1,2.00069761276245,0,2084574208,1.99966776371002,,,,,,,,,,,,,,,,,,,,,,,,,,,,,,,,,
,3869980574.99417,1.99985808134079,10210.5258789062,0.0396225816054238,2.3695142097456E-5,1,2,14.0008964538574,4.97919329768558,39.2399989068508,45.756973207382,6.86726464024831,1000,7.92082087649398E-6,,,,,,,,,,,,,,,,,,,,,1.99969613552094,2.00002002716064,10125.568359375,10295.4833984375,52.8521572133517,6.10636263695379,2.61208271980286,28,1,0,0,1,0.33935546875,35.6793746948242,1,6,1,1.99969613552094,0,2084574144,1.99985808134079,,,,,,,,,,,,,,,,,,,,,,,,,,,,,,,,,
,3869980636.94757,2.0000091791153,4014.76989746094,0.021851338518473,3.58641381283075E-5,1,2,14.0008964538574,4.97919608840097,39.2399989068508,25.2390244760354,3.75632532292707,1000,-2.23751927096718E-5,,,,,,,,,,,,,,,,,,,,,1.99978733062744,2.00023102760315,3919.70776367188,4109.83203125,52.8236277723998,6.10599223521592,2.59826469421387,28,1,0,0,1,0.335617065429687,34.2131004333496,1,6,1,1.99978733062744,0,2084574112,2.0000091791153,,,,,,,,,,,,,,,,,,,,,,,,,,,,,,,,,
,3869980704.0615,2.00005054473877,-2694.34399414062,-0.011995576835307,6.33891170114533E-5,1,2,14.0008964538574,4.97920045206198,39.2399989068508,-13.8474035785176,-2.11482694956943,100,-3.33854344575246E-5,,,,,,,,,,,,,,,,,,,,,2.00005054473877,2.00005054473877,-2699.34399414062,-2689.34399414062,52.8568469844671,6.10604894439424,2.59756398200989,28,1,0,0,1,0.3375244140625,35.190616607666,1,6,1,2.00005054473877,0,2084573888,2.00005054473877,,,,,,,,,,,,,,,,,,,,,,,,,,,,,,,,,
,3869980772.988,2.00005376338959,-9584.38623046875,-0.036926893078608,3.09230747551529E-5,1,2,14.0008964538574,4.97908814760023,39.2399989068508,-42.6323260526228,-6.46890458383977,100,-6.7164390661527E-5,,,,,,,,,,,,,,,,,,,,,2.00003528594971,2.00007224082947,-9669.53515625,-9499.2373046875,52.949469963996,6.10624582460044,2.59040927886963,28,1,0,0,1,0.338211059570313,33.7243423461914,1,6,1,2.00003528594971,0,2084574016,2.00005376338959,,,,,,,,,,,,,,,,,,,,,,,,,,,,,,,,,
,3869980834.95156,2.00007724761963,-15781.7543945313,-0.0499146381529911,2.01985619125244E-5,1,2,14.0008964538574,4.97903898665104,39.2399989068508,-57.6269375977793,-8.73747032672601,100,-8.51373160773737E-5,,,,,,,,,,,,,,,,,,,,,1.99996423721313,2.00019025802612,-15871.93359375,-15691.5751953125,52.9690106769768,6.10688992242001,2.58302664756775,28,1,0,0,1,0.337982177734375,32.7468223571777,1,6,1,1.99996423721313,0,2084574048,2.00007724761963,,,,,,,,,,,,,,,,,,,,,,,,,,,,,,,,,
,3869980905.12377,2.00004190206528,-22808.3056640625,-0.0601160992979749,2.184181312273E-5,1,2,14.0008964538574,4.97914792556876,39.2399989068508,-69.4058247428047,-10.529744709908,100,-0.000107909182110537,,,,,,,,,,,,,,,,,,,,,1.9999932050705,2.00009059906006,-22883.349609375,-22733.26171875,53.096806939871,6.10684685410888,2.5783543586731,28,1,0,0,1,0.337982177734375,33.2355842590332,1,6,1,2.00009059906006,0,2084574176,2.00004190206528,,,,,,,,,,,,,,,,,,,,,,,,,,,,,,,,,
,3869981004.04563,2.00000524520874,-32708.78125,-0.0703329186853636,2.68024112996034E-5,1,2,14.0008964538574,4.97921125215119,39.2399989068508,-81.2159777865998,-12.2322225171724,1000,-5.06657559149326E-5,,,,,,,,,,,,,,,,,,,,,2.00000524520874,2.00000524520874,-32708.78125,-32708.78125,53.3070650115441,6.10793255891223,2.56858944892883,28,1,0,0,1,0.339279174804687,34.2131004333496,1,6,1,2.00000524520874,0,2084574368,2.00000524520874,,,,,,,,,,,,,,,,,,,,,,,,,,,,,,,,,
,3869981080.94615,1.99987858533859,-40414.908203125,-0.0763988544048299,2.62560278191814E-5,1,2,14.0008964538574,4.97900223036294,39.2399989068508,-88.2148242799184,-13.2898549875012,1000,-5.80093390453477E-5,,,,,,,,,,,,,,,,,,,,,1.9997490644455,2.00000810623169,-40505.15625,-40324.66015625,53.5048170269095,6.10902255789752,2.57243084907532,28,1,0,0,1,0.337677001953125,33.7243423461914,1,6,1,2.00000810623169,0,2084574336,1.99987858533859,,,,,,,,,,,,,,,,,,,,,,,,,,,,,,,,,
,3869981142.92633,1.99994510412216,-46627.357421875,-0.0804179773516073,2.94051729948446E-5,1,2,14.0008964538574,4.97884147727578,39.2399989068508,-92.8506164390033,-13.9932266988386,1000,-6.5273638742737E-5,,,,,,,,,,,,,,,,,,,,,1.99967181682587,2.00021839141846,-46717.69140625,-46537.0234375,53.7002241567172,6.10968205497411,2.57128357887268,28,1,0,0,1,0.337371826171875,33.7243423461914,1,6,1,1.99967181682587,0,2084574336,1.99994510412216,,,,,,,,,,,,,,,,,,,,,,,,,,,,,,,,,
,3869981206.925,1.99983531236649,-47556.626953125,-0.0810949076685915,2.08760357087998E-5,1,2,14.0008964538574,4.97866851746988,39.2399989068508,-93.6413637335454,-14.0187433536278,1000,1.34935699361865E-5,,,,,,,,,,,,,,,,,,,,,1.99976432323456,1.99990630149841,-47646.62109375,-47466.6328125,53.7901114364288,6.11073054065208,2.56703400611877,28,1,0,0,1,0.3387451171875,33.2355842590332,1,6,1,1.99976432323456,0,2084574304,1.99983531236649,,,,,,,,,,,,,,,,,,,,,,,,,,,,,,,,,
,3869981268.9289,2.00015640258789,-41366.650390625,-0.0771916131530895,2.65334880706843E-5,1,2,14.0008964538574,4.97859081700285,39.2399989068508,-89.1296834675728,-13.3606610444558,1000,-1.84938987085573E-6,,,,,,,,,,,,,,,,,,,,,2.00011515617371,2.00019764900208,-41456.546875,-41276.75390625,53.6552805168614,6.11062620957858,2.55937194824219,28,1,0,0,1,0.338897705078125,32.7468223571777,1,6,1,2.00019764900208,0,2084574304,2.00015640258789,,,,,,,,,,,,,,,,,,,,,,,,,,,,,,,,,
,3869981330.88946,2.00002896785736,-35176.75,-0.0726528550227647,1.7320940778567E-5,1,2,14.0008964538574,4.97831846714131,39.2399989068508,-83.8818024676414,-12.579064708668,1000,-6.03386020546067E-6,,,,,,,,,,,,,,,,,,,,,1.99991297721863,2.00014495849609,-35266.65234375,-35086.84765625,53.4282174320249,6.11119772881496,2.56042146682739,28,1,0,0,1,0.338516235351562,34.2131004333496,1,6,1,2.00014495849609,0,2084574400,2.00002896785736,,,,,,,,,,,,,,,,,,,,,,,,,,,,,,,,,
,3869981392.88203,1.99990278482437,-28986.6025390625,-0.067176150828152,4.73223570706074E-5,1,2,14.0008964538574,4.97837427970417,39.2399989068508,-77.5508719736067,-11.6909825627722,1000,-5.75175652576997E-5,,,,,,,,,,,,,,,,,,,,,1.99974405765533,2.00006151199341,-29076.552734375,-28896.65234375,53.3090190828422,6.11013480090628,2.5543897151947,28,1,0,0,1,0.338973999023438,34.2131004333496,1,6,1,2.00006151199341,0,2084574240,1.99990278482437,,,,,,,,,,,,,,,,,,,,,,,,,,,,,,,,,
,3869981454.89167,1.99996143579483,-22796.0751953125,-0.0604925753085749,2.49061530532402E-5,1,2,14.0008964538574,4.97855637887574,39.2399989068508,-69.8415013245099,-10.5094257430383,1000,-3.54065003143555E-5,,,,,,,,,,,,,,,,,,,,,1.99985134601593,2.00007152557373,-22885.9453125,-22706.205078125,53.1894299193999,6.10857347621945,2.55919194221497,28,1,0,0,1,0.33966064453125,33.7243423461914,1,6,1,1.99985134601593,0,2084574112,1.99996143579483,,,,,,,,,,,,,,,,,,,,,,,,,,,,,,,,,
,3869981516.9728,2.00008368492126,-16595.9541015625,-0.0518508643439703,2.28281401689176E-5,1,2,14.0008964538574,4.97833283074184,39.2399989068508,-59.8634331188988,-8.98776644851189,1000,-1.32338341657162E-5,,,,,,,,,,,,,,,,,,,,,2.00003910064697,2.00012826919556,-16675.85546875,-16516.052734375,53.0620244707652,6.10866875475508,2.54938387870789,28,1,0,0,1,0.336227416992188,33.7243423461914,1,6,1,2.00012826919556,0,2084574240,2.00008368492126,,,,,,,,,,,,,,,,,,,,,,,,,,,,,,,,,
,3869981578.87715,2.00001412630081,-10412.8876953125,-0.0400408356779241,2.41874796580612E-5,1,2,14.0008964538574,4.9782092041035,39.2399989068508,-46.2280726436588,-6.93174809732639,1000,-2.73571656713824E-6,,,,,,,,,,,,,,,,,,,,,1.99978291988373,2.0002453327179,-10502.9873046875,-10322.7880859375,52.9842524331018,6.10780270184307,2.55312037467957,28,1,0,0,1,0.33935546875,36.6568908691406,1,6,1,1.99978291988373,0,2084574240,2.00001412630081,,,,,,,,,,,,,,,,,,,,,,,,,,,,,,,,,
,3869981640.88098,1.99995166063309,-4217.23071289063,-0.0225617148346563,3.63086625253398E-5,1,2,14.0008964538574,4.97821217396087,39.2399989068508,-26.0524022515268,-3.87674269856233,1000,2.36428743866609E-5,,,,,,,,,,,,,,,,,,,,,1.99985349178314,2.00004982948303,-4307.2373046875,-4127.22412109375,52.8716979263325,6.10709049212322,2.5544764995575,28,1,0,0,1,0.338287353515625,33.7243423461914,1,6,1,1.99985349178314,0,2084574080,1.99995166063309,,,,,,,,,,,,,,,,,,,,,,,,,,,,,,,,,
,3869981702.87822,2.00012582540512,1981.23217773438,0.00881207661793059,5.46549496364262E-5,1,2,14.0008964538574,4.97813416969996,39.2399989068508,10.1651944863474,1.58111356146856,1000,4.87833765212269E-5,,,,,,,,,,,,,,,,,,,,,1.9999293088913,2.00032234191895,1891.18237304687,2071.28198242187,52.9475158926979,6.10695335263142,2.545161485672,26,1,68,0,0,0.336074829101562,33.7243423461914,1,6,1,2.0001060962677,0,2084574016,2.00012582540512,,,,,,,,,,,,,,,,,,,,,,,,,,,,,,,,,
,3869981776.88104,2.00006461143494,9381.73388671875,0.0364385367805287,3.08227398132947E-5,1,2,14.0008964538574,4.97804045869854,39.2399989068508,42.0554185140551,6.38599901245287,100,7.01997114668837E-5,,,,,,,,,,,,,,,,,,,,,1.99987316131592,2.00025606155396,9291.634765625,9471.8330078125,52.9674474199383,6.10760277224466,2.54895639419556,28,1,0,0,1,0.33905029296875,35.6793746948242,1,6,1,1.99987316131592,0,2084574016,2.00006461143494,,,,,,,,,,,,,,,,,,,,,,,,,,,,,,,,,
,3869981846.86391,1.99992561340332,16384.3349609375,0.0509049866090429,2.54991676881312E-5,1,2,14.0008964538574,4.97787651737108,39.2399989068508,58.7512276601115,8.90675891775339,100,8.58290087395783E-5,,,,,,,,,,,,,,,,,,,,,1.9998973608017,1.99995386600494,16294.22265625,16474.447265625,53.1980278331114,6.10781641487646,2.54919338226318,28,1,0,0,1,0.338363647460937,33.2355842590332,1,6,1,1.99995386600494,0,2084574368,1.99992561340332,,,,,,,,,,,,,,,,,,,,,,,,,,,,,,,,,
,3869981925.96464,2.00031018257141,24298.1015625,0.0618632677413714,1.72547490718114E-5,1,2,14.0008964538574,4.97764401040241,39.2399989068508,71.3953644544003,10.8135274039798,100,9.57516634132673E-5,,,,,,,,,,,,,,,,,,,,,2.00031018257141,2.00031018257141,24298.1015625,24298.1015625,53.2660295142845,6.10993959134689,2.54713273048401,28,1,0,0,1,0.338897705078125,33.2355842590332,1,6,1,2.00031018257141,0,2084574272,2.00031018257141,,,,,,,,,,,,,,,,,,,,,,,,,,,,,,,,,
,3869982010.98113,2.00007605552673,32814.62890625,0.0705275137100985,2.3372568523645E-5,1,2,14.0008964538574,4.97733717723142,39.2399989068508,81.3879571277085,12.3244721772546,100,0.000107017808375308,,,,,,,,,,,,,,,,,,,,,2.00006628036499,2.00008583068848,32734.35546875,32894.90234375,53.435252088698,6.11061923094554,2.54622268676758,28,1,0,0,1,0.33782958984375,33.7243423461914,1,6,1,2.00008583068848,0,2084574272,2.00007605552673,,,,,,,,,,,,,,,,,,,,,,,,,,,,,,,,,
,3869982092.86089,2.00006198883057,41022.919921875,0.0768926499781488,1.71119215595509E-5,1,2,14.0008964538574,4.9776853805161,39.2399989068508,88.7566079148791,13.3403659667092,1000,3.20290231386627E-5,,,,,,,,,,,,,,,,,,,,,2.00004053115845,2.00008344650269,40932.671875,41113.16796875,53.7006149709768,6.11010803772311,2.54034996032715,28,1,0,0,1,0.338363647460937,33.7243423461914,1,6,1,2.00004053115845,0,2084574176,2.00006198883057,,,,,,,,,,,,,,,,,,,,,,,,,,,,,,,,,
,3869982154.96254,1.99981963634491,47247.736328125,0.0808514867516362,2.3988884818569E-5,1,2,14.0008964538574,4.97722066434952,39.2399989068508,93.3111451794607,14.0446634216071,1000,5.04019486825292E-5,,,,,,,,,,,,,,,,,,,,,1.99968218803406,1.99995708465576,47167.49609375,47327.9765625,53.7443861680538,6.11263221238923,2.54263591766357,28,1,0,0,1,0.337448120117188,34.2131004333496,1,6,1,1.99995708465576,0,2084574240,1.99981963634491,,,,,,,,,,,,,,,,,,,,,,,,,,,,,,,,,
,3869982593.05981,16.11279296875,26.2176666259766,0.00022396197604358,1.57019659929217E-7,1,5,14.0008964538574,5.00839845745332,39.2399989068508,0.260739515881625,0.0392907153619897,10,1.77986174352495E-7,,,,,,,,,,,,,,,,,,,,,16.11279296875,16.11279296875,26.2176666259766,26.2176666259766,53.0280236301787,6.11026635982339,5.47234010696411,70,1,0,0,1,0.341567993164063,32.2580642700195,2,1,1,16.11279296875,0,2084574560,16.11279296875,,,,,,,,,,,,,,,,,,,,,,,,,,,,,,,,,
,3869982791.30067,47.0207252502441,26.2176666259766,0.000164655256466763,2.88544593485127E-8,1,5,14.0008964538574,5.00850132516757,39.2599999904633,0.191695620589348,0.028911947344967,1,1.52206778721288E-7,,,,,,,,,,,,,,,,,,,,,47.0207252502441,47.0207252502441,26.2176666259766,26.2176666259766,52.9271935511979,6.10977967830828,6.55246686935425,70,1,0,0,1,0.339126586914063,33.2355842590332,2,1,1,47.0207252502441,0,2084574592,47.0207252502441,,,,,,,,,,,,,,,,,,,,,,,,,,,,,,,,,
,3869982986.61147,78.0176010131836,26.2176666259766,0.000150066021367588,2.30357269318334E-8,1,5,14.0008964538574,5.00813330573166,39.3100008368492,0.17469888502909,0.0263051378936763,1,1.02330742067266E-7,,,,,,,,,,,,,,,,,,,,,78.0176010131836,78.0176010131836,26.2176666259766,26.2176666259766,52.9873789471787,6.11273081496414,6.90862798690796,70,1,0,0,1,0.342178344726562,33.2355842590332,2,1,1,78.0176010131836,0,2084574528,78.0176010131836,,,,,,,,,,,,,,,,,,,,,,,,,,,,,,,,,
,3869983171.79369,108.334030151367,26.2176666259766,0.000138766888007408,2.86183895728024E-8,1,5,14.0008964538574,5.00795580378351,39.3700003623962,0.161536693835907,0.0243255472706712,1,9.65538199050734E-8,,,,,,,,,,,,,,,,,,,,,108.018684387207,108.649375915527,26.2176666259766,26.2176666259766,52.9791718477267,6.11323635054805,7.05412530899048,70,1,0,0,1,0.341339111328125,33.7243423461914,2,1,1,108.649375915527,0,2084574528,108.334030151367,,,,,,,,,,,,,,,,,,,,,,,,,,,,,,,,,
,3869983356.99171,139.003356933594,26.2176666259766,0.000130512214734545,2.27202270600626E-8,1,5,14.0008964538574,5.00777801264558,39.4500009715557,0.151918613632125,0.022886619131623,1,9.87425836205536E-8,,,,,,,,,,,,,,,,,,,,,139.003356933594,139.003356933594,26.2176666259766,26.2176666259766,52.9604127632652,6.1145817688436,7.16914939880371,69,1,64,0,0,0.344161987304687,33.7243423461914,2,1,1,139.003356933594,0,2084574432,139.003356933594,,,,,,,,,,,,,,,,,,,,,,,,,,,,,,,,,
,3869983544.46562,170.037414550781,26.2176666259766,0.000120906599146771,5.49523337863473E-8,1,5,14.0008964538574,5.00754703823299,39.5499989390373,0.140738612432302,0.0211328437887004,1,3.30875325932749E-8,,,,,,,,,,,,,,,,,,,,,170.037414550781,170.037414550781,26.2176666259766,26.2176666259766,53.005356403121,6.11639305078649,7.25796318054199,70,1,0,0,1,0.343475341796875,32.7468223571777,2,1,1,170.037414550781,0,2084574464,170.037414550781,,,,,,,,,,,,,,,,,,,,,,,,,,,,,,,,,
,3869983731.09289,201.015594482422,26.2176666259766,0.000111733742299418,1.22442274488533E-7,1,5,14.0008964538574,5.00741291607191,39.6700017154217,0.13005120109714,0.0195627347978215,1,5.97122613510019E-8,,,,,,,,,,,,,,,,,,,,,201.015594482422,201.015594482422,26.2176666259766,26.2176666259766,52.9908962755152,6.11620494292206,7.39131927490234,68,1,64,0,0,0.34271240234375,33.7243423461914,2,1,1,201.015594482422,0,2084574624,201.015594482422,,,,,,,,,,,,,,,,,,,,,,,,,,,,,,,,,
,3869983918.05318,232.003982543945,26.2176666259766,0.000103481209310526,3.54616708727479E-8,1,5,14.0008964538574,5.00697904261589,39.8100018501282,0.120434544839899,0.0180931368271187,1,3.59524137969374E-8,,,,,,,,,,,,,,,,,,,,,232.003982543945,232.003982543945,26.2176666259766,26.2176666259766,52.9553321778902,6.11744831120321,7.69333696365356,68,1,64,0,0,0.344696044921875,34.2131004333496,2,1,1,232.003982543945,0,2084574560,232.003982543945,,,,,,,,,,,,,,,,,,,,,,,,,,,,,,,,,
,3869984104.82193,263.023010253906,26.2176666259766,9.29563774589501E-5,5.59097969166673E-8,1,5,14.0008964538574,5.00670162508652,39.9800017476082,0.108155178624584,0.0163975825215606,1,1.57674152107796E-7,,,,,,,,,,,,,,,,,,,,,263.023010253906,263.023010253906,26.2176666259766,26.2176666259766,52.9615852060441,6.11737284554865,8.30878925323486,68,1,64,0,0,0.34454345703125,33.2355842590332,2,1,1,263.023010253906,0,2084574528,263.023010253906,,,,,,,,,,,,,,,,,,,,,,,,,,,,,,,,,
,3869984291.773,294.004913330078,26.2176666259766,9.02125965612577E-5,4.49613878148405E-8,1,5,14.0008964538574,5.00656732001695,40.1600003242493,0.104957605330516,0.0159212174467496,1,1.60098079876512E-7,,,,,,,,,,,,,,,,,,,,,294.004913330078,294.004913330078,26.2176666259766,26.2176666259766,52.9350098363902,6.11982754718835,8.57901096343994,69,1,64,0,0,0.344161987304687,33.7243423461914,2,1,1,294.004913330078,0,2084574624,294.004913330078,,,,,,,,,,,,,,,,,,,,,,,,,,,,,,,,,
,3869985064.86525,277.984680175781,26.4525241851807,0.000115406400474617,2.26260077499722E-8,1,5,14.0008964538574,4.99551418556101,40.0499999523163,0.133859866972177,0.0202702218403588,1,1.75113930473101E-7,,,,,,,,,,,,,,,,,,,,,277.984680175781,277.984680175781,26.4525241851807,26.4525241851807,52.9514240352941,6.12013522981371,9.25018119812012,68,1,64,0,0,0.345458984375,35.190616607666,2,1,1,277.984680175781,0,2084574720,277.984680175781,,,,,,,,,,,,,,,,,,,,,,,,,,,,,,,,,
,3869985248.39182,246.964340209961,26.4525241851807,0.000112970802217621,1.58019314020745E-8,1,5,14.0008964538574,4.99515885662934,39.9300009012222,0.131044241962429,0.0196905003073583,1,4.21547018730049E-8,,,,,,,,,,,,,,,,,,,,,246.964340209961,246.964340209961,26.4525241851807,26.4525241851807,52.9670566056787,6.12111338886924,9.65750217437744,69,1,64,0,0,0.340118408203125,33.7243423461914,2,1,1,246.964340209961,0,2084574432,246.964340209961,,,,,,,,,,,,,,,,,,,,,,,,,,,,,,,,,
,3869985433.30592,215.936370849609,26.4525241851807,0.000108538305791894,4.84769750089449E-8,1,5,14.0008964538574,4.99519318546841,39.7999994456768,0.125889292490897,0.0190151178834532,1,1.24123597801998E-7,,,,,,,,,,,,,,,,,,,,,215.936370849609,215.936370849609,26.4525241851807,26.4525241851807,52.9561138064094,6.120219917965,9.26480960845947,68,1,64,0,0,0.340728759765625,34.2131004333496,2,1,1,215.936370849609,0,2084574144,215.936370849609,,,,,,,,,,,,,,,,,,,,,,,,,,,,,,,,,
,3869985619.20105,184.998931884766,26.4525241851807,0.000104057189186265,5.8988226345335E-8,1,5,14.0008964538574,4.99438234220897,39.7100001573563,0.120671316905484,0.0181797116901483,1,7.91609282268347E-8,,,,,,,,,,,,,,,,,,,,,184.998931884766,184.998931884766,26.4525241851807,26.4525241851807,52.9510332210345,6.12248891335161,8.94072341918945,70,1,0,0,1,0.339889526367188,32.7468223571777,2,1,1,184.998931884766,0,2084574400,184.998931884766,,,,,,,,,,,,,,,,,,,,,,,,,,,,,,,,,
,3869985805.26101,153.96598815918,26.4525241851807,0.000103408340135249,4.40178452863755E-8,1,5,14.0008964538574,4.99398262432577,39.5999997854233,0.119899904516958,0.0181012033204372,1,1.10466099329061E-7,,,,,,,,,,,,,,,,,,,,,153.96598815918,153.96598815918,26.4525241851807,26.4525241851807,52.8693530407748,6.12164312864449,8.6649923324585,70,1,0,0,1,0.336837768554687,34.2131004333496,2,1,1,153.96598815918,0,2084574560,153.96598815918,,,,,,,,,,,,,,,,,,,,,,,,,,,,,,,,,
,3869985991.79305,122.954223632812,26.4525241851807,0.000103320235096933,1.27797403522859E-8,1,5,14.0008964538574,4.99369979995577,39.5199991762638,0.11979747066249,0.0180228115784365,1,5.73050363684143E-8,,,,,,,,,,,,,,,,,,,,,122.954223632812,122.954223632812,26.4525241851807,26.4525241851807,53.0334950298133,6.12314392017874,8.42548751831055,70,1,0,0,1,0.336990356445313,33.7243423461914,2,1,1,122.954223632812,0,2084574304,122.954223632812,,,,,,,,,,,,,,,,,,,,,,,,,,,,,,,,,
,3869986177.08467,91.9879684448242,26.4525241851807,0.000101772602153477,1.22235880489337E-7,1,5,14.0008964538574,4.99296042475791,39.4299998879433,0.117976826908781,0.0177607189174091,1,6.64108488631537E-8,,,,,,,,,,,,,,,,,,,,,91.9879684448242,91.9879684448242,26.4525241851807,26.4525241851807,53.1354975515729,6.12587570799969,8.17098426818848,68,1,64,0,0,0.336837768554687,34.2131004333496,2,1,1,91.9879684448242,0,2084574048,91.9879684448242,,,,,,,,,,,,,,,,,,,,,,,,,,,,,,,,,
,3869986359.23449,60.9662284851074,26.4525241851807,9.97403424134113E-5,1.32847438494819E-8,1,5,14.0008964538574,4.99264589336699,39.3700003623962,0.115608202678944,0.0174217915924785,1,7.99787153941517E-8,,,,,,,,,,,,,,,,,,,,,60.9662284851074,60.9662284851074,26.4525241851807,26.4525241851807,53.051081671496,6.12875419564161,7.83350706100464,70,1,0,0,1,0.338211059570313,34.2131004333496,2,1,1,60.9662284851074,0,2084574208,60.9662284851074,,,,,,,,,,,,,,,,,,,,,,,,,,,,,,,,,
,3869986540.15986,29.9945602416992,26.4525241851807,9.99105434225522E-5,8.34782996637344E-9,1,5,14.0008964538574,4.99188483511441,39.3100008368492,0.115783929925508,0.0174266268018859,1,6.18507176718876E-8,,,,,,,,,,,,,,,,,,,,,29.9945602416992,29.9945602416992,26.4525241851807,26.4525241851807,52.9979309321883,6.13173020774174,7.20519685745239,70,1,0,0,1,0.338592529296875,33.7243423461914,2,1,1,29.9945602416992,0,2084574208,29.9945602416992,,,,,,,,,,,,,,,,,,,,,,,,,,,,,,,,,
,3869986896.36861,3.25759315490723,26.4525241851807,0.000117573002083335,5.17940920408944E-8,1,5,14.0008964538574,4.99125437844865,39.2599999904633,0.136212577248313,0.020609470471613,1,1.64040242754977E-7,,,,,,,,,,,,,,,,,,,,,3.00784111022949,3.50734519958496,26.4525241851807,26.4525241851807,53.0073104744191,6.13354405193282,3.42779612541199,70,1,0,0,1,0.335235595703125,33.2355842590332,6,1,1,3.50734519958496,0,2084574592,3.25759315490723,,,,,,,,,,,,,,,,,,,,,,,,,,,,,,,,,
,3869987099.17955,34.0328521728516,26.4525241851807,9.99276320126244E-5,3.44268911610529E-8,1,5,14.0008964538574,4.99049716208394,39.2699986696243,0.115760641095418,0.0174094842046559,1,5.03497027191785E-8,,,,,,,,,,,,,,,,,,,,,34.0328521728516,34.0328521728516,26.4525241851807,26.4525241851807,52.9717463767941,6.13441977476543,6.42238712310791,70,1,0,0,1,0.338897705078125,32.7468223571777,2,1,1,34.0328521728516,0,2084574624,34.0328521728516,,,,,,,,,,,,,,,,,,,,,,,,,,,,,,,,,
,3869987296.5149,65.0710830688477,26.4525241851807,0.000100061605398382,6.37249223812087E-8,1,5,14.0008964538574,4.99015126279511,39.2899997532368,0.115903000568145,0.0174417140863334,1,5.955174599488E-8,,,,,,,,,,,,,,,,,,,,,65.0710830688477,65.0710830688477,26.4525241851807,26.4525241851807,53.0577255139095,6.13532912772673,6.95829200744629,69,1,64,0,0,0.338287353515625,34.2131004333496,2,1,1,65.0710830688477,0,2084574592,65.0710830688477,,,,,,,,,,,,,,,,,,,,,,,,,,,,,,,,,
,3869987488.73225,96.0816497802734,26.4525241851807,9.99931616682965E-5,5.30915328000744E-8,1,5,14.0008964538574,4.98994347794608,39.3400005996227,0.115817863885324,0.0174227662293072,1,5.43306487293841E-8,,,,,,,,,,,,,,,,,,,,,96.0594482421875,96.1038513183594,26.4525241851807,26.4525241851807,53.1057956678422,6.13997582881498,7.16005086898804,70,1,0,0,1,0.338134765625,33.7243423461914,2,1,1,96.1038513183594,0,2084574656,96.0816497802734,,,,,,,,,,,,,,,,,,,,,,,,,,,,,,,,,
,3869987676.09207,127.009140014648,26.4525241851807,0.000100260462663842,1.14568362535806E-8,1,5,14.0008964538574,4.99008392761447,39.4099988043308,0.11614110901099,0.0174095639308334,1,2.27829152122992E-9,,,,,,,,,,,,,,,,,,,,,127.009140014648,127.009140014648,26.4525241851807,26.4525241851807,52.9717463767941,6.13884213822482,7.27243614196777,68,1,64,0,0,0.336837768554687,35.6793746948242,2,1,1,127.009140014648,0,2084574528,127.009140014648,,,,,,,,,,,,,,,,,,,,,,,,,,,,,,,,,
,3869987863.45766,158.001007080078,26.4525241851807,0.000100663700175902,2.40372154590591E-8,1,5,14.0008964538574,4.98991426044211,39.5100004971027,0.116604462868466,0.0174667373545272,1,-8.08379847675161E-9,,,,,,,,,,,,,,,,,,,,,158.001007080078,158.001007080078,26.4525241851807,26.4525241851807,53.1605096641883,6.13992862842345,7.35115098953247,69,1,64,0,0,0.336151123046875,32.2580642700195,2,1,1,158.001007080078,0,2084574528,158.001007080078,,,,,,,,,,,,,,,,,,,,,,,,,,,,,,,,,
,3869988050.18191,189.016220092773,26.4525241851807,9.78515390599166E-5,6.31043498125144E-8,1,5,14.0008964538574,4.98978995241553,39.6200008690357,0.113341586737864,0.0169877631434353,1,4.06384790385083E-10,,,,,,,,,,,,,,,,,,,,,189.016220092773,189.016220092773,26.4525241851807,26.4525241851807,53.046001086121,6.14145409151494,7.44338130950928,68,1,64,0,0,0.336532592773438,34.2131004333496,2,1,1,189.016220092773,0,2084574624,189.016220092773,,,,,,,,,,,,,,,,,,,,,,,,,,,,,,,,,
,3869988237.11242,220.036911010742,26.4525241851807,9.52470783270257E-5,1.71932108960017E-8,1,5,14.0008964538574,4.98970521365619,39.7600010037422,0.110316363698152,0.016574229584111,1,3.40782871389698E-8,,,,,,,,,,,,,,,,,,,,,220.036911010742,220.036911010742,26.4525241851807,26.4525241851807,53.1210374239672,6.14075338857275,7.58926916122436,69,1,64,0,0,0.337448120117188,34.2131004333496,2,1,1,220.036911010742,0,2084574400,220.036911010742,,,,,,,,,,,,,,,,,,,,,,,,,,,,,,,,,
,3869988423.5703,251.027084350586,26.4525241851807,9.22473023352574E-5,1.82243280266813E-8,1,5,14.0008964538574,4.9894614660761,39.9099998176098,0.106807185052259,0.0162345348337471,1,1.91358152840188E-7,,,,,,,,,,,,,,,,,,,,,251.027084350586,251.027084350586,26.4525241851807,26.4525241851807,53.0456102718614,6.14432312377211,7.92424440383911,68,1,64,0,0,0.33843994140625,35.6793746948242,2,1,1,251.027084350586,0,2084574592,251.027084350586,,,,,,,,,,,,,,,,,,,,,,,,,,,,,,,,,
,3869988610.78128,282.019012451172,26.4525241851807,9.01577573705057E-5,2.16582320758959E-8,1,5,14.0008964538574,4.98909476803505,40.0899983942509,0.104363237281907,0.0159575711127016,1,2.66817652691661E-7,,,,,,,,,,,,,,,,,,,,,282.019012451172,282.019012451172,26.4525241851807,26.4525241851807,53.1175200956306,6.14674755616999,8.37459754943848,69,1,64,0,0,0.337295532226562,34.2131004333496,2,1,1,282.019012451172,0,2084574624,282.019012451172,,,,,,,,,,,,,,,,,,,,,,,,,,,,,,,,,
,3869989006.87435,300.00325012207,44969.33203125,0.00175664569869093,1.89530078398725E-6,1,2,14.0008964538574,4.97666550155221,40.1900000870228,2.04187596223887,0.206091403888457,100,-8.46968726912995E-5,,,,,,,,,,,,,,,,,,,,,300.003051757812,300.003448486328,44879.375,45059.2890625,53.000275817746,6.15411555411167,8.12940406799316,26,1,68,0,0,0.333938598632812,34.7018585205078,1,6,1,300.003448486328,0,2084574144,300.00325012207,,,,,,,,,,,,,,,,,,,,,,,,,,,,,,,,,
,3869989078.90497,300.002410888672,37774.3203125,0.00157238860633308,2.04119027648281E-6,1,2,14.0008964538574,4.97646241522842,40.1900000870228,1.82449282412178,0.20516841826851,100,-5.78706073397748E-5,,,,,,,,,,,,,,,,,,,,,300.002166748047,300.002655029297,37689.3828125,37859.2578125,53.0405296864864,6.15450226444142,8.21018695831299,28,1,0,0,1,0.335311889648438,34.2131004333496,1,6,1,300.002655029297,0,2084574112,300.002410888672,,,,,,,,,,,,,,,,,,,,,,,,,,,,,,,,,
,3869989140.90697,300.001846313477,31582.59375,0.00141386123916083,1.74708015295927E-6,1,2,14.0008964538574,4.97590816112459,40.1900000870228,1.63986614460568,0.187296223376639,100,-4.95732694281816E-5,,,,,,,,,,,,,,,,,,,,,300.001678466797,300.002014160156,31498.044921875,31667.142578125,53.0909447259768,6.15697765224777,8.31653499603271,26,1,68,0,0,0.333099365234375,33.7243423461914,1,6,1,300.001678466797,0,2084574272,300.001846313477,,,,,,,,,,,,,,,,,,,,,,,,,,,,,,,,,
,3869989218.90333,300.00163269043,23793.5380859375,0.00118692716891192,2.36609433542445E-5,1,2,14.0008964538574,4.97595182855115,40.1900000870228,1.37880148747095,0.143039299310216,100,-5.39206215213134E-5,,,,,,,,,,,,,,,,,,,,,300.001251220703,300.002014160156,23708.642578125,23878.43359375,53.1311985947172,6.15723611828048,8.52118015289307,26,1,68,0,0,0.334930419921875,34.2131004333496,1,6,1,300.001251220703,0,2084574080,300.00163269043,,,,,,,,,,,,,,,,,,,,,,,,,,,,,,,,,
,3869989288.84573,300.001571655273,16808.7861328125,0.00102684760219457,6.14070918033824E-6,1,2,14.0008964538574,4.9756497831921,40.1900000870228,1.19113545694864,0.134459128196079,100,-3.7354912207732E-5,,,,,,,,,,,,,,,,,,,,,300.001525878906,300.001617431641,16718.822265625,16898.75,52.9932411610729,6.1580151887749,8.74036884307861,27,1,68,0,0,0.336074829101562,34.2131004333496,1,6,1,300.001525878906,0,2084574016,300.001571655273,,,,,,,,,,,,,,,,,,,,,,,,,,,,,,,,,
,3869989350.87369,300.001129150391,10610.6884765625,0.000858925661115128,1.93978721248924E-6,1,2,14.0008964538574,4.97524378154436,40.1900000870228,0.996587062513919,0.110096745222372,100,-3.32930686352708E-5,,,,,,,,,,,,,,,,,,,,,300.0009765625,300.001281738281,10525.669921875,10695.70703125,53.0389664294479,6.1608539079401,8.97007465362549,28,1,0,0,1,0.333328247070313,33.2355842590332,1,6,1,300.001251220703,0,2084574272,300.001129150391,,,,,,,,,,,,,,,,,,,,,,,,,,,,,,,,,
,3869989412.85133,300.001281738281,4419.42553710937,0.000661895748104568,4.09037516545883E-6,1,2,14.0008964538574,4.99683383380391,40.1900000870228,0.775640613540572,0.0654320298920127,100,-4.28247479814115E-5,,,,,,,,,,,,,,,,,,,,,300.001251220703,300.001312255859,4329.78369140625,4509.0673828125,53.0862549548614,6.15790447047583,9.19171619415283,28,1,0,0,1,0.340042114257812,34.7018585205078,1,6,1,300.001312255859,0,2084574016,300.001281738281,,,,,,,,,,,,,,,,,,,,,,,,,,,,,,,,,
,3869989474.83627,300.000305175781,-1779.18560791016,-0.00035674094605083,3.07615428267722E-6,1,2,14.0008964538574,4.99682178065064,40.1900000870228,-0.40563001089005,-0.118096483978631,100,-4.82884444294377E-5,,,,,,,,,,,,,,,,,,,,,300.000305175781,300.000305175781,-1868.8583984375,-1689.51281738281,53.1534750075152,6.15876422135546,9.41948699951172,27,1,68,0,0,0.337142944335937,35.6793746948242,1,6,1,300.000305175781,0,2084573984,300.000305175781,,,,,,,,,,,,,,,,,,,,,,,,,,,,,,,,,
,3869989536.81536,300.000442504883,-7979.31713867187,-0.000728077057846295,1.40507916310469E-5,1,2,14.0008964538574,4.99663197823033,40.1900000870228,-0.839709948428636,-0.161622564907548,100,-3.0144602460533E-5,,,,,,,,,,,,,,,,,,,,,300.000305175781,300.000579833984,-8069.37939453125,-7889.2548828125,53.2468796155633,6.15989825565825,9.6423397064209,27,1,68,0,0,0.341262817382812,34.2131004333496,1,6,1,300.000305175781,0,2084573920,300.000442504883,,,,,,,,,,,,,,,,,,,,,,,,,,,,,,,,,
,3869989602.82162,300.000625610352,-14581.3046875,-0.000929866909206559,9.989019816764E-7,1,2,14.0008964538574,4.99677486021374,40.1900000870228,-1.07846182360194,-0.166528948621302,10,-4.12294792731413E-6,,,,,,,,,,,,,,,,,,,,,300.00048828125,300.000762939453,-14671.4228515625,-14491.1865234375,53.1483944221402,6.15912955693711,9.78972816467285,28,1,0,0,1,0.343017578125,35.6793746948242,1,6,1,300.00048828125,0,2084574272,300.000625610352,,,,,,,,,,,,,,,,,,,,,,,,,,,,,,,,,
,3869989702.81163,300.001159667969,-24583.4990234375,-0.00120085562429703,1.03761046622209E-6,1,2,14.0008964538574,4.99619827054416,40.1900000870228,-1.39401781436095,-0.205099697702803,100,3.22922809945572E-6,,,,,,,,,,,,,,,,,,,,,300.001037597656,300.001281738281,-24673.568359375,-24493.4296875,53.1343251087941,6.16166638101321,10.1093254089355,28,1,0,0,1,0.342559814453125,33.7243423461914,1,6,1,300.001281738281,0,2084574144,300.001159667969,,,,,,,,,,,,,,,,,,,,,,,,,,,,,,,,,
,3869989764.79744,300.000595092773,-30789.978515625,-0.00136039347614852,1.20023480408165E-6,1,2,14.0008964538574,4.99594034265213,40.1900000870228,-1.57933352408752,-0.230798377200427,100,4.97922337100556E-6,,,,,,,,,,,,,,,,,,,,,300.000427246094,300.000762939453,-30884.830078125,-30695.126953125,53.1495668649191,6.16264508186388,10.2371292114258,28,1,0,0,1,0.339126586914063,34.2131004333496,1,6,1,300.000762939453,0,2084574016,300.000595092773,,,,,,,,,,,,,,,,,,,,,,,,,,,,,,,,,
,3869989826.799,300.000778198242,-37008.01953125,-0.00152148967069965,1.20121059770151E-6,1,2,14.0008964538574,4.99562922429111,40.1900000870228,-1.76595779352423,-0.259738420827067,100,4.1624836643689E-6,,,,,,,,,,,,,,,,,,,,,300.000427246094,300.001129150391,-37098.25390625,-36917.78515625,53.1057956678422,6.16423983984034,10.3689317703247,28,1,0,0,1,0.34393310546875,34.7018585205078,1,6,1,300.000427246094,0,2084574464,300.000778198242,,,,,,,,,,,,,,,,,,,,,,,,,,,,,,,,,
,3869989896.82809,300.000137329102,-44022.51171875,-0.00172523496006167,2.95813456974664E-5,1,2,14.0008964538574,4.99542262882419,40.1900000870228,-2.00257301743597,-0.292843830107472,100,6.15037495001422E-6,,,,,,,,,,,,,,,,,,,,,300.000122070313,300.000152587891,-44112.78515625,-43932.23828125,53.0315409585152,6.16516894346802,10.3922843933105,27,1,68,0,0,0.342254638671875,33.7243423461914,1,6,1,300.000122070313,0,2084574208,300.000137329102,,,,,,,,,,,,,,,,,,,,,,,,,,,,,,,,,
,3869989974.7945,300.000366210937,-48744.701171875,-0.00187601498829168,5.7415135743437E-6,1,2,14.0008964538574,4.99501128126476,40.1900000870228,-2.19947742164315,-0.170699691596312,100,0.000134016363313483,,,,,,,,,,,,,,,,,,,,,300,300.000732421875,-48834.609375,-48654.79296875,53.1612912927076,6.16686624722544,10.3794527053833,27,1,68,0,0,0.341567993164063,35.190616607666,1,6,1,300,0,2084574464,300.000366210937,,,,,,,,,,,,,,,,,,,,,,,,,,,,,,,,,
,3869990036.80674,300.000854492188,-42559.25390625,-0.0016949133254169,3.12130801795422E-6,1,2,14.0008964538574,4.99502976813799,40.1900000870228,-1.98347471687288,-0.178814116153729,100,9.98790198525906E-5,,,,,,,,,,,,,,,,,,,,,300.000701904297,300.001007080078,-42653.77734375,-42464.73046875,53.0975885683902,6.16730132847851,10.3535032272339,24,1,68,0,0,0.342178344726562,34.2131004333496,1,6,1,300.000701904297,0,2084574240,300.000854492188,,,,,,,,,,,,,,,,,,,,,,,,,,,,,,,,,
,3869990098.78986,300.000961303711,-36369.4765625,-0.00153916291840805,3.3539788178574E-6,1,2,14.0008964538574,4.99439735246594,40.1900000870228,-1.79758182882624,-0.184414698400436,100,7.16793872110343E-5,,,,,,,,,,,,,,,,,,,,,300.000915527344,300.001007080078,-36464.359375,-36274.59375,53.1218190524864,6.16986730012757,10.3356246948242,26,1,68,0,0,0.339431762695313,34.7018585205078,1,6,1,300.001007080078,0,2084574240,300.000961303711,,,,,,,,,,,,,,,,,,,,,,,,,,,,,,,,,
,3869990160.81472,299.999694824219,-30174.771484375,-0.0013810931764093,2.66198017536696E-6,1,2,14.0008964538574,4.99398848880754,40.1900000870228,-1.61178242954144,-0.172165605471476,100,5.85327501252686E-5,,,,,,,,,,,,,,,,,,,,,299.99951171875,299.999877929687,-30264.654296875,-30084.888671875,53.188257476621,6.17086068933536,10.3102407455444,28,1,0,0,1,0.337905883789063,34.2131004333496,1,6,1,299.999877929687,0,2084574272,299.999694824219,,,,,,,,,,,,,,,,,,,,,,,,,,,,,,,,,
,3869990230.90311,300.000198364258,-23175.841796875,-0.00119831969910819,1.21232687058328E-6,1,2,14.0008964538574,4.99355771047074,40.1900000870228,-1.39739796504952,-0.155452967699184,100,4.55346161501214E-5,,,,,,,,,,,,,,,,,,,,,300,300.000396728516,-23255.787109375,-23095.896484375,53.0823468122652,6.17192064364111,10.2977809906006,27,1,68,0,0,0.336151123046875,34.2131004333496,1,6,1,300,0,2084574464,300.000198364258,,,,,,,,,,,,,,,,,,,,,,,,,,,,,,,,,
,3869990292.76566,300.000366210937,-17000.728515625,-0.00103323410390322,2.20557234833223E-6,1,2,14.0008964538574,4.99321368123864,40.1800014078617,-1.20461813647428,-0.135039153438876,100,3.83861538345442E-5,,,,,,,,,,,,,,,,,,,,,300.000366210937,300.000366210937,-17095.6484375,-16905.80859375,53.1960737618133,6.17388989060846,10.2763719558716,28,1,0,0,1,0.3338623046875,34.2131004333496,1,6,1,300.000366210937,0,2084574144,300.000366210937,,,,,,,,,,,,,,,,,,,,,,,,,,,,,,,,,
,3869990354.80923,300.000457763672,-10802.8271484375,-0.000861288719528294,3.5564191128306E-6,1,2,14.0008964538574,4.99250409896284,40.1800014078617,-1.00472340165197,-0.107397860923325,100,3.64377896343029E-5,,,,,,,,,,,,,,,,,,,,,300.000091552734,300.000823974609,-10892.69140625,-10712.962890625,53.1745789775345,6.1763078704015,10.2665214538574,27,1,68,0,0,0.335235595703125,32.2580642700195,1,6,1,300.000823974609,0,2084574176,300.000457763672,,,,,,,,,,,,,,,,,,,,,,,,,,,,,,,,,
,3869990416.74793,300.000244140625,-4611.82421875,-0.000666822615311777,2.92373539876406E-5,1,2,14.0008964538574,4.99236767313028,40.1900000870228,-0.778494839277228,-0.078790824328163,100,3.19677971290463E-5,,,,,,,,,,,,,,,,,,,,,300.000152587891,300.000335693359,-4706.4599609375,-4517.1884765625,53.1382332513902,6.1768447290923,10.2613706588745,26,1,68,0,0,0.336456298828125,34.2131004333496,1,6,1,300.000335693359,0,2084574112,300.000244140625,,,,,,,,,,,,,,,,,,,,,,,,,,,,,,,,,
,3869990494.73853,300.000961303711,3181.29296875,0.000506561652870154,3.15421473363895E-6,1,2,14.0008964538574,4.99187651755072,40.1900000870228,0.581126716716865,0.127814835866442,100,3.43602244811118E-5,,,,,,,,,,,,,,,,,,,,,300.000915527344,300.001007080078,3091.23706054687,3271.34887695313,53.1972462045922,6.17892743255514,10.2423276901245,27,1,68,0,0,0.336532592773438,34.2131004333496,1,6,1,300.000915527344,0,2084573920,300.000961303711,,,,,,,,,,,,,,,,,,,,,,,,,,,,,,,,,
,3869990556.76825,299.999923706055,9391.83837890625,0.000775105794594674,1.06066415280247E-6,1,2,14.0008964538574,4.99176614185406,40.1900000870228,0.895741441538738,0.151739071234543,100,1.47582023349248E-5,,,,,,,,,,,,,,,,,,,,,299.999633789063,300.000213623047,9301.7451171875,9481.931640625,53.2269480883229,6.17942930651269,10.2321805953979,28,1,0,0,1,0.336227416992188,34.2131004333496,1,6,1,299.999633789063,0,2084574112,299.999923706055,,,,,,,,,,,,,,,,,,,,,,,,,,,,,,,,,
,3869990622.73582,300.000259399414,15984.8706054687,0.000975564420785568,9.43886396603609E-7,1,2,14.0008964538574,4.99125928599715,40.1900000870228,1.13001878863506,0.172405223722942,10,2.56711968201998E-6,,,,,,,,,,,,,,,,,,,,,300.000061035156,300.000457763672,15894.7529296875,16074.98828125,53.0565530711306,6.18223677972892,10.2258834838867,28,1,0,0,1,0.339279174804687,34.2131004333496,1,6,1,300.000457763672,0,2084574112,300.000259399414,,,,,,,,,,,,,,,,,,,,,,,,,,,,,,,,,
,3869990712.75172,300.001022338867,24993.24609375,0.00121752774487699,1.29614229563522E-6,1,2,14.0008964538574,4.99049164062466,40.1900000870228,1.41082014830477,0.209558340309864,100,-1.59634901443302E-6,,,,,,,,,,,,,,,,,,,,,300.0009765625,300.001068115234,24898.115234375,25088.376953125,53.0037931460825,6.18520962124804,10.2062463760376,28,1,0,0,1,0.340042114257812,35.6793746948242,1,6,1,300.0009765625,0,2084574240,300.001022338867,,,,,,,,,,,,,,,,,,,,,,,,,,,,,,,,,
,3869990774.71394,300.000549316406,31200.86328125,0.00137546706369382,1.25620594173717E-6,1,2,14.0008964538574,4.99016735024215,40.1900000870228,1.5937527106622,0.236292703435738,100,-2.17313156090175E-6,,,,,,,,,,,,,,,,,,,,,300.000549316406,300.000549316406,31110.5546875,31291.171875,53.1241639380441,6.185863708985,10.1906471252441,28,1,0,0,1,0.3363037109375,33.7243423461914,1,6,1,300.000549316406,0,2084574464,300.000549316406,,,,,,,,,,,,,,,,,,,,,,,,,,,,,,,,,
,3869990860.71508,300.000045776367,39820.369140625,0.00159606515965717,8.49507433871133E-5,1,2,14.0008964538574,4.98944857724902,40.1900000870228,1.83320090070149,0.379457095095389,100,8.84158105604603E-5,,,,,,,,,,,,,,,,,,,,,300.000030517578,300.000061035156,39730.26953125,39910.46875,53.1155660243325,6.1890846708341,10.1810626983643,28,1,0,0,1,0.338211059570313,35.6793746948242,1,6,1,300.000061035156,0,2084574400,300.000045776367,,,,,,,,,,,,,,,,,,,,,,,,,,,,,,,,,
,3869990946.77264,300.000106811523,48450.658203125,0.00180756325752917,1.47686549191875E-6,1,2,14.0008964538574,4.98929242194654,40.1900000870228,2.09382685060497,0.310986728855926,100,-2.38944759832642E-6,,,,,,,,,,,,,,,,,,,,,299.999938964844,300.000274658203,48360.3046875,48541.01171875,53.0635877278037,6.18956348402377,10.1755819320679,28,1,0,0,1,0.336227416992188,34.7018585205078,1,6,1,299.999938964844,0,2084574304,300.000106811523,,,,,,,,,,,,,,,,,,,,,,,,,,,,,,,,,
,3869990965.10808,300.000457763672,50000.21484375,0.00184214803217987,1.14379495512677E-6,1,2,14.0008964538574,4.98891947805838,40.1900000870228,2.13147551607772,0.331514487754461,100,1.0181835058465E-5,,,,,,,,,,,,,,,,,,,,,300.000122070313,300.000793457031,50000.203125,50000.2265625,53.0018390747845,6.19100779798671,10.1703252792358,28,1,0,0,1,0.338516235351562,35.190616607666,1,4,1,300.000122070313,0,2084574368,300.000457763672,,,,,,,,,,,,,,,,,,,,,,,,,,,,,,,,,