File: LT data/Bridport/D2/367-FC-ZFC-RTSIRM-contsweepwithloop-MsT-AC.dat
[Header]
; MPMS3 Data File (default extension .dat)
; Copyright (c) 2007, Quantum Design, Inc. All rights reserved.
TITLE,
FILEOPENTIME,3865775653.75274,06/30/2022,7:31 pm
BYAPP,MPMS3 w/ AC,1.0,1.1
INFO,MPMS3 Measurement Release 1.1.16 Build 424, MultiVu Release 2.3.4.19,APPNAME
INFO,Linear Motor Servo Controller,MOTOR_MODULE_NAME
INFO,3101-100 N2,MOTOR_HW_VERSION
INFO,,MOTOR_SERIAL_NUMBER
INFO,01.04.28,MOTOR_SOFTWARE_VERSION
INFO,Quantum Design Squid Module,SQUID_MODULE_NAME
INFO,3101-501 B0,SQUID_HW_VERSION
INFO,SQM327,SQUID_SERIAL_NUMBER
INFO,01.03.04,SQUID_SOFTWARE_VERSION
INFO,Quantum Design VSM Oven,OVEN_MODULE_NAME
INFO,3101-201 A3,OVEN_HW_VERSION
INFO,OVB365,OVEN_SERIAL_NUMBER
INFO,01.07.07,OVEN_SOFTWARE_VERSION
INFO,SQUID AC,AC_MODULE_NAME
INFO,3101-401 G0,AC_HW_VERSION
INFO,SAC220,AC_SERIAL_NUMBER
INFO,SQUID AC 00.95.07,AC_SOFTWARE_VERSION
INFO,TCI344,COIL_SERIAL_NUMBER
INFO,0,MOMENT_UNITS
INFO,sndst,SAMPLE_MATERIAL
INFO,,SAMPLE_COMMENT
INFO,139.94,SAMPLE_MASS
INFO,,SAMPLE_VOLUME
INFO,,SAMPLE_MOLECULAR_WEIGHT
INFO,,SAMPLE_SIZE
INFO,,SAMPLE_SHAPE
INFO,Straw,SAMPLE_HOLDER
INFO,Standard,SAMPLE_HOLDER_DETAIL
INFO,57.2,SAMPLE_OFFSET
DATATYPE,COMMENT,1
DATATYPE,TIME,2
STARTUPAXIS,X,2
STARTUPAXIS,Y1,5
FIELDGROUP, VSM,2,3,4,5,6,8,9,10,11,14,15
FIELDGROUP, DC, 2,3,4,14,56,57,58,59,60,61,62,63,64,65,66,67,68,69
FIELDGROUP, AC, 2,3,4,11,16,17,18,19,20,21,22,23,24,25,26,27,28,29,30
STARTUPGROUP, All
[Data]
Comment,Time Stamp (sec),Temperature (K),Magnetic Field (Oe),Moment (emu),M. Std. Err. (emu),Transport Action,Averaging Time (sec),Frequency (Hz),Peak Amplitude (mm),Center Position (mm),Lockin Signal' (V),Lockin Signal (V),Range,M. Quad. Signal (emu),AC Moment (emu),AC M. Std Err. (emu),AC Phase (deg),AC Phase Std. Err. (deg),AC Susceptibility (emu/Oe),AC Suscept. Std Err. (emu/Oe),AC X' (emu/Oe),AC X' Std Err. (emu/Oe),AC X'' (emu/Oe),AC X'' Std Err. (emu/Oe),AC Drive (Oe),AC Frequency (Hz),AC Averaging Time (sec),AC Cycles,AC Range,AC Measure Type,AC Signal' (V),AC Signal'' (V),AC Trim Coil Ratio,AC Trim Coil Phase,Min. Temperature (K),Max. Temperature (K),Min. Field (Oe),Max. Field (Oe),Mass (grams),Motor Lag (deg),Pressure (Torr),Measure Count,Measurement Number,SQUID Status (code),Motor Status (code),Measure Status (code),Motor Current (amps),Motor Temp. (C),Temp. Status (code),Field Status (code),Chamber Status (code),Chamber Temp (K),Redirection State,Average Temp (K),Rotation Angle (deg),Rotator state,DC Moment Fixed Ctr (emu),DC Moment Err Fixed Ctr (emu),DC Moment Free Ctr (emu),DC Moment Err Free Ctr (emu),DC Fixed Fit,DC Free Fit,DC Calculated Center (mm),DC Calculated Center Err (mm),DC Scan Length (mm),DC Scan Time (s),DC Number of Points,DC Squid Drift,DC Min V (V),DC Max V (V),DC Scans per Measure,Map 01,Map 02,Map 03,Map 04,Map 05,Map 06,Map 07,Map 08,Map 09,Map 10,Map 11,Map 12,Map 13,Map 14,Map 15,Map 16
,3865776773.52633,100.001220703125,49999.5234375,0.0506647070694248,6.26087796725873E-6,1,2,12.9061126708984,4.98257452748191,43.0100001394749,65.8349023686737,9.6397699955673,100,-2.41816893748029E-5,,,,,,,,,,,,,,,,,,,,,100.001220703125,100.001220703125,49999.5234375,49999.5234375,49.8819688402745,5.40367788537743,7.19489860534668,26,1,0,0,1,0.271835327148438,30.3030319213867,1,1,1,100.001220703125,0,100.001220703125,,,,,,,,,,,,,,,,,,,,,,,,,,,,,,,,,
,3865776869.5266,87.3842124938965,49999.5234375,0.0584276060985958,1.3057210626376E-5,1,2,12.9061126708984,4.98272455408507,42.9700016975403,75.9265510048358,11.1094694539388,100,-3.387928176849E-5,,,,,,,,,,,,,,,,,,,,,87.2196273803711,87.5487976074219,49999.5234375,49999.5234375,49.8358527576399,5.40229374173754,7.13482856750488,26,1,0,0,1,0.270843505859375,30.7917900085449,2,1,1,87.2196273803711,0,87.3842124938965,,,,,,,,,,,,,,,,,,,,,,,,,,,,,,,,,
,3865776956.42921,73.0258331298828,49999.5234375,0.0712732015937493,9.85575697176639E-5,1,2,12.9061126708984,4.98299848505981,42.9299995303154,92.6443720474297,13.4315444561245,100,-0.000134782540205409,,,,,,,,,,,,,,,,,,,,,72.8474426269531,73.2042236328125,49999.5234375,49999.5234375,49.959740877938,5.4018816021455,7.05945444107056,26,1,0,0,1,0.270233154296875,30.7917900085449,2,1,1,72.8474426269531,0,73.0258331298828,,,,,,,,,,,,,,,,,,,,,,,,,,,,,,,,,
,3865777106.53413,47.5250644683838,49999.5234375,0.112630902737871,0.000110065835186583,1,2,12.9061126708984,4.98441008881388,42.8700000047684,146.442215040982,21.3644866564206,1000,-0.000112553847619525,,,,,,,,,,,,,,,,,,,,,47.2444038391113,47.8057250976562,49999.5234375,49999.5234375,49.9534878497841,5.39676716445145,6.85090827941895,26,1,0,0,1,0.270843505859375,30.7917900085449,2,1,1,47.2444038391113,0,47.5250644683838,,,,,,,,,,,,,,,,,,,,,,,,,,,,,,,,,
,3865777177.91701,35.4295558929443,49999.5234375,0.147447383162588,6.80904312545058E-5,1,2,12.9061126708984,4.98482608413585,42.8499989211559,191.740066227727,27.9233837113606,1000,-0.00018470754074517,,,,,,,,,,,,,,,,,,,,,35.3259811401367,35.533130645752,49999.5234375,49999.5234375,50.0465016435726,5.3948751633591,6.65021848678589,26,1,0,0,1,0.267562866210938,31.7693061828613,2,1,1,35.3259811401367,0,35.4295558929443,,,,,,,,,,,,,,,,,,,,,,,,,,,,,,,,,
,3865777246.24974,23.9212312698364,49999.5234375,0.197046846640191,9.19089491967189E-5,1,2,12.9061126708984,4.9848564433687,42.8300015628338,256.214508773519,37.4986611210536,1000,-0.000106951577717119,,,,,,,,,,,,,,,,,,,,,23.7648639678955,24.0775985717773,49999.5234375,49999.5234375,49.9484072644091,5.39501424508294,6.30786991119385,26,1,0,0,1,0.269241333007813,31.7693061828613,2,1,1,23.7648639678955,0,23.9212312698364,,,,,,,,,,,,,,,,,,,,,,,,,,,,,,,,,
,3865777315.04427,12.7470369338989,49999.5234375,0.269546954596713,0.000138504224529253,1,2,12.9061126708984,4.98478145336749,42.8100004792213,350.485056409351,51.2395212645681,1000,-0.000188655099645502,,,,,,,,,,,,,,,,,,,,,12.5765218734741,12.9175519943237,49999.5234375,49999.5234375,50.0953534260245,5.39643823462943,5.41123962402344,26,1,0,0,1,0.268478393554687,31.7693061828613,2,1,1,12.5765218734741,0,12.7470369338989,,,,,,,,,,,,,,,,,,,,,,,,,,,,,,,,,
,3865777382.59461,3.17043077945709,49999.5234375,0.354288437804386,7.59902124433271E-5,1,2,12.9061126708984,4.984823928754,42.8100004792213,460.66629275421,67.4273680298344,1000,-0.000187887568564025,,,,,,,,,,,,,,,,,,,,,2.9597806930542,3.38108086585999,49999.5234375,49999.5234375,50.6776666728515,5.39898334336087,3.36198973655701,26,1,0,0,1,0.267562866210938,31.2805480957031,6,1,1,2.9597806930542,0,3.17043077945709,,,,,,,,,,,,,,,,,,,,,,,,,,,,,,,,,
,3865777451.90131,2.56682872772217,49999.5234375,0.357345520959956,3.31201995761641E-5,1,2,12.9061126708984,4.98463904614454,42.8100004792213,464.620151762162,67.9847380226833,1000,-0.000205587549361128,,,,,,,,,,,,,,,,,,,,,2.56606912612915,2.56758832931519,49999.5234375,49999.5234375,50.7175297273323,5.40119607777581,2.90927171707153,26,1,0,0,1,0.27252197265625,32.2580642700195,6,1,1,2.56758832931519,0,2.56682872772217,,,,,,,,,,,,,,,,,,,,,,,,,,,,,,,,,
,3865777522.25956,2.40884733200073,49999.5234375,0.358207628167619,3.99064289040952E-5,1,2,12.9061126708984,4.98468224519165,42.8100004792213,465.722273984519,68.3160681066177,1000,-7.80283619872902E-5,,,,,,,,,,,,,,,,,,,,,2.40693831443787,2.4107563495636,49999.5234375,49999.5234375,50.6882186578611,5.40173132476722,2.82396101951599,26,1,0,0,1,0.266799926757813,31.2805480957031,6,1,1,2.40693831443787,0,2.40884733200073,,,,,,,,,,,,,,,,,,,,,,,,,,,,,,,,,
,3865777594.79193,2.4863977432251,49999.5234375,0.357901313764123,3.82248664578869E-5,1,2,12.9061126708984,4.98461982235254,42.8100004792213,465.320181792355,68.2268573276635,1000,-0.000100722377511049,,,,,,,,,,,,,,,,,,,,,2.48516917228699,2.48762631416321,49999.5234375,49999.5234375,50.6917359861977,5.40194506700054,2.86115622520447,26,1,0,0,1,0.268020629882813,31.7693061828613,6,1,1,2.48516917228699,0,2.4863977432251,,,,,,,,,,,,,,,,,,,,,,,,,,,,,,,,,
,3865777666.59972,2.00236427783966,49999.5234375,0.360080080273775,0.000232844119076713,1,2,12.9061126708984,4.98456326829134,42.8100004792213,468.108977942669,68.8891017997807,1000,8.94243340794386E-5,,,,,,,,,,,,,,,,,,,,,2.00011444091797,2.00461411476135,49999.5234375,49999.5234375,50.70971344214,5.40269748266533,2.5909960269928,26,1,0,0,1,0.266799926757813,31.7693061828613,5,1,1,2.00461411476135,0,2.00236427783966,,,,,,,,,,,,,,,,,,,,,,,,,,,,,,,,,
,3865778074.71386,8.27020120620728,26.2244052886963,0.00068376519381976,3.87063613456545E-6,1,5,12.9061126708984,4.98386665496796,42.8100004792213,0.888849705167755,0.129971256422947,100,-4.59762514436073E-7,,,,,,,,,,,,,,,,,,,,,8.03004550933838,8.51035690307617,26.2244052886963,26.2244052886963,49.9702928629476,5.39999452366477,4.47017955780029,65,1,0,0,1,0.268096923828125,31.2805480957031,6,1,1,8.51035690307617,0,8.27020120620728,,,,,,,,,,,,,,,,,,,,,,,,,,,,,,,,,
,3865778280.40847,40.0293769836426,26.2244052886963,0.00011146045018116,3.66313879954115E-8,1,5,12.9061126708984,4.9850003550637,42.8199991583824,0.14494533352445,0.0211403562021206,1,-1.15713789354018E-7,,,,,,,,,,,,,,,,,,,,,40.0293769836426,40.0293769836426,26.2244052886963,26.2244052886963,50.0273517448514,5.39486663632798,6.27057695388794,65,1,0,0,1,0.270614624023438,31.2805480957031,2,1,1,40.0293769836426,0,40.0293769836426,,,,,,,,,,,,,,,,,,,,,,,,,,,,,,,,,
,3865778482.47643,72.1013031005859,26.2244052886963,8.01449695704561E-5,2.17904984815811E-8,1,5,12.9061126708984,4.98385748195938,42.8600013256073,0.104188619020717,0.0151952000309321,1,-8.37810643421257E-8,,,,,,,,,,,,,,,,,,,,,72.0766220092773,72.1259841918945,26.2244052886963,26.2244052886963,50.0148456885438,5.39969441943755,6.6459436416626,65,1,0,0,1,0.267715454101562,32.2580642700195,2,1,1,72.1259841918945,0,72.1013031005859,,,,,,,,,,,,,,,,,,,,,,,,,,,,,,,,,
,3865778678.56329,104.055305480957,26.2244052886963,5.9760018304866E-5,1.92770124920602E-8,1,5,12.9061126708984,4.98238210190846,42.909998446703,0.0776555098719339,0.0113277342880352,1,-6.0807941311263E-8,,,,,,,,,,,,,,,,,,,,,104.055305480957,104.055305480957,26.2244052886963,26.2244052886963,50.0504097861688,5.40375053685778,6.83326292037964,64,1,64,0,0,0.271987915039062,31.7693061828613,2,1,1,104.055305480957,0,104.055305480957,,,,,,,,,,,,,,,,,,,,,,,,,,,,,,,,,
,3865778872.3644,136.030578613281,26.2244052886963,4.17981206669619E-5,1.29568960139037E-8,1,5,12.9061126708984,4.98267905082632,42.9899990558624,0.0543209638953832,0.00791276921823227,1,-5.09074531389332E-8,,,,,,,,,,,,,,,,,,,,,136.030578613281,136.030578613281,26.2244052886963,26.2244052886963,50.0097651031687,5.40380756138479,6.92739820480347,65,1,0,0,1,0.272369384765625,31.7693061828613,2,1,1,136.030578613281,0,136.030578613281,,,,,,,,,,,,,,,,,,,,,,,,,,,,,,,,,
,3865779065.59927,168.130996704102,26.2244052886963,3.1500414187152E-5,1.05697309637109E-8,1,5,12.9061126708984,4.98301218743668,43.0900007486343,0.0409415197137734,0.0059663297674078,1,-3.64794217080653E-8,,,,,,,,,,,,,,,,,,,,,168.130996704102,168.130996704102,26.2244052886963,26.2244052886963,50.0336047730053,5.40348927584318,7.00124025344849,65,1,0,0,1,0.2716064453125,32.2580642700195,2,1,1,168.130996704102,0,168.130996704102,,,,,,,,,,,,,,,,,,,,,,,,,,,,,,,,,
,3865779259.00416,200.201507568359,26.2244052886963,2.33661467375892E-5,8.46642373626689E-9,1,5,12.9061126708984,4.98288934772672,43.2199984788895,0.0303683183325966,0.00442503441673373,1,-2.74232169305655E-8,,,,,,,,,,,,,,,,,,,,,200.201507568359,200.201507568359,26.2244052886963,26.2244052886963,50.0672147993322,5.40404419609252,7.07575941085815,65,1,0,0,1,0.2716064453125,31.7693061828613,2,1,1,200.201507568359,0,200.201507568359,,,,,,,,,,,,,,,,,,,,,,,,,,,,,,,,,
,3865779451.49134,232.01904296875,26.2244052886963,1.71780769612794E-5,7.89154282799956E-9,1,5,12.9061126708984,4.98299793540385,43.3700010180473,0.0223260039834026,0.0032569200666954,1,-1.73362274148642E-8,,,,,,,,,,,,,,,,,,,,,232.01904296875,232.01904296875,26.2244052886963,26.2244052886963,50.0730770132265,5.40379459658124,7.2247633934021,63,1,64,0,0,0.27069091796875,31.7693061828613,2,1,1,232.01904296875,0,232.01904296875,,,,,,,,,,,,,,,,,,,,,,,,,,,,,,,,,
,3865779644.23089,264.020843505859,26.2244052886963,1.27383851940425E-5,7.42696575304539E-9,1,5,12.9061126708984,4.98373698963443,43.529998511076,0.0165617936682509,0.00239852819663888,1,-2.60433793220766E-8,,,,,,,,,,,,,,,,,,,,,264.020843505859,264.020843505859,26.2244052886963,26.2244052886963,49.9835805477745,5.40210742676167,7.53779315948486,64,1,64,0,0,0.26885986328125,31.7693061828613,2,1,1,264.020843505859,0,264.020843505859,,,,,,,,,,,,,,,,,,,,,,,,,,,,,,,,,
,3865779837.17476,296.043853759766,26.2244052886963,9.6876250695842E-6,7.63075454025264E-9,1,5,12.9061126708984,4.98404587789153,43.7199994921684,0.0125964639305855,0.00182415339063307,1,-1.98844744014493E-8,,,,,,,,,,,,,,,,,,,,,296.043853759766,296.043853759766,26.2244052886963,26.2244052886963,50.0597893283995,5.40093746070153,7.36235857009888,63,1,64,0,0,0.268707275390625,31.7693061828613,2,1,1,296.043853759766,0,296.043853759766,,,,,,,,,,,,,,,,,,,,,,,,,,,,,,,,,
,3865781447.42927,2.00017213821411,41565.62109375,0.335342354975391,4.72329631632549E-5,1,2,12.9061126708984,4.98308538899003,42.8000018000603,435.768618506764,64.1254992989071,1000,8.00839079694316E-5,,,,,,,,,,,,,,,,,,,,,2.00015735626221,2.00018692016602,41475.81640625,41655.42578125,50.5600315807073,5.40609888867625,2.63071990013123,26,1,0,0,1,0.2716064453125,30.7917900085449,1,6,1,2.00018692016602,0,2.00017213821411,,,,,,,,,,,,,,,,,,,,,,,,,,,,,,,,,
,3865781518.31246,1.99985504150391,34487.298828125,0.310364666935163,4.68272161608769E-5,1,2,12.9061126708984,4.98299905160604,42.8000018000603,403.301203302918,59.3459769318481,1000,7.2776448248985E-5,,,,,,,,,,,,,,,,,,,,,1.99983036518097,1.99987971782684,34427.40234375,34547.1953125,50.4048783196399,5.40503630571454,2.61746668815613,26,1,0,0,1,0.270614624023438,31.2805480957031,1,6,1,1.99987971782684,0,1.99985504150391,,,,,,,,,,,,,,,,,,,,,,,,,,,,,,,,,
,3865781588.6559,2.00017607212067,27468.6796875,0.279916739166841,6.06764130703974E-5,1,2,12.9061126708984,4.9830343744622,42.8000018000603,363.748616199395,53.4622534968403,1000,1.77756539825524E-5,,,,,,,,,,,,,,,,,,,,,2.00015163421631,2.00020051002502,27398.724609375,27538.634765625,50.2934962556495,5.40403204566427,2.6246132850647,26,1,0,0,1,0.270919799804687,31.2805480957031,1,6,1,2.00020051002502,0,2.00017607212067,,,,,,,,,,,,,,,,,,,,,,,,,,,,,,,,,
,3865781656.95381,1.99994766712189,20645.0126953125,0.242878237681327,6.72164543728725E-5,1,2,12.9061126708984,4.98294873434178,42.8000018000603,315.623244699554,46.296071200538,1000,-5.45681955195855E-5,,,,,,,,,,,,,,,,,,,,,1.99978995323181,2.00010538101196,20550.04296875,20739.982421875,50.2172874750245,5.40369425090431,2.61981725692749,26,1,0,0,1,0.269241333007813,31.2805480957031,1,6,1,1.99978995323181,0,1.99994766712189,,,,,,,,,,,,,,,,,,,,,,,,,,,,,,,,,
,3865781728.83316,2.00018727779388,13467.0786132812,0.1906245179643,9.23489860211486E-5,1,2,12.9061126708984,4.9829749787427,42.8000018000603,247.712121283656,36.3946261004052,1000,2.261770537902E-6,,,,,,,,,,,,,,,,,,,,,2.00002646446228,2.00034809112549,13312.4091796875,13621.748046875,49.9980406753803,5.40327468814381,2.61535787582397,26,1,0,0,1,0.2703857421875,30.7917900085449,1,6,1,2.00002646446228,0,2.00018727779388,,,,,,,,,,,,,,,,,,,,,,,,,,,,,,,,,
,3865781798.288,1.99988728761673,6532.23974609375,0.120374310723649,0.000133785870244371,1,2,12.9061126708984,4.98296586840763,42.8000018000603,156.432742336757,22.9173025249176,1000,-4.84967971673475E-5,,,,,,,,,,,,,,,,,,,,,1.99976718425751,2.00000739097595,6417.40771484375,6647.07177734375,49.9734193770245,5.40338992347204,2.61947751045227,26,1,0,0,1,0.27130126953125,31.2805480957031,1,6,1,2.00000739097595,0,1.99988728761673,,,,,,,,,,,,,,,,,,,,,,,,,,,,,,,,,
,3865781878.58332,2.00027334690094,-1492.84814453125,-0.0269757971287,0.000234717110711883,1,2,12.9061126708984,4.98285312665759,42.8000018000603,-35.0507536028909,-5.1668839041084,100,-1.32162663315186E-5,,,,,,,,,,,,,,,,,,,,,2.00011324882507,2.00043344497681,-1587.86767578125,-1397.82861328125,49.9808448479572,5.40284339183302,2.6149468421936,26,1,0,0,1,0.271759033203125,30.7917900085449,1,6,1,2.00043344497681,0,2.00027334690094,,,,,,,,,,,,,,,,,,,,,,,,,,,,,,,,,
,3865781948.37766,1.99975180625916,-8476.02978515625,-0.138049379152603,0.000128541676075637,1,2,12.9061126708984,4.98242003271732,42.8000018000603,-179.340725524607,-26.5102854981516,100,-0.000122931230536866,,,,,,,,,,,,,,,,,,,,,1.99972629547119,1.99977731704712,-8635.96484375,-8316.0947265625,50.0476740863514,5.40440224026631,2.60488796234131,26,1,0,0,1,0.272293090820313,31.2805480957031,1,6,1,1.99977731704712,0,1.99975180625916,,,,,,,,,,,,,,,,,,,,,,,,,,,,,,,,,
,3865782033.6702,1.99970948696136,-17001.7568359375,-0.216721104395666,8.40690059316668E-5,1,2,12.9061126708984,4.98252392176236,42.8000018000603,-281.595340489383,-41.323227681794,1000,3.48149478835083E-5,,,,,,,,,,,,,,,,,,,,,1.99935245513916,2.00006651878357,-17096.857421875,-16906.65625,50.1316991521688,5.40497872741494,2.58708810806274,26,1,0,0,1,0.27191162109375,31.2805480957031,1,6,1,1.99935245513916,0,1.99970948696136,,,,,,,,,,,,,,,,,,,,,,,,,,,,,,,,,
,3865782103.48128,2.0000604391098,-23987.2275390625,-0.261581609663997,6.46746813716253E-5,1,2,12.9061126708984,4.98259046773081,42.8000018000603,-339.870184400613,-50.0193671491768,1000,-6.68344625320604E-5,,,,,,,,,,,,,,,,,,,,,2.00005292892456,2.00006794929504,-24147.212890625,-23827.2421875,50.2067354900149,5.40520787363262,2.56418204307556,26,1,0,0,1,0.27191162109375,30.7917900085449,1,6,1,2.00006794929504,0,2.0000604391098,,,,,,,,,,,,,,,,,,,,,,,,,,,,,,,,,
,3865782174.77574,2.00013720989227,-31127.171875,-0.296103942469727,5.42858116968771E-5,1,2,12.9061126708984,4.98266758290162,42.8000018000603,-384.752702457326,-56.4881491695455,1000,2.72987227191262E-5,,,,,,,,,,,,,,,,,,,,,2.00009250640869,2.00018191337585,-31207.330078125,-31047.013671875,50.2450352874572,5.40567370226706,2.55550837516785,26,1,0,0,1,0.270767211914062,31.7693061828613,1,6,1,2.00009250640869,0,2.00013720989227,,,,,,,,,,,,,,,,,,,,,,,,,,,,,,,,,
,3865782247.62455,2.00013035535812,-38425.5234375,-0.32458880805661,4.1342824275227E-5,1,2,12.9061126708984,4.98275310570912,42.8000018000603,-421.765341711501,-61.9939202387586,1000,-2.40857139575101E-5,,,,,,,,,,,,,,,,,,,,,1.9999121427536,2.00034856796265,-38540.6640625,-38310.3828125,50.4635004585823,5.40611350072629,2.55351376533508,26,1,0,0,1,0.271682739257813,31.7693061828613,1,6,1,2.00034856796265,0,2.00013035535812,,,,,,,,,,,,,,,,,,,,,,,,,,,,,,,,,
,3865782315.68707,1.99422132968903,-45242.564453125,-0.346893496551525,4.3245458243418E-5,1,2,12.9061126708984,4.9827314272923,42.8000018000603,-450.717032748134,-66.4434287996317,1000,-0.000171880807908445,,,,,,,,,,,,,,,,,,,,,1.99330079555511,1.99514186382294,-45332.6953125,-45152.43359375,50.5901242786977,5.40668027719346,2.53884625434875,26,1,0,0,1,0.272140502929687,31.2805480957031,1,6,1,1.99330079555511,0,1.99422132968903,,,,,,,,,,,,,,,,,,,,,,,,,,,,,,,,,
,3865782386.4714,1.99964678287506,-48374.96484375,-0.356218863465613,4.54315690075281E-5,1,2,12.9061126708984,4.98283531594308,42.8000018000603,-462.86579200965,-68.1036625362364,1000,-7.80493513726817E-5,,,,,,,,,,,,,,,,,,,,,1.99945855140686,1.99983501434326,-48444.8125,-48305.1171875,50.6819656297073,5.40702364812489,2.51415395736694,26,1,0,0,1,0.271987915039062,31.7693061828613,1,6,1,1.99983501434326,0,1.99964678287506,,,,,,,,,,,,,,,,,,,,,,,,,,,,,,,,,
,3865782456.81686,1.99967378377914,-41358.669921875,-0.335095138856724,4.26309546518945E-5,1,2,12.9061126708984,4.98275282647024,42.8000018000603,-435.423738669705,-63.9550835820943,1000,1.01189782264255E-5,,,,,,,,,,,,,,,,,,,,,1.9994865655899,1.99986100196838,-41458.33984375,-41259,50.5275939971592,5.40648694209499,2.49490761756897,26,1,0,0,1,0.271453857421875,33.2355842590332,5,6,1,1.99986100196838,0,1.99967378377914,,,,,,,,,,,,,,,,,,,,,,,,,,,,,,,,,
,3865782527.23901,1.99976205825806,-34326.236328125,-0.309954398585552,4.72994488974352E-5,1,2,12.9061126708984,4.98271594087185,42.8000018000603,-402.746581792114,-59.190266269411,1000,-1.6861588179154E-5,,,,,,,,,,,,,,,,,,,,,1.99961864948273,1.99990546703339,-34421.03515625,-34231.4375,50.3427388523611,5.40596255446097,2.48613619804382,26,1,0,0,1,0.271530151367187,31.2805480957031,1,6,1,1.99961864948273,0,1.99976205825806,,,,,,,,,,,,,,,,,,,,,,,,,,,,,,,,,
,3865782599.12928,1.9998659491539,-27150.1201171875,-0.278249576945372,6.38107549363518E-5,1,2,12.9061126708984,4.9826465945394,42.8000018000603,-361.548296182036,-53.0993668418932,1000,1.20818813729222E-5,,,,,,,,,,,,,,,,,,,,,1.99957573413849,2.00015616416931,-27304.947265625,-26995.29296875,50.3247613964188,5.40562597324517,2.49050784111023,26,1,0,0,1,0.271987915039062,31.2805480957031,1,6,1,1.99957573413849,0,1.9998659491539,,,,,,,,,,,,,,,,,,,,,,,,,,,,,,,,,
,3865782668.42242,1.9995573759079,-20237,-0.240581857747889,6.8864958221091E-5,1,2,12.9061126708984,4.98271073511466,42.8000018000603,-312.594873112443,-46.0132837417033,1000,-6.7554298103501E-5,,,,,,,,,,,,,,,,,,,,,1.99946975708008,1.99964499473572,-20346.85546875,-20127.14453125,50.2708290285919,5.40486428904253,2.48520350456238,26,1,0,0,1,0.271759033203125,31.7693061828613,1,6,1,1.99946975708008,0,1.9995573759079,,,,,,,,,,,,,,,,,,,,,,,,,,,,,,,,,
,3865782738.77066,2.00010859966278,-13209.8110351562,-0.188947782911432,9.61127383685012E-5,1,2,12.9061126708984,4.98257927606142,42.8000018000603,-245.509369405643,-36.0464727281896,1000,1.62293265765765E-5,,,,,,,,,,,,,,,,,,,,,1.99983620643616,2.0003809928894,-13299.59765625,-13120.0244140625,50.0351680300438,5.4043133386321,2.49501323699951,26,1,0,0,1,0.272293090820313,31.7693061828613,1,6,1,1.99983620643616,0,2.00010859966278,,,,,,,,,,,,,,,,,,,,,,,,,,,,,,,,,
,3865782811.30626,1.99961680173874,-5961.0693359375,-0.112745447856509,0.000141354901630407,1,2,12.9061126708984,4.98259259306178,42.8000018000603,-146.495198186376,-21.5171703212094,1000,3.4494190583453E-6,,,,,,,,,,,,,,,,,,,,,1.99955439567566,1.99967920780182,-6056.09521484375,-5866.04345703125,50.0508006004284,5.40436012493523,2.49656653404236,26,1,0,0,1,0.271759033203125,31.7693061828613,1,6,1,1.99955439567566,0,1.99961680173874,,,,,,,,,,,,,,,,,,,,,,,,,,,,,,,,,
,3865782898.29168,1.99980020523071,2728.46020507813,0.0513629850185227,0.000203623988236272,1,2,12.9061126708984,4.98235958259741,42.8000018000603,66.7277217569427,9.84346013593587,100,3.04581966085726E-5,,,,,,,,,,,,,,,,,,,,,1.99947333335876,2.00012707710266,2608.62646484375,2848.2939453125,50.0046845177938,5.40462291815111,2.48294830322266,26,1,0,0,1,0.272140502929687,31.2805480957031,5,6,1,2.00012707710266,0,1.99980020523071,,,,,,,,,,,,,,,,,,,,,,,,,,,,,,,,,
,3865782984.67951,2.00009298324585,11368.89453125,0.166698723443823,0.000106914007816987,1,2,12.9061126708984,4.98230964166793,42.8000018000603,216.57728012741,31.8423317504559,1000,1.86527553401592E-5,,,,,,,,,,,,,,,,,,,,,2.00009298324585,2.00009298324585,11368.89453125,11368.89453125,50.0472832720918,5.40524768009014,2.47664046287537,26,1,0,0,1,0.272064208984375,31.7693061828613,1,6,1,2.00009298324585,0,2.00009298324585,,,,,,,,,,,,,,,,,,,,,,,,,,,,,,,,,
,3865783056.3385,1.9997878074646,18535.2138671875,0.22831224955976,7.56091823611225E-5,1,2,12.9061126708984,4.98242628194236,42.8000018000603,296.639890479034,43.5877718623861,1000,6.11997979923676E-6,,,,,,,,,,,,,,,,,,,,,1.99960649013519,1.99996912479401,18370.220703125,18700.20703125,50.1852407057361,5.40504537512257,2.4577751159668,26,1,0,0,1,0.27252197265625,30.7917900085449,6,6,1,1.99960649013519,0,1.9997878074646,,,,,,,,,,,,,,,,,,,,,,,,,,,,,,,,,
,3865783125.82585,2.00026977062225,25486.3994140625,0.269128280826463,5.97790457255243E-5,1,2,12.9061126708984,4.98252099752038,42.8000018000603,349.691308330578,51.3071387517701,1000,-4.99822690478022E-5,,,,,,,,,,,,,,,,,,,,,2.00023460388184,2.00030493736267,25371.423828125,25601.375,50.2141609609476,5.40561289772313,2.46272563934326,26,1,0,0,1,0.272369384765625,31.7693061828613,5,6,1,2.00023460388184,0,2.00026977062225,,,,,,,,,,,,,,,,,,,,,,,,,,,,,,,,,
,3865783196.11242,2.00015330314636,32529.61328125,0.302176766858975,5.05460238579773E-5,1,2,12.9061126708984,4.98260645774952,42.8000018000603,392.621021458591,57.7535124937052,1000,5.51342291025381E-5,,,,,,,,,,,,,,,,,,,,,1.99999165534973,2.00031495094299,32444.326171875,32614.900390625,50.4717075580342,5.4062779064854,2.45080399513245,26,1,0,0,1,0.27099609375,31.7693061828613,1,6,1,2.00031495094299,0,2.00015330314636,,,,,,,,,,,,,,,,,,,,,,,,,,,,,,,,,
,3865783268.60263,1.99981051683426,39790.0390625,0.329393976675416,5.12574527839906E-5,1,2,12.9061126708984,4.98228132625152,42.8000018000603,427.95422424985,62.889167000357,1000,1.35651308222103E-5,,,,,,,,,,,,,,,,,,,,,1.99935042858124,2.00027060508728,39699.875,39880.203125,50.528766439938,5.40751064290182,2.45255756378174,26,1,0,0,1,0.272674560546875,31.2805480957031,1,6,1,2.00027060508728,0,1.99981051683426,,,,,,,,,,,,,,,,,,,,,,,,,,,,,,,,,
,3865783337.49707,2.00004708766937,46699.177734375,0.351003226139433,3.60185349450963E-5,1,2,12.9061126708984,4.98245400386161,42.8000018000603,456.034071246895,67.1370532956863,1000,0.000105967421423264,,,,,,,,,,,,,,,,,,,,,1.99986839294434,2.00022578239441,46584.09375,46814.26171875,50.5553418095919,5.40806452194785,2.45343494415283,26,1,0,0,1,0.272750854492187,31.7693061828613,1,6,1,2.00022578239441,0,2.00004708766937,,,,,,,,,,,,,,,,,,,,,,,,,,,,,,,,,
,3865783858.48495,16.0091876983643,26.4375095367432,0.000186670079176503,3.75595670594657E-7,1,5,12.9061126708984,4.99226649142128,42.8000018000603,0.24322508779877,0.0356214223893234,10,-8.34009155571264E-8,,,,,,,,,,,,,,,,,,,,,16.0091876983643,16.0091876983643,26.4375095367432,26.4375095367432,49.8925208252841,5.40357289470071,5.25883913040161,65,1,0,0,1,0.274658203125,31.7693061828613,2,1,1,16.0091876983643,0,16.0091876983643,,,,,,,,,,,,,,,,,,,,,,,,,,,,,,,,,
,3865784074.98452,50.0238761901855,26.4375095367432,9.16905501427682E-5,2.57078360592635E-8,1,5,12.9061126708984,4.99313875242381,42.8199991583824,0.11950405168313,0.0174675279068302,1,-6.67950095726491E-8,,,,,,,,,,,,,,,,,,,,,50.0238761901855,50.0238761901855,26.4375095367432,26.4375095367432,50.0027304464957,5.40015152340713,6.39173126220703,65,1,0,0,1,0.270614624023438,31.7693061828613,2,1,1,50.0238761901855,0,50.0238761901855,,,,,,,,,,,,,,,,,,,,,,,,,,,,,,,,,
,3865784276.04804,82.0876388549805,26.4375095367432,6.78719437735569E-5,1.80433147287835E-8,1,5,12.9061126708984,4.99215191469754,42.8799986839294,0.0884365671497786,0.0129209106643459,1,-5.36377066832725E-8,,,,,,,,,,,,,,,,,,,,,82.0876388549805,82.0876388549805,26.4375095367432,26.4375095367432,49.9179237521591,5.40478057044154,6.70146465301514,65,1,0,0,1,0.274887084960938,31.7693061828613,2,1,1,82.0876388549805,0,82.0876388549805,,,,,,,,,,,,,,,,,,,,,,,,,,,,,,,,,
,3865784470.69969,114.004173278809,26.4375095367432,5.11934548708107E-5,1.57879002716934E-8,1,5,12.9061126708984,4.99136291632761,42.9399982094765,0.0666927225339196,0.00972406944594311,1,-5.54774911963221E-8,,,,,,,,,,,,,,,,,,,,,114.004173278809,114.004173278809,26.4375095367432,26.4375095367432,50.0636974709957,5.40743601754351,6.85261917114258,64,1,64,0,0,0.27801513671875,31.7693061828613,2,1,1,114.004173278809,0,114.004173278809,,,,,,,,,,,,,,,,,,,,,,,,,,,,,,,,,
,3865784664.10791,146.053298950195,26.4375095367432,3.6997885157198E-5,1.03632424598833E-8,1,5,12.9061126708984,4.99170888524338,43.0199988186359,0.048204373844043,0.00702583984957117,1,-4.20129774322411E-8,,,,,,,,,,,,,,,,,,,,,146.053298950195,146.053298950195,26.4375095367432,26.4375095367432,49.9663847203514,5.40716423102024,6.94292974472046,65,1,0,0,1,0.277557373046875,31.7693061828613,2,1,1,146.053298950195,0,146.053298950195,,,,,,,,,,,,,,,,,,,,,,,,,,,,,,,,,
,3865784857.04788,178.041000366211,26.4375095367432,2.79763279045433E-5,8.9761491457006E-9,1,5,12.9061126708984,4.99251958036264,43.1299991905689,0.0364581330311896,0.00531659312461753,1,-2.96792137726211E-8,,,,,,,,,,,,,,,,,,,,,178.041000366211,178.041000366211,26.4375095367432,26.4375095367432,49.9659939060918,5.40464245659893,7.02416324615479,65,1,0,0,1,0.2734375,31.7693061828613,2,1,1,178.041000366211,0,178.041000366211,,,,,,,,,,,,,,,,,,,,,,,,,,,,,,,,,
,3865785050.59227,210.107009887695,26.4375095367432,2.08515625586607E-5,9.30031585141981E-9,1,5,12.9061126708984,4.99198527507507,43.2600006461143,0.0271686789674626,0.00396567635190345,1,-1.93103895886889E-8,,,,,,,,,,,,,,,,,,,,,210.107009887695,210.107009887695,26.4375095367432,26.4375095367432,49.9519245927457,5.40629601402626,7.12195777893066,64,1,64,0,0,0.27496337890625,31.2805480957031,2,1,1,210.107009887695,0,210.107009887695,,,,,,,,,,,,,,,,,,,,,,,,,,,,,,,,,
,3865785244.01549,242.148254394531,26.4375095367432,1.56392430831071E-5,8.49820230186345E-9,1,5,12.9061126708984,4.99238482092548,43.4099994599819,0.0203810459567827,0.00296445773049739,1,-2.23441750045356E-8,,,,,,,,,,,,,,,,,,,,,242.148254394531,242.148254394531,26.4375095367432,26.4375095367432,49.9390277221784,5.40508664306083,7.33323764801025,64,1,64,0,0,0.272979736328125,31.2805480957031,2,1,1,242.148254394531,0,242.148254394531,,,,,,,,,,,,,,,,,,,,,,,,,,,,,,,,,
,3865785435.87655,274.026824951172,26.4375095367432,1.18976702350767E-5,7.16220360281138E-9,1,5,12.9061126708984,4.99316216322217,43.5900017619133,0.0155074244841922,0.0022624901274381,1,-1.18079532580886E-8,,,,,,,,,,,,,,,,,,,,,274.026824951172,274.026824951172,26.4375095367432,26.4375095367432,49.8991646676976,5.40212084670533,7.57573413848877,63,1,64,0,0,0.273208618164062,31.7693061828613,2,1,1,274.026824951172,0,274.026824951172,,,,,,,,,,,,,,,,,,,,,,,,,,,,,,,,,
,3865786235.75994,295.999786376953,26.4124393463135,1.24971278725003E-5,6.86897400407524E-9,1,5,12.9061126708984,4.99405400558673,43.7100008130074,0.0162916952280747,0.00238485707766834,1,-6.43655970716876E-9,,,,,,,,,,,,,,,,,,,,,295.999786376953,295.999786376953,26.4124393463135,26.4124393463135,49.8839229115726,5.39863447287951,8.0462474822998,64,1,64,0,0,0.2716064453125,30.7917900085449,2,1,1,295.999786376953,0,295.999786376953,,,,,,,,,,,,,,,,,,,,,,,,,,,,,,,,,
,3865786411.5881,263.999237060547,26.4124393463135,1.38607086476358E-5,6.77547301341489E-9,1,5,12.9061126708984,4.99368862118122,43.5599982738495,0.0180701069913996,0.00262673729913664,1,-2.09978284592761E-8,,,,,,,,,,,,,,,,,,,,,263.999237060547,263.999237060547,26.4124393463135,26.4124393463135,49.9687296059091,5.39945621325156,7.85894727706909,64,1,64,0,0,0.271835327148438,31.2805480957031,2,1,1,263.999237060547,0,263.999237060547,,,,,,,,,,,,,,,,,,,,,,,,,,,,,,,,,
,3865786603.14171,231.978286743164,26.4124393463135,1.51788415456027E-5,7.04184787751485E-9,1,5,12.9061126708984,4.99329625474394,43.4099994599819,0.0197854021519491,0.00288278658469572,1,-1.79554678758007E-8,,,,,,,,,,,,,,,,,,,,,231.978286743164,231.978286743164,26.4124393463135,26.4124393463135,49.9163604951207,5.40101425103341,7.73163557052612,63,1,64,0,0,0.272369384765625,31.2805480957031,2,1,1,231.978286743164,0,231.978286743164,,,,,,,,,,,,,,,,,,,,,,,,,,,,,,,,,
,3865786795.77171,199.947280883789,26.4124393463135,1.65666733053431E-5,6.67323625107596E-9,1,5,12.9061126708984,4.99260469547838,43.2999990880489,0.0215909817360846,0.00314061252616152,1,-2.35432959374636E-8,,,,,,,,,,,,,,,,,,,,,199.947280883789,199.947280883789,26.4124393463135,26.4124393463135,49.9249584088322,5.40363759440674,7.61653518676758,65,1,0,0,1,0.272903442382813,31.2805480957031,2,1,1,199.947280883789,0,199.947280883789,,,,,,,,,,,,,,,,,,,,,,,,,,,,,,,,,
,3865786986.98072,167.989974975586,26.4124393463135,1.79928176876231E-5,6.53983608251141E-9,1,5,12.9061126708984,4.99169057843082,43.2000011205673,0.0234436973779041,0.00340958257604881,1,-2.59645836719802E-8,,,,,,,,,,,,,,,,,,,,,167.989974975586,167.989974975586,26.4124393463135,26.4124393463135,49.9999947466784,5.40779024360975,7.52063655853271,64,1,64,0,0,0.277175903320313,32.2580642700195,2,1,1,167.989974975586,0,167.989974975586,,,,,,,,,,,,,,,,,,,,,,,,,,,,,,,,,
,3865787180.46922,135.878356933594,26.4124393463135,1.94035061609055E-5,6.57648446618966E-9,1,5,12.9061126708984,4.99125041969501,43.0999994277954,0.0252786795355131,0.00367606327961599,1,-2.8296234826743E-8,,,,,,,,,,,,,,,,,,,,,135.878356933594,135.878356933594,26.4124393463135,26.4124393463135,49.9624765777553,5.40860497826868,7.42593240737915,65,1,0,0,1,0.277099609375,31.2805480957031,2,1,1,135.878356933594,0,135.878356933594,,,,,,,,,,,,,,,,,,,,,,,,,,,,,,,,,
,3865787371.57526,103.886299133301,26.4124393463135,2.02551790309513E-5,6.67612201574092E-9,1,5,12.9061126708984,4.99207146706134,43.0000014603138,0.026393570652377,0.00384339993038599,1,-2.56246991247873E-8,,,,,,,,,,,,,,,,,,,,,103.886299133301,103.886299133301,26.4124393463135,26.4124393463135,49.9781091481399,5.40333006866861,7.31696939468384,65,1,0,0,1,0.274200439453125,31.2805480957031,2,1,1,103.886299133301,0,103.886299133301,,,,,,,,,,,,,,,,,,,,,,,,,,,,,,,,,
,3865787561.06085,71.9745559692383,26.4124393463135,2.18206895381252E-5,6.49419781046295E-9,1,5,12.9061126708984,4.99253558537318,42.9299995303154,0.0284371025590499,0.00414180620699072,1,-2.69818395699103E-8,,,,,,,,,,,,,,,,,,,,,71.9745559692383,71.9745559692383,26.4124393463135,26.4124393463135,49.9996039324188,5.40240027039733,7.1642484664917,65,1,0,0,1,0.27313232421875,31.2805480957031,2,1,1,71.9745559692383,0,71.9745559692383,,,,,,,,,,,,,,,,,,,,,,,,,,,,,,,,,
,3865787748.70214,39.9783363342285,26.4124393463135,2.33245763303142E-5,5.78481350947078E-9,1,5,12.9061126708984,4.99367746310884,42.8600013256073,0.030407678071058,0.00442233022076251,1,-3.37136375267448E-8,,,,,,,,,,,,,,,,,,,,,39.9783363342285,39.9783363342285,26.4124393463135,26.4124393463135,50.0730770132265,5.39815971033977,6.8390941619873,65,1,0,0,1,0.27130126953125,31.2805480957031,2,1,1,39.9783363342285,0,39.9783363342285,,,,,,,,,,,,,,,,,,,,,,,,,,,,,,,,,
,3865787996.2263,7.89186763763428,26.4124393463135,2.48878347000547E-5,6.34121136634748E-9,1,5,12.9061126708984,4.99343064971279,42.8000018000603,0.0324423200526832,0.00472582068411781,1,-3.02766292390227E-8,,,,,,,,,,,,,,,,,,,,,7.89186763763428,7.89186763763428,26.4124393463135,26.4124393463135,50.0191446453995,5.39982804310308,4.6006908416748,65,1,0,0,1,0.272674560546875,31.2805480957031,6,1,1,7.89186763763428,0,7.89186763763428,,,,,,,,,,,,,,,,,,,,,,,,,,,,,,,,,
,3865788561.45652,26.0531921386719,26.4124393463135,2.33847604950885E-5,1.88960941119983E-8,1,5,12.9061126708984,4.99329607813721,42.8000018000603,0.0304792709014427,0.00445778838009576,1,-1.49846141275775E-8,,,,,,,,,,,,,,,,,,,,,26.0531921386719,26.0531921386719,26.4124393463135,26.4124393463135,50.0066385890918,5.39919049770146,5.90480947494507,65,1,0,0,1,0.272064208984375,31.2805480957031,2,1,1,26.0531921386719,0,26.0531921386719,,,,,,,,,,,,,,,,,,,,,,,,,,,,,,,,,
,3865788765.58959,58.0268249511719,26.4124393463135,2.20250821219743E-5,6.3918647126063E-9,1,5,12.9061126708984,4.99372356300668,42.8300015628338,0.0287116565856987,0.00419148277304406,1,-1.9957258824262E-8,,,,,,,,,,,,,,,,,,,,,58.0268249511719,58.0268249511719,26.4124393463135,26.4124393463135,50.0422026867168,5.39858130228763,6.54175090789795,65,1,0,0,1,0.271530151367187,31.7693061828613,2,1,1,58.0268249511719,0,58.0268249511719,,,,,,,,,,,,,,,,,,,,,,,,,,,,,,,,,
,3865788965.52031,90.0119094848633,26.4124393463135,2.02708839251161E-5,6.58805979021312E-9,1,5,12.9061126708984,4.99291299143465,42.8799986839294,0.0264189425928831,0.00385639848370422,1,-1.86543745756605E-8,,,,,,,,,,,,,,,,,,,,,90.0119094848633,90.0119094848633,26.4124393463135,26.4124393463135,50.0558811858034,5.40129369607799,6.8114972114563,64,1,64,0,0,0.272598266601562,31.7693061828613,2,1,1,90.0119094848633,0,90.0119094848633,,,,,,,,,,,,,,,,,,,,,,,,,,,,,,,,,
,3865789160.24723,122.167331695557,26.4124393463135,1.86936922857496E-5,5.86826805203793E-9,1,5,12.9061126708984,4.99280670558912,42.9500006139278,0.0243634657229598,0.00355081996000927,1,-2.13641029184086E-8,,,,,,,,,,,,,,,,,,,,,122.153106689453,122.18155670166,26.4124393463135,26.4124393463135,50.0339955872649,5.40217096260488,6.93979644775391,65,1,0,0,1,0.2728271484375,31.7693061828613,2,1,1,122.18155670166,0,122.167331695557,,,,,,,,,,,,,,,,,,,,,,,,,,,,,,,,,
,3865789353.87667,154.188034057617,26.4124393463135,1.71395781332044E-5,6.14574626296885E-9,1,5,12.9061126708984,4.99230544410721,43.0499985814095,0.02233531931333,0.00325193338230664,1,-2.206556889957E-8,,,,,,,,,,,,,,,,,,,,,154.188034057617,154.188034057617,26.4124393463135,26.4124393463135,50.0242252307745,5.40428919423742,7.01166486740112,65,1,0,0,1,0.2728271484375,31.7693061828613,2,1,1,154.188034057617,0,154.188034057617,,,,,,,,,,,,,,,,,,,,,,,,,,,,,,,,,
,3865789545.19932,186.008666992187,26.4124393463135,1.55406745519994E-5,6.33035396305432E-9,1,5,12.9061126708984,4.99254549089045,43.1599989533424,0.0202532688477932,0.00294751971689426,1,-2.09654830587162E-8,,,,,,,,,,,,,,,,,,,,,186.008666992187,186.008666992187,26.4124393463135,26.4124393463135,50.0379037298611,5.40406705429189,7.09649801254273,64,1,64,0,0,0.273284912109375,31.2805480957031,2,1,1,186.008666992187,0,186.008666992187,,,,,,,,,,,,,,,,,,,,,,,,,,,,,,,,,
,3865789738.69124,218.016555786133,26.4124393463135,1.39825615755441E-5,6.28713716319182E-9,1,5,12.9061126708984,4.99286157697637,43.2999990880489,0.0182247035811143,0.00264940644533185,1,-2.103484695745E-8,,,,,,,,,,,,,,,,,,,,,218.016555786133,218.016555786133,26.4124393463135,26.4124393463135,49.9972590468611,5.40266861171566,7.20140409469604,63,1,64,0,0,0.2728271484375,32.2580642700195,2,1,1,218.016555786133,0,218.016555786133,,,,,,,,,,,,,,,,,,,,,,,,,,,,,,,,,
,3865789931.00586,250.013626098633,26.4124393463135,1.2512174068252E-5,6.86009350517675E-9,1,5,12.9061126708984,4.99314028630682,43.4600003063679,0.0163075880735082,0.00238396346733167,1,-8.86318971343966E-9,,,,,,,,,,,,,,,,,,,,,250.013626098633,250.013626098633,26.4124393463135,26.4124393463135,49.9519245927457,5.40109346357951,7.38850402832031,64,1,64,0,0,0.27435302734375,31.7693061828613,2,1,1,250.013626098633,0,250.013626098633,,,,,,,,,,,,,,,,,,,,,,,,,,,,,,,,,
,3865790123.69198,282.049926757813,26.4124393463135,1.12158639852791E-5,6.19937552052917E-9,1,5,12.9061126708984,4.99339275599328,43.639998883009,0.0146216953825884,0.00211942604474096,1,-2.15266951129707E-8,,,,,,,,,,,,,,,,,,,,,282.049926757813,282.049926757813,26.4124393463135,26.4124393463135,50.010546731688,5.40057706730542,7.46520280838013,63,1,64,0,0,0.272293090820313,31.7693061828613,2,1,1,282.049926757813,0,282.049926757813,,,,,,,,,,,,,,,,,,,,,,,,,,,,,,,,,
,3865790465.42636,300.006958007812,44051.1796875,0.0126240629238646,3.58317303231209E-6,1,2,12.9061126708984,4.99384369537761,43.7299981713295,16.4606065238375,2.37894624567738,100,-2.9511390429961E-5,,,,,,,,,,,,,,,,,,,,,300.006774902344,300.007141113281,43891.45703125,44210.90234375,49.873370926563,5.39967546204574,7.42844676971436,25,1,68,0,0,0.272750854492187,31.7693061828613,1,6,1,300.006774902344,0,300.006958007812,,,,,,,,,,,,,,,,,,,,,,,,,,,,,,,,,
,3865790537.89633,300.004211425781,36818.080078125,0.0105622600692235,3.44652952717606E-6,1,2,12.9061126708984,4.99397030607893,43.7299981713295,13.7721866550514,1.99395079756044,100,-2.20286797214475E-5,,,,,,,,,,,,,,,,,,,,,300.004028320313,300.00439453125,36653.1171875,36983.04296875,49.9831897335149,5.39928847388727,7.48185729980469,25,1,64,0,0,0.270919799804687,31.2805480957031,1,6,1,300.00439453125,0,300.004211425781,,,,,,,,,,,,,,,,,,,,,,,,,,,,,,,,,
,3865790611.50654,300.003341674805,29469.7197265625,0.00850200571912698,3.70144922753396E-6,1,2,12.9061126708984,4.99383812772967,43.7299981713295,11.0850280956923,1.60747750545404,100,-1.57965494837535E-5,,,,,,,,,,,,,,,,,,,,,300.003234863281,300.003448486328,29414.83203125,29524.607421875,49.9265216658707,5.39969729897649,7.57795715332031,26,1,0,0,1,0.271987915039062,31.7693061828613,1,6,1,300.003448486328,0,300.003341674805,,,,,,,,,,,,,,,,,,,,,,,,,,,,,,,,,
,3865790679.65532,300.004623413086,22666.673828125,0.00655577163974724,3.23453009230981E-6,1,2,12.9061126708984,4.99393596589748,43.7299981713295,8.54802198298486,1.23759688502153,100,-1.36683695711767E-5,,,,,,,,,,,,,,,,,,,,,300.004486083984,300.004760742188,22566.927734375,22766.419921875,49.9214410804957,5.39913166362997,7.69655227661133,26,1,0,0,1,0.27252197265625,31.7693061828613,1,6,1,300.004486083984,0,300.004623413086,,,,,,,,,,,,,,,,,,,,,,,,,,,,,,,,,
,3865790752.20984,300.001174926758,15423.1596679687,0.00449426467069654,3.33823173310269E-6,1,2,12.9061126708984,4.99397919959532,43.7299981713295,5.86075509988686,0.844041842827955,100,-1.27416083700763E-5,,,,,,,,,,,,,,,,,,,,,300.0009765625,300.001373291016,15338.3564453125,15507.962890625,49.964821463313,5.39926337498828,7.86282682418823,26,1,0,0,1,0.272598266601562,29.8142719268799,1,6,1,300.0009765625,0,300.001174926758,,,,,,,,,,,,,,,,,,,,,,,,,,,,,,,,,
,3865790820.84376,300.001678466797,8565.59716796875,0.00254293535952897,3.26216727272194E-6,1,2,12.9061126708984,4.99395049238936,43.7299981713295,3.3168350560054,0.472521532637599,100,-1.10825399345297E-5,,,,,,,,,,,,,,,,,,,,,300.001556396484,300.001800537109,8485.7265625,8645.4677734375,49.9812356622168,5.39944149962057,8.0316047668457,24,1,68,0,0,0.271682739257813,31.7693061828613,1,6,1,300.001556396484,0,300.001678466797,,,,,,,,,,,,,,,,,,,,,,,,,,,,,,,,,
,3865790893.64858,300.001510620117,1290.32971191406,0.00045412993750804,3.33112878792153E-6,1,2,12.9061126708984,4.99376983782296,43.7299981713295,0.596284651500842,0.0573037442624577,100,-2.2752939661957E-5,,,,,,,,,,,,,,,,,,,,,300.001434326172,300.001586914063,1180.22351074219,1400.43591308594,49.926130851611,5.40001246808576,8.21962547302246,25,1,68,0,0,0.273056030273438,31.2805480957031,1,6,1,300.001586914063,0,300.001510620117,,,,,,,,,,,,,,,,,,,,,,,,,,,,,,,,,
,3865790963.71078,299.998626708984,-5716.51928710937,-0.00172372164664867,4.47417338226223E-6,1,2,12.9061126708984,4.99393592387906,43.7299981713295,-2.24651478566176,-0.332435530241568,100,-1.8007337498553E-6,,,,,,,,,,,,,,,,,,,,,299.998474121094,299.998779296875,-5806.474609375,-5626.56396484375,49.9706836772072,5.39953354336112,8.217848777771,26,1,0,0,1,0.270614624023438,30.7917900085449,1,6,1,299.998779296875,0,299.998626708984,,,,,,,,,,,,,,,,,,,,,,,,,,,,,,,,,
,3865791046.33065,300.001449584961,-13981.9702148438,-0.00407859001472218,3.32065263359984E-6,1,2,12.9061126708984,4.99395571230828,43.7299981713295,-5.31689266076346,-0.777992027712468,10,2.3412851616459E-6,,,,,,,,,,,,,,,,,,,,,300.001220703125,300.001678466797,-14066.9482421875,-13896.9921875,49.9855346190726,5.39937745316513,8.14901065826416,24,1,68,0,0,0.271759033203125,31.7693061828613,1,6,1,300.001220703125,0,300.001449584961,,,,,,,,,,,,,,,,,,,,,,,,,,,,,,,,,
,3865791167.27871,300.000885009766,-26073.626953125,-0.00751849463962206,3.42232305080849E-6,1,2,12.9061126708984,4.99386178195881,43.7299981713295,-9.79995299517468,-1.44076612612963,10,-7.85298732276056E-7,,,,,,,,,,,,,,,,,,,,,300.000671386719,300.001098632812,-26178.8125,-25968.44140625,50.0175813883611,5.39908022016082,8.08492660522461,23,1,68,0,0,0.27099609375,31.7693061828613,1,6,1,300.000671386719,0,300.000885009766,,,,,,,,,,,,,,,,,,,,,,,,,,,,,,,,,
,3865791260.04253,300.00065612793,-35370.26171875,-0.010167165044487,3.62567084821017E-6,1,2,12.9061126708984,4.99400378066578,43.7299981713295,-13.2550191219987,-1.93385151633126,100,1.01047145215608E-5,,,,,,,,,,,,,,,,,,,,,300.000579833984,300.000732421875,-35485.609375,-35254.9140625,49.9144064238226,5.39794468797026,8.04670906066895,26,1,0,0,1,0.271072387695313,31.2805480957031,1,6,1,300.000579833984,0,300.00065612793,,,,,,,,,,,,,,,,,,,,,,,,,,,,,,,,,
,3865791330.34652,299.999221801758,-42408.328125,-0.0121767139573753,3.71332580415928E-6,1,2,12.9061126708984,4.99388856708959,43.7299981713295,-15.8739607884529,-2.31879951600508,100,9.95726047204924E-6,,,,,,,,,,,,,,,,,,,,,299.999206542969,299.999237060547,-42498.453125,-42318.203125,49.9194870091976,5.39820353899943,8.03328323364258,26,1,0,0,1,0.271835327148438,32.2580642700195,1,6,1,299.999328613281,0,299.999221801758,,,,,,,,,,,,,,,,,,,,,,,,,,,,,,,,,
,3865791401.19306,299.999984741211,-49510.556640625,-0.0141847698694044,3.64568293334883E-6,1,2,12.9061126708984,4.99383985932937,43.7299981713295,-18.4914231734411,-2.7015070313952,100,1.13289709526857E-5,,,,,,,,,,,,,,,,,,,,,299.999816894531,300.000152587891,-49570.68359375,-49450.4296875,49.8366343861591,5.39804684019148,8.01521682739258,26,1,0,0,1,0.272064208984375,31.2805480957031,1,6,1,300.000152587891,0,299.999984741211,,,,,,,,,,,,,,,,,,,,,,,,,,,,,,,,,
,3865791469.38273,300.001602172852,-44502.578125,-0.0127855870374772,3.75603604877664E-6,1,2,12.9061126708984,4.99397217990928,43.7299981713295,-16.6726639273709,-2.40373030710785,100,3.42935208191781E-5,,,,,,,,,,,,,,,,,,,,,300.001373291016,300.001831054687,-44602.484375,-44402.671875,49.8280364724476,5.39812044564707,8.00076007843018,25,1,68,0,0,0.27130126953125,31.7693061828613,1,6,1,300.001373291016,0,300.001602172852,,,,,,,,,,,,,,,,,,,,,,,,,,,,,,,,,
,3865791541.95338,300.001937866211,-37261.3515625,-0.0107214474355985,3.48140774949174E-6,1,2,12.9061126708984,4.99396300121053,43.7299981713295,-13.9802862279251,-2.02016589200277,100,2.53006477690497E-5,,,,,,,,,,,,,,,,,,,,,300.001892089844,300.001983642578,-37346.32421875,-37176.37890625,49.8534393993226,5.39770383751497,7.98289155960083,26,1,0,0,1,0.271835327148438,31.2805480957031,1,6,1,300.001892089844,0,300.001937866211,,,,,,,,,,,,,,,,,,,,,,,,,,,,,,,,,
,3865791610.64976,300.000610351562,-30403.994140625,-0.00877208706376869,3.83060453830841E-6,1,2,12.9061126708984,4.99372530941596,43.7299981713295,-11.4369299329638,-1.65761450204614,100,1.69695482316004E-5,,,,,,,,,,,,,,,,,,,,,300.000457763672,300.000762939453,-30468.859375,-30339.12890625,49.853048585063,5.39844442810791,7.97676944732666,26,1,0,0,1,0.271453857421875,31.7693061828613,1,6,1,300.000457763672,0,300.000610351562,,,,,,,,,,,,,,,,,,,,,,,,,,,,,,,,,
,3865791680.92412,299.999465942383,-23391.75,-0.00677015609150097,3.5189431788491E-6,1,2,12.9061126708984,4.99371823656471,43.7299981713295,-8.82736306643765,-1.27563167069812,100,1.5924839802202E-5,,,,,,,,,,,,,,,,,,,,,299.999176025391,299.999755859375,-23491.71484375,-23291.78515625,49.9382460936591,5.39921389715922,7.97129583358765,24,1,68,0,0,0.271377563476562,31.7693061828613,1,6,1,299.999176025391,0,299.999465942383,,,,,,,,,,,,,,,,,,,,,,,,,,,,,,,,,
,3865791749.70151,299.99951171875,-16523.9130859375,-0.00481790018074675,3.30171934917514E-6,1,2,12.9061126708984,4.99376924969714,43.7299981713295,-6.28223647414744,-0.906033252758147,100,1.26889036246247E-5,,,,,,,,,,,,,,,,,,,,,299.99951171875,299.99951171875,-16583.876953125,-16463.94921875,49.9913968329668,5.39924341289696,7.96430921554565,26,1,0,0,1,0.270462036132813,31.7693061828613,1,6,1,299.99951171875,0,299.99951171875,,,,,,,,,,,,,,,,,,,,,,,,,,,,,,,,,
,3865791820.10252,300.000274658203,-9488.25830078125,-0.00281138506402176,3.25413091596341E-6,1,2,12.9061126708984,4.99394735607173,43.7299981713295,-3.66672321878007,-0.524149468252914,100,1.09131839976395E-5,,,,,,,,,,,,,,,,,,,,,300.000091552734,300.000457763672,-9603.083984375,-9373.4326171875,50.0042937035341,5.39894449818494,7.95328664779663,26,1,0,0,1,0.272064208984375,31.7693061828613,1,6,1,300.000091552734,0,300.000274658203,,,,,,,,,,,,,,,,,,,,,,,,,,,,,,,,,
,3865791887.63939,299.99951171875,-2743.90393066406,-0.000850452610235066,3.44976376475718E-6,1,2,12.9061126708984,4.99397983765236,43.7299981713295,-1.11154595539579,-0.142624728265633,100,1.55248436371968E-5,,,,,,,,,,,,,,,,,,,,,299.999206542969,299.999816894531,-2908.58984375,-2579.21801757813,49.9812356622168,5.39864310873198,7.94253063201904,24,1,68,0,0,0.272903442382813,31.7693061828613,1,6,1,299.999816894531,0,299.99951171875,,,,,,,,,,,,,,,,,,,,,,,,,,,,,,,,,
,3865791959.04786,300.001083374023,4393.46533203125,0.00132865872020136,2.6348606886282E-5,1,2,12.9061126708984,4.99394582815484,43.7299981713295,1.73524394089307,0.231691190184506,100,-1.74486513945157E-5,,,,,,,,,,,,,,,,,,,,,300.001037597656,300.001129150391,4318.552734375,4468.3779296875,49.9570051781207,5.39893344737628,7.93987226486206,25,1,68,0,0,0.271148681640625,32.2580642700195,1,6,1,300.001037597656,0,300.001083374023,,,,,,,,,,,,,,,,,,,,,,,,,,,,,,,,,
,3865792029.38563,300.001770019531,11428.7827148438,0.00335729814500065,3.15020190587943E-6,1,2,12.9061126708984,4.99387520450121,43.7299981713295,4.37657254849309,0.639965779704788,10,-2.25341793225255E-6,,,,,,,,,,,,,,,,,,,,,300.001708984375,300.001831054687,11338.6708984375,11518.89453125,49.9417634219957,5.39879090383914,7.93112850189209,26,1,0,0,1,0.271987915039062,31.2805480957031,1,6,1,300.001678466797,0,300.001770019531,,,,,,,,,,,,,,,,,,,,,,,,,,,,,,,,,
,3865792152.45604,299.999816894531,23740.896484375,0.0068618279226119,3.64381099266499E-6,1,2,12.9061126708984,4.99389830929262,43.7299981713295,8.94587141656572,1.30298732354961,100,-8.45528539413685E-6,,,,,,,,,,,,,,,,,,,,,299.999694824219,299.999938964844,23670.8984375,23810.89453125,49.9132339810437,5.39833962994389,7.92427778244019,26,1,0,0,1,0.270233154296875,31.7693061828613,1,6,1,299.999694824219,0,299.999816894531,,,,,,,,,,,,,,,,,,,,,,,,,,,,,,,,,
,3865792224.85301,299.998397827148,30986.453125,0.0089310357823293,3.53880865949671E-6,1,2,12.9061126708984,4.99395755547478,43.7299981713295,11.6435695963628,1.6969833213336,100,-1.02014271366182E-5,,,,,,,,,,,,,,,,,,,,,299.998229980469,299.998565673828,30901.298828125,31071.607421875,49.9624765777553,5.39855461776227,7.92926836013794,26,1,0,0,1,0.272750854492187,32.2580642700195,1,6,1,299.998229980469,0,299.998397827148,,,,,,,,,,,,,,,,,,,,,,,,,,,,,,,,,
,3865792291.29567,299.999984741211,37650.712890625,0.0108245997726423,3.57656858878298E-6,1,2,12.9061126708984,4.99391800178488,43.7299981713295,14.1120933155658,2.05673358157372,100,-1.23815241632248E-5,,,,,,,,,,,,,,,,,,,,,299.999877929687,300.000091552734,37555.65625,37745.76953125,49.9175329378995,5.39823001318293,7.9243016242981,26,1,0,0,1,0.271377563476562,32.2580642700195,1,6,1,300.000091552734,0,299.999984741211,,,,,,,,,,,,,,,,,,,,,,,,,,,,,,,,,
,3865792362.109,299.998825073242,44740.140625,0.0128342109683407,3.466523748309E-6,1,2,12.9061126708984,4.99381863381921,43.7299981713295,16.7310187411746,2.44224271022985,100,-1.18108938859694E-5,,,,,,,,,,,,,,,,,,,,,299.99853515625,299.999114990234,44619.92578125,44860.35546875,49.8495312567264,5.39866815147191,7.91361856460571,26,1,0,0,1,0.271987915039062,31.2805480957031,1,6,1,299.999114990234,0,299.998825073242,,,,,,,,,,,,,,,,,,,,,,,,,,,,,,,,,
,3865794658.20553,21.8667697906494,24.7953510284424,,,5,,,,42.8100004792213,,,,,2.26699903272338E-5,1.14686387067744E-8,0.421956475326928,0.00042559315023626,7.55663581128461E-6,3.82286559047116E-9,7.55643089023079E-6,2.06499302344451E-9,5.56505665289049E-8,3.21715792834823E-9,3.00001096961426,10.005763053894,10,100,1,3,0.0792954196737558,0.00837943148142841,0.00380452303215861,254.071800231934,21.8664302825928,21.8674373626709,24.7953510284424,24.7953510284424,,,5.82196092605591,,1,,,,,,1,1,1,21.8668880462646,0,21.86683798736,,,,,,,,,,,,,,,,,,,,,,,,,,,,,,,,,
,3865798995.49636,131.122634887695,24.7953510284424,,,5,,,,42.9800003767014,,,,,2.68634025668918E-6,4.55080742256106E-8,-0.358679939261921,0.0115397979670509,8.95446791431415E-7,1.51693587393016E-8,8.95429245465518E-7,1.11054492959802E-8,-5.60559094743619E-9,1.03333654002962E-8,2.99999986866325,1.00057637691498,19.98847910208,20,1,3,0.00945466400674706,5.55867349269226E-5,0.000413009955082089,253.501930236816,131.077850341797,131.132904052734,24.7953510284424,24.7953510284424,,,6.95071506500244,,1,,,,,,1,1,1,131.127548217773,0,131.119231541952,,,,,,,,,,,,,,,,,,,,,,,,,,,,,,,,,
,3865803282.50337,230.466827392578,24.7953510284424,,,5,,,,43.359998613596,,,,,1.50334183679606E-6,3.56014781274266E-9,0.748822546905841,0.00196963595507383,5.01086399112526E-7,1.18665070320767E-9,5.0104360450995E-7,6.57855401638521E-10,6.54872164890252E-9,9.87606278816751E-10,3.00016492057783,100.057640075684,10,1000,1,3,0.00523126859383006,0.000685100280096445,0.0122873084619641,197.717361450195,230.462112426758,230.471221923828,24.7953510284424,24.7953510284424,,,7.27674913406372,,1,,,,,,1,1,1,230.466171264648,0,230.467277195143,,,,,,,,,,,,,,,,,,,,,,,,,,,,,,,,,
,3865806219.52876,299.998657226562,24.7953510284424,,,5,,,,43.7400005757809,,,,,1.15393811625653E-6,4.34421686960055E-9,0.80412962783449,0.00337059015665952,3.84685132706385E-7,1.44821946640343E-9,3.84647247021693E-7,6.41946830688401E-10,5.39876689274874E-9,1.29816943787741E-9,2.99969512244519,100.057640075684,10,1000,1,3,0.00401523240943797,0.000529445882163171,0.0122889038175344,197.755950927734,299.993011474609,300.004669189453,24.7953510284424,24.7953510284424,,,8.09205722808838,,1,,,,,,1,1,1,299.996673583984,0,299.999445701132,,,,,,,,,,,,,,,,,,,,,,,,,,,,,,,,,