File: LT data/Bridport/D2/367-LT HYS.dat
[Header]
; MPMS3 Data File (default extension .dat)
; Copyright (c) 2007, Quantum Design, Inc. All rights reserved.
TITLE,
FILEOPENTIME,3865775653.75274,06/30/2022,7:31 pm
BYAPP,MPMS3 w/ AC,1.0,1.1
INFO,MPMS3 Measurement Release 1.1.16 Build 424, MultiVu Release 2.3.4.19,APPNAME
INFO,Linear Motor Servo Controller,MOTOR_MODULE_NAME
INFO,3101-100 N2,MOTOR_HW_VERSION
INFO,,MOTOR_SERIAL_NUMBER
INFO,01.04.28,MOTOR_SOFTWARE_VERSION
INFO,Quantum Design Squid Module,SQUID_MODULE_NAME
INFO,3101-501 B0,SQUID_HW_VERSION
INFO,SQM327,SQUID_SERIAL_NUMBER
INFO,01.03.04,SQUID_SOFTWARE_VERSION
INFO,Quantum Design VSM Oven,OVEN_MODULE_NAME
INFO,3101-201 A3,OVEN_HW_VERSION
INFO,OVB365,OVEN_SERIAL_NUMBER
INFO,01.07.07,OVEN_SOFTWARE_VERSION
INFO,SQUID AC,AC_MODULE_NAME
INFO,3101-401 G0,AC_HW_VERSION
INFO,SAC220,AC_SERIAL_NUMBER
INFO,SQUID AC 00.95.07,AC_SOFTWARE_VERSION
INFO,TCI344,COIL_SERIAL_NUMBER
INFO,0,MOMENT_UNITS
INFO,sndst,SAMPLE_MATERIAL
INFO,,SAMPLE_COMMENT
INFO,139.94,SAMPLE_MASS
INFO,,SAMPLE_VOLUME
INFO,,SAMPLE_MOLECULAR_WEIGHT
INFO,,SAMPLE_SIZE
INFO,,SAMPLE_SHAPE
INFO,Straw,SAMPLE_HOLDER
INFO,Standard,SAMPLE_HOLDER_DETAIL
INFO,57.2,SAMPLE_OFFSET
DATATYPE,COMMENT,1
DATATYPE,TIME,2
STARTUPAXIS,X,2
STARTUPAXIS,Y1,5
FIELDGROUP, VSM,2,3,4,5,6,8,9,10,11,14,15
FIELDGROUP, DC, 2,3,4,14,56,57,58,59,60,61,62,63,64,65,66,67,68,69
FIELDGROUP, AC, 2,3,4,11,16,17,18,19,20,21,22,23,24,25,26,27,28,29,30
STARTUPGROUP, All
[Data]
Comment,Time Stamp (sec),Temperature (K),Magnetic Field (Oe),Moment (emu),M. Std. Err. (emu),Transport Action,Averaging Time (sec),Frequency (Hz),Peak Amplitude (mm),Center Position (mm),Lockin Signal' (V),Lockin Signal (V),Range,M. Quad. Signal (emu),AC Moment (emu),AC M. Std Err. (emu),AC Phase (deg),AC Phase Std. Err. (deg),AC Susceptibility (emu/Oe),AC Suscept. Std Err. (emu/Oe),AC X' (emu/Oe),AC X' Std Err. (emu/Oe),AC X'' (emu/Oe),AC X'' Std Err. (emu/Oe),AC Drive (Oe),AC Frequency (Hz),AC Averaging Time (sec),AC Cycles,AC Range,AC Measure Type,AC Signal' (V),AC Signal'' (V),AC Trim Coil Ratio,AC Trim Coil Phase,Min. Temperature (K),Max. Temperature (K),Min. Field (Oe),Max. Field (Oe),Mass (grams),Motor Lag (deg),Pressure (Torr),Measure Count,Measurement Number,SQUID Status (code),Motor Status (code),Measure Status (code),Motor Current (amps),Motor Temp. (C),Temp. Status (code),Field Status (code),Chamber Status (code),Chamber Temp (K),Redirection State,Average Temp (K),Rotation Angle (deg),Rotator state,DC Moment Fixed Ctr (emu),DC Moment Err Fixed Ctr (emu),DC Moment Free Ctr (emu),DC Moment Err Free Ctr (emu),DC Fixed Fit,DC Free Fit,DC Calculated Center (mm),DC Calculated Center Err (mm),DC Scan Length (mm),DC Scan Time (s),DC Number of Points,DC Squid Drift,DC Min V (V),DC Max V (V),DC Scans per Measure,Map 01,Map 02,Map 03,Map 04,Map 05,Map 06,Map 07,Map 08,Map 09,Map 10,Map 11,Map 12,Map 13,Map 14,Map 15,Map 16
,3865781360.38005,1.99987709522247,50000.1875,0.36036750388355,2.67492429018819E-5,1,2,12.9061126708984,4.98362878229118,42.8100004792213,468.4074871121,68.5975481214771,1000,-0.00016316205032611,,,,,,,,,,,,,,,,,,,,,1.99987709522247,1.99987709522247,50000.1875,50000.1875,50.6886094721208,5.40543023943461,2.6223030090332,26,1,0,0,1,0.269393920898438,30.3030319213867,1,4,1,1.99987709522247,0,1.99987709522247,,,,,,,,,,,,,,,,,,,,,,,,,,,,,,,,,
,3865781409.17651,2.00019192695618,45384.259765625,0.347244634874736,5.46838177001382E-5,1,2,12.9061126708984,4.98334219106215,42.8000018000603,451.267556435632,66.4093025404383,1000,8.5229655180438E-5,,,,,,,,,,,,,,,,,,,,,2.00011157989502,2.00027227401733,45289.2734375,45479.24609375,50.6041935920438,5.40575889545118,2.62639760971069,25,1,68,0,0,0.269851684570313,31.2805480957031,1,6,1,2.00011157989502,0,2.00019192695618,,,,,,,,,,,,,,,,,,,,,,,,,,,,,,,,,
,3865781427.26394,2.0001277923584,43577.2578125,0.341752767781078,4.89872519933526E-5,1,2,12.9061126708984,4.98322285475234,42.8000018000603,444.144019401502,65.1631152400621,1000,-6.51583749653926E-5,,,,,,,,,,,,,,,,,,,,,2.00000023841858,2.00025534629822,43482.30859375,43672.20703125,50.5584683236688,5.40586636364246,2.62519931793213,26,1,0,0,1,0.269775390625,30.7917900085449,1,6,1,2.00000023841858,0,2.0001277923584,,,,,,,,,,,,,,,,,,,,,,,,,,,,,,,,,
,3865781447.42927,2.00017213821411,41565.62109375,0.335342354975391,4.72329631632549E-5,1,2,12.9061126708984,4.98308538899003,42.8000018000603,435.768618506764,64.1254992989071,1000,8.00839079694316E-5,,,,,,,,,,,,,,,,,,,,,2.00015735626221,2.00018692016602,41475.81640625,41655.42578125,50.5600315807073,5.40609888867625,2.63071990013123,26,1,0,0,1,0.2716064453125,30.7917900085449,1,6,1,2.00018692016602,0,2.00017213821411,,,,,,,,,,,,,,,,,,,,,,,,,,,,,,,,,
,3865781467.72694,2.00008207559586,39539.103515625,0.328597708028971,4.6395082861157E-5,1,2,12.9061126708984,4.98308884008807,42.8000018000603,427.011159218373,62.79077833618,1000,4.38112767243076E-5,,,,,,,,,,,,,,,,,,,,,1.99999487400055,2.00016927719116,39439.42578125,39638.78125,50.4853860571207,5.40564526494015,2.62711215019226,24,1,68,0,0,0.269927978515625,30.7917900085449,1,6,1,1.99999487400055,0,2.00008207559586,,,,,,,,,,,,,,,,,,,,,,,,,,,,,,,,,
,3865781487.84192,2.00010359287262,37532.544921875,0.321639987002196,5.43811736802154E-5,1,2,12.9061126708984,4.98306630076379,42.8000018000603,417.964246552782,61.479444459388,1000,5.71869810709865E-5,,,,,,,,,,,,,,,,,,,,,2.00004172325134,2.0001654624939,37452.76171875,37612.328125,50.437315903188,5.40570007814254,2.62207555770874,26,1,0,0,1,0.271835327148438,31.2805480957031,1,6,1,2.00004172325134,0,2.00010359287262,,,,,,,,,,,,,,,,,,,,,,,,,,,,,,,,,
,3865781506.26571,2.00006431341171,35690.17578125,0.314991845407112,4.61932386812392E-5,1,2,12.9061126708984,4.98302813509456,42.8000018000603,409.318093721552,60.2259511742955,1000,6.9783217823504E-5,,,,,,,,,,,,,,,,,,,,,1.99996912479401,2.00015950202942,35575.4765625,35804.875,50.3337501243899,5.4051364950342,2.62293696403503,26,1,0,0,1,0.270767211914062,30.7917900085449,1,6,1,2.00015950202942,0,2.00006431341171,,,,,,,,,,,,,,,,,,,,,,,,,,,,,,,,,
,3865781527.30228,1.99991828203201,33588.85546875,0.306386967822378,5.27703044958781E-5,1,2,12.9061126708984,4.98295293136046,42.8000018000603,398.141814662351,58.4853610684199,1000,-4.54376580924441E-6,,,,,,,,,,,,,,,,,,,,,1.99978411197662,2.0000524520874,33429.0078125,33748.703125,50.4009701770438,5.40501936091977,2.62053227424622,26,1,0,0,1,0.271377563476562,30.7917900085449,1,6,1,1.99978411197662,0,1.99991828203201,,,,,,,,,,,,,,,,,,,,,,,,,,,,,,,,,
,3865781546.22395,2.00000721216202,31701.3828125,0.29898806847456,5.69268578030084E-5,1,2,12.9061126708984,4.98296244594803,42.8000018000603,388.539583551984,56.9955491328227,1000,-6.41579063168779E-5,,,,,,,,,,,,,,,,,,,,,1.99977338314056,2.00024104118347,31611.37890625,31791.38671875,50.4599831302457,5.40489507702683,2.62340211868286,26,1,0,0,1,0.27069091796875,30.7917900085449,1,6,1,2.00024104118347,0,2.00000721216202,,,,,,,,,,,,,,,,,,,,,,,,,,,,,,,,,
,3865781566.29721,1.999831199646,29694.720703125,0.290234439527119,6.00607610316641E-5,1,2,12.9061126708984,4.98301539874803,42.8000018000603,377.166743760813,55.3480858476134,1000,-4.65820162638379E-5,,,,,,,,,,,,,,,,,,,,,1.99960541725159,2.00005698204041,29604.921875,29784.51953125,50.3122553401111,5.40469462551282,2.61765718460083,26,1,0,0,1,0.27069091796875,31.7693061828613,1,6,1,1.99960541725159,0,1.999831199646,,,,,,,,,,,,,,,,,,,,,,,,,,,,,,,,,
,3865781586.63657,1.99983417987823,27668.3828125,0.280888136625628,5.80952460409679E-5,1,2,12.9061126708984,4.9830343744622,42.8000018000603,365.011139818607,53.6463976011641,1000,1.67704603695708E-5,,,,,,,,,,,,,,,,,,,,,1.99951243400574,2.00015592575073,27558.626953125,27778.138671875,50.3290603532746,5.40403204566427,2.6148567199707,26,1,0,0,1,0.27099609375,31.2805480957031,1,6,1,2.00015592575073,0,1.99983417987823,,,,,,,,,,,,,,,,,,,,,,,,,,,,,,,,,
,3865781606.73673,2.00001502037048,25661.734375,0.270949185157783,6.3211209351785E-5,1,2,12.9061126708984,4.98297179692936,42.8000018000603,352.084480532111,51.7805067164877,1000,4.17623429411066E-5,,,,,,,,,,,,,,,,,,,,,1.99997806549072,2.00005197525024,25581.70703125,25741.76171875,50.2684841430342,5.40440163784237,2.61907815933228,26,1,0,0,1,0.2703857421875,30.7917900085449,1,6,1,2.00005197525024,0,2.00001502037048,,,,,,,,,,,,,,,,,,,,,,,,,,,,,,,,,
,3865781627.05557,2.00000327825546,23630.1943359375,0.260355516107303,5.91315992967705E-5,1,2,12.9061126708984,4.98299579283804,42.8100004792213,338.317936685906,49.7760987473624,1000,5.53572699753208E-5,,,,,,,,,,,,,,,,,,,,,1.99992954730988,2.00007700920105,23575.3515625,23685.037109375,50.2043906044572,5.40411634892928,2.62203764915466,26,1,0,0,1,0.269927978515625,31.2805480957031,1,6,1,2.00007700920105,0,2.00000327825546,,,,,,,,,,,,,,,,,,,,,,,,,,,,,,,,,
,3865781645.27073,1.9999486207962,21807.88671875,0.250067252304923,6.73720182585164E-5,1,2,12.9061126708984,4.98294519806952,42.8000018000603,324.952289244039,47.7537795205565,1000,1.10954557246493E-5,,,,,,,,,,,,,,,,,,,,,1.99990689754486,1.99999034404755,21758.0078125,21857.765625,50.1899304768515,5.40407947978815,2.61914801597595,26,1,0,0,1,0.271148681640625,31.2805480957031,1,6,1,1.99990689754486,0,1.9999486207962,,,,,,,,,,,,,,,,,,,,,,,,,,,,,,,,,
,3865781663.38388,1.99979704618454,20006.03125,0.239107245062554,6.72313435862745E-5,1,2,12.9061126708984,4.98300175897108,42.8000018000603,310.724882740815,45.5953539333969,1000,-4.03261392264745E-5,,,,,,,,,,,,,,,,,,,,,1.99965643882751,1.99993765354156,19951.15625,20060.90625,50.2622311148803,5.40332782757101,2.61719846725464,26,1,0,0,1,0.271148681640625,31.2805480957031,1,6,1,1.99993765354156,0,1.99979704618454,,,,,,,,,,,,,,,,,,,,,,,,,,,,,,,,,
,3865781682.45309,1.99964469671249,18098.732421875,0.225877580725988,7.62958791052242E-5,1,2,12.9061126708984,4.98306689424334,42.8000018000603,293.531775177399,43.1160786756141,1000,-5.23805972932437E-6,,,,,,,,,,,,,,,,,,,,,1.99951612949371,1.99977326393127,17934.046875,18263.41796875,50.173125463688,5.40356022852288,2.61806154251099,26,1,0,0,1,0.271530151367187,32.2580642700195,1,6,1,1.99977326393127,0,1.99964469671249,,,,,,,,,,,,,,,,,,,,,,,,,,,,,,,,,
,3865781703.34088,2.00002360343933,16017.2705078125,0.211475974277743,7.89553552424662E-5,1,2,12.9061126708984,4.98309463396773,42.8000018000603,274.818900348671,40.3666373552946,1000,-5.47534396106124E-6,,,,,,,,,,,,,,,,,,,,,2.00000381469727,2.0000433921814,15927.2646484375,16107.2763671875,50.1785968633226,5.40303131654557,2.60917735099792,26,1,0,0,1,0.270614624023438,31.2805480957031,1,6,1,2.00000381469727,0,2.00002360343933,,,,,,,,,,,,,,,,,,,,,,,,,,,,,,,,,
,3865781723.51048,1.99966675043106,14000.7431640625,0.195645176555432,8.72154785175317E-5,1,2,12.9061126708984,4.98300616748753,42.8000018000603,254.238884101486,37.3514872095018,1000,7.61356023251759E-7,,,,,,,,,,,,,,,,,,,,,1.99958491325378,1.99974858760834,13900.966796875,14100.51953125,50.0316507017072,5.4031650435401,2.61322069168091,26,1,0,0,1,0.27069091796875,30.7917900085449,1,6,1,1.99958491325378,0,1.99966675043106,,,,,,,,,,,,,,,,,,,,,,,,,,,,,,,,,
,3865781743.92883,2.0000815987587,11968.5581054687,0.17829420247977,9.95019433641138E-5,1,2,12.9061126708984,4.98281575922375,42.8000018000603,231.678661108872,34.0396314224042,1000,2.63568136715175E-6,,,,,,,,,,,,,,,,,,,,,1.99997937679291,2.00018382072449,11853.8203125,12083.2958984375,50.0226619737361,5.40354113933889,2.61967468261719,26,1,0,0,1,0.271072387695313,31.2805480957031,1,6,1,1.99997937679291,0,2.0000815987587,,,,,,,,,,,,,,,,,,,,,,,,,,,,,,,,,
,3865781765.09768,1.99953800439835,9845.36474609375,0.156826014597616,0.000110620926107983,1,2,12.9061126708984,4.98290861639791,42.8000018000603,203.791450888796,29.9172487428123,1000,-1.65328009961308E-5,,,,,,,,,,,,,,,,,,,,,1.99938690662384,1.99968910217285,9685.517578125,10005.2119140625,50.0527546717264,5.40335891037524,2.61617851257324,26,1,0,0,1,0.27130126953125,31.7693061828613,1,6,1,1.99938690662384,0,1.99953800439835,,,,,,,,,,,,,,,,,,,,,,,,,,,,,,,,,
,3865781783.89079,1.99971127510071,7966.91064453125,0.137204709439417,0.000131249261829283,1,2,12.9061126708984,4.98288510780199,42.8000018000603,178.295088187503,26.1589282737363,1000,-2.60437446730979E-5,,,,,,,,,,,,,,,,,,,,,1.99954795837402,1.99987459182739,7876.98681640625,8056.83447265625,50.0328231444861,5.40341235972728,2.61784768104553,24,1,68,0,0,0.271453857421875,31.7693061828613,1,6,1,1.99987459182739,0,1.99971127510071,,,,,,,,,,,,,,,,,,,,,,,,,,,,,,,,,
,3865781804.07937,2,5953.04663085938,0.112665264233068,0.00013968248447696,1,2,12.9061126708984,4.98295725510489,42.8000018000603,146.41166994137,21.4659493744896,1000,-3.27893144293374E-5,,,,,,,,,,,,,,,,,,,,,1.99993133544922,2.00006866455078,5868.01171875,6038.08154296875,50.0121099887264,5.40315800223233,2.61176061630249,26,1,0,0,1,0.27130126953125,31.7693061828613,1,6,1,2.00006866455078,0,2,,,,,,,,,,,,,,,,,,,,,,,,,,,,,,,,,
,3865781822.15147,1.99991798400879,4144.50891113281,0.0875407991922224,0.000162814682215842,1,2,12.9061126708984,4.98299813795014,42.8000018000603,113.76196079302,16.6865238896352,1000,-1.98518926647039E-5,,,,,,,,,,,,,,,,,,,,,1.99985897541046,1.99997699260712,4049.47680664063,4239.541015625,50.0941809832457,5.40300408345038,2.6162748336792,26,1,0,0,1,0.271377563476562,31.2805480957031,1,6,1,1.99985897541046,0,1.99991798400879,,,,,,,,,,,,,,,,,,,,,,,,,,,,,,,,,
,3865781840.26842,2.00004494190216,2335.11291503906,0.0582915106830108,0.000190706308895416,1,2,12.9061126708984,4.9829542131994,42.8000018000603,75.7517969476859,11.1034011624524,1000,-1.91089270656997E-5,,,,,,,,,,,,,,,,,,,,,1.99999690055847,2.00009298324585,2240.01806640625,2430.20776367187,49.9761550768418,5.4027881900964,2.61067652702332,26,1,0,0,1,0.270462036132813,31.7693061828613,1,6,1,2.00009298324585,0,2.00004494190216,,,,,,,,,,,,,,,,,,,,,,,,,,,,,,,,,
,3865781872.65869,1.99990785121918,-903.212707519531,-0.0132147258183793,0.000255391766596849,1,2,12.9061126708984,4.98291673938508,42.8000018000603,-17.1722212353257,-2.52108427044455,100,1.28293286662794E-6,,,,,,,,,,,,,,,,,,,,,1.99979662895203,2.00001907348633,-978.024963378906,-828.400451660156,50.000385560938,5.40306541436339,2.61382126808166,26,1,0,0,1,0.271530151367187,31.7693061828613,1,6,1,2.00001907348633,0,1.99990785121918,,,,,,,,,,,,,,,,,,,,,,,,,,,,,,,,,
,3865781892.97129,2.00012946128845,-2937.13342285156,-0.0551996684541983,0.000196865924125149,1,2,12.9061126708984,4.98285324406323,42.8000018000603,-71.7230546041794,-10.5736974847352,100,-2.77181291873755E-5,,,,,,,,,,,,,,,,,,,,,2.00006341934204,2.00019550323486,-2997.1162109375,-2877.15063476562,49.9437174932937,5.40326527052394,2.6029589176178,26,1,0,0,1,0.271759033203125,30.7917900085449,1,6,1,2.00019550323486,0,2.00012946128845,,,,,,,,,,,,,,,,,,,,,,,,,,,,,,,,,
,3865781911.12252,2.00000965595245,-4746.46069335937,-0.0859995419428393,0.000169686466533035,1,2,12.9061126708984,4.98285074049312,42.8000018000603,-111.739507068059,-16.4934589629222,100,-5.85332178431918E-5,,,,,,,,,,,,,,,,,,,,,2.00000667572021,2.00001263618469,-4806.44970703125,-4686.4716796875,49.9288665514284,5.40336850398664,2.60721611976624,26,1,0,0,1,0.271530151367187,31.7693061828613,1,6,1,2.00001263618469,0,2.00000965595245,,,,,,,,,,,,,,,,,,,,,,,,,,,,,,,,,
,3865781930.91101,2.00001353025436,-6725.55102539063,-0.115223101110173,0.000147992408910482,1,2,12.9061126708984,4.98268011416177,42.8000018000603,-149.69923331926,-22.1198024006038,100,-9.59349780496129E-5,,,,,,,,,,,,,,,,,,,,,1.99999988079071,2.00002717971802,-6815.52490234375,-6635.5771484375,50.0293058161495,5.40358747679997,2.59735655784607,26,1,0,0,1,0.271759033203125,32.7468223571777,1,6,1,1.99999988079071,0,2.00001353025436,,,,,,,,,,,,,,,,,,,,,,,,,,,,,,,,,
,3865781951.05733,1.99999976158142,-8741.1318359375,-0.140456450841607,0.000127921600195473,1,2,12.9061126708984,4.98242003271732,42.8000018000603,-182.469685282184,-26.9594621366021,100,-0.000115019169600191,,,,,,,,,,,,,,,,,,,,,1.99977731704712,2.00022220611572,-8836.2705078125,-8645.9931640625,50.0293058161495,5.40440224026631,2.59621214866638,26,1,0,0,1,0.271987915039062,31.2805480957031,1,6,1,2.00022220611572,0,1.99999976158142,,,,,,,,,,,,,,,,,,,,,,,,,,,,,,,,,
,3865781984.60094,1.9999423623085,-12091.8076171875,-0.176446541480204,0.000103047111879814,1,2,12.9061126708984,4.98251701754485,42.8000018000603,-229.271257735385,-33.5969296305374,1000,6.44357847478555E-5,,,,,,,,,,,,,,,,,,,,,1.99993562698364,1.99994909763336,-12256.625,-11926.990234375,50.0187538311399,5.40443063891647,2.59645295143127,26,1,0,0,1,0.27252197265625,31.7693061828613,1,6,1,1.99994909763336,0,1.9999423623085,,,,,,,,,,,,,,,,,,,,,,,,,,,,,,,,,
,3865782005.48704,2.00001472234726,-14186.6948242187,-0.194331864175885,8.92844190266373E-5,1,2,12.9061126708984,4.9826569434258,42.8000018000603,-252.520111652425,-37.0104271204847,1000,6.59503132745397E-5,,,,,,,,,,,,,,,,,,,,,1.99986946582794,2.00015997886658,-14276.8310546875,-14096.55859375,50.1684356925726,5.40438065264258,2.58622360229492,26,1,0,0,1,0.272216796875,31.7693061828613,1,6,1,2.00015997886658,0,2.00001472234726,,,,,,,,,,,,,,,,,,,,,,,,,,,,,,,,,
,3865782023.60424,2.00008594989777,-15996.4174804687,-0.2090617754083,8.6598680399895E-5,1,2,12.9061126708984,4.98264096104439,42.8000018000603,-271.656360973402,-39.835793921275,1000,5.53718905923882E-5,,,,,,,,,,,,,,,,,,,,,2.00004863739014,2.0001232624054,-16086.5419921875,-15906.29296875,50.1227104241976,5.40476670923256,2.58747315406799,26,1,0,0,1,0.271987915039062,31.2805480957031,1,6,1,2.00004863739014,0,2.00008594989777,,,,,,,,,,,,,,,,,,,,,,,,,,,,,,,,,
,3865782043.77273,2.0000017285347,-18016.5419921875,-0.223966121718132,7.52432004567066E-5,1,2,12.9061126708984,4.98259508352036,42.8000018000603,-291.010653957354,-42.7347939050187,1000,1.34537562930888E-5,,,,,,,,,,,,,,,,,,,,,1.9999293088913,2.0000741481781,-18116.67578125,-17916.408203125,50.1402970658803,5.40507032172011,2.57969617843628,26,1,0,0,1,0.272064208984375,30.3030319213867,1,6,1,1.9999293088913,0,2.0000017285347,,,,,,,,,,,,,,,,,,,,,,,,,,,,,,,,,
,3865782064.17407,2.00013077259064,-20056.7998046875,-0.237590645361076,7.23264466838703E-5,1,2,12.9061126708984,4.98265653345355,42.8000018000603,-308.715662301791,-45.3582957404773,1000,-3.45328795939173E-6,,,,,,,,,,,,,,,,,,,,,2.00010681152344,2.00015473365784,-20176.734375,-19936.865234375,50.1082502965918,5.40485475703117,2.57512927055359,26,1,0,0,1,0.270767211914062,31.2805480957031,1,6,1,2.00010681152344,0,2.00013077259064,,,,,,,,,,,,,,,,,,,,,,,,,,,,,,,,,
,3865782084.2783,2.00019407272339,-22067.06640625,-0.250046130693684,7.23757177918484E-5,1,2,12.9061126708984,4.9826085799624,42.8000018000603,-324.885329908804,-47.8042102552621,1000,-5.64998002054083E-5,,,,,,,,,,,,,,,,,,,,,2.00004816055298,2.0003399848938,-22137.359375,-21996.7734375,50.1965743192649,5.40519711675286,2.57572913169861,26,1,0,0,1,0.271987915039062,31.7693061828613,1,6,1,2.00004816055298,0,2.00019407272339,,,,,,,,,,,,,,,,,,,,,,,,,,,,,,,,,
,3865782103.48128,2.0000604391098,-23987.2275390625,-0.261581609663997,6.46746813716253E-5,1,2,12.9061126708984,4.98259046773081,42.8000018000603,-339.870184400613,-50.0193671491768,1000,-6.68344625320604E-5,,,,,,,,,,,,,,,,,,,,,2.00005292892456,2.00006794929504,-24147.212890625,-23827.2421875,50.2067354900149,5.40520787363262,2.56418204307556,26,1,0,0,1,0.27191162109375,30.7917900085449,1,6,1,2.00006794929504,0,2.0000604391098,,,,,,,,,,,,,,,,,,,,,,,,,,,,,,,,,
,3865782122.30998,1.99981343746185,-25868.0263671875,-0.271241784523282,6.08567014964831E-5,1,2,12.9061126708984,4.9825753632829,42.8000018000603,-352.412898196799,-51.9150005938532,1000,-0.000106741623020403,,,,,,,,,,,,,,,,,,,,,1.99959397315979,2.00003290176392,-25958.087890625,-25777.96484375,50.2575413437649,5.40535133057522,2.57108211517334,26,1,0,0,1,0.271759033203125,31.2805480957031,1,6,1,2.00003290176392,0,1.99981343746185,,,,,,,,,,,,,,,,,,,,,,,,,,,,,,,,,
,3865782142.45289,2.00004076957703,-27886.490234375,-0.281275158011826,6.13893484155605E-5,1,2,12.9061126708984,4.98258720567291,42.8000018000603,-365.447326315631,-53.8541078366091,1000,-0.000124977940021431,,,,,,,,,,,,,,,,,,,,,2.00000238418579,2.00007915496826,-27981.62890625,-27791.3515625,50.2591046008034,5.40539352251964,2.5658073425293,26,1,0,0,1,0.272064208984375,31.7693061828613,1,6,1,2.00007915496826,0,2.00004076957703,,,,,,,,,,,,,,,,,,,,,,,,,,,,,,,,,
,3865782162.62774,1.99982172250748,-29910.2958984375,-0.290721789774782,5.86292586349225E-5,1,2,12.9061126708984,4.9826281545786,42.8000018000603,-377.750158859939,-55.4938538792749,1000,1.34214009958501E-6,,,,,,,,,,,,,,,,,,,,,1.99980545043945,1.9998379945755,-30005.572265625,-29815.01953125,50.2786453137842,5.40542228809988,2.56274390220642,26,1,0,0,1,0.271453857421875,29.3255138397217,1,6,1,1.9998379945755,0,1.99982172250748,,,,,,,,,,,,,,,,,,,,,,,,,,,,,,,,,
,3865782183.01854,1.9999817609787,-31948.9033203125,-0.299557618427432,4.32965401599009E-5,1,2,12.9061126708984,4.98268259157824,42.8000018000603,-389.243860363361,-57.1345980235808,1000,3.73568178411133E-5,,,,,,,,,,,,,,,,,,,,,1.99993586540222,2.00002765655518,-32069.025390625,-31828.78125,50.4103497192746,5.40557682180815,2.55040693283081,26,1,0,0,1,0.27191162109375,31.7693061828613,1,6,1,1.99989688396454,0,1.9999817609787,,,,,,,,,,,,,,,,,,,,,,,,,,,,,,,,,
,3865782204.92505,2.00005739927292,-34147.521484375,-0.308696135205436,5.91794858393928E-5,1,2,12.9061126708984,4.98274688938612,42.8000018000603,-401.129279103084,-58.8541769546679,1000,5.73338793452031E-5,,,,,,,,,,,,,,,,,,,,,1.9996954202652,2.00041937828064,-34242.703125,-34052.33984375,50.3192899967842,5.40541632949395,2.54977583885193,26,1,0,0,1,0.273208618164062,31.2805480957031,1,6,1,2.00041937828064,0,2.00005739927292,,,,,,,,,,,,,,,,,,,,,,,,,,,,,,,,,
,3865782225.06708,2.00001567602158,-36165.96875,-0.316540143282653,5.08145811486897E-5,1,2,12.9061126708984,4.98274755076193,42.8000018000603,-411.316834282977,-60.3855358587364,1000,3.11967416340228E-5,,,,,,,,,,,,,,,,,,,,,1.99983775615692,2.00019359588623,-36256.12890625,-36075.80859375,50.5404908677265,5.40578771467787,2.54911041259766,26,1,0,0,1,0.27099609375,31.7693061828613,1,6,1,1.99983775615692,0,2.00001567602158,,,,,,,,,,,,,,,,,,,,,,,,,,,,,,,,,
,3865782245.24081,2.00002872943878,-38185.03515625,-0.323873226624454,5.46479312194536E-5,1,2,12.9061126708984,4.9827609209953,42.8000018000603,-420.835804741931,-61.8618095047055,1000,-2.74367798262739E-5,,,,,,,,,,,,,,,,,,,,,1.99998497962952,2.00007247924805,-38280.3359375,-38089.734375,50.5975497496304,5.40589915138219,2.55215072631836,26,1,0,0,1,0.27191162109375,31.7693061828613,1,6,1,1.9999121427536,0,2.00002872943878,,,,,,,,,,,,,,,,,,,,,,,,,,,,,,,,,
,3865782265.66524,2.00005567073822,-40228.65234375,-0.330850813966863,5.56055422781542E-5,1,2,12.9061126708984,4.98271927974947,42.8000018000603,-429.887573204811,-63.2602009533781,1000,-7.91065262417469E-5,,,,,,,,,,,,,,,,,,,,,1.99974656105042,2.00036478042603,-40343.81640625,-40113.48828125,50.5037543273227,5.40625185665402,2.54087209701538,26,1,0,0,1,0.271835327148438,31.7693061828613,1,6,1,1.99974656105042,0,2.00005567073822,,,,,,,,,,,,,,,,,,,,,,,,,,,,,,,,,
,3865782285.79182,2.00024664402008,-42247.724609375,-0.337501375030484,4.06472137759941E-5,1,2,12.9061126708984,4.98280944531363,42.8000018000603,-438.536582162658,-64.5571487439765,1000,-9.89270202420669E-5,,,,,,,,,,,,,,,,,,,,,2.0000319480896,2.00046133995056,-42307.83984375,-42187.609375,50.5995038209284,5.4060336050567,2.54495620727539,26,1,0,0,1,0.270614624023438,29.8142719268799,1,6,1,2.0000319480896,0,2.00024664402008,,,,,,,,,,,,,,,,,,,,,,,,,,,,,,,,,
,3865782303.90746,1.99947142601013,-44060.82421875,-0.343233174408508,3.84834876466306E-5,1,2,12.9061126708984,4.98278600571425,42.8000018000603,-445.973396470587,-65.70701424667,1000,-0.00014210506862337,,,,,,,,,,,,,,,,,,,,,1.99919986724854,1.99974298477173,-44120.95703125,-44000.69140625,50.6362403613323,5.40656098488784,2.54881691932678,26,1,0,0,1,0.271530151367187,31.7693061828613,1,6,1,1.99974298477173,0,1.99947142601013,,,,,,,,,,,,,,,,,,,,,,,,,,,,,,,,,
,3865782321.99101,1.99637693166733,-45873.857421875,-0.34873766677241,3.30486421823277E-5,1,2,12.9061126708984,4.98282787040576,42.8000018000603,-453.129336417635,-66.7722165546057,1000,-0.000152586757587462,,,,,,,,,,,,,,,,,,,,,1.99633955955505,1.9964143037796,-45944.03125,-45803.68359375,50.6628157309861,5.40658461254027,2.53132367134094,26,1,0,0,1,0.27191162109375,31.7693061828613,1,6,1,1.9964143037796,0,1.99637693166733,,,,,,,,,,,,,,,,,,,,,,,,,,,,,,,,,
,3865782341.89116,1.9992647767067,-47867.525390625,-0.354565928008181,4.54393316988469E-5,1,2,12.9061126708984,4.98279732747648,42.8000018000603,-460.697033237973,-67.8959773805522,1000,-0.000161615305984251,,,,,,,,,,,,,,,,,,,,,1.99904417991638,1.99948537349701,-47957.65625,-47777.39453125,50.5850436933227,5.40706361679226,2.51611495018005,26,1,0,0,1,0.271835327148438,31.2805480957031,1,6,1,1.99904417991638,0,1.9992647767067,,,,,,,,,,,,,,,,,,,,,,,,,,,,,,,,,
,3865782362.03026,2.00090885162354,-49885.931640625,-0.360112925862408,4.41482093751655E-5,1,2,12.9061126708984,4.9826933984144,42.8000018000603,-467.883684122192,-69.0037861789841,1000,-0.000200802122904365,,,,,,,,,,,,,,,,,,,,,2.00024366378784,2.00157403945923,-49981.08203125,-49790.78125,50.7722437236784,5.40723903854479,2.51228284835815,26,1,0,0,1,0.272064208984375,30.7917900085449,1,6,1,2.00024366378784,0,2.00090885162354,,,,,,,,,,,,,,,,,,,,,,,,,,,,,,,,,
,3865782382.20833,2.00005966424942,-48803.818359375,-0.357323661920143,4.05045517505086E-5,1,2,12.9061126708984,4.98287577324415,42.8000018000603,-464.313306730569,-68.2703458071052,1000,-4.34172735974742E-5,,,,,,,,,,,,,,,,,,,,,1.99983680248261,2.00028252601624,-48893.59765625,-48714.0390625,50.6714136446977,5.407109040999,2.51606774330139,26,1,0,0,1,0.270919799804687,30.7917900085449,1,6,1,1.99983680248261,0,2.00005966424942,,,,,,,,,,,,,,,,,,,,,,,,,,,,,,,,,
,3865782402.5043,1.99991351366043,-46777.708984375,-0.351630243434196,4.10028537378901E-5,1,2,12.9061126708984,4.9826915215364,42.8000018000603,-456.866909178815,-67.3459496050355,1000,-0.000171156976775104,,,,,,,,,,,,,,,,,,,,,1.9998916387558,1.99993538856506,-46887.359375,-46668.05859375,50.6858737723034,5.40759288207603,2.5131664276123,26,1,0,0,1,0.272598266601562,31.7693061828613,1,6,1,1.9998916387558,0,1.99991351366043,,,,,,,,,,,,,,,,,,,,,,,,,,,,,,,,,
,3865782422.61202,1.99979269504547,-44771.955078125,-0.345771309304751,5.65419603109025E-5,1,2,12.9061126708984,4.98262285700407,42.8000018000603,-449.267087604815,-66.0776355445718,1000,-5.6788005139359E-5,,,,,,,,,,,,,,,,,,,,,1.99927067756653,2.00031471252441,-44851.73046875,-44692.1796875,50.6577351456111,5.40722287681641,2.51003909111023,26,1,0,0,1,0.271377563476562,31.7693061828613,1,6,1,2.00031471252441,0,1.99979269504547,,,,,,,,,,,,,,,,,,,,,,,,,,,,,,,,,
,3865782443.02185,2.02859473228455,-42730.951171875,-0.339596672848037,4.29699734389616E-5,1,2,12.9061126708984,4.98274031985019,42.8000018000603,-441.239776848532,-65.0298714998215,1000,-0.000155876148369825,,,,,,,,,,,,,,,,,,,,,2.02567720413208,2.03151226043701,-42786.01953125,-42675.8828125,50.5815263649861,5.40694597845116,2.50339102745056,26,1,0,0,1,0.271072387695313,32.2580642700195,6,6,1,2.03151226043701,0,2.02859473228455,,,,,,,,,,,,,,,,,,,,,,,,,,,,,,,,,
,3865782461.10649,1.99993586540222,-40924.751953125,-0.333772309800278,4.70216432863995E-5,1,2,12.9061126708984,4.98281982318507,42.8000018000603,-433.720046617095,-63.6561579525032,1000,4.67559287795927E-5,,,,,,,,,,,,,,,,,,,,,1.99988198280334,1.9999897480011,-40979.6328125,-40869.87109375,50.5178236406688,5.40642160522693,2.49875998497009,26,1,0,0,1,0.27069091796875,31.7693061828613,5,6,1,1.99988198280334,0,1.99993586540222,,,,,,,,,,,,,,,,,,,,,,,,,,,,,,,,,
,3865782480.29893,1.99991124868393,-39012.701171875,-0.32698004266883,5.47901831056005E-5,1,2,12.9061126708984,4.9827996912007,42.8000018000603,-424.871632523371,-62.4951623654573,1000,-5.79048677117437E-5,,,,,,,,,,,,,,,,,,,,,1.9996417760849,2.00018072128296,-39182.51953125,-38842.8828125,50.4787422147073,5.40647793579543,2.49474573135376,26,1,0,0,1,0.272674560546875,32.2580642700195,5,6,1,2.00018072128296,0,1.99991124868393,,,,,,,,,,,,,,,,,,,,,,,,,,,,,,,,,
,3865782501.11214,1.99987298250198,-36931.767578125,-0.319835111910362,4.71424578760788E-5,1,2,12.9061126708984,4.98280982360982,42.8000018000603,-415.576177426255,-61.2158847252059,1000,-0.000122935877689428,,,,,,,,,,,,,,,,,,,,,1.99985611438751,1.99988985061646,-37016.578125,-36846.95703125,50.5299388827169,5.4063123548357,2.49042797088623,26,1,0,0,1,0.270919799804687,31.7693061828613,5,6,1,1.99988985061646,0,1.99987298250198,,,,,,,,,,,,,,,,,,,,,,,,,,,,,,,,,
,3865782521.25646,1.99999487400055,-34920.291015625,-0.312283930103075,5.21201158239676E-5,1,2,12.9061126708984,4.98274282044381,42.8000018000603,-405.752552565325,-59.799193913412,1000,-0.000142906936144535,,,,,,,,,,,,,,,,,,,,,1.99993920326233,2.00005054473877,-35020.09765625,-34820.484375,50.4990645562073,5.40579492723074,2.48497700691223,26,1,0,0,1,0.271987915039062,31.2805480957031,1,6,1,1.99993920326233,0,1.99999487400055,,,,,,,,,,,,,,,,,,,,,,,,,,,,,,,,,
,3865782539.36494,2.00003105401993,-33113.740234375,-0.30512362945829,6.41975986761173E-5,1,2,12.9061126708984,4.98275344788129,42.8000018000603,-396.464474551751,-58.331865013842,1000,-6.54579408877452E-5,,,,,,,,,,,,,,,,,,,,,1.99995696544647,2.00010514259338,-33213.7109375,-33013.76953125,50.4529484735726,5.40551486972589,2.48716807365417,26,1,0,0,1,0.270767211914062,31.2805480957031,1,6,1,1.99995696544647,0,2.00003105401993,,,,,,,,,,,,,,,,,,,,,,,,,,,,,,,,,
,3865782559.83924,1.99995720386505,-31072.611328125,-0.296719275445253,4.86626045584909E-5,1,2,12.9061126708984,4.9827523435453,42.8000018000603,-385.53593597131,-56.7807175862976,1000,-0.000106419883678549,,,,,,,,,,,,,,,,,,,,,1.99994432926178,1.99997007846832,-31197.291015625,-30947.931640625,50.4138670476111,5.40561348626667,2.48209285736084,26,1,0,0,1,0.271835327148438,30.7917900085449,1,6,1,1.99997007846832,0,1.99995720386505,,,,,,,,,,,,,,,,,,,,,,,,,,,,,,,,,
,3865782580.9374,1.99973148107529,-28966.7353515625,-0.286789902573217,5.36199749573438E-5,1,2,12.9061126708984,4.9827457641618,42.8000018000603,-372.631769305783,-54.893813375272,1000,-0.000113093980076971,,,,,,,,,,,,,,,,,,,,,1.99965298175812,1.99980998039246,-29131.552734375,-28801.91796875,50.3587622370053,5.4051631732256,2.48716998100281,26,1,0,0,1,0.272064208984375,31.2805480957031,1,6,1,1.99965298175812,0,1.99973148107529,,,,,,,,,,,,,,,,,,,,,,,,,,,,,,,,,
,3865782601.77159,1.99955040216446,-26885.6005859375,-0.277260147940677,5.80256479079326E-5,1,2,12.9061126708984,4.9827077237303,42.8100004792213,-360.263824684359,-52.9458469814299,1000,-1.44230715699596E-5,,,,,,,,,,,,,,,,,,,,,1.99952507019043,1.99957573413849,-26975.44921875,-26795.751953125,50.2966227697265,5.40548785921642,2.49016761779785,26,1,0,0,1,0.271072387695313,30.7917900085449,1,6,1,1.99952507019043,0,1.99955040216446,,,,,,,,,,,,,,,,,,,,,,,,,,,,,,,,,
,3865782622.05678,1.999656021595,-24863.8134765625,-0.267132578413256,6.48226570702874E-5,1,2,12.9061126708984,4.98255876614517,42.8000018000603,-347.084137893094,-51.0480786770906,1000,-4.34073372057301E-5,,,,,,,,,,,,,,,,,,,,,1.99926340579987,2.00004863739014,-24968.529296875,-24759.09765625,50.2008732761207,5.405779030244,2.48872017860413,26,1,0,0,1,0.272293090820313,31.2805480957031,1,6,1,2.00004863739014,0,1.999656021595,,,,,,,,,,,,,,,,,,,,,,,,,,,,,,,,,
,3865782642.24657,2.00009322166443,-22847.712890625,-0.256098337341397,6.45991582450961E-5,1,2,12.9061126708984,4.98268790025378,42.8000018000603,-332.754585155073,-48.9748361053655,1000,-6.74567058897771E-5,,,,,,,,,,,,,,,,,,,,,2.00008678436279,2.00009965896606,-22922.537109375,-22772.888671875,50.2426904018995,5.40563989080352,2.48263025283813,26,1,0,0,1,0.271530151367187,31.2805480957031,1,6,1,2.00008678436279,0,2.00009322166443,,,,,,,,,,,,,,,,,,,,,,,,,,,,,,,,,
,3865782660.57072,1.99991482496262,-21020.5908203125,-0.24549145883274,6.69699652084877E-5,1,2,12.9061126708984,4.98269910298968,42.8000018000603,-318.973789085104,-46.9468386354332,1000,-6.48592775472177E-5,,,,,,,,,,,,,,,,,,,,,1.99959528446198,2.00023436546326,-21135.279296875,-20905.90234375,50.1633551071976,5.40490585923255,2.4786958694458,26,1,0,0,1,0.271530151367187,31.7693061828613,1,6,1,1.99973177909851,0,1.99991482496262,,,,,,,,,,,,,,,,,,,,,,,,,,,,,,,,,
,3865782678.65933,1.99990093708038,-19213.8896484375,-0.234181657506967,7.16121548414322E-5,1,2,12.9061126708984,4.98271413584126,42.8000018000603,-304.277811967192,-44.7986977991762,1000,-7.30395997075537E-5,,,,,,,,,,,,,,,,,,,,,1.9998916387558,1.99991023540497,-19328.52734375,-19099.251953125,50.1864131485149,5.40504474942693,2.47478365898132,26,1,0,0,1,0.271224975585938,31.2805480957031,1,6,1,1.99991023540497,0,1.99990093708038,,,,,,,,,,,,,,,,,,,,,,,,,,,,,,,,,
,3865782699.83313,2.00018846988678,-17097.716796875,-0.219014921515405,8.25504360350077E-5,1,2,12.9061126708984,4.98257357443934,42.8000018000603,-284.576393626616,-41.7842643695164,1000,1.74212358452676E-5,,,,,,,,,,,,,,,,,,,,,1.9999852180481,2.00039172172546,-17262.46484375,-16932.96875,50.2348741167072,5.40525035083588,2.47965097427368,26,1,0,0,1,0.270767211914062,31.2805480957031,1,6,1,1.9999852180481,0,2.00018846988678,,,,,,,,,,,,,,,,,,,,,,,,,,,,,,,,,
,3865782718.61676,2.0002475976944,-15221.2236328125,-0.205496553122561,8.74413807594779E-5,1,2,12.9061126708984,4.98250026592046,42.8000018000603,-267.008639825852,-39.1851921082137,1000,3.11156924790227E-5,,,,,,,,,,,,,,,,,,,,,1.99979472160339,2.0007004737854,-15316.193359375,-15126.25390625,50.1535847507072,5.40530533088503,2.49170017242432,26,1,0,0,1,0.272064208984375,31.2805480957031,6,6,1,1.99979472160339,0,2.0002475976944,,,,,,,,,,,,,,,,,,,,,,,,,,,,,,,,,
,3865782738.77066,2.00010859966278,-13209.8110351562,-0.188947782911432,9.61127383685012E-5,1,2,12.9061126708984,4.98257927606142,42.8000018000603,-245.509369405643,-36.0464727281896,1000,1.62293265765765E-5,,,,,,,,,,,,,,,,,,,,,1.99983620643616,2.0003809928894,-13299.59765625,-13120.0244140625,50.0351680300438,5.4043133386321,2.49501323699951,26,1,0,0,1,0.272293090820313,31.7693061828613,1,6,1,1.99983620643616,0,2.00010859966278,,,,,,,,,,,,,,,,,,,,,,,,,,,,,,,,,
,3865782758.90651,1.99968940019608,-11197.1064453125,-0.170802789055555,0.000104058677514008,1,2,12.9061126708984,4.9826543074361,42.8000018000603,-221.935371330781,-32.5991035420884,1000,4.24371288974597E-6,,,,,,,,,,,,,,,,,,,,,1.99958121776581,1.99979758262634,-11291.9755859375,-11102.2373046875,50.0508006004284,5.4041184643588,2.49538445472717,26,1,0,0,1,0.271453857421875,31.7693061828613,1,6,1,1.99958121776581,0,1.99968940019608,,,,,,,,,,,,,,,,,,,,,,,,,,,,,,,,,
,3865782779.3158,2.00021475553513,-9163.3798828125,-0.150478243004638,0.000115034665890962,1,2,12.9061126708984,4.98268952355745,42.8000018000603,-195.526788444126,-28.7304714817837,1000,-4.10184380243601E-6,,,,,,,,,,,,,,,,,,,,,1.99960196018219,2.00082755088806,-9283.3017578125,-9043.4580078125,50.1148941390053,5.40409082704421,2.49351072311401,26,1,0,0,1,0.270843505859375,31.7693061828613,1,6,1,1.99960196018219,0,2.00021475553513,,,,,,,,,,,,,,,,,,,,,,,,,,,,,,,,,
,3865782800.62112,1.99988335371017,-7034.8408203125,-0.125456186007469,0.000133505961663289,1,2,12.9061126708984,4.98255149686625,42.8000018000603,-163.008282058137,-23.9471735162763,1000,3.98061370739242E-7,,,,,,,,,,,,,,,,,,,,,1.99984681606293,1.99991989135742,-7184.7978515625,-6884.8837890625,50.0957442402841,5.40454631374284,2.49625611305237,26,1,0,0,1,0.271987915039062,31.7693061828613,1,6,1,1.99991989135742,0,1.99988335371017,,,,,,,,,,,,,,,,,,,,,,,,,,,,,,,,,
,3865782821.39661,1.99709784984589,-4956.65087890625,-0.099243595965213,0.000147247084868326,1,2,12.9061126708984,4.9825355130167,42.8000018000603,-128.950391628175,-18.9344302694134,1000,7.37894017480778E-6,,,,,,,,,,,,,,,,,,,,,1.99438405036926,1.99981164932251,-5046.55615234375,-4866.74560546875,50.0953534260245,5.40469933231742,2.48740601539612,26,1,0,0,1,0.272216796875,31.7693061828613,1,6,1,1.99438405036926,0,1.99709784984589,,,,,,,,,,,,,,,,,,,,,,,,,,,,,,,,,
,3865782841.60231,1.99764496088028,-2933.37902832031,-0.0687859333767426,0.000174542564305923,1,2,12.9061126708984,4.98260743336745,42.8000018000603,-89.3838401659211,-13.0811824366735,1000,3.7880873342859E-5,,,,,,,,,,,,,,,,,,,,,1.99655318260193,1.99873673915863,-3038.24536132812,-2828.5126953125,49.9956957898226,5.40383520629671,2.48038601875305,26,1,0,0,1,0.27191162109375,30.3030319213867,6,6,1,1.99655318260193,0,1.99764496088028,,,,,,,,,,,,,,,,,,,,,,,,,,,,,,,,,
,3865782875.11861,1.99906706809998,409.286254882812,-0.00193719484508887,0.000276732659694521,1,2,12.9061126708984,4.98249504553432,42.8000018000603,-2.51932770652349,-0.353953168578139,100,1.21774324970957E-5,,,,,,,,,,,,,,,,,,,,,1.99906706809998,1.99906706809998,409.286254882812,409.286254882812,50.0672147993322,5.40403043955624,2.48348569869995,26,1,0,0,1,0.272445678710938,31.2805480957031,6,6,1,1.99906706809998,0,1.99906706809998,,,,,,,,,,,,,,,,,,,,,,,,,,,,,,,,,
,3865782895.89878,1.99986499547958,2493.72534179687,0.0475321458252536,0.000208150829799069,1,2,12.9061126708984,4.98236864499817,42.8000018000603,61.7510652959919,9.10943709822766,100,2.82749626597756E-5,,,,,,,,,,,,,,,,,,,,,1.99964487552643,2.00008511543274,2398.79345703125,2588.6572265625,50.0976983115822,5.40450186624029,2.48885822296143,26,1,0,0,1,0.2716064453125,31.2805480957031,5,6,1,1.99964487552643,0,1.99986499547958,,,,,,,,,,,,,,,,,,,,,,,,,,,,,,,,,
,3865782916.41566,2.00031876564026,4543.51635742188,0.0828115258693201,0.000172141342753928,1,2,12.9061126708984,4.98222525133694,42.8000018000603,107.579919458696,15.8683947710019,100,4.8014050273312E-5,,,,,,,,,,,,,,,,,,,,,2.00004816055298,2.00058937072754,4428.67822265625,4658.3544921875,50.0332139587457,5.40482897285912,2.4879207611084,26,1,0,0,1,0.272598266601562,30.7917900085449,5,6,1,2.00004816055298,0,2.00031876564026,,,,,,,,,,,,,,,,,,,,,,,,,,,,,,,,,
,3865782937.51585,2.00019109249115,6647.59838867187,0.115267407171559,0.000149657411372504,1,2,12.9061126708984,4.98221279579664,42.8000018000603,149.738222884053,22.1174600245523,100,8.98670588436897E-5,,,,,,,,,,,,,,,,,,,,,2.00011587142944,2.00026631355286,6487.61962890625,6807.5771484375,50.0293058161495,5.40494511443424,2.48751950263977,26,1,0,0,1,0.272369384765625,31.2805480957031,5,6,1,2.00011587142944,0,2.00019109249115,,,,,,,,,,,,,,,,,,,,,,,,,,,,,,,,,
,3865782958.39528,1.99969869852066,8738.35595703125,0.140534092970557,0.000128463478120882,1,2,12.9061126708984,4.98225520503406,42.8000018000603,182.55716587699,27.0064480393989,100,0.000140742274200232,,,,,,,,,,,,,,,,,,,,,1.9992583990097,2.00013899803162,8648.2255859375,8828.486328125,50.0250068592938,5.40503495156125,2.47762393951416,26,1,0,0,1,0.27252197265625,31.7693061828613,1,6,1,2.00013899803162,0,1.99969869852066,,,,,,,,,,,,,,,,,,,,,,,,,,,,,,,,,
,3865782990.75453,1.99993413686752,11978.9560546875,0.174530273223437,0.000102130278496916,1,2,12.9061126708984,4.98228836363252,42.8000018000603,226.752829637903,33.3241181100531,1000,8.77294706770822E-6,,,,,,,,,,,,,,,,,,,,,1.99967992305756,2.00018835067749,11909.0390625,12048.873046875,50.0132824315053,5.40528116082988,2.47834038734436,26,1,0,0,1,0.272445678710938,31.2805480957031,1,6,1,1.99967992305756,0,1.99993413686752,,,,,,,,,,,,,,,,,,,,,,,,,,,,,,,,,
,3865783011.11738,2.00014692544937,14013.9233398438,0.192808997278137,9.55535386616038E-5,1,2,12.9061126708984,4.98230631250151,42.8000018000603,250.501819936528,36.8165552680123,1000,1.13725038004781E-5,,,,,,,,,,,,,,,,,,,,,1.99942243099213,2.00087141990662,13958.966796875,14068.8798828125,50.0449383865341,5.40536697165087,2.47238278388977,26,1,0,0,1,0.272445678710938,31.2805480957031,1,6,1,1.99942243099213,0,2.00014692544937,,,,,,,,,,,,,,,,,,,,,,,,,,,,,,,,,
,3865783030.86191,1.9998499751091,15989.2412109375,0.209189836490543,8.74154561294034E-5,1,2,12.9061126708984,4.98228217162751,42.8000018000603,271.784815215739,39.9272389735713,1000,-6.98390572520601E-7,,,,,,,,,,,,,,,,,,,,,1.99976301193237,1.99993693828583,15899.0732421875,16079.4091796875,50.0746402702649,5.40551820499838,2.47181987762451,26,1,0,0,1,0.271530151367187,31.2805480957031,1,6,1,1.99993693828583,0,1.9998499751091,,,,,,,,,,,,,,,,,,,,,,,,,,,,,,,,,
,3865783051.06245,2.00541526079178,18009.50390625,0.22418504289727,5.72338043328356E-5,1,2,12.9061126708984,4.98243627966369,42.8000018000603,291.278817429651,42.796736908768,1000,3.53234318918251E-6,,,,,,,,,,,,,,,,,,,,,1.99101579189301,2.01981472969055,17909.513671875,18109.494140625,50.0609617711784,5.4049215851081,2.47631669044495,26,1,0,0,1,0.271682739257813,31.7693061828613,6,6,1,2.01981472969055,0,2.00541526079178,,,,,,,,,,,,,,,,,,,,,,,,,,,,,,,,,
,3865783071.47594,1.99761176109314,20050.3818359375,0.237888429112242,4.7801942081489E-5,1,2,12.9061126708984,4.9824823125855,42.8000018000603,309.088780701498,45.4035284100079,1000,-3.76587033278902E-6,,,,,,,,,,,,,,,,,,,,,1.97664737701416,2.01857614517212,19930.41015625,20170.353515625,50.1848498914765,5.40498613279085,2.46655321121216,26,1,0,0,1,0.272445678710938,31.7693061828613,6,6,1,2.01857614517212,0,1.99761176109314,,,,,,,,,,,,,,,,,,,,,,,,,,,,,,,,,
,3865783091.53621,1.99965000152588,22055.7783203125,0.250249317821807,4.72097819674049E-5,1,2,12.9061126708984,4.98242399961636,42.8000018000603,325.146182031369,47.7467791441369,1000,-1.56375164466829E-5,,,,,,,,,,,,,,,,,,,,,1.98418617248535,2.01511383056641,21990.48046875,22121.076171875,50.1993100190822,5.40535010541596,2.45520424842834,26,1,0,0,1,0.27191162109375,31.2805480957031,6,6,1,2.01511383056641,0,1.99965000152588,,,,,,,,,,,,,,,,,,,,,,,,,,,,,,,,,
,3865783110.78322,2.00096559524536,23981.216796875,0.261639074852744,7.39369943141267E-5,1,2,12.9061126708984,4.98259725838046,42.8000018000603,339.965666503611,49.8931770331513,1000,-3.88001187392619E-5,,,,,,,,,,,,,,,,,,,,,1.99991893768311,2.00201225280762,23821.212890625,24141.220703125,50.2028273474188,5.40492716421763,2.45213794708252,26,1,0,0,1,0.27191162109375,31.7693061828613,6,6,1,2.00201225280762,0,2.00096559524536,,,,,,,,,,,,,,,,,,,,,,,,,,,,,,,,,
,3865783129.60597,1.99986988306046,25861.7568359375,0.271221146157312,5.59456066911313E-5,1,2,12.9061126708984,4.98244401894018,42.8000018000603,352.401866177013,51.7128388520718,1000,-4.43408344565261E-5,,,,,,,,,,,,,,,,,,,,,1.99954998493195,2.00018978118896,25771.68359375,25951.830078125,50.2395638878226,5.40609495311879,2.45519089698791,26,1,0,0,1,0.273056030273438,31.2805480957031,5,6,1,1.99954998493195,0,1.99986988306046,,,,,,,,,,,,,,,,,,,,,,,,,,,,,,,,,
,3865783149.73873,1.99994975328445,27885.724609375,0.281322601275885,6.59366047498516E-5,1,2,12.9061126708984,4.98252477232116,42.8000018000603,365.533288734366,53.6528782056449,1000,-3.61358773926248E-5,,,,,,,,,,,,,,,,,,,,,1.99983608722687,2.00006341934204,27795.5,27975.94921875,50.3849467923996,5.40572238879308,2.45255255699158,26,1,0,0,1,0.272216796875,30.7917900085449,5,6,1,2.00006341934204,0,1.99994975328445,,,,,,,,,,,,,,,,,,,,,,,,,,,,,,,,,
,3865783169.94921,1.99991536140442,29909.654296875,0.290727671090263,5.96679195952772E-5,1,2,12.9061126708984,4.98255719172886,42.8000018000603,377.747830734535,55.5102658504836,1000,1.1279793008767E-5,,,,,,,,,,,,,,,,,,,,,1.99976515769958,2.00006556510925,29809.36328125,30009.9453125,50.3185083682649,5.4061697302927,2.45272660255432,26,1,0,0,1,0.272216796875,31.7693061828613,1,6,1,2.00006556510925,0,1.99991536140442,,,,,,,,,,,,,,,,,,,,,,,,,,,,,,,,,
,3865783188.09902,2.0001939535141,31728.1396484375,0.298705982758177,5.10801704097964E-5,1,2,12.9061126708984,4.9826646157824,42.8000018000603,388.117002454815,57.0962953395264,1000,5.85027191508382E-5,,,,,,,,,,,,,,,,,,,,,2.00005745887756,2.00033044815063,31632.8125,31823.466796875,50.3794753927649,5.40589517179422,2.44997358322144,26,1,0,0,1,0.271530151367187,31.2805480957031,1,6,1,2.00005745887756,0,2.0001939535141,,,,,,,,,,,,,,,,,,,,,,,,,,,,,,,,,
,3865783208.50286,1.99893283843994,33772.98046875,0.307047598239306,4.7756901120305E-5,1,2,12.9061126708984,4.98263114055299,42.8100004792213,398.948035180642,58.7153471401502,1000,7.94875581748559E-5,,,,,,,,,,,,,,,,,,,,,1.99793004989624,1.99993562698364,33657.80859375,33888.15234375,50.4111313477938,5.40613435091492,2.45049524307251,26,1,0,0,1,0.271682739257813,31.7693061828613,1,6,1,1.99793004989624,0,1.99893283843994,,,,,,,,,,,,,,,,,,,,,,,,,,,,,,,,,
,3865783229.62005,1.99958527088165,35891.99609375,0.315631090043423,4.04529166548924E-5,1,2,12.9061126708984,4.98228194733582,42.8000018000603,410.058038681266,60.3655390157779,1000,9.30651514106563E-5,,,,,,,,,,,,,,,,,,,,,1.99949634075165,1.99967420101166,35731.81640625,36052.17578125,50.3982344772265,5.40729515108938,2.45418882369995,26,1,0,0,1,0.271835327148438,31.7693061828613,1,6,1,1.99949634075165,0,1.99958527088165,,,,,,,,,,,,,,,,,,,,,,,,,,,,,,,,,
,3865783250.44833,2.00014555454254,37976.462890625,0.323033209301036,4.09313970927501E-5,1,2,12.9061126708984,4.98222935436089,42.8000018000603,419.672825778523,61.7502757044451,1000,7.21353474922139E-5,,,,,,,,,,,,,,,,,,,,,2.00006484985352,2.00022625923157,37886.26953125,38066.65625,50.5193868977073,5.40817931319018,2.45980715751648,26,1,0,0,1,0.272674560546875,31.2805480957031,1,6,1,2.00022625923157,0,2.00014555454254,,,,,,,,,,,,,,,,,,,,,,,,,,,,,,,,,
,3865783270.66637,2.00036871433258,40000.5859375,0.330073122510192,4.89928976636803E-5,1,2,12.9061126708984,4.98229396068967,42.8000018000603,428.837359159848,63.0241699431891,1000,1.75286699613226E-5,,,,,,,,,,,,,,,,,,,,,2.00027060508728,2.00046682357788,39900.2578125,40100.9140625,50.4365342746688,5.40776540840307,2.45657110214233,26,1,0,0,1,0.2728271484375,31.2805480957031,1,6,1,2.00046682357788,0,2.00036871433258,,,,,,,,,,,,,,,,,,,,,,,,,,,,,,,,,
,3865783291.17192,1.99969530105591,42054.8828125,0.336773973888096,3.85475038334371E-5,1,2,12.9061126708984,4.98235549078339,42.8000018000603,437.54488357778,64.3452128562106,1000,4.90302245367483E-5,,,,,,,,,,,,,,,,,,,,,1.9994695186615,1.99992108345032,41944.6953125,42165.0703125,50.5358010966111,5.40808329843251,2.45626091957092,26,1,0,0,1,0.273284912109375,31.2805480957031,1,6,1,1.9994695186615,0,1.99969530105591,,,,,,,,,,,,,,,,,,,,,,,,,,,,,,,,,
,3865783311.20547,1.99979740381241,44063.921875,0.343168226533271,5.48684233382272E-5,1,2,12.9061126708984,4.98236504127694,42.8000018000603,445.84787624256,65.6064138022448,1000,8.02215951963534E-5,,,,,,,,,,,,,,,,,,,,,1.99977791309357,1.99981689453125,43998.76171875,44129.08203125,50.6647698022842,5.40802160766551,2.45113658905029,26,1,0,0,1,0.272979736328125,31.2805480957031,1,6,1,1.99981689453125,0,1.99979740381241,,,,,,,,,,,,,,,,,,,,,,,,,,,,,,,,,
,3865783329.24059,2.00028097629547,45872.48828125,0.348618654478059,4.55964953286419E-5,1,2,12.9061126708984,4.98246993375545,42.8000018000603,452.944203761916,66.6390119314648,1000,7.27379966378152E-5,,,,,,,,,,,,,,,,,,,,,2.00003933906555,2.00052261352539,45802.40234375,45942.57421875,50.6159180198323,5.40767229895103,2.44649434089661,26,1,0,0,1,0.272903442382813,32.2580642700195,1,6,1,2.00052261352539,0,2.00028097629547,,,,,,,,,,,,,,,,,,,,,,,,,,,,,,,,,
,3865783349.16219,1.99028426408768,47867.2265625,0.354646821165458,3.24013332956182E-5,1,2,12.9061126708984,4.98237305521905,42.8000018000603,460.751566132761,67.8722696951366,1000,0.000137737137937757,,,,,,,,,,,,,,,,,,,,,1.98287093639374,1.99769759178162,47777.0703125,47957.3828125,50.676103415813,5.40858778093284,2.43525528907776,26,1,0,0,1,0.272293090820313,31.2805480957031,6,6,1,1.99769759178162,0,1.99028426408768,,,,,,,,,,,,,,,,,,,,,,,,,,,,,,,,,
,3865783369.30667,2.00416123867035,49886.259765625,0.360058176467991,4.83353965879097E-5,1,2,12.9061126708984,4.9824512681203,42.8000018000603,467.795431868422,68.8876450705507,1000,0.000123083895701995,,,,,,,,,,,,,,,,,,,,,2.0026957988739,2.0056266784668,49791.05859375,49981.4609375,50.6850921437842,5.40889575337102,2.44459176063538,26,1,0,0,1,0.272216796875,31.2805480957031,5,6,1,2.0026957988739,0,2.00416123867035,,,,,,,,,,,,,,,,,,,,,,,,,,,,,,,,,
,3865783373.61006,1.99895340204239,50000.48828125,0.360444664002884,2.75363827072573E-5,1,2,12.9061126708984,4.98254107037427,42.8000018000603,468.324531931154,68.8605173302885,1000,4.40832941334234E-5,,,,,,,,,,,,,,,,,,,,,1.99854063987732,1.99936616420746,50000.4765625,50000.5,50.7179205415919,5.40845890097636,2.43814754486084,26,1,0,0,1,0.271835327148438,32.2580642700195,5,4,1,1.99936616420746,0,1.99895340204239,,,,,,,,,,,,,,,,,,,,,,,,,,,,,,,,,