File: LT data/Bridport/D2/367-RT HYS.dat
[Header]
; MPMS3 Data File (default extension .dat)
; Copyright (c) 2007, Quantum Design, Inc. All rights reserved.
TITLE,
FILEOPENTIME,3865775653.75274,06/30/2022,7:31 pm
BYAPP,MPMS3 w/ AC,1.0,1.1
INFO,MPMS3 Measurement Release 1.1.16 Build 424, MultiVu Release 2.3.4.19,APPNAME
INFO,Linear Motor Servo Controller,MOTOR_MODULE_NAME
INFO,3101-100 N2,MOTOR_HW_VERSION
INFO,,MOTOR_SERIAL_NUMBER
INFO,01.04.28,MOTOR_SOFTWARE_VERSION
INFO,Quantum Design Squid Module,SQUID_MODULE_NAME
INFO,3101-501 B0,SQUID_HW_VERSION
INFO,SQM327,SQUID_SERIAL_NUMBER
INFO,01.03.04,SQUID_SOFTWARE_VERSION
INFO,Quantum Design VSM Oven,OVEN_MODULE_NAME
INFO,3101-201 A3,OVEN_HW_VERSION
INFO,OVB365,OVEN_SERIAL_NUMBER
INFO,01.07.07,OVEN_SOFTWARE_VERSION
INFO,SQUID AC,AC_MODULE_NAME
INFO,3101-401 G0,AC_HW_VERSION
INFO,SAC220,AC_SERIAL_NUMBER
INFO,SQUID AC 00.95.07,AC_SOFTWARE_VERSION
INFO,TCI344,COIL_SERIAL_NUMBER
INFO,0,MOMENT_UNITS
INFO,sndst,SAMPLE_MATERIAL
INFO,,SAMPLE_COMMENT
INFO,139.94,SAMPLE_MASS
INFO,,SAMPLE_VOLUME
INFO,,SAMPLE_MOLECULAR_WEIGHT
INFO,,SAMPLE_SIZE
INFO,,SAMPLE_SHAPE
INFO,Straw,SAMPLE_HOLDER
INFO,Standard,SAMPLE_HOLDER_DETAIL
INFO,57.2,SAMPLE_OFFSET
DATATYPE,COMMENT,1
DATATYPE,TIME,2
STARTUPAXIS,X,2
STARTUPAXIS,Y1,5
FIELDGROUP, VSM,2,3,4,5,6,8,9,10,11,14,15
FIELDGROUP, DC, 2,3,4,14,56,57,58,59,60,61,62,63,64,65,66,67,68,69
FIELDGROUP, AC, 2,3,4,11,16,17,18,19,20,21,22,23,24,25,26,27,28,29,30
STARTUPGROUP, All
[Data]
Comment,Time Stamp (sec),Temperature (K),Magnetic Field (Oe),Moment (emu),M. Std. Err. (emu),Transport Action,Averaging Time (sec),Frequency (Hz),Peak Amplitude (mm),Center Position (mm),Lockin Signal' (V),Lockin Signal (V),Range,M. Quad. Signal (emu),AC Moment (emu),AC M. Std Err. (emu),AC Phase (deg),AC Phase Std. Err. (deg),AC Susceptibility (emu/Oe),AC Suscept. Std Err. (emu/Oe),AC X' (emu/Oe),AC X' Std Err. (emu/Oe),AC X'' (emu/Oe),AC X'' Std Err. (emu/Oe),AC Drive (Oe),AC Frequency (Hz),AC Averaging Time (sec),AC Cycles,AC Range,AC Measure Type,AC Signal' (V),AC Signal'' (V),AC Trim Coil Ratio,AC Trim Coil Phase,Min. Temperature (K),Max. Temperature (K),Min. Field (Oe),Max. Field (Oe),Mass (grams),Motor Lag (deg),Pressure (Torr),Measure Count,Measurement Number,SQUID Status (code),Motor Status (code),Measure Status (code),Motor Current (amps),Motor Temp. (C),Temp. Status (code),Field Status (code),Chamber Status (code),Chamber Temp (K),Redirection State,Average Temp (K),Rotation Angle (deg),Rotator state,DC Moment Fixed Ctr (emu),DC Moment Err Fixed Ctr (emu),DC Moment Free Ctr (emu),DC Moment Err Free Ctr (emu),DC Fixed Fit,DC Free Fit,DC Calculated Center (mm),DC Calculated Center Err (mm),DC Scan Length (mm),DC Scan Time (s),DC Number of Points,DC Squid Drift,DC Min V (V),DC Max V (V),DC Scans per Measure,Map 01,Map 02,Map 03,Map 04,Map 05,Map 06,Map 07,Map 08,Map 09,Map 10,Map 11,Map 12,Map 13,Map 14,Map 15,Map 16
,3865790403.35381,300.007446289063,50000.3515625,0.0143155838798474,1.5631009722968E-6,1,2,12.9061126708984,4.9938722066945,43.7299981713295,18.6589763949665,2.74786584750682,10,4.99988774850832E-6,,,,,,,,,,,,,,,,,,,,,300.007446289063,300.007446289063,50000.3515625,50000.3515625,49.8800147689764,5.39964797682591,7.40789604187012,26,1,0,0,1,0.271530151367187,30.7917900085449,1,4,1,300.007446289063,0,300.007446289063,,,,,,,,,,,,,,,,,,,,,,,,,,,,,,,,,
,3865790453.37067,300.006927490234,45253.96484375,0.01302616816616,3.56617506916702E-6,1,2,12.9061126708984,4.99394275787261,43.7299981713295,16.9860402802012,2.45034207309002,100,-3.38632429941266E-5,,,,,,,,,,,,,,,,,,,,,300.006927490234,300.006927490234,45249.0078125,45258.921875,49.8053692453899,5.3995491433748,7.43383359909058,25,1,68,0,0,0.272903442382813,31.2805480957031,1,6,1,300.006927490234,0,300.006927490234,,,,,,,,,,,,,,,,,,,,,,,,,,,,,,,,,
,3865790472.36083,300.006698608398,43362.205078125,0.0124513272449223,3.29933308787887E-6,1,2,12.9061126708984,4.99395717532313,43.7299981713295,16.2356944390296,2.34781850418478,100,-2.80728879874301E-5,,,,,,,,,,,,,,,,,,,,,300.006683349609,300.006713867188,43292.39453125,43432.015625,49.8960381536207,5.39920620409851,7.43134260177612,24,1,68,0,0,0.270919799804687,31.2805480957031,1,6,1,300.006713867188,0,300.006698608398,,,,,,,,,,,,,,,,,,,,,,,,,,,,,,,,,
,3865790490.46463,300.004837036133,41550.306640625,0.0119397454640496,3.71524188520056E-6,1,2,12.9061126708984,4.9939980402459,43.7299981713295,15.5689185918484,2.2506060769234,100,-2.75136747179454E-5,,,,,,,,,,,,,,,,,,,,,300.004791259766,300.0048828125,41475.5,41625.11328125,49.9257400373514,5.39939921179645,7.44669532775879,26,1,0,0,1,0.270767211914062,31.7693061828613,1,6,1,300.0048828125,0,300.004837036133,,,,,,,,,,,,,,,,,,,,,,,,,,,,,,,,,
,3865790508.65409,300.004379272461,39733.212890625,0.0114214615495488,3.36105467016463E-6,1,2,12.9061126708984,4.99401629001955,43.7299981713295,14.8927906483736,2.1555370195124,100,-2.43133521240973E-5,,,,,,,,,,,,,,,,,,,,,300.004211425781,300.004547119141,39658.40625,39808.01953125,49.9175329378995,5.3989982009413,7.46325635910034,24,1,68,0,0,0.27069091796875,31.2805480957031,1,6,1,300.004211425781,0,300.004379272461,,,,,,,,,,,,,,,,,,,,,,,,,,,,,,,,,
,3865790526.72637,300.003067016602,37931.203125,0.0109065389687213,3.71376709421672E-6,1,2,12.9061126708984,4.99397959542132,43.7299981713295,14.2211403587546,2.05888447240848,100,-2.27965017642397E-5,,,,,,,,,,,,,,,,,,,,,300.002777099609,300.003356933594,37851.3203125,38011.0859375,49.8991646676976,5.39907885929499,7.47820234298706,26,1,0,0,1,0.271759033203125,31.7693061828613,1,6,1,300.002777099609,0,300.003067016602,,,,,,,,,,,,,,,,,,,,,,,,,,,,,,,,,
,3865790544.80553,300.003265380859,36128.86328125,0.0103906947346718,3.83670055576516E-6,1,2,12.9061126708984,4.9939084889403,43.7299981713295,13.5482390654347,1.96157937979377,100,-2.16318486685179E-5,,,,,,,,,,,,,,,,,,,,,300.003143310547,300.003387451172,36053.99609375,36203.73046875,49.9515337784861,5.39911028438921,7.48925828933716,26,1,0,0,1,0.2734375,31.2805480957031,1,6,1,300.003387451172,0,300.003265380859,,,,,,,,,,,,,,,,,,,,,,,,,,,,,,,,,
,3865790562.96438,300.003189086914,34311.962890625,0.00987467005298026,3.86452730357191E-6,1,2,12.9061126708984,4.99393845891489,43.7299981713295,12.8753226250972,1.86546889196024,100,-1.95677956453023E-5,,,,,,,,,,,,,,,,,,,,,300.003051757812,300.003326416016,34237.1015625,34386.82421875,49.9534878497841,5.39902729981442,7.5162353515625,25,1,68,0,0,0.271835327148438,31.7693061828613,1,6,1,300.003326416016,0,300.003189086914,,,,,,,,,,,,,,,,,,,,,,,,,,,,,,,,,
,3865790581.27273,300.003463745117,32484.548828125,0.00935891226479718,3.85817368875654E-6,1,2,12.9061126708984,4.99385176717847,43.7299981713295,12.2024638460087,1.76852745739645,100,-1.81347360299571E-5,,,,,,,,,,,,,,,,,,,,,300.003326416016,300.003601074219,32359.625,32609.47265625,49.8917391967649,5.39955062092628,7.5296835899353,26,1,0,0,1,0.271453857421875,31.7693061828613,1,6,1,300.003326416016,0,300.003463745117,,,,,,,,,,,,,,,,,,,,,,,,,,,,,,,,,
,3865790599.37569,300.003662109375,30682.6171875,0.00884407617502185,3.43325223053801E-6,1,2,12.9061126708984,4.99383897340604,43.7299981713295,11.5306180446689,1.67493591846164,100,-1.42973085427975E-5,,,,,,,,,,,,,,,,,,,,,300.003570556641,300.003753662109,30562.703125,30802.53125,49.9534878497841,5.3996836740232,7.56081247329712,26,1,0,0,1,0.271835327148438,31.7693061828613,1,6,1,300.003753662109,0,300.003662109375,,,,,,,,,,,,,,,,,,,,,,,,,,,,,,,,,
,3865790617.45323,300.00341796875,28870.7763671875,0.00832937808054442,3.7648591498429E-6,1,2,12.9061126708984,4.99384161063399,43.7299981713295,10.8601293941323,1.57371790797412,100,-1.63368764421656E-5,,,,,,,,,,,,,,,,,,,,,300.002868652344,300.003967285156,28755.86328125,28985.689453125,49.9624765777553,5.39971309874127,7.58572340011597,26,1,0,0,1,0.272064208984375,31.7693061828613,1,6,1,300.002868652344,0,300.00341796875,,,,,,,,,,,,,,,,,,,,,,,,,,,,,,,,,
,3865790633.2893,300.003707885742,27293.5634765625,0.00787210177362141,3.48568136608244E-6,1,2,12.9061126708984,4.99392245780951,43.7299981713295,10.2645532062398,1.48461018563503,100,-1.7546352223913E-5,,,,,,,,,,,,,,,,,,,,,300.003662109375,300.003753662109,27198.783203125,27388.34375,49.9112799097457,5.39952685257269,7.60754346847534,26,1,0,0,1,0.271759033203125,31.7693061828613,1,6,1,300.003662109375,0,300.003707885742,,,,,,,,,,,,,,,,,,,,,,,,,,,,,,,,,
,3865790651.4274,300.004287719727,25481.56640625,0.0073547993704023,2.97836433101682E-6,1,2,12.9061126708984,4.99393491949526,43.7299981713295,9.58977977042489,1.38902022487181,100,-1.48866498794715E-5,,,,,,,,,,,,,,,,,,,,,300.004150390625,300.004425048828,25391.7421875,25571.390625,49.9468440073707,5.39923720648524,7.63543176651001,25,1,68,0,0,0.273284912109375,31.7693061828613,1,6,1,300.004150390625,0,300.004287719727,,,,,,,,,,,,,,,,,,,,,,,,,,,,,,,,,
,3865790669.58218,300.003341674805,23669.7255859375,0.0068416292674945,3.3141932733921E-6,1,2,12.9061126708984,4.99391255069933,43.7299981713295,8.92019962427797,1.29489702829535,100,-1.16985458279909E-5,,,,,,,,,,,,,,,,,,,,,300.003234863281,300.003448486328,23574.900390625,23764.55078125,49.9886611331495,5.39931263664761,7.67981481552124,26,1,0,0,1,0.271759033203125,30.7917900085449,1,6,1,300.003234863281,0,300.003341674805,,,,,,,,,,,,,,,,,,,,,,,,,,,,,,,,,
,3865790687.67813,300.002517700195,21862.373046875,0.00632802249771129,3.62746998812091E-6,1,2,12.9061126708984,4.99396736366096,43.7299981713295,8.25100186339385,1.19551454735597,100,-1.25018880173445E-5,,,,,,,,,,,,,,,,,,,,,300.002410888672,300.002624511719,21767.609375,21957.13671875,49.903854438813,5.39898943232063,7.70704412460327,26,1,0,0,1,0.272369384765625,32.2580642700195,1,6,1,300.002624511719,0,300.002517700195,,,,,,,,,,,,,,,,,,,,,,,,,,,,,,,,,
,3865790705.8555,300.00227355957,20050.6083984375,0.00581035169392572,3.01274767308728E-6,1,2,12.9061126708984,4.99393948967848,43.7299981713295,7.57616810495684,1.0962913040738,100,-1.2564145460746E-5,,,,,,,,,,,,,,,,,,,,,300.002227783203,300.002319335937,19960.78515625,20140.431640625,49.9573959923803,5.39903614210957,7.74724626541138,26,1,0,0,1,0.271377563476562,31.2805480957031,1,6,1,300.002227783203,0,300.00227355957,,,,,,,,,,,,,,,,,,,,,,,,,,,,,,,,,
,3865790721.95028,300.002487182617,18443.416015625,0.00535464962126234,3.60259028738677E-6,1,2,12.9061126708984,4.99392265967132,43.7299981713295,6.98221200854569,1.00846186342891,100,-1.29928440206816E-5,,,,,,,,,,,,,,,,,,,,,300.002471923828,300.002502441406,18353.611328125,18533.220703125,49.954660292563,5.39914437501811,7.7819128036499,26,1,0,0,1,0.272064208984375,31.2805480957031,1,6,1,300.002502441406,0,300.002487182617,,,,,,,,,,,,,,,,,,,,,,,,,,,,,,,,,
,3865790740.06312,300.002334594727,16630.8984375,0.00483599102195559,3.5038296311863E-6,1,2,12.9061126708984,4.99398965188152,43.7299981713295,6.30584072685296,0.912046473288893,100,-1.07765769733936E-5,,,,,,,,,,,,,,,,,,,,,300.002288818359,300.002380371094,16536.080078125,16725.716796875,49.9448899360726,5.39925307123837,7.83067512512207,24,1,68,0,0,0.2734375,31.2805480957031,1,6,1,300.002380371094,0,300.002334594727,,,,,,,,,,,,,,,,,,,,,,,,,,,,,,,,,
,3865790758.5116,300.001373291016,14789.091796875,0.00432210573639207,3.23007084061641E-6,1,2,12.9061126708984,4.99396673867821,43.7299981713295,5.63613995529269,0.812327687657583,100,-1.17772244512249E-5,,,,,,,,,,,,,,,,,,,,,300.001281738281,300.00146484375,14729.2275390625,14848.9560546875,49.9468440073707,5.39908799202864,7.87674856185913,26,1,0,0,1,0.272750854492187,31.2805480957031,1,6,1,300.001281738281,0,300.001373291016,,,,,,,,,,,,,,,,,,,,,,,,,,,,,,,,,
,3865790776.65396,300.001022338867,12982.4345703125,0.00380576891134424,3.28486182983471E-6,1,2,12.9061126708984,4.99382199232011,43.7299981713295,4.96272962650752,0.714517854882625,100,-1.09354582276816E-5,,,,,,,,,,,,,,,,,,,,,300.000946044922,300.001098632812,12922.5400390625,13042.3291015625,49.9808448479572,5.39954100889474,7.91329288482666,26,1,0,0,1,0.272140502929687,31.2805480957031,1,6,1,300.000946044922,0,300.001022338867,,,,,,,,,,,,,,,,,,,,,,,,,,,,,,,,,
,3865790792.81954,300.001907348633,11363.8354492187,0.003347288869409,3.05347643535732E-6,1,2,12.9061126708984,4.99386971359566,43.7299981713295,4.36523971830099,0.626335547219086,100,-1.12390785768992E-5,,,,,,,,,,,,,,,,,,,,,300.001678466797,300.002136230469,11243.8134765625,11483.857421875,49.9523154070053,5.39934535110131,7.95532131195068,26,1,0,0,1,0.271072387695313,31.7693061828613,1,6,1,300.00244140625,0,300.001907348633,,,,,,,,,,,,,,,,,,,,,,,,,,,,,,,,,
,3865790808.59476,300.002182006836,9790.0205078125,0.00288819536395749,3.17085028561515E-6,1,2,12.9061126708984,4.99389760172968,43.7299981713295,3.76678207844057,0.53892275623358,100,-1.08581059214081E-5,,,,,,,,,,,,,,,,,,,,,300.002105712891,300.002258300781,9695.1201171875,9884.9208984375,49.9964774183418,5.39970732994402,7.99755477905273,26,1,0,0,1,0.271224975585938,31.2805480957031,1,6,1,300.002105712891,0,300.002182006836,,,,,,,,,,,,,,,,,,,,,,,,,,,,,,,,,
,3865790826.72565,300.002166748047,7976.58154296875,0.00237101062889045,3.05386435605514E-6,1,2,12.9061126708984,4.99404720341886,43.7299981713295,3.09293725736273,0.438780658860751,100,-1.17189104796098E-5,,,,,,,,,,,,,,,,,,,,,300.001983642578,300.002349853516,7876.72314453125,8076.43994140625,49.9319930655053,5.39955299486299,8.04765129089356,26,1,0,0,1,0.272979736328125,30.7917900085449,1,6,1,300.001983642578,0,300.002166748047,,,,,,,,,,,,,,,,,,,,,,,,,,,,,,,,,
,3865790844.86218,300.00146484375,6162.541015625,0.00185384987607902,3.00615020459395E-6,1,2,12.9061126708984,4.99389684375542,43.7299981713295,2.41883675078932,0.338787182698077,100,-1.24408836038352E-5,,,,,,,,,,,,,,,,,,,,,300.00146484375,300.00146484375,6067.6279296875,6257.4541015625,49.9812356622168,5.3996734634066,8.09279060363769,26,1,0,0,1,0.271682739257813,31.7693061828613,1,6,1,300.00146484375,0,300.00146484375,,,,,,,,,,,,,,,,,,,,,,,,,,,,,,,,,
,3865790862.9396,300.001876831055,4354.1162109375,0.00133459569053379,3.23947187413878E-6,1,2,12.9061126708984,4.99385301235548,43.7299981713295,1.74237336134833,0.236660934907834,100,-1.45035005657645E-5,,,,,,,,,,,,,,,,,,,,,300.001647949219,300.002105712891,4259.2470703125,4448.9853515625,50.0269609305918,5.39970176411263,8.1388578414917,26,1,0,0,1,0.270538330078125,31.2805480957031,1,6,1,300.001647949219,0,300.001876831055,,,,,,,,,,,,,,,,,,,,,,,,,,,,,,,,,
,3865790881.12308,300.000457763672,2539.71826171875,0.000812587608865469,3.07896527148595E-6,1,2,12.9061126708984,4.9938431221502,43.7299981713295,1.06258919053222,0.132363878866481,100,-1.78298731494532E-5,,,,,,,,,,,,,,,,,,,,,300.000274658203,300.000640869141,2449.81323242187,2629.62329101562,49.964821463313,5.40012910046478,8.18885231018066,26,1,0,0,1,0.271453857421875,31.7693061828613,1,6,1,300.000640869141,0,300.000457763672,,,,,,,,,,,,,,,,,,,,,,,,,,,,,,,,,
,3865790901.42667,300.000183105469,510.730331420898,0.000200495568882921,3.83819961232407E-6,1,2,12.9061126708984,4.99381124380182,43.7299981713295,0.266437659842589,0.00366330996092309,100,-2.66445176736828E-5,,,,,,,,,,,,,,,,,,,,,299.999816894531,300.000549316406,400.661773681641,620.798889160156,50.0226619737361,5.39986418053348,8.22910881042481,26,1,0,0,1,0.2740478515625,31.2805480957031,1,6,1,299.999816894531,0,300.000183105469,,,,,,,,,,,,,,,,,,,,,,,,,,,,,,,,,
,3865790919.51549,300.00032043457,-1298.23968505859,-0.00043153490184048,3.67517271292358E-6,1,2,12.9061126708984,4.99388327576109,43.7299981713295,-0.56023053178944,-0.0980473498962874,100,-1.18228222455244E-5,,,,,,,,,,,,,,,,,,,,,300.000152587891,300.00048828125,-1408.32080078125,-1188.15856933594,49.9515337784861,5.39994507951177,8.24534225463867,26,1,0,0,1,0.27252197265625,30.7917900085449,1,6,1,300.000152587891,0,300.00032043457,,,,,,,,,,,,,,,,,,,,,,,,,,,,,,,,,
,3865790935.47834,300.000534057617,-2892.50671386719,-0.000910174286970478,3.27054115551245E-6,1,2,12.9061126708984,4.99396003651248,43.7299981713295,-1.18498565022268,-0.184020598818394,100,-7.45942094568979E-6,,,,,,,,,,,,,,,,,,,,,300.00048828125,300.000579833984,-2987.48876953125,-2797.52465820313,49.9503613357072,5.39949537439346,8.24553680419922,26,1,0,0,1,0.270843505859375,31.7693061828613,1,6,1,300.00048828125,0,300.000534057617,,,,,,,,,,,,,,,,,,,,,,,,,,,,,,,,,
,3865790951.58747,299.999801635742,-4502.23022460937,-0.00137782054912408,4.1089326552776E-6,1,2,12.9061126708984,4.9939077916719,43.7299981713295,-1.79509602932512,-0.269766537744467,100,-4.54130314521006E-6,,,,,,,,,,,,,,,,,,,,,299.999694824219,299.999908447266,-4597.193359375,-4407.26708984375,49.9679479773899,5.39978145488528,8.22810935974121,26,1,0,0,1,0.27099609375,31.7693061828613,1,6,1,299.999694824219,0,299.999801635742,,,,,,,,,,,,,,,,,,,,,,,,,,,,,,,,,
,3865790970.12566,299.999969482422,-6356.296875,-0.00189571962921339,3.46465234897985E-6,1,2,12.9061126708984,4.99392378819148,43.7299981713295,-2.47045636093535,-0.367061078598534,100,-3.09696251474893E-6,,,,,,,,,,,,,,,,,,,,,299.999816894531,300.000122070313,-6406.263671875,-6306.330078125,49.9319930655053,5.39939764686819,8.21754264831543,26,1,0,0,1,0.2728271484375,31.2805480957031,1,6,1,299.999816894531,0,299.999969482422,,,,,,,,,,,,,,,,,,,,,,,,,,,,,,,,,
,3865790991.9,299.999984741211,-8531.412109375,-0.0025306973285211,3.26738189803208E-6,1,2,12.9061126708984,4.99385182301315,43.7299981713295,-3.29880684534713,-0.483673123434211,10,7.19235581227125E-7,,,,,,,,,,,,,,,,,,,,,299.999908447266,300.000061035156,-8626.375,-8436.44921875,49.9581776208995,5.39978994780209,8.1884183883667,26,1,0,0,1,0.271759033203125,31.2805480957031,1,6,1,300.000061035156,0,299.999984741211,,,,,,,,,,,,,,,,,,,,,,,,,,,,,,,,,
,3865791008.00104,300.000335693359,-10146.4946289062,-0.00299080003057011,3.14728161283729E-6,1,2,12.9061126708984,4.99391235281266,43.7299981713295,-3.89912216843096,-0.568233139125583,10,3.44739395892989E-6,,,,,,,,,,,,,,,,,,,,,300.000305175781,300.000366210937,-10236.3310546875,-10056.658203125,49.9898335759284,5.39940489573845,8.1731481552124,26,1,0,0,1,0.270309448242187,31.2805480957031,1,6,1,300.000366210937,0,300.000335693359,,,,,,,,,,,,,,,,,,,,,,,,,,,,,,,,,
,3865791034.18306,300.00114440918,-12762.1284179688,-0.00373613998892662,2.9687256869203E-6,1,2,12.9061126708984,4.99387830979143,43.7299981713295,-4.8702699715084,-0.713303435040642,10,1.64655653261166E-6,,,,,,,,,,,,,,,,,,,,,300.001098632812,300.001190185547,-12857.1171875,-12667.1396484375,49.9913968329668,5.39992367595415,8.151686668396,25,1,68,0,0,0.271530151367187,31.7693061828613,1,6,1,300.001190185547,0,300.00114440918,,,,,,,,,,,,,,,,,,,,,,,,,,,,,,,,,
,3865791061.62319,300.001373291016,-15507.0283203125,-0.00454040543257177,3.55737660523361E-6,1,2,12.9061126708984,4.99394776516477,43.7299981713295,-5.91913889524994,-0.864502124911227,10,3.81802883668199E-6,,,,,,,,,,,,,,,,,,,,,300.000885009766,300.001861572266,-15676.8037109375,-15337.2529296875,49.9480164501495,5.39881972681041,8.13810539245606,24,1,68,0,0,0.2716064453125,30.7917900085449,1,6,1,300.001861572266,0,300.001373291016,,,,,,,,,,,,,,,,,,,,,,,,,,,,,,,,,
,3865791079.83476,300.001022338867,-17327.048828125,-0.00505664493519558,3.49233104716958E-6,1,2,12.9061126708984,4.99392085436052,43.7299981713295,-6.59184101941828,-0.964477084259348,10,2.95621325475715E-6,,,,,,,,,,,,,,,,,,,,,300.001007080078,300.001037597656,-17486.83984375,-17167.2578125,49.9163604951207,5.39869263673823,8.12456703186035,25,1,64,0,0,0.271224975585938,31.7693061828613,1,6,1,300.001037597656,0,300.001022338867,,,,,,,,,,,,,,,,,,,,,,,,,,,,,,,,,
,3865791115.02358,300.001068115234,-20847.41796875,-0.00603178489562577,3.6500102513897E-6,1,2,12.9061126708984,4.99394535289655,43.7299981713295,-7.86325330341388,-1.14934801583674,10,4.39312172407439E-6,,,,,,,,,,,,,,,,,,,,,300.001007080078,300.001129150391,-20917.384765625,-20777.451171875,49.900727924736,5.39858502051548,8.10143947601318,24,1,68,0,0,0.2716064453125,31.2805480957031,1,6,1,300.001007080078,0,300.001068115234,,,,,,,,,,,,,,,,,,,,,,,,,,,,,,,,,
,3865791148.54055,300.0009765625,-24202.73828125,-0.00700632247201509,3.78704553961106E-6,1,2,12.9061126708984,4.99376247099508,43.7299981713295,-9.13313852583416,-1.33557672644544,10,4.64218019554165E-6,,,,,,,,,,,,,,,,,,,,,300.000915527344,300.001037597656,-24377.828125,-24027.6484375,49.9503613357072,5.39929266589256,8.08633422851562,25,1,68,0,0,0.272064208984375,31.2805480957031,1,6,1,300.000915527344,0,300.0009765625,,,,,,,,,,,,,,,,,,,,,,,,,,,,,,,,,
,3865791183.31009,300.001770019531,-27681.6025390625,-0.00797971512132842,3.42604272660233E-6,1,2,12.9061126708984,4.99378168700147,43.7299981713295,-10.4013674221757,-1.52590040308861,10,1.63295088091771E-6,,,,,,,,,,,,,,,,,,,,,300.001739501953,300.001800537109,-27771.720703125,-27591.484375,49.9308206227264,5.39929964791165,8.07716751098633,25,1,68,0,0,0.271759033203125,31.7693061828613,1,6,1,300.001739501953,0,300.001770019531,,,,,,,,,,,,,,,,,,,,,,,,,,,,,,,,,
,3865791213.67519,300.000122070313,-30721.748046875,-0.0088436935490342,3.48635018368773E-6,1,2,12.9061126708984,4.99402734670016,43.7299981713295,-11.5304536305801,-1.67682704751025,100,1.28582854280825E-5,,,,,,,,,,,,,,,,,,,,,300,300.000244140625,-30837.04296875,-30606.453125,49.9183145664187,5.39784014887647,8.06772708892822,24,1,68,0,0,0.272598266601562,31.2805480957031,1,6,1,300,0,300.000122070313,,,,,,,,,,,,,,,,,,,,,,,,,,,,,,,,,
,3865791231.79472,300.000228881836,-32534.9609375,-0.00936048390974259,3.27625843706407E-6,1,2,12.9061126708984,4.99392635066856,43.7299981713295,-12.2030153817671,-1.78079547092266,100,8.9823749557484E-6,,,,,,,,,,,,,,,,,,,,,300.000152587891,300.000305175781,-32640.2734375,-32429.6484375,49.910889095486,5.39837139184078,8.05728816986084,26,1,0,0,1,0.272750854492187,31.7693061828613,1,6,1,300.000305175781,0,300.000228881836,,,,,,,,,,,,,,,,,,,,,,,,,,,,,,,,,
,3865791249.82678,300.000183105469,-34343.25390625,-0.00988146910052355,3.63315239089951E-6,1,2,12.9061126708984,4.9939551946553,43.7299981713295,-12.8826071831854,-1.87793273709363,100,1.10115483440434E-5,,,,,,,,,,,,,,,,,,,,,300.000152587891,300.000213623047,-34443.5,-34243.0078125,49.9128431667841,5.39826799576216,8.05012893676758,26,1,0,0,1,0.271377563476562,31.7693061828613,1,6,1,300.000152587891,0,300.000183105469,,,,,,,,,,,,,,,,,,,,,,,,,,,,,,,,,
,3865791265.85875,300.000762939453,-35951.00390625,-0.0103419330499426,4.20981373296414E-6,1,2,12.9061126708984,4.99398290128487,43.7299981713295,-13.483036821653,-1.96537863818766,100,1.15850309087164E-5,,,,,,,,,,,,,,,,,,,,,300.000640869141,300.000885009766,-36046.13671875,-35855.87109375,49.8964289678803,5.39796835361964,8.04573440551758,26,1,0,0,1,0.272903442382813,31.7693061828613,1,6,1,300.000640869141,0,300.000762939453,,,,,,,,,,,,,,,,,,,,,,,,,,,,,,,,,
,3865791281.9738,299.999420166016,-37564.373046875,-0.010800693883147,3.9884085368057E-6,1,2,12.9061126708984,4.99402916989741,43.7299981713295,-14.0811381783754,-2.05381032810794,100,1.11613115250607E-5,,,,,,,,,,,,,,,,,,,,,299.999206542969,299.999633789063,-37659.375,-37469.37109375,49.8561750991399,5.39765443163454,8.04439067840576,26,1,0,0,1,0.272216796875,31.7693061828613,1,6,1,299.999206542969,0,299.999420166016,,,,,,,,,,,,,,,,,,,,,,,,,,,,,,,,,
,3865791300.11104,299.999755859375,-39382.6328125,-0.011315606539409,4.17417609823252E-6,1,2,12.9061126708984,4.99393158279444,43.7299981713295,-14.7511576859603,-2.15766112993603,100,7.09320533707731E-6,,,,,,,,,,,,,,,,,,,,,299.999572753906,299.999938964844,-39472.76953125,-39292.49609375,49.9085442099284,5.39825066420076,8.03390407562256,25,1,68,0,0,0.270843505859375,31.2805480957031,1,6,1,299.999938964844,0,299.999755859375,,,,,,,,,,,,,,,,,,,,,,,,,,,,,,,,,
,3865791318.60882,300.000457763672,-41236.515625,-0.0118303603136097,3.40198991778463E-6,1,2,12.9061126708984,4.99390303688854,43.7299981713295,-15.4223127342991,-2.25416545802904,100,8.66706573673265E-6,,,,,,,,,,,,,,,,,,,,,300.000305175781,300.000610351562,-41296.62890625,-41176.40234375,49.8393700859764,5.39833210015458,8.03157711029053,26,1,0,0,1,0.273513793945313,32.2580642700195,1,6,1,300.000610351562,0,300.000457763672,,,,,,,,,,,,,,,,,,,,,,,,,,,,,,,,,
,3865791336.72722,299.999633789063,-43049.525390625,-0.0123481854957908,3.80965499861524E-6,1,2,12.9061126708984,4.99398936894944,43.7299981713295,-16.09796131499,-2.35145795208202,100,1.01444867606594E-5,,,,,,,,,,,,,,,,,,,,,299.999603271484,299.999664306641,-43109.6015625,-42989.44921875,49.9175329378995,5.3980557889938,8.02653789520264,26,1,0,0,1,0.271835327148438,30.7917900085449,1,6,1,299.999664306641,0,299.999633789063,,,,,,,,,,,,,,,,,,,,,,,,,,,,,,,,,
,3865791354.8349,299.999801635742,-44862.669921875,-0.0128651139356572,3.28699695189947E-6,1,2,12.9061126708984,4.99394674015913,43.7299981713295,-16.7718005475839,-2.44894270036992,100,1.12782671991607E-5,,,,,,,,,,,,,,,,,,,,,299.999664306641,299.999938964844,-44922.7578125,-44802.58203125,49.863209755813,5.3980556388333,8.01803779602051,26,1,0,0,1,0.271377563476562,31.7693061828613,1,6,1,299.999938964844,0,299.999801635742,,,,,,,,,,,,,,,,,,,,,,,,,,,,,,,,,
,3865791370.96098,299.99983215332,-46485.31640625,-0.0133215140896656,3.78018782697063E-6,1,2,12.9061126708984,4.99390844004889,43.7299981713295,-17.3659619721907,-2.54018249394496,100,8.31133733324908E-6,,,,,,,,,,,,,,,,,,,,,299.999633789063,300.000030517578,-46605.60546875,-46365.02734375,49.8636005700726,5.398232136975,8.01770305633545,24,1,68,0,0,0.270233154296875,31.2805480957031,1,6,1,299.999633789063,0,299.99983215332,,,,,,,,,,,,,,,,,,,,,,,,,,,,,,,,,
,3865791389.05033,299.99983215332,-48293.640625,-0.0138381576129762,3.38702704546965E-6,1,2,12.9061126708984,4.99388005745841,43.7299981713295,-18.0392039402656,-2.6394399182321,100,8.04795776983114E-6,,,,,,,,,,,,,,,,,,,,,299.999633789063,300.000030517578,-48408.94921875,-48178.33203125,49.873370926563,5.3979263266719,8.01110935211182,26,1,0,0,1,0.27130126953125,30.7917900085449,1,6,1,299.999633789063,0,299.99983215332,,,,,,,,,,,,,,,,,,,,,,,,,,,,,,,,,
,3865791407.18316,300.000946044922,-49995.400390625,-0.0143337392929288,2.44630004146088E-6,1,2,12.9061126708984,4.99384102476362,43.7299981713295,-18.6854518523003,-2.73107480475215,100,1.05307975877388E-5,,,,,,,,,,,,,,,,,,,,,300.00048828125,300.001403808594,-49999.65234375,-49991.1484375,49.8768882548995,5.39824649719447,8.01291561126709,26,1,0,0,1,0.270462036132813,31.7693061828613,1,6,1,300.001403808594,0,300.000946044922,,,,,,,,,,,,,,,,,,,,,,,,,,,,,,,,,
,3865791425.26785,300.001007080078,-48908.662109375,-0.0140543933353399,3.94549380686352E-6,1,2,12.9061126708984,4.99385531301046,43.7299981713295,-18.329247183021,-2.62424291380604,100,5.14602222362267E-5,,,,,,,,,,,,,,,,,,,,,300.000885009766,300.001129150391,-49023.41796875,-48793.90625,49.7811387612937,5.39794594019038,8.00591468811035,25,1,68,0,0,0.271987915039062,32.2580642700195,1,6,1,300.000885009766,0,300.001007080078,,,,,,,,,,,,,,,,,,,,,,,,,,,,,,,,,
,3865791443.38553,299.999801635742,-47097.169921875,-0.0135331256809652,3.78026655248794E-6,1,2,12.9061126708984,4.99379919962376,43.7299981713295,-17.6477265797995,-2.53656127306851,100,4.21178136085504E-5,,,,,,,,,,,,,,,,,,,,,299.999603271484,300,-47206.8984375,-46987.44140625,49.8112314592841,5.39822761758663,8.00492572784424,25,1,68,0,0,0.271835327148438,31.7693061828613,1,6,1,299.999603271484,0,299.999801635742,,,,,,,,,,,,,,,,,,,,,,,,,,,,,,,,,
,3865791459.25204,300.000732421875,-45515.3515625,-0.0130764518685423,4.13464312951232E-6,1,2,12.9061126708984,4.99402214810776,43.7299981713295,-17.0522922475784,-2.45779858032804,100,3.5572109737156E-5,,,,,,,,,,,,,,,,,,,,,300.000732421875,300.000732421875,-45610.296875,-45420.40625,49.8780606976784,5.39779049047513,7.99643468856812,26,1,0,0,1,0.2703857421875,31.2805480957031,1,6,1,300.000732421875,0,300.000732421875,,,,,,,,,,,,,,,,,,,,,,,,,,,,,,,,,
,3865791477.43957,300.001495361328,-43699.142578125,-0.0125538255461403,3.66996862167728E-6,1,2,12.9061126708984,4.99400926238396,43.7299981713295,-16.3703641423709,-2.36187499429199,100,3.23738688215929E-5,,,,,,,,,,,,,,,,,,,,,300.001434326172,300.001556396484,-43784.08984375,-43614.1953125,49.8815780260149,5.39785425850728,7.99479818344116,26,1,0,0,1,0.27313232421875,32.7468223571777,1,6,1,300.001556396484,0,300.001495361328,,,,,,,,,,,,,,,,,,,,,,,,,,,,,,,,,
,3865791495.63704,300.000839233398,-41887.90234375,-0.0120387312093284,3.34346011303709E-6,1,2,12.9061126708984,4.99396634109043,43.7299981713295,-15.6984571752954,-2.26512543066996,100,3.09016899512623E-5,,,,,,,,,,,,,,,,,,,,,300.000732421875,300.000946044922,-41967.7734375,-41808.03125,49.829599729486,5.39770227757483,7.99361181259155,26,1,0,0,1,0.271224975585938,30.7917900085449,1,6,1,300.000946044922,0,300.000839233398,,,,,,,,,,,,,,,,,,,,,,,,,,,,,,,,,
,3865791513.64427,300.001373291016,-40085.732421875,-0.0115228229343551,3.56196736471968E-6,1,2,12.9061126708984,4.99391047262942,43.7299981713295,-15.0249610169446,-2.17154841509366,100,2.6871776543098E-5,,,,,,,,,,,,,,,,,,,,,300.001281738281,300.00146484375,-40180.5,-39990.96484375,49.8714168552649,5.39830446177282,7.98754549026489,26,1,0,0,1,0.271759033203125,32.2580642700195,1,6,1,300.001281738281,0,300.001373291016,,,,,,,,,,,,,,,,,,,,,,,,,,,,,,,,,
,3865791529.76024,300.001495361328,-38478.955078125,-0.0110657406157194,3.68346294636658E-6,1,2,12.9061126708984,4.99393424777842,43.7299981713295,-14.4292807570932,-2.08387702810865,100,2.69913252042744E-5,,,,,,,,,,,,,,,,,,,,,300.001403808594,300.001586914063,-38573.78125,-38384.12890625,49.7983345887168,5.39776007963609,7.99243402481079,26,1,0,0,1,0.272750854492187,31.7693061828613,1,6,1,300.001403808594,0,300.001495361328,,,,,,,,,,,,,,,,,,,,,,,,,,,,,,,,,
,3865791547.91039,300.001617431641,-36662.2578125,-0.0105468556182301,3.0637903280398E-6,1,2,12.9061126708984,4.99394247040103,43.7299981713295,-13.7523339174439,-1.98870811458835,100,2.37756587841914E-5,,,,,,,,,,,,,,,,,,,,,300.001586914063,300.001647949219,-36757.33984375,-36567.17578125,49.9347287653226,5.3978861402862,7.9902138710022,25,1,68,0,0,0.27252197265625,31.7693061828613,1,6,1,300.001586914063,0,300.001617431641,,,,,,,,,,,,,,,,,,,,,,,,,,,,,,,,,
,3865791566.36574,300.001907348633,-34825.6171875,-0.0100336465868937,3.9817321109194E-6,1,2,12.9061126708984,4.99391914170894,43.7299981713295,-13.0827350090314,-1.89414366856937,100,2.09169157866506E-5,,,,,,,,,,,,,,,,,,,,,300.001831054687,300.001983642578,-34880.515625,-34770.71875,49.888612682688,5.39790318818604,7.98668813705444,26,1,0,0,1,0.271377563476562,31.2805480957031,1,6,1,300.001983642578,0,300.001907348633,,,,,,,,,,,,,,,,,,,,,,,,,,,,,,,,,
,3865791584.51897,300.000503540039,-33009.0859375,-0.00951758111296389,3.14598783139638E-6,1,2,12.9061126708984,4.99390997996919,43.7299981713295,-12.4094298954315,-1.79931991104563,100,1.78439098066328E-5,,,,,,,,,,,,,,,,,,,,,300.000457763672,300.000549316406,-33064.109375,-32954.0625,49.9605225064572,5.39801203380411,7.97819375991821,26,1,0,0,1,0.271987915039062,31.2805480957031,1,6,1,300.000457763672,0,300.000503540039,,,,,,,,,,,,,,,,,,,,,,,,,,,,,,,,,
,3865791600.3591,299.999771118164,-31432.2060546875,-0.009061942023065,3.41252537952925E-6,1,2,12.9061126708984,4.99380971832577,43.7299981713295,-11.8158097411257,-1.70772574882146,100,2.11373896770531E-5,,,,,,,,,,,,,,,,,,,,,299.99951171875,300.000030517578,-31516.99609375,-31347.416015625,49.8983830391784,5.39828353066562,7.9780125617981,26,1,0,0,1,0.2716064453125,31.7693061828613,1,6,1,300.000030517578,0,299.999771118164,,,,,,,,,,,,,,,,,,,,,,,,,,,,,,,,,
,3865791616.50475,300.000686645508,-29820.3701171875,-0.00860247254536827,3.43821515834178E-6,1,2,12.9061126708984,4.99383606076315,43.7299981713295,-11.2165167741658,-1.62303301347159,100,1.86214684492953E-5,,,,,,,,,,,,,,,,,,,,,300.000640869141,300.000732421875,-29920.25390625,-29720.486328125,49.9577868066399,5.39828347691661,7.97628021240234,26,1,0,0,1,0.270843505859375,31.7693061828613,1,6,1,300.000732421875,0,300.000686645508,,,,,,,,,,,,,,,,,,,,,,,,,,,,,,,,,
,3865791632.50784,300.001190185547,-28223.564453125,-0.00814260278781211,3.81582609238537E-6,1,2,12.9061126708984,4.99373687257562,43.7299981713295,-10.6160630923907,-1.53994973724335,100,1.47693805709563E-5,,,,,,,,,,,,,,,,,,,,,300.000885009766,300.001495361328,-28313.35546875,-28133.7734375,49.9198778234572,5.3989178884868,7.974937915802,26,1,0,0,1,0.273513793945313,33.2355842590332,1,6,1,300.001495361328,0,300.001190185547,,,,,,,,,,,,,,,,,,,,,,,,,,,,,,,,,
,3865791650.65802,300.000213623047,-26407.04296875,-0.00762676377149078,3.80530651092202E-6,1,2,12.9061126708984,4.99383206863949,43.7299981713295,-9.94387952825755,-1.44185358920827,100,1.42771072840919E-5,,,,,,,,,,,,,,,,,,,,,300.000122070313,300.000305175781,-26496.853515625,-26317.232421875,49.9194870091976,5.39832215063482,7.97232246398926,26,1,0,0,1,0.272293090820313,31.7693061828613,1,6,1,300.000122070313,0,300.000213623047,,,,,,,,,,,,,,,,,,,,,,,,,,,,,,,,,
,3865791668.76669,300.001800537109,-24604.7041015625,-0.00711184327621902,3.53186075517277E-6,1,2,12.9061126708984,4.99380889881016,43.7299981713295,-9.27269356529717,-1.3428999879932,100,1.45393194390101E-5,,,,,,,,,,,,,,,,,,,,,300.001708984375,300.001892089844,-24699.478515625,-24509.9296875,49.9218318947553,5.39899812148764,7.96801042556763,24,1,68,0,0,0.273590087890625,31.7693061828613,1,6,1,300.001892089844,0,300.001800537109,,,,,,,,,,,,,,,,,,,,,,,,,,,,,,,,,
,3865791686.90169,299.999008178711,-22793.08984375,-0.00659827353900344,3.42420000243582E-6,1,2,12.9061126708984,4.99371503454731,43.7299981713295,-8.60301479509077,-1.24480362115937,100,1.43243295252926E-5,,,,,,,,,,,,,,,,,,,,,299.998687744141,299.999328613281,-22882.92578125,-22703.25390625,49.9202686377168,5.39899961388277,7.96749401092529,26,1,0,0,1,0.272216796875,31.2805480957031,1,6,1,299.999328613281,0,299.999008178711,,,,,,,,,,,,,,,,,,,,,,,,,,,,,,,,,
,3865791703.36523,300,-21150.5537109375,-0.0061388900616558,3.30963302541749E-6,1,2,12.9061126708984,4.99393899433347,43.7299981713295,-8.00438816277704,-1.15938801921632,100,1.24240939206841E-5,,,,,,,,,,,,,,,,,,,,,299.999969482422,300.000030517578,-21205.302734375,-21095.8046875,49.9980406753803,5.39833638991663,7.97225952148438,26,1,0,0,1,0.271377563476562,31.7693061828613,1,6,1,300.000030517578,0,300,,,,,,,,,,,,,,,,,,,,,,,,,,,,,,,,,
,3865791719.50532,299.999328613281,-19538.341796875,-0.00567998802873396,2.83132925627814E-6,1,2,12.9061126708984,4.99392240060743,43.7299981713295,-7.40603998321203,-1.07243983940192,100,1.17064396359667E-5,,,,,,,,,,,,,,,,,,,,,299.999176025391,299.999481201172,-19658.099609375,-19418.583984375,49.9503613357072,5.39841517105743,7.96200466156006,26,1,0,0,1,0.27099609375,32.2580642700195,1,6,1,299.999481201172,0,299.999328613281,,,,,,,,,,,,,,,,,,,,,,,,,,,,,,,,,
,3865791737.57742,299.998687744141,-17731.546875,-0.00516413010254625,3.5457862440806E-6,1,2,12.9061126708984,4.99387704986124,43.7299981713295,-6.73333896807308,-0.975006894275736,100,1.06595799958631E-5,,,,,,,,,,,,,,,,,,,,,299.998321533203,299.999053955078,-17851.2734375,-17611.8203125,49.9366828366207,5.39860790388389,7.95924854278564,24,1,68,0,0,0.27069091796875,31.2805480957031,1,6,1,299.998321533203,0,299.998687744141,,,,,,,,,,,,,,,,,,,,,,,,,,,,,,,,,
,3865791755.63201,299.998321533203,-15929.765625,-0.00464604520358009,3.36761783925263E-6,1,2,12.9061126708984,4.9937413168429,43.7299981713295,-6.05818450737986,-0.87313938291992,100,1.26726178749369E-5,,,,,,,,,,,,,,,,,,,,,299.998291015625,299.998352050781,-16044.53515625,-15814.99609375,49.9929600900053,5.39928297712946,7.95762586593628,26,1,0,0,1,0.272064208984375,31.7693061828613,1,6,1,299.998352050781,0,299.998321533203,,,,,,,,,,,,,,,,,,,,,,,,,,,,,,,,,
,3865791773.73813,299.999938964844,-14123.24609375,-0.00413069035467351,3.40333518591247E-6,1,2,12.9061126708984,4.99391810674039,43.7299981713295,-5.38674106710847,-0.774398577396988,100,1.27458916586815E-5,,,,,,,,,,,,,,,,,,,,,299.999725341797,300.000152587891,-14237.9716796875,-14008.5205078125,50.0046845177938,5.39853350803865,7.95879793167114,26,1,0,0,1,0.2716064453125,31.2805480957031,1,6,1,299.999725341797,0,299.999938964844,,,,,,,,,,,,,,,,,,,,,,,,,,,,,,,,,
,3865791791.81082,299.999649047852,-12321.2778320312,-0.00361465324307206,3.48048968823863E-6,1,2,12.9061126708984,4.99397924796881,43.7299981713295,-4.71380980706073,-0.678072929917277,100,1.0841765160055E-5,,,,,,,,,,,,,,,,,,,,,299.999298095703,300,-12431.30859375,-12211.2470703125,49.9702928629476,5.39862966686106,7.96079397201538,26,1,0,0,1,0.271148681640625,31.7693061828613,1,6,1,299.999298095703,0,299.999649047852,,,,,,,,,,,,,,,,,,,,,,,,,,,,,,,,,
,3865791809.90934,299.999725341797,-10507.32421875,-0.00309812886579563,3.16495362642935E-6,1,2,12.9061126708984,4.99391227767347,43.7299981713295,-4.04056268147179,-0.578309730417204,100,1.14846636399235E-5,,,,,,,,,,,,,,,,,,,,,299.999633789063,299.999816894531,-10612.359375,-10402.2890625,49.9476256358899,5.39875620113214,7.95085763931274,26,1,0,0,1,0.271224975585938,31.7693061828613,1,6,1,299.999633789063,0,299.999725341797,,,,,,,,,,,,,,,,,,,,,,,,,,,,,,,,,
,3865791825.92394,300.000259399414,-8913.87890625,-0.00263873750612499,3.19746864871443E-6,1,2,12.9061126708984,4.99389368645626,43.7299981713295,-3.44168097532139,-0.490704104227223,100,1.12018666096253E-5,,,,,,,,,,,,,,,,,,,,,300.000213623047,300.000305175781,-9003.796875,-8823.9609375,50.010546731688,5.39905764536562,7.95021629333496,26,1,0,0,1,0.27008056640625,31.2805480957031,1,6,1,300.000305175781,0,300.000259399414,,,,,,,,,,,,,,,,,,,,,,,,,,,,,,,,,
,3865791842.02208,299.999481201172,-7300.15014648438,-0.00217871401995954,3.32968058193167E-6,1,2,12.9061126708984,4.99389179317787,43.7299981713295,-2.84204167943862,-0.402661737075346,100,1.11634133867975E-5,,,,,,,,,,,,,,,,,,,,,299.999267578125,299.999694824219,-7395.3828125,-7204.91748046875,49.9593500636784,5.39906038523185,7.95157098770142,26,1,0,0,1,0.273208618164062,33.7243423461914,1,6,1,299.999267578125,0,299.999481201172,,,,,,,,,,,,,,,,,,,,,,,,,,,,,,,,,
,3865791858.35292,299.998764038086,-5666.48974609375,-0.00171520572880846,3.16395520590952E-6,1,2,12.9061126708984,4.993929610256,43.7299981713295,-2.23823792478752,-0.311557514757114,100,1.2964732725741E-5,,,,,,,,,,,,,,,,,,,,,299.998748779297,299.998779296875,-5736.43798828125,-5596.54150390625,49.9835805477745,5.39905784501999,7.94613552093506,24,1,68,0,0,0.271453857421875,30.7917900085449,1,6,1,299.998748779297,0,299.998764038086,,,,,,,,,,,,,,,,,,,,,,,,,,,,,,,,,
,3865791876.4531,299.999145507812,-3863.22338867188,-0.00119869245033493,3.44421599158524E-6,1,2,12.9061126708984,4.99397339708828,43.7299981713295,-1.56548388849047,-0.20926546322221,100,1.55607063968876E-5,,,,,,,,,,,,,,,,,,,,,299.999084472656,299.999206542969,-3938.12353515625,-3788.3232421875,49.9687296059091,5.39861712114019,7.95549869537353,26,1,0,0,1,0.2734375,31.2805480957031,1,6,1,299.999084472656,0,299.999145507812,,,,,,,,,,,,,,,,,,,,,,,,,,,,,,,,,
,3865791894.57888,300.000244140625,-2049.45239257813,-0.000673635376710803,3.139818501156E-6,1,2,12.9061126708984,4.99391660373774,43.7299981713295,-0.882182394239868,-0.101036533499907,100,2.14518706947187E-5,,,,,,,,,,,,,,,,,,,,,299.999877929687,300.000610351562,-2119.40087890625,-1979.50390625,49.9683387916495,5.39893250813206,7.94298267364502,26,1,0,0,1,0.27099609375,31.7693061828613,1,6,1,300.000610351562,0,300.000244140625,,,,,,,,,,,,,,,,,,,,,,,,,,,,,,,,,
,3865791912.63052,299.999954223633,-245.490272521973,-0.00011291866788027,4.19514177280762E-6,1,2,12.9061126708984,4.9939371284066,43.7299981713295,-0.153488967666249,0.021260774076039,100,3.28995959145087E-5,,,,,,,,,,,,,,,,,,,,,299.999877929687,300.000030517578,-330.399932861328,-160.580612182617,49.9632582062745,5.39857504821043,7.94483232498169,25,1,68,0,0,0.27374267578125,31.7693061828613,1,6,1,300.000030517578,0,299.999954223633,,,,,,,,,,,,,,,,,,,,,,,,,,,,,,,,,
,3865791928.69026,299.999938964844,1358.80529785156,0.000454900993068534,3.60502871278351E-6,1,2,12.9061126708984,4.99388458006611,43.7299981713295,0.590306290480012,0.105119024944728,100,1.38153099641178E-5,,,,,,,,,,,,,,,,,,,,,299.999694824219,300.000183105469,1258.6962890625,1458.91430664062,49.9722469342457,5.39864988309237,7.94583129882813,26,1,0,0,1,0.271148681640625,30.3030319213867,1,6,1,300.000183105469,0,299.999938964844,,,,,,,,,,,,,,,,,,,,,,,,,,,,,,,,,
,3865791946.80197,300.001617431641,3172.95874023438,0.000992322168753005,3.33380593419918E-6,1,2,12.9061126708984,4.99391947056333,43.7299981713295,1.29184120275101,0.201176720927367,100,8.55431593970337E-6,,,,,,,,,,,,,,,,,,,,,300.001586914063,300.001647949219,3077.87036132812,3268.04711914063,49.9855346190726,5.39881537457005,7.93904399871826,26,1,0,0,1,0.271530151367187,31.7693061828613,1,6,1,300.001586914063,0,300.001617431641,,,,,,,,,,,,,,,,,,,,,,,,,,,,,,,,,
,3865791964.99934,300.000427246094,4988.0400390625,0.00151726040245834,3.99786083444073E-6,1,2,12.9061126708984,4.99392559773552,43.7299981713295,1.97688238373989,0.296340914550305,100,4.44213104200163E-6,,,,,,,,,,,,,,,,,,,,,300.000183105469,300.000671386719,4907.900390625,5068.1796875,49.8678995269284,5.39915217947245,7.94388055801392,26,1,0,0,1,0.272369384765625,31.7693061828613,1,6,1,300.000671386719,0,300.000427246094,,,,,,,,,,,,,,,,,,,,,,,,,,,,,,,,,
,3865791981.02494,300.000915527344,6592.36669921875,0.00197658855212074,3.17449649935077E-6,1,2,12.9061126708984,4.99396944984747,43.7299981713295,2.57581396234693,0.383145446354615,100,3.55213798211244E-6,,,,,,,,,,,,,,,,,,,,,300.000518798828,300.001312255859,6497.40966796875,6687.32373046875,50.0121099887264,5.39866124054392,7.94028759002686,26,1,0,0,1,0.270462036132813,31.7693061828613,1,6,1,300.001312255859,0,300.000915527344,,,,,,,,,,,,,,,,,,,,,,,,,,,,,,,,,
,3865792001.18197,299.999984741211,8608.05419921875,0.00255131842272259,3.06846312614316E-6,1,2,12.9061126708984,4.99387050525344,43.7299981713295,3.32567850883271,0.487791969531251,10,-5.90736622846326E-7,,,,,,,,,,,,,,,,,,,,,299.999694824219,300.000274658203,8517.9677734375,8698.140625,49.9402001649572,5.39897631164029,7.94351100921631,26,1,0,0,1,0.270843505859375,32.2580642700195,1,6,1,300.000274658203,0,299.999984741211,,,,,,,,,,,,,,,,,,,,,,,,,,,,,,,,,
,3865792019.31364,300.000686645508,10423.123046875,0.0030695885974421,3.20265216748525E-6,1,2,12.9061126708984,4.99385980590345,43.7299981713295,4.00128385950251,0.586572384115875,10,-9.46259090155695E-7,,,,,,,,,,,,,,,,,,,,,300.000274658203,300.001098632812,10328.1162109375,10518.1298828125,49.9491888929284,5.39878218497123,7.93476438522339,26,1,0,0,1,0.270919799804687,31.2805480957031,1,6,1,300.001098632812,0,300.000686645508,,,,,,,,,,,,,,,,,,,,,,,,,,,,,,,,,
,3865792037.45198,300.00065612793,12233.5029296875,0.00358693415885007,2.92894459318981E-6,1,2,12.9061126708984,4.99389660653743,43.7299981713295,4.67589054664555,0.684175319057166,10,-2.07583962471666E-6,,,,,,,,,,,,,,,,,,,,,300.000549316406,300.000762939453,12138.52734375,12328.478515625,49.9382460936591,5.39894697898335,7.93991661071777,26,1,0,0,1,0.273971557617187,31.7693061828613,1,6,1,300.000762939453,0,300.00065612793,,,,,,,,,,,,,,,,,,,,,,,,,,,,,,,,,
,3865792079.33947,300.001098632812,16424.0869140625,0.00473786711706965,3.52574646103481E-6,1,2,12.9061126708984,4.99395030029144,43.7299981713295,6.17707674079117,0.898622840451878,100,-6.65152636266783E-6,,,,,,,,,,,,,,,,,,,,,300.001098632812,300.001098632812,16419.0859375,16429.087890625,49.9233951517937,5.39872046949346,7.93499422073364,26,1,0,0,1,0.27130126953125,31.7693061828613,1,6,1,300.001098632812,0,300.001098632812,,,,,,,,,,,,,,,,,,,,,,,,,,,,,,,,,
,3865792109.94584,300.001098632812,19484.9580078125,0.00565349411140669,3.5103069046092E-6,1,2,12.9061126708984,4.99398083896456,43.7299981713295,7.370265923617,1.07664462694691,10,-4.60195044725519E-6,,,,,,,,,,,,,,,,,,,,,300.001098632812,300.001098632812,19389.9765625,19579.939453125,49.9061993243707,5.39818318135404,7.93312168121338,25,1,68,0,0,0.271835327148438,31.2805480957031,1,6,1,300.001098632812,0,300.001098632812,,,,,,,,,,,,,,,,,,,,,,,,,,,,,,,,,
,3865792142.27729,300.000411987305,22721.001953125,0.00657693412942129,3.53323595433062E-6,1,2,12.9061126708984,4.99390149881276,43.7299981713295,8.57442082089226,1.24914761840143,100,-7.90672866920228E-6,,,,,,,,,,,,,,,,,,,,,300.000335693359,300.00048828125,22641,22801.00390625,49.9398093506976,5.39843611578034,7.93407773971558,26,1,0,0,1,0.27252197265625,31.7693061828613,1,6,1,300.000335693359,0,300.000411987305,,,,,,,,,,,,,,,,,,,,,,,,,,,,,,,,,
,3865792158.38575,300.000457763672,24331.078125,0.00703181226208239,3.74833692021057E-6,1,2,12.9061126708984,4.99393449577195,43.7299981713295,9.16776514573266,1.33399015489953,100,-9.65357486491216E-6,,,,,,,,,,,,,,,,,,,,,300.000152587891,300.000762939453,24240.953125,24421.203125,49.9065901386303,5.39842987667897,7.92446517944336,24,1,68,0,0,0.27191162109375,29.3255138397217,1,6,1,300.000762939453,0,300.000457763672,,,,,,,,,,,,,,,,,,,,,,,,,,,,,,,,,
,3865792176.48241,300.000061035156,26142.029296875,0.00754999033305309,3.86262124250066E-6,1,2,12.9061126708984,4.99388458653144,43.7299981713295,9.84306481510396,1.43322538340344,100,-9.633951147206E-6,,,,,,,,,,,,,,,,,,,,,299.999664306641,300.000457763672,26041.73828125,26242.3203125,49.9327746940245,5.39859251974273,7.92947626113892,26,1,0,0,1,0.27069091796875,31.7693061828613,1,6,1,299.999633789063,0,300.000061035156,,,,,,,,,,,,,,,,,,,,,,,,,,,,,,,,,
,3865792194.58507,300.000366210937,27955.63671875,0.00806675298577269,3.54926237904139E-6,1,2,12.9061126708984,4.99392794955163,43.7299981713295,10.5171233900158,1.52986269115213,100,-1.14280942628498E-5,,,,,,,,,,,,,,,,,,,,,300.000305175781,300.000427246094,27855.345703125,28055.927734375,49.9273032943899,5.39833290940029,7.92974901199341,26,1,0,0,1,0.273208618164062,30.7917900085449,1,6,1,300.000305175781,0,300.000366210937,,,,,,,,,,,,,,,,,,,,,,,,,,,,,,,,,
,3865792212.69874,299.999725341797,29774.1328125,0.00858401383479463,3.68478539058926E-6,1,2,12.9061126708984,4.993910835368,43.7299981713295,11.1910723881412,1.63055441231022,100,-1.01655997407511E-5,,,,,,,,,,,,,,,,,,,,,299.999633789063,299.999816894531,29678.83203125,29869.43359375,49.9210502662361,5.39846480271975,7.92698287963867,26,1,0,0,1,0.273818969726562,31.2805480957031,1,6,1,299.999816894531,0,299.999725341797,,,,,,,,,,,,,,,,,,,,,,,,,,,,,,,,,
,3865792230.86014,299.999145507812,31592.6611328125,0.00910207423654768,3.5283438449124E-6,1,2,12.9061126708984,4.99391198437111,43.7299981713295,11.8669969949615,1.72542370442657,100,-1.34934556720355E-5,,,,,,,,,,,,,,,,,,,,,299.998779296875,299.99951171875,31502.318359375,31683.00390625,49.8839229115726,5.39883688630146,7.920334815979,26,1,0,0,1,0.271377563476562,31.7693061828613,1,6,1,299.99951171875,0,299.999145507812,,,,,,,,,,,,,,,,,,,,,,,,,,,,,,,,,
,3865792246.9417,300.000640869141,33201.4765625,0.00956080203446728,3.3570408503006E-6,1,2,12.9061126708984,4.9938521032711,43.7299981713295,12.4645482023789,1.81448886428141,100,-1.25336736156104E-5,,,,,,,,,,,,,,,,,,,,,300.000396728516,300.000885009766,33106.29296875,33296.66015625,49.9605225064572,5.39901000371347,7.92720031738281,26,1,0,0,1,0.270156860351562,32.2580642700195,1,6,1,300.000396728516,0,300.000640869141,,,,,,,,,,,,,,,,,,,,,,,,,,,,,,,,,
,3865792263.43143,299.999298095703,34854.79296875,0.0100215119130074,3.82995671090728E-6,1,2,12.9061126708984,4.99389107455218,43.7299981713295,13.0654560255419,1.90105284606275,100,-1.3822171306521E-5,,,,,,,,,,,,,,,,,,,,,299.999267578125,299.999328613281,34799.63671875,34909.94921875,49.8768882548995,5.3984498221083,7.92003774642944,26,1,0,0,1,0.271377563476562,31.2805480957031,1,6,1,299.999267578125,0,299.999298095703,,,,,,,,,,,,,,,,,,,,,,,,,,,,,,,,,
,3865792279.58578,299.998443603516,36472.919921875,0.0104813452680953,3.16727308954064E-6,1,2,12.9061126708984,4.99385410143699,43.7299981713295,13.6641485197924,1.99281668701512,100,-1.09615692549065E-5,,,,,,,,,,,,,,,,,,,,,299.998291015625,299.998596191406,36362.74609375,36583.09375,49.9101074669668,5.3985548220858,7.92607593536377,26,1,0,0,1,0.272979736328125,31.2805480957031,1,6,1,299.998596191406,0,299.998443603516,,,,,,,,,,,,,,,,,,,,,,,,,,,,,,,,,
,3865792297.63528,300.000183105469,38281.986328125,0.0109993856202046,3.33932253501955E-6,1,2,12.9061126708984,4.9939119463816,43.7299981713295,14.3398831383258,2.09031545677341,100,-1.22936404643235E-5,,,,,,,,,,,,,,,,,,,,,299.999969482422,300.000396728516,38166.83984375,38397.1328125,49.9183145664187,5.39836708892971,7.91500186920166,26,1,0,0,1,0.271835327148438,31.7693061828613,1,6,1,300.000396728516,0,300.000183105469,,,,,,,,,,,,,,,,,,,,,,,,,,,,,,,,,
,3865792315.72239,300.000366210937,40095.57421875,0.0115156758212294,3.3953224109303E-6,1,2,12.9061126708984,4.9938472433163,43.7299981713295,15.0125414708077,2.18945088237572,100,-1.20576432988139E-5,,,,,,,,,,,,,,,,,,,,,299.999938964844,300.000793457031,39980.34765625,40210.80078125,49.9300389942072,5.39865258633719,7.91995286941528,26,1,0,0,1,0.271377563476562,31.2805480957031,1,6,1,299.999938964844,0,300.000366210937,,,,,,,,,,,,,,,,,,,,,,,,,,,,,,,,,
,3865792333.76787,300.001098632812,41904.369140625,0.0120339373443875,3.23044435815146E-6,1,2,12.9061126708984,4.99383513354761,43.7299981713295,15.687482493373,2.29235685354736,100,-9.24169233021417E-6,,,,,,,,,,,,,,,,,,,,,300.000579833984,300.001617431641,41794.19140625,42014.546875,49.8710260410053,5.3988686983261,7.91383171081543,26,1,0,0,1,0.272216796875,31.7693061828613,1,6,1,300.000579833984,0,300.001098632812,,,,,,,,,,,,,,,,,,,,,,,,,,,,,,,,,
,3865792351.88668,300.000457763672,43717.958984375,0.01254947669539,3.47719170810652E-6,1,2,12.9061126708984,4.99376354262643,43.7299981713295,16.3594123195948,2.38915425292968,100,-1.06811285211963E-5,,,,,,,,,,,,,,,,,,,,,300.000457763672,300.000457763672,43607.77734375,43828.140625,49.8104498307649,5.39919018315094,7.92401218414307,26,1,0,0,1,0.271835327148438,32.2580642700195,1,6,1,300.000457763672,0,300.000457763672,,,,,,,,,,,,,,,,,,,,,,,,,,,,,,,,,
,3865792369.9735,299.999649047852,45531.66015625,0.0130660070154422,3.68331918334588E-6,1,2,12.9061126708984,4.99375204799709,43.7299981713295,17.032874382034,2.48631434340444,100,-1.20170888214255E-5,,,,,,,,,,,,,,,,,,,,,299.999542236328,299.999755859375,45421.51171875,45641.80859375,49.8675087126687,5.39901580540972,7.9171199798584,26,1,0,0,1,0.272445678710938,31.7693061828613,1,6,1,299.999755859375,0,299.999649047852,,,,,,,,,,,,,,,,,,,,,,,,,,,,,,,,,
,3865792388.08903,299.999496459961,47345.091796875,0.0135818916647925,3.72866724535611E-6,1,2,12.9061126708984,4.99371745187574,43.7299981713295,17.7049365879239,2.58632206112202,100,-1.1060107164757E-5,,,,,,,,,,,,,,,,,,,,,299.999450683594,299.999542236328,47234.765625,47455.41796875,49.8096682022457,5.39888605411674,7.91995811462402,26,1,0,0,1,0.274124145507813,31.7693061828613,1,6,1,299.999542236328,0,299.999496459961,,,,,,,,,,,,,,,,,,,,,,,,,,,,,,,,,
,3865792404.07916,300.001113891602,48948.9609375,0.0140385963520505,3.61711696970315E-6,1,2,12.9061126708984,4.99384717264095,43.7299981713295,18.3011191654185,2.67223173070545,100,-1.23184073259699E-5,,,,,,,,,,,,,,,,,,,,,300.000915527344,300.001312255859,48858.7734375,49039.1484375,49.8780606976784,5.39887659483907,7.91226100921631,26,1,0,0,1,0.2716064453125,31.7693061828613,1,6,1,300.000915527344,0,300.001113891602,,,,,,,,,,,,,,,,,,,,,,,,,,,,,,,,,
,3865792416.8997,299.999938964844,50000.20703125,0.0143410926841,1.8551290566808E-6,1,2,12.9061126708984,4.99376575720545,43.7299981713295,18.6944883259252,2.73346819960601,100,-9.73057879652945E-6,,,,,,,,,,,,,,,,,,,,,299.999755859375,300.000122070313,50000.17578125,50000.23828125,49.8901759397264,5.39911015979521,7.91859579086304,26,1,0,0,1,0.271453857421875,31.7693061828613,1,4,1,300.000122070313,0,299.999938964844,,,,,,,,,,,,,,,,,,,,,,,,,,,,,,,,,