File: LT data/Bridport/D2/378-FC-ZFC-RTSIRM-contsweepwithloop-MsT.dat
[Header]
; MPMS3 Data File (default extension .dat)
; Copyright (c) 2007, Quantum Design, Inc. All rights reserved.
TITLE,
FILEOPENTIME,3866083946.14096,07/04/2022,9:10 am
BYAPP,MPMS3 w/ AC,1.0,1.1
INFO,MPMS3 Measurement Release 1.1.16 Build 424, MultiVu Release 2.3.4.19,APPNAME
INFO,Linear Motor Servo Controller,MOTOR_MODULE_NAME
INFO,3101-100 N2,MOTOR_HW_VERSION
INFO,,MOTOR_SERIAL_NUMBER
INFO,01.04.28,MOTOR_SOFTWARE_VERSION
INFO,Quantum Design Squid Module,SQUID_MODULE_NAME
INFO,3101-501 B0,SQUID_HW_VERSION
INFO,SQM327,SQUID_SERIAL_NUMBER
INFO,01.03.04,SQUID_SOFTWARE_VERSION
INFO,Quantum Design VSM Oven,OVEN_MODULE_NAME
INFO,3101-201 A3,OVEN_HW_VERSION
INFO,OVB365,OVEN_SERIAL_NUMBER
INFO,01.07.07,OVEN_SOFTWARE_VERSION
INFO,SQUID AC,AC_MODULE_NAME
INFO,3101-401 G0,AC_HW_VERSION
INFO,SAC220,AC_SERIAL_NUMBER
INFO,SQUID AC 00.95.07,AC_SOFTWARE_VERSION
INFO,TCI344,COIL_SERIAL_NUMBER
INFO,0,MOMENT_UNITS
INFO,sndst,SAMPLE_MATERIAL
INFO,,SAMPLE_COMMENT
INFO,123.03,SAMPLE_MASS
INFO,,SAMPLE_VOLUME
INFO,,SAMPLE_MOLECULAR_WEIGHT
INFO,,SAMPLE_SIZE
INFO,,SAMPLE_SHAPE
INFO,Straw,SAMPLE_HOLDER
INFO,Standard,SAMPLE_HOLDER_DETAIL
INFO,59.79,SAMPLE_OFFSET
DATATYPE,COMMENT,1
DATATYPE,TIME,2
STARTUPAXIS,X,2
STARTUPAXIS,Y1,5
FIELDGROUP, VSM,2,3,4,5,6,8,9,10,11,14,15
FIELDGROUP, DC, 2,3,4,14,56,57,58,59,60,61,62,63,64,65,66,67,68,69
FIELDGROUP, AC, 2,3,4,11,16,17,18,19,20,21,22,23,24,25,26,27,28,29,30
STARTUPGROUP, All
[Data]
Comment,Time Stamp (sec),Temperature (K),Magnetic Field (Oe),Moment (emu),M. Std. Err. (emu),Transport Action,Averaging Time (sec),Frequency (Hz),Peak Amplitude (mm),Center Position (mm),Lockin Signal' (V),Lockin Signal (V),Range,M. Quad. Signal (emu),AC Moment (emu),AC M. Std Err. (emu),AC Phase (deg),AC Phase Std. Err. (deg),AC Susceptibility (emu/Oe),AC Suscept. Std Err. (emu/Oe),AC X' (emu/Oe),AC X' Std Err. (emu/Oe),AC X'' (emu/Oe),AC X'' Std Err. (emu/Oe),AC Drive (Oe),AC Frequency (Hz),AC Averaging Time (sec),AC Cycles,AC Range,AC Measure Type,AC Signal' (V),AC Signal'' (V),AC Trim Coil Ratio,AC Trim Coil Phase,Min. Temperature (K),Max. Temperature (K),Min. Field (Oe),Max. Field (Oe),Mass (grams),Motor Lag (deg),Pressure (Torr),Measure Count,Measurement Number,SQUID Status (code),Motor Status (code),Measure Status (code),Motor Current (amps),Motor Temp. (C),Temp. Status (code),Field Status (code),Chamber Status (code),Chamber Temp (K),Redirection State,Average Temp (K),Rotation Angle (deg),Rotator state,DC Moment Fixed Ctr (emu),DC Moment Err Fixed Ctr (emu),DC Moment Free Ctr (emu),DC Moment Err Free Ctr (emu),DC Fixed Fit,DC Free Fit,DC Calculated Center (mm),DC Calculated Center Err (mm),DC Scan Length (mm),DC Scan Time (s),DC Number of Points,DC Squid Drift,DC Min V (V),DC Max V (V),DC Scans per Measure,Map 01,Map 02,Map 03,Map 04,Map 05,Map 06,Map 07,Map 08,Map 09,Map 10,Map 11,Map 12,Map 13,Map 14,Map 15,Map 16
,3866084950.10054,100.001998901367,49999.46484375,0.0461369492906702,2.49125715722832E-6,1,2,12.9061126708984,4.98631587976089,42.0500002801418,60.0192212060343,8.75663342173572,100,-4.57921456456274E-5,,,,,,,,,,,,,,,,,,,,,100.001998901367,100.001998901367,49999.46484375,49999.46484375,49.6302844570822,5.35078322061967,7.38684892654419,26,1,0,0,1,0.268402099609375,29.3255138397217,1,1,1,100.001998901367,0,100.001998901367,,,,,,,,,,,,,,,,,,,,,,,,,,,,,,,,,
,3866085037.04107,88.7330093383789,49999.46484375,0.0527096418917506,1.87705012578346E-5,1,2,12.9061126708984,4.9862635050626,42.0200005173683,68.566884815212,10.0154832338343,100,-4.34564901627912E-5,,,,,,,,,,,,,,,,,,,,,88.615348815918,88.8506698608398,49999.46484375,49999.46484375,49.6439629561687,5.35164339766233,7.33593511581421,25,1,64,0,0,0.26763916015625,30.3030319213867,2,1,1,88.615348815918,0,88.7330093383789,,,,,,,,,,,,,,,,,,,,,,,,,,,,,,,,,
,3866085119.50869,75.3003349304199,49999.46484375,0.0635505062742189,1.76631262841761E-5,1,2,12.9061126708984,4.98625714641734,41.9799983501434,82.6691665775437,12.0741038191179,100,-5.33598710488316E-5,,,,,,,,,,,,,,,,,,,,,75.1260070800781,75.4746627807617,49999.46484375,49999.46484375,49.6076172300245,5.3515683820874,7.28001165390015,25,1,64,0,0,0.267333984375,30.3030319213867,2,1,1,75.1260070800781,0,75.3003349304199,,,,,,,,,,,,,,,,,,,,,,,,,,,,,,,,,
,3866085216.16875,58.9674987792969,49999.46484375,0.0833025457236206,2.91878286549856E-5,1,2,12.9061126708984,4.98631390734357,41.9399999082088,108.356273535864,15.8877234492822,100,-2.33296379276626E-5,,,,,,,,,,,,,,,,,,,,,58.8150787353516,59.1199188232422,49999.46484375,49999.46484375,49.6889065960245,5.3518925051958,7.17320203781128,26,1,0,0,1,0.26702880859375,30.7917900085449,2,1,1,58.8150787353516,0,58.9674987792969,,,,,,,,,,,,,,,,,,,,,,,,,,,,,,,,,
,3866085326.95994,39.9772205352783,49999.46484375,0.122894173905795,0.000122765041845891,1,2,12.9061126708984,4.98637451908381,41.9000014662743,159.867133951261,23.37729114365,1000,-8.19851473827031E-5,,,,,,,,,,,,,,,,,,,,,39.8005523681641,40.1538887023926,49999.46484375,49999.46484375,49.6838260106495,5.35163155759353,6.95520210266113,26,1,0,0,1,0.2752685546875,30.3030319213867,2,1,1,39.8005523681641,0,39.9772205352783,,,,,,,,,,,,,,,,,,,,,,,,,,,,,,,,,
,3866085395.50993,28.4539594650269,49999.46484375,0.162032257833026,0.00022479981488325,1,2,12.9061126708984,4.98634691145455,41.8800003826618,210.731086606635,31.1437309215012,1000,0.000139244524942802,,,,,,,,,,,,,,,,,,,,,28.2948932647705,28.6130256652832,49999.46484375,49999.46484375,49.7104013803033,5.35200487408806,6.68389129638672,26,1,0,0,1,0.275955200195313,30.7917900085449,2,1,1,28.2948932647705,0,28.4539594650269,,,,,,,,,,,,,,,,,,,,,,,,,,,,,,,,,
,3866085466.25527,16.7615585327148,49999.46484375,0.219319676165977,0.000103590103600849,1,2,12.9061126708984,4.98627647884433,41.8599992990494,285.279022330739,41.8242814686209,1000,-6.49712457290599E-5,,,,,,,,,,,,,,,,,,,,,16.6806030273438,16.8425140380859,49999.46484375,49999.46484375,49.8424966000534,5.35217734301546,6.05711650848389,26,1,0,0,1,0.267486572265625,31.2805480957031,2,1,1,16.6806030273438,0,16.7615585327148,,,,,,,,,,,,,,,,,,,,,,,,,,,,,,,,,
,3866085534.43432,7.04726457595825,49999.46484375,0.28709323820743,0.000137552406846295,1,2,12.9061126708984,4.98643587033733,41.8399982154369,373.484170565575,54.5316632478293,1000,-0.000253797787227278,,,,,,,,,,,,,,,,,,,,,6.88241386413574,7.21211528778076,49999.46484375,49999.46484375,50.0980891258418,5.35439785367559,4.52658128738403,26,1,0,0,1,0.267486572265625,30.7917900085449,6,1,1,6.88241386413574,0,7.04726457595825,,,,,,,,,,,,,,,,,,,,,,,,,,,,,,,,,
,3866085605.17766,2.34282374382019,49999.46484375,0.315575517356013,2.91347613093359E-5,1,2,12.9061126708984,4.98654736143568,41.8399982154369,410.503168056239,60.2631243921839,1000,-3.33268464278522E-5,,,,,,,,,,,,,,,,,,,,,2.33915758132935,2.34648990631104,49999.46484375,49999.46484375,50.4724891865534,5.35638162055299,2.7915678024292,26,1,0,0,1,0.266494750976562,31.2805480957031,6,1,1,2.33915758132935,0,2.34282374382019,,,,,,,,,,,,,,,,,,,,,,,,,,,,,,,,,
,3866085673.43953,2.26508235931396,49999.46484375,0.315892176974739,4.07758369750541E-5,1,2,12.9061126708984,4.98658209760401,41.8399982154369,410.922702855702,60.299667593363,1000,-5.22079393334969E-5,,,,,,,,,,,,,,,,,,,,,2.26320505142212,2.26695966720581,49999.46484375,49999.46484375,50.5162603836303,5.35658873373326,2.73918700218201,26,1,0,0,1,0.268096923828125,31.2805480957031,6,1,1,2.26320505142212,0,2.26508235931396,,,,,,,,,,,,,,,,,,,,,,,,,,,,,,,,,
,3866085741.93549,2.20862364768982,49999.46484375,0.316149411929724,4.62649157716121E-5,1,2,12.9061126708984,4.98656058493622,41.8399982154369,411.257069849525,60.3331646270732,1000,-6.39664932720046E-5,,,,,,,,,,,,,,,,,,,,,2.20302295684814,2.21422433853149,49999.46484375,49999.46484375,50.4892941997169,5.35700433666928,2.69689893722534,26,1,0,0,1,0.2752685546875,30.7917900085449,2,1,1,2.21422433853149,0,2.20862364768982,,,,,,,,,,,,,,,,,,,,,,,,,,,,,,,,,
,3866085808.41724,2.07739567756653,49999.46484375,0.316548938292667,2.97179689737269E-5,1,2,12.9061126708984,4.98651324028515,41.8399982154369,411.7715435895,60.406919569124,1000,-6.53421327211149E-5,,,,,,,,,,,,,,,,,,,,,2.06825470924377,2.08653664588928,49999.46484375,49999.46484375,50.493202342313,5.35642594631911,2.61472129821777,26,1,0,0,1,0.267715454101562,30.7917900085449,2,1,1,2.06825470924377,0,2.07739567756653,,,,,,,,,,,,,,,,,,,,,,,,,,,,,,,,,
,3866085874.88832,1.99991500377655,49999.46484375,0.316806454200041,3.24796424002265E-5,1,2,12.9061126708984,4.98652230657013,41.8399982154369,412.113241913027,60.4176505330999,1000,-9.50429616936796E-5,,,,,,,,,,,,,,,,,,,,,1.99983847141266,1.99999153614044,49999.46484375,49999.46484375,50.5600315807073,5.3568326836828,2.54015421867371,26,1,0,0,1,0.267715454101562,29.3255138397217,5,1,1,1.99983847141266,0,1.99991500377655,,,,,,,,,,,,,,,,,,,,,,,,,,,,,,,,,
,3866086351.42189,25.1586074829102,26.4375095367432,0.000151740152518311,1.36932569354338E-7,1,5,12.9061126708984,4.99636591810918,41.8399982154369,0.197950384750243,0.0289199619571038,1,-1.2091053348301E-7,,,,,,,,,,,,,,,,,,,,,25.0240039825439,25.2932109832764,26.4375095367432,26.4375095367432,49.6549057554379,5.35240230900826,6.0434079170227,65,1,0,0,1,0.27679443359375,30.7917900085449,2,1,1,25.2932109832764,0,25.1586074829102,,,,,,,,,,,,,,,,,,,,,,,,,,,,,,,,,
,3866086548.36569,56.0034370422363,26.4375095367432,0.000101478562856174,2.31091845445044E-8,1,5,12.9061126708984,4.99632693048659,41.8700017035007,0.132390832709044,0.0192729779595529,1,-1.32594829242891E-7,,,,,,,,,,,,,,,,,,,,,56.0034370422363,56.0034370422363,26.4375095367432,26.4375095367432,49.7010218380726,5.35325771723795,6.74100399017334,65,1,0,0,1,0.275650024414062,31.2805480957031,2,1,1,56.0034370422363,0,56.0034370422363,,,,,,,,,,,,,,,,,,,,,,,,,,,,,,,,,
,3866086742.91781,87.0702896118164,26.4375095367432,7.83065757741154E-5,2.03444026569767E-8,1,5,12.9061126708984,4.99625740129835,41.9199988245964,0.102160399788202,0.014857069131947,1,-1.13630842874523E-7,,,,,,,,,,,,,,,,,,,,,87.0702896118164,87.0702896118164,26.4375095367432,26.4375095367432,49.7100105660437,5.3537161996567,6.99689388275146,65,1,0,0,1,0.27679443359375,31.7693061828613,2,1,1,87.0702896118164,0,87.0702896118164,,,,,,,,,,,,,,,,,,,,,,,,,,,,,,,,,
,3866086930.41991,118.03889465332,26.4375095367432,5.93888111701916E-5,2.05326217738798E-8,1,5,12.9061126708984,4.99631688831995,41.9799983501434,0.0774832534113621,0.0112538898562533,1,-9.6995915148792E-8,,,,,,,,,,,,,,,,,,,,,118.03889465332,118.03889465332,26.4375095367432,26.4375095367432,49.7447930351495,5.35302513810997,7.12213611602783,63,1,64,0,0,0.277633666992187,33.7243423461914,2,1,1,118.03889465332,0,118.03889465332,,,,,,,,,,,,,,,,,,,,,,,,,,,,,,,,,
,3866087117.56117,149.004302978516,26.4375095367432,4.52277638164112E-5,1.15127520070556E-8,1,5,12.9061126708984,4.99620279845714,42.0700013637543,0.0590058131248243,0.00856982560060831,1,-7.41287133578495E-8,,,,,,,,,,,,,,,,,,,,,149.004302978516,149.004302978516,26.4375095367432,26.4375095367432,49.7299420932841,5.35330529222165,7.21309566497803,64,1,64,0,0,0.266647338867187,31.2805480957031,2,1,1,149.004302978516,0,149.004302978516,,,,,,,,,,,,,,,,,,,,,,,,,,,,,,,,,
,3866087304.98977,180.017288208008,26.4375095367432,3.49168450628454E-5,9.41958010069824E-9,1,5,12.9061126708984,4.99604684037314,42.1800017356873,0.0455533614847808,0.0066052745493278,1,-6.53048124081517E-8,,,,,,,,,,,,,,,,,,,,,180.017288208008,180.017288208008,26.4375095367432,26.4375095367432,49.7404940782937,5.35461566091091,7.28598070144653,65,1,0,0,1,0.286178588867187,31.2805480957031,2,1,1,180.017288208008,0,180.017288208008,,,,,,,,,,,,,,,,,,,,,,,,,,,,,,,,,
,3866087491.55512,211.006958007813,26.4375095367432,2.7169977111531E-5,8.14019185661571E-9,1,5,12.9061126708984,4.99579369880347,42.3099994659424,0.0354435052533077,0.00514341919465493,1,-4.77511830851192E-8,,,,,,,,,,,,,,,,,,,,,211.006958007813,211.006958007813,26.4375095367432,26.4375095367432,49.6592047122937,5.35493446521895,7.36258506774902,64,1,64,0,0,0.277252197265625,30.3030319213867,2,1,1,211.006958007813,0,211.006958007813,,,,,,,,,,,,,,,,,,,,,,,,,,,,,,,,,
,3866087678.44411,242.013107299805,26.4375095367432,2.11219390775141E-5,8.09641785979135E-9,1,5,12.9061126708984,4.99564893682941,42.45999827981,0.0275513600244217,0.00400718216801805,1,-3.03350342629599E-8,,,,,,,,,,,,,,,,,,,,,242.013107299805,242.013107299805,26.4375095367432,26.4375095367432,49.6494343558033,5.35614953287541,7.50792646408081,64,1,64,0,0,0.277938842773438,31.7693061828613,2,1,1,242.013107299805,0,242.013107299805,,,,,,,,,,,,,,,,,,,,,,,,,,,,,,,,,
,3866087864.86978,273.005065917969,26.4375095367432,1.6427709599817E-5,6.78975577910782E-9,1,5,12.9061126708984,4.9954807625574,42.62999817729,0.0214278834971818,0.00311192848086708,1,-2.70696398588381E-8,,,,,,,,,,,,,,,,,,,,,273.005065917969,273.005065917969,26.4375095367432,26.4375095367432,49.6834351963899,5.35789830950743,7.61864423751831,65,1,0,0,1,0.277175903320313,31.7693061828613,2,1,1,273.005065917969,0,273.005065917969,,,,,,,,,,,,,,,,,,,,,,,,,,,,,,,,,
,3866089554.70215,1.99982011318207,47535.734375,0.311423864686146,3.76269505594764E-5,1,2,12.9061126708984,4.97574620322176,41.8399982154369,403.904716014183,59.0511833531281,1000,-0.000216514976397226,,,,,,,,,,,,,,,,,,,,,1.99982011318207,1.99982011318207,47535.734375,47535.734375,50.5178236406688,5.35745449518884,2.60355710983276,26,1,0,0,1,0.269012451171875,30.3030319213867,1,6,1,1.99982011318207,0,1.99982011318207,,,,,,,,,,,,,,,,,,,,,,,,,,,,,,,,,
,3866089630.52564,2.00003588199615,39963.4375,0.289700590220509,4.80040071422245E-5,1,2,12.9061126708984,4.97568906869594,41.8399982154369,375.673893027661,55.2749763329165,1000,6.36830475798557E-5,,,,,,,,,,,,,,,,,,,,,2.00003480911255,2.00003695487976,39908.53125,40018.34375,50.3388307097649,5.35655487094286,2.59888505935669,26,1,0,0,1,0.268707275390625,30.3030319213867,1,6,1,2.00003695487976,0,2.00003588199615,,,,,,,,,,,,,,,,,,,,,,,,,,,,,,,,,
,3866089696.64231,1.99985688924789,33364.2109375,0.267536608822389,4.68908477533875E-5,1,2,12.9061126708984,4.97566845074143,41.8399982154369,346.932014697995,51.0345965089294,1000,5.01845762045608E-5,,,,,,,,,,,,,,,,,,,,,1.99981510639191,1.99989867210388,33269.41796875,33459.00390625,50.1379521803226,5.35584605625097,2.60077834129334,26,1,0,0,1,0.268478393554687,30.3030319213867,1,6,1,1.99981510639191,0,1.99985688924789,,,,,,,,,,,,,,,,,,,,,,,,,,,,,,,,,
,3866089765.15063,1.99997711181641,26520.4326171875,0.24016777911734,5.42473382802387E-5,1,2,12.9061126708984,4.97566149299584,41.8399982154369,311.447777932659,45.763963055643,1000,6.69807820721731E-6,,,,,,,,,,,,,,,,,,,,,1.99990177154541,2.0000524520874,26430.740234375,26610.125,50.0171905741014,5.35510904883198,2.60184979438782,26,1,0,0,1,0.266647338867187,30.3030319213867,1,6,1,2.0000524520874,0,1.99997711181641,,,,,,,,,,,,,,,,,,,,,,,,,,,,,,,,,
,3866089833.7791,1.99976855516434,19671.607421875,0.206189873505678,6.46637143998651E-5,1,2,12.9061126708984,4.97561223315068,41.8399982154369,267.383458556782,39.2773603574899,1000,-3.16890943642212E-6,,,,,,,,,,,,,,,,,,,,,1.99973261356354,1.99980449676514,19561.65234375,19781.5625,49.9542694783034,5.35464691265554,2.59570932388306,26,1,0,0,1,0.267791748046875,30.7917900085449,1,6,1,1.99973261356354,0,1.99976855516434,,,,,,,,,,,,,,,,,,,,,,,,,,,,,,,,,
,3866089900.24157,1.99989885091782,13032.8276367188,0.163331185260666,8.23223635977019E-5,1,2,12.9061126708984,4.97562892410958,41.8399982154369,211.807584055122,31.1028844730329,1000,-1.05446851002081E-5,,,,,,,,,,,,,,,,,,,,,1.9998072385788,1.99999046325684,12923.078125,13142.5771484375,49.7963805174187,5.35375546319088,2.60238480567932,26,1,0,0,1,0.2679443359375,30.7917900085449,1,6,1,1.9998072385788,0,1.99989885091782,,,,,,,,,,,,,,,,,,,,,,,,,,,,,,,,,
,3866089966.89931,1.99983358383179,6372.73071289063,0.103620370847834,0.000117435699478106,1,2,12.9061126708984,4.97564779399638,41.8399982154369,134.379183276849,19.7067813789588,1000,-2.64136858000575E-5,,,,,,,,,,,,,,,,,,,,,1.99968647956848,1.99998068809509,6257.9677734375,6487.49365234375,49.741275706813,5.35295507942972,2.60497832298279,26,1,0,0,1,0.267562866210938,30.3030319213867,1,6,1,1.99998068809509,0,1.99983358383179,,,,,,,,,,,,,,,,,,,,,,,,,,,,,,,,,
,3866090059.31658,1.99996536970139,-2867.18493652344,-0.0469439907551765,0.000175688877240778,1,2,12.9061126708984,4.97558167893852,41.8399982154369,-60.8719494562491,-8.96738349302588,100,-1.85901731852668E-5,,,,,,,,,,,,,,,,,,,,,1.99990403652191,2.00002670288086,-2966.96801757812,-2767.40185546875,49.6959412526976,5.35312878923071,2.59741568565369,26,1,0,0,1,0.268783569335938,31.2805480957031,1,6,1,1.99990403652191,0,1.99996536970139,,,,,,,,,,,,,,,,,,,,,,,,,,,,,,,,,
,3866090129.77267,2.00004428625107,-9911.2080078125,-0.133782692221346,0.000100767382420767,1,2,12.9061126708984,4.97561410989422,41.8399982154369,-173.475121690339,-25.5664622096873,100,-6.1193285775813E-5,,,,,,,,,,,,,,,,,,,,,1.99999749660492,2.00009107589722,-10006.1650390625,-9816.2509765625,49.7764489901783,5.35358290612215,2.59324073791504,26,1,0,0,1,0.277099609375,30.7917900085449,1,6,1,1.99999749660492,0,2.00004428625107,,,,,,,,,,,,,,,,,,,,,,,,,,,,,,,,,
,3866090210.55979,2.00007462501526,-17986.3310546875,-0.194916157035156,7.14946498801764E-5,1,2,12.9061126708984,4.97563859701364,41.8399982154369,-252.767960346766,-37.1152711730005,1000,1.44254371884075E-5,,,,,,,,,,,,,,,,,,,,,2.0000433921814,2.00010585784912,-18096.46875,-17876.193359375,49.919096194938,5.35459088283967,2.57681918144226,26,1,0,0,1,0.267562866210938,30.3030319213867,1,6,1,2.0000433921814,0,2.00007462501526,,,,,,,,,,,,,,,,,,,,,,,,,,,,,,,,,
,3866090277.19371,1.99995309114456,-24652.1953125,-0.230905626921768,5.96951816872766E-5,1,2,12.9061126708984,4.97563908536946,41.8399982154369,-299.43412978304,-44.0032804979991,1000,-9.90917049847473E-6,,,,,,,,,,,,,,,,,,,,,1.99980676174164,2.00009942054749,-24767.158203125,-24537.232421875,49.9847529905534,5.35476855825016,2.56033635139465,26,1,0,0,1,0.268630981445313,31.2805480957031,1,6,1,2.00009942054749,0,1.99995309114456,,,,,,,,,,,,,,,,,,,,,,,,,,,,,,,,,
,3866090345.37543,1.99995809793472,-31482.85546875,-0.26026573648031,4.73177192677909E-5,1,2,12.9061126708984,4.97567215888025,41.8399982154369,-337.519667276144,-49.5393868509029,1000,3.46837993541606E-5,,,,,,,,,,,,,,,,,,,,,1.99990665912628,2.00000953674316,-31577.982421875,-31387.728515625,50.1617918501592,5.35559560407879,2.55763673782349,26,1,0,0,1,0.267562866210938,32.2580642700195,1,6,1,1.99990665912628,0,1.99995809793472,,,,,,,,,,,,,,,,,,,,,,,,,,,,,,,,,
,3866090411.80684,1.99847358465195,-38134.779296875,-0.283790922484256,4.28651499015431E-5,1,2,12.9061126708984,4.97569002045093,41.8399982154369,-368.023522362077,-54.0590248725498,1000,5.78287095753049E-6,,,,,,,,,,,,,,,,,,,,,1.99812662601471,1.99882054328918,-38230.03125,-38039.52734375,50.2743463569284,5.35684820286949,2.53264212608337,26,1,0,0,1,0.267486572265625,30.7917900085449,1,6,1,1.99812662601471,0,1.99847358465195,,,,,,,,,,,,,,,,,,,,,,,,,,,,,,,,,
,3866090478.44244,2.00352299213409,-44812.013671875,-0.303737395906145,4.8866085484757E-5,1,2,12.9061126708984,4.97568139099289,41.8399982154369,-393.863165133509,-58.0369783711932,1000,-0.0001314663798643,,,,,,,,,,,,,,,,,,,,,2.00322389602661,2.00382208824158,-44922.14453125,-44701.8828125,50.3783029499861,5.35714119553863,2.50023531913757,26,1,0,0,1,0.277023315429687,30.7917900085449,5,6,1,2.00322389602661,0,2.00352299213409,,,,,,,,,,,,,,,,,,,,,,,,,,,,,,,,,
,3866090547.13086,2.00049209594727,-48903.419921875,-0.314831697288566,2.17950220432593E-5,1,2,12.9061126708984,4.97565917125882,41.8399982154369,-408.268587401615,-60.0083698003782,1000,-2.20737480440245E-5,,,,,,,,,,,,,,,,,,,,,2.00013566017151,2.00084853172302,-48963.24609375,-48843.59375,50.5240766688226,5.35758846298334,2.49640107154846,26,1,0,0,1,0.277557373046875,30.7917900085449,6,6,1,2.00013566017151,0,2.00049209594727,,,,,,,,,,,,,,,,,,,,,,,,,,,,,,,,,
,3866090609.53678,1.99910545349121,-42675.939453125,-0.297877931270776,5.14170283850883E-5,1,2,12.9061126708984,4.97566259732737,41.8399982154369,-386.277030311332,-56.8216482546295,1000,-5.53462809027999E-5,,,,,,,,,,,,,,,,,,,,,1.99206709861755,2.00614380836487,-42745.96875,-42605.91015625,50.3415664095822,5.35712702072207,2.48053431510925,26,1,0,0,1,0.267562866210938,30.7917900085449,6,6,1,2.00614380836487,0,1.99910545349121,,,,,,,,,,,,,,,,,,,,,,,,,,,,,,,,,
,3866090674.06328,2.00004422664642,-36232.494140625,-0.277756900965991,4.11316014785016E-5,1,2,12.9061126708984,4.97560764060684,41.8399982154369,-360.172903462274,-53.0256910987868,1000,-8.48051454492653E-5,,,,,,,,,,,,,,,,,,,,,1.99936056137085,2.000727891922,-36287.53125,-36177.45703125,50.2024365331592,5.35643597636481,2.47501492500305,26,1,0,0,1,0.268402099609375,31.2805480957031,5,6,1,1.99936056137085,0,2.00004422664642,,,,,,,,,,,,,,,,,,,,,,,,,,,,,,,,,
,3866090742.19049,2.00001245737076,-29435.81640625,-0.25250920953561,4.62944276167388E-5,1,2,12.9061126708984,4.97557454654854,41.8399982154369,-327.43399032218,-48.1825779342676,1000,-5.95874649767213E-5,,,,,,,,,,,,,,,,,,,,,1.99999630451202,2.00002861022949,-29530.673828125,-29340.958984375,50.0449383865341,5.35595949695755,2.47522139549255,26,1,0,0,1,0.26824951171875,30.7917900085449,5,6,1,1.99999630451202,0,2.00001245737076,,,,,,,,,,,,,,,,,,,,,,,,,,,,,,,,,
,3866090808.6859,2.00008702278137,-22797.8095703125,-0.222689541703801,6.06294431352798E-5,1,2,12.9061126708984,4.97560969906134,41.8399982154369,-288.784539301759,-42.3876743850394,1000,2.86368750600212E-5,,,,,,,,,,,,,,,,,,,,,1.99922728538513,2.00094676017761,-22892.62890625,-22702.990234375,49.9624765777553,5.35527697968739,2.47295236587524,26,1,0,0,1,0.267868041992187,30.7917900085449,1,6,1,1.99922728538513,0,2.00008702278137,,,,,,,,,,,,,,,,,,,,,,,,,,,,,,,,,
,3866090873.14334,1.99748980998993,-16363.8603515625,-0.186390067547784,7.09554205310779E-5,1,2,12.9061126708984,4.97560519198874,41.8399982154369,-241.703826932297,-35.5267336546838,1000,-1.34320809932777E-5,,,,,,,,,,,,,,,,,,,,,1.99539303779602,1.99958658218384,-16453.708984375,-16274.01171875,49.8593016132168,5.35442908643343,2.47302746772766,26,1,0,0,1,0.269241333007813,31.2805480957031,5,6,1,1.99958658218384,0,1.99748980998993,,,,,,,,,,,,,,,,,,,,,,,,,,,,,,,,,
,3866090940.00733,1.99983024597168,-9682.92236328125,-0.136315658773071,9.6105725207088E-5,1,2,12.9061126708984,4.9755797160372,41.8399982154369,-176.776625126768,-25.9226958806914,1000,3.60265624096191E-5,,,,,,,,,,,,,,,,,,,,,1.99975228309631,1.99990820884705,-9802.9755859375,-9562.869140625,49.7709775905437,5.35424115125666,2.47301030158997,26,1,0,0,1,0.268096923828125,30.7917900085449,5,6,1,1.99990820884705,0,1.99983024597168,,,,,,,,,,,,,,,,,,,,,,,,,,,,,,,,,
,3866091006.28081,1.99992442131042,-3063.22875976562,-0.0625943155427079,0.000152460750948862,1,2,12.9061126708984,4.97560085343194,41.8399982154369,-81.1733500164657,-11.9073849409108,1000,1.34885804892862E-5,,,,,,,,,,,,,,,,,,,,,1.9998140335083,2.00003480911255,-3138.14135742188,-2988.31616210937,49.672101582861,5.35318979054987,2.48136782646179,26,1,0,0,1,0.268096923828125,30.7917900085449,1,6,1,1.9998140335083,0,1.99992442131042,,,,,,,,,,,,,,,,,,,,,,,,,,,,,,,,,
,3866091094.74963,1.99980902671814,5783.095703125,0.0888494604279048,0.000139652581928445,1,2,12.9061126708984,4.97558254513272,41.8399982154369,115.204541476894,17.0129349553053,100,6.65224737061142E-5,,,,,,,,,,,,,,,,,,,,,1.99979031085968,1.9998277425766,5688.1513671875,5878.0400390625,49.7682418907264,5.35358835889229,2.46831274032593,26,1,0,0,1,0.267333984375,30.7917900085449,1,6,1,1.9998277425766,0,1.99980902671814,,,,,,,,,,,,,,,,,,,,,,,,,,,,,,,,,
,3866091181.35972,1.9942786693573,14444.17578125,0.171467989144755,8.34442083587085E-5,1,2,12.9061126708984,4.9755860476052,41.8399982154369,222.350765518745,32.6922267595348,1000,1.99765784943556E-5,,,,,,,,,,,,,,,,,,,,,1.99110412597656,1.99745321273804,14349.17578125,14539.17578125,49.8620373130341,5.3541364262401,2.44622278213501,26,1,0,0,1,0.267181396484375,30.7917900085449,6,6,1,1.99110412597656,0,1.9942786693573,,,,,,,,,,,,,,,,,,,,,,,,,,,,,,,,,
,3866091249.99382,2.00039255619049,21310.337890625,0.21410765653152,6.21026533160665E-5,1,2,12.9061126708984,4.97564460674201,41.8399982154369,277.650233293959,40.809222231232,1000,1.46153725868077E-5,,,,,,,,,,,,,,,,,,,,,2.00027942657471,2.00050568580627,21230.38671875,21390.2890625,49.9523154070053,5.35509384151436,2.45182251930237,26,1,0,0,1,0.268325805664062,31.2805480957031,5,6,1,2.00050568580627,0,2.00039255619049,,,,,,,,,,,,,,,,,,,,,,,,,,,,,,,,,
,3866091317.69721,1.99954998493195,28086.130859375,0.246801931437588,4.71931434941181E-5,1,2,12.9061126708984,4.97569248526434,41.8399982154369,320.04693030132,47.0746080726153,1000,4.24282641146866E-5,,,,,,,,,,,,,,,,,,,,,1.99948871135712,1.99961125850678,27925.70703125,28246.5546875,50.0234436022553,5.35562157266429,2.44766211509705,26,1,0,0,1,0.267715454101562,31.7693061828613,1,6,1,1.99948871135712,0,1.99954998493195,,,,,,,,,,,,,,,,,,,,,,,,,,,,,,,,,
,3866091384.84164,1.99985647201538,34814.91015625,0.272513627888395,5.00370109690708E-5,1,2,12.9061126708984,4.97569408790296,41.8399982154369,353.393045027875,51.9541149639279,1000,2.77825724688009E-5,,,,,,,,,,,,,,,,,,,,,1.99984347820282,1.99986946582794,34719.74609375,34910.07421875,50.178206049063,5.35652428989393,2.43591594696045,26,1,0,0,1,0.27740478515625,31.2805480957031,1,6,1,1.99986946582794,0,1.99985647201538,,,,,,,,,,,,,,,,,,,,,,,,,,,,,,,,,
,3866091449.29719,1.99995338916779,41273.341796875,0.293515266164987,4.59369831592968E-5,1,2,12.9061126708984,4.97571832033153,41.8399982154369,380.656831342453,55.7783331740955,1000,-0.00010893979505279,,,,,,,,,,,,,,,,,,,,,1.99978566169739,2.00012111663818,41183.3359375,41363.34765625,50.3228073251207,5.35685349305618,2.43537497520447,26,1,0,0,1,0.2679443359375,30.7917900085449,1,6,1,2.00012111663818,0,1.99995338916779,,,,,,,,,,,,,,,,,,,,,,,,,,,,,,,,,
,3866091518.01169,2.00921666622162,48157.849609375,0.312569000418089,3.62064544847746E-5,1,2,12.9061126708984,4.97568710541664,41.8399982154369,405.331649325654,59.6178020835962,1000,5.29467436621012E-5,,,,,,,,,,,,,,,,,,,,,2.00750637054443,2.0109269618988,48037.45703125,48278.2421875,50.5549509953323,5.35778406485539,2.42782497406006,26,1,0,0,1,0.267410278320313,31.2805480957031,6,6,1,2.00750637054443,0,2.00921666622162,,,,,,,,,,,,,,,,,,,,,,,,,,,,,,,,,
,3866092024.64858,23.3602256774902,26.2745456695557,0.000143823890045635,1.44180275826755E-7,1,5,12.9061126708984,4.97544329324829,41.8399982154369,0.186498314585376,0.0274034010209217,1,3.59030350857537E-9,,,,,,,,,,,,,,,,,,,,,23.0614852905273,23.6589660644531,26.2745456695557,26.2745456695557,49.761598048313,5.35271970329395,5.93345212936401,65,1,0,0,1,0.268020629882813,30.3030319213867,2,1,1,23.6589660644531,0,23.3602256774902,,,,,,,,,,,,,,,,,,,,,,,,,,,,,,,,,
,3866092220.43813,54.0115127563477,26.2745456695557,9.67988932633244E-5,2.14927249299759E-8,1,5,12.9061126708984,4.97544291077592,41.8599992990494,0.125538766339098,0.0183183261150538,1,-9.41293340904957E-8,,,,,,,,,,,,,,,,,,,,,54.0115127563477,54.0115127563477,26.2745456695557,26.2745456695557,49.7115738230822,5.35302586331746,6.66463756561279,65,1,0,0,1,0.2691650390625,31.2805480957031,2,1,1,54.0115127563477,0,54.0115127563477,,,,,,,,,,,,,,,,,,,,,,,,,,,,,,,,,
,3866092414.70712,85.0161437988281,26.2745456695557,7.48826502978962E-5,1.9084425019143E-8,1,5,12.9061126708984,4.97538862647761,41.9199988245964,0.0971169311226876,0.0141509486712079,1,-8.80150396781415E-8,,,,,,,,,,,,,,,,,,,,,85.0161437988281,85.0161437988281,26.2745456695557,26.2745456695557,49.7592531627553,5.3530055016001,6.94600486755371,65,1,0,0,1,0.2691650390625,30.7917900085449,2,1,1,85.0161437988281,0,85.0161437988281,,,,,,,,,,,,,,,,,,,,,,,,,,,,,,,,,
,3866092602.52182,116.026000976563,26.2745456695557,5.77945779318039E-5,1.81986732917329E-8,1,5,12.9061126708984,4.97531459181422,41.9799983501434,0.0749547304218244,0.0109129246690033,1,-7.45447103466031E-8,,,,,,,,,,,,,,,,,,,,,116.026000976563,116.026000976563,26.2745456695557,26.2745456695557,49.715872779938,5.35397163204105,7.08596086502075,63,1,64,0,0,0.267410278320313,30.7917900085449,2,1,1,116.026000976563,0,116.026000976563,,,,,,,,,,,,,,,,,,,,,,,,,,,,,,,,,
,3866092790.43461,147.058944702148,26.2745456695557,4.42120512929491E-5,1.11975297971891E-8,1,5,12.9061126708984,4.97526422829239,42.0700013637543,0.0573399703438848,0.00833819975650825,1,-6.46741975063071E-8,,,,,,,,,,,,,,,,,,,,,147.058944702148,147.058944702148,26.2745456695557,26.2745456695557,49.6959412526976,5.35284397360299,7.17529678344727,65,1,0,0,1,0.26824951171875,31.2805480957031,2,1,1,147.058944702148,0,147.058944702148,,,,,,,,,,,,,,,,,,,,,,,,,,,,,,,,,
,3866092977.3944,178.004257202148,26.2745456695557,3.44737372496725E-5,9.62135415003725E-9,1,5,12.9061126708984,4.98590553000836,42.1800017356873,0.044846584033836,0.00650729751497775,1,-6.10834501952674E-8,,,,,,,,,,,,,,,,,,,,,178.004257202148,178.004257202148,26.2745456695557,26.2745456695557,49.783874461111,5.35467082660104,7.23751640319824,63,1,64,0,0,0.269241333007813,31.2805480957031,2,1,1,178.004257202148,0,178.004257202148,,,,,,,,,,,,,,,,,,,,,,,,,,,,,,,,,
,3866093164.91515,209.047286987305,26.2745456695557,2.67628069361875E-5,7.77210964940003E-9,1,5,12.9061126708984,4.98574214097464,42.3000007867813,0.0348135125818343,0.00505417710450228,1,-4.53943480624711E-8,,,,,,,,,,,,,,,,,,,,,209.047286987305,209.047286987305,26.2745456695557,26.2745456695557,49.7064932377072,5.35536623964586,7.3277759552002,64,1,64,0,0,0.269622802734375,30.7917900085449,2,1,1,209.047286987305,0,209.047286987305,,,,,,,,,,,,,,,,,,,,,,,,,,,,,,,,,
,3866093350.81955,240.009674072266,26.2745456695557,2.07114135908309E-5,8.42886622801186E-9,1,5,12.9061126708984,4.98537158122462,42.4499996006489,0.0269388750263479,0.00391143608387307,1,-3.47628033876607E-8,,,,,,,,,,,,,,,,,,,,,240.009674072266,240.009674072266,26.2745456695557,26.2745456695557,49.6920331101014,5.35737820118836,7.52011728286743,64,1,64,0,0,0.269012451171875,31.7693061828613,2,1,1,240.009674072266,0,240.009674072266,,,,,,,,,,,,,,,,,,,,,,,,,,,,,,,,,
,3866093537.52259,271.0712890625,26.2745456695557,1.6504561683401E-5,8.68869579619183E-9,1,5,12.9061126708984,4.98541812438487,42.6199994981289,0.0214663344537194,0.00312423369888885,1,-2.21356869284627E-8,,,,,,,,,,,,,,,,,,,,,271.0712890625,271.0712890625,26.2745456695557,26.2745456695557,49.700631023813,5.35656708720265,7.79519462585449,64,1,64,0,0,0.267791748046875,31.2805480957031,2,1,1,271.0712890625,0,271.0712890625,,,,,,,,,,,,,,,,,,,,,,,,,,,,,,,,,
,3866094297.18682,299.999908447266,26.3497619628906,1.75177250076817E-5,8.20313185604391E-9,1,5,12.9061126708984,5.00559267415552,42.7800007164478,0.0229119259509275,0.00334517092902187,1,-1.56004500115747E-8,,,,,,,,,,,,,,,,,,,,,299.999908447266,299.999908447266,26.3497619628906,26.3497619628906,49.6662393689668,5.35758046499984,8.14810371398926,65,1,0,0,1,0.276718139648438,29.8142719268799,2,1,1,299.999908447266,0,299.999908447266,,,,,,,,,,,,,,,,,,,,,,,,,,,,,,,,,
,3866094505.75988,268.983978271484,26.3497619628906,1.91261840719508E-5,6.17642792616676E-9,1,5,12.9061126708984,5.00527278610337,42.6199994981289,0.0250163728688853,0.00363201798603821,1,-3.23095821569813E-8,,,,,,,,,,,,,,,,,,,,,268.983978271484,268.983978271484,26.3497619628906,26.3497619628906,49.712746265861,5.35857866902322,8.02279186248779,64,1,64,0,0,0.269241333007813,31.2805480957031,2,1,1,268.983978271484,0,268.983978271484,,,,,,,,,,,,,,,,,,,,,,,,,,,,,,,,,
,3866094692.55775,237.972106933594,26.3497619628906,2.0825709124086E-5,7.0604191245709E-9,1,5,12.9061126708984,5.00532543508654,42.4900017678738,0.0272399105399941,0.00395332776329408,1,-3.63156410267325E-8,,,,,,,,,,,,,,,,,,,,,237.972106933594,237.972106933594,26.3497619628906,26.3497619628906,49.6717107686014,5.35758089838024,7.88334894180298,63,1,64,0,0,0.268096923828125,31.7693061828613,2,1,1,237.972106933594,0,237.972106933594,,,,,,,,,,,,,,,,,,,,,,,,,,,,,,,,,
,3866094879.24586,206.980911254883,26.3497619628906,2.27481833902865E-5,7.61860892112015E-9,1,5,12.9061126708984,5.0059887189715,42.3699989914894,0.0297584804054594,0.00432950098837342,1,-3.16927950655577E-8,,,,,,,,,,,,,,,,,,,,,206.980911254883,206.980911254883,26.3497619628906,26.3497619628906,49.7459654779283,5.35547218625987,7.78597736358643,64,1,64,0,0,0.28594970703125,31.2805480957031,2,1,1,206.980911254883,0,206.980911254883,,,,,,,,,,,,,,,,,,,,,,,,,,,,,,,,,
,3866095066.25296,175.754333496094,26.3497619628906,2.49255070676893E-5,5.77870996966338E-9,1,5,12.9061126708984,5.00613636254231,42.2700010240078,0.0326087421501401,0.00473995381320449,1,-3.78896113330226E-8,,,,,,,,,,,,,,,,,,,,,175.754333496094,175.754333496094,26.3497619628906,26.3497619628906,49.7315053503226,5.3541435049307,7.71023797988892,65,1,0,0,1,0.276107788085938,31.2805480957031,2,1,1,175.754333496094,0,175.754333496094,,,,,,,,,,,,,,,,,,,,,,,,,,,,,,,,,
,3866095246.24055,145.904144287109,26.3497619628906,2.72676980623554E-5,6.23220735400566E-9,1,5,12.9061126708984,5.00603741888902,42.1600006520748,0.0356725679420046,0.00518081741432839,1,-4.48105218238323E-8,,,,,,,,,,,,,,,,,,,,,145.904144287109,145.904144287109,26.3497619628906,26.3497619628906,49.8374160146784,5.35445964714724,7.62654256820679,65,1,0,0,1,0.274734497070313,30.7917900085449,2,1,1,145.904144287109,0,145.904144287109,,,,,,,,,,,,,,,,,,,,,,,,,,,,,,,,,
,3866095431.00472,114.894004821777,26.3497619628906,2.94280785484093E-5,6.49434608488542E-9,1,5,12.9061126708984,5.00613971111794,42.0800000429153,0.0384971213965861,0.00561073203092796,1,-3.3615608452344E-8,,,,,,,,,,,,,,,,,,,,,114.894004821777,114.894004821777,26.3497619628906,26.3497619628906,49.7651153766495,5.35373360705151,7.53510093688965,64,1,64,0,0,0.275726318359375,31.2805480957031,2,1,1,114.894004821777,0,114.894004821777,,,,,,,,,,,,,,,,,,,,,,,,,,,,,,,,,
,3866095616.36349,83.9715728759766,26.3497619628906,3.20843550004715E-5,6.80043705421951E-9,1,5,12.9061126708984,5.00612353177369,41.9999994337559,0.0419717971194922,0.00611723618998115,1,-3.65822454055548E-8,,,,,,,,,,,,,,,,,,,,,83.9715728759766,83.9715728759766,26.3497619628906,26.3497619628906,49.7213441795726,5.35427271940718,7.40952825546265,64,1,64,0,0,0.28472900390625,31.2805480957031,2,1,1,83.9715728759766,0,83.9715728759766,,,,,,,,,,,,,,,,,,,,,,,,,,,,,,,,,
,3866095798.63412,52.8316307067871,26.3497619628906,3.52005974048695E-5,6.66969750626796E-9,1,5,12.9061126708984,5.00628338397142,41.9300012290478,0.0460520056941124,0.00670095368119285,1,-4.83373568089075E-8,,,,,,,,,,,,,,,,,,,,,52.8316307067871,52.8316307067871,26.3497619628906,26.3497619628906,49.7166544084572,5.3537329878891,7.20652723312378,64,1,64,0,0,0.2850341796875,31.2805480957031,2,1,1,52.8316307067871,0,52.8316307067871,,,,,,,,,,,,,,,,,,,,,,,,,,,,,,,,,
,3866095980.00951,21.98069190979,26.3497619628906,3.9160090860508E-5,8.93767853130227E-9,1,5,12.9061126708984,5.00626651358335,41.8800003826618,0.0512306216892031,0.00746312412605542,1,-4.73085436877626E-8,,,,,,,,,,,,,,,,,,,,,21.98069190979,21.98069190979,26.3497619628906,26.3497619628906,49.7682418907264,5.3534273472355,6.58966255187988,65,1,0,0,1,0.275650024414062,31.2805480957031,2,1,1,21.98069190979,0,21.98069190979,,,,,,,,,,,,,,,,,,,,,,,,,,,,,,,,,
,3866096402.53757,11.0054864883423,26.3497619628906,4.30207583824486E-5,1.28463417721755E-8,1,5,12.9061126708984,5.00639328142807,41.8500006198883,0.0562836555417655,0.00819660831185347,1,-5.3938576997458E-8,,,,,,,,,,,,,,,,,,,,,11.0054864883423,11.0054864883423,26.3497619628906,26.3497619628906,49.7045391664091,5.35323384490036,5.10892057418823,65,1,0,0,1,0.27557373046875,31.7693061828613,6,1,1,11.0054864883423,0,11.0054864883423,,,,,,,,,,,,,,,,,,,,,,,,,,,,,,,,,
,3866096602.98648,42.1058464050293,26.3497619628906,3.64294790515568E-5,6.0356216162109E-9,1,5,12.9061126708984,5.00642734791559,41.8500006198883,0.0476602600768957,0.00694453515360199,1,-4.28640931862329E-8,,,,,,,,,,,,,,,,,,,,,42.1058464050293,42.1058464050293,26.3497619628906,26.3497619628906,49.7713684048033,5.35300753114031,6.53879737854004,65,1,0,0,1,0.27618408203125,30.7917900085449,2,1,1,42.1058464050293,0,42.1058464050293,,,,,,,,,,,,,,,,,,,,,,,,,,,,,,,,,
,3866096798.70849,73.1292037963867,26.3497619628906,3.32398708257463E-5,5.90553184236979E-9,1,5,12.9061126708984,5.00628150977133,41.8899990618229,0.0434883759409529,0.00631708199876284,1,-5.37603587925568E-8,,,,,,,,,,,,,,,,,,,,,73.1292037963867,73.1292037963867,26.3497619628906,26.3497619628906,49.712746265861,5.35327012337925,6.94040870666504,65,1,0,0,1,0.285263061523438,30.7917900085449,2,1,1,73.1292037963867,0,73.1292037963867,,,,,,,,,,,,,,,,,,,,,,,,,,,,,,,,,
,3866096988.85836,104.124015808105,26.3497619628906,3.00021796670951E-5,5.90243947131854E-9,1,5,12.9061126708984,5.0061892663234,41.9499985873699,0.0392516091835596,0.00570040196672076,1,-4.94604542318915E-8,,,,,,,,,,,,,,,,,,,,,104.124015808105,104.124015808105,26.3497619628906,26.3497619628906,49.7299420932841,5.35411210987335,7.11598777770996,65,1,0,0,1,0.284957885742187,31.2805480957031,2,1,1,104.124015808105,0,104.124015808105,,,,,,,,,,,,,,,,,,,,,,,,,,,,,,,,,
,3866097176.67829,135.137588500977,26.3497619628906,2.72370731379153E-5,6.00444217056721E-9,1,5,12.9061126708984,5.00599349459012,42.0299991965294,0.0356316078918167,0.00517805302803478,1,-4.23763617980215E-8,,,,,,,,,,,,,,,,,,,,,135.137588500977,135.137588500977,26.3497619628906,26.3497619628906,49.7334594216207,5.35453485909492,7.21808910369873,64,1,64,0,0,0.276260375976562,31.7693061828613,2,1,1,135.137588500977,0,135.137588500977,,,,,,,,,,,,,,,,,,,,,,,,,,,,,,,,,
,3866097362.99825,166.029357910156,26.3497619628906,2.45971771123829E-5,6.92767494093125E-9,1,5,12.9061126708984,5.00601617636223,42.1300008893013,0.0321794558754385,0.00466829670567654,1,-4.43200382981791E-8,,,,,,,,,,,,,,,,,,,,,166.029357910156,166.029357910156,26.3497619628906,26.3497619628906,49.7936448176014,5.35502373335551,7.28910875320435,64,1,64,0,0,0.284500122070313,30.7917900085449,2,1,1,166.029357910156,0,166.029357910156,,,,,,,,,,,,,,,,,,,,,,,,,,,,,,,,,
,3866097549.94388,197.016098022461,26.3497619628906,2.21634251575111E-5,6.72820699817311E-9,1,5,12.9061126708984,5.0059289082056,42.2499999403954,0.0289940333080963,0.00421132773639005,1,-3.60848878113342E-8,,,,,,,,,,,,,,,,,,,,,197.016098022461,197.016098022461,26.3497619628906,26.3497619628906,49.7643337481303,5.35536197671839,7.35330057144165,64,1,64,0,0,0.267181396484375,30.7917900085449,2,1,1,197.016098022461,0,197.016098022461,,,,,,,,,,,,,,,,,,,,,,,,,,,,,,,,,
,3866097737.14609,228.119567871094,26.3497619628906,1.99779158760891E-5,6.4053981960245E-9,1,5,12.9061126708984,5.00559693583748,42.3900000751018,0.0261326750023959,0.00379478932354335,1,-3.32240847339771E-8,,,,,,,,,,,,,,,,,,,,,228.119567871094,228.119567871094,26.3497619628906,26.3497619628906,49.7416665210726,5.35663915590497,7.46207284927368,63,1,64,0,0,0.26885986328125,31.2805480957031,2,1,1,228.119567871094,0,228.119567871094,,,,,,,,,,,,,,,,,,,,,,,,,,,,,,,,,
,3866097923.44378,259.001922607422,26.3497619628906,1.79893556843632E-5,7.39708909516603E-9,1,5,12.9061126708984,5.0055380198627,42.5500012934208,0.0235333597063073,0.00340159469148965,1,-4.17029790078799E-8,,,,,,,,,,,,,,,,,,,,,259.001922607422,259.001922607422,26.3497619628906,26.3497619628906,49.6912514815822,5.35722284080776,7.69233894348145,63,1,64,0,0,0.268020629882813,31.7693061828613,2,1,1,259.001922607422,0,259.001922607422,,,,,,,,,,,,,,,,,,,,,,,,,,,,,,,,,
,3866098110.1089,290.068664550781,26.3497619628906,1.62301947553413E-5,5.87911887378543E-9,1,5,12.9061126708984,5.00547451754669,42.7299998700619,0.0212281377636487,0.00309300873753386,1,-1.91904027069613E-8,,,,,,,,,,,,,,,,,,,,,290.068664550781,290.068664550781,26.3497619628906,26.3497619628906,49.7080564947457,5.35718821458526,7.60805988311768,63,1,64,0,0,0.26824951171875,31.2805480957031,2,1,1,290.068664550781,0,290.068664550781,,,,,,,,,,,,,,,,,,,,,,,,,,,,,,,,,
,3866098408.10275,300.006896972656,43582.234375,0.0116545858239976,3.13003970393483E-6,1,2,12.9061126708984,5.00542483944126,42.7800007164478,15.2464324356362,2.19967220003729,100,-3.00884169086585E-5,,,,,,,,,,,,,,,,,,,,,300.006713867188,300.007080078125,43492.28515625,43672.18359375,49.6459170274668,5.35778872930784,7.64414834976196,26,1,0,0,1,0.268402099609375,31.7693061828613,1,6,1,300.006713867188,0,300.006896972656,,,,,,,,,,,,,,,,,,,,,,,,,,,,,,,,,
,3866098476.8762,300.003463745117,36713.626953125,0.00984574856485128,3.12834698708952E-6,1,2,12.9061126708984,5.00541954924768,42.7800007164478,12.8798356620974,1.8601220953122,100,-2.40035946261222E-5,,,,,,,,,,,,,,,,,,,,,300.003387451172,300.003540039063,36593.5625,36833.69140625,49.6130886296591,5.35801986345,7.68790817260742,26,1,0,0,1,0.268783569335938,31.2805480957031,1,6,1,300.003387451172,0,300.003463745117,,,,,,,,,,,,,,,,,,,,,,,,,,,,,,,,,
,3866098547.10844,300.002593994141,29704.5986328125,0.00798508936203422,3.58992412830833E-6,1,2,12.9061126708984,5.00543105687134,42.7800007164478,10.4458206844821,1.50863074272194,100,-1.94432918652668E-5,,,,,,,,,,,,,,,,,,,,,300.002471923828,300.002716064453,29614.80078125,29794.396484375,49.6885157817649,5.35784612764674,7.77223205566406,25,1,68,0,0,0.27801513671875,31.2805480957031,1,6,1,300.002471923828,0,300.002593994141,,,,,,,,,,,,,,,,,,,,,,,,,,,,,,,,,
,3866098613.71609,300.002151489258,23055.9599609375,0.00622811097987325,3.27533086009682E-6,1,2,12.9061126708984,5.0054733366898,42.7800007164478,8.1479618878883,1.17353919855801,100,-1.75798919411337E-5,,,,,,,,,,,,,,,,,,,,,300.001861572266,300.00244140625,22946.216796875,23165.703125,49.6443537704283,5.35774557515039,7.87446212768555,26,1,0,0,1,0.276870727539062,31.2805480957031,1,6,1,300.001861572266,0,300.002151489258,,,,,,,,,,,,,,,,,,,,,,,,,,,,,,,,,
,3866098680.25759,300.002365112305,16411.6518554687,0.00447086156786438,2.88661015311086E-6,1,2,12.9061126708984,5.00544706829338,42.7800007164478,5.8490943904989,0.841692428450007,100,-1.317705678797E-5,,,,,,,,,,,,,,,,,,,,,300.002227783203,300.002502441406,16296.8759765625,16526.427734375,49.6881249675053,5.35769599655004,8.01883983612061,26,1,0,0,1,0.268325805664062,31.2805480957031,1,6,1,300.002227783203,0,300.002365112305,,,,,,,,,,,,,,,,,,,,,,,,,,,,,,,,,
,3866098750.55277,300.000915527344,9385.4912109375,0.00260514885371028,2.76209239956522E-6,1,2,12.9061126708984,5.00546295054225,42.7800007164478,3.40895556221048,0.485672755003784,100,-1.13330111076869E-5,,,,,,,,,,,,,,,,,,,,,300.000732421875,300.001098632812,9295.611328125,9475.37109375,49.7143095228995,5.35776392009558,8.16810703277588,26,1,0,0,1,0.26885986328125,31.2805480957031,1,6,1,300.000732421875,0,300.000915527344,,,,,,,,,,,,,,,,,,,,,,,,,,,,,,,,,
,3866098819.28407,300.001663208008,2520.03747558594,0.000780339017355516,2.82850797633287E-6,1,2,12.9061126708984,5.00537925194038,42.7800007164478,1.02381116157666,0.126918091793183,100,-1.75843529837164E-5,,,,,,,,,,,,,,,,,,,,,300.001525878906,300.001800537109,2410.18823242187,2629.88671875,49.7021942808514,5.35783629862506,8.31991481781006,26,1,0,0,1,0.277328491210938,31.7693061828613,1,6,1,300.001800537109,0,300.001663208008,,,,,,,,,,,,,,,,,,,,,,,,,,,,,,,,,
,3866098887.9036,299.999145507812,-4342.01318359375,-0.00125514188278239,4.00116338618189E-6,1,2,12.9061126708984,5.00532677244652,42.7800007164478,-1.64056294128563,-0.246132773247783,100,-3.82975929559974E-6,,,,,,,,,,,,,,,,,,,,,299.999145507812,299.999145507812,-4396.92529296875,-4287.10107421875,49.7150911514187,5.35797795653596,8.2827615737915,24,1,68,0,0,0.2685546875,31.2805480957031,1,6,1,299.999145507812,0,299.999145507812,,,,,,,,,,,,,,,,,,,,,,,,,,,,,,,,,
,3866098958.42377,300.000396728516,-11391.921875,-0.00312670627193831,3.06862615037279E-6,1,2,12.9061126708984,5.00529609660392,42.7800007164478,-4.08901256860512,-0.598083140526703,10,1.9744328337716E-6,,,,,,,,,,,,,,,,,,,,,300,300.000793457031,-11507.0986328125,-11276.7451171875,49.7010218380726,5.35815034653725,8.23233985900879,26,1,0,0,1,0.268478393554687,31.7693061828613,1,6,1,300.000793457031,0,300.000396728516,,,,,,,,,,,,,,,,,,,,,,,,,,,,,,,,,
,3866099038.6957,300.001510620117,-19416.740234375,-0.00526006437230667,3.22770574271576E-6,1,2,12.9061126708984,5.00533260195186,42.7800007164478,-6.87974583077352,-1.00125627815085,10,7.07675477559277E-6,,,,,,,,,,,,,,,,,,,,,300.001495361328,300.001525878906,-19506.74609375,-19326.734375,49.6877341532456,5.35792955301217,8.18986129760742,25,1,68,0,0,0.268783569335938,31.2805480957031,1,6,1,300.001525878906,0,300.001510620117,,,,,,,,,,,,,,,,,,,,,,,,,,,,,,,,,
,3866099131.3433,300.001052856445,-28692.853515625,-0.00771601250001381,3.32704847997635E-6,1,2,12.9061126708984,5.00526623723098,42.7800007164478,-10.0914095158083,-1.47099301141698,100,8.64279534283071E-6,,,,,,,,,,,,,,,,,,,,,300.000610351562,300.001495361328,-28782.990234375,-28602.716796875,49.641618070611,5.35760401607854,8.15564155578613,26,1,0,0,1,0.27679443359375,31.7693061828613,1,6,1,300.000640869141,0,300.001052856445,,,,,,,,,,,,,,,,,,,,,,,,,,,,,,,,,
,3866099195.76454,300.001159667969,-35144.439453125,-0.00942620599135108,3.56396306203756E-6,1,2,12.9061126708984,5.00523077429379,42.7800007164478,-12.3279532162942,-1.79711571031602,100,1.0476972155804E-5,,,,,,,,,,,,,,,,,,,,,300.000701904297,300.001617431641,-35234.5078125,-35054.37109375,49.6134794439187,5.35760131137755,8.13434982299805,26,1,0,0,1,0.287322998046875,30.7917900085449,1,6,1,300.000701904297,0,300.001159667969,,,,,,,,,,,,,,,,,,,,,,,,,,,,,,,,,
,3866099264.50135,300.000946044922,-42027.39453125,-0.0112375137162717,3.21879115908914E-6,1,2,12.9061126708984,5.00535842510687,42.7800007164478,-14.6976937737205,-2.14035191024044,100,1.41480263184401E-5,,,,,,,,,,,,,,,,,,,,,300.000915527344,300.0009765625,-42097.48046875,-41957.30859375,49.6248130574476,5.35669710579107,8.11990737915039,25,1,68,0,0,0.268325805664062,31.2805480957031,1,6,1,300.000915527344,0,300.000946044922,,,,,,,,,,,,,,,,,,,,,,,,,,,,,,,,,
,3866099330.11262,300.000839233398,-48603.701171875,-0.0129982633083436,3.80935975163883E-6,1,2,12.9061126708984,5.00518945975192,42.7800007164478,-16.9989118443177,-2.48163210750667,100,1.17486466198643E-5,,,,,,,,,,,,,,,,,,,,,300.000549316406,300.001129150391,-48758.81640625,-48448.5859375,49.6068356015053,5.35688429117905,8.11239147186279,26,1,0,0,1,0.278167724609375,31.7693061828613,1,6,1,300.001129150391,0,300.000839233398,,,,,,,,,,,,,,,,,,,,,,,,,,,,,,,,,
,3866099399.34938,300.000411987305,-45310.421875,-0.0121306992728391,3.30331636583129E-6,1,2,12.9061126708984,5.00522518628542,42.7800007164478,-15.8698723167331,-2.27934578811295,100,3.90107112052909E-5,,,,,,,,,,,,,,,,,,,,,300.000030517578,300.000793457031,-45410.12890625,-45210.71484375,49.6130886296591,5.35703611322265,8.09897994995117,26,1,0,0,1,0.267715454101562,32.7468223571777,1,6,1,300.000793457031,0,300.000411987305,,,,,,,,,,,,,,,,,,,,,,,,,,,,,,,,,
,3866099465.88625,300.001251220703,-38668.32421875,-0.010372011762862,3.2756679306514E-6,1,2,12.9061126708984,5.00530531648048,42.7800007164478,-13.5679900481969,-1.95846320715575,100,2.60676562621957E-5,,,,,,,,,,,,,,,,,,,,,300.001251220703,300.001251220703,-38743.13671875,-38593.51171875,49.6486527272841,5.35722969895541,8.09500694274902,26,1,0,0,1,0.26885986328125,31.7693061828613,1,6,1,300.001251220703,0,300.001251220703,,,,,,,,,,,,,,,,,,,,,,,,,,,,,,,,,
,3866099536.25736,300.000869750977,-31641.6142578125,-0.00850618528621937,3.80146043285971E-6,1,2,12.9061126708984,5.00535822951382,42.7800007164478,-11.1266855180853,-1.61105499310944,100,1.76488233983765E-5,,,,,,,,,,,,,,,,,,,,,300.000823974609,300.000915527344,-31736.583984375,-31546.64453125,49.6853892676879,5.35725787543124,8.08512306213379,26,1,0,0,1,0.269088745117187,31.2805480957031,1,6,1,300.000915527344,0,300.000869750977,,,,,,,,,,,,,,,,,,,,,,,,,,,,,,,,,
,3866099602.86891,300.000717163086,-24998.3896484375,-0.00674917954991492,3.68620882304774E-6,1,2,12.9061126708984,5.00534687756032,42.7800007164478,-8.82853401261573,-1.27716829968204,100,1.48515451444779E-5,,,,,,,,,,,,,,,,,,,,,300.000701904297,300.000732421875,-25108.11328125,-24888.666015625,49.6384915565341,5.35745063305593,8.07278251647949,25,1,68,0,0,0.268325805664062,31.2805480957031,1,6,1,300.000701904297,0,300.000717163086,,,,,,,,,,,,,,,,,,,,,,,,,,,,,,,,,
,3866099667.37353,300.001647949219,-18555.146484375,-0.00504475994479946,3.06671587256825E-6,1,2,12.9061126708984,5.00534919165908,42.7800007164478,-6.59954082049637,-0.950982953312202,100,1.38947470722837E-5,,,,,,,,,,,,,,,,,,,,,300.001617431641,300.001678466797,-18669.91015625,-18440.3828125,49.6857800819476,5.35767463486227,8.06780624389648,26,1,0,0,1,0.268630981445313,31.2805480957031,1,6,1,300.001617431641,0,300.001647949219,,,,,,,,,,,,,,,,,,,,,,,,,,,,,,,,,
,3866099734.94479,300.000564575195,-11811.619140625,-0.00323143661229085,3.36888430749843E-6,1,2,12.9061126708984,5.00542136926703,42.7800007164478,-4.22799204546672,-0.605420651748517,100,1.1765454241838E-5,,,,,,,,,,,,,,,,,,,,,300.000305175781,300.000823974609,-11981.3193359375,-11641.9189453125,49.7186084797553,5.35765745585467,8.067551612854,24,1,68,0,0,0.267868041992187,30.3030319213867,1,6,1,300.000305175781,0,300.000564575195,,,,,,,,,,,,,,,,,,,,,,,,,,,,,,,,,
,3866099802.16264,300.000381469727,-5096.71704101562,-0.00146563377394349,3.1104992948874E-6,1,2,12.9061126708984,5.00540587892802,42.7800007164478,-1.919243940005,-0.263522962603541,100,1.37995511168206E-5,,,,,,,,,,,,,,,,,,,,,300.000030517578,300.000732421875,-5186.7412109375,-5006.69287109375,49.7240798793899,5.35746199221221,8.06850242614746,26,1,0,0,1,0.270309448242187,31.7693061828613,1,6,1,300.000732421875,0,300.000381469727,,,,,,,,,,,,,,,,,,,,,,,,,,,,,,,,,
,3866099870.94012,300.00048828125,1778.87841796875,0.000560276789250008,3.29559274352168E-6,1,2,12.9061126708984,5.00540381983913,42.7800007164478,0.73058171435164,0.121832792073075,100,1.08557605851787E-5,,,,,,,,,,,,,,,,,,,,,300.000091552734,300.000885009766,1668.96020507813,1888.79663085938,49.6943779956591,5.35721065083295,8.06706047058105,26,1,0,0,1,0.269393920898438,30.7917900085449,1,6,1,300.000091552734,0,300.00048828125,,,,,,,,,,,,,,,,,,,,,,,,,,,,,,,,,
,3866099951.21719,299.999237060547,9803.6591796875,0.00271817675710985,3.1898272809494E-6,1,2,12.9061126708984,5.00545779901927,42.7800007164478,3.5547995130243,0.520718529085358,10,-1.13812044585621E-6,,,,,,,,,,,,,,,,,,,,,299.998840332031,299.999633789063,9708.68359375,9898.634765625,49.6482619130245,5.35754433981436,8.05959320068359,26,1,0,0,1,0.2777099609375,31.2805480957031,1,6,1,299.999633789063,0,299.999237060547,,,,,,,,,,,,,,,,,,,,,,,,,,,,,,,,,
,3866100019.92632,300.00048828125,16674.24609375,0.00453621847987147,3.31739485935345E-6,1,2,12.9061126708984,5.00550124952902,42.7800007164478,5.93320864786285,0.864084484009092,10,-5.66552463626838E-6,,,,,,,,,,,,,,,,,,,,,300.000335693359,300.000640869141,16559.26953125,16789.22265625,49.7080564947457,5.3572359274012,8.06027126312256,25,1,68,0,0,0.2685546875,31.2805480957031,1,6,1,300.000335693359,0,300.00048828125,,,,,,,,,,,,,,,,,,,,,,,,,,,,,,,,,
,3866100110.14845,300.001312255859,25701.66015625,0.00688157948957564,3.50402167940113E-6,1,2,12.9061126708984,5.0054233027693,42.7800007164478,9.00015058170226,1.31427672427672,10,-5.94644262712176E-6,,,,,,,,,,,,,,,,,,,,,300.001312255859,300.001312255859,25701.66015625,25701.66015625,49.6748372826783,5.35771808268978,8.06489944458008,25,1,68,0,0,0.278091430664062,31.7693061828613,1,6,1,300.001312255859,0,300.001312255859,,,,,,,,,,,,,,,,,,,,,,,,,,,,,,,,,
,3866100205.45308,300.000411987305,35250.814453125,0.0094474980924038,3.24551953226955E-6,1,2,12.9061126708984,5.00542656257039,42.7800007164478,12.3569620248799,1.79796606236399,100,-1.30299643081962E-5,,,,,,,,,,,,,,,,,,,,,300.000396728516,300.000427246094,35130.44921875,35371.1796875,49.6435721419091,5.35788213234865,8.05714988708496,26,1,0,0,1,0.2685546875,31.2805480957031,1,6,1,300.000396728516,0,300.000411987305,,,,,,,,,,,,,,,,,,,,,,,,,,,,,,,,,
,3866100275.57285,300.000427246094,42280.353515625,0.01131779688402,3.44438261763464E-6,1,2,12.9061126708984,5.00542331683107,42.7800007164478,14.8031239140444,2.15460528658699,100,-1.50725757542794E-5,,,,,,,,,,,,,,,,,,,,,300.000335693359,300.000518798828,42185.078125,42375.62890625,49.6349742281976,5.3574275120243,8.05328941345215,26,1,0,0,1,0.268783569335938,31.7693061828613,1,6,1,300.000518798828,0,300.000427246094,,,,,,,,,,,,,,,,,,,,,,,,,,,,,,,,,
,3866100344.16873,299.999465942383,49154.67578125,0.0131337944569534,3.41543195058003E-6,1,2,12.9061126708984,5.00537473501228,42.7800007164478,17.1775875029995,2.50395746137697,100,-1.46854248724064E-5,,,,,,,,,,,,,,,,,,,,,299.999206542969,299.999725341797,49069.359375,49239.9921875,49.6298936428226,5.35740188374635,8.05286502838135,26,1,0,0,1,0.267791748046875,31.7693061828613,1,6,1,299.999206542969,0,299.999465942383,,,,,,,,,,,,,,,,,,,,,,,,,,,,,,,,,
,3866100354.76297,300.000640869141,50000.232421875,0.0133602858764301,1.13469110916276E-6,1,2,12.9061126708984,5.00534812140535,42.7800007164478,17.4731402053739,2.55081974077768,100,-1.21087138950276E-5,,,,,,,,,,,,,,,,,,,,,300.000610351562,300.000671386719,50000.2265625,50000.23828125,49.6255946859668,5.3576024585273,8.05085849761963,26,1,0,0,1,0.278091430664062,31.7693061828613,1,4,1,300.000671386719,0,300.000640869141,,,,,,,,,,,,,,,,,,,,,,,,,,,,,,,,,