File: LT data/Bridport/D2/380_BR_FULL_SEQUENCE_2.dat
[Header]
; MPMS3 Data File (default extension .dat)
; Copyright (c) 2007, Quantum Design, Inc. All rights reserved.
TITLE,
FILEOPENTIME,3873536498.21952,09/28/2022,4:32 pm
BYAPP,MPMS3 w/ AC,1.0,1.1
INFO,MPMS3 Measurement Release 1.1.16 Build 424, MultiVu Release 2.3.4.19,APPNAME
INFO,Linear Motor Servo Controller,MOTOR_MODULE_NAME
INFO,3101-100 N0,MOTOR_HW_VERSION
INFO,MMC1047,MOTOR_SERIAL_NUMBER
INFO,01.04.28,MOTOR_SOFTWARE_VERSION
INFO,Quantum Design Squid Module,SQUID_MODULE_NAME
INFO,3101-501 B0,SQUID_HW_VERSION
INFO,SQM278,SQUID_SERIAL_NUMBER
INFO,01.03.04,SQUID_SOFTWARE_VERSION
INFO,Quantum Design VSM Oven,OVEN_MODULE_NAME
INFO,3101-201 A3,OVEN_HW_VERSION
INFO,OVB323,OVEN_SERIAL_NUMBER
INFO,01.07.07,OVEN_SOFTWARE_VERSION
INFO,SQUID AC,AC_MODULE_NAME
INFO,3101-401 G0,AC_HW_VERSION
INFO,SAC258,AC_SERIAL_NUMBER
INFO,SQUID AC 00.95.07,AC_SOFTWARE_VERSION
INFO,TCI127,COIL_SERIAL_NUMBER
INFO,0,MOMENT_UNITS
INFO,sndst,SAMPLE_MATERIAL
INFO,,SAMPLE_COMMENT
INFO,,SAMPLE_MASS
INFO,,SAMPLE_VOLUME
INFO,,SAMPLE_MOLECULAR_WEIGHT
INFO,,SAMPLE_SIZE
INFO,,SAMPLE_SHAPE
INFO,Straw,SAMPLE_HOLDER
INFO,Standard,SAMPLE_HOLDER_DETAIL
INFO,67.23,SAMPLE_OFFSET
DATATYPE,COMMENT,1
DATATYPE,TIME,2
STARTUPAXIS,X,2
STARTUPAXIS,Y1,5
FIELDGROUP, VSM,2,3,4,5,6,8,9,10,11,14,15
FIELDGROUP, DC, 2,3,4,14,56,57,58,59,60,61,62,63,64,65,66,67,68,69
FIELDGROUP, AC, 2,3,4,11,16,17,18,19,20,21,22,23,24,25,26,27,28,29,30
STARTUPGROUP, All
[Data]
Comment,Time Stamp (sec),Temperature (K),Magnetic Field (Oe),Moment (emu),M. Std. Err. (emu),Transport Action,Averaging Time (sec),Frequency (Hz),Peak Amplitude (mm),Center Position (mm),Lockin Signal' (V),Lockin Signal (V),Range,M. Quad. Signal (emu),AC Moment (emu),AC M. Std Err. (emu),AC Phase (deg),AC Phase Std. Err. (deg),AC Susceptibility (emu/Oe),AC Suscept. Std Err. (emu/Oe),AC X' (emu/Oe),AC X' Std Err. (emu/Oe),AC X'' (emu/Oe),AC X'' Std Err. (emu/Oe),AC Drive (Oe),AC Frequency (Hz),AC Averaging Time (sec),AC Cycles,AC Range,AC Measure Type,AC Signal' (V),AC Signal'' (V),AC Trim Coil Ratio,AC Trim Coil Phase,Min. Temperature (K),Max. Temperature (K),Min. Field (Oe),Max. Field (Oe),Mass (grams),Motor Lag (deg),Pressure (Torr),Measure Count,Measurement Number,SQUID Status (code),Motor Status (code),Measure Status (code),Motor Current (amps),Motor Temp. (C),Temp. Status (code),Field Status (code),Chamber Status (code),Chamber Temp (K),Redirection State,Evercool Status,Average Temp (K),Rotation Angle (deg),Rotator state,DC Moment Fixed Ctr (emu),DC Moment Err Fixed Ctr (emu),DC Moment Free Ctr (emu),DC Moment Err Free Ctr (emu),DC Fixed Fit,DC Free Fit,DC Calculated Center (mm),DC Calculated Center Err (mm),DC Scan Length (mm),DC Scan Time (s),DC Number of Points,DC Squid Drift,DC Min V (V),DC Max V (V),DC Scans per Measure,Map 01,Map 02,Map 03,Map 04,Map 05,Map 06,Map 07,Map 08,Map 09,Map 10,Map 11,Map 12,Map 13,Map 14,Map 15,Map 16
"FC",3873536838.93324
,3873537704.73173,88.3159828186035,49999.53125,0.047312235308835,1.13989641704035E-5,1,2,13.1008939743042,5.00974768788677,29.6000000089407,55.1307972572535,8.10345737452818,100,2.00513854845934E-5,,,,,,,,,,,,,,,,,,,,,88.1613006591797,88.4706649780273,49999.53125,49999.53125,51.8970071628516,5.72942130776275,7.59678840637207,26,1,0,0,1,0.291061401367188,32.2580642700195,2,1,1,88.1613006591797,0,2084573184,88.3159828186035,,,,,,,,,,,,,,,,,,,,,,,,,,,,,,,,,
,3873537843.64642,65.2044677734375,49999.53125,0.0667159725806943,2.18261705866547E-5,1,2,13.1008939743042,5.00982558757013,29.5299999415874,77.7516666024756,11.3664654300181,1000,-2.37588814468653E-5,,,,,,,,,,,,,,,,,,,,,65.0439300537109,65.3650054931641,49999.53125,49999.53125,51.8598798081882,5.73092615455649,7.40332984924316,26,1,0,0,1,0.29083251953125,33.7243423461914,2,1,1,65.0439300537109,0,2084573184,65.2044677734375,,,,,,,,,,,,,,,,,,,,,,,,,,,,,,,,,
,3873537990.49815,40.1093521118164,49999.53125,0.108414276756537,0.00281767358997383,1,2,13.1008939743042,5.00916220841653,29.4700004160404,126.808882075996,15.1588602802329,1000,-0.00287807593390355,,,,,,,,,,,,,,,,,,,,,39.9128532409668,40.305850982666,49999.53125,49999.53125,52.0603675233709,5.72823531508048,7.04817771911621,26,1,0,0,1,0.290756225585937,33.7243423461914,2,1,1,39.9128532409668,0,2084573184,40.1093521118164,,,,,,,,,,,,,,,,,,,,,,,,,,,,,,,,,
,3873538093.77871,22.7342042922974,49999.53125,0.165022643706048,0.00282392338320079,1,2,13.1008939743042,5.00764076463012,29.449999332428,192.598972342923,25.3913278817097,1000,-0.00238274632453064,,,,,,,,,,,,,,,,,,,,,22.5926551818848,22.87575340271,49999.53125,49999.53125,51.9235825325055,5.73316555862959,6.48068904876709,25,1,64,0,0,0.294265747070313,32.7468223571777,2,1,1,22.5926551818848,0,2084573184,22.7342042922974,,,,,,,,,,,,,,,,,,,,,,,,,,,,,,,,,
,3873538163.13803,11.4160785675049,49999.53125,0.227810797933033,0.000386806425446842,1,2,13.1008939743042,5.0067352329943,29.4400006532669,265.21288765765,39.1328338843607,1000,0.000222863430929751,,,,,,,,,,,,,,,,,,,,,11.288537979126,11.5436191558838,49999.53125,49999.53125,52.3339375051017,5.73886894699254,4.6042423248291,26,1,0,0,1,0.2984619140625,32.7468223571777,2,1,1,11.288537979126,0,2084573184,11.4160785675049,,,,,,,,,,,,,,,,,,,,,,,,,,,,,,,,,
,3873538232.62317,2.0611572265625,49999.53125,0.2849407839266,3.76514929559292E-5,1,2,13.1008939743042,5.00660682472546,29.4400006532669,331.719340895957,48.8851476989487,1000,0.000227569180414101,,,,,,,,,,,,,,,,,,,,,2.055006980896,2.067307472229,49999.53125,49999.53125,53.1186925384095,5.74127279235441,2.38317084312439,26,1,0,0,1,0.298614501953125,32.7468223571777,2,1,1,2.055006980896,0,2084573184,2.0611572265625,,,,,,,,,,,,,,,,,,,,,,,,,,,,,,,,,
,3873538302.13834,2.0513459444046,49999.53125,0.285089563237596,3.48893601861618E-5,1,2,13.1008939743042,5.00556446466811,29.4400006532669,331.801819560293,48.8562184829943,1000,0.000193137647055506,,,,,,,,,,,,,,,,,,,,,2.05000400543213,2.05268788337708,49999.53125,49999.53125,53.1444862795441,5.74650705264728,2.22411894798279,26,1,0,0,1,0.297088623046875,33.2355842590332,2,1,1,2.05268788337708,0,2084573184,2.0513459444046,,,,,,,,,,,,,,,,,,,,,,,,,,,,,,,,,
,3873538371.5292,2.11688721179962,49999.53125,0.284898540018591,2.89282015073548E-5,1,2,13.1008939743042,5.00492598648145,29.4400006532669,331.520594821399,48.8131124929896,1000,0.000191580830199276,,,,,,,,,,,,,,,,,,,,,2.11661052703857,2.11716389656067,49999.53125,49999.53125,53.0725764557748,5.7491093368947,2.25548768043518,26,1,0,0,1,0.298690795898438,33.2355842590332,2,1,1,2.11716389656067,0,2084573184,2.11688721179962,,,,,,,,,,,,,,,,,,,,,,,,,,,,,,,,,
,3873538441.00791,2.19037342071533,49999.53125,0.284667239810881,2.93701608848799E-5,1,2,13.1008939743042,5.00380595887098,29.4400006532669,331.153998067428,48.7157234761325,1000,0.000154899150693744,,,,,,,,,,,,,,,,,,,,,2.18869471549988,2.19205212593079,49999.53125,49999.53125,53.112048695996,5.75390094724975,2.30747509002686,26,1,0,0,1,0.29266357421875,33.2355842590332,2,1,1,2.19205212593079,0,2084573184,2.19037342071533,,,,,,,,,,,,,,,,,,,,,,,,,,,,,,,,,
,3873538510.43151,2.21366429328918,49999.53125,0.284674540226907,2.32623677437389E-5,1,2,13.1008939743042,5.0023241972828,29.4400006532669,331.032163304491,48.6501091890594,1000,0.000114758408742434,,,,,,,,,,,,,,,,,,,,,2.21349096298218,2.21383762359619,49999.53125,49999.53125,53.117129281371,5.76017202082952,2.31990098953247,26,1,0,0,1,0.293350219726562,32.2580642700195,2,1,1,2.21383762359619,0,2084573184,2.21366429328918,,,,,,,,,,,,,,,,,,,,,,,,,,,,,,,,,
,3873538579.93725,2.2314817905426,49999.53125,0.284645325947957,2.99025101270591E-5,1,2,13.1008939743042,5.00087975320266,29.4400006532669,330.862751586601,48.6372641632934,1000,0.000124896318170149,,,,,,,,,,,,,,,,,,,,,2.23037362098694,2.23258996009827,49999.53125,49999.53125,52.8904570107941,5.76567134539544,2.33997273445129,26,1,0,0,1,0.296096801757812,33.2355842590332,2,1,1,2.23037362098694,0,2084573184,2.2314817905426,,,,,,,,,,,,,,,,,,,,,,,,,,,,,,,,,
,3873538649.36789,2.24624168872833,49999.53125,0.284520784914842,4.93476822759435E-5,1,2,13.1008939743042,5.00003806002635,29.4400006532669,330.636923464274,48.6262462469689,1000,0.000143523438795717,,,,,,,,,,,,,,,,,,,,,2.24533176422119,2.24715161323547,49999.53125,49999.53125,53.2097522608999,5.76870399414566,2.34875416755676,26,1,0,0,1,0.298614501953125,33.7243423461914,2,1,1,2.24533176422119,0,2084573600,2.24624168872833,,,,,,,,,,,,,,,,,,,,,,,,,,,,,,,,,
,3873538718.86378,2.18194055557251,49999.53125,0.284763089644308,3.71167621202372E-5,1,2,13.1008939743042,4.99898821576542,29.4400006532669,330.822904496433,48.642219963011,1000,0.000134058917191026,,,,,,,,,,,,,,,,,,,,,2.17556595802307,2.18831515312195,49999.53125,49999.53125,53.0616336565056,5.77296895736738,2.3122341632843,26,1,0,0,1,0.293426513671875,31.7693061828613,2,1,1,2.18831515312195,0,2084574144,2.18194055557251,,,,,,,,,,,,,,,,,,,,,,,,,,,,,,,,,
,3873538788.30751,2.1989574432373,49999.53125,0.284781218717008,4.30019933856757E-5,1,2,13.1008939743042,4.99721421985855,29.4400006532669,330.687975030512,48.5643509332401,1000,8.51497385525218E-5,,,,,,,,,,,,,,,,,,,,,2.19884562492371,2.1990692615509,49999.53125,49999.53125,53.0725764557748,5.77913633776938,2.31992793083191,26,1,0,0,1,0.29388427734375,32.7468223571777,2,1,1,2.19884562492371,0,2084574048,2.1989574432373,,,,,,,,,,,,,,,,,,,,,,,,,,,,,,,,,
,3873538857.79089,2.24417912960052,49999.53125,0.284324562543031,3.77496638194645E-5,1,2,13.1008939743042,4.99639764897719,29.4400006532669,330.066830573019,48.5801682529295,1000,0.000175266270464251,,,,,,,,,,,,,,,,,,,,,2.24176001548767,2.24659824371338,49999.53125,49999.53125,52.9686198627171,5.78311168586871,2.35038638114929,26,1,0,0,1,0.298995971679687,33.2355842590332,2,1,1,2.24659824371338,0,2084574112,2.24417912960052,,,,,,,,,,,,,,,,,,,,,,,,,,,,,,,,,
,3873538927.18622,2.15074300765991,49999.53125,0.284725283675605,3.4970607992909E-5,1,2,13.1008939743042,4.99538279704488,29.4400006532669,330.440904366519,48.6152026818437,1000,0.000158626244815439,,,,,,,,,,,,,,,,,,,,,2.14788699150085,2.15359902381897,49999.53125,49999.53125,53.061242842246,5.78769816038966,2.29181385040283,26,1,0,0,1,0.301132202148438,33.2355842590332,2,1,1,2.14788699150085,0,2084574336,2.15074300765991,,,,,,,,,,,,,,,,,,,,,,,,,,,,,,,,,
,3873538996.66144,1.99892550706863,49999.53125,0.285272095819668,2.3713853317951E-5,1,2,13.1008939743042,4.9967485331726,29.4400006532669,331.204042602027,48.7149143043628,1000,0.000148339354708407,,,,,,,,,,,,,,,,,,,,,1.99828457832336,1.9995664358139,49999.53125,49999.53125,53.0436562005633,5.78143538449373,2.20314335823059,26,1,0,0,1,0.295486450195313,33.2355842590332,5,1,1,1.9995664358139,0,2084574016,1.99892550706863,,,,,,,,,,,,,,,,,,,,,,,,,,,,,,,,,
,3873539477.21664,15.0183715820313,26.4401626586914,0.000339074812002252,6.58425131046966E-7,1,2,13.1008939743042,1.97834606460983,29.4400006532669,0.0805341016692969,0.0119622401410286,10,6.5813859286471E-7,,,,,,,,,,,,,,,,,,,,,15.0183715820313,15.0183715820313,26.4401626586914,26.4401626586914,52.1783934297748,5.93388808308498,4.63322162628174,26,1,0,0,1,0.1397705078125,31.2805480957031,6,1,1,15.0183715820313,0,2084574272,15.0183715820313,,,,,,,,,,,,,,,,,,,,,,,,,,,,,,,,,
,3873539701.49095,50.0289573669434,26.4401626586914,0.000101737686485996,1.51608986597266E-6,1,2,13.1008939743042,1.98101742732578,29.449999332428,0.0241736790266111,0.00395413647349433,1,1.69092660277058E-6,,,,,,,,,,,,,,,,,,,,,50.0289573669434,50.0289573669434,26.4401626586914,26.4401626586914,51.9122489189766,5.90376105847588,6.66922950744629,26,1,0,0,1,0.142669677734375,30.7917900085449,2,1,1,50.0706939697266,0,2084574304,50.0289573669434,,,,,,,,,,,,,,,,,,,,,,,,,,,,,,,,,
,3873539921.41954,85.0737380981445,26.4401626586914,7.44467688705687E-5,3.93070785964682E-8,1,2,13.1008939743042,1.99921930237672,29.5100007206202,0.0180398692587162,0.00266228861596162,1,7.46885891057918E-8,,,,,,,,,,,,,,,,,,,,,85.0737380981445,85.0737380981445,26.4401626586914,26.4401626586914,51.9091224048997,5.9310523166152,6.96559619903564,26,1,0,0,1,0.14129638671875,30.7917900085449,2,1,1,85.0737380981445,0,2084574144,85.0737380981445,,,,,,,,,,,,,,,,,,,,,,,,,,,,,,,,,
,3873540133.54197,120.027610778809,26.4401626586914,5.34781779397402E-5,4.52039593712873E-8,1,2,13.1008939743042,1.99603820501096,29.5800007879734,0.0129212525856912,0.00189632254731779,1,1.08298530828742E-8,,,,,,,,,,,,,,,,,,,,,120.027610778809,120.027610778809,26.4401626586914,26.4401626586914,51.9579741873517,5.96584988204912,7.11176443099976,26,1,0,0,1,0.146942138671875,31.7693061828613,2,1,1,120.027610778809,0,2084574496,120.027610778809,,,,,,,,,,,,,,,,,,,,,,,,,,,,,,,,,
,3873540344.48361,155.022552490234,26.4401626586914,3.83438544362659E-5,5.06967541360883E-7,1,2,13.1008939743042,1.99531603892796,29.6800006181002,0.00927232473126085,0.00126226174292296,1,-3.91762395543955E-7,,,,,,,,,,,,,,,,,,,,,155.022552490234,155.022552490234,26.4401626586914,26.4401626586914,52.0205044688901,5.97371094805723,7.20812129974365,26,1,0,0,1,0.148773193359375,31.2805480957031,2,1,1,155.022552490234,0,2084574144,155.022552490234,,,,,,,,,,,,,,,,,,,,,,,,,,,,,,,,,
,3873540556.03095,190.043960571289,26.4401626586914,2.84336969651584E-5,4.22536328638918E-8,1,2,13.1008939743042,1.99431277512603,29.8100002110004,0.00685843554927739,0.00100923658117646,1,1.66860581856973E-8,,,,,,,,,,,,,,,,,,,,,190.043960571289,190.043960571289,26.4401626586914,26.4401626586914,51.7610038005055,5.97886592260682,7.33198547363281,25,1,64,0,0,0.150375366210938,30.7917900085449,2,1,1,190.043960571289,0,2084574176,190.043960571289,,,,,,,,,,,,,,,,,,,,,,,,,,,,,,,,,
,3873540766.34372,225.016662597656,26.4401626586914,2.08078801984404E-5,4.72901398081362E-8,1,2,13.1008939743042,1.99265981161198,29.9699995666742,0.00500880397603648,0.00075337753862138,1,7.85366190065979E-8,,,,,,,,,,,,,,,,,,,,,225.016662597656,225.016662597656,26.4401626586914,26.4401626586914,51.7860159131209,5.98601449082232,7.5693793296814,25,1,64,0,0,0.155258178710938,31.2805480957031,2,1,1,225.016662597656,0,2084574272,225.016662597656,,,,,,,,,,,,,,,,,,,,,,,,,,,,,,,,,
,3873540969.40041,258.617813110352,26.4401626586914,1.54432290639813E-5,4.85667664114329E-8,1,2,13.1008939743042,1.99133925918115,30.1399994641542,0.00371537872845161,0.000540667673711926,1,-1.55977641005551E-8,,,,,,,,,,,,,,,,,,,,,258.464691162109,258.770935058594,26.4401626586914,26.4401626586914,51.7078530611978,5.99635950047912,8.06289386749268,25,1,64,0,0,0.15167236328125,31.2805480957031,2,1,1,258.770935058594,0,2084574112,258.617813110352,,,,,,,,,,,,,,,,,,,,,,,,,,,,,,,,,
,3873541175.96477,293.032745361328,26.4401626586914,1.15915731497984E-5,4.74382464879431E-8,1,2,13.1008939743042,1.99080488696753,30.349999666214,0.00278582333925936,0.000415807306141125,1,3.0686519413068E-8,,,,,,,,,,,,,,,,,,,,,293.032745361328,293.032745361328,26.4401626586914,26.4401626586914,51.5937352973901,5.98932346693122,7.98832082748413,24,1,64,0,0,0.143661499023438,31.2805480957031,2,1,1,293.032745361328,0,2084574240,293.032745361328,,,,,,,,,,,,,,,,,,,,,,,,,,,,,,,,,
,3873543025.3376,2.00038975477219,43545.310546875,0.270935689521488,3.52419357599476E-5,1,2,13.1008939743042,4.99166263027943,29.4300001114607,314.095719267328,46.3055852227631,1000,0.000231253716963879,,,,,,,,,,,,,,,,,,,,,1.9995790719986,2.00120043754578,43450.34765625,43640.2734375,52.626266571294,5.80011477923505,2.21510338783264,26,1,0,0,1,0.308685302734375,33.2355842590332,1,6,1,1.9995790719986,0,2084573184,2.00038975477219,,,,,,,,,,,,,,,,,,,,,,,,,,,,,,,,,
,3873543094.78859,1.99947029352188,36610.126953125,0.25177779853399,3.77220108124347E-5,1,2,13.1008939743042,4.99234350514932,29.4199995696545,291.936193129469,43.07741959986,1000,0.000247571183727144,,,,,,,,,,,,,,,,,,,,,1.99757301807404,2.00136756896973,36520.12109375,36700.1328125,52.5441955767748,5.79819682347987,2.21360659599304,26,1,0,0,1,0.307540893554687,32.7468223571777,1,6,1,2.00136756896973,0,2084573184,1.99947029352188,,,,,,,,,,,,,,,,,,,,,,,,,,,,,,,,,
,3873543164.29755,1.99951601028442,29665.1572265625,0.22899151763246,6.17923806871752E-5,1,2,13.1008939743042,4.99104182842235,29.4300001114607,265.418288560389,39.1663246510329,1000,0.000226706437577333,,,,,,,,,,,,,,,,,,,,,1.99872469902039,2.00030732154846,29580.236328125,29750.078125,52.4515725972459,5.80405400979059,2.20700216293335,26,1,0,0,1,0.308609008789063,32.7468223571777,1,6,1,2.00030732154846,0,2084573184,1.99951601028442,,,,,,,,,,,,,,,,,,,,,,,,,,,,,,,,,
,3873543233.71688,1.99947780370712,22734.306640625,0.201056162425869,5.67254981152891E-5,1,2,13.1008939743042,4.99015182739335,29.4300001114607,232.987587925233,34.334155460207,1000,0.000159736103756888,,,,,,,,,,,,,,,,,,,,,1.99798333644867,2.00097227096558,22649.34375,22819.26953125,52.1479099175247,5.80790209635064,2.19671988487244,26,1,0,0,1,0.299835205078125,32.7468223571777,1,6,1,2.00097227096558,0,2084573184,1.99947780370712,,,,,,,,,,,,,,,,,,,,,,,,,,,,,,,,,
,3873543303.19614,2.00001603364944,15799.3876953125,0.165137306001478,6.11902626530459E-5,1,2,13.1008939743042,4.98962433201404,29.4300001114607,191.337560831474,28.1842392362397,1000,0.000120918062250132,,,,,,,,,,,,,,,,,,,,,1.99668490886688,2.00334715843201,15709.3994140625,15889.3759765625,52.0740460224574,5.81030625156297,2.19622921943665,26,1,0,0,1,0.307769775390625,32.7468223571777,1,6,1,1.99668490886688,0,2084573184,2.00001603364944,,,,,,,,,,,,,,,,,,,,,,,,,,,,,,,,,
,3873543372.63284,1.99896138906479,8855.990234375,0.116060875247073,9.19243911588241E-5,1,2,13.1008939743042,4.98869811435951,29.4300001114607,134.443158407974,19.7803365935595,1000,6.53015024778969E-5,,,,,,,,,,,,,,,,,,,,,1.9980126619339,1.99991011619568,8766.0205078125,8945.9599609375,51.9603190729093,5.81250001284292,2.18945813179016,26,1,0,0,1,0.29998779296875,32.7468223571777,1,6,1,1.99991011619568,0,2084573184,1.99896138906479,,,,,,,,,,,,,,,,,,,,,,,,,,,,,,,,,
,3873543442.15509,1.99973201751709,1908.92041015625,0.0409765964116796,0.000152474113368649,1,2,13.1008939743042,4.98954679244033,29.4300001114607,47.4864792066958,6.92735974420255,1000,-2.69767450508128E-5,,,,,,,,,,,,,,,,,,,,,1.99971485137939,1.99974918365479,1828.90771484375,1988.93310546875,51.9462497595632,5.80777564212455,2.18271827697754,26,1,0,0,1,0.309219360351562,34.7018585205078,1,6,1,1.99971485137939,0,2084573184,1.99973201751709,,,,,,,,,,,,,,,,,,,,,,,,,,,,,,,,,
,3873543515.55814,2.00008904933929,-5429.78833007812,-0.0757319677179976,0.000121226320085006,1,2,13.1008939743042,4.99016742296103,29.4300001114607,-87.7439419382034,-13.0421947690467,100,-0.000154621154796632,,,,,,,,,,,,,,,,,,,,,2.00007843971252,2.00009965896606,-5519.41796875,-5340.15869140625,51.9153754330536,5.80836403422638,2.18522834777832,26,1,0,0,1,0.300369262695313,33.7243423461914,1,6,1,2.00009965896606,0,2084573184,2.00008904933929,,,,,,,,,,,,,,,,,,,,,,,,,,,,,,,,,
,3873543602.99126,2.00059646368027,-14177.2358398438,-0.152779409454111,7.12103211646264E-5,1,2,13.1008939743042,4.98976336077661,29.4300001114607,-176.989583184232,-26.3239439482106,100,-0.000325730432122702,,,,,,,,,,,,,,,,,,,,,1.99953711032867,2.00165581703186,-14262.310546875,-14092.1611328125,52.1240702476882,5.80830834386013,2.1799488067627,26,1,0,0,1,0.301284790039063,32.7468223571777,1,6,1,2.00165581703186,0,2084573184,2.00059646368027,,,,,,,,,,,,,,,,,,,,,,,,,,,,,,,,,
,3873543686.21553,1.99971091747284,-22500.2021484375,-0.199346379866474,6.10315520109325E-5,1,2,13.1008939743042,4.98956376978172,29.4300001114607,-230.965279675554,-34.0559504256324,1000,-0.000175113730615019,,,,,,,,,,,,,,,,,,,,,1.9994889497757,1.99993288516998,-22585.263671875,-22415.140625,52.362076131794,5.8076361044818,2.18139004707336,26,1,0,0,1,0.299911499023438,33.7243423461914,1,6,1,1.99993288516998,0,2084573184,1.99971091747284,,,,,,,,,,,,,,,,,,,,,,,,,,,,,,,,,
,3873543755.65297,2.00032079219818,-29453.9951171875,-0.228306406394709,5.25766068622896E-5,1,2,13.1008939743042,4.98969371606037,29.4300001114607,-264.519520566579,-39.0653748936305,1000,-0.000252785037189044,,,,,,,,,,,,,,,,,,,,,1.99986410140991,2.00077748298645,-29544.330078125,-29363.66015625,52.570380132169,5.80634369885293,2.17221879959106,26,1,0,0,1,0.299758911132812,32.7468223571777,1,6,1,2.00077748298645,0,2084573632,2.00032079219818,,,,,,,,,,,,,,,,,,,,,,,,,,,,,,,,,
,3873543825.21335,2.00071382522583,-36427.974609375,-0.251343094586697,8.35557477333745E-5,1,2,13.1008939743042,4.98988214414216,29.4300001114607,-291.190527131968,-43.248831939668,1000,-0.00048486217458896,,,,,,,,,,,,,,,,,,,,,2.00060343742371,2.00082421302795,-36518.21484375,-36337.734375,52.7610974908614,5.80575564184594,2.17377376556396,26,1,0,0,1,0.309982299804687,32.7468223571777,1,6,1,2.00060343742371,0,2084573856,2.00071382522583,,,,,,,,,,,,,,,,,,,,,,,,,,,,,,,,,
,3873543894.59647,2.00006246566772,-43372.416015625,-0.270842895057378,0.000185725780964544,1,2,13.1008939743042,4.98988649541299,29.4300001114607,-313.788222078369,-46.5629436318626,1000,-0.000486846369326308,,,,,,,,,,,,,,,,,,,,,1.99990177154541,2.00022315979004,-43462.64453125,-43282.1875,53.0061380316402,5.8070046630915,2.17631936073303,26,1,0,0,1,0.29937744140625,32.7468223571777,1,6,1,1.99990177154541,0,2084573824,2.00006246566772,,,,,,,,,,,,,,,,,,,,,,,,,,,,,,,,,
,3873543965.34391,1.99886608123779,-50000.3125,-0.286935083489787,4.69970111717915E-5,1,2,13.1008939743042,4.98991034232722,29.4300001114607,-332.447019471706,-49.2426351435182,1000,-0.000440539119232972,,,,,,,,,,,,,,,,,,,,,1.99886608123779,1.99886608123779,-50000.3125,-50000.3125,53.1671535066018,5.80569245167523,2.17177295684814,26,1,0,0,1,0.308380126953125,33.2355842590332,1,6,1,1.99886608123779,0,2084573760,1.99886608123779,,,,,,,,,,,,,,,,,,,,,,,,,,,,,,,,,
,3873544035.51872,1.99991554021835,-43018.1640625,-0.270419884849624,4.34634584267325E-5,1,2,13.1008939743042,4.99065207549069,29.4300001114607,-313.394002035814,-46.3056074725348,1000,-0.000318194391314314,,,,,,,,,,,,,,,,,,,,,1.99955999851227,2.00027108192444,-43103.15234375,-42933.17578125,52.9060895811787,5.80301557775433,2.16907358169556,24,1,68,0,0,0.30914306640625,33.2355842590332,1,6,1,2.00027108192444,0,2084573792,1.99991554021835,,,,,,,,,,,,,,,,,,,,,,,,,,,,,,,,,
,3873544104.94637,1.99991244077682,-36084.703125,-0.251038459567112,4.46756240444541E-5,1,2,13.1008939743042,4.99131994202715,29.4300001114607,-290.993349994886,-42.9521816493199,1000,-0.000258568042581754,,,,,,,,,,,,,,,,,,,,,1.99979054927826,2.00003433227539,-36174.6796875,-35994.7265625,52.6387726276017,5.80006115022378,2.17253661155701,26,1,0,0,1,0.306472778320313,33.2355842590332,1,6,1,2.00003433227539,0,2084573792,1.99991244077682,,,,,,,,,,,,,,,,,,,,,,,,,,,,,,,,,
,3873544174.47221,1.99979555606842,-29145.935546875,-0.227825809568603,5.66376944166739E-5,1,2,13.1008939743042,4.99062507384084,29.4300001114607,-264.036348356581,-38.9617676232724,1000,-0.000225018932939598,,,,,,,,,,,,,,,,,,,,,1.99945759773254,2.0001335144043,-29235.8125,-29056.05859375,52.6528419409479,5.80294322077667,2.17056608200073,26,1,0,0,1,0.307540893554687,33.2355842590332,1,6,1,1.99945759773254,0,2084573728,1.99979555606842,,,,,,,,,,,,,,,,,,,,,,,,,,,,,,,,,
,3873544244.04566,2.00000965595245,-22196.7578125,-0.19919038773963,5.13092011139528E-5,1,2,13.1008939743042,4.99151899367638,29.4199995696545,-230.912695538543,-34.0381014086478,1000,-0.000166453385156031,,,,,,,,,,,,,,,,,,,,,1.99998164176941,2.0000376701355,-22276.7578125,-22116.7578125,52.3339375051017,5.79780241475638,2.16492795944214,26,1,0,0,1,0.307998657226562,33.2355842590332,1,6,1,2.0000376701355,0,2084573888,2.00000965595245,,,,,,,,,,,,,,,,,,,,,,,,,,,,,,,,,
,3873544313.44081,2.00045365095139,-15268.0009765625,-0.162354564751829,7.00220231655458E-5,1,2,13.1008939743042,4.99096593892192,29.4199995696545,-188.179998972994,-27.7482757563913,1000,-0.000143494464905481,,,,,,,,,,,,,,,,,,,,,1.99989545345306,2.00101184844971,-15347.98828125,-15188.013671875,52.1850372721882,5.8001912764773,2.16931509971619,26,1,0,0,1,0.307998657226562,34.2131004333496,1,6,1,1.99989545345306,0,2084573888,2.00045365095139,,,,,,,,,,,,,,,,,,,,,,,,,,,,,,,,,
,3873544382.79732,2.00027787685394,-8338.37890625,-0.111807036541252,9.42982156244346E-5,1,2,13.1008939743042,4.99190648653916,29.4300001114607,-129.630810362509,-19.0825727201113,1000,-7.15754193658937E-5,,,,,,,,,,,,,,,,,,,,,2.00022387504578,2.00033187866211,-8433.373046875,-8243.384765625,51.9513303449382,5.79706957654652,2.15974640846252,26,1,0,0,1,0.307388305664063,33.2355842590332,1,6,1,2.00022387504578,0,2084573728,2.00027787685394,,,,,,,,,,,,,,,,,,,,,,,,,,,,,,,,,
,3873544452.25656,2.00017929077148,-1397.46588134766,-0.0332932210980888,0.000164936582760526,1,2,13.1008939743042,4.99167868984138,29.4300001114607,-38.6075196041026,-5.61839950846541,1000,3.34799524779708E-5,,,,,,,,,,,,,,,,,,,,,2.00017762184143,2.00018095970154,-1487.54663085938,-1307.38513183594,52.0122973694382,5.79830053011689,2.16266918182373,26,1,0,0,1,0.305633544921875,33.7243423461914,1,6,1,2.00018095970154,0,2084573504,2.00017929077148,,,,,,,,,,,,,,,,,,,,,,,,,,,,,,,,,
,3873544533.83574,1.99986654520035,6756.96362304687,0.0906359520492593,0.000115677558441725,1,2,13.1008939743042,4.99020540212522,29.4300001114607,105.010726843616,15.6245089380018,100,0.00019838585568837,,,,,,,,,,,,,,,,,,,,,1.99964892864227,2.00008416175842,6681.83349609375,6832.09375,51.9904117708997,5.80448056884756,2.15698194503784,26,1,0,0,1,0.3082275390625,33.2355842590332,1,6,1,1.99964892864227,0,2084573184,1.99986654520035,,,,,,,,,,,,,,,,,,,,,,,,,,,,,,,,,
,3873544615.0004,1.99993890523911,14880.3969726562,0.158083176155888,6.83723647203627E-5,1,2,13.1008939743042,4.99106103500104,29.4300001114607,183.229664642837,27.048953321915,1000,0.000165586191428144,,,,,,,,,,,,,,,,,,,,,1.99984061717987,2.00003719329834,14795.2294921875,14965.564453125,52.2245095124094,5.8011883722948,2.16243648529053,26,1,0,0,1,0.2972412109375,33.7243423461914,1,6,1,2.00003719329834,0,2084573856,1.99993890523911,,,,,,,,,,,,,,,,,,,,,,,,,,,,,,,,,
,3873544684.49502,2.00024700164795,21833.1162109375,0.196741573303381,5.5527583346654E-5,1,2,13.1008939743042,4.99024815110653,29.4300001114607,227.98930703673,33.6297961988397,1000,0.00018351320740582,,,,,,,,,,,,,,,,,,,,,1.9998791217804,2.0006148815155,21748.029296875,21918.203125,52.3128335350824,5.80405784282636,2.1611819267273,26,1,0,0,1,0.3076171875,33.2355842590332,1,6,1,1.9998791217804,0,2084573504,2.00024700164795,,,,,,,,,,,,,,,,,,,,,,,,,,,,,,,,,
,3873544753.96167,1.99983263015747,28791.46484375,0.22627472444767,5.09738337140546E-5,1,2,13.1008939743042,4.9904070666517,29.4300001114607,262.219138794291,38.718347270223,1000,0.000244372814461604,,,,,,,,,,,,,,,,,,,,,1.99959206581116,2.00007319450378,28706.2421875,28876.6875,52.4781479668998,5.80387169457924,2.16490530967712,26,1,0,0,1,0.308074951171875,33.2355842590332,1,6,1,1.99959206581116,0,2084573792,1.99983263015747,,,,,,,,,,,,,,,,,,,,,,,,,,,,,,,,,
,3873544823.44063,2.00026381015778,35752.513671875,0.250000977960083,3.79844585581977E-5,1,2,13.1008939743042,4.99007098918642,29.4300001114607,289.686138413682,42.7803472644377,1000,0.000275334848390706,,,,,,,,,,,,,,,,,,,,,2.00012159347534,2.00040602684021,35672.203125,35832.82421875,52.6801989391209,5.80624302885318,2.16276907920837,26,1,0,0,1,0.299224853515625,31.7693061828613,1,6,1,2.00040602684021,0,2084573984,2.00026381015778,,,,,,,,,,,,,,,,,,,,,,,,,,,,,,,,,
,3873544892.86315,2.00018751621246,42712.802734375,0.269785466298553,5.00703337359616E-5,1,2,13.1008939743042,4.99034526328818,29.4300001114607,312.635125167956,46.1705555946441,1000,0.000298088397754472,,,,,,,,,,,,,,,,,,,,,2.00001692771912,2.00035810470581,42627.57421875,42798.03125,52.8341797574094,5.8050113898445,2.15936803817749,26,1,0,0,1,0.3082275390625,32.7468223571777,1,6,1,2.00035810470581,0,2084573728,2.00018751621246,,,,,,,,,,,,,,,,,,,,,,,,,,,,,,,,,
,3873544962.33687,2.0000758767128,49674.662109375,0.286356156024208,0.000114266446963649,1,2,13.1008939743042,4.98905747358054,29.4199995696545,331.698542315789,49.1197461270404,1000,0.000429493325216653,,,,,,,,,,,,,,,,,,,,,1.99990165233612,2.00025010108948,49584.8359375,49764.48828125,52.9463434499191,5.81064806087043,2.16499924659729,26,1,0,0,1,0.30487060546875,32.7468223571777,1,6,1,1.99990165233612,0,2084573760,2.0000758767128,,,,,,,,,,,,,,,,,,,,,,,,,,,,,,,,,
,3873545479.14185,32.0110130310059,26.2176666259766,0.000120069448046916,4.00407787064167E-7,1,5,13.1008939743042,5.00047772808474,29.4300001114607,0.139546883867589,0.0205300135762522,1,6.65266530075846E-8,,,,,,,,,,,,,,,,,,,,,32.0110130310059,32.0110130310059,26.2176666259766,26.2176666259766,51.8086831401786,5.80308527599357,6.2766752243042,66,1,0,0,1,0.308990478515625,32.7468223571777,2,1,1,32.0110130310059,0,2084574144,32.0110130310059,,,,,,,,,,,,,,,,,,,,,,,,,,,,,,,,,
,3873545701.58246,67.0705642700195,26.2176666259766,8.25993107938321E-5,1.8947872483339E-8,1,5,13.1008939743042,5.00002955002248,29.4700004160404,0.0959916710610186,0.014085281743003,1,1.46614685101432E-8,,,,,,,,,,,,,,,,,,,,,67.0705642700195,67.0705642700195,26.2176666259766,26.2176666259766,51.9681353581017,5.80497205311274,6.8241024017334,66,1,0,0,1,0.309982299804687,33.2355842590332,2,1,1,67.0705642700195,0,2084574272,67.0705642700195,,,,,,,,,,,,,,,,,,,,,,,,,,,,,,,,,
,3873545917.39482,102.026840209961,26.2176666259766,6.14966682830055E-5,1.55403363494224E-8,1,5,13.1008939743042,4.99837435773516,29.5400004833937,0.0714354290222732,0.0104749608306649,1,4.95327859927432E-9,,,,,,,,,,,,,,,,,,,,,102.026840209961,102.026840209961,26.2176666259766,26.2176666259766,52.0611491518901,5.8096507693737,7.0163631439209,66,1,0,0,1,0.311126708984375,33.7243423461914,2,1,1,102.026840209961,0,2084574336,102.026840209961,,,,,,,,,,,,,,,,,,,,,,,,,,,,,,,,,
,3873546128.95642,137.048110961914,26.2176666259766,4.41129971760031E-5,1.27148398994695E-8,1,5,13.1008939743042,4.99823905118617,29.6299997717142,0.0512441230379869,0.00748797979222607,1,-1.8545767822512E-8,,,,,,,,,,,,,,,,,,,,,137.048110961914,137.048110961914,26.2176666259766,26.2176666259766,51.8673052791209,5.81098436386825,7.12248706817627,66,1,0,0,1,0.302963256835937,33.2355842590332,2,1,1,137.048110961914,0,2084574144,137.048110961914,,,,,,,,,,,,,,,,,,,,,,,,,,,,,,,,,
,3873546340.7558,172.000946044922,26.2176666259766,3.20574022088145E-5,6.71755455660832E-9,1,5,13.1008939743042,4.99629934767757,29.7400001436472,0.0372172139767393,0.00545384644933962,1,-3.80754699299347E-10,,,,,,,,,,,,,,,,,,,,,172.000946044922,172.000946044922,26.2176666259766,26.2176666259766,51.9544568590151,5.82118576128756,7.21495246887207,66,1,0,0,1,0.300979614257812,33.2355842590332,2,1,1,172.000946044922,0,2084574432,172.000946044922,,,,,,,,,,,,,,,,,,,,,,,,,,,,,,,,,
,3873546551.21606,207.027084350586,26.2176666259766,2.36060850395152E-5,7.68017908158423E-9,1,5,13.1008939743042,4.99110294899712,29.8800002783537,0.027364059813431,0.00402142184246717,1,9.40253824934838E-9,,,,,,,,,,,,,,,,,,,,,207.027084350586,207.027084350586,26.2176666259766,26.2176666259766,51.8798113354286,5.8370615824307,7.32528734207153,66,1,0,0,1,0.309677124023438,33.7243423461914,2,1,1,207.027084350586,0,2084574336,207.027084350586,,,,,,,,,,,,,,,,,,,,,,,,,,,,,,,,,
,3873546762.38853,242.042984008789,26.2176666259766,1.71578023231917E-5,7.73595567020259E-9,1,5,13.1008939743042,4.98696795995077,30.0500001758337,0.0198646060303621,0.00293011708166237,1,1.59771307735969E-8,,,,,,,,,,,,,,,,,,,,,242.042984008789,242.042984008789,26.2176666259766,26.2176666259766,52.0095616696209,5.85326768661636,7.65493726730347,64,1,64,0,0,0.314712524414063,33.2355842590332,2,1,1,242.042984008789,0,2084574240,242.042984008789,,,,,,,,,,,,,,,,,,,,,,,,,,,,,,,,,
,3873546973.05985,277.012084960938,26.2176666259766,1.27909749206653E-5,1.11806891552046E-7,1,5,13.1008939743042,4.99546906386537,30.239999294281,0.0148582514180754,0.00209401724362445,1,-7.04324071802147E-8,,,,,,,,,,,,,,,,,,,,,277.012084960938,277.012084960938,26.2176666259766,26.2176666259766,51.5171357025055,5.85284707109883,8.07890033721924,65,1,64,0,0,0.299758911132812,33.2355842590332,2,1,1,277.012084960938,0,2084574336,277.012084960938,,,,,,,,,,,,,,,,,,,,,,,,,,,,,,,,,
,3873547787.16668,290.997985839844,26.2176666259766,1.37889277353741E-5,1.03220926521897E-7,1,5,13.1008939743042,4.99743405653882,30.3199999034405,0.0160194241957356,0.00230564979675326,1,-3.54443832919691E-8,,,,,,,,,,,,,,,,,,,,,290.997985839844,290.997985839844,26.2176666259766,26.2176666259766,51.6593920930055,5.84814918380592,9.36376285552979,65,1,64,0,0,0.304946899414063,32.2580642700195,2,1,1,290.997985839844,0,2084573184,290.997985839844,,,,,,,,,,,,,,,,,,,,,,,,,,,,,,,,,
,3873547981.41624,255.994033813477,26.2176666259766,1.5430459211226E-5,1.08346405010729E-7,1,5,13.1008939743042,4.99845942973939,30.1500000059605,0.017915516460633,0.00269087744081049,1,5.5033450644176E-8,,,,,,,,,,,,,,,,,,,,,255.994033813477,255.994033813477,26.2176666259766,26.2176666259766,51.8422931665055,5.83467848028329,8.90164947509766,65,1,64,0,0,0.315170288085937,32.7468223571777,2,1,1,255.994033813477,0,2084574112,255.994033813477,,,,,,,,,,,,,,,,,,,,,,,,,,,,,,,,,
,3873548190.60082,220.970062255859,26.2176666259766,1.7477983562153E-5,1.13951419366526E-8,1,5,13.1008939743042,5.00109659184353,30.009999871254,0.0203156885868563,0.00299619835606649,1,1.58918363879498E-8,,,,,,,,,,,,,,,,,,,,,220.970062255859,220.970062255859,26.2176666259766,26.2176666259766,52.0634940374478,5.84739410362309,8.47611618041992,66,1,0,0,1,0.308990478515625,32.7468223571777,2,1,1,220.970062255859,0,2084573728,220.970062255859,,,,,,,,,,,,,,,,,,,,,,,,,,,,,,,,,
,3873548400.68491,185.954116821289,26.2176666259766,1.9631503154877E-5,8.96981201617846E-9,1,5,13.1008939743042,5.00628712710472,29.8900008201599,0.0228552471412046,0.00334799175283262,1,-1.27438423524633E-9,,,,,,,,,,,,,,,,,,,,,185.954116821289,185.954116821289,26.2176666259766,26.2176666259766,51.9947107277555,5.81875746935546,8.17670917510986,66,1,0,0,1,0.298690795898438,33.2355842590332,2,1,1,185.954116821289,0,2084573760,185.954116821289,,,,,,,,,,,,,,,,,,,,,,,,,,,,,,,,,
,3873548610.43358,150.947814941406,26.2176666259766,2.21681833009901E-5,9.88355467355617E-9,1,5,13.1008939743042,5.00691392237331,29.7800004482269,0.0258145443652938,0.0037707314411302,1,-1.04841435386024E-8,,,,,,,,,,,,,,,,,,,,,150.947814941406,150.947814941406,26.2176666259766,26.2176666259766,51.9954923562747,5.81847285912124,7.9381685256958,66,1,0,0,1,0.299606323242188,33.7243423461914,2,1,1,150.947814941406,0,2084574048,150.947814941406,,,,,,,,,,,,,,,,,,,,,,,,,,,,,,,,,
,3873548819.44528,115.994911193848,26.2176666259766,2.42097110900223E-5,2.4459797230551E-8,1,5,13.1008939743042,5.00724649646025,29.6800006181002,0.0281884843156094,0.00415937494569373,1,2.37618070195365E-8,,,,,,,,,,,,,,,,,,,,,115.994911193848,115.994911193848,26.2176666259766,26.2176666259766,52.1877729720055,5.816796901299,7.73705577850342,66,1,0,0,1,0.2978515625,33.2355842590332,2,1,1,115.994911193848,0,2084574048,115.994911193848,,,,,,,,,,,,,,,,,,,,,,,,,,,,,,,,,
,3873549029.34174,80.9883422851562,26.2176666259766,2.71916489440115E-5,9.1381952239932E-9,1,5,13.1008939743042,5.00776200313558,29.5800007879734,0.0316716168143849,0.00462755023304107,1,-1.17873028087352E-8,,,,,,,,,,,,,,,,,,,,,80.9883422851562,80.9883422851562,26.2176666259766,26.2176666259766,51.9736067577363,5.81531793513074,7.51989555358887,65,1,64,0,0,0.296554565429687,33.7243423461914,2,1,1,80.9883422851562,0,2084573888,80.9883422851562,,,,,,,,,,,,,,,,,,,,,,,,,,,,,,,,,
,3873549233.15852,45.9356994628906,26.2176666259766,3.15710396550493E-5,6.92886635317322E-8,1,5,13.1008939743042,5.00904291523032,29.5000001788139,0.0367734275881708,0.00545840627329485,1,5.81004205777873E-8,,,,,,,,,,,,,,,,,,,,,45.9356994628906,45.9356994628906,26.2176666259766,26.2176666259766,51.9212376469478,5.80990232569284,7.19359683990478,64,1,64,0,0,0.307769775390625,31.2805480957031,2,1,1,45.9356994628906,0,2084573184,45.9356994628906,,,,,,,,,,,,,,,,,,,,,,,,,,,,,,,,,
,3873549441.27859,10.9733257293701,26.2176666259766,5.45776389396984E-5,9.17530069146932E-8,1,5,13.1008939743042,5.01039551791149,29.4599998742342,0.0635968108917014,0.00942818325255213,1,9.06066583332884E-8,,,,,,,,,,,,,,,,,,,,,10.9733257293701,10.9733257293701,26.2176666259766,26.2176666259766,51.9884576996017,5.80580931536359,4.8524923324585,65,1,64,0,0,0.29998779296875,33.7243423461914,2,1,1,10.9733257293701,0,2084573184,10.9733257293701,,,,,,,,,,,,,,,,,,,,,,,,,,,,,,,,,
,3873549832.47995,26.0070419311523,26.2176666259766,3.98188762605802E-5,2.02337641116091E-8,1,5,13.1008939743042,5.00812364458577,29.4400006532669,0.0463814484513268,0.00679409763286159,1,-2.72924146496351E-9,,,,,,,,,,,,,,,,,,,,,26.0070419311523,26.0070419311523,26.2176666259766,26.2176666259766,52.0326197109382,5.81426869677461,6.13210010528564,66,1,0,0,1,0.300750732421875,33.2355842590332,2,1,1,26.0070419311523,0,2084574048,26.0070419311523,,,,,,,,,,,,,,,,,,,,,,,,,,,,,,,,,
,3873550056.57206,61.0264358520508,26.2176666259766,2.95771651386704E-5,5.48605567082819E-8,1,5,13.1008939743042,5.00604047338357,29.4700004160404,0.0344284613991989,0.00506617901340603,1,1.73079968037079E-8,,,,,,,,,,,,,,,,,,,,,61.0264358520508,61.0264358520508,26.2176666259766,26.2176666259766,51.9595374443901,5.82173870355102,6.80291986465454,64,1,64,0,0,0.298614501953125,33.2355842590332,2,1,1,61.0264358520508,0,2084574304,61.0264358520508,,,,,,,,,,,,,,,,,,,,,,,,,,,,,,,,,
,3873550273.91272,96.0589294433594,26.2176666259766,2.51055491418356E-5,5.85623986667629E-9,1,5,13.1008939743042,5.00326493189362,29.5299999415874,0.0292044013553139,0.00427197089948548,1,-6.75354209150058E-9,,,,,,,,,,,,,,,,,,,,,96.0589294433594,96.0589294433594,26.2176666259766,26.2176666259766,51.9587558158709,5.83197376929981,7.02494239807129,66,1,0,0,1,0.304183959960937,34.7018585205078,2,1,1,96.0589294433594,0,2084574240,96.0589294433594,,,,,,,,,,,,,,,,,,,,,,,,,,,,,,,,,
,3873550485.69267,131.027709960938,26.2176666259766,2.22146809034102E-5,6.7146442696273E-9,1,5,13.1008939743042,5.00219677963337,29.6000000089407,0.0258339339200309,0.00377828242927334,1,-6.53333249695954E-9,,,,,,,,,,,,,,,,,,,,,131.027709960938,131.027709960938,26.2176666259766,26.2176666259766,52.3155692348998,5.82522498027634,7.1278862953186,66,1,0,0,1,0.301971435546875,31.7693061828613,2,1,1,131.027709960938,0,2084574272,131.027709960938,,,,,,,,,,,,,,,,,,,,,,,,,,,,,,,,,
,3873550696.50281,166.022796630859,26.2176666259766,1.92709262807297E-5,8.68124586676124E-9,1,5,13.1008939743042,5.00112977345317,29.7200009226799,0.0224029570909318,0.0032829962610371,1,-1.90729293804544E-10,,,,,,,,,,,,,,,,,,,,,166.022796630859,166.022796630859,26.2176666259766,26.2176666259766,51.9630547727266,5.84091437762938,7.20734977722168,64,1,64,0,0,0.307693481445313,33.7243423461914,2,1,1,166.022796630859,0,2084574336,166.022796630859,,,,,,,,,,,,,,,,,,,,,,,,,,,,,,,,,
,3873550907.76595,201.004608154297,26.2176666259766,1.65434767022665E-5,8.41879353522618E-9,1,5,13.1008939743042,4.99596949048108,29.8599991947412,0.019203087115755,0.00282363132217886,1,7.89306543476747E-9,,,,,,,,,,,,,,,,,,,,,201.004608154297,201.004608154297,26.2176666259766,26.2176666259766,52.0959316209959,5.85424120200106,7.28349590301514,64,1,64,0,0,0.315093994140625,33.2355842590332,2,1,1,201.004608154297,0,2084574304,201.004608154297,,,,,,,,,,,,,,,,,,,,,,,,,,,,,,,,,
,3873551118.71945,236.035369873047,26.2176666259766,1.42610544025919E-5,7.46865415983598E-9,1,5,13.1008939743042,4.99399986476332,30.0200004130602,0.0165427767438054,0.00244512815253443,1,1.74943571218898E-8,,,,,,,,,,,,,,,,,,,,,236.035369873047,236.035369873047,26.2176666259766,26.2176666259766,51.9052142623036,5.86698930270057,7.45509624481201,65,1,64,0,0,0.316925048828125,34.2131004333496,2,1,1,236.035369873047,0,2084574272,236.035369873047,,,,,,,,,,,,,,,,,,,,,,,,,,,,,,,,,
,3873551329.24331,271.025726318359,26.2176666259766,1.26786518817669E-5,5.93053852321854E-9,1,5,13.1008939743042,4.99140087711941,30.2099995315075,0.014694963460511,0.00218255664271329,1,2.44576576345892E-8,,,,,,,,,,,,,,,,,,,,,271.025726318359,271.025726318359,26.2176666259766,26.2176666259766,51.708634689717,5.86897439766787,7.76759576797485,66,1,0,0,1,0.30792236328125,33.2355842590332,2,1,1,271.025726318359,0,2084574208,271.025726318359,,,,,,,,,,,,,,,,,,,,,,,,,,,,,,,,,
,3873551774.20907,300.005920410156,46926.35546875,0.0104304787772518,4.4436745962155E-6,1,2,13.1008939743042,5.00555660055905,30.3700007498264,12.1543759036214,1.68596494470305,100,-8.01508913319607E-5,,,,,,,,,,,,,,,,,,,,,300.005920410156,300.005920410156,46926.35546875,46926.35546875,51.8055566261016,5.86358589676717,7.70672464370728,25,1,68,0,0,0.30914306640625,33.2355842590332,1,6,1,300.005920410156,0,2084573184,300.005920410156,,,,,,,,,,,,,,,,,,,,,,,,,,,,,,,,,
,3873551842.40887,300.003555297852,40115.27734375,0.00891668751102201,3.49355083387341E-6,1,2,13.1008939743042,5.00463689820798,30.3700007498264,10.3851605102611,1.45839348649808,100,-5.3492214347573E-5,,,,,,,,,,,,,,,,,,,,,300.003540039063,300.003570556641,40025.3515625,40205.203125,51.8524543372555,5.86659551011443,7.83125734329224,25,1,68,0,0,0.31005859375,33.7243423461914,1,6,1,300.003570556641,0,2084573184,300.003555297852,,,,,,,,,,,,,,,,,,,,,,,,,,,,,,,,,
,3873551911.86476,300.002227783203,33175.5625,0.00739705473514474,5.90292696397435E-6,1,2,13.1008939743042,5.00554260503238,30.3700007498264,8.61646229862595,1.21684171537592,100,-3.86283508793744E-5,,,,,,,,,,,,,,,,,,,,,300.002166748047,300.002288818359,33085.62890625,33265.49609375,51.8860643635824,5.86282733772178,8.0181303024292,25,1,68,0,0,0.301742553710937,32.7468223571777,1,6,1,300.002166748047,0,2084573184,300.002227783203,,,,,,,,,,,,,,,,,,,,,,,,,,,,,,,,,
,3873551989.3613,300.002136230469,25440.7451171875,0.00570328741966651,2.87149621636723E-6,1,2,13.1008939743042,5.00444819041222,30.3700007498264,6.64156202108178,0.937128641695477,100,-3.0466922444811E-5,,,,,,,,,,,,,,,,,,,,,300.002044677734,300.002227783203,25355.78125,25525.708984375,51.8782480783901,5.86720029506825,8.3120288848877,26,1,0,0,1,0.311126708984375,33.2355842590332,1,6,1,300.002227783203,0,2084573952,300.002136230469,,,,,,,,,,,,,,,,,,,,,,,,,,,,,,,,,
,3873552058.71047,300.001358032227,18516.0625,0.00417996112072474,4.99176047514647E-6,1,2,13.1008939743042,5.00447983432684,30.3700007498264,4.86824586707944,0.68289639780156,100,-2.57108874557347E-5,,,,,,,,,,,,,,,,,,,,,300.001190185547,300.001525878906,18426.037109375,18606.087890625,51.9544568590151,5.86661357926063,8.66357040405273,26,1,0,0,1,0.307083129882812,33.7243423461914,1,6,1,300.001525878906,0,2084574016,300.001358032227,,,,,,,,,,,,,,,,,,,,,,,,,,,,,,,,,
,3873552128.19013,300.000259399414,11574.8149414062,0.00265493461767515,3.65654765025634E-6,1,2,13.1008939743042,5.00469835275242,30.3700007498264,3.09362526504272,0.424681560498384,100,-2.41434537247246E-5,,,,,,,,,,,,,,,,,,,,,300.000213623047,300.000305175781,11484.8330078125,11664.796875,51.967744543842,5.86511080808093,9.06439399719238,23,1,68,0,0,0.313339233398438,33.2355842590332,1,6,1,300.000305175781,0,2084573664,300.000259399414,,,,,,,,,,,,,,,,,,,,,,,,,,,,,,,,,
,3873552197.6572,300.000839233398,4628.40673828125,0.00112338925449036,8.71257878805013E-6,1,2,13.1008939743042,5.0062467623595,30.3700007498264,1.31681087581759,0.130434321606462,100,-5.25973501084421E-5,,,,,,,,,,,,,,,,,,,,,300.000823974609,300.000854492188,4538.37548828125,4718.43798828125,51.8419023522459,5.86138468803972,9.50000190734863,25,1,68,0,0,0.309219360351562,33.2355842590332,1,6,1,300.000854492188,0,2084573632,300.000839233398,,,,,,,,,,,,,,,,,,,,,,,,,,,,,,,,,
,3873552267.19686,300.000595092773,-2319.88012695313,-0.000571281811582961,2.90524864997734E-6,1,2,13.1008939743042,5.00530403572083,30.3700007498264,-0.656975504635784,-0.151548014900634,100,-4.64859656577723E-5,,,,,,,,,,,,,,,,,,,,,300.000335693359,300.000854492188,-2399.98559570313,-2239.77465820313,51.8852827350632,5.86514072018972,9.81790065765381,24,1,68,0,0,0.31646728515625,33.2355842590332,1,6,1,300.000854492188,0,2084573280,300.000595092773,,,,,,,,,,,,,,,,,,,,,,,,,,,,,,,,,
,3873552346.61086,300.00065612793,-10260.16796875,-0.00234334680901272,2.45695840370897E-6,1,2,13.1008939743042,5.00482756883185,30.3700007498264,-2.72418123851181,-0.418996818216819,100,-1.66225828137911E-5,,,,,,,,,,,,,,,,,,,,,300.000549316406,300.000762939453,-10340.205078125,-10180.130859375,51.9536752304959,5.86663668777121,9.67448234558105,26,1,0,0,1,0.312957763671875,33.2355842590332,1,6,1,300.000762939453,0,2084573184,300.00065612793,,,,,,,,,,,,,,,,,,,,,,,,,,,,,,,,,
,3873552439.77511,300.001037597656,-19583.8662109375,-0.00439775600437797,2.69851369828634E-6,1,2,13.1008939743042,5.0055018570136,30.3700007498264,-5.11756554151388,-0.75826559160436,100,-6.95617382018158E-6,,,,,,,,,,,,,,,,,,,,,300.0009765625,300.001098632812,-19673.953125,-19493.779296875,51.8489370089189,5.86314751699585,9.49571323394775,26,1,0,0,1,0.313491821289063,33.2355842590332,1,6,1,300.0009765625,0,2084574304,300.001037597656,,,,,,,,,,,,,,,,,,,,,,,,,,,,,,,,,
,3873552509.23331,299.99967956543,-26536.8759765625,-0.00592577136261646,2.7965642782243E-6,1,2,13.1008939743042,5.00564160160986,30.3700007498264,-6.89601640897182,-1.02131705512232,100,-8.98617736020711E-6,,,,,,,,,,,,,,,,,,,,,299.99951171875,299.999847412109,-26627.111328125,-26446.640625,51.7062898041593,5.86258821750877,9.4002513885498,26,1,0,0,1,0.320892333984375,32.7468223571777,1,6,1,299.999847412109,0,2084574080,299.99967956543,,,,,,,,,,,,,,,,,,,,,,,,,,,,,,,,,
,3873552586.72345,299.999298095703,-34293.6015625,-0.00762942130013283,2.88071427446765E-6,1,2,13.1008939743042,5.00605366168014,30.3700007498264,-8.879676179782,-1.31479624280531,100,-1.13126491414559E-5,,,,,,,,,,,,,,,,,,,,,299.999084472656,299.99951171875,-34373.8203125,-34213.3828125,51.713715275092,5.85872033884514,9.32577228546143,26,1,0,0,1,0.309371948242188,34.2131004333496,1,6,1,299.999084472656,0,2084574048,299.999298095703,,,,,,,,,,,,,,,,,,,,,,,,,,,,,,,,,
,3873552682.02507,300.000122070313,-43848.357421875,-0.0096934097283025,2.93863076791937E-5,1,2,13.1008939743042,5.00654026700432,30.3700007498264,-11.2831701076392,-1.67248659966272,100,-1.58944143184149E-5,,,,,,,,,,,,,,,,,,,,,299.999877929687,300.000366210937,-43923.625,-43773.08984375,51.8446380520632,5.85765931904623,9.23215103149414,26,1,0,0,1,0.31005859375,34.7018585205078,1,6,1,299.999877929687,0,2084573888,300.000122070313,,,,,,,,,,,,,,,,,,,,,,,,,,,,,,,,,
,3873552767.2627,299.999877929687,-48159.99609375,-0.0107395423901471,6.68123576760607E-6,1,2,13.1008939743042,5.00675536506062,30.3700007498264,-12.5220514524035,-1.71370970650561,100,0.000102101584096538,,,,,,,,,,,,,,,,,,,,,299.999603271484,300.000152587891,-48244.890625,-48075.1015625,51.7176234176882,5.85727102033836,9.1697883605957,23,1,68,0,0,0.309982299804687,34.2131004333496,1,6,1,299.999603271484,0,2084574080,299.999877929687,,,,,,,,,,,,,,,,,,,,,,,,,,,,,,,,,
,3873552836.72529,299.999496459961,-41221.39453125,-0.00920222119400155,3.7176628683698E-6,1,2,13.1008939743042,5.0067980259411,30.3700007498264,-10.7270878150045,-1.48623587085255,100,7.21824549262894E-5,,,,,,,,,,,,,,,,,,,,,299.999298095703,299.999694824219,-41306.3828125,-41136.40625,51.7719465997747,5.85721750998538,9.12597751617432,25,1,68,0,0,0.31524658203125,34.2131004333496,1,6,1,299.999298095703,0,2084574016,299.999496459961,,,,,,,,,,,,,,,,,,,,,,,,,,,,,,,,,
,3873552906.24347,300,-34277.947265625,-0.00766855420140899,4.69576137709273E-6,1,2,13.1008939743042,5.00621503109692,30.3700007498264,-8.93630115451266,-1.24874588369641,100,5.12089108079054E-5,,,,,,,,,,,,,,,,,,,,,299.999816894531,300.000183105469,-34357.921875,-34197.97265625,51.8192351251882,5.86078627416044,9.09210109710693,24,1,68,0,0,0.310897827148438,35.190616607666,1,6,1,299.999816894531,0,2084573952,300,,,,,,,,,,,,,,,,,,,,,,,,,,,,,,,,,
,3873552975.61907,300.000564575195,-27353.20703125,-0.00614717411532295,3.45100423957401E-6,1,2,13.1008939743042,5.00657786540451,30.3600002080202,-7.16404314791727,-1.00174061991341,100,4.0504481323758E-5,,,,,,,,,,,,,,,,,,,,,300.000396728516,300.000732421875,-27448.103515625,-27258.310546875,51.7914873127555,5.85987456752141,9.05907440185547,24,1,68,0,0,0.30731201171875,33.2355842590332,1,6,1,300.000732421875,0,2084573920,300.000564575195,,,,,,,,,,,,,,,,,,,,,,,,,,,,,,,,,
,3873553060.95331,299.999771118164,-18832.3427734375,-0.00423984139303364,3.40206356861191E-5,1,2,13.1008939743042,5.00656613824814,30.3600002080202,-4.94705307744842,-0.650860444303035,100,6.23438792277261E-5,,,,,,,,,,,,,,,,,,,,,299.999389648438,300.000152587891,-18922.220703125,-18742.46484375,51.8360401383516,5.8594755464679,9.02853775024414,26,1,0,0,1,0.3106689453125,33.2355842590332,1,6,1,299.999389648438,0,2084574112,299.999771118164,,,,,,,,,,,,,,,,,,,,,,,,,,,,,,,,,
,3873553138.44873,300.000381469727,-11091.9946289062,-0.00254964931232661,1.32085245362126E-5,1,2,13.1008939743042,5.00670049574491,30.3700007498264,-2.97257693435129,-0.408261336771078,100,2.3020279189547E-5,,,,,,,,,,,,,,,,,,,,,300.000152587891,300.000610351562,-11172.013671875,-11011.9755859375,51.864178765044,5.85970516722063,8.99386501312256,25,1,68,0,0,0.308303833007812,34.2131004333496,1,6,1,300.000152587891,0,2084574016,300.000381469727,,,,,,,,,,,,,,,,,,,,,,,,,,,,,,,,,
,3873553207.79921,299.99919128418,-4166.34057617188,-0.00103053208620373,1.30960647453011E-5,1,2,13.1008939743042,5.00519247957356,30.3700007498264,-1.20957933999324,-0.106180812649171,100,5.97949508107241E-5,,,,,,,,,,,,,,,,,,,,,299.999053955078,299.999328613281,-4256.43359375,-4076.24755859375,51.7590497292074,5.86520879858314,8.96587753295898,25,1,68,0,0,0.311126708984375,33.2355842590332,1,6,1,299.999053955078,0,2084573664,299.99919128418,,,,,,,,,,,,,,,,,,,,,,,,,,,,,,,,,
,3873553295.13866,300.000701904297,4572.38037109375,0.00108075464213585,4.0715216659327E-6,1,2,13.1008939743042,5.00782384717395,30.3700007498264,1.25263504433998,0.226243838521487,100,3.58625672645812E-5,,,,,,,,,,,,,,,,,,,,,300.000396728516,300.001007080078,4482.73828125,4662.0224609375,51.8633971365247,5.85513602318621,8.9432258605957,26,1,0,0,1,0.307464599609375,33.7243423461914,1,6,1,300.001007080078,0,2084573184,300.000701904297,,,,,,,,,,,,,,,,,,,,,,,,,,,,,,,,,
,3873553364.69811,300.000534057617,11528.9921875,0.00262368109033787,3.58602464879042E-6,1,2,13.1008939743042,5.00690687155176,30.3700007498264,3.05178834550224,0.46979297150801,100,1.89538492659199E-5,,,,,,,,,,,,,,,,,,,,,300.000427246094,300.000640869141,11453.955078125,11604.029296875,51.8907541346978,5.8592529833848,8.92775154113769,26,1,0,0,1,0.316390991210937,33.2355842590332,1,6,1,300.000427246094,0,2084573664,300.000534057617,,,,,,,,,,,,,,,,,,,,,,,,,,,,,,,,,
,3873553465.82649,300.000152587891,21643.009765625,0.00486140637637948,2.49348712212822E-6,1,2,13.1008939743042,5.0065756753084,30.3700007498264,5.65769282528282,0.846026574813828,100,1.41882942117957E-5,,,,,,,,,,,,,,,,,,,,,300.000061035156,300.000244140625,21558.1015625,21727.91796875,51.8669144648613,5.85973725607138,8.90201187133789,26,1,0,0,1,0.30975341796875,33.7243423461914,1,6,1,300.000244140625,0,2084574016,300.000152587891,,,,,,,,,,,,,,,,,,,,,,,,,,,,,,,,,
,3873553535.33394,299.999862670898,28600.8701171875,0.00640023359330301,1.27847811129352E-5,1,2,13.1008939743042,5.00624075548632,30.3700007498264,7.44651100055664,1.12306075188424,100,2.67000888531746E-5,,,,,,,,,,,,,,,,,,,,,299.999755859375,299.999969482422,28515.59765625,28686.142578125,51.9435140597459,5.86157004134355,8.88416290283203,26,1,0,0,1,0.309906005859375,33.2355842590332,1,6,1,299.999969482422,0,2084573792,299.999862670898,,,,,,,,,,,,,,,,,,,,,,,,,,,,,,,,,
,3873553604.75945,300.000625610352,35561.814453125,0.00792663615771675,2.53964270103706E-6,1,2,13.1008939743042,5.00681154375213,30.3700007498264,9.22674050173599,1.37182531810187,100,1.6494234552926E-5,,,,,,,,,,,,,,,,,,,,,300.000518798828,300.000732421875,35481.6484375,35641.98046875,51.8399482809478,5.8588321649734,8.8718376159668,26,1,0,0,1,0.31890869140625,33.2355842590332,1,6,1,300.000732421875,0,2084573888,300.000625610352,,,,,,,,,,,,,,,,,,,,,,,,,,,,,,,,,
,3873553692.0841,300.001068115234,44317.322265625,0.00987250041628787,2.80615182135106E-5,1,2,13.1008939743042,5.00739951149922,30.3700007498264,11.4909694757076,1.7271358810559,100,3.62303241660081E-5,,,,,,,,,,,,,,,,,,,,,300.000823974609,300.001312255859,44232.44921875,44402.1953125,51.7359916878901,5.85661980704532,8.85950756072998,26,1,0,0,1,0.317001342773438,31.7693061828613,1,6,1,300.001312255859,0,2084573792,300.001068115234,,,,,,,,,,,,,,,,,,,,,,,,,,,,,,,,,
,3873553751.75423,299.999755859375,50000.2265625,0.0110888318391999,1.26381292753551E-6,1,2,13.1008939743042,5.00854408574262,30.3700007498264,12.9124955557384,1.92916289003922,100,3.09227204949101E-5,,,,,,,,,,,,,,,,,,,,,299.999664306641,299.999847412109,50000.203125,50000.25,51.8606614367074,5.85094073543771,8.85753154754639,26,1,0,0,1,0.306015014648438,33.2355842590332,1,4,1,299.999664306641,0,2084574080,299.999755859375,,,,,,,,,,,,,,,,,,,,,,,,,,,,,,,,,