File: LT data/Bridport/Wareham W1/426 Full sequence.dat
[Header]
; MPMS3 Data File (default extension .dat)
; Copyright (c) 2007, Quantum Design, Inc. All rights reserved.
TITLE,
FILEOPENTIME,3870081349.30405,08/19/2022,4:47 pm
BYAPP,MPMS3 w/ AC,1.0,1.1
INFO,MPMS3 Measurement Release 1.1.16 Build 424, MultiVu Release 2.3.4.19,APPNAME
INFO,Linear Motor Servo Controller,MOTOR_MODULE_NAME
INFO,3101-100 N0,MOTOR_HW_VERSION
INFO,MMC1047,MOTOR_SERIAL_NUMBER
INFO,01.04.28,MOTOR_SOFTWARE_VERSION
INFO,Quantum Design Squid Module,SQUID_MODULE_NAME
INFO,3101-501 B0,SQUID_HW_VERSION
INFO,SQM278,SQUID_SERIAL_NUMBER
INFO,01.03.04,SQUID_SOFTWARE_VERSION
INFO,Quantum Design VSM Oven,OVEN_MODULE_NAME
INFO,3101-201 A3,OVEN_HW_VERSION
INFO,OVB323,OVEN_SERIAL_NUMBER
INFO,01.07.07,OVEN_SOFTWARE_VERSION
INFO,SQUID AC,AC_MODULE_NAME
INFO,3101-401 G0,AC_HW_VERSION
INFO,SAC258,AC_SERIAL_NUMBER
INFO,SQUID AC 00.95.07,AC_SOFTWARE_VERSION
INFO,TCI127,COIL_SERIAL_NUMBER
INFO,0,MOMENT_UNITS
INFO,sandstone,SAMPLE_MATERIAL
INFO,,SAMPLE_COMMENT
INFO,,SAMPLE_MASS
INFO,,SAMPLE_VOLUME
INFO,,SAMPLE_MOLECULAR_WEIGHT
INFO,,SAMPLE_SIZE
INFO,,SAMPLE_SHAPE
INFO,Straw,SAMPLE_HOLDER
INFO,Standard,SAMPLE_HOLDER_DETAIL
INFO,65.3,SAMPLE_OFFSET
DATATYPE,COMMENT,1
DATATYPE,TIME,2
STARTUPAXIS,X,2
STARTUPAXIS,Y1,5
FIELDGROUP, VSM,2,3,4,5,6,8,9,10,11,14,15
FIELDGROUP, DC, 2,3,4,14,56,57,58,59,60,61,62,63,64,65,66,67,68,69
FIELDGROUP, AC, 2,3,4,11,16,17,18,19,20,21,22,23,24,25,26,27,28,29,30
STARTUPGROUP, All
[Data]
Comment,Time Stamp (sec),Temperature (K),Magnetic Field (Oe),Moment (emu),M. Std. Err. (emu),Transport Action,Averaging Time (sec),Frequency (Hz),Peak Amplitude (mm),Center Position (mm),Lockin Signal' (V),Lockin Signal (V),Range,M. Quad. Signal (emu),AC Moment (emu),AC M. Std Err. (emu),AC Phase (deg),AC Phase Std. Err. (deg),AC Susceptibility (emu/Oe),AC Suscept. Std Err. (emu/Oe),AC X' (emu/Oe),AC X' Std Err. (emu/Oe),AC X'' (emu/Oe),AC X'' Std Err. (emu/Oe),AC Drive (Oe),AC Frequency (Hz),AC Averaging Time (sec),AC Cycles,AC Range,AC Measure Type,AC Signal' (V),AC Signal'' (V),AC Trim Coil Ratio,AC Trim Coil Phase,Min. Temperature (K),Max. Temperature (K),Min. Field (Oe),Max. Field (Oe),Mass (grams),Motor Lag (deg),Pressure (Torr),Measure Count,Measurement Number,SQUID Status (code),Motor Status (code),Measure Status (code),Motor Current (amps),Motor Temp. (C),Temp. Status (code),Field Status (code),Chamber Status (code),Chamber Temp (K),Redirection State,Evercool Status,Average Temp (K),Rotation Angle (deg),Rotator state,DC Moment Fixed Ctr (emu),DC Moment Err Fixed Ctr (emu),DC Moment Free Ctr (emu),DC Moment Err Free Ctr (emu),DC Fixed Fit,DC Free Fit,DC Calculated Center (mm),DC Calculated Center Err (mm),DC Scan Length (mm),DC Scan Time (s),DC Number of Points,DC Squid Drift,DC Min V (V),DC Max V (V),DC Scans per Measure,Map 01,Map 02,Map 03,Map 04,Map 05,Map 06,Map 07,Map 08,Map 09,Map 10,Map 11,Map 12,Map 13,Map 14,Map 15,Map 16
"FC",3870081640.49671
,3870082493.34649,89.3394508361816,49999.609375,0.0798147735139382,1.86607044853279E-5,1,2,14.0008964538574,4.98034025889685,41.9999994337559,92.2074140769057,13.7984506964903,1000,-1.80392608279107E-5,,,,,,,,,,,,,,,,,,,,,89.2057266235352,89.4731750488281,49999.609375,49999.609375,52.5316895204671,6.10005261630922,7.62535381317139,28,1,0,0,1,0.337905883789063,33.2355842590332,2,1,1,89.2057266235352,0,2084573184,89.3394508361816,,,,,,,,,,,,,,,,,,,,,,,,,,,,,,,,,
,3870082619.57664,68.5600051879883,49999.609375,0.106333099451986,0.000214045210660609,1,2,14.0008964538574,4.98516535363781,41.9199988245964,122.941487439835,18.8656716579252,100,0.000371654525763099,,,,,,,,,,,,,,,,,,,,,68.4537811279297,68.6662292480469,49999.609375,49999.609375,52.6528419409479,6.12669208648473,7.4580717086792,26,1,64,0,0,0.34454345703125,33.7243423461914,2,1,1,68.4537811279297,0,2084573184,68.5600051879883,,,,,,,,,,,,,,,,,,,,,,,,,,,,,,,,,
,3870082719.32769,51.5112457275391,49999.609375,0.142801835728936,0.000261797994913203,1,2,14.0008964538574,4.98367557651283,41.9000014662743,165.101557964823,24.8958412683729,1000,0.000127665296174938,,,,,,,,,,,,,,,,,,,,,51.3556060791016,51.6668853759766,49999.609375,49999.609375,52.8670081552171,6.13488222188379,7.25427961349487,28,1,0,0,1,0.34088134765625,32.7468223571777,2,1,1,51.3556060791016,0,2084573184,51.5112457275391,,,,,,,,,,,,,,,,,,,,,,,,,,,,,,,,,
,3870082783.24481,40.6214828491211,49999.609375,0.179263989761259,6.97356525800462E-5,1,2,14.0008964538574,4.98162265558994,41.8800003826618,207.145335847095,31.184803346604,1000,0.000117221513734803,,,,,,,,,,,,,,,,,,,,,40.4603271484375,40.7826385498047,49999.609375,49999.609375,53.1073589248806,6.1342339858047,7.0501184463501,28,1,0,0,1,0.336761474609375,33.7243423461914,2,1,1,40.4603271484375,0,2084573184,40.6214828491211,,,,,,,,,,,,,,,,,,,,,,,,,,,,,,,,,
,3870082847.16949,29.806568145752,49999.609375,0.231260204649626,0.000102895151860321,1,2,14.0008964538574,4.97981053331438,41.8500006198883,267.095116244771,40.1908472502229,1000,0.000135027864936454,,,,,,,,,,,,,,,,,,,,,29.639741897583,29.9733943939209,49999.609375,49999.609375,53.178096305871,6.14118502512301,6.72963523864746,28,1,0,0,1,0.336456298828125,33.7243423461914,2,1,1,29.639741897583,0,2084573184,29.806568145752,,,,,,,,,,,,,,,,,,,,,,,,,,,,,,,,,
,3870082911.19742,19.1377468109131,49999.609375,0.304131262751604,0.000161530464990536,1,2,14.0008964538574,4.97996560853264,41.8299995362759,351.233718326435,53.1212114783412,1000,0.000405910749916696,,,,,,,,,,,,,,,,,,,,,19.0006370544434,19.2748565673828,49999.609375,49999.609375,52.9889422042171,6.14115169074489,6.16973638534546,28,1,0,0,1,0.33721923828125,33.7243423461914,2,1,1,19.0006370544434,0,2084573184,19.1377468109131,,,,,,,,,,,,,,,,,,,,,,,,,,,,,,,,,
,3870082975.23249,9.49584722518921,49999.609375,0.401200659762099,0.000156753684793339,1,2,14.0008964538574,4.98081084286638,41.8200008571148,463.458339106031,70.0174779485839,1000,0.000470479944259161,,,,,,,,,,,,,,,,,,,,,9.39954566955566,9.59214878082275,49999.609375,49999.609375,53.2261664598037,6.14107030072906,4.93702173233032,28,1,0,0,1,0.335617065429687,33.7243423461914,6,1,1,9.39954566955566,0,2084575008,9.49584722518921,,,,,,,,,,,,,,,,,,,,,,,,,,,,,,,,,
,3870083039.20168,2.00029301643372,49999.609375,0.481612569943005,4.62318198138511E-5,1,2,14.0008964538574,4.98071832337318,41.8200008571148,556.345090364998,83.9744124067555,1000,0.000500424586521191,,,,,,,,,,,,,,,,,,,,,1.99964570999146,2.00094032287598,49999.609375,49999.609375,53.8753089450249,6.14681490547481,2.57315993309021,28,1,0,0,1,0.335464477539063,33.2355842590332,5,1,1,2.00094032287598,0,2084574560,2.00029301643372,,,,,,,,,,,,,,,,,,,,,,,,,,,,,,,,,
,3870083436.16911,7.22961235046387,26.4154415130615,0.00144256501789597,6.2367407608823E-6,1,5,14.0008964538574,4.97935663975858,41.8200008571148,1.66595969947818,0.250170943469356,100,4.08285300447278E-7,,,,,,,,,,,,,,,,,,,,,7.00643014907837,7.45279455184937,26.4154415130615,26.4154415130615,53.0069196601595,6.14506014641594,4.31818532943726,70,1,0,0,1,0.336380004882812,32.7468223571777,6,1,1,7.45279455184937,0,2084574368,7.22961235046387,,,,,,,,,,,,,,,,,,,,,,,,,,,,,,,,,
,3870083642.29222,39.0499496459961,26.4154415130615,0.000181941202000398,7.70486226162665E-8,1,5,14.0008964538574,4.97762046065009,41.8299995362759,0.209999281099543,0.031633324389721,1,1.34960403595409E-7,,,,,,,,,,,,,,,,,,,,,39.0499496459961,39.0499496459961,26.4154415130615,26.4154415130615,53.0420929435248,6.14613115659006,6.37313079833984,69,1,64,0,0,0.332870483398438,34.7018585205078,2,1,1,39.0499496459961,0,2084574560,39.0499496459961,,,,,,,,,,,,,,,,,,,,,,,,,,,,,,,,,
,3870083845.26812,71.0663757324219,26.4154415130615,0.000128843985972811,4.55094828965095E-8,1,5,14.0008964538574,4.98793270510113,41.8599992990494,0.149165168163265,0.0223378671856506,1,-1.56633755527271E-8,,,,,,,,,,,,,,,,,,,,,71.0663757324219,71.0663757324219,26.4154415130615,26.4154415130615,52.929147622496,6.14812795859098,6.7880220413208,70,1,0,0,1,0.3350830078125,33.7243423461914,2,1,1,71.0663757324219,0,2084574464,71.0663757324219,,,,,,,,,,,,,,,,,,,,,,,,,,,,,,,,,
,3870084042.02775,103.031646728516,26.4154415130615,9.66895402345787E-5,2.32780246644871E-8,1,5,14.0008964538574,4.98663161538071,41.9300012290478,0.111897025916536,0.0167664266051209,1,-3.67540408708975E-9,,,,,,,,,,,,,,,,,,,,,103.031646728516,103.031646728516,26.4154415130615,26.4154415130615,52.8228461438806,6.15299156653499,6.99078130722046,70,1,0,0,1,0.339202880859375,34.2131004333496,2,1,1,103.031646728516,0,2084574304,103.031646728516,,,,,,,,,,,,,,,,,,,,,,,,,,,,,,,,,
,3870084235.78127,135.098159790039,26.4154415130615,7.01208585646884E-5,1.67162214438168E-8,1,5,14.0008964538574,4.98478396033147,42.0200005173683,0.0810984543733252,0.0122129047817598,1,4.91457767182001E-8,,,,,,,,,,,,,,,,,,,,,135.098159790039,135.098159790039,26.4154415130615,26.4154415130615,52.8064319449767,6.15715808853414,7.10729360580444,70,1,0,0,1,0.342330932617188,34.2131004333496,2,1,1,135.098159790039,0,2084574624,135.098159790039,,,,,,,,,,,,,,,,,,,,,,,,,,,,,,,,,
,3870084429.06942,167.055053710938,26.4154415130615,5.25449776707888E-5,1.69208202103793E-8,1,5,14.0008964538574,4.98315358744376,42.1199984848499,0.0607428488484087,0.00914960654245541,1,3.86246113095482E-8,,,,,,,,,,,,,,,,,,,,,167.055053710938,167.055053710938,26.4154415130615,26.4154415130615,52.7696954045729,6.16336998686789,7.19991636276245,68,1,64,0,0,0.335159301757812,33.2355842590332,2,1,1,167.055053710938,0,2084574560,167.055053710938,,,,,,,,,,,,,,,,,,,,,,,,,,,,,,,,,
,3870084621.52527,199.003814697266,26.4154415130615,3.92513681587847E-5,1.73398848151868E-8,1,5,14.0008964538574,4.98091966205249,42.2299988567829,0.0453295381932137,0.00694499143949106,1,1.2793803776195E-7,,,,,,,,,,,,,,,,,,,,,199.003814697266,199.003814697266,26.4154415130615,26.4154415130615,52.8388695285248,6.17455844923265,7.29874229431152,69,1,64,0,0,0.332489013671875,33.2355842590332,2,1,1,199.003814697266,0,2084574592,199.003814697266,,,,,,,,,,,,,,,,,,,,,,,,,,,,,,,,,
,3870084814.64531,231.041091918945,26.4154415130615,2.91124139290291E-5,1.29768371658645E-8,1,5,14.0008964538574,5.00054228951562,42.3900000751018,0.0337989266197236,0.0052282472770573,1,1.36855472283436E-7,,,,,,,,,,,,,,,,,,,,,231.041091918945,231.041091918945,26.4154415130615,26.4154415130615,52.7552352769671,6.18008794296386,7.53468418121338,69,1,64,0,0,0.344924926757812,33.7243423461914,2,1,1,231.041091918945,0,2084574560,231.041091918945,,,,,,,,,,,,,,,,,,,,,,,,,,,,,,,,,
,3870085007.1258,263.021545410156,26.4154415130615,2.14775400756317E-5,8.68065170489565E-9,1,5,14.0008964538574,5.00051921481288,42.5599999725819,0.0249257348257361,0.00391777809278593,1,1.53202165843815E-7,,,,,,,,,,,,,,,,,,,,,263.021545410156,263.021545410156,26.4154415130615,26.4154415130615,52.7114640798902,6.17881344784092,8.02404117584228,68,1,64,0,0,0.343017578125,33.7243423461914,2,1,1,263.021545410156,0,2084574496,263.021545410156,,,,,,,,,,,,,,,,,,,,,,,,,,,,,,,,,
,3870085200.1703,295.114807128906,26.4154415130615,1.58918682371238E-5,1.01854349663371E-8,1,5,14.0008964538574,5.00088372815393,42.7500009536743,0.0184352199755806,0.00296556937137694,1,1.70500633497929E-7,,,,,,,,,,,,,,,,,,,,,295.114807128906,295.114807128906,26.4154415130615,26.4154415130615,52.7001304663613,6.18023446817325,8.00628566741943,68,1,64,0,0,0.344085693359375,34.2131004333496,2,1,1,295.114807128906,0,2084574912,295.114807128906,,,,,,,,,,,,,,,,,,,,,,,,,,,,,,,,,
,3870086823.8618,2.00028491020203,43590.556640625,0.459835702556968,6.77969360313994E-5,1,2,14.0008964538574,4.97878363110422,41.8200008571148,530.861197761366,80.3903609257923,1000,0.000700072634737965,,,,,,,,,,,,,,,,,,,,,2.00006604194641,2.00050377845764,43500.60546875,43680.5078125,53.4661264152076,6.18803334667605,2.53285765647888,27,1,68,0,0,0.338516235351562,33.2355842590332,1,6,1,2.00050377845764,0,2084574304,2.00028491020203,,,,,,,,,,,,,,,,,,,,,,,,,,,,,,,,,
,3870086887.98174,2.00006955862045,37189.3359375,0.431691151483808,4.55105829502604E-5,1,2,14.0008964538574,4.9779265407305,41.8200008571148,498.285779821846,75.2071976444969,1000,0.000445355273760589,,,,,,,,,,,,,,,,,,,,,1.99997794628143,2.00016117095947,37099.37890625,37279.29296875,53.1941196905152,6.19124148440332,2.51737475395203,28,1,0,0,1,0.34454345703125,32.2580642700195,1,6,1,2.00016117095947,0,2084574144,2.00006955862045,,,,,,,,,,,,,,,,,,,,,,,,,,,,,,,,,
,3870086951.85575,1.99954980611801,30808.58203125,0.398369010651345,6.57669283672043E-5,1,2,14.0008964538574,4.99905280845743,41.8200008571148,462.52834909877,70.026614656423,1000,0.000593156933028941,,,,,,,,,,,,,,,,,,,,,1.99922394752502,1.999875664711,30719.15625,30898.0078125,53.0925079830152,6.18767211719418,2.51623249053955,28,1,0,0,1,0.34820556640625,32.2580642700195,1,6,1,1.999875664711,0,2084574112,1.99954980611801,,,,,,,,,,,,,,,,,,,,,,,,,,,,,,,,,
,3870087015.85628,1.99966651201248,24417.3857421875,0.35757533309759,8.00182004295886E-5,1,2,14.0008964538574,4.99914980385024,41.8200008571148,415.183587775515,62.8062955226883,1000,0.000488347839267836,,,,,,,,,,,,,,,,,,,,,1.99943995475769,1.99989306926727,24327.806640625,24506.96484375,52.9744820766114,6.18677100446843,2.50520372390747,28,1,0,0,1,0.336227416992188,34.7018585205078,1,6,1,1.99977588653564,0,2084574176,1.99966651201248,,,,,,,,,,,,,,,,,,,,,,,,,,,,,,,,,
,3870087079.85843,2.00001788139343,18026.677734375,0.306130223701461,9.79452008994349E-5,1,2,14.0008964538574,4.99950844849847,41.8200008571148,355.51324421188,53.5934767069301,1000,0.000261264861382137,,,,,,,,,,,,,,,,,,,,,1.99989819526672,2.00013756752014,17936.888671875,18116.466796875,52.8212828868421,6.18462835497854,2.50164818763733,28,1,0,0,1,0.345840454101562,33.2355842590332,1,6,1,1.99989819526672,0,2084574144,2.00001788139343,,,,,,,,,,,,,,,,,,,,,,,,,,,,,,,,,
,3870087143.88716,1.99995303153992,11634.9448242187,0.237677233128301,0.000133436943676965,1,2,14.0008964538574,4.99992117082169,41.8200008571148,276.038739156822,41.6877169272818,1000,0.000265974976177288,,,,,,,,,,,,,,,,,,,,,1.99990510940552,2.00000095367432,11544.9072265625,11724.982421875,52.7466373632556,6.18216812866863,2.4943265914917,28,1,0,0,1,0.340042114257812,34.7018585205078,1,6,1,1.99990510940552,0,2084574272,1.99995303153992,,,,,,,,,,,,,,,,,,,,,,,,,,,,,,,,,
,3870087207.93447,1.99988478422165,5233.71850585937,0.139939335918601,0.000189929743214974,1,2,14.0008964538574,4.99995647215729,41.8200008571148,162.538865224642,24.4685010168087,1000,9.0666930172444E-5,,,,,,,,,,,,,,,,,,,,,1.99982738494873,1.99994218349457,5158.72412109375,5308.712890625,52.5668628038325,6.18118378059884,2.48689484596252,28,1,0,0,1,0.341415405273438,33.7243423461914,1,6,1,1.99994218349457,0,2084574144,1.99988478422165,,,,,,,,,,,,,,,,,,,,,,,,,,,,,,,,,
,3870087271.88027,2.00031894445419,-1159.75158691406,-0.0257917369281267,0.000315762665108981,1,2,14.0008964538574,5.00054084605803,41.8200008571148,-29.9528474536707,-4.57069335191049,1000,-6.85703705714209E-5,,,,,,,,,,,,,,,,,,,,,1.99909293651581,2.00154495239258,-1249.7333984375,-1069.76977539062,52.6809805676402,6.17856473541939,2.48947691917419,28,1,0,0,1,0.339202880859375,35.190616607666,1,6,1,1.99909293651581,0,2084574048,2.00031894445419,,,,,,,,,,,,,,,,,,,,,,,,,,,,,,,,,
,3870087335.91929,2.00011432170868,-7559.30932617187,-0.171313811425755,0.000176566598550997,1,2,14.0008964538574,5.00041844163575,41.8099984526634,-198.997254323421,-30.015866515656,1000,-0.000160610211183423,,,,,,,,,,,,,,,,,,,,,2.00000786781311,2.00022077560425,-7649.3779296875,-7469.24072265625,52.6985672093229,6.17972158061568,2.48287177085876,28,1,0,0,1,0.339813232421875,32.7468223571777,1,6,1,2.00034475326538,0,2084573824,2.00011432170868,,,,,,,,,,,,,,,,,,,,,,,,,,,,,,,,,
,3870087399.82732,1.9998779296875,-13956.16015625,-0.26164957429133,0.000121382524049856,1,2,14.0008964538574,5.00067184763028,41.8200008571148,-303.940088857308,-45.9287719087471,1000,-0.0003158274945496,,,,,,,,,,,,,,,,,,,,,1.99986362457275,1.99989223480225,-14051.296875,-13861.0234375,52.7763392469864,6.17928218798028,2.47101950645447,28,1,0,0,1,0.345382690429687,33.2355842590332,1,6,1,1.99986362457275,0,2084574144,1.9998779296875,,,,,,,,,,,,,,,,,,,,,,,,,,,,,,,,,
,3870087463.81536,2.00003343820572,-20358.294921875,-0.324860375693042,8.69582301920562E-5,1,2,14.0008964538574,5.00041712854425,41.8200008571148,-377.342826574522,-57.0067827523319,1000,-0.000380368459812882,,,,,,,,,,,,,,,,,,,,,1.99997317790985,2.00009369850159,-20453.486328125,-20263.103515625,52.9408720502844,6.18135884910426,2.4693558216095,28,1,0,0,1,0.345230102539063,33.7243423461914,1,6,1,2.00009369850159,0,2084574112,2.00003343820572,,,,,,,,,,,,,,,,,,,,,,,,,,,,,,,,,
,3870087527.87425,1.99991279840469,-26767.068359375,-0.372648135211118,7.34859088936254E-5,1,2,14.0008964538574,5.00063938585577,41.8200008571148,-432.88539076302,-65.3460669407014,1000,-0.000392751880619972,,,,,,,,,,,,,,,,,,,,,1.99973213672638,2.00009346008301,-26857.359375,-26676.77734375,53.0120002455345,6.18132827525807,2.46540641784668,28,1,0,0,1,0.3448486328125,34.2131004333496,1,6,1,1.99973213672638,0,2084574144,1.99991279840469,,,,,,,,,,,,,,,,,,,,,,,,,,,,,,,,,
,3870087591.78883,1.99998295307159,-33170.748046875,-0.410849864685242,7.14426805795026E-5,1,2,14.0008964538574,5.00030620785684,41.8200008571148,-477.179377173723,-72.2946254764782,1000,-0.000653699493624702,,,,,,,,,,,,,,,,,,,,,1.99978804588318,2.00017786026001,-33261.03515625,-33080.4609375,53.1796595629095,6.18342552220249,2.46886825561523,28,1,0,0,1,0.34027099609375,33.7243423461914,1,6,1,1.99978804588318,0,2084574272,1.99998295307159,,,,,,,,,,,,,,,,,,,,,,,,,,,,,,,,,
,3870087655.861,1.99998873472214,-39588.521484375,-0.442456003390646,0.00012504153159164,1,2,14.0008964538574,5.00050541169082,41.8200008571148,-513.910951986382,-77.8995420568146,1000,-0.000737596563893865,,,,,,,,,,,,,,,,,,,,,1.99998593330383,1.99999153614044,-39673.76953125,-39503.2734375,53.284788598746,6.18257990422859,2.46704173088074,28,1,0,0,1,0.345611572265625,33.7243423461914,1,6,1,1.99999153614044,0,2084574240,1.99998873472214,,,,,,,,,,,,,,,,,,,,,,,,,,,,,,,,,
,3870087719.84369,1.9998574256897,-46002.115234375,-0.469347183844025,0.000132956878665549,1,2,14.0008964538574,5.0003099253431,41.8200008571148,-545.096934394967,-82.7509660115893,1000,-0.000886958208441562,,,,,,,,,,,,,,,,,,,,,1.99962759017944,2.00008726119995,-46087.33203125,-45916.8984375,53.5200587830345,6.18442732400124,2.45899367332458,28,1,0,0,1,0.343093872070313,34.2131004333496,1,6,1,2.00008726119995,0,2084574144,1.9998574256897,,,,,,,,,,,,,,,,,,,,,,,,,,,,,,,,,
,3870087785.78464,2.00000339746475,-47955.470703125,-0.477045464762247,4.33376993327954E-5,1,2,14.0008964538574,5.00055516307688,41.8200008571148,-554.114268666775,-83.856637843476,1000,-0.000679962488571903,,,,,,,,,,,,,,,,,,,,,1.99987590312958,2.00013089179993,-48045,-47865.94140625,53.4528387303807,6.1828705523407,2.45509934425354,27,1,68,0,0,0.347061157226562,33.2355842590332,1,6,1,2.00013089179993,0,2084574368,2.00000339746475,,,,,,,,,,,,,,,,,,,,,,,,,,,,,,,,,
,3870087849.79147,1.99990946054459,-41565.630859375,-0.451571112435544,6.53109998307513E-5,1,2,14.0008964538574,5.00042977241319,41.8200008571148,-524.516933771862,-79.3030587114287,1000,-0.000580965028334129,,,,,,,,,,,,,,,,,,,,,1.99983954429626,1.99997937679291,-41655.0625,-41476.19921875,53.3910900773614,6.18330510284532,2.45903849601746,27,1,68,0,0,0.34454345703125,33.2355842590332,1,6,1,1.99983954429626,0,2084574272,1.99990946054459,,,,,,,,,,,,,,,,,,,,,,,,,,,,,,,,,
,3870087913.88085,2.00016689300537,-35166.326171875,-0.421843281851357,5.91559320859858E-5,1,2,14.0008964538574,5.00049828982608,41.8200008571148,-489.986322636112,-74.1505580805955,1000,-0.000600180692822248,,,,,,,,,,,,,,,,,,,,,1.99998188018799,2.00035190582275,-35246.26953125,-35086.3828125,53.1960737618133,6.18268903815838,2.44999384880066,28,1,0,0,1,0.345077514648438,34.2131004333496,1,6,1,2.00035190582275,0,2084574336,2.00016689300537,,,,,,,,,,,,,,,,,,,,,,,,,,,,,,,,,
,3870087977.83394,1.99994432926178,-28781.384765625,-0.38638252726824,7.37563345858634E-5,1,2,14.0008964538574,5.00044121750816,41.8200008571148,-448.788483302721,-67.9277148151274,1000,-0.000559579342036121,,,,,,,,,,,,,,,,,,,,,1.9997456073761,2.00014305114746,-28866.3046875,-28696.46484375,53.0991518254287,6.18177616143586,2.44802069664001,28,1,0,0,1,0.340194702148438,33.7243423461914,1,6,1,1.9997456073761,0,2084574272,1.99994432926178,,,,,,,,,,,,,,,,,,,,,,,,,,,,,,,,,
,3870088041.78187,1.99992561340332,-22396.7958984375,-0.342625767673848,8.93743843689653E-5,1,2,14.0008964538574,5.00065421537092,41.8200008571148,-397.990439464442,-60.2233353164515,1000,-0.000483003078056715,,,,,,,,,,,,,,,,,,,,,1.99991202354431,1.99993920326233,-22486.708984375,-22306.8828125,52.9733096338325,6.18046152347061,2.45228743553162,28,1,0,0,1,0.345993041992188,32.7468223571777,1,6,1,1.99991202354431,0,2084574400,1.99992561340332,,,,,,,,,,,,,,,,,,,,,,,,,,,,,,,,,
,3870088105.76509,2.00017559528351,-16006.8540039062,-0.286772959892061,0.00010934813438871,1,2,14.0008964538574,5.00055168569346,41.8200008571148,-333.114113373904,-50.3295355460911,1000,-0.000339621498901391,,,,,,,,,,,,,,,,,,,,,2.00009226799011,2.0002589225769,-16096.7802734375,-15916.927734375,52.859973498544,6.18077764699159,2.4447615146637,28,1,0,0,1,0.345230102539063,34.2131004333496,1,6,1,2.00009226799011,0,2084574176,2.00017559528351,,,,,,,,,,,,,,,,,,,,,,,,,,,,,,,,,
,3870088169.76036,2.00029385089874,-9613.03857421875,-0.210787344951484,0.000141918935761367,1,2,14.0008964538574,5.0000045567881,41.8200008571148,-244.817179783338,-36.9542508280588,1000,-0.000220438895971598,,,,,,,,,,,,,,,,,,,,,2.00021052360535,2.00037717819214,-9703.044921875,-9523.0322265625,52.7399935208421,6.1825159936201,2.4430570602417,28,1,0,0,1,0.340728759765625,32.2580642700195,1,6,1,2.00037717819214,0,2084574016,2.00029385089874,,,,,,,,,,,,,,,,,,,,,,,,,,,,,,,,,
,3870088233.81193,2.00000888109207,-3211.84924316406,-0.0996410203205975,0.0010096705904533,1,2,14.0008964538574,4.99960936892871,41.8200008571148,-115.856301159184,-16.5200228848006,1000,0.000710817203623487,,,,,,,,,,,,,,,,,,,,,1.99997818470001,2.00003957748413,-3296.96069335937,-3126.73779296875,52.7986156597844,6.18404062849682,2.44902062416077,28,1,0,0,1,0.339736938476562,32.2580642700195,1,6,1,1.99997818470001,0,2084574144,2.00000888109207,,,,,,,,,,,,,,,,,,,,,,,,,,,,,,,,,
,3870088297.74895,2.00010132789612,3181.818359375,0.0813926259010381,0.000249266504195163,1,2,14.0008964538574,4.99979602527272,41.8200008571148,94.5213310124341,14.3081024439116,1000,0.000119178031419378,,,,,,,,,,,,,,,,,,,,,2.0000536441803,2.00014901161194,3091.71899414063,3271.91772460937,52.7442924776979,6.18237500067391,2.44041347503662,28,1,0,0,1,0.346755981445313,34.2131004333496,1,6,1,2.0000536441803,0,2084573696,2.00010132789612,,,,,,,,,,,,,,,,,,,,,,,,,,,,,,,,,
,3870088361.7895,1.99995511770248,9582.7109375,0.204018076437887,0.000156976678720404,1,2,14.0008964538574,5.00013597327282,41.8200008571148,236.959537924734,35.7971465078887,1000,0.000237752809004183,,,,,,,,,,,,,,,,,,,,,1.99979269504547,2.0001175403595,9492.6123046875,9672.8095703125,52.7294415358325,6.18190700746897,2.4466118812561,28,1,0,0,1,0.339126586914063,34.7018585205078,1,6,1,2.0001175403595,0,2084574048,1.99995511770248,,,,,,,,,,,,,,,,,,,,,,,,,,,,,,,,,
,3870088425.74473,1.99986290931702,15985.37109375,0.2839427349433,0.000111772557678321,1,2,14.0008964538574,5.0001195555977,41.8200008571148,329.792743242506,49.7861806733781,1000,0.000301305916548308,,,,,,,,,,,,,,,,,,,,,1.99981284141541,1.99991297721863,15895.259765625,16075.482421875,53.0280236301787,6.18270712735081,2.44072675704956,28,1,0,0,1,0.342483520507812,33.7243423461914,1,6,1,1.99981284141541,0,2084574048,1.99986290931702,,,,,,,,,,,,,,,,,,,,,,,,,,,,,,,,,
,3870088489.73085,2.00016736984253,22388.1669921875,0.341344834657784,8.37263255557544E-5,1,2,14.0008964538574,5.00020362478549,41.8200008571148,396.474296612612,59.8453972482014,1000,0.000356186198347136,,,,,,,,,,,,,,,,,,,,,2.0001163482666,2.00021839141846,22298.0546875,22478.279296875,53.0479551574191,6.18292428112379,2.44291806221008,28,1,0,0,1,0.340957641601562,34.2131004333496,1,6,1,2.0001163482666,0,2084574464,2.00016736984253,,,,,,,,,,,,,,,,,,,,,,,,,,,,,,,,,
,3870088553.77403,2.00021159648895,28795.828125,0.385515479697705,7.70212662212888E-5,1,2,14.0008964538574,5.00013533753502,41.8200008571148,447.744072658768,67.7627864414077,1000,0.000552559001109367,,,,,,,,,,,,,,,,,,,,,2.00005555152893,2.00036764144897,28705.611328125,28886.044921875,53.1495668649191,6.18381833389427,2.44528555870056,28,1,0,0,1,0.346450805664063,33.7243423461914,1,6,1,2.00005555152893,0,2084574112,2.00021159648895,,,,,,,,,,,,,,,,,,,,,,,,,,,,,,,,,
,3870088617.79586,2.00000071525574,35215.533203125,0.421570634995956,5.87985549327735E-5,1,2,14.0008964538574,5.0002900552918,41.8200008571148,489.660943956018,73.9659217456948,1000,0.000485829231224022,,,,,,,,,,,,,,,,,,,,,1.99996185302734,2.00003957748413,35130.66796875,35300.3984375,53.2511785724191,6.18425345902681,2.44496393203735,28,1,0,0,1,0.339736938476562,33.7243423461914,1,6,1,1.99996185302734,0,2084574368,2.00000071525574,,,,,,,,,,,,,,,,,,,,,,,,,,,,,,,,,
,3870088681.77273,2.00008201599121,41629.95703125,0.451533283088305,7.21689700956873E-5,1,2,14.0008964538574,5.00024900854249,41.8200008571148,524.428206131449,79.4142265122584,1000,0.000685781567034264,,,,,,,,,,,,,,,,,,,,,2.00003981590271,2.00012421607971,41545.16015625,41714.75390625,53.4782416572557,6.18508621026234,2.44492864608765,28,1,0,0,1,0.341796875,33.7243423461914,1,6,1,2.00003981590271,0,2084574048,2.00008201599121,,,,,,,,,,,,,,,,,,,,,,,,,,,,,,,,,
,3870088745.75351,2.00004994869232,48040.138671875,0.477282902530935,6.54921466548782E-5,1,2,14.0008964538574,5.00031920297613,41.8200008571148,554.362759088032,83.8308037334655,1000,0.000626904241083015,,,,,,,,,,,,,,,,,,,,,2.00003385543823,2.00006604194641,47949.921875,48130.35546875,53.6158082766403,6.18561113947272,2.44425988197327,28,1,0,0,1,0.337905883789063,34.2131004333496,1,6,1,2.00006604194641,0,2084574240,2.00004994869232,,,,,,,,,,,,,,,,,,,,,,,,,,,,,,,,,
,3870089214.26556,22.1739664077759,26.2671089172363,0.000228394016798744,1.09030613264833E-6,1,5,14.0008964538574,4.9903464889521,41.8200008571148,0.264751132219026,0.0385851955694851,1,-9.24329797884778E-7,,,,,,,,,,,,,,,,,,,,,21.6277275085449,22.7202053070068,26.2671089172363,26.2671089172363,52.6063350440536,6.18334790663993,5.74232959747314,70,1,0,0,1,0.33477783203125,34.7018585205078,2,1,1,22.7202053070068,0,2084574464,22.1739664077759,,,,,,,,,,,,,,,,,,,,,,,,,,,,,,,,,
,3870089412.47227,53.0323715209961,26.2671089172363,0.000144059220941212,2.83570689865582E-7,1,5,14.0008964538574,4.99094193900442,41.8500006198883,0.166907935986917,0.0250849103951215,1,5.84719492241915E-8,,,,,,,,,,,,,,,,,,,,,53.0140037536621,53.0507392883301,26.2671089172363,26.2671089172363,52.6454164700152,6.18042415688733,6.50606870651245,70,1,0,0,1,0.3369140625,34.2131004333496,2,1,1,53.0507392883301,0,2084574688,53.0323715209961,,,,,,,,,,,,,,,,,,,,,,,,,,,,,,,,,
,3870089613.3325,85.035572052002,26.2671089172363,0.000107188872183599,2.99966635514673E-8,1,5,14.0008964538574,4.99135724724008,41.9000014662743,0.124207738435111,0.0186432075224429,1,2.30755602610806E-8,,,,,,,,,,,,,,,,,,,,,85.0179901123047,85.0531539916992,26.2671089172363,26.2671089172363,52.6172778433229,6.18118176954447,6.78484582901001,70,1,0,0,1,0.33721923828125,32.2580642700195,2,1,1,85.0531539916992,0,2084574560,85.035572052002,,,,,,,,,,,,,,,,,,,,,,,,,,,,,,,,,
,3870089807.57602,117.007911682129,26.2671089172363,8.09262637830023E-5,2.30466003054577E-8,1,5,14.0008964538574,4.99198229949778,41.9699996709824,0.0937949117413555,0.0140567296794112,1,-8.08216197914002E-10,,,,,,,,,,,,,,,,,,,,,117.007911682129,117.007911682129,26.2671089172363,26.2671089172363,52.7016937233998,6.17595477680166,6.93294954299927,70,1,0,0,1,0.34027099609375,33.7243423461914,2,1,1,117.007911682129,0,2084574496,117.007911682129,,,,,,,,,,,,,,,,,,,,,,,,,,,,,,,,,
,3870090001.04374,149.027969360352,26.2671089172363,5.97032391246957E-5,7.23485659873212E-8,1,5,14.0008964538574,4.99201857178322,42.0599989593029,0.0691882070585842,0.0104342476438721,1,5.44578766704479E-8,,,,,,,,,,,,,,,,,,,,,149.027969360352,149.027969360352,26.2671089172363,26.2671089172363,52.6301747138902,6.17410414419031,7.02332448959351,70,1,0,0,1,0.336990356445313,33.7243423461914,2,1,1,149.027969360352,0,2084574496,149.027969360352,,,,,,,,,,,,,,,,,,,,,,,,,,,,,,,,,
,3870090193.92678,181.030410766602,26.2671089172363,4.45842396440363E-5,1.39251676280407E-8,1,5,14.0008964538574,4.99214175225592,42.1699993312359,0.0516732413964694,0.00776428948580675,1,1.65943245283568E-8,,,,,,,,,,,,,,,,,,,,,181.030410766602,181.030410766602,26.2671089172363,26.2671089172363,52.6579225263229,6.17633405023156,7.12100410461426,69,1,64,0,0,0.34027099609375,34.2131004333496,2,1,1,181.030410766602,0,2084574560,181.030410766602,,,,,,,,,,,,,,,,,,,,,,,,,,,,,,,,,
,3870090386.54965,213.01985168457,26.2671089172363,3.34012217305733E-5,1.34457285093903E-8,1,5,14.0008964538574,4.9905772547956,42.3000007867813,0.0386811387070218,0.00590740369876956,1,9.28561643860932E-8,,,,,,,,,,,,,,,,,,,,,213.01985168457,213.01985168457,26.2671089172363,26.2671089172363,52.6477613555729,6.17918568613936,7.27729892730713,68,1,64,0,0,0.335693359375,34.2131004333496,2,1,1,213.01985168457,0,2084574400,213.01985168457,,,,,,,,,,,,,,,,,,,,,,,,,,,,,,,,,
,3870090579.79081,245.012252807617,26.2671089172363,2.46693524995209E-5,1.08812456636693E-8,1,5,14.0008964538574,4.99044041033583,42.45999827981,0.0285566434870609,0.00443785197029432,1,1.33277097878664E-7,,,,,,,,,,,,,,,,,,,,,245.012252807617,245.012252807617,26.2671089172363,26.2671089172363,52.6860611530152,6.18145794120126,7.67730808258057,70,1,0,0,1,0.335540771484375,33.7243423461914,2,1,1,245.012252807617,0,2084574528,245.012252807617,,,,,,,,,,,,,,,,,,,,,,,,,,,,,,,,,
,3870090772.19627,277.030212402344,26.2671089172363,1.85697625706606E-5,1.02771320279264E-8,1,5,14.0008964538574,4.99152069470986,42.62999817729,0.0214941181556756,0.00339701328663412,1,1.48149791997559E-7,,,,,,,,,,,,,,,,,,,,,277.030212402344,277.030212402344,26.2671089172363,26.2671089172363,52.631347156669,6.17557639433842,8.37098598480225,68,1,64,0,0,0.3399658203125,34.2131004333496,2,1,1,277.030212402344,0,2084574528,277.030212402344,,,,,,,,,,,,,,,,,,,,,,,,,,,,,,,,,
,3870091568.7723,293.979583740234,26.4772434234619,1.92243888260971E-5,7.4109880103403E-9,1,5,14.0008964538574,5.01204682298481,42.7200011909008,0.0224005350990467,0.0033997103505371,1,3.55690708100074E-8,,,,,,,,,,,,,,,,,,,,,293.979583740234,293.979583740234,26.4772434234619,26.4772434234619,52.6606582261402,6.17808963843221,8.72645092010498,69,1,64,0,0,0.346298217773438,31.7693061828613,2,1,1,293.979583740234,0,2084573184,293.979583740234,,,,,,,,,,,,,,,,,,,,,,,,,,,,,,,,,
,3870091742.01263,261.962280273438,26.4772434234619,2.27133301361061E-5,9.73361646956415E-8,1,5,14.0008964538574,5.01115357867077,42.5599999725819,0.0264677353676095,0.00395948329317593,1,-6.22612473176815E-9,,,,,,,,,,,,,,,,,,,,,261.962280273438,261.962280273438,26.4772434234619,26.4772434234619,52.7282690930537,6.17654991412755,9.09186458587646,70,1,0,0,1,0.338516235351562,33.7243423461914,2,1,1,261.962280273438,0,2084574528,261.962280273438,,,,,,,,,,,,,,,,,,,,,,,,,,,,,,,,,
,3870091934.89346,229.959075927734,26.4772434234619,2.64480017487082E-5,1.58424573085082E-7,1,5,14.0008964538574,5.01094297295748,42.4299985170364,0.03080577504767,0.00469129066636411,1,6.22969607038217E-8,,,,,,,,,,,,,,,,,,,,,229.959075927734,229.959075927734,26.4772434234619,26.4772434234619,52.6880152243133,6.17963481595073,8.69201850891113,70,1,0,0,1,0.342788696289063,33.7243423461914,2,1,1,229.959075927734,0,2084574560,229.959075927734,,,,,,,,,,,,,,,,,,,,,,,,,,,,,,,,,
,3870092124.18552,197.953826904297,26.4772434234619,3.03438205584392E-5,7.76910958795832E-9,1,5,14.0008964538574,5.01078058298739,42.3099994659424,0.0353533232231304,0.00530584685700811,1,6.04513111687725E-9,,,,,,,,,,,,,,,,,,,,,197.953826904297,197.953826904297,26.4772434234619,26.4772434234619,52.6985672093229,6.18006140695871,8.41629791259766,70,1,0,0,1,0.343017578125,36.1681327819824,2,1,1,197.953826904297,0,2084574304,197.953826904297,,,,,,,,,,,,,,,,,,,,,,,,,,,,,,,,,
,3870092317.18354,165.972412109375,26.4772434234619,3.46573223164103E-5,6.31660263561453E-9,1,5,14.0008964538574,5.01026115248846,42.2100014984608,0.0403751024025111,0.00604583636610819,1,-4.58176817592418E-9,,,,,,,,,,,,,,,,,,,,,165.972412109375,165.972412109375,26.4772434234619,26.4772434234619,52.8705254835537,6.1824419379964,8.17716693878174,70,1,0,0,1,0.337142944335937,32.7468223571777,2,1,1,165.972412109375,0,2084574368,165.972412109375,,,,,,,,,,,,,,,,,,,,,,,,,,,,,,,,,
,3870092509.65558,133.975776672363,26.4772434234619,3.95505183727165E-5,6.97372663445692E-9,1,5,14.0008964538574,5.00998070329291,42.1199984848499,0.0460707712000102,0.00690693045324048,1,1.66883166493499E-9,,,,,,,,,,,,,,,,,,,,,133.963088989258,133.988464355469,26.4772434234619,26.4772434234619,52.8494215135344,6.18301288968484,7.98427248001099,69,1,64,0,0,0.34332275390625,33.2355842590332,2,1,1,133.963088989258,0,2084574240,133.975776672363,,,,,,,,,,,,,,,,,,,,,,,,,,,,,,,,,
,3870092701.86037,101.996208190918,26.4772434234619,4.46310782954675E-5,7.47703913666761E-9,1,5,14.0008964538574,5.01011080308595,42.0200005173683,0.051991126518934,0.0077922371141184,1,-2.51950695072283E-11,,,,,,,,,,,,,,,,,,,,,101.996208190918,101.996208190918,26.4772434234619,26.4772434234619,52.7626607478998,6.18292438311739,7.7761287689209,70,1,0,0,1,0.337677001953125,35.6793746948242,2,1,1,101.996208190918,0,2084574464,101.996208190918,,,,,,,,,,,,,,,,,,,,,,,,,,,,,,,,,
,3870092891.42259,69.9634246826172,26.4772434234619,5.11716997099934E-5,1.32703304124878E-8,1,5,14.0008964538574,5.00977334573369,41.9399999082088,0.0596033594766742,0.00894255382662144,1,7.88359924569327E-9,,,,,,,,,,,,,,,,,,,,,69.9411163330078,69.9857330322266,26.4772434234619,26.4772434234619,52.6864519672748,6.18421123962976,7.53187417984009,69,1,64,0,0,0.337448120117188,33.7243423461914,2,1,1,69.9411163330078,0,2084574464,69.9634246826172,,,,,,,,,,,,,,,,,,,,,,,,,,,,,,,,,
,3870093077.66005,37.9748306274414,26.4772434234619,6.10313340069845E-5,8.99861932010505E-8,1,5,14.0008964538574,5.00989069546066,41.8800003826618,0.0711084767881621,0.0105420661540828,1,-9.69347202373539E-8,,,,,,,,,,,,,,,,,,,,,37.9748306274414,37.9748306274414,26.4772434234619,26.4772434234619,52.6360369277844,6.18313126369084,7.12359619140625,70,1,0,0,1,0.349044799804687,32.7468223571777,2,1,1,37.9748306274414,0,2084574368,37.9748306274414,,,,,,,,,,,,,,,,,,,,,,,,,,,,,,,,,
,3870093360.59971,5.95373487472534,26.4772434234619,0.000118820493163057,1.61044004754636E-8,1,5,14.0008964538574,5.0098946593013,41.8200008571148,0.138389688129684,0.0208571638266779,1,9.71877657709101E-8,,,,,,,,,,,,,,,,,,,,,5.95373487472534,5.95373487472534,26.4772434234619,26.4772434234619,52.7079467515537,6.18304338781844,4.32456827163696,70,1,0,0,1,0.341415405273438,32.7468223571777,6,1,1,5.95373487472534,0,2084575680,5.95373487472534,,,,,,,,,,,,,,,,,,,,,,,,,,,,,,,,,
,3870093665.98522,28.0295505523682,26.4772434234619,7.03661735580192E-5,4.52640749968446E-8,1,5,14.0008964538574,5.0096043174376,41.8299995362759,0.0819453462253036,0.0123719321652425,1,7.57577287007193E-8,,,,,,,,,,,,,,,,,,,,,28.0093116760254,28.0497894287109,26.4772434234619,26.4772434234619,52.7579709767844,6.18353204780986,6.08993482589722,70,1,0,0,1,0.341262817382812,34.2131004333496,2,1,1,28.0497894287109,0,2084574592,28.0295505523682,,,,,,,,,,,,,,,,,,,,,,,,,,,,,,,,,
,3870093870.49748,60.0414924621582,26.4772434234619,5.3994904825039E-5,1.10881473436338E-8,1,5,14.0008964538574,5.01001439423762,41.8599992990494,0.0628944937434321,0.00944647091258975,1,1.68266481615978E-8,,,,,,,,,,,,,,,,,,,,,60.0414924621582,60.0414924621582,26.4772434234619,26.4772434234619,52.8017421738614,6.18160740828983,6.7180814743042,70,1,0,0,1,0.34423828125,34.2131004333496,2,1,1,60.0414924621582,0,2084574720,60.0414924621582,,,,,,,,,,,,,,,,,,,,,,,,,,,,,,,,,
,3870094069.5052,92.0121459960937,26.4772434234619,4.66604776829386E-5,2.48761694457422E-8,1,5,14.0008964538574,5.01012818172713,41.9100001454353,0.0543553752294716,0.00814712490504532,1,4.29520123757524E-10,,,,,,,,,,,,,,,,,,,,,92.0121459960937,92.0121459960937,26.4772434234619,26.4772434234619,52.8916294535729,6.18141710253513,6.93628168106079,70,1,0,0,1,0.345077514648438,34.2131004333496,2,1,1,92.0121459960937,0,2084574336,92.0121459960937,,,,,,,,,,,,,,,,,,,,,,,,,,,,,,,,,
,3870094263.12424,124.045135498047,26.4772434234619,4.07555200396514E-5,8.46729799978335E-9,1,5,14.0008964538574,5.00981400677938,41.9799983501434,0.047474044625549,0.00710486310863749,1,-8.7305906288681E-9,,,,,,,,,,,,,,,,,,,,,124.045135498047,124.045135498047,26.4772434234619,26.4772434234619,52.7603158623421,6.18293418706106,7.05989074707031,68,1,64,0,0,0.336532592773438,34.2131004333496,2,1,1,124.045135498047,0,2084574624,124.045135498047,,,,,,,,,,,,,,,,,,,,,,,,,,,,,,,,,
,3870094456.11583,156.025192260742,26.4772434234619,3.55473874445096E-5,7.20676896979599E-9,1,5,14.0008964538574,5.00991769505635,42.0800000429153,0.0414104223632896,0.00618463628040615,1,-1.83273252404941E-8,,,,,,,,,,,,,,,,,,,,,156.025192260742,156.025192260742,26.4772434234619,26.4772434234619,52.6778540535633,6.18390551411064,7.15424585342407,70,1,0,0,1,0.348434448242188,34.2131004333496,2,1,1,156.025192260742,0,2084574496,156.025192260742,,,,,,,,,,,,,,,,,,,,,,,,,,,,,,,,,
,3870094649.62083,188.002227783203,26.4772434234619,3.03967193705753E-5,7.37749066601274E-9,1,5,14.0008964538574,5.00985546020987,42.1999990940094,0.0354073924334869,0.00530321361202222,1,-2.9684633610661E-9,,,,,,,,,,,,,,,,,,,,,188.002227783203,188.002227783203,26.4772434234619,26.4772434234619,52.8662265266979,6.18376596314087,7.22742605209351,69,1,64,0,0,0.335769653320313,33.7243423461914,2,1,1,188.002227783203,0,2084574560,188.002227783203,,,,,,,,,,,,,,,,,,,,,,,,,,,,,,,,,
,3870094842.567,220.025939941406,26.4772434234619,2.59360224411567E-5,8.16405694784344E-9,1,5,14.0008964538574,5.0093564640202,42.3300005495548,0.0301972267037362,0.00459072962708266,1,5.44697164589827E-8,,,,,,,,,,,,,,,,,,,,,220.025939941406,220.025939941406,26.4772434234619,26.4772434234619,52.6919233669094,6.18435417656201,7.35691976547241,69,1,64,0,0,0.336837768554687,34.2131004333496,2,1,1,220.025939941406,0,2084574528,220.025939941406,,,,,,,,,,,,,,,,,,,,,,,,,,,,,,,,,
,3870095035.38174,252.07731628418,26.4772434234619,2.19843340866738E-5,9.42231397768733E-9,1,5,14.0008964538574,5.00906051703569,42.4900017678738,0.0255895854305543,0.00392157376489241,1,7.24657231831228E-8,,,,,,,,,,,,,,,,,,,,,252.07731628418,252.07731628418,26.4772434234619,26.4772434234619,52.7825922751402,6.18769314494034,7.6674017906189,68,1,64,0,0,0.340118408203125,33.7243423461914,2,1,1,252.07731628418,0,2084574624,252.07731628418,,,,,,,,,,,,,,,,,,,,,,,,,,,,,,,,,
,3870095228.07299,284.041107177734,26.4772434234619,1.84699170161664E-5,8.85265986267113E-9,1,5,14.0008964538574,5.00988440138374,42.6799990236759,0.0214853184117143,0.00341857642100317,1,1.66602945968594E-7,,,,,,,,,,,,,,,,,,,,,284.041107177734,284.041107177734,26.4772434234619,26.4772434234619,52.736085378246,6.18509936768922,7.89638376235962,69,1,64,0,0,0.337066650390625,33.7243423461914,2,1,1,284.041107177734,0,2084574464,284.041107177734,,,,,,,,,,,,,,,,,,,,,,,,,,,,,,,,,
,3870095615.96003,300.002960205078,45572.951171875,0.0187486748986509,5.54846530177213E-6,1,2,14.0008964538574,5.00001163538722,42.7599996328354,21.7922641671506,3.17530434154662,100,-7.64927369137293E-5,,,,,,,,,,,,,,,,,,,,,300.002868652344,300.003051757812,45478.03125,45667.87109375,52.6673020685537,6.1846850427188,7.78639936447144,26,1,68,0,0,0.340576171875,35.190616607666,1,6,1,300.003051757812,0,2084574272,300.002960205078,,,,,,,,,,,,,,,,,,,,,,,,,,,,,,,,,
,3870095696.04979,300.001617431641,37574.271484375,0.0154570279386848,5.29865067150379E-6,1,2,14.0008964538574,5.00027437695787,42.7599996328354,17.9659697217036,2.62879391746663,100,-5.37876349558351E-5,,,,,,,,,,,,,,,,,,,,,300.001525878906,300.001708984375,37489.26953125,37659.2734375,52.7567985340056,6.18416781755784,7.90421295166016,27,1,68,0,0,0.345687866210937,34.2131004333496,1,6,1,300.001708984375,0,2084574176,300.001617431641,,,,,,,,,,,,,,,,,,,,,,,,,,,,,,,,,
,3870095768.02347,300.002395629883,30384.5673828125,0.0124955803334525,4.62812481029951E-6,1,2,14.0008964538574,5.00068346074884,42.7500009536743,14.5254142645419,2.1258912690802,100,-4.30427280842934E-5,,,,,,,,,,,,,,,,,,,,,300.002349853516,300.00244140625,30299.5859375,30469.548828125,52.738039449544,6.18162734556524,8.06326961517334,26,1,68,0,0,0.342941284179687,34.2131004333496,1,6,1,300.002349853516,0,2084574208,300.002395629883,,,,,,,,,,,,,,,,,,,,,,,,,,,,,,,,,
,3870095831.9737,300.002288818359,24003.22265625,0.00986217674653354,9.86126705879384E-6,1,2,14.0008964538574,5.00072600550366,42.7599996328354,11.4650653084621,1.67322150941909,100,-3.79866862014583E-5,,,,,,,,,,,,,,,,,,,,,300.002197265625,300.002380371094,23908.197265625,24098.248046875,52.7298323500921,6.18161232928286,8.24857139587402,26,1,68,0,0,0.344390869140625,33.7243423461914,1,6,1,300.002197265625,0,2084574336,300.002288818359,,,,,,,,,,,,,,,,,,,,,,,,,,,,,,,,,
,3870095911.94215,300.002151489258,16020.0126953125,0.00656281363099274,5.19973144321154E-6,1,2,14.0008964538574,5.00072926093238,42.7599996328354,7.63072205922366,1.10507939347155,100,-3.24837346889188E-5,,,,,,,,,,,,,,,,,,,,,300.001953125,300.002349853516,15930.080078125,16109.9453125,52.6215768001786,6.1827176555888,8.53561592102051,27,1,68,0,0,0.344467163085937,34.2131004333496,1,6,1,300.002349853516,0,2084574240,300.002151489258,,,,,,,,,,,,,,,,,,,,,,,,,,,,,,,,,
,3870095976.0176,300.001403808594,9616.10400390625,0.00393570028221221,8.16683386928402E-6,1,2,14.0008964538574,5.00075988095223,42.7599996328354,4.57739935310712,0.654456592052356,100,-2.65913481883361E-5,,,,,,,,,,,,,,,,,,,,,300.001342773438,300.00146484375,9526.09765625,9706.1103515625,52.7173262937844,6.18291251343863,8.78603649139404,26,1,68,0,0,0.345916748046875,34.7018585205078,1,6,1,300.00146484375,0,2084573952,300.001403808594,,,,,,,,,,,,,,,,,,,,,,,,,,,,,,,,,
,3870096039.97776,300.000717163086,3224.57507324219,0.00133808700290941,5.70095053562624E-6,1,2,14.0008964538574,5.00065469936603,42.7599996328354,1.56422072510526,0.169055202766898,100,-5.50412170263845E-5,,,,,,,,,,,,,,,,,,,,,300.000396728516,300.001037597656,3129.49438476562,3319.65576171875,52.6379909990825,6.18350605724062,9.01941776275635,27,1,68,0,0,0.344772338867188,34.7018585205078,1,6,1,300.000396728516,0,2084574176,300.000717163086,,,,,,,,,,,,,,,,,,,,,,,,,,,,,,,,,
,3870096119.9426,300.001174926758,-4768.876953125,-0.00192014922421035,1.60699370914486E-5,1,2,14.0008964538574,5.00080622069733,42.7599996328354,-2.22965342860047,-0.343299124427502,100,-7.68163334566468E-6,,,,,,,,,,,,,,,,,,,,,300.001159667969,300.001190185547,-4858.908203125,-4678.845703125,52.7399935208421,6.18269013930435,9.30625247955322,28,1,0,0,1,0.344390869140625,34.2131004333496,1,6,1,300.001190185547,0,2084573728,300.001174926758,,,,,,,,,,,,,,,,,,,,,,,,,,,,,,,,,
,3870096192.02225,300.000015258789,-11985.4096679688,-0.0048837668311467,4.56664857007583E-6,1,2,14.0008964538574,5.00128621632114,42.7500009536743,-5.67395029750855,-0.858467240243115,100,-6.79492933042766E-6,,,,,,,,,,,,,,,,,,,,,299.999816894531,300.000213623047,-12070.533203125,-11900.2861328125,52.8431684853806,6.18095360974384,9.65933418273926,28,1,0,0,1,0.341415405273438,34.2131004333496,1,6,1,300.000213623047,0,2084574304,300.000015258789,,,,,,,,,,,,,,,,,,,,,,,,,,,,,,,,,
,3870096272.00733,299.999816894531,-19988.11328125,-0.00818643392447708,4.04410461218078E-6,1,2,14.0008964538574,5.0011563816351,42.7599996328354,-9.51279218328386,-1.42457528906024,100,9.8661223092058E-7,,,,,,,,,,,,,,,,,,,,,299.999664306641,299.999969482422,-20072.767578125,-19903.458984375,52.6993488378421,6.18081660391978,9.83619403839111,28,1,0,0,1,0.344619750976562,32.2580642700195,1,6,1,299.999664306641,0,2084573952,299.999816894531,,,,,,,,,,,,,,,,,,,,,,,,,,,,,,,,,
,3870096335.95884,299.999816894531,-26380.7626953125,-0.0108276640777888,6.08198495376328E-6,1,2,14.0008964538574,5.00093232520463,42.7500009536743,-12.5810128031542,-1.88507900638865,100,4.40873237169758E-7,,,,,,,,,,,,,,,,,,,,,299.999786376953,299.999847412109,-26476.03515625,-26285.490234375,52.7450741062171,6.18167158541191,9.77170276641846,26,1,68,0,0,0.339279174804687,34.7018585205078,1,6,1,299.999847412109,0,2084574176,299.999816894531,,,,,,,,,,,,,,,,,,,,,,,,,,,,,,,,,
,3870096407.92702,300.001419067383,-33591.072265625,-0.0138007498374272,4.30122071790875E-6,1,2,14.0008964538574,5.00108842848797,42.7599996328354,-16.0366096286389,-2.40031099218833,100,2.69831437121571E-6,,,,,,,,,,,,,,,,,,,,,300.001220703125,300.001617431641,-33681.109375,-33501.03515625,52.707555937294,6.18118802296827,9.70336246490478,28,1,0,0,1,0.34454345703125,34.2131004333496,1,6,1,300.001220703125,0,2084574176,300.001419067383,,,,,,,,,,,,,,,,,,,,,,,,,,,,,,,,,
,3870096496.01543,300.00016784668,-42424.23046875,-0.0174420240883822,1.19867000550025E-5,1,2,14.0008964538574,5.00121664442753,42.7500009536743,-20.2686885168589,-3.03270036431043,100,4.29851871772675E-6,,,,,,,,,,,,,,,,,,,,,300.000061035156,300.000274658203,-42509.453125,-42339.0078125,52.6223584286979,6.17983451535054,9.62339878082275,28,1,0,0,1,0.343475341796875,33.2355842590332,1,6,1,300.000274658203,0,2084574016,300.00016784668,,,,,,,,,,,,,,,,,,,,,,,,,,,,,,,,,
,3870096599.93293,299.999389648438,-47756.267578125,-0.0196935667870987,8.27205152631821E-6,1,2,14.0008964538574,5.00094547423277,42.7599996328354,-22.9014342958974,-3.30347210332384,100,0.00010851839094103,,,,,,,,,,,,,,,,,,,,,299.999298095703,299.999481201172,-47846.1875,-47666.34765625,52.631347156669,6.18219996756639,9.5447587966919,24,1,68,0,0,0.344924926757812,34.2131004333496,1,6,1,299.999481201172,0,2084574336,299.999389648438,,,,,,,,,,,,,,,,,,,,,,,,,,,,,,,,,
,3870096671.96663,300.000534057617,-40562.91796875,-0.0167117481497419,5.68000959783624E-6,1,2,14.0008964538574,5.00069768634607,42.7599996328354,-19.4300633363025,-2.81977190086535,100,7.77349962383933E-5,,,,,,,,,,,,,,,,,,,,,300.000213623047,300.000854492188,-40647.83984375,-40477.99609375,52.7372578210248,6.18318273576573,9.50790119171143,26,1,68,0,0,0.345001220703125,33.7243423461914,1,6,1,300.000854492188,0,2084574304,300.000534057617,,,,,,,,,,,,,,,,,,,,,,,,,,,,,,,,,
,3870096735.96898,300.001266479492,-34173.236328125,-0.0140724291424824,5.09110257472063E-6,1,2,14.0008964538574,5.00101658329199,42.7599996328354,-16.3616967154638,-2.38264940717942,100,5.85751542625319E-5,,,,,,,,,,,,,,,,,,,,,300.001251220703,300.001281738281,-34258.12109375,-34088.3515625,52.6887968528325,6.18403909399449,9.47833251953125,27,1,68,0,0,0.345382690429687,34.2131004333496,1,6,1,300.001251220703,0,2084574272,300.001266479492,,,,,,,,,,,,,,,,,,,,,,,,,,,,,,,,,
,3870096817.94063,300.000183105469,-25986.3544921875,-0.0106863547318529,9.67153376563693E-6,1,2,14.0008964538574,5.0008774018886,42.7500009536743,-12.4249297174094,-1.8050724781275,100,4.8094863697596E-5,,,,,,,,,,,,,,,,,,,,,300,300.000366210937,-26081.26171875,-25891.447265625,52.6188411003613,6.18331959831652,9.44221687316895,27,1,68,0,0,0.344467163085937,35.190616607666,1,6,1,300.000366210937,0,2084574112,300.000183105469,,,,,,,,,,,,,,,,,,,,,,,,,,,,,,,,,
,3870096889.99608,300.000061035156,-18792.755859375,-0.00772121699950152,5.9345638686995E-6,1,2,14.0008964538574,5.00079677697224,42.7599996328354,-8.97718398295229,-1.30421664313363,100,3.47274710305729E-5,,,,,,,,,,,,,,,,,,,,,299.999542236328,300.000579833984,-18872.67578125,-18712.8359375,52.631347156669,6.18265515092987,9.4114933013916,28,1,0,0,1,0.345001220703125,32.7468223571777,1,6,1,300.000579833984,0,2084574304,300.000061035156,,,,,,,,,,,,,,,,,,,,,,,,,,,,,,,,,
,3870096969.94113,300.000045776367,-10807.5063476562,-0.00442312910789294,6.79549113059443E-6,1,2,14.0008964538574,5.00082056337037,42.7599996328354,-5.14504865934403,-0.731118938951065,100,3.36744268952475E-5,,,,,,,,,,,,,,,,,,,,,300,300.000091552734,-10892.3583984375,-10722.654296875,52.7794657610633,6.18227942991916,9.38665294647217,26,1,68,0,0,0.345001220703125,34.7018585205078,1,6,1,300.000091552734,0,2084574208,300.000045776367,,,,,,,,,,,,,,,,,,,,,,,,,,,,,,,,,
,3870097033.90116,300.001358032227,-4416.87939453125,-0.00181087921135285,1.30701473267403E-5,1,2,14.0008964538574,5.00103921175503,42.7599996328354,-2.11367887352762,-0.251916096647463,100,5.4606169540827E-5,,,,,,,,,,,,,,,,,,,,,300.001312255859,300.001403808594,-4506.904296875,-4326.8544921875,52.7200619936017,6.18141050554213,9.37377452850342,28,1,0,0,1,0.344696044921875,35.6793746948242,1,6,1,300.001403808594,0,2084574240,300.001358032227,,,,,,,,,,,,,,,,,,,,,,,,,,,,,,,,,
,3870097113.87168,299.999862670898,3581.72741699219,0.00145050399696057,4.99440707909115E-6,1,2,14.0008964538574,5.00085534166267,42.7500009536743,1.67902673074713,0.294722545445228,100,3.62586520100641E-5,,,,,,,,,,,,,,,,,,,,,299.999847412109,299.999877929687,3491.79516601562,3671.65966796875,52.685279524496,6.18250827902159,9.35786819458008,26,1,68,0,0,0.340652465820313,35.6793746948242,1,6,1,299.999877929687,0,2084573856,299.999862670898,,,,,,,,,,,,,,,,,,,,,,,,,,,,,,,,,
,3870097177.85102,300.000015258789,9982.49609375,0.00406786939387011,4.32997735767718E-6,1,2,14.0008964538574,5.00098127568812,42.7599996328354,4.72469229048504,0.721305663320228,100,1.10969049172637E-5,,,,,,,,,,,,,,,,,,,,,299.999786376953,300.000244140625,9892.76171875,10072.23046875,52.661830668919,6.18197900936602,9.34217357635498,28,1,0,0,1,0.3448486328125,34.2131004333496,1,6,1,300.000244140625,0,2084573952,300.000015258789,,,,,,,,,,,,,,,,,,,,,,,,,,,,,,,,,
,3870097245.9003,299.999298095703,16785.220703125,0.00687551257435648,4.09321612795863E-6,1,2,14.0008964538574,5.00100618125416,42.7599996328354,7.987762356104,1.20560066564719,10,7.08713675351544E-6,,,,,,,,,,,,,,,,,,,,,299.999145507812,299.999450683594,16695.06640625,16875.375,52.753281205669,6.18146797648746,9.31989765167236,28,1,0,0,1,0.344772338867188,34.2131004333496,1,6,1,299.999145507812,0,2084574080,299.999298095703,,,,,,,,,,,,,,,,,,,,,,,,,,,,,,,,,
,3870097353.8607,300.000518798828,27592.83203125,0.0113310194428297,4.32621879550135E-6,1,2,14.0008964538574,5.00089223021167,42.7599996328354,13.1656477771585,1.97323868651948,100,1.06510080779384E-8,,,,,,,,,,,,,,,,,,,,,300.000396728516,300.000640869141,27502.478515625,27683.185546875,52.6118064436882,6.18108321916743,9.30082893371582,28,1,0,0,1,0.340118408203125,34.7018585205078,1,6,1,300.000640869141,0,2084574304,300.000518798828,,,,,,,,,,,,,,,,,,,,,,,,,,,,,,,,,
,3870097442.00008,300.000457763672,36423.2109375,0.0149581251932925,1.4924126491897E-5,1,2,14.0008964538574,5.0006256553734,42.7599996328354,17.3808588860568,2.59047734806779,100,-1.22156979226147E-5,,,,,,,,,,,,,,,,,,,,,300.000213623047,300.000701904297,36342.98828125,36503.43359375,52.6063350440536,6.18266627647764,9.28497314453125,28,1,0,0,1,0.340499877929687,34.2131004333496,1,6,1,300.000213623047,0,2084574240,300.000457763672,,,,,,,,,,,,,,,,,,,,,,,,,,,,,,,,,
,3870097547.01329,300.001098632812,46947.484375,0.019263636630396,1.17789659455926E-5,1,2,14.0008964538574,5.00076419111582,42.7500009536743,22.3829207812205,3.34739372038995,100,-6.13509493593528E-6,,,,,,,,,,,,,,,,,,,,,300.001098632812,300.001098632812,46947.484375,46947.484375,52.5840586312556,6.18250600819141,9.26911640167236,28,1,0,0,1,0.34454345703125,34.2131004333496,1,6,1,300.001098632812,0,2084574304,300.001098632812,,,,,,,,,,,,,,,,,,,,,,,,,,,,,,,,,
,3870097580.01744,299.999725341797,50000.498046875,0.0205628727024356,2.06094946587505E-6,1,2,14.0008964538574,5.00060502833292,42.7599996328354,23.8879881968399,3.5962505616092,100,1.34636915258161E-5,,,,,,,,,,,,,,,,,,,,,299.999694824219,299.999755859375,50000.4609375,50000.53515625,52.697394766544,6.18241229770003,9.2646951675415,28,1,0,0,1,0.3448486328125,34.2131004333496,1,4,1,299.999694824219,0,2084574176,299.999725341797,,,,,,,,,,,,,,,,,,,,,,,,,,,,,,,,,