File: LT data/Bridport/Wareham W1/430-FC-ZFC-RTSIRM-contsweepwithloop.dat
[Header]
; MPMS3 Data File (default extension .dat)
; Copyright (c) 2007, Quantum Design, Inc. All rights reserved.
TITLE,
FILEOPENTIME,3865600482.03936,06/28/2022,6:52 pm
BYAPP,MPMS3 w/ AC,1.0,1.1
INFO,MPMS3 Measurement Release 1.1.16 Build 424, MultiVu Release 2.3.4.19,APPNAME
INFO,Linear Motor Servo Controller,MOTOR_MODULE_NAME
INFO,3101-100 N2,MOTOR_HW_VERSION
INFO,,MOTOR_SERIAL_NUMBER
INFO,01.04.28,MOTOR_SOFTWARE_VERSION
INFO,Quantum Design Squid Module,SQUID_MODULE_NAME
INFO,3101-501 B0,SQUID_HW_VERSION
INFO,SQM327,SQUID_SERIAL_NUMBER
INFO,01.03.04,SQUID_SOFTWARE_VERSION
INFO,Quantum Design VSM Oven,OVEN_MODULE_NAME
INFO,3101-201 A3,OVEN_HW_VERSION
INFO,OVB365,OVEN_SERIAL_NUMBER
INFO,01.07.07,OVEN_SOFTWARE_VERSION
INFO,SQUID AC,AC_MODULE_NAME
INFO,3101-401 G0,AC_HW_VERSION
INFO,SAC220,AC_SERIAL_NUMBER
INFO,SQUID AC 00.95.07,AC_SOFTWARE_VERSION
INFO,TCI344,COIL_SERIAL_NUMBER
INFO,0,MOMENT_UNITS
INFO,oil stained sst,SAMPLE_MATERIAL
INFO,,SAMPLE_COMMENT
INFO,276.83,SAMPLE_MASS
INFO,,SAMPLE_VOLUME
INFO,,SAMPLE_MOLECULAR_WEIGHT
INFO,,SAMPLE_SIZE
INFO,,SAMPLE_SHAPE
INFO,Straw,SAMPLE_HOLDER
INFO,Standard,SAMPLE_HOLDER_DETAIL
INFO,72.97,SAMPLE_OFFSET
DATATYPE,COMMENT,1
DATATYPE,TIME,2
STARTUPAXIS,X,2
STARTUPAXIS,Y1,5
FIELDGROUP, VSM,2,3,4,5,6,8,9,10,11,14,15
FIELDGROUP, DC, 2,3,4,14,56,57,58,59,60,61,62,63,64,65,66,67,68,69
FIELDGROUP, AC, 2,3,4,11,16,17,18,19,20,21,22,23,24,25,26,27,28,29,30
STARTUPGROUP, All
[Data]
Comment,Time Stamp (sec),Temperature (K),Magnetic Field (Oe),Moment (emu),M. Std. Err. (emu),Transport Action,Averaging Time (sec),Frequency (Hz),Peak Amplitude (mm),Center Position (mm),Lockin Signal' (V),Lockin Signal (V),Range,M. Quad. Signal (emu),AC Moment (emu),AC M. Std Err. (emu),AC Phase (deg),AC Phase Std. Err. (deg),AC Susceptibility (emu/Oe),AC Suscept. Std Err. (emu/Oe),AC X' (emu/Oe),AC X' Std Err. (emu/Oe),AC X'' (emu/Oe),AC X'' Std Err. (emu/Oe),AC Drive (Oe),AC Frequency (Hz),AC Averaging Time (sec),AC Cycles,AC Range,AC Measure Type,AC Signal' (V),AC Signal'' (V),AC Trim Coil Ratio,AC Trim Coil Phase,Min. Temperature (K),Max. Temperature (K),Min. Field (Oe),Max. Field (Oe),Mass (grams),Motor Lag (deg),Pressure (Torr),Measure Count,Measurement Number,SQUID Status (code),Motor Status (code),Measure Status (code),Motor Current (amps),Motor Temp. (C),Temp. Status (code),Field Status (code),Chamber Status (code),Chamber Temp (K),Redirection State,Average Temp (K),Rotation Angle (deg),Rotator state,DC Moment Fixed Ctr (emu),DC Moment Err Fixed Ctr (emu),DC Moment Free Ctr (emu),DC Moment Err Free Ctr (emu),DC Fixed Fit,DC Free Fit,DC Calculated Center (mm),DC Calculated Center Err (mm),DC Scan Length (mm),DC Scan Time (s),DC Number of Points,DC Squid Drift,DC Min V (V),DC Max V (V),DC Scans per Measure,Map 01,Map 02,Map 03,Map 04,Map 05,Map 06,Map 07,Map 08,Map 09,Map 10,Map 11,Map 12,Map 13,Map 14,Map 15,Map 16
,3865602520.20101,1.9998779296875,25.1839542388916,0.00804094774158775,7.26424336122984E-7,1,5,12.9061126708984,4.99633489505239,46.2500005960464,10.4891521940324,1.53560901259572,100,-4.0241857667012E-6,,,,,,,,,,,,,,,,,,,,,1.9998779296875,1.9998779296875,25.1839542388916,25.1839542388916,49.4974076088129,5.41269011807334,2.7000002861023,65,1,0,0,1,0.270309448242187,30.3030319213867,1,1,1,1.9998779296875,0,1.9998779296875,,,,,,,,,,,,,,,,,,,,,,,,,,,,,,,,,
,3865602699.98752,29.0371112823486,25.1839542388916,0.000180021192013317,9.74948868190443E-8,1,5,12.9061126708984,4.99688039141051,46.2599992752075,0.234857565290013,0.034453320421026,1,-3.73880450871037E-8,,,,,,,,,,,,,,,,,,,,,29.0371112823486,29.0371112823486,25.1839542388916,25.1839542388916,49.5783061605533,5.4100166697855,6.02032709121704,65,1,0,0,1,0.27496337890625,32.7468223571777,2,1,1,29.0371112823486,0,29.0371112823486,,,,,,,,,,,,,,,,,,,,,,,,,,,,,,,,,
,3865602878.82565,57.070426940918,25.1839542388916,0.000125413015730548,3.59581821867412E-8,1,5,12.9061126708984,4.99854297983575,46.28000035882,0.163702109227958,0.0239407469611311,1,-8.16633697886223E-8,,,,,,,,,,,,,,,,,,,,,57.070426940918,57.070426940918,25.1839542388916,25.1839542388916,49.5681449898033,5.40399403598551,6.55701303482056,65,1,0,0,1,0.276107788085938,31.2805480957031,2,1,1,57.070426940918,0,57.070426940918,,,,,,,,,,,,,,,,,,,,,,,,,,,,,,,,,
,3865603053.75212,85.0703811645508,25.1839542388916,9.59996684362749E-5,3.17324998409932E-8,1,5,12.9061126708984,4.99698577591166,46.3300012052059,0.125255706130654,0.0183066186338417,1,-7.11425321144737E-8,,,,,,,,,,,,,,,,,,,,,85.0703811645508,85.0703811645508,25.1839542388916,25.1839542388916,49.5177299503129,5.40804597159188,6.80258226394653,63,1,64,0,0,0.2703857421875,31.2805480957031,2,1,1,85.0703811645508,0,85.0703811645508,,,,,,,,,,,,,,,,,,,,,,,,,,,,,,,,,
,3865603223.76124,113.006042480469,25.1839542388916,7.35320284524116E-5,2.35899914256618E-8,1,5,12.9061126708984,4.99640406627092,46.3799983263016,0.0959280398754742,0.0140016820541023,1,-6.84384530430106E-8,,,,,,,,,,,,,,,,,,,,,113.006042480469,113.006042480469,25.1839542388916,25.1839542388916,49.529845192361,5.41184462697254,6.92748117446899,65,1,0,0,1,0.268020629882813,31.2805480957031,2,1,1,113.006042480469,0,113.006042480469,,,,,,,,,,,,,,,,,,,,,,,,,,,,,,,,,
,3865603393.3322,141.135711669922,25.1839542388916,5.35201023399575E-5,1.50920775659726E-8,1,5,12.9061126708984,4.9986420408489,46.459998935461,0.0698658490909378,0.0101904250913873,1,-5.52228144854139E-8,,,,,,,,,,,,,,,,,,,,,141.135711669922,141.135711669922,25.1839542388916,25.1839542388916,49.489200509361,5.40491223136762,7.00552749633789,65,1,0,0,1,0.276260375976562,31.2805480957031,2,1,1,141.135711669922,0,141.135711669922,,,,,,,,,,,,,,,,,,,,,,,,,,,,,,,,,
,3865603561.69342,169.0234375,25.1839542388916,4.10916566837324E-5,1.10617569305857E-8,1,5,12.9061126708984,5.00013275958896,46.5499982237816,0.053664181526519,0.00782605178876494,1,-4.333334944897E-8,,,,,,,,,,,,,,,,,,,,,169.0234375,169.0234375,25.1839542388916,25.1839542388916,49.4966259802937,5.40058100494458,7.07835102081299,65,1,0,0,1,0.280609130859375,31.2805480957031,2,1,1,169.0234375,0,169.0234375,,,,,,,,,,,,,,,,,,,,,,,,,,,,,,,,,
,3865603731.04636,197.027221679687,25.1839542388916,3.17562798524746E-5,1.01939213421516E-8,1,5,12.9061126708984,5.00135839749232,46.6599985957146,0.0414872593689189,0.00604679016024006,1,-3.60780761346312E-8,,,,,,,,,,,,,,,,,,,,,197.027221679687,197.027221679687,25.1839542388916,25.1839542388916,49.4141641715148,5.39593225324059,7.1559681892395,65,1,0,0,1,0.278854370117187,31.7693061828613,2,1,1,197.027221679687,0,197.027221679687,,,,,,,,,,,,,,,,,,,,,,,,,,,,,,,,,
,3865603899.40504,225.043426513672,25.1839542388916,2.45327147250988E-5,9.40418888230264E-9,1,5,12.9061126708984,5.00227756336963,46.79000005126,0.0320596579319857,0.00466429248768247,1,-3.41806203729841E-8,,,,,,,,,,,,,,,,,,,,,225.043426513672,225.043426513672,25.1839542388916,25.1839542388916,49.5220289071687,5.39192842550787,7.29846048355103,64,1,64,0,0,0.27496337890625,31.7693061828613,2,1,1,225.043426513672,0,225.043426513672,,,,,,,,,,,,,,,,,,,,,,,,,,,,,,,,,
,3865604068.34489,253.068878173828,25.1839542388916,1.93343363513054E-5,8.48017263825951E-9,1,5,12.9061126708984,5.00404037985067,46.9300001859665,0.0252788800707769,0.003677330315933,1,-2.72681984048865E-8,,,,,,,,,,,,,,,,,,,,,253.068878173828,253.068878173828,25.1839542388916,25.1839542388916,49.4872464380629,5.38294629509543,7.54620790481567,63,1,64,0,0,0.26824951171875,31.2805480957031,2,1,1,253.068878173828,0,253.068878173828,,,,,,,,,,,,,,,,,,,,,,,,,,,,,,,,,
,3865604237.74262,281.1064453125,25.1839542388916,1.54353410622621E-5,7.74000027287294E-9,1,5,12.9061126708984,5.00556434614301,47.0900014042854,0.0201901210079741,0.00293413179165804,1,-2.39661573038293E-8,,,,,,,,,,,,,,,,,,,,,281.1064453125,281.1064453125,25.1839542388916,25.1839542388916,49.4966259802937,5.37845834871661,7.68898963928223,64,1,64,0,0,0.269088745117187,31.7693061828613,2,1,1,281.1064453125,0,281.1064453125,,,,,,,,,,,,,,,,,,,,,,,,,,,,,,,,,
,3865606392.0775,1.99979209899902,45543.625,0.412641586021865,0.000207628971956143,1,2,12.9061126708984,5.0082781993039,46.2500005960464,539.885236818498,80.3909494092627,1000,0.000804717673052239,,,,,,,,,,,,,,,,,,,,,1.99956774711609,2.00001645088196,45468.76953125,45618.48046875,49.9847529905534,5.41322459860527,2.58761239051819,26,1,0,0,1,0.2862548828125,31.7693061828613,1,6,1,1.99956774711609,0,1.99979209899902,,,,,,,,,,,,,,,,,,,,,,,,,,,,,,,,,
,3865606452.43501,1.99789065122604,39513.591796875,0.390455937409942,0.000158925541491453,1,2,12.9061126708984,5.00841102823554,46.2500005960464,510.913283279104,75.826541647572,1000,0.000574244632995936,,,,,,,,,,,,,,,,,,,,,1.99785923957825,1.99792206287384,39408.9140625,39618.26953125,49.9585684351591,5.41220218748712,2.57932043075562,26,1,0,0,1,0.285873413085938,30.7917900085449,1,6,1,1.99792206287384,0,1.99789065122604,,,,,,,,,,,,,,,,,,,,,,,,,,,,,,,,,
,3865606512.75872,1.9995134472847,33493.478515625,0.364386331754061,0.000155667445408232,1,2,12.9061126708984,5.00792551397583,46.2500005960464,476.758168425202,70.6064413618169,1000,0.000422967162253081,,,,,,,,,,,,,,,,,,,,,1.99939012527466,1.99963676929474,33398.484375,33588.47265625,49.8323354293033,5.412742504829,2.58662366867065,26,1,0,0,1,0.287246704101562,31.2805480957031,1,6,1,1.99939012527466,0,1.9995134472847,,,,,,,,,,,,,,,,,,,,,,,,,,,,,,,,,
,3865606573.35329,2.00230348110199,27443.212890625,0.333114503966397,0.000122900331555818,1,2,12.9061126708984,5.00783098867263,46.2500005960464,435.846457849814,64.4402086056601,1000,0.000306392208407049,,,,,,,,,,,,,,,,,,,,,2.00216460227966,2.00244235992432,27368.23828125,27518.1875,49.7377583784764,5.41162327218637,2.58974647521973,26,1,0,0,1,0.27862548828125,31.2805480957031,1,6,1,2.00216460227966,0,2.00230348110199,,,,,,,,,,,,,,,,,,,,,,,,,,,,,,,,,
,3865606633.66034,2.00138998031616,21422.84375,0.294959788024605,9.27424388267836E-5,1,2,12.9061126708984,5.00805202833374,46.2500005960464,385.969152849366,56.9236666690741,1000,0.000164986864896153,,,,,,,,,,,,,,,,,,,,,2.00127768516541,2.00150227546692,21328.01171875,21517.67578125,49.697504509736,5.41008945134963,2.59103965759277,26,1,0,0,1,0.278244018554687,31.2805480957031,1,6,1,2.00127768516541,0,2.00138998031616,,,,,,,,,,,,,,,,,,,,,,,,,,,,,,,,,
,3865606696.08599,2.00044453144073,15193.3325195313,0.244351755898374,0.000102635123119151,1,2,12.9061126708984,5.00791078546626,46.2500005960464,319.755106074599,47.007886368547,1000,2.42057122641721E-5,,,,,,,,,,,,,,,,,,,,,2.00028705596924,2.00060200691223,15098.3251953125,15288.33984375,49.6373191137553,5.41096378887872,2.58085632324219,26,1,0,0,1,0.278549194335938,31.2805480957031,1,6,1,2.00028705596924,0,2.00044453144073,,,,,,,,,,,,,,,,,,,,,,,,,,,,,,,,,
,3865606754.81437,1.99989432096481,9325.10791015625,0.181395958249093,0.000138192077575659,1,2,12.9061126708984,5.00871526115382,46.2500005960464,237.425861596895,34.9012874844449,1000,1.55765437050329E-5,,,,,,,,,,,,,,,,,,,,,1.99984085559845,1.99994778633118,9265.1884765625,9385.02734375,49.5786969748129,5.40787344459946,2.58498096466064,26,1,0,0,1,0.285720825195313,31.2805480957031,1,6,1,1.99984085559845,0,1.99989432096481,,,,,,,,,,,,,,,,,,,,,,,,,,,,,,,,,
,3865606815.08183,1.99995708465576,3299.01013183594,0.0882322174818382,0.000206363000512596,1,2,12.9061126708984,5.00827593136757,46.2500005960464,115.47649390618,16.9393033290777,1000,-1.90416013157933E-5,,,,,,,,,,,,,,,,,,,,,1.99975609779358,2.00015807151794,3189.060546875,3408.95971679687,49.5818234888899,5.40895918018471,2.58927273750305,26,1,0,0,1,0.287094116210938,30.7917900085449,1,6,1,2.00015807151794,0,1.99995708465576,,,,,,,,,,,,,,,,,,,,,,,,,,,,,,,,,
,3865606890.72796,1.99994242191315,-4257.39196777344,-0.095115098510495,0.000209783174955244,1,2,12.9061126708984,5.00822167351826,46.2500005960464,-124.463496981137,-18.3916946348303,100,-7.97656728354273E-5,,,,,,,,,,,,,,,,,,,,,1.99932217597961,2.00056266784668,-4427.3994140625,-4087.38452148438,49.5740072036975,5.4090008305434,2.56952261924744,26,1,0,0,1,0.2777099609375,31.2805480957031,1,6,1,1.99932217597961,0,1.99994242191315,,,,,,,,,,,,,,,,,,,,,,,,,,,,,,,,,
,3865606962.21192,1.99954456090927,-11407.2407226562,-0.201486990393147,0.000133799986098549,1,2,12.9061126708984,5.00789362252291,46.2500005960464,-263.666483233459,-38.7285123237667,1000,5.22254989689559E-6,,,,,,,,,,,,,,,,,,,,,1.99950706958771,1.99958205223083,-11477.2265625,-11337.2548828125,49.5849500029668,5.41091560156248,2.53610372543335,26,1,0,0,1,0.277481079101562,31.2805480957031,5,6,1,1.99958205223083,0,1.99954456090927,,,,,,,,,,,,,,,,,,,,,,,,,,,,,,,,,
,3865607020.42455,1.99933487176895,-17232.287109375,-0.260743605985437,0.000116602445683653,1,2,12.9061126708984,5.00836611109001,46.2500005960464,-341.250376061971,-50.155764684269,1000,-1.67141324174874E-5,,,,,,,,,,,,,,,,,,,,,1.99927377700806,1.99939596652985,-17327.23828125,-17137.3359375,49.6607679693322,5.40955395939875,2.5210063457489,26,1,0,0,1,0.286636352539062,30.7917900085449,1,6,1,1.99939596652985,0,1.99933487176895,,,,,,,,,,,,,,,,,,,,,,,,,,,,,,,,,
,3865607076.8759,1.99999696016312,-22877.7294921875,-0.304015319624265,0.000123743186062663,1,2,12.9061126708984,5.00849933964723,46.2500005960464,-397.896561882617,-58.4872039785768,1000,-2.38142837598112E-5,,,,,,,,,,,,,,,,,,,,,1.99907791614532,2.00091600418091,-22977.58203125,-22777.876953125,49.7084473090053,5.40927367886864,2.49957466125488,26,1,0,0,1,0.276947021484375,31.2805480957031,6,6,1,1.99907791614532,0,1.99999696016312,,,,,,,,,,,,,,,,,,,,,,,,,,,,,,,,,
,3865607137.27514,2.00116521120071,-28918.82421875,-0.340711718802718,0.000167188724329006,1,2,12.9061126708984,5.00829725869277,46.2500005960464,-445.870531549407,-65.742531071284,1000,-0.000178959074046151,,,,,,,,,,,,,,,,,,,,,1.99993169307709,2.00239872932434,-29014.169921875,-28823.478515625,49.8045876168706,5.41084123381792,2.48910212516785,26,1,0,0,1,0.286788940429687,30.7917900085449,1,6,1,1.99993169307709,0,2.00116521120071,,,,,,,,,,,,,,,,,,,,,,,,,,,,,,,,,
,3865607199.03715,1.9986058473587,-35109.84765625,-0.37173252639611,0.000183271450440234,1,2,12.9061126708984,5.00798493921461,46.2500005960464,-486.33920960397,-72.2944658922573,1000,-0.000632751315273538,,,,,,,,,,,,,,,,,,,,,1.9974604845047,1.99975121021271,-35275.07421875,-34944.62109375,49.914015609563,5.41211023335389,2.48868894577026,26,1,0,0,1,0.277938842773438,30.7917900085449,1,6,1,1.99975121021271,0,1.9986058473587,,,,,,,,,,,,,,,,,,,,,,,,,,,,,,,,,
,3865607258.21135,2.00018739700317,-41036.279296875,-0.395559222277425,0.000237211429759107,1,2,12.9061126708984,5.00861684161301,46.2500005960464,-517.594700950423,-76.9989560623212,1000,-0.000716937968195033,,,,,,,,,,,,,,,,,,,,,2.00012016296387,2.00025463104248,-41136.4375,-40936.12109375,49.9542694783034,5.41056515816481,2.4764199256897,26,1,0,0,1,0.286636352539062,31.2805480957031,5,6,1,2.00025463104248,0,2.00018739700317,,,,,,,,,,,,,,,,,,,,,,,,,,,,,,,,,
,3865607317.90718,1.99989247322083,-47015.990234375,-0.417170770294014,0.000287392532712206,1,2,12.9061126708984,5.00855375314835,46.2500005960464,-545.865182527306,-81.1969962141834,1000,-0.000750453851815303,,,,,,,,,,,,,,,,,,,,,1.99926662445068,2.00051832199097,-47176.2265625,-46855.75390625,50.0945717975053,5.41144923499473,2.47812104225159,26,1,0,0,1,0.285873413085938,31.2805480957031,6,6,1,1.99926662445068,0,1.99989247322083,,,,,,,,,,,,,,,,,,,,,,,,,,,,,,,,,
,3865607381.34753,1.99932760000229,-47101.40234375,-0.417343779408876,0.000218942251798015,1,2,12.9061126708984,5.0090263626407,46.2500005960464,-546.107686240452,-81.6220943421834,1000,-0.00104159998711884,,,,,,,,,,,,,,,,,,,,,1.99902606010437,1.99962913990021,-47166.2109375,-47036.59375,50.0273517448514,5.40935036122591,2.47586464881897,26,1,0,0,1,0.2850341796875,31.2805480957031,1,6,1,1.99902606010437,0,1.99932760000229,,,,,,,,,,,,,,,,,,,,,,,,,,,,,,,,,
,3865607439.49046,1.99946802854538,-41298.263671875,-0.395130994263356,0.00227200458035878,1,2,12.9061126708984,5.00884192239069,46.2500005960464,-517.41684735619,-74.5380362505385,1000,0.00110392652415694,,,,,,,,,,,,,,,,,,,,,1.9992264509201,1.99970960617065,-41397.921875,-41198.60546875,50.041030243938,5.41015590532756,2.46850752830505,26,1,0,0,1,0.286407470703125,32.2580642700195,5,6,1,1.9992264509201,0,1.99946802854538,,,,,,,,,,,,,,,,,,,,,,,,,,,,,,,,,
,3865607501.91252,2.00042343139648,-35064.45703125,-0.366923709080883,0.00459361663458333,1,2,12.9061126708984,5.00898713757498,46.2500005960464,-480.091560617089,-71.9958669345518,1000,-0.00109565100900351,,,,,,,,,,,,,,,,,,,,,2.00039863586426,2.00044822692871,-35159.21875,-34969.6953125,49.8573475419187,5.40860425118712,2.46401858329773,26,1,0,0,1,0.28472900390625,31.2805480957031,1,6,1,2.00044822692871,0,2.00042343139648,,,,,,,,,,,,,,,,,,,,,,,,,,,,,,,,,
,3865607560.74355,2.00038576126099,-29195.7802734375,-0.342871431970361,0.000169269099071786,1,2,12.9061126708984,5.00836065455077,46.2500005960464,-448.610040139048,-66.805249270937,1000,-0.000672782882765937,,,,,,,,,,,,,,,,,,,,,1.99979186058044,2.00097966194153,-29310.51171875,-29081.048828125,49.7487011777457,5.41010986902983,2.46581792831421,26,1,0,0,1,0.285568237304687,31.7693061828613,1,6,1,1.99979186058044,0,2.00038576126099,,,,,,,,,,,,,,,,,,,,,,,,,,,,,,,,,
,3865607623.04559,2.00008630752563,-22976.8095703125,-0.305895569926944,0.000122520688370489,1,2,12.9061126708984,5.00858175107775,46.2500005960464,-400.274080388599,-59.4804137504355,1000,-0.00050539862076063,,,,,,,,,,,,,,,,,,,,,1.99987363815308,2.00029897689819,-23101.4453125,-22852.173828125,49.7358043071783,5.40835123052015,2.47589755058289,26,1,0,0,1,0.2783203125,30.7917900085449,1,6,1,2.00029897689819,0,2.00008630752563,,,,,,,,,,,,,,,,,,,,,,,,,,,,,,,,,
,3865607685.25356,2.00121510028839,-16767.7314453125,-0.25874624927943,9.58573290976354E-5,1,2,12.9061126708984,5.00830227927895,46.2500005960464,-338.636545588034,-49.728047676479,1000,1.59833155593345E-5,,,,,,,,,,,,,,,,,,,,,2.00038933753967,2.00204086303711,-16862.53125,-16672.931640625,49.6732740256399,5.40878611805851,2.47665119171143,26,1,0,0,1,0.28533935546875,30.7917900085449,1,6,1,2.00038933753967,0,2.00121510028839,,,,,,,,,,,,,,,,,,,,,,,,,,,,,,,,,
,3865607747.74684,1.99939453601837,-10526.4912109375,-0.195964152914488,0.000128890024790148,1,2,12.9061126708984,5.00868757251562,46.2500005960464,-256.484254592552,-37.7561728236914,1000,-5.67083167564673E-5,,,,,,,,,,,,,,,,,,,,,1.99926686286926,1.99952220916748,-10621.5732421875,-10431.4091796875,49.6650669261879,5.4066110568969,2.46906208992004,26,1,0,0,1,0.277862548828125,31.2805480957031,1,6,1,1.99952220916748,0,1.99939453601837,,,,,,,,,,,,,,,,,,,,,,,,,,,,,,,,,
,3865607807.44718,1.99938106536865,-4556.70361328125,-0.10987616893472,0.00018641600474963,1,2,12.9061126708984,5.00819994361586,46.2500005960464,-143.804302193397,-21.0689591193262,1000,4.29840798006503E-5,,,,,,,,,,,,,,,,,,,,,1.99889600276947,1.99986612796783,-4716.39404296875,-4397.01318359375,49.5888581455629,5.40747467068006,2.48080515861511,26,1,0,0,1,0.285873413085938,31.2805480957031,1,6,1,1.99889600276947,0,1.99938106536865,,,,,,,,,,,,,,,,,,,,,,,,,,,,,,,,,
,3865607886.91798,1.99973326921463,3378.78002929687,0.0755604147491227,0.000226667409266617,1,2,12.9061126708984,5.00808161864524,46.2500005960464,98.8743496544982,14.5886661656965,100,4.70796595388212E-5,,,,,,,,,,,,,,,,,,,,,1.99949622154236,1.9999703168869,3308.80029296875,3448.759765625,49.6283303857841,5.40891931724103,2.47362637519836,26,1,0,0,1,0.286178588867187,32.2580642700195,1,6,1,1.9999703168869,0,1.99973326921463,,,,,,,,,,,,,,,,,,,,,,,,,,,,,,,,,
,3865607963.21722,2.00010192394257,11014.3564453125,0.197115653261952,0.000133544322817856,1,2,12.9061126708984,5.00774423551907,46.2500005960464,257.930536526044,37.9196523617618,1000,2.00718129842906E-5,,,,,,,,,,,,,,,,,,,,,1.99908208847046,2.00112175941467,10919.2177734375,11109.4951171875,49.5646276614668,5.40970678327115,2.47158122062683,26,1,0,0,1,0.287246704101562,31.2805480957031,1,6,1,1.99908208847046,0,2.00010192394257,,,,,,,,,,,,,,,,,,,,,,,,,,,,,,,,,
,3865608025.05637,2.0001158118248,17200.1455078125,0.260797125068987,0.000145630822583191,1,2,12.9061126708984,5.00826877214064,46.2500005960464,341.2991845812,50.246097084818,1000,7.89158252517077E-5,,,,,,,,,,,,,,,,,,,,,1.9999612569809,2.0002703666687,17050.189453125,17350.1015625,49.6963320669572,5.40954091617842,2.45763731002808,26,1,0,0,1,0.286483764648438,31.2805480957031,5,6,1,1.9999612569809,0,2.0001158118248,,,,,,,,,,,,,,,,,,,,,,,,,,,,,,,,,
,3865608089.42391,2.00089609622955,23636.7509765625,0.309150605212278,0.000280682495583731,1,2,12.9061126708984,5.00824148677039,46.2500005960464,404.431042688691,60.5427631474728,1000,0.000843259544247318,,,,,,,,,,,,,,,,,,,,,2.00067448616028,2.00111770629883,23471.771484375,23801.73046875,49.7932540033418,5.40994788086104,2.45894265174866,26,1,0,0,1,0.2862548828125,31.7693061828613,1,6,1,2.00067448616028,0,2.00089609622955,,,,,,,,,,,,,,,,,,,,,,,,,,,,,,,,,
,3865608152.9483,1.99949616193771,30000.4501953125,0.336587511077858,0.00550023478138763,1,2,12.9061126708984,5.00829306598008,46.2500005960464,440.954159226717,61.6707647249972,1000,-0.00232629237453849,,,,,,,,,,,,,,,,,,,,,1.99901497364044,1.99997735023499,29940.34765625,30060.552734375,49.8202201872553,5.41033481206736,2.44843220710754,26,1,0,0,1,0.2783203125,31.2805480957031,1,6,1,1.99997735023499,0,1.99949616193771,,,,,,,,,,,,,,,,,,,,,,,,,,,,,,,,,
,3865608211.08428,1.9995208978653,35822.48828125,0.373639509403036,0.000370512401615265,1,2,12.9061126708984,5.00836749227945,46.2500005960464,488.695122684009,73.9747049249242,1000,0.00163052326394263,,,,,,,,,,,,,,,,,,,,,1.99945032596588,1.99959146976471,35732.43359375,35912.54296875,49.9519245927457,5.410357254396,2.43947052955627,26,1,0,0,1,0.276260375976562,31.2805480957031,5,6,1,1.99959146976471,0,1.9995208978653,,,,,,,,,,,,,,,,,,,,,,,,,,,,,,,,,
,3865608273.46627,1.9998437166214,42075.458984375,0.391202913973774,0.00588439206633148,1,2,12.9061126708984,5.00846861952976,46.2500005960464,511.42713545335,79.18430095173,1000,0.00302908318505612,,,,,,,,,,,,,,,,,,,,,1.99960398674011,2.00008344650269,41985.30859375,42165.609375,50.0601801426591,5.41088568555167,2.43877649307251,25,1,68,0,0,0.28717041015625,32.7468223571777,1,6,1,2.00008344650269,0,1.9998437166214,,,,,,,,,,,,,,,,,,,,,,,,,,,,,,,,,
,3865608335.96923,1.99319392442703,48338.96875,0.403172553577282,0.00782573605784613,1,2,12.9061126708984,5.00847953251131,46.2500005960464,527.255325836271,80.3927179322831,1000,0.0021937206197784,,,,,,,,,,,,,,,,,,,,,1.97895753383636,2.0074303150177,48248.8203125,48429.1171875,50.1492857938515,5.41208787269397,2.43250036239624,25,1,68,0,0,0.277557373046875,30.7917900085449,6,6,1,2.0074303150177,0,1.99319392442703,,,,,,,,,,,,,,,,,,,,,,,,,,,,,,,,,
,3865608870.33986,20.951192855835,25.484806060791,0.000180692940308853,1.18617267455181E-7,1,5,12.9061126708984,4.99817514964043,46.2500005960464,0.235816001475207,0.0346184887556969,1,-1.91001269123944E-8,,,,,,,,,,,,,,,,,,,,,20.5860023498535,21.3163833618164,25.484806060791,25.484806060791,49.5216380929091,5.40544675915872,5.60969018936157,65,1,0,0,1,0.274810791015625,32.7468223571777,2,1,1,21.3163833618164,0,20.951192855835,,,,,,,,,,,,,,,,,,,,,,,,,,,,,,,,,
,3865609043.54108,48.1007080078125,25.484806060791,0.000129610804318155,3.82196601402037E-8,1,5,12.9061126708984,5.00026459114539,46.2700016796589,0.169260791096057,0.0247699426740104,1,-7.22052872401454E-8,,,,,,,,,,,,,,,,,,,,,48.1007080078125,48.1007080078125,25.484806060791,25.484806060791,49.6150427009572,5.39716893884564,6.35454225540161,65,1,0,0,1,0.280838012695313,31.2805480957031,2,1,1,48.1007080078125,0,48.1007080078125,,,,,,,,,,,,,,,,,,,,,,,,,,,,,,,,,
,3865609219.20689,76.0295867919922,25.484806060791,9.90243970301941E-5,2.49082827502575E-8,1,5,12.9061126708984,4.99864138524822,46.3100001215935,0.129262914233151,0.0188874090301048,1,-7.70435555674255E-8,,,,,,,,,,,,,,,,,,,,,76.0295867919922,76.0295867919922,25.484806060791,25.484806060791,49.5646276614668,5.40460069608812,6.67168235778809,65,1,0,0,1,0.273590087890625,30.7917900085449,2,1,1,76.0295867919922,0,76.0295867919922,,,,,,,,,,,,,,,,,,,,,,,,,,,,,,,,,
,3865609391.1161,104.079154968262,25.484806060791,7.70920973537042E-5,2.14600750365618E-8,1,5,12.9061126708984,4.99845288270039,46.3600009679794,0.100628806326775,0.0146975893037339,1,-6.4414208881485E-8,,,,,,,,,,,,,,,,,,,,,104.079154968262,104.079154968262,25.484806060791,25.484806060791,49.5302360066206,5.40439403959216,6.82353639602661,65,1,0,0,1,0.282821655273438,31.2805480957031,2,1,1,104.079154968262,0,104.079154968262,,,,,,,,,,,,,,,,,,,,,,,,,,,,,,,,,
,3865609560.1489,132.021102905273,25.484806060791,5.68413333301586E-5,1.59882840390962E-8,1,5,12.9061126708984,4.99862867995478,46.4299991726875,0.0741998589456022,0.0108315476352303,1,-5.19163657251878E-8,,,,,,,,,,,,,,,,,,,,,132.021102905273,132.021102905273,25.484806060791,25.484806060791,49.5462593912649,5.40520842999226,6.91729164123535,64,1,64,0,0,0.266494750976562,31.2805480957031,2,1,1,132.021102905273,0,132.021102905273,,,,,,,,,,,,,,,,,,,,,,,,,,,,,,,,,
,3865609728.77863,160.009704589844,25.484806060791,4.39881217505092E-5,1.2164846630929E-8,1,5,12.9061126708984,5.00088799211729,46.5199984610081,0.0574596964471773,0.00837479387580914,1,-4.99652113498473E-8,,,,,,,,,,,,,,,,,,,,,160.009704589844,160.009704589844,25.484806060791,25.484806060791,49.504442265486,5.39685357312188,6.99869298934937,65,1,0,0,1,0.279083251953125,31.2805480957031,2,1,1,160.009704589844,0,160.009704589844,,,,,,,,,,,,,,,,,,,,,,,,,,,,,,,,,
,3865609898.86762,188.159729003906,25.484806060791,3.42801413917349E-5,1.0681409910055E-8,1,5,12.9061126708984,5.00222685861674,46.6299988329411,0.0447964472077108,0.00652174817439466,1,-4.44589902574135E-8,,,,,,,,,,,,,,,,,,,,,188.159729003906,188.159729003906,25.484806060791,25.484806060791,49.5353165919956,5.39193626854608,7.07062721252441,64,1,64,0,0,0.278244018554687,31.2805480957031,2,1,1,188.159729003906,0,188.159729003906,,,,,,,,,,,,,,,,,,,,,,,,,,,,,,,,,
,3865610066.50884,216.013137817383,25.484806060791,2.661961484697E-5,9.19354171484482E-9,1,5,12.9061126708984,5.00237289726327,46.7500016093254,0.0347876405581898,0.00506210342003667,1,-3.63969973833262E-8,,,,,,,,,,,,,,,,,,,,,216.013137817383,216.013137817383,25.484806060791,25.484806060791,49.4954535375149,5.38873341890479,7.18201494216919,65,1,0,0,1,0.273971557617187,31.2805480957031,2,1,1,216.013137817383,0,216.013137817383,,,,,,,,,,,,,,,,,,,,,,,,,,,,,,,,,
,3865610235.71861,244.093551635742,25.484806060791,2.1061665949892E-5,7.8986285371059E-9,1,5,12.9061126708984,5.00400330075053,46.8900017440319,0.0275361151297923,0.00401191017539919,1,-2.50464252227847E-8,,,,,,,,,,,,,,,,,,,,,244.093551635742,244.093551635742,25.484806060791,25.484806060791,49.4215896424475,5.38524946788277,7.48967409133911,65,1,0,0,1,0.269546508789062,31.2805480957031,2,1,1,244.093551635742,0,244.093551635742,,,,,,,,,,,,,,,,,,,,,,,,,,,,,,,,,
,3865610404.29098,272.029998779297,25.484806060791,1.68823951940151E-5,8.38900479032186E-9,1,5,12.9061126708984,5.00542072442625,47.0299981534481,0.0220810934358112,0.00321556306863575,1,-2.12523438124348E-8,,,,,,,,,,,,,,,,,,,,,272.029998779297,272.029998779297,25.484806060791,25.484806060791,49.4614526969283,5.38009611260356,7.93254709243774,64,1,64,0,0,0.2716064453125,31.2805480957031,2,1,1,272.029998779297,0,272.029998779297,,,,,,,,,,,,,,,,,,,,,,,,,,,,,,,,,
,3865610654.04298,299.944641113281,25.484806060791,1.35696598502382E-5,7.15047164152674E-9,1,5,12.9061126708984,5.00624691536679,47.189999371767,0.0177534757961821,0.00257749892466552,1,-2.29610065564209E-8,,,,,,,,,,,,,,,,,,,,,299.944641113281,299.944641113281,25.484806060791,25.484806060791,49.4692689821206,5.37677834642208,7.60484266281128,65,1,0,0,1,0.27801513671875,32.2580642700195,1,1,1,299.944641113281,0,299.944641113281,,,,,,,,,,,,,,,,,,,,,,,,,,,,,,,,,
,3865611337.79395,273.971130371094,25.4597358703613,1.90528719776016E-5,7.16540393043015E-9,1,5,12.9061126708984,4.9862543850092,47.0499992370605,0.0247855763932261,0.0036143142342889,1,-2.02884885194126E-8,,,,,,,,,,,,,,,,,,,,,273.971130371094,273.971130371094,25.4597358703613,25.4597358703613,49.5181207645726,5.37660902909688,8.43253040313721,65,1,0,0,1,0.268783569335938,30.7917900085449,2,1,1,273.971130371094,0,273.971130371094,,,,,,,,,,,,,,,,,,,,,,,,,,,,,,,,,
,3865611507.59834,245.980682373047,25.4597358703613,2.02941836431853E-5,7.03439585838733E-9,1,5,12.9061126708984,4.98584487510084,46.9300001859665,0.0263992984159965,0.0038359739038828,1,-3.18923440723023E-8,,,,,,,,,,,,,,,,,,,,,245.980682373047,245.980682373047,25.4597358703613,25.4597358703613,49.4692689821206,5.37637358190383,8.17902088165283,64,1,64,0,0,0.272216796875,31.2805480957031,2,1,1,245.980682373047,0,245.980682373047,,,,,,,,,,,,,,,,,,,,,,,,,,,,,,,,,
,3865611676.63143,217.887680053711,25.4597358703613,2.13789409726862E-5,6.70449976198514E-9,1,5,12.9061126708984,4.98501517294143,46.8100011348724,0.0278031706783979,0.00404492430381046,1,-2.98624502093364E-8,,,,,,,,,,,,,,,,,,,,,217.887680053711,217.887680053711,25.4597358703613,25.4597358703613,49.4981892373322,5.38301672185812,8.02963638305664,64,1,64,0,0,0.269851684570313,31.2805480957031,2,1,1,217.887680053711,0,217.887680053711,,,,,,,,,,,,,,,,,,,,,,,,,,,,,,,,,
,3865611844.34772,189.969711303711,25.4597358703613,2.2505510644962E-5,6.6774437022609E-9,1,5,12.9061126708984,4.98434248404246,46.730000525713,0.0292661694850385,0.0042337790158383,1,-4.95029783406807E-8,,,,,,,,,,,,,,,,,,,,,189.969711303711,189.969711303711,25.4597358703613,25.4597358703613,49.4489466406206,5.38298696516606,7.88888549804687,64,1,64,0,0,0.268173217773438,30.7917900085449,2,1,1,189.969711303711,0,189.969711303711,,,,,,,,,,,,,,,,,,,,,,,,,,,,,,,,,
,3865612011.40102,161.990600585938,25.4597358703613,2.35221073444865E-5,7.20490722756989E-9,1,5,12.9061126708984,4.98114063555756,46.62000015378,0.0305560407893853,0.00445167352717606,1,-2.81447283331981E-8,,,,,,,,,,,,,,,,,,,,,161.990600585938,161.990600585938,25.4597358703613,25.4597358703613,49.3582777323898,5.39658362236726,7.77049446105957,64,1,64,0,0,0.276260375976562,31.2805480957031,2,1,1,161.990600585938,0,161.990600585938,,,,,,,,,,,,,,,,,,,,,,,,,,,,,,,,,
,3865612180.06488,133.946228027344,25.4597358703613,2.4038803499975E-5,6.22289328769642E-9,1,5,12.9061126708984,4.98090207328754,46.5399995446205,0.031224713464512,0.00455209065272934,1,-2.65021631555898E-8,,,,,,,,,,,,,,,,,,,,,133.946228027344,133.946228027344,25.4597358703613,25.4597358703613,49.5861224457456,5.39774504638111,7.66328573226929,65,1,0,0,1,0.277099609375,32.2580642700195,2,1,1,133.946228027344,0,133.946228027344,,,,,,,,,,,,,,,,,,,,,,,,,,,,,,,,,
,3865612347.2407,105.986068725586,25.4597358703613,2.38518918788495E-5,5.76226103348155E-9,1,5,12.9061126708984,4.98068937717745,46.4700013399124,0.0309776949730616,0.00453258181106262,1,-1.38548779999873E-8,,,,,,,,,,,,,,,,,,,,,105.986068725586,105.986068725586,25.4597358703613,25.4597358703613,49.4653608395245,5.39651580508432,7.5405969619751,63,1,64,0,0,0.277633666992187,31.2805480957031,2,1,1,105.986068725586,0,105.986068725586,,,,,,,,,,,,,,,,,,,,,,,,,,,,,,,,,
,3865612514.63719,77.9943923950195,25.4597358703613,2.43648806817346E-5,8.03326133470217E-9,1,5,12.9061126708984,4.98071159358055,46.399999409914,0.0316453080046967,0.0046221349412621,1,-2.02817734352199E-8,,,,,,,,,,,,,,,,,,,,,77.9943923950195,77.9943923950195,25.4597358703613,25.4597358703613,49.5443053199668,5.39665488840826,7.38032484054565,65,1,0,0,1,0.276336669921875,30.7917900085449,2,1,1,77.9943923950195,0,77.9943923950195,,,,,,,,,,,,,,,,,,,,,,,,,,,,,,,,,
,3865612678.33608,49.9721603393555,25.4597358703613,2.37269314025815E-5,5.99753042991833E-9,1,5,12.9061126708984,4.98108616043007,46.339999884367,0.0308204085617634,0.00449875455801794,1,-2.19329236345145E-8,,,,,,,,,,,,,,,,,,,,,49.9721603393555,49.9721603393555,25.4597358703613,25.4597358703613,49.5083504080822,5.39543248924425,7.1219596862793,65,1,0,0,1,0.276718139648438,30.3030319213867,2,1,1,49.9721603393555,0,49.9721603393555,,,,,,,,,,,,,,,,,,,,,,,,,,,,,,,,,
,3865612842.71986,21.9648265838623,25.4597358703613,1.80041166915824E-5,1.57441031966287E-8,1,5,12.9061126708984,4.98103977059435,46.28000035882,0.023386195018179,0.00341487334087083,1,-1.56879846007062E-8,,,,,,,,,,,,,,,,,,,,,21.9648265838623,21.9648265838623,25.4597358703613,25.4597358703613,49.5380522918129,5.396315834495,6.49457693099976,65,1,0,0,1,0.276641845703125,31.7693061828613,2,1,1,21.9648265838623,0,21.9648265838623,,,,,,,,,,,,,,,,,,,,,,,,,,,,,,,,,
,3865613474.04372,8.01892471313477,25.4597358703613,2.36708593906966E-6,5.93608594818814E-8,1,5,12.9061126708984,4.97791972039478,46.2599992752075,0.00307205536591307,0.000448096999307198,1,-2.43022045714805E-9,,,,,,,,,,,,,,,,,,,,,8.01892471313477,8.01892471313477,25.4597358703613,25.4597358703613,49.5079595938225,5.40627332528875,4.48396253585815,65,1,0,0,1,0.26885986328125,31.2805480957031,6,1,1,8.01892471313477,0,8.01892471313477,,,,,,,,,,,,,,,,,,,,,,,,,,,,,,,,,
,3865613655.80892,36.1162567138672,25.4597358703613,2.20749648779342E-5,8.13199939710069E-9,1,5,12.9061126708984,4.98346782027675,46.2599992752075,0.0286940418333127,0.0041869422772283,1,-2.14856597418914E-8,,,,,,,,,,,,,,,,,,,,,36.1162567138672,36.1162567138672,25.4597358703613,25.4597358703613,49.4774760815725,5.38706365740655,6.20227003097534,64,1,64,0,0,0.268402099609375,31.2805480957031,2,1,1,36.1162567138672,0,36.1162567138672,,,,,,,,,,,,,,,,,,,,,,,,,,,,,,,,,
,3865613833.83414,64.2291946411133,25.4597358703613,2.42968585188339E-5,5.67357615583492E-9,1,5,12.9061126708984,4.97922103809485,46.289999037981,0.0315429560679493,0.00461223765808684,1,-1.64148406120753E-8,,,,,,,,,,,,,,,,,,,,,64.2291946411133,64.2291946411133,25.4597358703613,25.4597358703613,49.550167533861,5.40294819619244,6.65216112136841,65,1,0,0,1,0.274505615234375,30.7917900085449,2,1,1,64.2291946411133,0,64.2291946411133,,,,,,,,,,,,,,,,,,,,,,,,,,,,,,,,,
,3865614006.39333,92.0003967285156,25.4597358703613,2.39261822829538E-5,5.91111914445537E-9,1,5,12.9061126708984,4.97899739251828,46.339999884367,0.031060269495623,0.00453818883169356,1,-1.8781486373028E-8,,,,,,,,,,,,,,,,,,,,,92.0003967285156,92.0003967285156,25.4597358703613,25.4597358703613,49.4919362091783,5.40353470950294,6.8480110168457,63,1,64,0,0,0.275955200195313,31.2805480957031,2,1,1,92.0003967285156,0,92.0003967285156,,,,,,,,,,,,,,,,,,,,,,,,,,,,,,,,,
,3865614176.55847,120.008659362793,25.4597358703613,2.31490125357163E-5,5.58643426101296E-9,1,5,12.9061126708984,4.9811271453301,46.399999409914,0.0300696050849915,0.00439233262245494,1,-1.90089287820839E-8,,,,,,,,,,,,,,,,,,,,,120.008659362793,120.008659362793,25.4597358703613,25.4597358703613,49.504442265486,5.39546578207972,6.94791316986084,65,1,0,0,1,0.2752685546875,31.7693061828613,2,1,1,120.008659362793,0,120.008659362793,,,,,,,,,,,,,,,,,,,,,,,,,,,,,,,,,
,3865614346.17359,148.124237060547,25.4597358703613,2.21502232776629E-5,6.37996916155204E-9,1,5,12.9061126708984,4.98236580219765,46.4800000190735,0.0287839853918785,0.00419265593580343,1,-2.71429448058029E-8,,,,,,,,,,,,,,,,,,,,,148.124237060547,148.124237060547,25.4597358703613,25.4597358703613,49.5376614775533,5.39331595318205,7.03412628173828,63,1,64,0,0,0.271530151367187,31.7693061828613,2,1,1,148.124237060547,0,148.124237060547,,,,,,,,,,,,,,,,,,,,,,,,,,,,,,,,,
,3865614514.56065,176.013748168945,25.4597358703613,2.0932126752547E-5,6.70231428842908E-9,1,5,12.9061126708984,4.98285360555503,46.5800017118454,0.0272046317430526,0.0039639466779237,1,-2.46419299686082E-8,,,,,,,,,,,,,,,,,,,,,176.013748168945,176.013748168945,25.4597358703613,25.4597358703613,49.4520731546975,5.39001725402493,7.09855318069458,64,1,64,0,0,0.27008056640625,31.2805480957031,2,1,1,176.013748168945,0,176.013748168945,,,,,,,,,,,,,,,,,,,,,,,,,,,,,,,,,
,3865614684.19629,204.023941040039,25.4597358703613,1.96861336386382E-5,6.4923063550454E-9,1,5,12.9061126708984,4.98344704626959,46.6899983584881,0.0255904445876679,0.0037225062123264,1,-2.78755012925467E-8,,,,,,,,,,,,,,,,,,,,,204.023941040039,204.023941040039,25.4597358703613,25.4597358703613,49.5661909185052,5.38791768096832,7.18084859848022,63,1,64,0,0,0.270004272460938,31.2805480957031,2,1,1,204.023941040039,0,204.023941040039,,,,,,,,,,,,,,,,,,,,,,,,,,,,,,,,,
,3865614852.55222,232.000503540039,25.4597358703613,1.8381246897452E-5,5.95010094616202E-9,1,5,12.9061126708984,4.98436637636109,46.8199998140335,0.0239020088486739,0.00346561884795658,1,-3.45229126487273E-8,,,,,,,,,,,,,,,,,,,,,232.000503540039,232.000503540039,25.4597358703613,25.4597358703613,49.428233484861,5.3839734233986,7.35385847091675,65,1,0,0,1,0.272445678710938,31.7693061828613,2,1,1,232.000503540039,0,232.000503540039,,,,,,,,,,,,,,,,,,,,,,,,,,,,,,,,,
,3865615021.80264,260.08464050293,25.4597358703613,1.70449427319952E-5,6.38114138970156E-9,1,5,12.9061126708984,4.9854359791975,46.9699986279011,0.0221715254799747,0.00321127032329923,1,-3.46040184357592E-8,,,,,,,,,,,,,,,,,,,,,260.031036376953,260.138244628906,25.4597358703613,25.4597358703613,49.4184631283706,5.37855211627475,7.6408314704895,64,1,64,0,0,0.269317626953125,31.7693061828613,2,1,1,260.138244628906,0,260.08464050293,,,,,,,,,,,,,,,,,,,,,,,,,,,,,,,,,
,3865615189.67826,288.005920410156,25.4597358703613,1.58972068542649E-5,6.82782300649448E-9,1,5,12.9061126708984,4.98621069246165,47.12999984622,0.0206822478943001,0.00300148994717932,1,-2.781497905091E-8,,,,,,,,,,,,,,,,,,,,,288.005920410156,288.005920410156,25.4597358703613,25.4597358703613,49.4974076088129,5.3772389622083,7.64629364013672,63,1,64,0,0,0.268783569335938,31.7693061828613,2,1,1,288.005920410156,0,288.005920410156,,,,,,,,,,,,,,,,,,,,,,,,,,,,,,,,,
,3865615485.32914,300.003173828125,44860.07421875,0.0162045858310718,4.61765623675653E-6,1,2,12.9061126708984,4.98642884702806,47.189999371767,21.0842513733612,3.05420996550928,100,-3.25834452890143E-5,,,,,,,,,,,,,,,,,,,,,300.003082275391,300.003265380859,44760.34765625,44959.80078125,49.3746919312937,5.37557183238144,7.55663156509399,26,1,0,0,1,0.269088745117187,30.7917900085449,1,6,1,300.003082275391,0,300.003173828125,,,,,,,,,,,,,,,,,,,,,,,,,,,,,,,,,
,3865615547.76043,300.004150390625,38625.533203125,0.0139729400098601,4.81399038171477E-6,1,2,12.9061126708984,4.98644222674633,47.189999371767,18.179891823935,2.63884251243124,100,-2.40684401878409E-5,,,,,,,,,,,,,,,,,,,,,300.003997802734,300.004302978516,38530.70703125,38720.359375,49.3703929744379,5.37533414211783,7.59021759033203,25,1,68,0,0,0.277252197265625,30.7917900085449,1,6,1,300.004302978516,0,300.004150390625,,,,,,,,,,,,,,,,,,,,,,,,,,,,,,,,,
,3865615610.58052,300.002944946289,32354.8994140625,0.0117428320056331,4.1900368800794E-6,1,2,12.9061126708984,4.98645411445005,47.189999371767,15.277808274415,2.22169568220157,100,-1.7144190998613E-5,,,,,,,,,,,,,,,,,,,,,300.002868652344,300.003021240234,32290.015625,32419.783203125,49.4196355711495,5.37549911163202,7.65304756164551,26,1,0,0,1,0.2777099609375,31.2805480957031,1,6,1,300.003021240234,0,300.002944946289,,,,,,,,,,,,,,,,,,,,,,,,,,,,,,,,,
,3865615668.64393,300.00260925293,26555.23828125,0.00965234652411708,3.82991391489358E-6,1,2,12.9061126708984,4.98644590108871,47.189999371767,12.5585005943567,1.82269976594476,100,-1.67678351337677E-5,,,,,,,,,,,,,,,,,,,,,300.002502441406,300.002716064453,26460.55078125,26649.92578125,49.4086927718802,5.37572433673093,7.7372841835022,26,1,0,0,1,0.267791748046875,30.7917900085449,1,6,1,300.002502441406,0,300.00260925293,,,,,,,,,,,,,,,,,,,,,,,,,,,,,,,,,
,3865615729.10771,300.002731323242,20519.939453125,0.00749645013577924,4.12582238170259E-6,1,2,12.9061126708984,4.98647501667025,47.189999371767,9.7541558361372,1.41169134736524,100,-1.60298038861581E-5,,,,,,,,,,,,,,,,,,,,,300.002593994141,300.002868652344,20420.125,20619.75390625,49.4907637663995,5.37565364580145,7.85619354248047,26,1,0,0,1,0.2789306640625,31.2805480957031,1,6,1,300.002593994141,0,300.002731323242,,,,,,,,,,,,,,,,,,,,,,,,,,,,,,,,,
,3865615787.72679,300.001419067383,14669.6025390625,0.00540550628478475,3.91678038913282E-6,1,2,12.9061126708984,4.98651793075745,47.189999371767,7.03364746291694,1.01740387002845,100,-1.19772405524007E-5,,,,,,,,,,,,,,,,,,,,,300.0009765625,300.001861572266,14549.84375,14789.361328125,49.4813842241687,5.37539640802844,7.98738288879395,26,1,0,0,1,0.26763916015625,31.2805480957031,1,6,1,300.001861572266,0,300.001419067383,,,,,,,,,,,,,,,,,,,,,,,,,,,,,,,,,
,3865615845.16133,300.000793457031,8930.78271484375,0.0033122235419365,3.825824422935E-6,1,2,12.9061126708984,4.98651847832863,47.189999371767,4.31063530970633,0.618188437435811,100,-1.13564960447423E-5,,,,,,,,,,,,,,,,,,,,,300.000762939453,300.000823974609,8765.958984375,9095.6064453125,49.4884188808418,5.3752878171909,8.14089965820312,26,1,0,0,1,0.267486572265625,31.2805480957031,1,6,1,300.000823974609,0,300.000793457031,,,,,,,,,,,,,,,,,,,,,,,,,,,,,,,,,
,3865615906.46671,300.000732421875,2804.67639160156,0.00113237950902166,3.81310620491806E-6,1,2,12.9061126708984,4.98653157258715,47.189999371767,1.47673229827305,0.190848348391905,100,-1.96407940735279E-5,,,,,,,,,,,,,,,,,,,,,300.000640869141,300.000823974609,2719.84204101562,2889.5107421875,49.4544180402552,5.37536618157054,8.29885959625244,26,1,0,0,1,0.278167724609375,30.7917900085449,1,6,1,300.000640869141,0,300.000732421875,,,,,,,,,,,,,,,,,,,,,,,,,,,,,,,,,
,3865615974.8569,300.000854492188,-4027.07592773438,-0.00157511723794187,4.76165217535888E-6,1,2,12.9061126708984,4.98652250453342,47.189999371767,-2.04756733005923,-0.309931278424428,100,-6.86397309918879E-6,,,,,,,,,,,,,,,,,,,,,300.000701904297,300.001007080078,-4117.0185546875,-3937.13330078125,49.4532455974764,5.3756624918132,8.47464942932129,26,1,0,0,1,0.267868041992187,31.2805480957031,1,6,1,300.001007080078,0,300.000854492188,,,,,,,,,,,,,,,,,,,,,,,,,,,,,,,,,
,3865616039.3335,299.999526977539,-10476.0297851562,-0.0038933197550004,3.957130817481E-6,1,2,12.9061126708984,4.98652792220982,47.189999371767,-5.06451250747282,-0.742939285300723,10,8.22563805189033E-7,,,,,,,,,,,,,,,,,,,,,299.999359130859,299.999694824219,-10566.00390625,-10386.0556640625,49.4876372523225,5.3756222396766,8.66285705566406,26,1,0,0,1,0.269699096679687,32.2580642700195,1,6,1,299.999359130859,0,299.999526977539,,,,,,,,,,,,,,,,,,,,,,,,,,,,,,,,,
,3865616124.16921,300.001876831055,-18962.1376953125,-0.00692770525183223,4.20468432511201E-6,1,2,12.9061126708984,4.98640862400367,47.189999371767,-9.01283861873081,-1.31215297769352,100,8.97925051626948E-6,,,,,,,,,,,,,,,,,,,,,300.001556396484,300.002197265625,-19077.126953125,-18847.1484375,49.4215896424475,5.37514931075741,8.85843086242676,26,1,0,0,1,0.267868041992187,30.7917900085449,1,6,1,300.001556396484,0,300.001876831055,,,,,,,,,,,,,,,,,,,,,,,,,,,,,,,,,
,3865616182.36605,299.999954223633,-24782.3642578125,-0.00902153718045081,4.44144596733851E-6,1,2,12.9061126708984,4.986488648256,47.189999371767,-11.7378004113356,-1.70432568420953,100,1.51152428629793E-5,,,,,,,,,,,,,,,,,,,,,299.999755859375,300.000152587891,-24877.208984375,-24687.51953125,49.4606710684091,5.37515428520481,8.82214641571045,26,1,0,0,1,0.2679443359375,32.7468223571777,1,6,1,299.999755859375,0,299.999954223633,,,,,,,,,,,,,,,,,,,,,,,,,,,,,,,,,
,3865616243.12822,300.001007080078,-30866.791015625,-0.0111851809869357,4.68430069762506E-6,1,2,12.9061126708984,4.9864852718943,47.189999371767,-14.5510048515739,-2.12579919564166,100,8.95727472974351E-6,,,,,,,,,,,,,,,,,,,,,300.000885009766,300.001129150391,-30987.107421875,-30746.474609375,49.5056147082649,5.37520987152366,8.77007389068604,26,1,0,0,1,0.2691650390625,31.7693061828613,1,6,1,300.001129150391,0,300.001007080078,,,,,,,,,,,,,,,,,,,,,,,,,,,,,,,,,
,3865616305.48849,299.999862670898,-37113.525390625,-0.0134250476100428,4.14301937892958E-6,1,2,12.9061126708984,4.98644613277118,47.189999371767,-17.4648845485744,-2.55018182411965,100,1.17404431611487E-5,,,,,,,,,,,,,,,,,,,,,299.999816894531,299.999908447266,-37228.87890625,-36998.171875,49.3973591583514,5.37458285950182,8.73811531066895,26,1,0,0,1,0.269012451171875,31.7693061828613,1,6,1,299.999816894531,0,299.999862670898,,,,,,,,,,,,,,,,,,,,,,,,,,,,,,,,,
,3865616367.80392,300.000106811523,-43359.5546875,-0.0156644376789368,4.2643947324702E-6,1,2,12.9061126708984,4.98641498230997,47.189999371767,-20.3773536453433,-2.97972788846184,100,1.0481936498288E-5,,,,,,,,,,,,,,,,,,,,,299.999908447266,300.000305175781,-43459.65625,-43259.453125,49.3844622877841,5.37434653141452,8.7094144821167,26,1,0,0,1,0.26885986328125,31.7693061828613,1,6,1,300.000305175781,0,300.000106811523,,,,,,,,,,,,,,,,,,,,,,,,,,,,,,,,,
,3865616430.13777,299.99934387207,-49605.556640625,-0.0178958238485385,4.0629098844219E-6,1,2,12.9061126708984,4.98646805582426,47.189999371767,-23.2799213787752,-3.40776022701945,100,9.26766942291511E-6,,,,,,,,,,,,,,,,,,,,,299.999298095703,299.999389648438,-49700.73828125,-49510.375,49.3805541451879,5.37421865178553,8.6754322052002,24,1,68,0,0,0.266952514648438,31.7693061828613,1,6,1,299.999298095703,0,299.99934387207,,,,,,,,,,,,,,,,,,,,,,,,,,,,,,,,,
,3865616490.56034,300.000015258789,-45115.517578125,-0.016310458156204,4.53859493316037E-6,1,2,12.9061126708984,4.9864417739565,47.189999371767,-21.2227886400331,-3.06936681661057,100,3.64933963697334E-5,,,,,,,,,,,,,,,,,,,,,299.999694824219,300.000335693359,-45210.375,-45020.66015625,49.3743011170341,5.3744599659327,8.65893650054932,26,1,0,0,1,0.268402099609375,31.7693061828613,1,6,1,299.999694824219,0,300.000015258789,,,,,,,,,,,,,,,,,,,,,,,,,,,,,,,,,
,3865616552.33183,300.001388549805,-38947.546875,-0.0140752471066302,4.22733619377869E-6,1,2,12.9061126708984,4.98626819171227,47.189999371767,-18.3129493946298,-2.65227760376148,100,2.86697974930694E-5,,,,,,,,,,,,,,,,,,,,,300.0009765625,300.001800537109,-39112.30859375,-38782.78515625,49.4950627232552,5.3747274118691,8.64149856567383,24,1,68,0,0,0.27099609375,31.7693061828613,1,6,1,300.0009765625,0,300.001388549805,,,,,,,,,,,,,,,,,,,,,,,,,,,,,,,,,
,3865616613.64322,300.000411987305,-32828.8056640625,-0.0119170211812601,4.47110168599533E-6,1,2,12.9061126708984,4.98630629546925,47.189999371767,-15.5046067805599,-2.24898878773307,100,2.16799773067466E-5,,,,,,,,,,,,,,,,,,,,,300.000305175781,300.000518798828,-32903.60546875,-32754.005859375,49.4981892373322,5.37511100924174,8.62254428863525,26,1,0,0,1,0.26885986328125,31.7693061828613,1,6,1,300.000305175781,0,300.000411987305,,,,,,,,,,,,,,,,,,,,,,,,,,,,,,,,,
,3865616673.9977,300.000762939453,-26805.3857421875,-0.00975765311049162,4.5352692586251E-6,1,2,12.9061126708984,4.98634657581849,47.189999371767,-12.6952569867903,-1.84186028822618,100,1.7468558805197E-5,,,,,,,,,,,,,,,,,,,,,300.000610351562,300.000915527344,-26905.17578125,-26705.595703125,49.4493374548802,5.37505851769123,8.60349559783935,26,1,0,0,1,0.268630981445313,31.2805480957031,1,6,1,300.000610351562,0,300.000762939453,,,,,,,,,,,,,,,,,,,,,,,,,,,,,,,,,
,3865616733.62904,300.000381469727,-20850.740234375,-0.00759259293773057,4.1101864277241E-6,1,2,12.9061126708984,4.98636893007429,47.189999371767,-9.8783548769874,-1.43386459837459,100,1.30749364637422E-5,,,,,,,,,,,,,,,,,,,,,299.999969482422,300.000793457031,-21015.388671875,-20686.091796875,49.4852923667649,5.37521492660825,8.59210205078125,26,1,0,0,1,0.26763916015625,31.2805480957031,1,6,1,300.000793457031,0,300.000381469727,,,,,,,,,,,,,,,,,,,,,,,,,,,,,,,,,
,3865616798.7867,299.998428344727,-14347.5336914062,-0.00528770186155903,4.170767858175E-6,1,2,12.9061126708984,4.98635949922894,47.189999371767,-6.87998081028757,-0.995680244462146,100,1.13368255123617E-5,,,,,,,,,,,,,,,,,,,,,299.998321533203,299.99853515625,-14437.3134765625,-14257.75390625,49.463797582486,5.37534997895308,8.57897281646729,26,1,0,0,1,0.268173217773438,31.7693061828613,1,6,1,299.998321533203,0,299.998428344727,,,,,,,,,,,,,,,,,,,,,,,,,,,,,,,,,
,3865616859.60491,299.999481201172,-8268.9423828125,-0.00311929216456375,3.73783534659235E-6,1,2,12.9061126708984,4.98635668138128,47.189999371767,-4.05959255478634,-0.580592140509281,100,1.1895372628137E-5,,,,,,,,,,,,,,,,,,,,,299.999298095703,299.999664306641,-8323.75390625,-8214.130859375,49.4579353685918,5.37541528169354,8.57270526885986,26,1,0,0,1,0.268096923828125,30.3030319213867,1,6,1,299.999664306641,0,299.999481201172,,,,,,,,,,,,,,,,,,,,,,,,,,,,,,,,,
,3865616917.77154,300.001129150391,-2458.80126953125,-0.00100728416800248,4.23488770499198E-6,1,2,12.9061126708984,4.98636750014005,47.189999371767,-1.31339449408329,-0.170714956228495,100,1.67347675323934E-5,,,,,,,,,,,,,,,,,,,,,300.001037597656,300.001220703125,-2558.6845703125,-2358.91796875,49.514603436236,5.37527425714154,8.56595897674561,25,1,68,0,0,0.2679443359375,31.2805480957031,1,6,1,300.001220703125,0,300.001129150391,,,,,,,,,,,,,,,,,,,,,,,,,,,,,,,,,
,3865616984.27598,300.000885009766,4189.12939453125,0.00162935556345183,4.4287271921827E-6,1,2,12.9061126708984,4.98635720358401,47.189999371767,2.11823420849195,0.318828528974011,100,5.74712115488193E-6,,,,,,,,,,,,,,,,,,,,,300.000885009766,300.000885009766,4109.08349609375,4269.17529296875,49.5357074062552,5.3754205643487,8.54966259002686,26,1,0,0,1,0.268096923828125,31.2805480957031,1,6,1,300.000885009766,0,300.000885009766,,,,,,,,,,,,,,,,,,,,,,,,,,,,,,,,,
,3865617052.64876,300.000427246094,11024.0786132813,0.00409730782516121,3.9997333053219E-6,1,2,12.9061126708984,4.98637175034252,47.189999371767,5.33004007036922,0.779040030864767,10,-3.01116744159505E-6,,,,,,,,,,,,,,,,,,,,,300.000091552734,300.000762939453,10928.9208984375,11119.236328125,49.4372222128321,5.37532538273815,8.53999996185303,26,1,0,0,1,0.268096923828125,32.7468223571777,1,6,1,300.000091552734,0,300.000427246094,,,,,,,,,,,,,,,,,,,,,,,,,,,,,,,,,
,3865617121.31008,300.00114440918,17894.7158203125,0.00655437833499869,4.41398675778828E-6,1,2,12.9061126708984,4.98636250972096,47.189999371767,8.52631131738118,1.24635407945985,10,-4.70685122542273E-6,,,,,,,,,,,,,,,,,,,,,300.001129150391,300.001159667969,17819.521484375,17969.91015625,49.4110376574379,5.37530820097847,8.53578472137451,25,1,68,0,0,0.269317626953125,31.7693061828613,1,6,1,300.001159667969,0,300.00114440918,,,,,,,,,,,,,,,,,,,,,,,,,,,,,,,,,
,3865617191.81705,299.999496459961,24946.4365234375,0.00908851283196472,4.40079361037557E-6,1,2,12.9061126708984,4.98640188209018,47.189999371767,11.8238286231417,1.72254518656999,100,-1.09155957369078E-5,,,,,,,,,,,,,,,,,,,,,299.9990234375,299.999969482422,24831.478515625,25061.39453125,49.4747403817552,5.37543726558705,8.52519035339356,26,1,0,0,1,0.267868041992187,30.7917900085449,1,6,1,299.999969482422,0,299.999496459961,,,,,,,,,,,,,,,,,,,,,,,,,,,,,,,,,
,3865617254.21717,300.000045776367,31197.3759765625,0.0113269553752783,3.98955845604756E-6,1,2,12.9061126708984,4.98639683688863,47.189999371767,14.7358501130686,2.14741265640267,100,-1.31284089374725E-5,,,,,,,,,,,,,,,,,,,,,299.999633789063,300.000457763672,31092.177734375,31302.57421875,49.4911545806591,5.37499661257822,8.52167987823486,26,1,0,0,1,0.268096923828125,31.7693061828613,1,6,1,300.000457763672,0,300.000045776367,,,,,,,,,,,,,,,,,,,,,,,,,,,,,,,,,
,3865617316.52225,299.999038696289,37441.099609375,0.0135706011223915,4.27696679547294E-6,1,2,12.9061126708984,4.98639619185487,47.189999371767,17.6542751073382,2.57584983269177,100,-1.33627704136753E-5,,,,,,,,,,,,,,,,,,,,,299.998901367188,299.999176025391,37345.921875,37536.27734375,49.4020489294668,5.37497632876185,8.51468944549561,26,1,0,0,1,0.2685546875,31.2805480957031,1,6,1,299.999176025391,0,299.999038696289,,,,,,,,,,,,,,,,,,,,,,,,,,,,,,,,,
,3865617373.21274,300.000259399414,43122.431640625,0.0155916701730093,4.46804275757879E-6,1,2,12.9061126708984,4.98637985295425,47.189999371767,20.2830347166529,2.96216314513579,100,-1.32727236422056E-5,,,,,,,,,,,,,,,,,,,,,300.000091552734,300.000427246094,43007.375,43237.48828125,49.4208080139283,5.37479415519669,8.50726699829102,26,1,0,0,1,0.268173217773438,31.2805480957031,1,6,1,300.000427246094,0,300.000259399414,,,,,,,,,,,,,,,,,,,,,,,,,,,,,,,,,
,3865617433.39417,300.000411987305,49155.0859375,0.0177596135771278,4.09361046349295E-6,1,2,12.9061126708984,4.9863933077763,47.189999371767,23.1028116493882,3.37789356460865,100,-1.21631755783401E-5,,,,,,,,,,,,,,,,,,,,,300.000366210937,300.000457763672,49059.734375,49250.4375,49.3981407868706,5.37474108685409,8.50297451019287,26,1,0,0,1,0.26763916015625,31.7693061828613,1,6,1,300.000366210937,0,300.000411987305,,,,,,,,,,,,,,,,,,,,,,,,,,,,,,,,,
,3865617443.89749,300.000259399414,50000.46484375,0.0180684301344189,8.61503715458592E-7,1,2,12.9061126708984,4.98640672317228,47.189999371767,23.5045237392782,3.43735523103182,100,-1.18276708841374E-5,,,,,,,,,,,,,,,,,,,,,300.000122070313,300.000396728516,50000.4296875,50000.5,49.3727378599956,5.37480018999583,8.5069408416748,26,1,0,0,1,0.26824951171875,30.7917900085449,1,4,1,300.000396728516,0,300.000259399414,,,,,,,,,,,,,,,,,,,,,,,,,,,,,,,,,