File: LT data/Bridport/Wareham W1/430-FC-ZFC-2.5T-2K-100K.dat
[Header]
; MPMS3 Data File (default extension .dat)
; Copyright (c) 2007, Quantum Design, Inc. All rights reserved.
TITLE,
FILEOPENTIME,3865654207.71958,06/29/2022,9:47 am
BYAPP,MPMS3 w/ AC,1.0,1.1
INFO,MPMS3 Measurement Release 1.1.16 Build 424, MultiVu Release 2.3.4.19,APPNAME
INFO,Linear Motor Servo Controller,MOTOR_MODULE_NAME
INFO,3101-100 N2,MOTOR_HW_VERSION
INFO,,MOTOR_SERIAL_NUMBER
INFO,01.04.28,MOTOR_SOFTWARE_VERSION
INFO,Quantum Design Squid Module,SQUID_MODULE_NAME
INFO,3101-501 B0,SQUID_HW_VERSION
INFO,SQM327,SQUID_SERIAL_NUMBER
INFO,01.03.04,SQUID_SOFTWARE_VERSION
INFO,Quantum Design VSM Oven,OVEN_MODULE_NAME
INFO,3101-201 A3,OVEN_HW_VERSION
INFO,OVB365,OVEN_SERIAL_NUMBER
INFO,01.07.07,OVEN_SOFTWARE_VERSION
INFO,SQUID AC,AC_MODULE_NAME
INFO,3101-401 G0,AC_HW_VERSION
INFO,SAC220,AC_SERIAL_NUMBER
INFO,SQUID AC 00.95.07,AC_SOFTWARE_VERSION
INFO,TCI344,COIL_SERIAL_NUMBER
INFO,0,MOMENT_UNITS
INFO,oil stained sst,SAMPLE_MATERIAL
INFO,,SAMPLE_COMMENT
INFO,276.83,SAMPLE_MASS
INFO,,SAMPLE_VOLUME
INFO,,SAMPLE_MOLECULAR_WEIGHT
INFO,,SAMPLE_SIZE
INFO,,SAMPLE_SHAPE
INFO,Straw,SAMPLE_HOLDER
INFO,Standard,SAMPLE_HOLDER_DETAIL
INFO,60.35,SAMPLE_OFFSET
DATATYPE,COMMENT,1
DATATYPE,TIME,2
STARTUPAXIS,X,2
STARTUPAXIS,Y1,5
FIELDGROUP, VSM,2,3,4,5,6,8,9,10,11,14,15
FIELDGROUP, DC, 2,3,4,14,56,57,58,59,60,61,62,63,64,65,66,67,68,69
FIELDGROUP, AC, 2,3,4,11,16,17,18,19,20,21,22,23,24,25,26,27,28,29,30
STARTUPGROUP, All
[Data]
Comment,Time Stamp (sec),Temperature (K),Magnetic Field (Oe),Moment (emu),M. Std. Err. (emu),Transport Action,Averaging Time (sec),Frequency (Hz),Peak Amplitude (mm),Center Position (mm),Lockin Signal' (V),Lockin Signal (V),Range,M. Quad. Signal (emu),AC Moment (emu),AC M. Std Err. (emu),AC Phase (deg),AC Phase Std. Err. (deg),AC Susceptibility (emu/Oe),AC Suscept. Std Err. (emu/Oe),AC X' (emu/Oe),AC X' Std Err. (emu/Oe),AC X'' (emu/Oe),AC X'' Std Err. (emu/Oe),AC Drive (Oe),AC Frequency (Hz),AC Averaging Time (sec),AC Cycles,AC Range,AC Measure Type,AC Signal' (V),AC Signal'' (V),AC Trim Coil Ratio,AC Trim Coil Phase,Min. Temperature (K),Max. Temperature (K),Min. Field (Oe),Max. Field (Oe),Mass (grams),Motor Lag (deg),Pressure (Torr),Measure Count,Measurement Number,SQUID Status (code),Motor Status (code),Measure Status (code),Motor Current (amps),Motor Temp. (C),Temp. Status (code),Field Status (code),Chamber Status (code),Chamber Temp (K),Redirection State,Average Temp (K),Rotation Angle (deg),Rotator state,DC Moment Fixed Ctr (emu),DC Moment Err Fixed Ctr (emu),DC Moment Free Ctr (emu),DC Moment Err Free Ctr (emu),DC Fixed Fit,DC Free Fit,DC Calculated Center (mm),DC Calculated Center Err (mm),DC Scan Length (mm),DC Scan Time (s),DC Number of Points,DC Squid Drift,DC Min V (V),DC Max V (V),DC Scans per Measure,Map 01,Map 02,Map 03,Map 04,Map 05,Map 06,Map 07,Map 08,Map 09,Map 10,Map 11,Map 12,Map 13,Map 14,Map 15,Map 16
,3865656082.03359,1.99932372570038,25.4471988677979,0.00786364105595706,5.28697510394934E-7,1,5,12.9061126708984,4.98101713495471,46.2500005960464,10.2138015450735,1.49490170810176,100,-4.2339704614293E-6,,,,,,,,,,,,,,,,,,,,,1.99932372570038,1.99932372570038,25.4471988677979,25.4471988677979,49.5028790084476,5.3951924114528,2.51685237884521,65,1,0,0,1,0.27679443359375,30.7917900085449,1,1,1,1.99932372570038,0,1.99932372570038,,,,,,,,,,,,,,,,,,,,,,,,,,,,,,,,,
,3865656092.02166,3.08157634735107,25.4471988677979,0.00746958666174991,4.36237597810662E-5,1,5,12.9061126708984,4.98096641496928,46.2500005960464,9.70151213403472,1.42219905261816,100,-2.30584228151267E-6,,,,,,,,,,,,,,,,,,,,,3.08157634735107,3.08157634735107,25.4471988677979,25.4471988677979,49.5235921642072,5.39554846555958,2.97427034378052,65,1,0,0,1,0.274734497070313,30.7917900085449,6,1,1,3.08157634735107,0,3.08157634735107,,,,,,,,,,,,,,,,,,,,,,,,,,,,,,,,,
,3865656106.25339,5.01172733306885,25.4471988677979,0.00338927057729781,4.77123648848618E-5,1,5,12.9061126708984,4.98095730144679,46.2500005960464,4.40192000379292,0.645713694036901,100,-7.36046237302079E-7,,,,,,,,,,,,,,,,,,,,,5.01172733306885,5.01172733306885,25.4471988677979,25.4471988677979,49.4372222128321,5.39490515284739,3.67029190063477,65,1,0,0,1,0.27618408203125,30.7917900085449,6,1,1,5.01172733306885,0,5.01172733306885,,,,,,,,,,,,,,,,,,,,,,,,,,,,,,,,,
,3865656130.51592,8.58937835693359,25.4471988677979,0.000928933728806889,5.30132720796599E-6,1,5,12.9061126708984,4.98086204125765,46.2500005960464,1.20634514022172,0.17767973188008,10,3.42509403536336E-7,,,,,,,,,,,,,,,,,,,,,8.58937835693359,8.58937835693359,25.4471988677979,25.4471988677979,49.6541241269187,5.39531992753544,4.49753856658936,65,1,0,0,1,0.27679443359375,30.3030319213867,6,1,1,8.58937835693359,0,8.58937835693359,,,,,,,,,,,,,,,,,,,,,,,,,,,,,,,,,
,3865656139.36882,9.91696071624756,25.4471988677979,0.000599775290429036,2.53481793442121E-6,1,5,12.9061126708984,4.98077587338693,46.2500005960464,0.778895157989931,0.11454516123361,10,8.81374387446352E-8,,,,,,,,,,,,,,,,,,,,,9.57319641113281,10.2607250213623,25.4471988677979,25.4471988677979,49.5357074062552,5.39561705672604,4.7756814956665,65,1,0,0,1,0.278701782226562,30.7917900085449,6,1,1,10.2607250213623,0,9.91696071624756,,,,,,,,,,,,,,,,,,,,,,,,,,,,,,,,,
,3865656149.40159,11.4473037719727,25.4471988677979,0.000479245779665324,1.623354792979E-6,1,5,12.9061126708984,4.98058391213085,46.2500005960464,0.62234668595117,0.091451416804339,10,1.64874440187884E-8,,,,,,,,,,,,,,,,,,,,,11.0559005737305,11.8387069702148,25.4471988677979,25.4471988677979,49.5200748358706,5.39650437833325,4.97700214385986,65,1,0,0,1,0.277481079101562,30.7917900085449,6,1,1,11.8387069702148,0,11.4473037719727,,,,,,,,,,,,,,,,,,,,,,,,,,,,,,,,,
,3865656160.79122,13.1640419960022,25.4471988677979,0.000401051063915088,1.07008213229778E-6,1,5,12.9061126708984,4.98035005798373,46.2500005960464,0.520774267769953,0.0764888164078731,10,-1.40417740985293E-8,,,,,,,,,,,,,,,,,,,,,13.0094318389893,13.3186521530151,25.4471988677979,25.4471988677979,49.5337533349572,5.39713114817148,5.14282369613647,65,1,0,0,1,0.276336669921875,30.7917900085449,6,1,1,13.3186521530151,0,13.1640419960022,,,,,,,,,,,,,,,,,,,,,,,,,,,,,,,,,
,3865656173.08438,15.0086040496826,25.4471988677979,0.000348302864046731,7.42204060656175E-7,1,5,12.9061126708984,4.98021300487825,46.2500005960464,0.452264429288592,0.0664094409867914,10,-2.49959012166921E-8,,,,,,,,,,,,,,,,,,,,,15.0086040496826,15.0086040496826,25.4471988677979,25.4471988677979,49.4665332823033,5.39770578570731,5.3110089302063,65,1,0,0,1,0.278244018554687,31.2805480957031,6,1,1,15.0086040496826,0,15.0086040496826,,,,,,,,,,,,,,,,,,,,,,,,,,,,,,,,,
,3865656195.34484,18.5706558227539,25.4471988677979,0.000281135975113335,4.0609099981883E-7,1,5,12.9061126708984,4.98048040799655,46.2500005960464,0.365052134814371,0.0537769951889263,1,1.10688611410508E-7,,,,,,,,,,,,,,,,,,,,,18.5224628448486,18.6188488006592,25.4471988677979,25.4471988677979,49.4712230534187,5.39632345421672,5.58354711532593,65,1,0,0,1,0.278778076171875,34.7018585205078,2,1,1,18.6188488006592,0,18.5706558227539,,,,,,,,,,,,,,,,,,,,,,,,,,,,,,,,,
,3865656205.44205,20.1466550827026,25.4471988677979,0.000251536701837282,2.81152808617291E-7,1,5,12.9061126708984,4.98045713569788,46.2500005960464,0.326623899274735,0.0480585810771524,1,5.57470805939744E-8,,,,,,,,,,,,,,,,,,,,,19.758020401001,20.5352897644043,25.4471988677979,25.4471988677979,49.6310660856014,5.39663905343561,5.69888925552368,65,1,0,0,1,0.277938842773438,31.7693061828613,2,1,1,20.5352897644043,0,20.1466550827026,,,,,,,,,,,,,,,,,,,,,,,,,,,,,,,,,
,3865656214.85254,21.5719175338745,25.4471988677979,0.000236595910357023,2.30093546785825E-7,1,5,12.9061126708984,4.98069710949839,46.2500005960464,0.307245605616491,0.0451953462606716,1,4.34182975544502E-8,,,,,,,,,,,,,,,,,,,,,21.1974258422852,21.9464092254639,25.4471988677979,25.4471988677979,49.5067871510437,5.39564925960195,5.78199338912964,65,1,0,0,1,0.275650024414062,30.7917900085449,2,1,1,21.9464092254639,0,21.5719175338745,,,,,,,,,,,,,,,,,,,,,,,,,,,,,,,,,
,3865656225.64358,23.2445020675659,25.4471988677979,0.000224260654591836,1.93201833513395E-7,1,5,12.9061126708984,4.98092591844197,46.2500005960464,0.291247969523759,0.0428266011602642,1,2.94588035248133E-8,,,,,,,,,,,,,,,,,,,,,23.0013771057129,23.4876270294189,25.4471988677979,25.4471988677979,49.3871979876014,5.39510797288904,5.84056186676025,65,1,0,0,1,0.275421142578125,30.7917900085449,2,1,1,23.4876270294189,0,23.2445020675659,,,,,,,,,,,,,,,,,,,,,,,,,,,,,,,,,
,3865656237.06938,25.0744132995605,25.4471988677979,0.000213931216466552,1.60047857343593E-7,1,5,12.9061126708984,4.98122147945622,46.2500005960464,0.2778572245158,0.0408509428690188,1,2.31172159091237E-8,,,,,,,,,,,,,,,,,,,,,25.0241432189941,25.124683380127,25.4471988677979,25.4471988677979,49.5470410197841,5.39406313994234,5.91382026672363,65,1,0,0,1,0.27191162109375,31.2805480957031,2,1,1,25.124683380127,0,25.0744132995605,,,,,,,,,,,,,,,,,,,,,,,,,,,,,,,,,
,3865656249.46466,27.0065746307373,25.4471988677979,0.000205209231222174,1.36282805279604E-7,1,5,12.9061126708984,4.98177217468653,46.2500005960464,0.266577106013123,0.0391458344825664,1,-1.30074966801849E-8,,,,,,,,,,,,,,,,,,,,,27.0065746307373,27.0065746307373,25.4471988677979,25.4471988677979,49.5638460329476,5.39264983944523,5.98001766204834,65,1,0,0,1,0.2716064453125,31.7693061828613,2,1,1,27.0065746307373,0,27.0065746307373,,,,,,,,,,,,,,,,,,,,,,,,,,,,,,,,,
,3865656262.97102,29.0037822723389,25.4471988677979,0.000194294848332586,1.11268955996572E-7,1,5,12.9061126708984,4.98173561661201,46.2500005960464,0.252398393001219,0.0370482911555943,1,-2.39604784548191E-8,,,,,,,,,,,,,,,,,,,,,29.0037822723389,29.0037822723389,25.4471988677979,25.4471988677979,49.5943295451976,5.39286408294627,6.03272247314453,65,1,0,0,1,0.273056030273438,31.2805480957031,2,1,1,29.0037822723389,0,29.0037822723389,,,,,,,,,,,,,,,,,,,,,,,,,,,,,,,,,
,3865656275.83659,31.0522556304932,25.4471988677979,0.000188162441133286,9.93730255478504E-8,1,5,12.9061126708984,4.98205315990957,46.2500005960464,0.244460015232686,0.035841219261282,1,-5.47282733066185E-8,,,,,,,,,,,,,,,,,,,,,31.0522556304932,31.0522556304932,25.4471988677979,25.4471988677979,49.4622343254475,5.39198813900956,6.10143375396729,65,1,0,0,1,0.271377563476562,31.2805480957031,2,1,1,31.0522556304932,0,31.0522556304932,,,,,,,,,,,,,,,,,,,,,,,,,,,,,,,,,
,3865656288.78957,33.0126609802246,25.4471988677979,0.00018033166898092,8.1915074648207E-8,1,5,12.9061126708984,4.98264888592624,46.2500005960464,0.234325699352709,0.0343552162317221,1,-5.25803429423197E-8,,,,,,,,,,,,,,,,,,,,,33.0126609802246,33.0126609802246,25.4471988677979,25.4471988677979,49.5060055225245,5.39010890695528,6.15056467056274,65,1,0,0,1,0.27099609375,30.7917900085449,2,1,1,33.0126609802246,0,33.0126609802246,,,,,,,,,,,,,,,,,,,,,,,,,,,,,,,,,
,3865656301.62999,35.0165214538574,25.4471988677979,0.000175638775285196,7.61602654150693E-8,1,5,12.9061126708984,4.982491580134,46.2599992752075,0.228218701278295,0.0334518901898657,1,-5.72093132134047E-8,,,,,,,,,,,,,,,,,,,,,35.0165214538574,35.0165214538574,25.4471988677979,25.4471988677979,49.4598894398898,5.39066719081951,6.19825029373169,65,1,0,0,1,0.27099609375,31.7693061828613,2,1,1,35.0165214538574,0,35.0165214538574,,,,,,,,,,,,,,,,,,,,,,,,,,,,,,,,,
,3865656314.50278,37.0173187255859,25.4471988677979,0.00016963747903922,6.64806490055322E-8,1,5,12.9061126708984,4.98271707889117,46.2599992752075,0.220436928110442,0.0322968184517777,1,-6.61282126875236E-8,,,,,,,,,,,,,,,,,,,,,37.0173187255859,37.0173187255859,25.4471988677979,25.4471988677979,49.519684021611,5.39001426711673,6.24912214279175,65,1,0,0,1,0.2703857421875,29.3255138397217,2,1,1,37.0173187255859,0,37.0173187255859,,,,,,,,,,,,,,,,,,,,,,,,,,,,,,,,,
,3865656327.20339,39.0115547180176,25.4471988677979,0.000166086360385905,5.85555625242952E-8,1,5,12.9061126708984,4.98280018208489,46.2700016796589,0.215827728297879,0.0316196035414315,1,-6.61816386813863E-8,,,,,,,,,,,,,,,,,,,,,39.0115547180176,39.0115547180176,25.4471988677979,25.4471988677979,49.5024881941879,5.38981051692086,6.31243896484375,65,1,0,0,1,0.270843505859375,31.2805480957031,2,1,1,39.0115547180176,0,39.0115547180176,,,,,,,,,,,,,,,,,,,,,,,,,,,,,,,,,
,3865656340.16674,41.0224685668945,25.4471988677979,0.000161197371598752,5.36832358703834E-8,1,5,12.9061126708984,4.98270949162963,46.2599992752075,0.209470651541441,0.030677991122808,1,-7.19751577070552E-8,,,,,,,,,,,,,,,,,,,,,41.0224685668945,41.0224685668945,25.4471988677979,25.4471988677979,49.4497282691398,5.39002353153584,6.35387229919434,64,1,64,0,0,0.270614624023438,30.3030319213867,2,1,1,41.0224685668945,0,41.0224685668945,,,,,,,,,,,,,,,,,,,,,,,,,,,,,,,,,
,3865656352.83189,43.0157279968262,25.4471988677979,0.000158195701627311,5.21852289133171E-8,1,5,12.9061126708984,4.98260031522723,46.2599992752075,0.205565341295612,0.0300949809095724,1,-7.89665794412746E-8,,,,,,,,,,,,,,,,,,,,,43.0157279968262,43.0157279968262,25.4471988677979,25.4471988677979,49.509522850861,5.39014336175071,6.39856290817261,65,1,0,0,1,0.270462036132813,31.7693061828613,2,1,1,43.0157279968262,0,43.0157279968262,,,,,,,,,,,,,,,,,,,,,,,,,,,,,,,,,
,3865656365.72389,45.0224418640137,25.4471988677979,0.000153960760960032,5.5140444435318E-8,1,5,12.9061126708984,4.98252116851628,46.2599992752075,0.200057227832935,0.0292928221115632,1,-7.36620063994034E-8,,,,,,,,,,,,,,,,,,,,,45.0224418640137,45.0224418640137,25.4471988677979,25.4471988677979,49.4387854698706,5.39071253562865,6.42762231826782,65,1,0,0,1,0.26947021484375,31.2805480957031,2,1,1,45.0224418640137,0,45.0224418640137,,,,,,,,,,,,,,,,,,,,,,,,,,,,,,,,,
,3865656378.53894,47.0579414367676,25.4471988677979,0.000149754569579952,5.54043953092192E-8,1,5,12.9061126708984,4.98238461664309,46.2700016796589,0.194574141775308,0.0285598527258381,1,-1.90006631113617E-8,,,,,,,,,,,,,,,,,,,,,47.0579414367676,47.0579414367676,25.4471988677979,25.4471988677979,49.5048330797456,5.391348503541,6.47519302368164,65,1,0,0,1,0.27008056640625,30.7917900085449,2,1,1,47.0579414367676,0,47.0579414367676,,,,,,,,,,,,,,,,,,,,,,,,,,,,,,,,,
,3865656390.92077,49.0025596618652,25.4471988677979,0.000147153522491139,4.84595656360628E-8,1,5,12.9061126708984,4.98225920342346,46.2700016796589,0.191190505403203,0.0280448857558778,1,-3.24679990505114E-8,,,,,,,,,,,,,,,,,,,,,49.0025596618652,49.0025596618652,25.4471988677979,25.4471988677979,49.6361466709764,5.39129906641346,6.51029491424561,65,1,0,0,1,0.27252197265625,28.8367557525635,2,1,1,49.0025596618652,0,49.0025596618652,,,,,,,,,,,,,,,,,,,,,,,,,,,,,,,,,
,3865656403.68419,51.0763893127441,25.4471988677979,0.000143170088705396,4.63553192446058E-8,1,5,12.9061126708984,4.98185717748186,46.28000035882,0.18599782229406,0.0272559109402209,1,-5.21481649164171E-8,,,,,,,,,,,,,,,,,,,,,51.0763893127441,51.0763893127441,25.4471988677979,25.4471988677979,49.5661909185052,5.39285260020482,6.52948570251465,64,1,64,0,0,0.271759033203125,31.2805480957031,2,1,1,51.0763893127441,0,51.0763893127441,,,,,,,,,,,,,,,,,,,,,,,,,,,,,,,,,
,3865656416.48717,53.0939140319824,25.4471988677979,0.000140692606143676,4.32720827907344E-8,1,5,12.9061126708984,4.9813414962572,46.28000035882,0.182751067310231,0.0267910398946406,1,-4.30271876626235E-8,,,,,,,,,,,,,,,,,,,,,53.0939140319824,53.0939140319824,25.4471988677979,25.4471988677979,49.4782577100918,5.39427194270717,6.57213163375854,65,1,0,0,1,0.274734497070313,30.7917900085449,2,1,1,53.0939140319824,0,53.0939140319824,,,,,,,,,,,,,,,,,,,,,,,,,,,,,,,,,
,3865656429.34602,55.1439170837402,25.4471988677979,0.000137130972572792,5.12553962243953E-8,1,5,12.9061126708984,4.98043690964504,46.28000035882,0.178077367876909,0.0261189929389361,1,-3.20544936319115E-8,,,,,,,,,,,,,,,,,,,,,55.1439170837402,55.1439170837402,25.4471988677979,25.4471988677979,49.5763520892552,5.39656736413052,6.59709167480469,64,1,64,0,0,0.282440185546875,31.2805480957031,2,1,1,55.1439170837402,0,55.1439170837402,,,,,,,,,,,,,,,,,,,,,,,,,,,,,,,,,
,3865656441.26117,57.0050163269043,25.4471988677979,0.000134896163476121,4.83648867535252E-8,1,5,12.9061126708984,4.97848283832131,46.28000035882,0.175084135535201,0.0256416330130749,1,-6.04475712867415E-8,,,,,,,,,,,,,,,,,,,,,57.0050163269043,57.0050163269043,25.4471988677979,25.4471988677979,49.5435236914476,5.40357532608277,6.61341047286987,65,1,0,0,1,0.268478393554687,30.7917900085449,2,1,1,57.0050163269043,0,57.0050163269043,,,,,,,,,,,,,,,,,,,,,,,,,,,,,,,,,
,3865656453.8996,59.0363922119141,25.4471988677979,0.000132707843013685,4.25843618987642E-8,1,5,12.9061126708984,4.97790055144591,46.289999037981,0.172214894033014,0.0252259232065063,1,-5.60722695904183E-8,,,,,,,,,,,,,,,,,,,,,59.0363922119141,59.0363922119141,25.4471988677979,25.4471988677979,49.5923754738995,5.40405802645782,6.63905715942383,65,1,0,0,1,0.269851684570313,30.7917900085449,2,1,1,59.0363922119141,0,59.0363922119141,,,,,,,,,,,,,,,,,,,,,,,,,,,,,,,,,
,3865656466.75274,61.0133666992188,25.4471988677979,0.000129494975454325,3.8563075735828E-8,1,5,12.9061126708984,4.97739202380152,46.289999037981,0.168023117967161,0.0246000405437673,1,-6.36739504774222E-8,,,,,,,,,,,,,,,,,,,,,61.0133666992188,61.0133666992188,25.4471988677979,25.4471988677979,49.5689266183226,5.40727894114218,6.65741062164307,65,1,0,0,1,0.269546508789062,31.7693061828613,2,1,1,61.0133666992188,0,61.0133666992188,,,,,,,,,,,,,,,,,,,,,,,,,,,,,,,,,
,3865656479.77805,63.0202827453613,25.4471988677979,0.000126583561225768,3.8909091927802E-8,1,5,12.9061126708984,4.98662547711216,46.289999037981,0.164682959617586,0.0240478492018582,1,-1.09776556844076E-7,,,,,,,,,,,,,,,,,,,,,63.0202827453613,63.0202827453613,25.4471988677979,25.4471988677979,49.5407879916302,5.41226421482581,6.68556213378906,64,1,64,0,0,0.2679443359375,31.2805480957031,2,1,1,63.0202827453613,0,63.0202827453613,,,,,,,,,,,,,,,,,,,,,,,,,,,,,,,,,
,3865656492.39471,65.0448226928711,25.4471988677979,0.00012466234684124,3.37372805048405E-8,1,5,12.9061126708984,4.98607708311605,46.289999037981,0.16215581157806,0.0236971478681072,1,-9.43162802302033E-8,,,,,,,,,,,,,,,,,,,,,65.0448226928711,65.0448226928711,25.4471988677979,25.4471988677979,49.5392247345918,5.41470715104772,6.70881462097168,65,1,0,0,1,0.272445678710938,30.7917900085449,2,1,1,65.0448226928711,0,65.0448226928711,,,,,,,,,,,,,,,,,,,,,,,,,,,,,,,,,
,3865656504.74648,67.006965637207,25.4471988677979,0.000121740317522202,3.26190399640875E-8,1,5,12.9061126708984,4.98723941684673,46.3000014424324,0.158408168282741,0.0231399069303028,1,-9.93045897027483E-8,,,,,,,,,,,,,,,,,,,,,67.006965637207,67.006965637207,25.4471988677979,25.4471988677979,49.5200748358706,5.41097382125886,6.73059272766113,65,1,0,0,1,0.27099609375,31.7693061828613,2,1,1,67.006965637207,0,67.006965637207,,,,,,,,,,,,,,,,,,,,,,,,,,,,,,,,,
,3865656516.86631,69.0351028442383,25.4471988677979,0.000119887550137147,3.08870357012093E-8,1,5,12.9061126708984,4.98883163931699,46.3000014424324,0.156065206733951,0.0228120306703753,1,-8.69789527681837E-8,,,,,,,,,,,,,,,,,,,,,69.0351028442383,69.0351028442383,25.4471988677979,25.4471988677979,49.5317992636591,5.40517795719185,6.75149917602539,65,1,0,0,1,0.27618408203125,30.7917900085449,2,1,1,69.0351028442383,0,69.0351028442383,,,,,,,,,,,,,,,,,,,,,,,,,,,,,,,,,
,3865656529.77397,71.0345001220703,25.4471988677979,0.000117198319152611,3.30121136776667E-8,1,5,12.9061126708984,4.98804338248272,46.3000014424324,0.152528530458525,0.0223096517469596,1,-7.40621373655819E-8,,,,,,,,,,,,,,,,,,,,,71.0345001220703,71.0345001220703,25.4471988677979,25.4471988677979,49.5466502055245,5.40699507198812,6.7686595916748,65,1,0,0,1,0.281600952148438,30.7917900085449,2,1,1,71.0345001220703,0,71.0345001220703,,,,,,,,,,,,,,,,,,,,,,,,,,,,,,,,,
,3865656542.53602,73.1181640625,25.4471988677979,0.000115479687228191,3.25519534642241E-8,1,5,12.9061126708984,4.98718806992029,46.3100001215935,0.150260326930136,0.0219451981331502,1,-9.75767888119191E-8,,,,,,,,,,,,,,,,,,,,,73.1181640625,73.1181640625,25.4471988677979,25.4471988677979,49.5747888322168,5.41043918836887,6.77544641494751,65,1,0,0,1,0.285491943359375,30.7917900085449,2,1,1,73.1181640625,0,73.1181640625,,,,,,,,,,,,,,,,,,,,,,,,,,,,,,,,,
,3865656555.2985,75.0910873413086,25.4471988677979,0.000112799883395104,2.981887336422E-8,1,5,12.9061126708984,4.98782340412467,46.3100001215935,0.146798086967183,0.0214504945636243,1,-8.70748885625074E-8,,,,,,,,,,,,,,,,,,,,,75.0910873413086,75.0910873413086,25.4471988677979,25.4471988677979,49.5931571024187,5.40709532275049,6.79340171813965,65,1,0,0,1,0.277938842773438,30.7917900085449,2,1,1,75.0910873413086,0,75.0910873413086,,,,,,,,,,,,,,,,,,,,,,,,,,,,,,,,,
,3865656568.14418,77.1750411987305,25.4471988677979,0.000111155486707251,3.30750453985732E-8,1,5,12.9061126708984,4.98804879625656,46.3100001215935,0.14466809023629,0.0211333540543075,1,-9.02441689949069E-8,,,,,,,,,,,,,,,,,,,,,77.1750411987305,77.1750411987305,25.4471988677979,25.4471988677979,49.5829959316687,5.40660578480658,6.80672836303711,65,1,0,0,1,0.272293090820313,31.2805480957031,2,1,1,77.1750411987305,0,77.1750411987305,,,,,,,,,,,,,,,,,,,,,,,,,,,,,,,,,
,3865656579.64868,79.0148391723633,25.4471988677979,0.000109503291863155,3.02132829299531E-8,1,5,12.9061126708984,4.98774526904461,46.3199988007545,0.142505171567215,0.020820336682743,1,-8.6686821773253E-8,,,,,,,,,,,,,,,,,,,,,79.0148391723633,79.0148391723633,25.4471988677979,25.4471988677979,49.4813842241687,5.40790139363427,6.81786918640137,65,1,0,0,1,0.27862548828125,30.7917900085449,2,1,1,79.0148391723633,0,79.0148391723633,,,,,,,,,,,,,,,,,,,,,,,,,,,,,,,,,
,3865656592.38704,81.0302810668945,25.4471988677979,0.000106965097337007,2.86731975838194E-8,1,5,12.9061126708984,4.98750769574479,46.3199988007545,0.139191932180123,0.0203416888132051,1,-8.05963587455394E-8,,,,,,,,,,,,,,,,,,,,,81.0302810668945,81.0302810668945,25.4471988677979,25.4471988677979,49.5110861078995,5.40766833284795,6.84705924987793,65,1,0,0,1,0.282058715820313,30.7917900085449,2,1,1,81.0302810668945,0,81.0302810668945,,,,,,,,,,,,,,,,,,,,,,,,,,,,,,,,,
,3865656604.49842,83.013557434082,25.4471988677979,0.000105361449417471,2.70053590186766E-8,1,5,12.9061126708984,4.98848068231045,46.3199988007545,0.137143761560849,0.0200348644676086,1,-8.50310541046022E-8,,,,,,,,,,,,,,,,,,,,,83.013557434082,83.013557434082,25.4471988677979,25.4471988677979,49.5540756764572,5.40333239836701,6.84466886520386,64,1,64,0,0,0.282135009765625,30.7917900085449,2,1,1,83.013557434082,0,83.013557434082,,,,,,,,,,,,,,,,,,,,,,,,,,,,,,,,,
,3865656617.38598,85.049690246582,25.4471988677979,0.000102975351050603,3.39230338745836E-8,1,5,12.9061126708984,4.98831303578372,46.3300012052059,0.134030644045974,0.0195865356769273,1,-7.82489737148941E-8,,,,,,,,,,,,,,,,,,,,,85.049690246582,85.049690246582,25.4471988677979,25.4471988677979,49.5544664907168,5.40402925808391,6.86418151855469,63,1,64,0,0,0.274887084960938,30.7917900085449,2,1,1,85.049690246582,0,85.049690246582,,,,,,,,,,,,,,,,,,,,,,,,,,,,,,,,,
,3865656630.09219,87.1837196350098,25.4471988677979,0.00010139105354322,2.91975014164036E-8,1,5,12.9061126708984,4.98861714257183,46.3300012052059,0.13197556801337,0.0193159768569928,1,-5.4661137802472E-8,,,,,,,,,,,,,,,,,,,,,87.1750335693359,87.1924057006836,25.4471988677979,25.4471988677979,49.4837291097264,5.40286165446072,6.86925554275513,65,1,0,0,1,0.284194946289062,30.3030319213867,2,1,1,87.1924057006836,0,87.1837196350098,,,,,,,,,,,,,,,,,,,,,,,,,,,,,,,,,
,3865656641.002,89.0028762817383,25.4471988677979,9.91341117723886E-5,2.7309091328156E-8,1,5,12.9061126708984,4.98915495999458,46.3300012052059,0.129062163869431,0.018856091476536,1,-7.86215004205405E-8,,,,,,,,,,,,,,,,,,,,,89.0028762817383,89.0028762817383,25.4471988677979,25.4471988677979,49.5845591887072,5.40064387377944,6.87761640548706,65,1,0,0,1,0.274810791015625,30.7917900085449,2,1,1,89.0028762817383,0,89.0028762817383,,,,,,,,,,,,,,,,,,,,,,,,,,,,,,,,,
,3865656653.67998,91.0257949829102,25.4471988677979,9.75477686983971E-5,2.77463381372847E-8,1,5,12.9061126708984,4.98859260227123,46.339999884367,0.126978699188615,0.0185386314825033,1,-8.7189880012531E-8,,,,,,,,,,,,,,,,,,,,,91.0257949829102,91.0257949829102,25.4471988677979,25.4471988677979,49.5884673313033,5.40267342558235,6.89048910140991,64,1,64,0,0,0.27557373046875,31.2805480957031,2,1,1,91.0257949829102,0,91.0257949829102,,,,,,,,,,,,,,,,,,,,,,,,,,,,,,,,,
,3865656666.25543,93.1859130859375,25.4471988677979,9.53159832337488E-5,2.86908979465787E-8,1,5,12.9061126708984,4.98898209912117,46.339999884367,0.124084874241523,0.0181320627644685,1,-7.3218655146603E-8,,,,,,,,,,,,,,,,,,,,,93.1859130859375,93.1859130859375,25.4471988677979,25.4471988677979,49.5259370497649,5.40169653028562,6.9094672203064,64,1,64,0,0,0.274505615234375,30.7917900085449,2,1,1,93.1859130859375,0,93.1859130859375,,,,,,,,,,,,,,,,,,,,,,,,,,,,,,,,,
,3865656677.58731,95.0162658691406,25.4471988677979,9.38464735666773E-5,2.5925702126612E-8,1,5,12.9061126708984,4.98861454188033,46.3499985635281,0.122158696217891,0.0178540557099789,1,-6.94886690220127E-8,,,,,,,,,,,,,,,,,,,,,95.0162658691406,95.0162658691406,25.4471988677979,25.4471988677979,49.4985800515918,5.40248765686504,6.90605926513672,65,1,0,0,1,0.279388427734375,31.7693061828613,2,1,1,95.0162658691406,0,95.0162658691406,,,,,,,,,,,,,,,,,,,,,,,,,,,,,,,,,
,3865656689.76746,97.0057067871094,25.4471988677979,9.22900525080857E-5,2.95433449242003E-8,1,5,12.9061126708984,4.98823119166419,46.3499985635281,0.120114858373639,0.0175894551240813,1,-4.26727163145491E-8,,,,,,,,,,,,,,,,,,,,,97.0057067871094,97.0057067871094,25.4471988677979,25.4471988677979,49.514603436236,5.40438535471527,6.92254114151001,65,1,0,0,1,0.279159545898438,30.7917900085449,2,1,1,97.0057067871094,0,97.0057067871094,,,,,,,,,,,,,,,,,,,,,,,,,,,,,,,,,
,3865656707.46428,99.0400390625,25.4471988677979,8.96996229534437E-5,2.30498763993218E-8,1,5,12.9061126708984,4.98771876760192,46.3499985635281,0.116729121234257,0.0170760968423188,1,-5.46824859990287E-8,,,,,,,,,,,,,,,,,,,,,99.0400390625,99.0400390625,25.4471988677979,25.4471988677979,49.5841683744476,5.40602202065583,6.91890525817871,65,1,0,0,1,0.276565551757813,31.2805480957031,6,1,1,99.0400390625,0,99.0400390625,,,,,,,,,,,,,,,,,,,,,,,,,,,,,,,,,
,3865658316.31005,1.99954414367676,25.3719882965088,0.00743742837315766,6.33676465577003E-7,1,5,12.9061126708984,5.00763408693754,46.2500005960464,9.73147435612242,1.43261116739616,10,2.20760683882139E-6,,,,,,,,,,,,,,,,,,,,,1.99954414367676,1.99954414367676,25.3719882965088,25.3719882965088,49.4950627232552,5.41046081038309,2.56882309913635,65,1,0,0,1,0.270156860351562,30.7917900085449,1,1,1,1.99954414367676,0,1.99954414367676,,,,,,,,,,,,,,,,,,,,,,,,,,,,,,,,,
,3865658326.6053,3.15304279327393,25.3719882965088,0.00611032152995033,8.39579011239668E-5,1,5,12.9061126708984,5.00767531335954,46.2500005960464,7.99483991022991,1.17889195176448,10,3.26342106661561E-6,,,,,,,,,,,,,,,,,,,,,3.01625561714172,3.28982996940613,25.3719882965088,25.3719882965088,49.499361680111,5.4102335762497,3.10707831382751,65,1,0,0,1,0.278854370117187,30.7917900085449,6,1,1,3.28982996940613,0,3.15304279327393,,,,,,,,,,,,,,,,,,,,,,,,,,,,,,,,,
,3865658340.47862,5.02880334854126,25.3719882965088,0.00229774203219802,3.35998411716918E-5,1,5,12.9061126708984,5.00746216100853,46.2500005960464,3.00640398444801,0.442052095180401,10,2.83107310903746E-7,,,,,,,,,,,,,,,,,,,,,5.02880334854126,5.02880334854126,25.3719882965088,25.3719882965088,49.5658001042456,5.41104240292202,3.72024440765381,65,1,0,0,1,0.27069091796875,30.7917900085449,6,1,1,5.02880334854126,0,5.02880334854126,,,,,,,,,,,,,,,,,,,,,,,,,,,,,,,,,
,3865658354.96416,7.12884092330933,25.3719882965088,0.000864598341369163,7.09529871692649E-6,1,5,12.9061126708984,5.00750205800188,46.2500005960464,1.13131360680609,0.166024077008257,10,-1.33375143259056E-7,,,,,,,,,,,,,,,,,,,,,7.12884092330933,7.12884092330933,25.3719882965088,25.3719882965088,49.5396155488514,5.41065458291662,4.23915386199951,65,1,0,0,1,0.270156860351562,30.7917900085449,6,1,1,7.12884092330933,0,7.12884092330933,,,,,,,,,,,,,,,,,,,,,,,,,,,,,,,,,
,3865658367.8292,9.06331539154053,25.3719882965088,0.000470915206314134,2.72025515196384E-6,1,5,12.9061126708984,5.00755940391317,46.2500005960464,0.616210748647594,0.0903226045605302,10,-1.53737245360818E-7,,,,,,,,,,,,,,,,,,,,,9.05241680145264,9.07421398162842,25.3719882965088,25.3719882965088,49.5317992636591,5.41006016012752,4.57851076126099,65,1,0,0,1,0.27984619140625,30.7917900085449,6,1,1,9.07421398162842,0,9.06331539154053,,,,,,,,,,,,,,,,,,,,,,,,,,,,,,,,,
,3865658386.56639,11.863796710968,25.3719882965088,0.000276713898600897,9.0234156412689E-7,1,5,12.9061126708984,5.00745613916156,46.2500005960464,0.362044615503848,0.0533163221343365,1,9.57620563236382E-8,,,,,,,,,,,,,,,,,,,,,11.5546131134033,12.1729803085327,25.3719882965088,25.3719882965088,49.5142126219764,5.4104306680321,4.98037624359131,65,1,0,0,1,0.286407470703125,31.2805480957031,6,1,1,12.1729803085327,0,11.863796710968,,,,,,,,,,,,,,,,,,,,,,,,,,,,,,,,,
,3865658396.26407,13.3056001663208,25.3719882965088,0.000235372696115343,5.33262677516611E-7,1,5,12.9061126708984,5.00779140274324,46.2500005960464,0.307988333469472,0.0453241935104127,1,5.78501470140463E-8,,,,,,,,,,,,,,,,,,,,,13.0498094558716,13.56139087677,25.3719882965088,25.3719882965088,49.4610618826687,5.40921350656723,5.14697599411011,65,1,0,0,1,0.2862548828125,30.7917900085449,6,1,1,13.56139087677,0,13.3056001663208,,,,,,,,,,,,,,,,,,,,,,,,,,,,,,,,,
,3865658408.06064,15.0494508743286,25.3719882965088,0.000210371237917685,3.33839401304123E-7,1,5,12.9061126708984,5.00881375450015,46.2500005960464,0.275349084771071,0.0405424507080965,1,6.77950821421285E-8,,,,,,,,,,,,,,,,,,,,,15.0128955841064,15.0860061645508,25.3719882965088,25.3719882965088,49.489200509361,5.40559474102036,5.28221368789673,65,1,0,0,1,0.285263061523438,31.2805480957031,6,1,1,15.0860061645508,0,15.0494508743286,,,,,,,,,,,,,,,,,,,,,,,,,,,,,,,,,
,3865658420.87445,17.0163860321045,25.3719882965088,0.000194227985730726,2.27750717386753E-7,1,5,12.9061126708984,5.00907845946775,46.2500005960464,0.254239373410665,0.037427583045847,1,5.76053435629111E-8,,,,,,,,,,,,,,,,,,,,,17.0163860321045,17.0163860321045,25.3719882965088,25.3719882965088,49.4977984230725,5.40406938216161,5.45307636260986,65,1,0,0,1,0.285720825195313,31.7693061828613,2,1,1,17.0163860321045,0,17.0163860321045,,,,,,,,,,,,,,,,,,,,,,,,,,,,,,,,,
,3865658434.04172,19.0236759185791,25.3719882965088,0.000178930276464615,1.29308765437675E-7,1,5,12.9061126708984,5.00911767777302,46.2500005960464,0.234220024842352,0.0344638325516527,1,4.0638460613067E-8,,,,,,,,,,,,,,,,,,,,,19.0236759185791,19.0236759185791,25.3719882965088,25.3719882965088,49.5040514512264,5.4037150105326,5.58550071716309,65,1,0,0,1,0.2838134765625,30.7917900085449,2,1,1,19.0236759185791,0,19.0236759185791,,,,,,,,,,,,,,,,,,,,,,,,,,,,,,,,,
,3865658446.46064,21.0459899902344,25.3719882965088,0.000172354439855171,1.00206932730442E-7,1,5,12.9061126708984,5.0093347575762,46.2500005960464,0.225627759537492,0.0331867076393321,1,2.95493622219137E-8,,,,,,,,,,,,,,,,,,,,,21.0459899902344,21.0459899902344,25.3719882965088,25.3719882965088,49.5521216051591,5.40291724706911,5.6969313621521,65,1,0,0,1,0.284423828125,31.2805480957031,2,1,1,21.0459899902344,0,21.0459899902344,,,,,,,,,,,,,,,,,,,,,,,,,,,,,,,,,
,3865658459.10199,23.0057811737061,25.3719882965088,0.000164340583147622,7.535745049458E-8,1,5,12.9061126708984,5.00911287063851,46.2500005960464,0.215125378408021,0.0316293312839315,1,1.87371753737968E-8,,,,,,,,,,,,,,,,,,,,,23.0057811737061,23.0057811737061,25.3719882965088,25.3719882965088,49.5142126219764,5.40429203656614,5.78326416015625,65,1,0,0,1,0.284576416015625,30.7917900085449,2,1,1,23.0057811737061,0,23.0057811737061,,,,,,,,,,,,,,,,,,,,,,,,,,,,,,,,,
,3865658471.69084,25.0262279510498,25.3719882965088,0.000160382562346093,6.19562202318485E-8,1,5,12.9061126708984,5.00923731873027,46.2500005960464,0.209951574543259,0.0308683736208543,1,1.80865699020544E-8,,,,,,,,,,,,,,,,,,,,,25.0262279510498,25.0262279510498,25.3719882965088,25.3719882965088,49.6064447872456,5.40387660500258,5.85241508483887,65,1,0,0,1,0.275421142578125,30.7917900085449,2,1,1,25.0262279510498,0,25.0262279510498,,,,,,,,,,,,,,,,,,,,,,,,,,,,,,,,,
,3865658484.62101,27.0290489196777,25.3719882965088,0.000155495369892667,6.82086291460648E-8,1,5,12.9061126708984,5.0099349096755,46.2500005960464,0.203603067603836,0.0298687354092975,1,-3.19863669804737E-8,,,,,,,,,,,,,,,,,,,,,27.0290489196777,27.0290489196777,25.3719882965088,25.3719882965088,49.5681449898033,5.4003694076339,5.91877222061157,65,1,0,0,1,0.282821655273438,30.3030319213867,2,1,1,27.0290489196777,0,27.0290489196777,,,,,,,,,,,,,,,,,,,,,,,,,,,,,,,,,
,3865658497.41736,29.0302028656006,25.3719882965088,0.000152762076382647,4.63008038226799E-8,1,5,12.9061126708984,5.01121722737743,46.2500005960464,0.200102531441904,0.0293077237398878,1,-6.69089413789437E-8,,,,,,,,,,,,,,,,,,,,,29.0302028656006,29.0302028656006,25.3719882965088,25.3719882965088,49.519684021611,5.39592323525544,5.96969842910767,65,1,0,0,1,0.281219482421875,29.8142719268799,2,1,1,29.0302028656006,0,29.0302028656006,,,,,,,,,,,,,,,,,,,,,,,,,,,,,,,,,
,3865658510.73298,31.0533618927002,25.3719882965088,0.000149271412676702,5.92648077730667E-8,1,5,12.9061126708984,5.00347291568922,46.2500005960464,0.195106081871591,0.0285866414134524,1,-5.73542139499451E-8,,,,,,,,,,,,,,,,,,,,,31.0533618927002,31.0533618927002,25.3719882965088,25.3719882965088,49.5071779653033,5.39197161708653,6.05204391479492,65,1,0,0,1,0.278778076171875,30.7917900085449,2,1,1,31.0533618927002,0,31.0533618927002,,,,,,,,,,,,,,,,,,,,,,,,,,,,,,,,,
,3865658523.43522,33.0150947570801,25.3719882965088,0.000147123288740796,3.70848304497697E-8,1,5,12.9061126708984,5.0010295905111,46.2500005960464,0.192164988181818,0.0281690633808084,1,-4.65255156088744E-8,,,,,,,,,,,,,,,,,,,,,33.0150947570801,33.0150947570801,25.3719882965088,25.3719882965088,49.5439145057072,5.39445050471167,6.11566638946533,65,1,0,0,1,0.275955200195313,30.7917900085449,2,1,1,33.0150947570801,0,33.0150947570801,,,,,,,,,,,,,,,,,,,,,,,,,,,,,,,,,
,3865658536.29332,35.0098876953125,25.3719882965088,0.00014412152297955,3.17828681516254E-8,1,5,12.9061126708984,5.00073578830917,46.2599992752075,0.188231140594047,0.02757576407625,1,-5.80526381374129E-8,,,,,,,,,,,,,,,,,,,,,35.0098876953125,35.0098876953125,25.3719882965088,25.3719882965088,49.5138218077168,5.39564640362773,6.17191600799561,65,1,0,0,1,0.279693603515625,31.2805480957031,2,1,1,35.0098876953125,0,35.0098876953125,,,,,,,,,,,,,,,,,,,,,,,,,,,,,,,,,
,3865658548.9803,37.0089340209961,25.3719882965088,0.000142396239464485,3.11862286048772E-8,1,5,12.9061126708984,5.0001652272716,46.2599992752075,0.185952143001633,0.0272137942983071,1,-7.8422479874136E-8,,,,,,,,,,,,,,,,,,,,,37.0089340209961,37.0089340209961,25.3719882965088,25.3719882965088,49.5028790084476,5.39731664361546,6.20767164230347,65,1,0,0,1,0.27984619140625,31.2805480957031,2,1,1,37.0089340209961,0,37.0089340209961,,,,,,,,,,,,,,,,,,,,,,,,,,,,,,,,,
,3865658562.1271,39.0425910949707,25.3719882965088,0.000139947158111741,2.79584289762721E-8,1,5,12.9061126708984,4.99951362382146,46.2599992752075,0.18272197871893,0.0267313632063072,1,-8.43485576008484E-8,,,,,,,,,,,,,,,,,,,,,39.0425910949707,39.0425910949707,25.3719882965088,25.3719882965088,49.5372706632937,5.40094921261416,6.25883102416992,65,1,0,0,1,0.281600952148438,30.7917900085449,2,1,1,39.0425910949707,0,39.0425910949707,,,,,,,,,,,,,,,,,,,,,,,,,,,,,,,,,
,3865658574.62842,41.0265197753906,25.3719882965088,0.000137617197203706,2.75336431445511E-8,1,5,12.9061126708984,4.99920212655842,46.2599992752075,0.179667299499536,0.0262628134867153,1,-9.91909252776103E-8,,,,,,,,,,,,,,,,,,,,,41.0265197753906,41.0265197753906,25.3719882965088,25.3719882965088,49.5740072036975,5.40301830711035,6.29205703735352,65,1,0,0,1,0.281143188476562,31.2805480957031,2,1,1,41.0265197753906,0,41.0265197753906,,,,,,,,,,,,,,,,,,,,,,,,,,,,,,,,,
,3865658587.71025,43.0073699951172,25.3719882965088,0.000136104195117753,2.9565947183856E-8,1,5,12.9061126708984,4.99909955275459,46.2599992752075,0.177687878836669,0.0259665229962825,1,-1.03312024295794E-7,,,,,,,,,,,,,,,,,,,,,43.0073699951172,43.0073699951172,25.3719882965088,25.3719882965088,49.6013642018706,5.40289310581348,6.34623050689697,65,1,0,0,1,0.281143188476562,31.7693061828613,2,1,1,43.0073699951172,0,43.0073699951172,,,,,,,,,,,,,,,,,,,,,,,,,,,,,,,,,
,3865658600.29993,45.0208854675293,25.3719882965088,0.00013378509702688,2.66662251781401E-8,1,5,12.9061126708984,4.99791941058828,46.2599992752075,0.174600683101686,0.0255277639113893,1,-9.22565581158013E-8,,,,,,,,,,,,,,,,,,,,,45.0208854675293,45.0208854675293,25.3719882965088,25.3719882965088,49.5935479166783,5.40736491033797,6.38014125823975,65,1,0,0,1,0.274734497070313,30.7917900085449,2,1,1,45.0208854675293,0,45.0208854675293,,,,,,,,,,,,,,,,,,,,,,,,,,,,,,,,,
,3865658612.88225,47.0215950012207,25.3719882965088,0.00013213743803114,2.89244465649051E-8,1,5,12.9061126708984,4.99787448677578,46.2700016796589,0.172443365111745,0.0252458214028691,1,-6.60097537270293E-8,,,,,,,,,,,,,,,,,,,,,47.0215950012207,47.0215950012207,25.3719882965088,25.3719882965088,49.5435236914476,5.4074349369926,6.41129493713379,65,1,0,0,1,0.276565551757813,31.2805480957031,2,1,1,47.0215950012207,0,47.0215950012207,,,,,,,,,,,,,,,,,,,,,,,,,,,,,,,,,
,3865658625.96952,49.0239562988281,25.3719882965088,0.000129776076022137,2.85422687343032E-8,1,5,12.9061126708984,4.9969461520602,46.2700016796589,0.169320965764004,0.0247655323715404,1,-8.2214778460266E-8,,,,,,,,,,,,,,,,,,,,,49.0239562988281,49.0239562988281,25.3719882965088,25.3719882965088,49.5732255751783,5.41090360744845,6.44940137863159,65,1,0,0,1,0.26824951171875,31.2805480957031,2,1,1,49.0239562988281,0,49.0239562988281,,,,,,,,,,,,,,,,,,,,,,,,,,,,,,,,,
,3865658638.28748,51.0338249206543,25.3719882965088,0.000128242226863324,2.60399021026477E-8,1,5,12.9061126708984,4.99733951816137,46.2700016796589,0.167339580774182,0.0244660360770314,1,-8.85146200069183E-8,,,,,,,,,,,,,,,,,,,,,51.0338249206543,51.0338249206543,25.3719882965088,25.3719882965088,49.5427420629283,5.40970176906521,6.47935962677002,64,1,64,0,0,0.268096923828125,31.2805480957031,2,1,1,51.0338249206543,0,51.0338249206543,,,,,,,,,,,,,,,,,,,,,,,,,,,,,,,,,
,3865658651.08235,53.0900573730469,25.3719882965088,0.000125874731584161,2.68234990959059E-8,1,5,12.9061126708984,4.99681610222874,46.2700016796589,0.164225958271672,0.0240124559800772,1,-8.56423889414515E-8,,,,,,,,,,,,,,,,,,,,,53.0900573730469,53.0900573730469,25.3719882965088,25.3719882965088,49.5396155488514,5.41075754894341,6.5134596824646,65,1,0,0,1,0.274276733398438,30.3030319213867,2,1,1,53.0900573730469,0,53.0900573730469,,,,,,,,,,,,,,,,,,,,,,,,,,,,,,,,,
,3865658663.90187,55.1288166046143,25.3719882965088,0.000124399365924185,3.00843794731315E-8,1,5,12.9061126708984,4.99704036066983,46.28000035882,0.162313732700843,0.0237158749814618,1,-9.73824051272575E-8,,,,,,,,,,,,,,,,,,,,,55.1168785095215,55.140754699707,25.3719882965088,25.3719882965088,49.5743980179572,5.41059569057576,6.53509855270386,65,1,0,0,1,0.268783569335938,31.2805480957031,2,1,1,55.140754699707,0,55.1288166046143,,,,,,,,,,,,,,,,,,,,,,,,,,,,,,,,,
,3865658676.73518,57.1560745239258,25.3719882965088,0.000122076796523865,2.51401029880619E-8,1,5,12.9061126708984,4.9973048659877,46.28000035882,0.159289258492555,0.0233146343048415,1,-6.5048551018185E-8,,,,,,,,,,,,,,,,,,,,,57.1560745239258,57.1560745239258,25.3719882965088,25.3719882965088,49.5317992636591,5.40921769496169,6.5652346611023,65,1,0,0,1,0.268325805664062,31.7693061828613,2,1,1,57.1560745239258,0,57.1560745239258,,,,,,,,,,,,,,,,,,,,,,,,,,,,,,,,,
,3865658688.53056,59.0254592895508,25.3719882965088,0.000120660292385114,2.59787014852072E-8,1,5,12.9061126708984,4.9965700788621,46.28000035882,0.157413846772087,0.0230031069436046,1,-9.20832229382125E-8,,,,,,,,,,,,,,,,,,,,,59.0254592895508,59.0254592895508,25.3719882965088,25.3719882965088,49.5208564643899,5.41187951292804,6.59130811691284,65,1,0,0,1,0.26824951171875,31.2805480957031,2,1,1,59.0254592895508,0,59.0254592895508,,,,,,,,,,,,,,,,,,,,,,,,,,,,,,,,,
,3865658701.21652,61.0244941711426,25.3719882965088,0.000118600368123565,2.08247813440625E-8,1,5,12.9061126708984,4.99711120452409,46.28000035882,0.154748057644318,0.0226266907721139,1,-8.06517112279044E-8,,,,,,,,,,,,,,,,,,,,,61.0244941711426,61.0244941711426,25.3719882965088,25.3719882965088,49.5493859053418,5.41030045781919,6.61678075790405,65,1,0,0,1,0.26824951171875,31.7693061828613,2,1,1,61.0244941711426,0,61.0244941711426,,,,,,,,,,,,,,,,,,,,,,,,,,,,,,,,,
,3865658713.57787,63.0129661560059,25.3719882965088,0.000117272371559941,2.90597037411094E-8,1,5,12.9061126708984,4.99581043823032,46.289999037981,0.152960931572663,0.0223553137158484,1,-8.73076437543965E-8,,,,,,,,,,,,,,,,,,,,,63.0129661560059,63.0129661560059,25.3719882965088,25.3719882965088,49.4723954961975,5.41593799214454,6.63507080078125,63,1,64,0,0,0.267333984375,30.7917900085449,2,1,1,63.0129661560059,0,63.0129661560059,,,,,,,,,,,,,,,,,,,,,,,,,,,,,,,,,
,3865658726.74066,65.0138397216797,25.3719882965088,0.000115171276365516,2.32604720671354E-8,1,5,12.9061126708984,4.99534507136351,46.289999037981,0.1502034755774,0.0219337833950339,1,-9.9652338554743E-8,,,,,,,,,,,,,,,,,,,,,65.0138397216797,65.0138397216797,25.3719882965088,25.3719882965088,49.5650184757264,5.4183950292264,6.66151142120361,65,1,0,0,1,0.266189575195313,30.7917900085449,2,1,1,65.0138397216797,0,65.0138397216797,,,,,,,,,,,,,,,,,,,,,,,,,,,,,,,,,
,3865658739.1952,67.0410766601562,25.3719882965088,0.000113875053483287,2.61485277869267E-8,1,5,12.9061126708984,4.99510226648306,46.289999037981,0.148501722028381,0.0216931542368168,1,-9.2619613081985E-8,,,,,,,,,,,,,,,,,,,,,67.0410766601562,67.0410766601562,25.3719882965088,25.3719882965088,49.4907637663995,5.41886282145964,6.68240880966186,63,1,64,0,0,0.268478393554687,30.7917900085449,2,1,1,67.0410766601562,0,67.0410766601562,,,,,,,,,,,,,,,,,,,,,,,,,,,,,,,,,
,3865658751.59529,69.005744934082,25.3719882965088,0.000111958091856763,2.2624256742909E-8,1,5,12.9061126708984,4.99551615879203,46.3000014424324,0.146018358537127,0.021333582662269,1,-8.86592591049064E-8,,,,,,,,,,,,,,,,,,,,,69.005744934082,69.005744934082,25.3719882965088,25.3719882965088,49.519684021611,5.41695808077412,6.70174074172974,65,1,0,0,1,0.273284912109375,31.2805480957031,2,1,1,69.005744934082,0,69.005744934082,,,,,,,,,,,,,,,,,,,,,,,,,,,,,,,,,
,3865658764.39022,71.018684387207,25.3719882965088,0.000110603538287169,2.27986592996677E-8,1,5,12.9061126708984,4.99540595177484,46.3100001215935,0.144248580993693,0.0210658080566518,1,-9.44982435143225E-8,,,,,,,,,,,,,,,,,,,,,71.018684387207,71.018684387207,25.3719882965088,25.3719882965088,49.5912030311206,5.41735846803828,6.70977926254273,65,1,0,0,1,0.26641845703125,31.2805480957031,2,1,1,71.018684387207,0,71.018684387207,,,,,,,,,,,,,,,,,,,,,,,,,,,,,,,,,
,3865658777.19589,73.0535774230957,25.3719882965088,0.000108682215156015,2.8233528860237E-8,1,5,12.9061126708984,4.99585971692877,46.3199988007545,0.141757737199601,0.0207236953902389,1,-7.66082933580124E-8,,,,,,,,,,,,,,,,,,,,,73.0421524047852,73.0650024414062,25.3719882965088,25.3719882965088,49.4852923667649,5.41378704050064,6.73670673370361,64,1,64,0,0,0.268096923828125,31.2805480957031,2,1,1,73.0650024414062,0,73.0535774230957,,,,,,,,,,,,,,,,,,,,,,,,,,,,,,,,,
,3865658789.03466,75.0085296630859,25.3719882965088,0.000107395074644609,2.36981781298382E-8,1,5,12.9061126708984,4.99566071237532,46.3199988007545,0.140073015134673,0.0204637845997794,1,-8.5924990397792E-8,,,,,,,,,,,,,,,,,,,,,75.0085296630859,75.0085296630859,25.3719882965088,25.3719882965088,49.524764606986,5.41619315760221,6.7377552986145,65,1,0,0,1,0.27008056640625,31.2805480957031,2,1,1,75.0085296630859,0,75.0085296630859,,,,,,,,,,,,,,,,,,,,,,,,,,,,,,,,,
,3865658802.10182,77.0022048950195,25.3719882965088,0.000105434016456308,2.2998586090923E-8,1,5,12.9061126708984,4.99632747192487,46.3100001215935,0.137538979756375,0.0201074731318126,1,-7.3927051898958E-8,,,,,,,,,,,,,,,,,,,,,77.0022048950195,77.0022048950195,25.3719882965088,25.3719882965088,49.4970167945533,5.41358868180955,6.75485515594482,65,1,0,0,1,0.269012451171875,31.2805480957031,2,1,1,77.0022048950195,0,77.0022048950195,,,,,,,,,,,,,,,,,,,,,,,,,,,,,,,,,
,3865658814.62324,79.0343627929688,25.3719882965088,0.000104209225374028,2.18934791343689E-8,1,5,12.9061126708984,4.99610713347795,46.3199988007545,0.135933497910311,0.0198681390338746,1,-7.65367946864692E-8,,,,,,,,,,,,,,,,,,,,,79.0343627929688,79.0343627929688,25.3719882965088,25.3719882965088,49.5052238940052,5.41416698918167,6.77236986160278,65,1,0,0,1,0.266342163085938,31.2805480957031,2,1,1,79.0343627929688,0,79.0343627929688,,,,,,,,,,,,,,,,,,,,,,,,,,,,,,,,,
,3865658827.54191,81.0503387451172,25.3719882965088,0.00010227361804116,2.06943034671583E-8,1,5,12.9061126708984,4.99702566577446,46.3199988007545,0.13344204695295,0.019510711404396,1,-7.00690566024766E-8,,,,,,,,,,,,,,,,,,,,,81.0503387451172,81.0503387451172,25.3719882965088,25.3719882965088,49.5028790084476,5.41020833987015,6.77792835235596,65,1,0,0,1,0.274505615234375,30.7917900085449,2,1,1,81.0503387451172,0,81.0503387451172,,,,,,,,,,,,,,,,,,,,,,,,,,,,,,,,,
,3865658839.44979,83.0203323364258,25.3719882965088,0.000101111463469712,2.13304858590031E-8,1,5,12.9061126708984,4.99632822297612,46.3199988007545,0.131900930936151,0.019278309376643,1,-7.45819123853045E-8,,,,,,,,,,,,,,,,,,,,,83.0203323364258,83.0203323364258,25.3719882965088,25.3719882965088,49.5075687795629,5.41298401590522,6.79680776596069,65,1,0,0,1,0.268707275390625,30.7917900085449,2,1,1,83.0203323364258,0,83.0203323364258,,,,,,,,,,,,,,,,,,,,,,,,,,,,,,,,,
,3865658851.86839,85.0877838134766,25.3719882965088,9.92456925419308E-5,2.33932243885553E-8,1,5,12.9061126708984,4.99599158040536,46.3300012052059,0.129455989714421,0.0189125988581088,1,-7.94838088499235E-8,,,,,,,,,,,,,,,,,,,,,85.0877838134766,85.0877838134766,25.3719882965088,25.3719882965088,49.5255462355052,5.41438425353164,6.80095911026001,63,1,64,0,0,0.27069091796875,30.7917900085449,2,1,1,85.0877838134766,0,85.0877838134766,,,,,,,,,,,,,,,,,,,,,,,,,,,,,,,,,
,3865658863.95634,87.0204544067383,25.3719882965088,9.80693951998809E-5,2.19726669830402E-8,1,5,12.9061126708984,4.99599410067703,46.339999884367,0.127922840626087,0.0186808181099826,1,-8.4395473135022E-8,,,,,,,,,,,,,,,,,,,,,87.0204544067383,87.0204544067383,25.3719882965088,25.3719882965088,49.5329717064379,5.41474714468228,6.81437063217163,65,1,0,0,1,0.271530151367187,31.7693061828613,2,1,1,87.0204544067383,0,87.0204544067383,,,,,,,,,,,,,,,,,,,,,,,,,,,,,,,,,
,3865658875.97912,89.0154113769531,25.3719882965088,9.69254025194596E-5,2.45206316653579E-8,1,5,12.9061126708984,4.99660799556489,46.3300012052059,0.126452137126669,0.0184677318503291,1,-8.2147610352227E-8,,,,,,,,,,,,,,,,,,,,,89.0154113769531,89.0154113769531,25.3719882965088,25.3719882965088,49.4849015525052,5.41212083482496,6.83101320266724,65,1,0,0,1,0.271987915039062,30.7917900085449,2,1,1,89.0154113769531,0,89.0154113769531,,,,,,,,,,,,,,,,,,,,,,,,,,,,,,,,,
,3865658888.61758,91.022705078125,25.3719882965088,9.50828794320292E-5,2.04860793568815E-8,1,5,12.9061126708984,4.99569737141258,46.339999884367,0.124018285269248,0.0181007843057034,1,-8.92151791770597E-8,,,,,,,,,,,,,,,,,,,,,91.022705078125,91.022705078125,25.3719882965088,25.3719882965088,49.5732255751783,5.41564481303524,6.83417415618897,65,1,0,0,1,0.268096923828125,30.7917900085449,2,1,1,91.022705078125,0,91.022705078125,,,,,,,,,,,,,,,,,,,,,,,,,,,,,,,,,
,3865658900.94805,93.0912551879883,25.3719882965088,9.39303589699627E-5,2.29651902039269E-8,1,5,12.9061126708984,4.99548797443186,46.339999884367,0.122506904740949,0.0178866529424301,1,-8.32851646370298E-8,,,,,,,,,,,,,,,,,,,,,93.0912551879883,93.0912551879883,25.3719882965088,25.3719882965088,49.5587654475726,5.41743062774905,6.84852600097656,64,1,64,0,0,0.266342163085938,30.7917900085449,2,1,1,93.0912551879883,0,93.0912551879883,,,,,,,,,,,,,,,,,,,,,,,,,,,,,,,,,
,3865658912.6999,95.0372695922852,25.3719882965088,9.21876128486645E-5,2.33438947948857E-8,1,5,12.9061126708984,4.99716972742006,46.3499985635281,0.120288416685999,0.0175786120634686,1,-6.98313858213004E-8,,,,,,,,,,,,,,,,,,,,,95.0372695922852,95.0372695922852,25.3719882965088,25.3719882965088,49.5622827759091,5.40955730882544,6.86563014984131,64,1,64,0,0,0.275421142578125,31.7693061828613,2,1,1,95.0372695922852,0,95.0372695922852,,,,,,,,,,,,,,,,,,,,,,,,,,,,,,,,,
,3865658924.59195,97.0307693481445,25.3719882965088,9.09827128316576E-5,2.14000270402852E-8,1,5,12.9061126708984,4.99549735771542,46.3499985635281,0.118662545604597,0.017327160810343,1,-7.93168565731631E-8,,,,,,,,,,,,,,,,,,,,,97.0307693481445,97.0307693481445,25.3719882965088,25.3719882965088,49.5517307908995,5.41711724271009,6.87196445465088,65,1,0,0,1,0.266494750976562,31.2805480957031,2,1,1,97.0307693481445,0,97.0307693481445,,,,,,,,,,,,,,,,,,,,,,,,,,,,,,,,,
,3865658942.20071,99.0156707763672,25.3719882965088,8.90085025803951E-5,1.44559594086041E-8,1,5,12.9061126708984,4.99516243261865,46.3499985635281,0.116076137959676,0.0169541423349902,1,-7.41045747413697E-8,,,,,,,,,,,,,,,,,,,,,99.0156707763672,99.0156707763672,25.3719882965088,25.3719882965088,49.4778668958322,5.41820331862217,6.87114286422729,65,1,0,0,1,0.266876220703125,31.2805480957031,6,1,1,99.0156707763672,0,99.0156707763672,,,,,,,,,,,,,,,,,,,,,,,,,,,,,,,,,
,3865659016.56376,99.9553375244141,25.3719882965088,8.75750261052681E-5,7.95032041893211E-9,1,5,12.9061126708984,4.99403129581661,46.3499985635281,0.114174003878163,0.0166518122437557,1,-9.13139734720175E-8,,,,,,,,,,,,,,,,,,,,,99.9553375244141,99.9553375244141,25.3719882965088,25.3719882965088,49.5071779653033,5.42280348392155,6.87098789215088,65,1,0,0,1,0.271148681640625,31.7693061828613,1,1,1,99.9553375244141,0,99.9553375244141,,,,,,,,,,,,,,,,,,,,,,,,,,,,,,,,,