File: LT data/Bridport/Wareham W1/439-FC-ZFC-RTSIRM-contsweepwithloop-MsT.dat
[Header]
; MPMS3 Data File (default extension .dat)
; Copyright (c) 2007, Quantum Design, Inc. All rights reserved.
TITLE,
FILEOPENTIME,3865998574.2137,07/03/2022,9:27 am
BYAPP,MPMS3 w/ AC,1.0,1.1
INFO,MPMS3 Measurement Release 1.1.16 Build 424, MultiVu Release 2.3.4.19,APPNAME
INFO,Linear Motor Servo Controller,MOTOR_MODULE_NAME
INFO,3101-100 N2,MOTOR_HW_VERSION
INFO,,MOTOR_SERIAL_NUMBER
INFO,01.04.28,MOTOR_SOFTWARE_VERSION
INFO,Quantum Design Squid Module,SQUID_MODULE_NAME
INFO,3101-501 B0,SQUID_HW_VERSION
INFO,SQM327,SQUID_SERIAL_NUMBER
INFO,01.03.04,SQUID_SOFTWARE_VERSION
INFO,Quantum Design VSM Oven,OVEN_MODULE_NAME
INFO,3101-201 A3,OVEN_HW_VERSION
INFO,OVB365,OVEN_SERIAL_NUMBER
INFO,01.07.07,OVEN_SOFTWARE_VERSION
INFO,SQUID AC,AC_MODULE_NAME
INFO,3101-401 G0,AC_HW_VERSION
INFO,SAC220,AC_SERIAL_NUMBER
INFO,SQUID AC 00.95.07,AC_SOFTWARE_VERSION
INFO,TCI344,COIL_SERIAL_NUMBER
INFO,0,MOMENT_UNITS
INFO,sndst,SAMPLE_MATERIAL
INFO,,SAMPLE_COMMENT
INFO,119.59,SAMPLE_MASS
INFO,,SAMPLE_VOLUME
INFO,,SAMPLE_MOLECULAR_WEIGHT
INFO,,SAMPLE_SIZE
INFO,,SAMPLE_SHAPE
INFO,Straw,SAMPLE_HOLDER
INFO,Standard,SAMPLE_HOLDER_DETAIL
INFO,56.85,SAMPLE_OFFSET
DATATYPE,COMMENT,1
DATATYPE,TIME,2
STARTUPAXIS,X,2
STARTUPAXIS,Y1,5
FIELDGROUP, VSM,2,3,4,5,6,8,9,10,11,14,15
FIELDGROUP, DC, 2,3,4,14,56,57,58,59,60,61,62,63,64,65,66,67,68,69
FIELDGROUP, AC, 2,3,4,11,16,17,18,19,20,21,22,23,24,25,26,27,28,29,30
STARTUPGROUP, All
[Data]
Comment,Time Stamp (sec),Temperature (K),Magnetic Field (Oe),Moment (emu),M. Std. Err. (emu),Transport Action,Averaging Time (sec),Frequency (Hz),Peak Amplitude (mm),Center Position (mm),Lockin Signal' (V),Lockin Signal (V),Range,M. Quad. Signal (emu),AC Moment (emu),AC M. Std Err. (emu),AC Phase (deg),AC Phase Std. Err. (deg),AC Susceptibility (emu/Oe),AC Suscept. Std Err. (emu/Oe),AC X' (emu/Oe),AC X' Std Err. (emu/Oe),AC X'' (emu/Oe),AC X'' Std Err. (emu/Oe),AC Drive (Oe),AC Frequency (Hz),AC Averaging Time (sec),AC Cycles,AC Range,AC Measure Type,AC Signal' (V),AC Signal'' (V),AC Trim Coil Ratio,AC Trim Coil Phase,Min. Temperature (K),Max. Temperature (K),Min. Field (Oe),Max. Field (Oe),Mass (grams),Motor Lag (deg),Pressure (Torr),Measure Count,Measurement Number,SQUID Status (code),Motor Status (code),Measure Status (code),Motor Current (amps),Motor Temp. (C),Temp. Status (code),Field Status (code),Chamber Status (code),Chamber Temp (K),Redirection State,Average Temp (K),Rotation Angle (deg),Rotator state,DC Moment Fixed Ctr (emu),DC Moment Err Fixed Ctr (emu),DC Moment Free Ctr (emu),DC Moment Err Free Ctr (emu),DC Fixed Fit,DC Free Fit,DC Calculated Center (mm),DC Calculated Center Err (mm),DC Scan Length (mm),DC Scan Time (s),DC Number of Points,DC Squid Drift,DC Min V (V),DC Max V (V),DC Scans per Measure,Map 01,Map 02,Map 03,Map 04,Map 05,Map 06,Map 07,Map 08,Map 09,Map 10,Map 11,Map 12,Map 13,Map 14,Map 15,Map 16
,3865999701.06738,100.001258850098,49999.67578125,0.045136144824913,4.49023956070947E-5,1,2,12.9061126708984,4.97659178793057,45.3100018203258,58.5460576967874,8.61354405679279,100,9.42318293868519E-6,,,,,,,,,,,,,,,,,,,,,100.001258850098,100.001258850098,49999.67578125,49999.67578125,49.5681449898033,5.38282873828366,7.09158992767334,26,1,0,0,1,0.2667236328125,29.8142719268799,1,1,1,100.001258850098,0,100.001258850098,,,,,,,,,,,,,,,,,,,,,,,,,,,,,,,,,
,3865999817.1995,84.1963310241699,49999.67578125,0.0546717852824062,1.32683804847798E-5,1,2,12.9061126708984,4.97626581412569,45.2600009739399,70.917472609999,10.3691566667163,100,-3.72802005730837E-5,,,,,,,,,,,,,,,,,,,,,84.0339736938477,84.3586883544922,49999.67578125,49999.67578125,49.6713199543418,5.38408091051548,7.01131916046143,26,1,0,0,1,0.276107788085938,33.2355842590332,2,1,1,84.0339736938477,0,84.1963310241699,,,,,,,,,,,,,,,,,,,,,,,,,,,,,,,,,
,3865999899.81817,70.3376007080078,49999.67578125,0.0669914762304248,4.63235110164331E-5,1,2,12.9061126708984,4.97616342420612,45.219998806715,86.8876336160874,12.7584777829647,100,-4.73004036115271E-6,,,,,,,,,,,,,,,,,,,,,70.221809387207,70.4533920288086,49999.67578125,49999.67578125,49.6361466709764,5.38409379121275,6.9364013671875,25,1,64,0,0,0.287704467773438,28.3479976654053,2,1,1,70.221809387207,0,70.3376007080078,,,,,,,,,,,,,,,,,,,,,,,,,,,,,,,,,
,3866000036.42417,47.1409759521484,49999.67578125,0.102239233146501,4.32081091795795E-5,1,2,12.9061126708984,4.97613143474637,45.159999281168,132.608589488829,19.4305183147552,100,-3.85941511110425E-5,,,,,,,,,,,,,,,,,,,,,47.1409759521484,47.1409759521484,49999.67578125,49999.67578125,49.7115738230822,5.38521765809706,6.73582983016968,26,1,0,0,1,0.278549194335938,31.2805480957031,2,1,1,47.1409759521484,0,47.1409759521484,,,,,,,,,,,,,,,,,,,,,,,,,,,,,,,,,
,3866000116.63151,33.5750427246094,49999.67578125,0.140281558001651,7.15321438175795E-5,1,2,12.9061126708984,4.97611005760606,45.1399981975555,181.963369781908,26.569185445063,1000,-0.000123193990920943,,,,,,,,,,,,,,,,,,,,,33.2836990356445,33.8663864135742,49999.67578125,49999.67578125,49.7318961645822,5.38500510664744,6.50419187545776,26,1,0,0,1,0.267715454101562,30.7917900085449,2,1,1,33.2836990356445,0,33.5750427246094,,,,,,,,,,,,,,,,,,,,,,,,,,,,,,,,,
,3866000184.12918,22.2949819564819,49999.67578125,0.185026378400939,0.000581141490847609,1,2,12.9061126708984,4.97613609439191,45.109998434782,239.898928315965,35.7658794934317,1000,0.000394048055620819,,,,,,,,,,,,,,,,,,,,,22.1959056854248,22.3940582275391,49999.67578125,49999.67578125,49.7612072340533,5.38555278840704,6.14882946014404,24,1,64,0,0,0.2783203125,30.7917900085449,2,1,1,22.1959056854248,0,22.2949819564819,,,,,,,,,,,,,,,,,,,,,,,,,,,,,,,,,
,3866000252.57193,11.1785387992859,49999.67578125,0.248151059317008,0.000124255591078838,1,2,12.9061126708984,4.97598713128947,45.109998434782,321.854193883933,47.1253318241534,1000,-0.000119686902922195,,,,,,,,,,,,,,,,,,,,,11.0986108779907,11.2584667205811,49999.67578125,49999.67578125,49.9659939060918,5.38701393061525,5.08349132537842,25,1,64,0,0,0.27801513671875,30.7917900085449,2,1,1,11.0986108779907,0,11.1785387992859,,,,,,,,,,,,,,,,,,,,,,,,,,,,,,,,,
,3866000319.18135,2.3329621553421,49999.67578125,0.303379138188368,4.56588018318319E-5,1,2,12.9061126708984,4.97621578633965,45.109998434782,393.518176462413,57.5680619855067,1000,-0.000184203030384071,,,,,,,,,,,,,,,,,,,,,2.32546997070313,2.34045433998108,49999.67578125,49999.67578125,50.4267639181784,5.39031157995219,2.93075132369995,26,1,0,0,1,0.278396606445313,30.7917900085449,6,1,1,2.32546997070313,0,2.3329621553421,,,,,,,,,,,,,,,,,,,,,,,,,,,,,,,,,
,3866000387.34986,2.27630472183228,49999.67578125,0.303717717415232,4.65594565936327E-5,1,2,12.9061126708984,4.9761776726345,45.109998434782,393.949679930954,57.655020966603,1000,-0.000166418784971872,,,,,,,,,,,,,,,,,,,,,2.27554869651794,2.27706074714661,49999.67578125,49999.67578125,50.5029726988034,5.39068697176279,2.66110444068909,26,1,0,0,1,0.27740478515625,30.7917900085449,6,1,1,2.27706074714661,0,2.27630472183228,,,,,,,,,,,,,,,,,,,,,,,,,,,,,,,,,
,3866000457.82542,2.11549246311188,49999.67578125,0.304165991929536,5.0960803222792E-5,1,2,12.9061126708984,4.97610853617303,45.109998434782,394.527751697815,57.7095067002865,1000,-0.000189395924698148,,,,,,,,,,,,,,,,,,,,,2.11323952674866,2.1177453994751,49999.67578125,49999.67578125,50.4693626724765,5.39130943191149,2.56105208396912,26,1,0,0,1,0.288925170898438,30.3030319213867,2,1,1,2.11323952674866,0,2.11549246311188,,,,,,,,,,,,,,,,,,,,,,,,,,,,,,,,,
,3866000526.51089,2.20298588275909,49999.67578125,0.303923140195575,3.52590471811465E-5,1,2,12.9061126708984,4.97603568053792,45.109998434782,394.203210073876,57.6719239436744,1000,-0.000181779810062979,,,,,,,,,,,,,,,,,,,,,2.1975793838501,2.20839238166809,49999.67578125,49999.67578125,50.4650637156207,5.39118593029159,2.6162109375,26,1,0,0,1,0.278167724609375,31.7693061828613,2,1,1,2.1965503692627,0,2.20298588275909,,,,,,,,,,,,,,,,,,,,,,,,,,,,,,,,,
,3866000596.8064,1.99952447414398,49999.67578125,0.304472822347988,3.3624599591648E-5,1,2,12.9061126708984,4.97606866686518,45.109998434782,394.926232430407,57.7333821108439,1000,-0.000215562113281118,,,,,,,,,,,,,,,,,,,,,1.99930965900421,1.99973928928375,49999.67578125,49999.67578125,50.460764758765,5.39094465911729,2.48333334922791,26,1,0,0,1,0.2783203125,31.2805480957031,5,1,1,1.99973928928375,0,1.99952447414398,,,,,,,,,,,,,,,,,,,,,,,,,,,,,,,,,
,3866001029.3537,14.423143863678,26.5628662109375,0.000433241981782922,1.62516875471129E-6,1,5,12.9061126708984,4.97579153302785,45.109998434782,0.561918604491457,0.0820604907066515,10,-3.70994384468324E-7,,,,,,,,,,,,,,,,,,,,,14.0463361740112,14.7999515533447,26.5628662109375,26.5628662109375,49.7537817631206,5.3866403415551,5.15609550476074,65,1,0,0,1,0.277938842773438,30.3030319213867,6,1,1,14.7999515533447,0,14.423143863678,,,,,,,,,,,,,,,,,,,,,,,,,,,,,,,,,
,3866001225.88443,45.0742950439453,26.5628662109375,0.000101309789808219,2.90558665188534E-8,1,5,12.9061126708984,4.9756710865798,45.109998434782,0.131397004522226,0.019176177046147,1,-9.62280591449697E-8,,,,,,,,,,,,,,,,,,,,,45.0742950439453,45.0742950439453,26.5628662109375,26.5628662109375,49.7858285324091,5.3866708137592,6.27513647079468,65,1,0,0,1,0.287551879882813,30.3030319213867,2,1,1,45.0742950439453,0,45.0742950439453,,,,,,,,,,,,,,,,,,,,,,,,,,,,,,,,,
,3866001420.96897,76.0261688232422,26.5628662109375,7.69421670168559E-5,1.96376234060956E-8,1,5,12.9061126708984,4.97557090041296,45.1500006020069,0.0997928027613461,0.014542969118085,1,-8.88366211308446E-8,,,,,,,,,,,,,,,,,,,,,76.0261688232422,76.0261688232422,26.5628662109375,26.5628662109375,49.822565072813,5.38724529982276,6.60932207107544,65,1,0,0,1,0.287704467773438,30.7917900085449,2,1,1,76.0261688232422,0,76.0261688232422,,,,,,,,,,,,,,,,,,,,,,,,,,,,,,,,,
,3866001611.35484,107.093971252441,26.5628662109375,5.96982041445557E-5,1.58916570405925E-8,1,5,12.9061126708984,4.9755442250095,45.2100001275539,0.0774291173618586,0.0112696032578673,1,-7.97000809754071E-8,,,,,,,,,,,,,,,,,,,,,107.093971252441,107.093971252441,26.5628662109375,26.5628662109375,49.8045876168706,5.3872046363435,6.77268981933594,65,1,0,0,1,0.278167724609375,31.2805480957031,2,1,1,107.093971252441,0,107.093971252441,,,,,,,,,,,,,,,,,,,,,,,,,,,,,,,,,
,3866001798.47994,138.022659301758,26.5628662109375,4.47848173154525E-5,1.17607500811566E-8,1,5,12.9061126708984,4.97571467022811,45.2999994158745,0.0580866376082944,0.008471602296336,1,-4.67698021073959E-8,,,,,,,,,,,,,,,,,,,,,138.022659301758,138.022659301758,26.5628662109375,26.5628662109375,49.7912999320437,5.38737252124739,6.8719334602356,65,1,0,0,1,0.288009643554687,31.2805480957031,2,1,1,138.022659301758,0,138.022659301758,,,,,,,,,,,,,,,,,,,,,,,,,,,,,,,,,
,3866001985.28945,169.058013916016,26.5628662109375,3.545052674902E-5,1.06316012284656E-8,1,5,12.9061126708984,4.97552899680587,45.4000011086464,0.0459813353782293,0.00667942161178205,1,-5.71737288332724E-8,,,,,,,,,,,,,,,,,,,,,169.058013916016,169.058013916016,26.5628662109375,26.5628662109375,49.7729316618418,5.38897093245519,6.94718170166016,64,1,64,0,0,0.288925170898438,31.2805480957031,2,1,1,169.058013916016,0,169.058013916016,,,,,,,,,,,,,,,,,,,,,,,,,,,,,,,,,
,3866002172.28873,200.037170410156,26.5628662109375,2.78780636379209E-5,9.38515994536196E-9,1,5,12.9061126708984,4.97472321090762,45.5200001597404,0.0361536438428559,0.0052347000385659,1,-5.78859692736135E-8,,,,,,,,,,,,,,,,,,,,,200.037170410156,200.037170410156,26.5628662109375,26.5628662109375,49.8206110015149,5.39052697474322,7.03660440444946,63,1,64,0,0,0.269851684570313,31.7693061828613,2,1,1,200.037170410156,0,200.037170410156,,,,,,,,,,,,,,,,,,,,,,,,,,,,,,,,,
,3866002359.17123,231.051193237305,26.5628662109375,2.21255293705718E-5,7.53131881555834E-9,1,5,12.9061126708984,4.99485854155471,45.6600002944469,0.0288553080902862,0.00418799873951191,1,-3.84107666622279E-8,,,,,,,,,,,,,,,,,,,,,231.051193237305,231.051193237305,26.5628662109375,26.5628662109375,49.7369767499572,5.39355965935614,7.17142057418823,64,1,64,0,0,0.280227661132813,31.2805480957031,2,1,1,231.051193237305,0,231.051193237305,,,,,,,,,,,,,,,,,,,,,,,,,,,,,,,,,
,3866002546.13771,262.1005859375,26.5628662109375,1.77506299257075E-5,7.48593816474212E-9,1,5,12.9061126708984,4.99445476262638,45.8200015127659,0.02314699664766,0.0033602252042632,1,-3.02759354510202E-8,,,,,,,,,,,,,,,,,,,,,262.1005859375,262.1005859375,26.5628662109375,26.5628662109375,49.7580807199764,5.39524494754449,7.4567699432373,63,1,64,0,0,0.272064208984375,32.2580642700195,2,1,1,262.1005859375,0,262.1005859375,,,,,,,,,,,,,,,,,,,,,,,,,,,,,,,,,
,3866002733.34983,293.172424316406,26.5628662109375,1.44947032330852E-5,6.53863783216779E-9,1,5,12.9061126708984,4.99439729034054,46.009998768568,0.0189003649441582,0.00274768228044486,1,-2.17662934896862E-8,,,,,,,,,,,,,,,,,,,,,293.172424316406,293.172424316406,26.5628662109375,26.5628662109375,49.6705383258226,5.39344145128512,7.29808759689331,63,1,64,0,0,0.270843505859375,30.7917900085449,2,1,1,293.172424316406,0,293.172424316406,,,,,,,,,,,,,,,,,,,,,,,,,,,,,,,,,
,3866004350.22201,1.99996900558472,42119.767578125,0.28332743340872,5.47048622934597E-5,1,2,12.9061126708984,5.00661548655983,45.099999755621,370.624070565483,54.4856295787048,1000,2.76081675008447E-5,,,,,,,,,,,,,,,,,,,,,1.99990200996399,2.00003600120544,42004.87890625,42234.65625,50.3181175540053,5.39117521984504,2.53228211402893,26,1,0,0,1,0.2777099609375,30.7917900085449,1,6,1,1.99990200996399,0,1.99996900558472,,,,,,,,,,,,,,,,,,,,,,,,,,,,,,,,,
,3866004420.55373,1.99986547231674,35101.126953125,0.260901856361668,5.17433845627166E-5,1,2,12.9061126708984,5.00657238321826,45.099999755621,341.291471447159,50.1269649967694,1000,-9.34633751624877E-6,,,,,,,,,,,,,,,,,,,,,1.99983370304108,1.99989724159241,35016.3359375,35185.91796875,50.2110344468707,5.39053661907553,2.53447556495666,26,1,0,0,1,0.267791748046875,30.3030319213867,1,6,1,1.99983370304108,0,1.99986547231674,,,,,,,,,,,,,,,,,,,,,,,,,,,,,,,,,
,3866004487.17078,1.99988061189651,28451.9443359375,0.235980197024444,5.81517596877931E-5,1,2,12.9061126708984,5.00659837304734,45.099999755621,308.718463628959,45.1667384966047,1000,-0.000140220596926492,,,,,,,,,,,,,,,,,,,,,1.99986934661865,1.99989187717438,28337.287109375,28566.6015625,50.0894912121303,5.38968055158015,2.5309727191925,26,1,0,0,1,0.266876220703125,30.7917900085449,1,6,1,1.99989187717438,0,1.99988061189651,,,,,,,,,,,,,,,,,,,,,,,,,,,,,,,,,
,3866004556.77806,1.99983245134354,21498.21484375,0.204008678081861,9.11351762756429E-5,1,2,12.9061126708984,5.0065426510963,45.099999755621,266.867691313931,39.1844918434244,1000,-1.59351487041413E-5,,,,,,,,,,,,,,,,,,,,,1.99979412555695,1.99987077713013,21338.3671875,21658.0625,49.9894427616688,5.38902164503706,2.52746510505676,26,1,0,0,1,0.267105102539062,30.7917900085449,1,6,1,1.99979412555695,0,1.99983245134354,,,,,,,,,,,,,,,,,,,,,,,,,,,,,,,,,
,3866004623.93779,1.99988228082657,14794.4194335938,0.16567829597344,8.3975270319041E-5,1,2,12.9061126708984,5.006466187215,45.099999755621,216.737092488763,31.7212296556395,1000,-8.96671202762522E-5,,,,,,,,,,,,,,,,,,,,,1.99975526332855,2.00000929832458,14699.607421875,14889.2314453125,49.9151880523418,5.38840292900531,2.52888154983521,26,1,0,0,1,0.277633666992187,31.2805480957031,1,6,1,1.99975526332855,0,1.99988228082657,,,,,,,,,,,,,,,,,,,,,,,,,,,,,,,,,
,3866004690.41978,1.99989861249924,8151.458984375,0.114426124725132,0.000100891153305527,1,2,12.9061126708984,5.00646353929887,45.099999755621,149.682845161223,21.9563372008373,1000,-2.52277812294461E-5,,,,,,,,,,,,,,,,,,,,,1.99979913234711,1.99999809265137,8056.708984375,8246.208984375,49.7741041046207,5.38837221428347,2.53730988502502,26,1,0,0,1,0.276947021484375,31.2805480957031,1,6,1,1.99999809265137,0,1.99989861249924,,,,,,,,,,,,,,,,,,,,,,,,,,,,,,,,,
,3866004781.32154,1.99947047233582,-933.316833496094,-0.00888646775402509,0.000208742670241246,1,2,12.9061126708984,5.00640896948276,45.099999755621,-11.623914236428,-1.70822442162253,100,-4.07184982180964E-7,,,,,,,,,,,,,,,,,,,,,1.99930036067963,1.999640583992,-998.056762695313,-868.576904296875,49.8053692453899,5.38756232333385,2.53454828262329,26,1,0,0,1,0.268173217773438,30.7917900085449,1,6,1,1.999640583992,0,1.99947047233582,,,,,,,,,,,,,,,,,,,,,,,,,,,,,,,,,
,3866004855.6875,2.00002717971802,-8366.28125,-0.110077919068469,0.000105635705054041,1,2,12.9061126708984,5.00643879503817,45.099999755621,-143.974835026962,-21.2515151828245,100,-7.48598790180466E-5,,,,,,,,,,,,,,,,,,,,,1.99998044967651,2.00007390975952,-8456.142578125,-8276.419921875,49.829599729486,5.38810121951058,2.52184820175171,26,1,0,0,1,0.277557373046875,31.2805480957031,1,6,1,1.99998044967651,0,2.00002717971802,,,,,,,,,,,,,,,,,,,,,,,,,,,,,,,,,
,3866004938.24127,1.99989193677902,-16621.685546875,-0.175407709173784,7.09470601366343E-5,1,2,12.9061126708984,5.00637698462373,45.099999755621,-229.452700068697,-33.6274598477977,1000,6.11062396612478E-5,,,,,,,,,,,,,,,,,,,,,1.99974453449249,2.00003933906555,-16716.767578125,-16526.603515625,49.9573959923803,5.38891169910481,2.50233459472656,26,1,0,0,1,0.268325805664062,29.8142719268799,1,6,1,2.00003933906555,0,1.99989193677902,,,,,,,,,,,,,,,,,,,,,,,,,,,,,,,,,
,3866005004.73511,2.00003206729889,-23272.1865234375,-0.212289670320686,7.2698686303008E-5,1,2,12.9061126708984,5.00639935164989,45.099999755621,-277.707009799057,-40.6514905848476,1000,0.000109790022349712,,,,,,,,,,,,,,,,,,,,,1.99997210502625,2.00009202957153,-23367.19921875,-23177.173828125,50.020707902438,5.38941719176997,2.48740410804749,26,1,0,0,1,0.267181396484375,30.7917900085449,1,6,1,2.00009202957153,0,2.00003206729889,,,,,,,,,,,,,,,,,,,,,,,,,,,,,,,,,
,3866005075.54123,1.99997347593307,-30365.994140625,-0.24309046466841,4.60147407769545E-5,1,2,12.9061126708984,5.00647080976281,45.099999755621,-317.97415474813,-46.7635656163457,1000,-3.71768904773982E-5,,,,,,,,,,,,,,,,,,,,,1.99993622303009,2.00001072883606,-30425.9140625,-30306.07421875,50.0617433996976,5.38977717551253,2.48114442825317,26,1,0,0,1,0.278091430664062,31.2805480957031,1,6,1,1.99993622303009,0,1.99997347593307,,,,,,,,,,,,,,,,,,,,,,,,,,,,,,,,,
,3866005141.66858,1.99549686908722,-36988.087890625,-0.267191720012352,6.04044407075551E-5,1,2,12.9061126708984,5.00647946620117,45.099999755621,-349.515332111672,-51.2998941893293,1000,3.57221361680775E-5,,,,,,,,,,,,,,,,,,,,,1.99542808532715,1.99556565284729,-37078.1875,-36897.98828125,50.223931317438,5.39082709355898,2.47279143333435,26,1,0,0,1,0.26763916015625,31.7693061828613,1,6,1,1.99542808532715,0,1.99549686908722,,,,,,,,,,,,,,,,,,,,,,,,,,,,,,,,,
,3866005206.4029,1.99995958805084,-43474.642578125,-0.287131554529141,4.95023231539253E-5,1,2,12.9061126708984,5.00642693863791,45.099999755621,-375.581148777403,-55.2098669585054,1000,-2.46075131358017E-5,,,,,,,,,,,,,,,,,,,,,1.99957203865051,2.00034713745117,-43539.734375,-43409.55078125,50.3259338391976,5.3912527873504,2.4407525062561,26,1,0,0,1,0.278091430664062,31.2805480957031,1,6,1,1.99957203865051,0,1.99995958805084,,,,,,,,,,,,,,,,,,,,,,,,,,,,,,,,,
,3866005274.44004,2.00019228458405,-49999.736328125,-0.304796560918985,4.97703506275843E-5,1,2,12.9061126708984,5.00647720549985,45.099999755621,-398.690970553295,-58.6237404457576,1000,-3.86664327427058E-5,,,,,,,,,,,,,,,,,,,,,2.00001692771912,2.00036764144897,-49999.7734375,-49999.69921875,50.4298904322553,5.39200493797032,2.43481397628784,26,1,0,0,1,0.267868041992187,31.7693061828613,1,4,1,2.00001692771912,0,2.00019228458405,,,,,,,,,,,,,,,,,,,,,,,,,,,,,,,,,
,3866005341.11717,2.00522029399872,-43708.494140625,-0.287877548463293,4.96492333983337E-5,1,2,12.9061126708984,5.00651173723415,45.099999755621,-376.565654139308,-55.3560545210221,1000,-2.57690292934141E-5,,,,,,,,,,,,,,,,,,,,,2.00377368927002,2.00666689872742,-43803.43359375,-43613.5546875,50.3415664095822,5.39108138039638,2.41812801361084,26,1,0,0,1,0.267791748046875,29.8142719268799,6,6,1,2.00377368927002,0,2.00522029399872,,,,,,,,,,,,,,,,,,,,,,,,,,,,,,,,,
,3866005409.6166,1.99978542327881,-36871.55078125,-0.266938510668329,4.33447220019619E-5,1,2,12.9061126708984,5.0065289528735,45.099999755621,-349.167457019998,-51.3981880060856,1000,-7.60772990401114E-5,,,,,,,,,,,,,,,,,,,,,1.99959623813629,1.99997460842133,-36966.33203125,-36776.76953125,50.2090803755726,5.39026492049174,2.41214346885681,26,1,0,0,1,0.2777099609375,30.7917900085449,5,6,1,1.99997460842133,0,1.99978542327881,,,,,,,,,,,,,,,,,,,,,,,,,,,,,,,,,
,3866005476.12521,1.99977725744247,-30228.9287109375,-0.243064185409122,4.57236749187887E-5,1,2,12.9061126708984,5.00642835010164,45.099999755621,-317.932963790471,-46.7786782923716,1000,-5.30152201232206E-5,,,,,,,,,,,,,,,,,,,,,1.99958610534668,1.99996840953827,-30318.595703125,-30139.26171875,50.0758127130438,5.38985556731579,2.4162859916687,26,1,0,0,1,0.277481079101562,31.7693061828613,1,6,1,1.99996840953827,0,1.99977725744247,,,,,,,,,,,,,,,,,,,,,,,,,,,,,,,,,
,3866005542.57625,2.00000303983688,-23595.884765625,-0.2146582281264,5.49808971848319E-5,1,2,12.9061126708984,5.00639725182786,45.099999755621,-280.779701936835,-41.2791088636235,1000,-2.20728529071612E-5,,,,,,,,,,,,,,,,,,,,,1.99954497814178,2.00046110153198,-23690.69140625,-23501.078125,50.0214895309572,5.38898814137169,2.41064119338989,26,1,0,0,1,0.268707275390625,31.7693061828613,1,6,1,1.99954497814178,0,2.00000303983688,,,,,,,,,,,,,,,,,,,,,,,,,,,,,,,,,
,3866005609.08481,2.01472771167755,-16962.6337890625,-0.179269306747522,8.33306898622929E-5,1,2,12.9061126708984,5.00637509434223,45.099999755621,-234.489912288124,-34.4634606398734,1000,-1.0719660773502E-5,,,,,,,,,,,,,,,,,,,,,2.0081193447113,2.0213360786438,-17052.59375,-16872.673828125,49.9077625814091,5.388624252401,2.41515064239502,24,1,68,0,0,0.27740478515625,30.7917900085449,6,6,1,2.0213360786438,0,2.01472771167755,,,,,,,,,,,,,,,,,,,,,,,,,,,,,,,,,
,3866005677.74462,1.99970436096191,-10102.125,-0.131591604174771,9.61914020110713E-5,1,2,12.9061126708984,5.00634267451686,45.099999755621,-172.127665052691,-25.2753396837996,1000,9.05469189331892E-6,,,,,,,,,,,,,,,,,,,,,1.99957358837128,1.99983513355255,-10211.88671875,-9992.36328125,49.853048585063,5.38858422364834,2.41190695762634,26,1,0,0,1,0.268783569335938,31.2805480957031,1,6,1,1.99957358837128,0,1.99970436096191,,,,,,,,,,,,,,,,,,,,,,,,,,,,,,,,,
,3866005747.35538,2.00009179115295,-3147.98168945313,-0.0595375242919452,0.000144444010203842,1,2,12.9061126708984,5.00632837653902,45.099999755621,-77.8838788145022,-11.3915794198496,1000,3.77287911565946E-5,,,,,,,,,,,,,,,,,,,,,2.00005006790161,2.0001335144043,-3307.91040039063,-2988.05297851562,49.7373675642168,5.38795353110329,2.40652227401733,26,1,0,0,1,0.277633666992187,30.7917900085449,1,6,1,2.00005006790161,0,2.00009179115295,,,,,,,,,,,,,,,,,,,,,,,,,,,,,,,,,
,3866005834.7253,1.99985325336456,5588.43725585937,0.0795747073078865,0.000131366860159668,1,2,12.9061126708984,5.00641418968825,45.099999755621,104.08017366825,15.3468908254536,100,4.21865613972839E-5,,,,,,,,,,,,,,,,,,,,,1.99981033802032,1.9998961687088,5498.51318359375,5678.361328125,49.8522669565437,5.38761458601215,2.41228199005127,26,1,0,0,1,0.26702880859375,30.7917900085449,1,6,1,1.99981033802032,0,1.99985325336456,,,,,,,,,,,,,,,,,,,,,,,,,,,,,,,,,
,3866005916.73299,1.99999922513962,13784.5229492187,0.156743288518467,8.40728629947458E-5,1,2,12.9061126708984,5.00635928098461,45.099999755621,205.027399078019,30.1114901993633,1000,-6.94484050765448E-6,,,,,,,,,,,,,,,,,,,,,1.99986565113068,2.00013279914856,13629.6708984375,13939.375,49.9253492230918,5.38868140656055,2.39759492874146,26,1,0,0,1,0.268478393554687,31.2805480957031,1,6,1,1.99986565113068,0,1.99999922513962,,,,,,,,,,,,,,,,,,,,,,,,,,,,,,,,,
,3866005983.76844,1.9999897480011,20495.6884765625,0.198176723081468,6.71128410563609E-5,1,2,12.9061126708984,5.00642121998506,45.099999755621,259.236878346099,38.0162394554179,1000,-5.12591118304737E-5,,,,,,,,,,,,,,,,,,,,,1.99987030029297,2.00010919570923,20400.70703125,20590.669921875,49.9824081049957,5.38939734925501,2.38795852661133,26,1,0,0,1,0.266799926757813,31.2805480957031,1,6,1,1.99987030029297,0,1.9999897480011,,,,,,,,,,,,,,,,,,,,,,,,,,,,,,,,,
,3866006052.27773,1.99984806776047,27344.833984375,0.231000073834623,5.51404698673892E-5,1,2,12.9061126708984,5.00647270687597,45.099999755621,302.177889692677,44.3125415547944,1000,-6.03900484566849E-5,,,,,,,,,,,,,,,,,,,,,1.99979746341705,1.99989867210388,27254.689453125,27434.978515625,50.0593985141399,5.38954251358169,2.37828350067139,26,1,0,0,1,0.277328491210938,31.2805480957031,1,6,1,1.99979746341705,0,1.99984806776047,,,,,,,,,,,,,,,,,,,,,,,,,,,,,,,,,
,3866006122.84803,2.00019192695618,34424.37109375,0.258359800933953,5.64105285869598E-5,1,2,12.9061126708984,5.00637631707706,45.099999755621,337.937642969571,49.7038772277608,1000,4.27579765906116E-5,,,,,,,,,,,,,,,,,,,,,1.99996495246887,2.00041890144348,34339.06640625,34509.67578125,50.1594469646015,5.39098028861873,2.37442302703857,26,1,0,0,1,0.277862548828125,31.7693061828613,1,6,1,1.99996495246887,0,2.00019192695618,,,,,,,,,,,,,,,,,,,,,,,,,,,,,,,,,
,3866006191.59091,1.99997043609619,41308.78515625,0.280698278452395,5.3127425982893E-5,1,2,12.9061126708984,5.00634319562368,45.099999755621,367.185561766417,53.7808635537066,1000,-0.000121770139386288,,,,,,,,,,,,,,,,,,,,,1.9999566078186,1.99998426437378,41243.78125,41373.7890625,50.3192899967842,5.39166835620277,2.36917448043823,26,1,0,0,1,0.2777099609375,31.2805480957031,1,6,1,1.99998426437378,0,1.99997043609619,,,,,,,,,,,,,,,,,,,,,,,,,,,,,,,,,
,3866006258.08153,2.0167965888977,47967.734375,0.299479164237112,5.03976966425374E-5,1,2,12.9061126708984,5.00650681684037,45.099999755621,391.753211678517,57.5031067224034,1000,-3.72144371011872E-5,,,,,,,,,,,,,,,,,,,,,2.0118727684021,2.02172040939331,47907.6015625,48027.8671875,50.4392699744861,5.39158823320849,2.37591433525085,26,1,0,0,1,0.278396606445313,31.2805480957031,6,6,1,2.02172040939331,0,2.0167965888977,,,,,,,,,,,,,,,,,,,,,,,,,,,,,,,,,
,3866006760.1611,22.2664375305176,26.1993350982666,0.00015387771583215,3.25738733079158E-7,1,5,12.9061126708984,5.00610717034917,45.099999755621,0.201262370061318,0.0295762622325738,1,6.44815510540496E-9,,,,,,,,,,,,,,,,,,,,,21.754150390625,22.7787246704102,26.1993350982666,26.1993350982666,49.7979437744572,5.38842699999442,5.61921548843384,65,1,0,0,1,0.268096923828125,30.7917900085449,2,1,1,22.7787246704102,0,22.2664375305176,,,,,,,,,,,,,,,,,,,,,,,,,,,,,,,,,
,3866006962.83302,54.0128288269043,26.1993350982666,8.51082595639165E-5,2.18967393240871E-8,1,5,12.9061126708984,5.00606417465014,45.1200008392334,0.111331749077633,0.0162435295714262,1,-8.40646438010242E-8,,,,,,,,,,,,,,,,,,,,,54.0128288269043,54.0128288269043,26.1993350982666,26.1993350982666,49.7307237218033,5.38820789409271,6.36283302307129,65,1,0,0,1,0.2789306640625,31.2805480957031,2,1,1,54.0128288269043,0,54.0128288269043,,,,,,,,,,,,,,,,,,,,,,,,,,,,,,,,,
,3866007157.40959,85.0302505493164,26.1993350982666,6.61912167203224E-5,1.68697873862946E-8,1,5,12.9061126708984,5.00606435054328,45.1700016856194,0.0865861641853302,0.0126320000098939,1,-6.62015832086988E-8,,,,,,,,,,,,,,,,,,,,,85.0302505493164,85.0302505493164,26.1993350982666,26.1993350982666,49.7780122472168,5.38851982167347,6.64873456954956,63,1,64,0,0,0.268630981445313,31.2805480957031,2,1,1,85.0302505493164,0,85.0302505493164,,,,,,,,,,,,,,,,,,,,,,,,,,,,,,,,,
,3866007345.8518,116.07829284668,26.1993350982666,5.18960240211448E-5,1.93195169309627E-8,1,5,12.9061126708984,5.00604023461403,45.2399998903275,0.0678898290695064,0.00987677641320654,1,-7.25839563517612E-8,,,,,,,,,,,,,,,,,,,,,116.07829284668,116.07829284668,26.1993350982666,26.1993350982666,49.8100590165053,5.38809258213408,6.78175640106201,63,1,64,0,0,0.278472900390625,30.7917900085449,2,1,1,116.07829284668,0,116.07829284668,,,,,,,,,,,,,,,,,,,,,,,,,,,,,,,,,
,3866007533.08559,147.017303466797,26.1993350982666,3.99484106541048E-5,1.00048127654397E-8,1,5,12.9061126708984,5.00605599011977,45.3200004994869,0.0522614560324118,0.00759521017491438,1,-6.17967745792725E-8,,,,,,,,,,,,,,,,,,,,,147.017303466797,147.017303466797,26.1993350982666,26.1993350982666,49.7670694479476,5.3885514597481,6.86335372924805,64,1,64,0,0,0.2679443359375,31.7693061828613,2,1,1,147.017303466797,0,147.017303466797,,,,,,,,,,,,,,,,,,,,,,,,,,,,,,,,,
,3866007719.62349,178.007553100586,26.1993350982666,3.1785205957334E-5,8.50758139276162E-9,1,5,12.9061126708984,5.00601474326564,45.4300008714199,0.0415850346301966,0.00602026743447663,1,-6.66319429774215E-8,,,,,,,,,,,,,,,,,,,,,178.007553100586,178.007553100586,26.1993350982666,26.1993350982666,49.7955988888995,5.38883513396441,6.94068479537964,65,1,0,0,1,0.268783569335938,30.7917900085449,2,1,1,178.007553100586,0,178.007553100586,,,,,,,,,,,,,,,,,,,,,,,,,,,,,,,,,
,3866007906.93132,209.024719238281,26.1993350982666,2.51644798701584E-5,9.44291777503583E-9,1,5,12.9061126708984,5.00466162469233,45.559998601675,0.0329081139360737,0.00478135115003374,1,-3.98396385190518E-8,,,,,,,,,,,,,,,,,,,,,209.024719238281,209.024719238281,26.1993350982666,26.1993350982666,49.7096197517841,5.3944617086085,7.03280830383301,63,1,64,0,0,0.268707275390625,31.2805480957031,2,1,1,209.024719238281,0,209.024719238281,,,,,,,,,,,,,,,,,,,,,,,,,,,,,,,,,
,3866008094.20294,240.093154907227,26.1993350982666,2.0155657989092E-5,7.91269245593008E-9,1,5,12.9061126708984,5.004255289913,45.719999819994,0.0263572321149733,0.00381388032722197,1,-4.36439440834436E-8,,,,,,,,,,,,,,,,,,,,,240.093154907227,240.093154907227,26.1993350982666,26.1993350982666,49.7119646373418,5.39536920563267,7.24732255935669,65,1,0,0,1,0.268630981445313,31.7693061828613,2,1,1,240.093154907227,0,240.093154907227,,,,,,,,,,,,,,,,,,,,,,,,,,,,,,,,,
,3866008280.45503,271.0751953125,26.1993350982666,1.63963684693878E-5,6.28839945261657E-9,1,5,12.9061126708984,5.00385557912963,45.8699986338615,0.0214361124880955,0.00312098215259697,1,-2.11314553277013E-8,,,,,,,,,,,,,,,,,,,,,271.0751953125,271.0751953125,26.1993350982666,26.1993350982666,49.7123554516014,5.39678931933352,7.53383588790894,64,1,64,0,0,0.270538330078125,31.7693061828613,2,1,1,271.0751953125,0,271.0751953125,,,,,,,,,,,,,,,,,,,,,,,,,,,,,,,,,
,3866009039.66309,299.999725341797,26.4751167297363,1.7453043930629E-5,6.57060622161174E-9,1,5,12.9061126708984,5.00483722355966,46.0299998521805,0.0228219677763009,0.0033357886931557,1,-1.27336356537864E-8,,,,,,,,,,,,,,,,,,,,,299.999725341797,299.999725341797,26.4751167297363,26.4751167297363,49.6666301832264,5.39333665865673,7.90558385848999,65,1,0,0,1,0.269317626953125,29.8142719268799,6,1,1,299.999725341797,0,299.999725341797,,,,,,,,,,,,,,,,,,,,,,,,,,,,,,,,,
,3866009249.21004,268.918853759766,26.4751167297363,1.90291106237738E-5,7.25355806503884E-9,1,5,12.9061126708984,5.00450891687302,45.889999717474,0.0248842138109459,0.00361196391359743,1,-3.27945232356771E-8,,,,,,,,,,,,,,,,,,,,,268.918853759766,268.918853759766,26.4751167297363,26.4751167297363,49.6627220406303,5.39400682389426,7.78222227096558,64,1,64,0,0,0.269622802734375,31.2805480957031,2,1,1,268.918853759766,0,268.918853759766,,,,,,,,,,,,,,,,,,,,,,,,,,,,,,,,,
,3866009437.43202,237.984146118164,26.4751167297363,2.06305584554855E-5,8.0776876418344E-9,1,5,12.9061126708984,5.00431380206971,45.7400009036064,0.0269766901851198,0.00391744058627988,1,-3.4242225570277E-8,,,,,,,,,,,,,,,,,,,,,237.984146118164,237.984146118164,26.4751167297363,26.4751167297363,49.720953365313,5.39474008126161,7.62551689147949,64,1,64,0,0,0.268783569335938,30.7917900085449,2,1,1,237.984146118164,0,237.984146118164,,,,,,,,,,,,,,,,,,,,,,,,,,,,,,,,,
,3866009622.1363,206.979751586914,26.4751167297363,2.24885133018985E-5,6.61205577224589E-9,1,5,12.9061126708984,5.00431077664535,45.6300005316734,0.0294072227096926,0.00426288286704278,1,-4.29502561585751E-8,,,,,,,,,,,,,,,,,,,,,206.979751586914,206.979751586914,26.4751167297363,26.4751167297363,49.7678510764668,5.39530235080296,7.52304744720459,64,1,64,0,0,0.2679443359375,31.7693061828613,2,1,1,206.979751586914,0,206.979751586914,,,,,,,,,,,,,,,,,,,,,,,,,,,,,,,,,
,3866009808.1552,175.989349365234,26.4751167297363,2.44198411218048E-5,6.30636628901437E-9,1,5,12.9061126708984,5.00490717174457,45.5200001597404,0.0319367594165962,0.00463860258329571,1,-3.98713038922821E-8,,,,,,,,,,,,,,,,,,,,,175.989349365234,175.989349365234,26.4751167297363,26.4751167297363,49.7506552490437,5.39217746818921,7.43442058563232,64,1,64,0,0,0.270004272460938,31.2805480957031,2,1,1,175.989349365234,0,175.989349365234,,,,,,,,,,,,,,,,,,,,,,,,,,,,,,,,,
,3866009994.32731,144.994766235352,26.4751167297363,2.64345339077622E-5,7.12323830736119E-9,1,5,12.9061126708984,5.00570559998303,45.4300008714199,0.0345818955972164,0.00500497048974091,1,-5.65024977882181E-8,,,,,,,,,,,,,,,,,,,,,144.994766235352,144.994766235352,26.4751167297363,26.4751167297363,49.7541725773803,5.38991278399747,7.34684562683105,64,1,64,0,0,0.269012451171875,31.7693061828613,2,1,1,144.994766235352,0,144.994766235352,,,,,,,,,,,,,,,,,,,,,,,,,,,,,,,,,
,3866010179.78266,113.844108581543,26.4751167297363,2.82878657639248E-5,6.17780702751255E-9,1,5,12.9061126708984,5.00600104088219,45.3200004994869,0.0370068173887029,0.00537455094533939,1,-4.65191325539688E-8,,,,,,,,,,,,,,,,,,,,,113.844108581543,113.844108581543,26.4751167297363,26.4751167297363,49.8237375155918,5.38932273585076,7.26297569274902,65,1,0,0,1,0.277481079101562,31.2805480957031,2,1,1,113.844108581543,0,113.844108581543,,,,,,,,,,,,,,,,,,,,,,,,,,,,,,,,,
,3866010364.446,82.9647064208984,26.4751167297363,3.04420986056783E-5,8.82963193749273E-9,1,5,12.9061126708984,5.00607060747643,45.2399998903275,0.0398253763686775,0.00578688884632609,1,-4.78199293228954E-8,,,,,,,,,,,,,,,,,,,,,82.9647064208984,82.9647064208984,26.4751167297363,26.4751167297363,49.7752765473995,5.38730297166748,7.1322717666626,64,1,64,0,0,0.269699096679687,30.7917900085449,2,1,1,82.9647064208984,0,82.9647064208984,,,,,,,,,,,,,,,,,,,,,,,,,,,,,,,,,
,3866010546.80747,51.9828567504883,26.4751167297363,3.33401886020823E-5,6.49653746388256E-9,1,5,12.9061126708984,5.00624225023022,45.1800003647804,0.0436179048447818,0.00634451982055268,1,-4.74681393846109E-8,,,,,,,,,,,,,,,,,,,,,51.9828567504883,51.9828567504883,26.4751167297363,26.4751167297363,49.7713684048033,5.38709202296677,6.91168117523193,65,1,0,0,1,0.268020629882813,31.2805480957031,2,1,1,51.9828567504883,0,51.9828567504883,,,,,,,,,,,,,,,,,,,,,,,,,,,,,,,,,
,3866010728.22781,20.9109783172607,26.4751167297363,4.10709247280141E-5,1.60326389600454E-8,1,5,12.9061126708984,5.00635623605249,45.1399981975555,0.0537331441469379,0.00781826615577661,1,-5.66662088799792E-8,,,,,,,,,,,,,,,,,,,,,20.9109783172607,20.9109783172607,26.4751167297363,26.4751167297363,49.702585095111,5.38697517236811,6.29157209396362,65,1,0,0,1,0.277633666992187,30.3030319213867,2,1,1,20.9109783172607,0,20.9109783172607,,,,,,,,,,,,,,,,,,,,,,,,,,,,,,,,,
,3866011112.90349,12.0260248184204,26.4751167297363,4.80768664662237E-5,2.02544910098235E-8,1,5,12.9061126708984,5.00641066901105,45.099999755621,0.0629003070062795,0.00914985531214304,1,-6.80157970782998E-8,,,,,,,,,,,,,,,,,,,,,12.0260248184204,12.0260248184204,26.4751167297363,26.4751167297363,49.776839804438,5.38782667805545,5.01220321655273,65,1,0,0,1,0.276718139648438,31.2805480957031,6,1,1,12.0260248184204,0,12.0260248184204,,,,,,,,,,,,,,,,,,,,,,,,,,,,,,,,,
,3866011312.28671,43.026481628418,26.4751167297363,3.47983407579483E-5,8.19095657912536E-9,1,5,12.9061126708984,5.00629101718319,45.109998434782,0.0455241110377304,0.0066361687435692,1,-3.87816792271551E-8,,,,,,,,,,,,,,,,,,,,,43.026481628418,43.026481628418,26.4751167297363,26.4751167297363,49.7502644347841,5.38777905114613,6.25653839111328,65,1,0,0,1,0.27862548828125,31.2805480957031,2,1,1,43.026481628418,0,43.026481628418,,,,,,,,,,,,,,,,,,,,,,,,,,,,,,,,,
,3866011508.25688,74.0124969482422,26.4751167297363,3.14605059088675E-5,7.34663386508788E-9,1,5,12.9061126708984,5.00622826186461,45.1500006020069,0.0411593841829559,0.00598156424533338,1,-4.87944277556578E-8,,,,,,,,,,,,,,,,,,,,,74.0124969482422,74.0124969482422,26.4751167297363,26.4751167297363,49.7701959620245,5.38824249022425,6.64334440231323,63,1,64,0,0,0.2783203125,31.7693061828613,2,1,1,74.0124969482422,0,74.0124969482422,,,,,,,,,,,,,,,,,,,,,,,,,,,,,,,,,
,3866011697.80994,105.033134460449,26.4751167297363,2.86961380383388E-5,6.22658728454708E-9,1,5,12.9061126708984,5.0062688968768,45.2100001275539,0.0375413905445359,0.00546851051263724,1,-3.49720823782892E-8,,,,,,,,,,,,,,,,,,,,,105.033134460449,105.033134460449,26.4751167297363,26.4751167297363,49.7815295755533,5.38840760878408,6.80108642578125,65,1,0,0,1,0.268936157226562,31.7693061828613,2,1,1,105.033134460449,0,105.033134460449,,,,,,,,,,,,,,,,,,,,,,,,,,,,,,,,,
,3866011886.01166,136.134262084961,26.4751167297363,2.61977121620102E-5,6.5768800429107E-9,1,5,12.9061126708984,5.00614839852182,45.2900007367134,0.0342723485629051,0.00498781093157945,1,-3.53036858649955E-8,,,,,,,,,,,,,,,,,,,,,136.134262084961,136.134262084961,26.4751167297363,26.4751167297363,49.8311629865245,5.3889546411945,6.91006708145142,65,1,0,0,1,0.269241333007813,31.2805480957031,2,1,1,136.134262084961,0,136.134262084961,,,,,,,,,,,,,,,,,,,,,,,,,,,,,,,,,
,3866012073.05666,167.107116699219,26.4751167297363,2.37822810154817E-5,6.66328311603788E-9,1,5,12.9061126708984,5.0057961463198,45.389998704195,0.0311120629515211,0.00450917595919483,1,-4.60510088723528E-8,,,,,,,,,,,,,,,,,,,,,167.107116699219,167.107116699219,26.4751167297363,26.4751167297363,49.710792194563,5.39003188517225,6.97308492660522,64,1,64,0,0,0.269393920898438,31.2805480957031,2,1,1,167.107116699219,0,167.107116699219,,,,,,,,,,,,,,,,,,,,,,,,,,,,,,,,,
,3866012260.00498,198.071502685547,26.4751167297363,2.14951177295976E-5,6.49087909624172E-9,1,5,12.9061126708984,5.00497258193862,45.5100014805794,0.0281136924648288,0.0040733788188139,1,-4.25457442736222E-8,,,,,,,,,,,,,,,,,,,,,198.071502685547,198.071502685547,26.4751167297363,26.4751167297363,49.7389308212553,5.39296556197577,7.04632091522217,64,1,64,0,0,0.27008056640625,30.7917900085449,2,1,1,198.071502685547,0,198.071502685547,,,,,,,,,,,,,,,,,,,,,,,,,,,,,,,,,
,3866012446.85301,229.094604492187,26.4751167297363,1.94279109888989E-5,6.89114289779603E-9,1,5,12.9061126708984,5.00415103157007,45.6500016152859,0.0254028839215199,0.00368930251392592,1,-3.19439466085573E-8,,,,,,,,,,,,,,,,,,,,,229.094604492187,229.094604492187,26.4751167297363,26.4751167297363,49.7530001346014,5.39585245539166,7.15855360031128,64,1,64,0,0,0.269317626953125,31.2805480957031,2,1,1,229.094604492187,0,229.094604492187,,,,,,,,,,,,,,,,,,,,,,,,,,,,,,,,,
,3866012633.89749,260.144500732422,26.4751167297363,1.75190786490662E-5,6.65112826472829E-9,1,5,12.9061126708984,5.00365985254609,45.8099991083145,0.0229038647976145,0.00332627254670004,1,-2.8875293353669E-8,,,,,,,,,,,,,,,,,,,,,260.144500732422,260.144500732422,26.4751167297363,26.4751167297363,49.7854377181495,5.39750630722871,7.43879795074463,64,1,64,0,0,0.2703857421875,31.7693061828613,2,1,1,260.144500732422,0,260.144500732422,,,,,,,,,,,,,,,,,,,,,,,,,,,,,,,,,
,3866012820.72929,291.062438964844,26.4751167297363,1.58721335230014E-5,6.98020775651024E-9,1,5,12.9061126708984,5.00427803725958,46.000000089407,0.0207532047961166,0.00302149058642841,1,-2.05036809764223E-8,,,,,,,,,,,,,,,,,,,,,291.062438964844,291.062438964844,26.4751167297363,26.4751167297363,49.746356292188,5.39638481234659,7.31294965744019,63,1,64,0,0,0.269622802734375,29.8142719268799,2,1,1,291.062438964844,0,291.062438964844,,,,,,,,,,,,,,,,,,,,,,,,,,,,,,,,,
,3866013112.61311,300.006546020508,43302.66796875,0.0110155089587787,2.74142017659606E-6,1,2,12.9061126708984,5.00459838453489,46.0299998521805,14.4073629057795,2.07656691879782,100,-2.99731620022587E-5,,,,,,,,,,,,,,,,,,,,,300.006500244141,300.006591796875,43212.84375,43392.4921875,49.6091804870629,5.39469183820369,7.33871078491211,25,1,68,0,0,0.271453857421875,30.7917900085449,1,6,1,300.006500244141,0,300.006546020508,,,,,,,,,,,,,,,,,,,,,,,,,,,,,,,,,
,3866013179.09516,300.003799438477,36668.71484375,0.00935225120440199,3.0147910788709E-6,1,2,12.9061126708984,5.00464188674239,46.0299998521805,12.2313461257999,1.76824144957282,100,-2.14710027589708E-5,,,,,,,,,,,,,,,,,,,,,300.003570556641,300.004028320313,36573.58203125,36763.84765625,49.6353650424572,5.39456564031947,7.39307975769043,26,1,0,0,1,0.27099609375,30.7917900085449,1,6,1,300.003570556641,0,300.003799438477,,,,,,,,,,,,,,,,,,,,,,,,,,,,,,,,,
,3866013247.58836,300.002639770508,29829.529296875,0.00764032275768293,3.46874200086132E-6,1,2,12.9061126708984,5.00465777641501,46.0299998521805,9.99213239776689,1.44669319320262,100,-1.59179120435723E-5,,,,,,,,,,,,,,,,,,,,,300.002593994141,300.002685546875,29734.541015625,29924.517578125,49.7221258080918,5.39486615370614,7.48503255844116,25,1,68,0,0,0.268478393554687,31.7693061828613,1,6,1,300.002685546875,0,300.002639770508,,,,,,,,,,,,,,,,,,,,,,,,,,,,,,,,,
,3866013314.09996,300.002365112305,23185.703125,0.00598380410531209,3.1847347612427E-6,1,2,12.9061126708984,5.00470456504781,46.0299998521805,7.82639023791234,1.1291245247266,100,-1.54665574363018E-5,,,,,,,,,,,,,,,,,,,,,300.002288818359,300.00244140625,23095.892578125,23275.513671875,49.726033950688,5.39420932048129,7.59613990783691,26,1,0,0,1,0.267257690429687,31.7693061828613,1,6,1,300.00244140625,0,300.002365112305,,,,,,,,,,,,,,,,,,,,,,,,,,,,,,,,,
,3866013382.67981,300.002212524414,16341.7529296875,0.00427030032486901,2.76509450527443E-6,1,2,12.9061126708984,5.00482416301534,46.0299998521805,5.58549671370596,0.805405029478425,100,-1.13540948855202E-5,,,,,,,,,,,,,,,,,,,,,300.002166748047,300.002258300781,16236.96875,16446.537109375,49.7057116091879,5.39378565798433,7.75170755386353,26,1,0,0,1,0.271377563476562,31.2805480957031,1,6,1,300.002258300781,0,300.002212524414,,,,,,,,,,,,,,,,,,,,,,,,,,,,,,,,,
,3866013451.2133,300.000762939453,9495.3720703125,0.00255476535356465,3.04082910225178E-6,1,2,12.9061126708984,5.00485023931812,46.0399985313416,3.34242380433551,0.47640305954235,100,-1.09572130631957E-5,,,,,,,,,,,,,,,,,,,,,300.000732421875,300.000793457031,9415.451171875,9575.29296875,49.7428389638514,5.39375335958499,7.91077184677124,26,1,0,0,1,0.266647338867187,30.7917900085449,1,6,1,300.000793457031,0,300.000762939453,,,,,,,,,,,,,,,,,,,,,,,,,,,,,,,,,
,3866013517.77536,300.000946044922,2839.60668945313,0.000870484135233166,3.10319854148264E-6,1,2,12.9061126708984,5.00481341888023,46.0399985313416,1.1414218191159,0.144823417508395,100,-1.71176909449944E-5,,,,,,,,,,,,,,,,,,,,,300.000854492188,300.001037597656,2769.69580078125,2909.517578125,49.6885157817649,5.3935282532712,8.08223819732666,26,1,0,0,1,0.268478393554687,31.2805480957031,1,6,1,300.001037597656,0,300.000946044922,,,,,,,,,,,,,,,,,,,,,,,,,,,,,,,,,
,3866013592.39474,300.001663208008,-4616.67993164063,-0.0013119805868037,3.9266654987175E-6,1,2,12.9061126708984,5.00483227065798,46.0299998521805,-1.71431877206122,-0.259281812678075,100,-5.56234181828077E-6,,,,,,,,,,,,,,,,,,,,,300.001251220703,300.002075195313,-4736.4384765625,-4496.92138671875,49.682262753611,5.39349108501298,8.04966926574707,24,1,68,0,0,0.270767211914062,31.2805480957031,1,6,1,300.001251220703,0,300.001663208008,,,,,,,,,,,,,,,,,,,,,,,,,,,,,,,,,
,3866013682.17942,300.001220703125,-13596.9033203125,-0.00354131999744499,3.19889777986492E-6,1,2,12.9061126708984,5.00481891259245,46.0299998521805,-4.63100652013376,-0.674630196750987,10,4.27896126510674E-6,,,,,,,,,,,,,,,,,,,,,300.001220703125,300.001220703125,-13596.9033203125,-13596.9033203125,49.7678510764668,5.39355555702581,7.97897720336914,24,1,68,0,0,0.269851684570313,31.2805480957031,1,6,1,300.001220703125,0,300.001220703125,,,,,,,,,,,,,,,,,,,,,,,,,,,,,,,,,
,3866013763.45619,300.000854492188,-21721.84375,-0.00561020034603734,2.90401685150102E-6,1,2,12.9061126708984,5.00487605427307,46.0399985313416,-7.33695501043395,-1.06643672452956,100,8.56644131364691E-6,,,,,,,,,,,,,,,,,,,,,300.000823974609,300.000885009766,-21796.83203125,-21646.85546875,49.6971136954764,5.39310860727787,7.94266986846924,25,1,68,0,0,0.268173217773438,31.2805480957031,1,6,1,300.000885009766,0,300.000854492188,,,,,,,,,,,,,,,,,,,,,,,,,,,,,,,,,
,3866013832.1388,299.999328613281,-28592.767578125,-0.00731842154599538,3.46366557382701E-6,1,2,12.9061126708984,5.00472156775055,46.0299998521805,-9.56995489185976,-1.39502900499107,100,8.16240940698059E-6,,,,,,,,,,,,,,,,,,,,,299.999206542969,299.999450683594,-28652.84375,-28532.69140625,49.6681934402649,5.39394796246895,7.91019344329834,26,1,0,0,1,0.271377563476562,31.2805480957031,1,6,1,299.999206542969,0,299.999328613281,,,,,,,,,,,,,,,,,,,,,,,,,,,,,,,,,
,3866013898.62917,300.000137329102,-35259.533203125,-0.00898047869315969,3.17184646899588E-6,1,2,12.9061126708984,5.00480436827194,46.0299998521805,-11.7432929508595,-1.71411800114993,100,8.3105836706038E-6,,,,,,,,,,,,,,,,,,,,,299.999938964844,300.000335693359,-35314.671875,-35204.39453125,49.682262753611,5.3935342660662,7.89706230163574,26,1,0,0,1,0.26763916015625,31.2805480957031,1,6,1,300.000335693359,0,300.000137329102,,,,,,,,,,,,,,,,,,,,,,,,,,,,,,,,,
,3866013966.79222,299.999374389648,-42087.51953125,-0.0106926734085344,1.92705417461364E-5,1,2,12.9061126708984,5.00468924669199,46.0399985313416,-13.9778216750529,-2.06786374107311,100,-1.07578399622232E-5,,,,,,,,,,,,,,,,,,,,,299.999237060547,299.99951171875,-42177.6171875,-41997.421875,49.6560781982168,5.39374574747696,7.88128566741943,26,1,0,0,1,0.268707275390625,30.7917900085449,1,6,1,299.99951171875,0,299.999374389648,,,,,,,,,,,,,,,,,,,,,,,,,,,,,,,,,
,3866014041.32297,300.000076293945,-49555.263671875,-0.0125542719832017,3.10343998421731E-6,1,2,12.9061126708984,5.00466354337588,46.0299998521805,-16.4152260024921,-2.40078374420612,100,8.08060020424109E-6,,,,,,,,,,,,,,,,,,,,,300,300.000152587891,-49650.49609375,-49460.03125,49.5763520892552,5.39318441526327,7.86477851867676,26,1,0,0,1,0.270156860351562,31.7693061828613,1,6,1,300,0,300.000076293945,,,,,,,,,,,,,,,,,,,,,,,,,,,,,,,,,
,3866014107.80133,300.000274658203,-44307.224609375,-0.0112584227858673,3.2160627948749E-6,1,2,12.9061126708984,5.00462001493497,46.0399985313416,-14.7259851999939,-2.11677493307872,100,3.49153262526333E-5,,,,,,,,,,,,,,,,,,,,,300.000244140625,300.000305175781,-44401.95703125,-44212.4921875,49.697504509736,5.39371400011002,7.85923433303833,26,1,0,0,1,0.268173217773438,31.7693061828613,1,6,1,300.000244140625,0,300.000274658203,,,,,,,,,,,,,,,,,,,,,,,,,,,,,,,,,
,3866014174.30994,300.000473022461,-37669.822265625,-0.00959720269065725,3.22716157055693E-6,1,2,12.9061126708984,5.00442694653553,46.0299998521805,-12.5514073520408,-1.81134386810669,100,2.44059836664516E-5,,,,,,,,,,,,,,,,,,,,,300.000091552734,300.000854492188,-37764.49609375,-37575.1484375,49.6490435415437,5.39423081374807,7.84785461425781,26,1,0,0,1,0.268173217773438,30.3030319213867,1,6,1,300.000854492188,0,300.000473022461,,,,,,,,,,,,,,,,,,,,,,,,,,,,,,,,,
,3866014240.77516,300.001113891602,-31037.19921875,-0.00793685285630171,3.48346344786308E-6,1,2,12.9061126708984,5.00455741050433,46.0299998521805,-10.380549899463,-1.49665812279122,100,2.12327335681506E-5,,,,,,,,,,,,,,,,,,,,,300.000427246094,300.001800537109,-31126.990234375,-30947.408203125,49.6259855002264,5.39454387346517,7.83708381652832,24,1,68,0,0,0.269317626953125,31.2805480957031,1,6,1,300.001800537109,0,300.001113891602,,,,,,,,,,,,,,,,,,,,,,,,,,,,,,,,,
,3866014309.31272,300.000793457031,-24194.6533203125,-0.00623177638377551,3.28583708189835E-6,1,2,12.9061126708984,5.00475885850652,46.0299998521805,-8.15052112495499,-1.17813224601424,100,1.44261380873166E-5,,,,,,,,,,,,,,,,,,,,,300.000671386719,300.000915527344,-24289.416015625,-24099.890625,49.6392731850533,5.39324281073385,7.82510566711426,26,1,0,0,1,0.270538330078125,31.2805480957031,1,6,1,300.000671386719,0,300.000793457031,,,,,,,,,,,,,,,,,,,,,,,,,,,,,,,,,
,3866014377.91291,299.999618530273,-17346.8671875,-0.00452020907847621,3.05859615434412E-6,1,2,12.9061126708984,5.00481694295966,46.0399985313416,-5.91265775527174,-0.8505254659038,100,1.3557546870916E-5,,,,,,,,,,,,,,,,,,,,,299.999420166016,299.999816894531,-17421.716796875,-17272.017578125,49.6877341532456,5.39296824557667,7.82313442230225,26,1,0,0,1,0.268402099609375,29.3255138397217,1,6,1,299.999816894531,0,299.999618530273,,,,,,,,,,,,,,,,,,,,,,,,,,,,,,,,,
,3866014442.3782,299.998657226562,-10911.283203125,-0.00291061414637001,2.8923893600017E-6,1,2,12.9061126708984,5.00485141625162,46.0299998521805,-3.80789926045902,-0.543347037991117,100,1.20348901820411E-5,,,,,,,,,,,,,,,,,,,,,299.998626708984,299.998687744141,-11021.0947265625,-10801.4716796875,49.7526093203418,5.3932572349041,7.81209516525269,26,1,0,0,1,0.2679443359375,31.7693061828613,1,6,1,299.998687744141,0,299.998657226562,,,,,,,,,,,,,,,,,,,,,,,,,,,,,,,,,
,3866014510.98663,299.999938964844,-4057.29895019531,-0.00118406783759737,2.90181942287063E-6,1,2,12.9061126708984,5.00472388127884,46.0299998521805,-1.55095272726896,-0.207994186524388,100,1.48673980648212E-5,,,,,,,,,,,,,,,,,,,,,299.999908447266,299.999969482422,-4127.2724609375,-3987.32543945313,49.7600347912745,5.39399618191114,7.81376934051514,26,1,0,0,1,0.267715454101562,33.2355842590332,1,6,1,299.999969482422,0,299.999938964844,,,,,,,,,,,,,,,,,,,,,,,,,,,,,,,,,
,3866014588.63935,300.002029418945,3708.904296875,0.00110262381299595,3.24014746317858E-6,1,2,12.9061126708984,5.00456136047443,46.0299998521805,1.44022044783569,0.22081838076234,100,6.91392957245807E-6,,,,,,,,,,,,,,,,,,,,,300.001159667969,300.002899169922,3548.59326171875,3869.21533203125,49.7827020183322,5.39438400997335,7.80740594863892,26,1,0,0,1,0.268020629882813,31.2805480957031,1,6,1,300.002899169922,0,300.002029418945,,,,,,,,,,,,,,,,,,,,,,,,,,,,,,,,,
,3866014659.96221,300.000366210937,10838.978515625,0.0028845809351458,2.81580130245684E-6,1,2,12.9061126708984,5.00460771330516,46.0399985313416,3.77161160274647,0.551872086088072,10,-1.66138137415198E-6,,,,,,,,,,,,,,,,,,,,,300.000061035156,300.000671386719,10729.0166015625,10948.9404296875,49.6881249675053,5.39402271571488,7.80268287658691,26,1,0,0,1,0.268020629882813,31.7693061828613,1,6,1,300.000061035156,0,300.000366210937,,,,,,,,,,,,,,,,,,,,,,,,,,,,,,,,,
,3866014758.4911,299.999847412109,20695.8701171875,0.00535624873753203,3.35372574432883E-6,1,2,12.9061126708984,5.00473097214201,46.0299998521805,7.00475252889977,1.01678358917159,100,-9.20239393071502E-6,,,,,,,,,,,,,,,,,,,,,299.999664306641,300.000030517578,20600.712890625,20791.02734375,49.7408848925533,5.39369447675034,7.78736686706543,26,1,0,0,1,0.269546508789062,31.2805480957031,1,6,1,300.000030517578,0,299.999847412109,,,,,,,,,,,,,,,,,,,,,,,,,,,,,,,,,
,3866014824.97204,300.000244140625,27344.9228515625,0.00701988760104467,3.14472607504855E-6,1,2,12.9061126708984,5.0045768266075,46.0299998521805,9.17980893389384,1.33395515929785,100,-1.09758003579676E-5,,,,,,,,,,,,,,,,,,,,,300.000183105469,300.000305175781,27254.8046875,27435.041015625,49.6369282994956,5.39451705620022,7.78809070587158,26,1,0,0,1,0.269775390625,31.2805480957031,1,6,1,300.000305175781,0,300.000244140625,,,,,,,,,,,,,,,,,,,,,,,,,,,,,,,,,
,3866014893.48754,300.001419067383,34213.88671875,0.00873327498910364,3.43650475777539E-6,1,2,12.9061126708984,5.00466200785767,46.0299998521805,11.4200768158178,1.66350813035381,100,-1.06512856275992E-5,,,,,,,,,,,,,,,,,,,,,300.001098632812,300.001739501953,34118.69140625,34309.08203125,49.720953365313,5.39427588874184,7.7883186340332,26,1,0,0,1,0.267868041992187,31.7693061828613,1,6,1,300.001098632812,0,300.001419067383,,,,,,,,,,,,,,,,,,,,,,,,,,,,,,,,,
,3866014964.13763,300.000244140625,41293.849609375,0.0104916994160192,3.05864732791916E-6,1,2,12.9061126708984,5.00463701589253,46.0299998521805,13.7191431000074,2.00009517609962,100,-1.15280809736674E-5,,,,,,,,,,,,,,,,,,,,,300.000183105469,300.000305175781,41213.859375,41373.83984375,49.7014126523322,5.39391701411539,7.77686595916748,26,1,0,0,1,0.268478393554687,31.7693061828613,1,6,1,300.000305175781,0,300.000244140625,,,,,,,,,,,,,,,,,,,,,,,,,,,,,,,,,
,3866015030.62996,300.000213623047,47952.7734375,0.0121541449067845,2.67189455425716E-6,1,2,12.9061126708984,5.00464921284359,46.0299998521805,15.8929906546997,2.31737605205435,100,-1.30862111445204E-5,,,,,,,,,,,,,,,,,,,,,300.000091552734,300.000335693359,47877.65625,48027.890625,49.5884673313033,5.39376983000699,7.77290916442871,26,1,0,0,1,0.268325805664062,31.7693061828613,1,6,1,300.000335693359,0,300.000213623047,,,,,,,,,,,,,,,,,,,,,,,,,,,,,,,,,
,3866015054.68017,299.999725341797,50000.26953125,0.0126692284942553,1.01481876016638E-6,1,2,12.9061126708984,5.00467181198926,46.0399985313416,16.5672807229069,2.41115985091536,100,-1.70368964328202E-5,,,,,,,,,,,,,,,,,,,,,299.999359130859,300.000091552734,50000.23828125,50000.30078125,49.6740556541591,5.39372244019966,7.7760705947876,26,1,0,0,1,0.266799926757813,31.2805480957031,1,4,1,300.000091552734,0,299.999725341797,,,,,,,,,,,,,,,,,,,,,,,,,,,,,,,,,