File: LT data/Bridport/Wareham W1/443-FC-ZFC-RTSIRM-contsweepwithloop-MsT.dat
[Header]
; MPMS3 Data File (default extension .dat)
; Copyright (c) 2007, Quantum Design, Inc. All rights reserved.
TITLE,
FILEOPENTIME,3865908530.71809,07/02/2022,8:26 am
BYAPP,MPMS3 w/ AC,1.0,1.1
INFO,MPMS3 Measurement Release 1.1.16 Build 424, MultiVu Release 2.3.4.19,APPNAME
INFO,Linear Motor Servo Controller,MOTOR_MODULE_NAME
INFO,3101-100 N2,MOTOR_HW_VERSION
INFO,,MOTOR_SERIAL_NUMBER
INFO,01.04.28,MOTOR_SOFTWARE_VERSION
INFO,Quantum Design Squid Module,SQUID_MODULE_NAME
INFO,3101-501 B0,SQUID_HW_VERSION
INFO,SQM327,SQUID_SERIAL_NUMBER
INFO,01.03.04,SQUID_SOFTWARE_VERSION
INFO,Quantum Design VSM Oven,OVEN_MODULE_NAME
INFO,3101-201 A3,OVEN_HW_VERSION
INFO,OVB365,OVEN_SERIAL_NUMBER
INFO,01.07.07,OVEN_SOFTWARE_VERSION
INFO,SQUID AC,AC_MODULE_NAME
INFO,3101-401 G0,AC_HW_VERSION
INFO,SAC220,AC_SERIAL_NUMBER
INFO,SQUID AC 00.95.07,AC_SOFTWARE_VERSION
INFO,TCI344,COIL_SERIAL_NUMBER
INFO,0,MOMENT_UNITS
INFO,sndst,SAMPLE_MATERIAL
INFO,,SAMPLE_COMMENT
INFO,129.65,SAMPLE_MASS
INFO,,SAMPLE_VOLUME
INFO,,SAMPLE_MOLECULAR_WEIGHT
INFO,,SAMPLE_SIZE
INFO,,SAMPLE_SHAPE
INFO,Straw,SAMPLE_HOLDER
INFO,Standard,SAMPLE_HOLDER_DETAIL
INFO,56.69,SAMPLE_OFFSET
DATATYPE,COMMENT,1
DATATYPE,TIME,2
STARTUPAXIS,X,2
STARTUPAXIS,Y1,5
FIELDGROUP, VSM,2,3,4,5,6,8,9,10,11,14,15
FIELDGROUP, DC, 2,3,4,14,56,57,58,59,60,61,62,63,64,65,66,67,68,69
FIELDGROUP, AC, 2,3,4,11,16,17,18,19,20,21,22,23,24,25,26,27,28,29,30
STARTUPGROUP, All
[Data]
Comment,Time Stamp (sec),Temperature (K),Magnetic Field (Oe),Moment (emu),M. Std. Err. (emu),Transport Action,Averaging Time (sec),Frequency (Hz),Peak Amplitude (mm),Center Position (mm),Lockin Signal' (V),Lockin Signal (V),Range,M. Quad. Signal (emu),AC Moment (emu),AC M. Std Err. (emu),AC Phase (deg),AC Phase Std. Err. (deg),AC Susceptibility (emu/Oe),AC Suscept. Std Err. (emu/Oe),AC X' (emu/Oe),AC X' Std Err. (emu/Oe),AC X'' (emu/Oe),AC X'' Std Err. (emu/Oe),AC Drive (Oe),AC Frequency (Hz),AC Averaging Time (sec),AC Cycles,AC Range,AC Measure Type,AC Signal' (V),AC Signal'' (V),AC Trim Coil Ratio,AC Trim Coil Phase,Min. Temperature (K),Max. Temperature (K),Min. Field (Oe),Max. Field (Oe),Mass (grams),Motor Lag (deg),Pressure (Torr),Measure Count,Measurement Number,SQUID Status (code),Motor Status (code),Measure Status (code),Motor Current (amps),Motor Temp. (C),Temp. Status (code),Field Status (code),Chamber Status (code),Chamber Temp (K),Redirection State,Average Temp (K),Rotation Angle (deg),Rotator state,DC Moment Fixed Ctr (emu),DC Moment Err Fixed Ctr (emu),DC Moment Free Ctr (emu),DC Moment Err Free Ctr (emu),DC Fixed Fit,DC Free Fit,DC Calculated Center (mm),DC Calculated Center Err (mm),DC Scan Length (mm),DC Scan Time (s),DC Number of Points,DC Squid Drift,DC Min V (V),DC Max V (V),DC Scans per Measure,Map 01,Map 02,Map 03,Map 04,Map 05,Map 06,Map 07,Map 08,Map 09,Map 10,Map 11,Map 12,Map 13,Map 14,Map 15,Map 16
,3865909695.37317,100.001853942871,49999.4765625,0.0581941590545239,6.31409169849767E-6,1,2,12.9061126708984,5.00584606209374,40.1699990034103,76.1173511435966,11.1258812850749,100,-4.23562706095917E-5,,,,,,,,,,,,,,,,,,,,,100.001853942871,100.001853942871,49999.4765625,49999.4765625,49.6427905133899,5.35220433893863,7.14133405685425,26,1,0,0,1,0.2862548828125,29.3255138397217,1,1,1,100.001853942871,0,100.001853942871,,,,,,,,,,,,,,,,,,,,,,,,,,,,,,,,,
,3865909799.33319,85.9086875915527,49999.4765625,0.0684939863819514,1.6983945403616E-5,1,2,12.9061126708984,5.00603747521194,40.1300005614758,89.5907771786098,13.1191279776061,100,-3.19862571981713E-5,,,,,,,,,,,,,,,,,,,,,85.7103118896484,86.107063293457,49999.4765625,49999.4765625,49.6947688099187,5.35165855682916,7.07430171966553,25,1,64,0,0,0.285415649414062,30.7917900085449,2,1,1,85.7103118896484,0,85.9086875915527,,,,,,,,,,,,,,,,,,,,,,,,,,,,,,,,,
,3865909916.68041,66.2624206542969,49999.4765625,0.0910062089136547,2.6443296225007E-5,1,2,12.9061126708984,5.00628872290508,40.0700010359287,119.059631390099,17.3349508707686,1000,-0.000116904650796152,,,,,,,,,,,,,,,,,,,,,66.2624206542969,66.2624206542969,49999.4765625,49999.4765625,49.720953365313,5.35005555498993,6.97529458999634,26,1,0,0,1,0.27496337890625,30.7917900085449,2,1,1,66.2624206542969,0,66.2624206542969,,,,,,,,,,,,,,,,,,,,,,,,,,,,,,,,,
,3865910040.58386,45.3444271087646,49999.4765625,0.13572164961727,5.30132714429641E-5,1,2,12.9061126708984,5.00629209943579,40.0299988687038,177.564364170086,25.8169029042786,1000,-0.000201495384498295,,,,,,,,,,,,,,,,,,,,,45.2178726196289,45.4709815979004,49999.4765625,49999.4765625,49.7021942808514,5.35011702488095,6.77790832519531,26,1,0,0,1,0.285263061523438,31.2805480957031,2,1,1,45.2178726196289,0,45.3444271087646,,,,,,,,,,,,,,,,,,,,,,,,,,,,,,,,,
,3865910109.20466,33.6590557098389,49999.4765625,0.176751645673584,0.000170223260137477,1,2,12.9061126708984,5.00625029526483,39.9999991059303,231.199128640334,33.9070783549916,1000,-4.38590802379673E-5,,,,,,,,,,,,,,,,,,,,,33.4632873535156,33.8548240661621,49999.4765625,49999.4765625,49.7498736205245,5.35232382878661,6.55994653701782,26,1,0,0,1,0.283966064453125,30.7917900085449,2,1,1,33.4632873535156,0,33.6590557098389,,,,,,,,,,,,,,,,,,,,,,,,,,,,,,,,,
,3865910177.85453,22.2438821792603,49999.4765625,0.235555057334721,0.000109623809388425,1,2,12.9061126708984,5.00627009406762,39.9900004267693,308.140834976795,45.0348000536803,1000,-0.000175465633225131,,,,,,,,,,,,,,,,,,,,,22.1372356414795,22.350528717041,49999.4765625,49999.4765625,49.8890034969476,5.35088091346011,6.17264175415039,26,1,0,0,1,0.276107788085938,30.7917900085449,2,1,1,22.1372356414795,0,22.2438821792603,,,,,,,,,,,,,,,,,,,,,,,,,,,,,,,,,
,3865910246.07345,11.1487698554993,49999.4765625,0.313863124932875,0.00391349405458155,1,2,12.9061126708984,5.00633656286018,39.9699993431568,410.402090270516,61.2658878900132,1000,0.000728395805041049,,,,,,,,,,,,,,,,,,,,,10.9817962646484,11.3157434463501,49999.4765625,49999.4765625,49.9988223038995,5.35227278110309,5.1115870475769,26,1,0,0,1,0.285797119140625,31.2805480957031,2,1,1,10.9817962646484,0,11.1487698554993,,,,,,,,,,,,,,,,,,,,,,,,,,,,,,,,,
,3865910316.61223,2.31239557266235,49999.4765625,0.392919851857434,6.44979989569219E-5,1,2,12.9061126708984,5.00646825341147,39.9699993431568,513.977695254146,75.4517100832948,1000,-4.28361949958933E-5,,,,,,,,,,,,,,,,,,,,,2.30930733680725,2.31548380851746,49999.4765625,49999.4765625,50.5959864925919,5.35554624832498,2.87650942802429,26,1,0,0,1,0.28472900390625,31.2805480957031,6,1,1,2.30930733680725,0,2.31239557266235,,,,,,,,,,,,,,,,,,,,,,,,,,,,,,,,,
,3865910387.2499,2.27435719966888,49999.4765625,0.393030482420073,6.67019920429234E-5,1,2,12.9061126708984,5.00645385217461,39.9699993431568,514.12812250381,75.4196904861745,1000,-8.33353992922937E-5,,,,,,,,,,,,,,,,,,,,,2.27393293380737,2.2747814655304,49999.4765625,49999.4765625,50.5912967214765,5.35606835205799,2.66724872589111,26,1,0,0,1,0.284652709960938,31.7693061828613,6,1,1,2.27393293380737,0,2.27435719966888,,,,,,,,,,,,,,,,,,,,,,,,,,,,,,,,,
,3865910451.73758,2.13123083114624,49999.4765625,0.393713613903607,7.39955469696577E-5,1,2,12.9061126708984,5.00638802160273,39.9699993431568,515.028181334549,75.4410280686316,1000,-0.000166321776281781,,,,,,,,,,,,,,,,,,,,,2.13095569610596,2.13150596618652,49999.4765625,49999.4765625,50.6350679185534,5.35610027621449,2.5863139629364,26,1,0,0,1,0.277252197265625,30.7917900085449,2,1,1,2.13150596618652,0,2.13123083114624,,,,,,,,,,,,,,,,,,,,,,,,,,,,,,,,,
,3865910518.37049,2.16860222816467,49999.4765625,0.393599975445191,6.82633013607223E-5,1,2,12.9061126708984,5.00638416053144,39.9699993431568,514.870237140837,75.4786293859476,1000,-0.000120818653046261,,,,,,,,,,,,,,,,,,,,,2.16676664352417,2.17043781280518,49999.4765625,49999.4765625,50.6694595733996,5.35615511939013,2.59913969039917,26,1,0,0,1,0.276718139648438,31.2805480957031,2,1,1,2.16676664352417,0,2.16860222816467,,,,,,,,,,,,,,,,,,,,,,,,,,,,,,,,,
,3865910586.58516,1.99919617176056,49999.4765625,0.394044802751945,7.8223710494398E-5,1,2,12.9061126708984,5.0063726532277,39.9699993431568,515.44537761475,75.5982885979768,1000,-9.4503485804556E-5,,,,,,,,,,,,,,,,,,,,,1.99915099143982,1.9992413520813,49999.4765625,49999.4765625,50.6686779448804,5.35603660474195,2.49278664588928,26,1,0,0,1,0.275650024414062,31.7693061828613,5,1,1,1.9992413520813,0,1.99919617176056,,,,,,,,,,,,,,,,,,,,,,,,,,,,,,,,,
,3865911034.72378,18.0293388366699,26.2118682861328,0.000401272402389267,5.9601180490601E-7,1,5,12.9061126708984,5.00624627780387,39.9699993431568,0.524931156501804,0.0766420180614822,10,-3.56315291963756E-7,,,,,,,,,,,,,,,,,,,,,18.0293388366699,18.0293388366699,26.2118682861328,26.2118682861328,49.8385884574572,5.35083827085889,5.41715812683105,65,1,0,0,1,0.276107788085938,30.7917900085449,2,1,1,18.0293388366699,0,18.0293388366699,,,,,,,,,,,,,,,,,,,,,,,,,,,,,,,,,
,3865911234.34725,49.0196838378906,26.2118682861328,0.000213931811625485,6.8072129584579E-8,1,5,12.9061126708984,5.00610154474524,39.9800017476082,0.279850095660279,0.0408386187120551,1,-2.05381643577374E-7,,,,,,,,,,,,,,,,,,,,,49.0196838378906,49.0196838378906,26.2118682861328,26.2118682861328,49.7959897031591,5.35088482224634,6.37934017181396,65,1,0,0,1,0.27618408203125,30.7917900085449,2,1,1,49.0196838378906,0,49.0196838378906,,,,,,,,,,,,,,,,,,,,,,,,,,,,,,,,,
,3865911429.4062,80.0144119262695,26.2118682861328,0.000153356154616942,4.50810091347389E-8,1,5,12.9061126708984,5.00581510056277,40.0200001895428,0.200590508108048,0.029292009136822,1,-1.32428682694457E-7,,,,,,,,,,,,,,,,,,,,,80.0144119262695,80.0144119262695,26.2118682861328,26.2118682861328,49.788955046486,5.35228344882364,6.6817307472229,64,1,64,0,0,0.267868041992187,31.7693061828613,2,1,1,80.0144119262695,0,80.0144119262695,,,,,,,,,,,,,,,,,,,,,,,,,,,,,,,,,
,3865911617.64724,111.020393371582,26.2118682861328,0.000112727955491327,3.1962537574917E-8,1,5,12.9061126708984,5.00512657438125,40.0899983942509,0.147431414605539,0.0214517868945722,1,-1.55338606079366E-7,,,,,,,,,,,,,,,,,,,,,111.020393371582,111.020393371582,26.2118682861328,26.2118682861328,49.8280364724476,5.35534610782178,6.83213710784912,65,1,0,0,1,0.270004272460938,30.7917900085449,2,1,1,111.020393371582,0,111.020393371582,,,,,,,,,,,,,,,,,,,,,,,,,,,,,,,,,
,3865911805.41832,142.05290222168,26.2118682861328,7.94918504016164E-5,2.58242554907014E-8,1,5,12.9061126708984,5.00392166567651,40.1699990034103,0.10393333451211,0.0150890918058287,1,-1.34685447239536E-7,,,,,,,,,,,,,,,,,,,,,142.05290222168,142.05290222168,26.2118682861328,26.2118682861328,49.8221742585533,5.36079272711884,6.94157791137695,63,1,64,0,0,0.270233154296875,31.2805480957031,2,1,1,142.05290222168,0,142.05290222168,,,,,,,,,,,,,,,,,,,,,,,,,,,,,,,,,
,3865912023.41053,178.104873657227,26.2118682861328,5.18029699475839E-5,1.82123018826535E-8,1,5,12.9061126708984,5.00278111705822,40.2900017797947,0.0677087914651211,0.00983354737369695,1,-8.51096732409212E-8,,,,,,,,,,,,,,,,,,,,,178.104873657227,178.104873657227,26.2118682861328,26.2118682861328,49.8475771854284,5.36596674412259,7.03041839599609,64,1,64,0,0,0.271453857421875,31.7693061828613,2,1,1,178.104873657227,0,178.104873657227,,,,,,,,,,,,,,,,,,,,,,,,,,,,,,,,,
,3865912210.50192,209.119552612305,26.2118682861328,3.56370591150745E-5,1.31567185204651E-8,1,5,12.9061126708984,5.00219404906816,40.4199995100498,0.0465721564498404,0.00675975660714021,1,-6.15887034008296E-8,,,,,,,,,,,,,,,,,,,,,209.119552612305,209.119552612305,26.2118682861328,26.2118682861328,49.7424481495918,5.36825712454259,7.11611366271973,64,1,64,0,0,0.27557373046875,30.7917900085449,2,1,1,209.140838623047,0,209.119552612305,,,,,,,,,,,,,,,,,,,,,,,,,,,,,,,,,
,3865912397.41606,240.04118347168,26.2118682861328,2.50112872858812E-5,1.12054310479743E-8,1,5,12.9061126708984,5.00085802716848,40.5699983239174,0.0326738035509375,0.00474163149881453,1,-4.38521099053114E-8,,,,,,,,,,,,,,,,,,,,,240.04118347168,240.04118347168,26.2118682861328,26.2118682861328,49.7881734179668,5.37079365913189,7.26276588439941,64,1,64,0,0,0.271148681640625,31.2805480957031,2,1,1,240.04118347168,0,240.04118347168,,,,,,,,,,,,,,,,,,,,,,,,,,,,,,,,,
,3865912584.9096,271.250457763672,26.2118682861328,1.76241369358721E-5,7.81278023156836E-9,1,5,12.9061126708984,5.00134417357065,40.7399982213974,0.0230259959568215,0.00334603636254455,1,-2.75290409509847E-8,,,,,,,,,,,,,,,,,,,,,271.250457763672,271.250457763672,26.2118682861328,26.2118682861328,49.7983345887168,5.37318869043521,7.42747831344605,65,1,0,0,1,0.27496337890625,31.2805480957031,2,1,1,271.250457763672,0,271.250457763672,,,,,,,,,,,,,,,,,,,,,,,,,,,,,,,,,
,3865914273.72612,2.00006985664368,48749.396484375,0.390399021073586,7.34512056585937E-5,1,2,12.9061126708984,4.97545475742062,39.9600006639957,506.283330248652,74.0703173447956,1000,-0.000232691605488197,,,,,,,,,,,,,,,,,,,,,2.00006985664368,2.00006985664368,48744.40234375,48754.390625,50.6143547627938,5.35654072493282,2.55855107307434,26,1,0,0,1,0.268173217773438,30.3030319213867,1,6,1,2.00006985664368,0,2.00006985664368,,,,,,,,,,,,,,,,,,,,,,,,,,,,,,,,,
,3865914358.37162,1.99974972009659,40298.099609375,0.359315343936614,5.53563527659616E-5,1,2,12.9061126708984,4.9753910703113,39.9600006639957,465.929941350278,68.4069560439405,1000,-3.26531745150587E-5,,,,,,,,,,,,,,,,,,,,,1.99974656105042,1.99975287914276,40208.08203125,40388.1171875,50.5021910702842,5.35607140875782,2.55507850646973,26,1,0,0,1,0.26824951171875,30.3030319213867,1,6,1,1.99975287914276,0,1.99974972009659,,,,,,,,,,,,,,,,,,,,,,,,,,,,,,,,,
,3865914426.89416,1.99982362985611,33454.3828125,0.330271143804791,6.39981572447363E-5,1,2,12.9061126708984,4.9753685223732,39.9600006639957,428.268921227068,62.8512885774508,1000,-4.99037434062182E-5,,,,,,,,,,,,,,,,,,,,,1.99975776672363,1.99988949298859,33359.46484375,33549.30078125,50.2880248560149,5.35530189735406,2.54354000091553,26,1,0,0,1,0.268707275390625,30.7917900085449,1,6,1,1.99975776672363,0,1.99982362985611,,,,,,,,,,,,,,,,,,,,,,,,,,,,,,,,,
,3865914495.4413,1.99968206882477,26615.490234375,0.29580442543686,8.34306492131871E-5,1,2,12.9061126708984,4.97533718933993,39.9600006639957,383.598520168256,56.1102817686437,1000,-0.000184606681533067,,,,,,,,,,,,,,,,,,,,,1.99967610836029,1.99968802928925,26520.84765625,26710.1328125,50.1762519777649,5.35421783817787,2.54900145530701,26,1,0,0,1,0.26947021484375,30.7917900085449,1,6,1,1.99999356269836,0,1.99968206882477,,,,,,,,,,,,,,,,,,,,,,,,,,,,,,,,,
,3865914563.95365,1.99977892637253,19771.591796875,0.253225323012481,8.45494266589679E-5,1,2,12.9061126708984,4.97540859336409,39.9600006639957,328.360712912254,48.2248250275808,1000,-1.12931059396017E-5,,,,,,,,,,,,,,,,,,,,,1.99970495700836,1.99985289573669,19691.583984375,19851.599609375,50.0433751294957,5.35316389043789,2.54537034034729,26,1,0,0,1,0.269241333007813,30.3030319213867,1,6,1,1.99970495700836,0,1.99977892637253,,,,,,,,,,,,,,,,,,,,,,,,,,,,,,,,,
,3865914632.68262,1.99990040063858,12913.150390625,0.198150719523984,9.65710303277464E-5,1,2,12.9061126708984,4.97532223170635,39.9600006639957,256.958324254851,37.6000916942874,1000,-0.00011316142251709,,,,,,,,,,,,,,,,,,,,,1.9996737241745,2.00012707710266,12853.1796875,12973.12109375,49.829599729486,5.352497348625,2.55273699760437,26,1,0,0,1,0.269927978515625,31.2805480957031,1,6,1,1.9996737241745,0,1.99990040063858,,,,,,,,,,,,,,,,,,,,,,,,,,,,,,,,,
,3865914699.16358,1.99999129772186,6268.10278320312,0.124347737330409,0.000148127680560462,1,2,12.9061126708984,4.97533288893522,39.9600006639957,161.247959606383,23.6260204517274,1000,-4.76126969021889E-5,,,,,,,,,,,,,,,,,,,,,1.99995994567871,2.00002264976501,6208.1513671875,6328.05419921875,49.8354619433803,5.35210012453034,2.54276967048645,26,1,0,0,1,0.268630981445313,30.7917900085449,1,6,1,2.00002264976501,0,1.99999129772186,,,,,,,,,,,,,,,,,,,,,,,,,,,,,,,,,
,3865914771.56633,1.99981343746185,-972.960540771484,-0.0141719677596957,0.000269372818087297,1,2,12.9061126708984,4.97529291623242,39.9600006639957,-18.3762286498108,-2.69989606645826,100,-1.71232333071138E-7,,,,,,,,,,,,,,,,,,,,,1.99965715408325,1.99996972084045,-1087.69860839844,-858.222473144531,49.802242731313,5.35171960383333,2.54081058502197,26,1,0,0,1,0.26824951171875,30.7917900085449,1,6,1,1.99996972084045,0,1.99981343746185,,,,,,,,,,,,,,,,,,,,,,,,,,,,,,,,,
,3865914838.05519,1.99996972084045,-7615.97729492188,-0.133519242847674,0.000147455840502221,1,2,12.9061126708984,4.97526522628268,39.9600006639957,-173.103781358253,-25.5996639265133,100,-0.000127448128730469,,,,,,,,,,,,,,,,,,,,,1.99984192848206,2.00009751319885,-7725.908203125,-7506.04638671875,49.8292089152264,5.35190700832968,2.53655123710632,26,1,0,0,1,0.269927978515625,30.7917900085449,1,6,1,2.00009751319885,0,1.99996972084045,,,,,,,,,,,,,,,,,,,,,,,,,,,,,,,,,
,3865914924.5845,1.99993944168091,-16266.2768554687,-0.2245541881669,0.000147362982817662,1,2,12.9061126708984,4.97528770191266,39.9600006639957,-291.187321246792,-42.6623256597507,1000,8.77825960089011E-5,,,,,,,,,,,,,,,,,,,,,1.99984383583069,2.00003504753113,-16346.2421875,-16186.3115234375,49.9812356622168,5.35325677018374,2.5215048789978,26,1,0,0,1,0.269393920898438,31.2805480957031,1,6,1,2.00003504753113,0,1.99993944168091,,,,,,,,,,,,,,,,,,,,,,,,,,,,,,,,,
,3865914991.10406,1.99988859891891,-22922.0244140625,-0.272889079611536,8.2025514896194E-5,1,2,12.9061126708984,4.97531252694296,39.9600006639957,-353.866441060581,-51.8519441917224,1000,0.000101846484715152,,,,,,,,,,,,,,,,,,,,,1.99985480308533,1.9999223947525,-22996.88671875,-22847.162109375,50.0789392271207,5.35336476199201,2.50156545639038,26,1,0,0,1,0.268936157226562,30.7917900085449,1,6,1,1.9999223947525,0,1.99988859891891,,,,,,,,,,,,,,,,,,,,,,,,,,,,,,,,,
,3865915057.57843,1.99991077184677,-29579.287109375,-0.310972447440308,9.82432336725228E-5,1,2,12.9061126708984,4.97531969434822,39.9600006639957,-403.2203577626,-59.3004463556076,1000,-4.75290551967239E-5,,,,,,,,,,,,,,,,,,,,,1.99986696243286,1.99995458126068,-29654.38671875,-29504.1875,50.1633551071976,5.35371586761216,2.49167561531067,26,1,0,0,1,0.268478393554687,31.2805480957031,1,6,1,1.99986696243286,0,1.99991077184677,,,,,,,,,,,,,,,,,,,,,,,,,,,,,,,,,
,3865915124.07605,2.00021076202393,-36240.91796875,-0.342388063358193,8.58977403957624E-5,1,2,12.9061126708984,4.97539902256212,39.9600006639957,-443.985263820414,-65.1558830655542,1000,5.31556734497973E-5,,,,,,,,,,,,,,,,,,,,,1.99998426437378,2.00043725967407,-36316.19921875,-36165.63671875,50.3466469949573,5.35463609862752,2.48939871788025,26,1,0,0,1,0.268630981445313,31.2805480957031,1,6,1,1.99998426437378,0,2.00021076202393,,,,,,,,,,,,,,,,,,,,,,,,,,,,,,,,,
,3865915192.40111,1.99894237518311,-43083.91015625,-0.369836349142233,7.67241701087318E-5,1,2,12.9061126708984,4.97538105150579,39.9600006639957,-479.549405660348,-70.5590484871746,1000,-8.15205908739618E-5,,,,,,,,,,,,,,,,,,,,,1.9986435174942,1.99924123287201,-43178.9375,-42988.8828125,50.5123522410342,5.35525252288142,2.45999073982239,26,1,0,0,1,0.268936157226562,30.7917900085449,1,6,1,1.99924123287201,0,1.99894237518311,,,,,,,,,,,,,,,,,,,,,,,,,,,,,,,,,
,3865915260.87757,2.00018441677094,-49921.73046875,-0.39359089974732,6.68175094605823E-5,1,2,12.9061126708984,4.97538346040982,39.9600006639957,-510.383042302959,-74.8740978620352,1000,8.05934663252518E-5,,,,,,,,,,,,,,,,,,,,,1.99958801269531,2.00078082084656,-49992.93359375,-49850.52734375,50.6749309730342,5.35625438991502,2.445396900177,26,1,0,0,1,0.269317626953125,31.2805480957031,1,6,1,1.99958801269531,0,2.00018441677094,,,,,,,,,,,,,,,,,,,,,,,,,,,,,,,,,
,3865915329.4952,1.99995744228363,-43738.759765625,-0.372242296931307,8.31556358475707E-5,1,2,12.9061126708984,4.97537571493486,39.9600006639957,-482.656887076768,-71.0960294596334,1000,-0.000142258371937492,,,,,,,,,,,,,,,,,,,,,1.99976897239685,2.00014591217041,-43843.51953125,-43634,50.564330537563,5.35559712806433,2.43003368377686,26,1,0,0,1,0.27008056640625,31.2805480957031,5,6,1,1.99976897239685,0,1.99995744228363,,,,,,,,,,,,,,,,,,,,,,,,,,,,,,,,,
,3865915396.00982,1.99998337030411,-37096.41015625,-0.346438872160321,7.76216803777759E-5,1,2,12.9061126708984,4.97531611968259,39.9600006639957,-449.244833175716,-65.8074868609529,1000,0.000144565145728329,,,,,,,,,,,,,,,,,,,,,1.99995458126068,2.00001215934753,-37206.328125,-36986.4921875,50.3704866647938,5.35445360811743,2.42701244354248,26,1,0,0,1,0.268478393554687,31.7693061828613,1,6,1,2.00001215934753,0,1.99998337030411,,,,,,,,,,,,,,,,,,,,,,,,,,,,,,,,,
,3865915462.51779,2.00011485815048,-30458.46875,-0.31608608122579,7.89293912402564E-5,1,2,12.9061126708984,4.9752947365597,39.9600006639957,-409.852779103849,-60.2427893016493,1000,-2.33475981637293E-5,,,,,,,,,,,,,,,,,,,,,1.99986946582794,2.00036025047302,-30568.19140625,-30348.74609375,50.2016549046399,5.35429778387802,2.42671537399292,26,1,0,0,1,0.268478393554687,30.7917900085449,1,6,1,2.00036025047302,0,2.00011485815048,,,,,,,,,,,,,,,,,,,,,,,,,,,,,,,,,
,3865915529.04034,1.9999908208847,-23820.697265625,-0.279688947457428,8.32543305012438E-5,1,2,12.9061126708984,4.97525235511181,39.9600006639957,-362.658768429204,-53.2735561402939,1000,3.76614147698925E-6,,,,,,,,,,,,,,,,,,,,,1.99997591972351,2.0000057220459,-23940.474609375,-23700.919921875,50.0894912121303,5.35344486318686,2.41954183578491,26,1,0,0,1,0.268936157226562,31.2805480957031,1,6,1,2.0000057220459,0,1.9999908208847,,,,,,,,,,,,,,,,,,,,,,,,,,,,,,,,,
,3865915595.54964,2.00025987625122,-17177.5439453125,-0.234360354955758,9.67172572173644E-5,1,2,12.9061126708984,4.97528901725297,39.9600006639957,-303.906480569098,-44.5046604029969,1000,0.000107598456798276,,,,,,,,,,,,,,,,,,,,,2.00008296966553,2.00043678283691,-17292.263671875,-17062.82421875,49.9867070618514,5.3527120894418,2.4259352684021,26,1,0,0,1,0.27008056640625,31.2805480957031,1,6,1,2.00043678283691,0,2.00025987625122,,,,,,,,,,,,,,,,,,,,,,,,,,,,,,,,,
,3865915662.09587,2.00002002716064,-10536.90234375,-0.174838971159431,0.000118640286554103,1,2,12.9061126708984,4.97527857217617,39.9600006639957,-226.709144912945,-33.2858829113892,1000,1.52292960088631E-5,,,,,,,,,,,,,,,,,,,,,1.99994492530823,2.00009512901306,-10651.947265625,-10421.857421875,49.8065416881687,5.35242897782191,2.42876529693604,26,1,0,0,1,0.26885986328125,31.2805480957031,1,6,1,1.99994492530823,0,2.00002002716064,,,,,,,,,,,,,,,,,,,,,,,,,,,,,,,,,
,3865915730.60659,1.99999636411667,-3687.9072265625,-0.0865775091094982,0.000186254782977386,1,2,12.9061126708984,4.97522644181574,39.9600006639957,-112.265179429935,-16.4549623668088,1000,2.87040167045449E-5,,,,,,,,,,,,,,,,,,,,,1.99997246265411,2.00002026557922,-3747.99633789063,-3627.81811523438,49.8163120446591,5.35208466781262,2.4319531917572,24,1,68,0,0,0.268325805664062,31.2805480957031,1,6,1,2.00002026557922,0,1.99999636411667,,,,,,,,,,,,,,,,,,,,,,,,,,,,,,,,,
,3865915821.03478,1.99959170818329,5353.28247070313,0.100566622062682,0.000171472479499116,1,2,12.9061126708984,4.97524220335396,39.9600006639957,130.384659823196,19.2554324643565,100,7.58687527969725E-5,,,,,,,,,,,,,,,,,,,,,1.9993622303009,1.99982118606567,5248.3662109375,5458.19873046875,49.7823112040726,5.35207938314926,2.42232394218445,26,1,0,0,1,0.277938842773438,31.7693061828613,1,6,1,1.99982118606567,0,1.99959170818329,,,,,,,,,,,,,,,,,,,,,,,,,,,,,,,,,
,3865915909.88688,2.00004553794861,14239.1752929688,0.206803302344342,0.000101861621628371,1,2,12.9061126708984,4.97528760432464,39.9600006639957,268.151820199447,39.4076159552989,1000,9.94740089131282E-6,,,,,,,,,,,,,,,,,,,,,2.00001883506775,2.00007224082947,14179.080078125,14299.2705078125,49.8925208252841,5.3524795566805,2.4096622467041,26,1,0,0,1,0.269775390625,30.7917900085449,1,6,1,2.00001883506775,0,2.00004553794861,,,,,,,,,,,,,,,,,,,,,,,,,,,,,,,,,
,3865915976.03028,2.00044751167297,20855.736328125,0.259267038415043,9.71034571622755E-5,1,2,12.9061126708984,4.97530384370151,39.9600006639957,336.184309338179,49.3795244779486,1000,-7.27166700945239E-6,,,,,,,,,,,,,,,,,,,,,2.00032258033752,2.00057244300842,20760.7421875,20950.73046875,50.0844106267553,5.35300391587485,2.39462876319885,26,1,0,0,1,0.269088745117187,30.7917900085449,1,6,1,2.00032258033752,0,2.00044751167297,,,,,,,,,,,,,,,,,,,,,,,,,,,,,,,,,
,3865916044.53489,2.00005412101746,27710.43359375,0.301141522313304,7.28825783679233E-5,1,2,12.9061126708984,4.97536980492899,39.9600006639957,390.500108278001,57.2807644424266,1000,-6.6414821709198E-5,,,,,,,,,,,,,,,,,,,,,1.99984335899353,2.00026488304138,27615.337890625,27805.529296875,50.0851922552745,5.35451803369378,2.39703679084778,26,1,0,0,1,0.270004272460938,31.2805480957031,1,6,1,2.00026488304138,0,2.00005412101746,,,,,,,,,,,,,,,,,,,,,,,,,,,,,,,,,
,3865916111.0255,1.99919050931931,34369.0703125,0.33417540898356,8.53868204336283E-5,1,2,12.9061126708984,4.97539497698938,39.9600006639957,433.329799667288,63.6294651962106,1000,-2.37249885125664E-5,,,,,,,,,,,,,,,,,,,,,1.99909317493439,1.99928784370422,34278.78125,34459.359375,50.2653576289572,5.35460978675978,2.38740968704224,26,1,0,0,1,0.26824951171875,31.2805480957031,1,6,1,1.99909317493439,0,1.99919050931931,,,,,,,,,,,,,,,,,,,,,,,,,,,,,,,,,
,3865916179.59024,2.00019800662994,41243.4375,0.362818691765344,8.64625079209181E-5,1,2,12.9061126708984,4.97542685210353,39.9600006639957,470.459714199795,69.1960315120725,1000,6.06530883976447E-5,,,,,,,,,,,,,,,,,,,,,2.00011372566223,2.00028228759766,41143.3828125,41343.4921875,50.5021910702842,5.35476014158776,2.38297367095947,26,1,0,0,1,0.2679443359375,31.7693061828613,1,6,1,2.00011372566223,0,2.00019800662994,,,,,,,,,,,,,,,,,,,,,,,,,,,,,,,,,
,3865916248.19073,1.9997131228447,48112.953125,0.38730926975023,7.13858150528909E-5,1,2,12.9061126708984,4.97542046986937,39.9600006639957,502.225748825427,73.7952163725427,1000,9.62751276250128E-6,,,,,,,,,,,,,,,,,,,,,1.99954009056091,1.99988615512848,48037.6328125,48188.2734375,50.6209986052073,5.35574115593188,2.38258457183838,26,1,0,0,1,0.268478393554687,30.7917900085449,1,6,1,1.99988615512848,0,1.9997131228447,,,,,,,,,,,,,,,,,,,,,,,,,,,,,,,,,
,3865916745.88173,21.9175786972046,26.4375095367432,0.000249193645568937,1.87854011661937E-7,1,5,12.9061126708984,5.00599650755332,39.9600006639957,0.325917772357153,0.0479070590679806,1,1.95855357082202E-8,,,,,,,,,,,,,,,,,,,,,21.5557994842529,22.2793579101562,26.4375095367432,26.4375095367432,49.7748857331399,5.35045646885277,5.64053583145142,65,1,0,0,1,0.286712646484375,32.7468223571777,2,1,1,22.2793579101562,0,21.9175786972046,,,,,,,,,,,,,,,,,,,,,,,,,,,,,,,,,
,3865916938.38745,52.0926170349121,26.4375095367432,0.000172808166082206,5.02544960463625E-8,1,5,12.9061126708984,5.00587997852542,39.9800017476082,0.226041859085932,0.0329812613995114,1,-1.69721641744289E-7,,,,,,,,,,,,,,,,,,,,,52.0926170349121,52.0926170349121,26.4375095367432,26.4375095367432,49.7389308212553,5.35102333799517,6.38271808624268,64,1,64,0,0,0.276031494140625,30.7917900085449,2,1,1,52.0926170349121,0,52.0926170349121,,,,,,,,,,,,,,,,,,,,,,,,,,,,,,,,,
,3865917133.17463,83.0331039428711,26.4375095367432,0.00012815052013673,3.38920428976251E-8,1,5,12.9061126708984,5.0055767064139,40.0299988687038,0.167612821639179,0.0244585147254671,1,-1.23987580728428E-7,,,,,,,,,,,,,,,,,,,,,83.0331039428711,83.0331039428711,26.4375095367432,26.4375095367432,49.7232982508706,5.35288206492932,6.67943239212036,64,1,64,0,0,0.2679443359375,30.3030319213867,2,1,1,83.0331039428711,0,83.0331039428711,,,,,,,,,,,,,,,,,,,,,,,,,,,,,,,,,
,3865917321.44838,114.015281677246,26.4375095367432,9.53844430505176E-5,2.79253006522665E-8,1,5,12.9061126708984,5.00469996922525,40.1000007987022,0.124732887631295,0.0181554097463881,1,-1.2669311990746E-7,,,,,,,,,,,,,,,,,,,,,114.015281677246,114.015281677246,26.4375095367432,26.4375095367432,49.753390948861,5.35682273937703,6.83301782608032,63,1,64,0,0,0.268936157226562,31.2805480957031,2,1,1,114.015281677246,0,114.015281677246,,,,,,,,,,,,,,,,,,,,,,,,,,,,,,,,,
,3865917509.55524,145.192626953125,26.4375095367432,6.83903927654143E-5,2.12678659305879E-8,1,5,12.9061126708984,5.00360621694197,40.1800014078617,0.0894074800955351,0.0130019438179406,1,-9.96031900542769E-8,,,,,,,,,,,,,,,,,,,,,145.181549072266,145.203704833984,26.4375095367432,26.4375095367432,49.7193901082745,5.36192346656322,6.91864013671875,64,1,64,0,0,0.270156860351562,31.7693061828613,2,1,1,145.203704833984,0,145.192626953125,,,,,,,,,,,,,,,,,,,,,,,,,,,,,,,,,
,3865917696.34191,176.151000976562,26.4375095367432,4.93883449568519E-5,1.65123250048575E-8,1,5,12.9061126708984,5.00249969697862,40.2900017797947,0.0645471941526332,0.00937779507250485,1,-7.8582967762915E-8,,,,,,,,,,,,,,,,,,,,,176.151000976562,176.151000976562,26.4375095367432,26.4375095367432,49.8440598570918,5.36581523240143,6.98852682113647,64,1,64,0,0,0.27435302734375,31.2805480957031,2,1,1,176.151000976562,0,176.151000976562,,,,,,,,,,,,,,,,,,,,,,,,,,,,,,,,,
,3865917883.75882,207.189270019531,26.4375095367432,3.5125563652293E-5,1.31453331771733E-8,1,5,12.9061126708984,5.00152876458091,40.4100008308887,0.0458937015778631,0.0066714396355675,1,-5.30907820141362E-8,,,,,,,,,,,,,,,,,,,,,207.189270019531,207.189270019531,26.4375095367432,26.4375095367432,49.8487496282072,5.37070395377996,7.08392906188965,64,1,64,0,0,0.279693603515625,31.7693061828613,2,1,1,207.189270019531,0,207.189270019531,,,,,,,,,,,,,,,,,,,,,,,,,,,,,,,,,
,3865918069.20925,238.019165039062,26.4375095367432,2.53184390210884E-5,9.97625030626518E-9,1,5,12.9061126708984,5.0003969020183,40.5599996447563,0.0330697603525884,0.00480620843915984,1,-3.90554113510104E-8,,,,,,,,,,,,,,,,,,,,,238.019165039062,238.019165039062,26.4375095367432,26.4375095367432,49.8929116395437,5.37523957880725,7.30307912826538,63,1,64,0,0,0.273818969726562,31.2805480957031,2,1,1,238.019165039062,0,238.019165039062,,,,,,,,,,,,,,,,,,,,,,,,,,,,,,,,,
,3865918256.37909,269.015563964844,26.4375095367432,1.86306091355439E-5,9.00152371515624E-9,1,5,12.9061126708984,5.00069839412663,40.7200008630753,0.0243372259109864,0.00353190887452385,1,-3.26020465984781E-8,,,,,,,,,,,,,,,,,,,,,269.015563964844,269.015563964844,26.4375095367432,26.4375095367432,49.8444506713514,5.37451019034262,7.68645334243774,65,1,0,0,1,0.277099609375,32.7468223571777,2,1,1,269.015563964844,0,269.015563964844,,,,,,,,,,,,,,,,,,,,,,,,,,,,,,,,,
,3865918524.97734,299.942657470703,26.4375095367432,1.3291010969171E-5,6.73757809086701E-9,1,5,12.9061126708984,5.00148101885492,40.8999994397163,0.0173677446968386,0.00250762292679283,1,-3.28892782393704E-8,,,,,,,,,,,,,,,,,,,,,299.942657470703,299.942657470703,26.4375095367432,26.4375095367432,49.758471534236,5.37264757603175,7.38086032867432,65,1,0,0,1,0.27740478515625,31.2805480957031,1,1,1,299.942657470703,0,299.942657470703,,,,,,,,,,,,,,,,,,,,,,,,,,,,,,,,,
,3865919223.94281,270.941680908203,26.4500465393066,2.03429686364219E-5,7.89971704077176E-9,1,5,12.9061126708984,4.99026984138357,40.7500006258488,0.0264957513743157,0.0038498840767342,1,-3.20479687751636E-8,,,,,,,,,,,,,,,,,,,,,270.941680908203,270.941680908203,26.4500465393066,26.4500465393066,49.763552119611,5.3755556112971,7.89138650894165,63,1,64,0,0,0.277023315429687,31.2805480957031,2,1,1,270.941680908203,0,270.941680908203,,,,,,,,,,,,,,,,,,,,,,,,,,,,,,,,,
,3865919411.0228,239.963363647461,26.4500465393066,2.27804677703712E-5,7.12563178752793E-9,1,5,12.9061126708984,4.99155013969079,40.6100004911423,0.0296796660630564,0.00432289626268576,1,-2.80835440081305E-8,,,,,,,,,,,,,,,,,,,,,239.963363647461,239.963363647461,26.4500465393066,26.4500465393066,49.7424481495918,5.37235135000064,7.72598791122436,65,1,0,0,1,0.272674560546875,31.2805480957031,2,1,1,239.963363647461,0,239.963363647461,,,,,,,,,,,,,,,,,,,,,,,,,,,,,,,,,
,3865919598.04282,208.880432128906,26.4500465393066,2.53284330591945E-5,6.8702281013562E-9,1,5,12.9061126708984,4.99074864328101,40.4900014400482,0.0329926254226071,0.00480013775656649,1,-3.52067351325477E-8,,,,,,,,,,,,,,,,,,,,,208.880432128906,208.880432128906,26.4500465393066,26.4500465393066,49.651779241361,5.37156335817485,7.61643218994141,65,1,0,0,1,0.275726318359375,31.2805480957031,2,1,1,208.880432128906,0,208.880432128906,,,,,,,,,,,,,,,,,,,,,,,,,,,,,,,,,
,3865919782.4794,177.988433837891,26.4500465393066,2.83497526379694E-5,7.52711001034614E-9,1,5,12.9061126708984,4.9913408090845,40.3899997472763,0.0369354252781661,0.00536610538414398,1,-4.51755442748279E-8,,,,,,,,,,,,,,,,,,,,,177.988433837891,177.988433837891,26.4500465393066,26.4500465393066,49.8057600596495,5.37106096696414,7.52239418029785,64,1,64,0,0,0.2734375,31.7693061828613,2,1,1,177.988433837891,0,177.988433837891,,,,,,,,,,,,,,,,,,,,,,,,,,,,,,,,,
,3865919970.00366,146.952102661133,26.4500465393066,3.12974566879267E-5,6.72925566367044E-9,1,5,12.9061126708984,4.99161754075592,40.2900017797947,0.0407782793492688,0.00592947402724111,1,-4.60652850005953E-8,,,,,,,,,,,,,,,,,,,,,146.952102661133,146.952102661133,26.4500465393066,26.4500465393066,49.738149192736,5.36982122794554,7.43513298034668,64,1,64,0,0,0.272064208984375,30.3030319213867,2,1,1,146.952102661133,0,146.952102661133,,,,,,,,,,,,,,,,,,,,,,,,,,,,,,,,,
,3865920156.24801,115.889129638672,26.4500465393066,3.39969539664012E-5,6.63848352726222E-9,1,5,12.9061126708984,4.99318901646801,40.2100011706352,0.0443158429089097,0.00643861126791394,1,-5.39839689302098E-8,,,,,,,,,,,,,,,,,,,,,115.889129638672,115.889129638672,26.4500465393066,26.4500465393066,49.8108406450245,5.36304411903694,7.33175468444824,63,1,64,0,0,0.27069091796875,28.8367557525635,2,1,1,115.889129638672,0,115.889129638672,,,,,,,,,,,,,,,,,,,,,,,,,,,,,,,,,
,3865920340.82967,84.9905014038086,26.4500465393066,3.69702266145452E-5,7.23974708685128E-9,1,5,12.9061126708984,4.99462558232651,40.1199981570244,0.0482112366286593,0.00700305523113496,1,-5.98426150003231E-8,,,,,,,,,,,,,,,,,,,,,84.9905014038086,84.9905014038086,26.4500465393066,26.4500465393066,49.7608164197937,5.35645662607038,7.20949840545654,65,1,0,0,1,0.28900146484375,31.2805480957031,2,1,1,84.9905014038086,0,84.9905014038086,,,,,,,,,,,,,,,,,,,,,,,,,,,,,,,,,
,3865920522.64939,53.9960441589355,26.4500465393066,4.00996606729306E-5,7.62751531339043E-9,1,5,12.9061126708984,4.99488424414223,40.0400012731552,0.0522952721876896,0.00760128392320515,1,-6.11602556890516E-8,,,,,,,,,,,,,,,,,,,,,53.9960441589355,53.9960441589355,26.4500465393066,26.4500465393066,49.7174360369764,5.35534818903557,6.98062181472778,65,1,0,0,1,0.278778076171875,31.2805480957031,2,1,1,53.9960441589355,0,53.9960441589355,,,,,,,,,,,,,,,,,,,,,,,,,,,,,,,,,
,3865920704.61171,22.985445022583,26.4500465393066,4.34024675523162E-5,9.64363202018227E-9,1,5,12.9061126708984,4.99497690676669,39.9999991059303,0.056602822381133,0.00823588121826103,1,-5.98291042288357E-8,,,,,,,,,,,,,,,,,,,,,22.985445022583,22.985445022583,26.4500465393066,26.4500465393066,49.8237375155918,5.35461438077767,6.39247417449951,65,1,0,0,1,0.278701782226562,31.2805480957031,2,1,1,22.985445022583,0,22.985445022583,,,,,,,,,,,,,,,,,,,,,,,,,,,,,,,,,
,3865921310.19616,10.0123682022095,26.4500465393066,4.69109785232705E-5,1.39851050066293E-8,1,5,12.9061126708984,4.99478108121451,39.9600006639957,0.0611741952379055,0.00890692639258275,1,-6.02374883161693E-8,,,,,,,,,,,,,,,,,,,,,10.0123682022095,10.0123682022095,26.4500465393066,26.4500465393066,49.8745433693418,5.35620353850081,4.77650880813599,65,1,0,0,1,0.279159545898438,31.2805480957031,6,1,1,10.0123682022095,0,10.0123682022095,,,,,,,,,,,,,,,,,,,,,,,,,,,,,,,,,
,3865921510.26384,41.0576591491699,26.4500465393066,4.16470129597334E-5,7.53581431697407E-9,1,5,12.9061126708984,4.99466612944289,39.9699993431568,0.0543114675882214,0.00788344183221923,1,-7.17077971427308E-8,,,,,,,,,,,,,,,,,,,,,41.0576591491699,41.0576591491699,26.4500465393066,26.4500465393066,49.8077141309476,5.35649542444733,6.23919153213501,65,1,0,0,1,0.278167724609375,30.7917900085449,2,1,1,41.0576591491699,0,41.0576591491699,,,,,,,,,,,,,,,,,,,,,,,,,,,,,,,,,
,3865921705.96686,72.0113143920898,26.4500465393066,3.82251917007512E-5,6.6275659585865E-9,1,5,12.9061126708984,4.9942874493973,40.0100015103817,0.0498430135952119,0.00724033217878595,1,-6.16871887670778E-8,,,,,,,,,,,,,,,,,,,,,72.0113143920898,72.0113143920898,26.4500465393066,26.4500465393066,49.7182176654956,5.35891611247335,6.66288089752197,65,1,0,0,1,0.279922485351562,31.2805480957031,2,1,1,72.0113143920898,0,72.0113143920898,,,,,,,,,,,,,,,,,,,,,,,,,,,,,,,,,
,3865921896.50816,103.027290344238,26.4500465393066,3.46123308468996E-5,7.28109516301597E-9,1,5,12.9061126708984,4.99386793148367,40.0700010359287,0.0451273116823886,0.00655159435611945,1,-5.86526775903954E-8,,,,,,,,,,,,,,,,,,,,,103.027290344238,103.027290344238,26.4500465393066,26.4500465393066,49.7827020183322,5.3609690311365,6.84714651107788,65,1,0,0,1,0.271148681640625,31.2805480957031,2,1,1,103.027290344238,0,103.027290344238,,,,,,,,,,,,,,,,,,,,,,,,,,,,,,,,,
,3865922084.03828,134.062927246094,26.4500465393066,3.14491733708883E-5,6.24109639680994E-9,1,5,12.9061126708984,4.99284711069648,40.1500016450882,0.0409899889193622,0.00596112963645304,1,-4.56338477203792E-8,,,,,,,,,,,,,,,,,,,,,134.062927246094,134.062927246094,26.4500465393066,26.4500465393066,49.8389792717168,5.36515779132517,6.93024158477783,65,1,0,0,1,0.270309448242187,30.7917900085449,2,1,1,134.062927246094,0,134.062927246094,,,,,,,,,,,,,,,,,,,,,,,,,,,,,,,,,
,3865922272.03746,165.161956787109,26.4500465393066,2.8168788128817E-5,6.36931447096526E-9,1,5,12.9061126708984,4.99194115689319,40.2499996125698,0.0367060091102389,0.0053316602569917,1,-4.57249820127675E-8,,,,,,,,,,,,,,,,,,,,,165.161956787109,165.161956787109,26.4500465393066,26.4500465393066,49.8319446150437,5.36711246897199,7.00632619857788,65,1,0,0,1,0.2716064453125,29.3255138397217,2,1,1,165.161956787109,0,165.161956787109,,,,,,,,,,,,,,,,,,,,,,,,,,,,,,,,,
,3865922457.73477,196.017547607422,26.4500465393066,2.49683023339783E-5,6.65194050466656E-9,1,5,12.9061126708984,4.99103184787185,40.3599999845028,0.0325284477132445,0.0047163613240048,1,-4.69161991457961E-8,,,,,,,,,,,,,,,,,,,,,196.017547607422,196.017547607422,26.4500465393066,26.4500465393066,49.8487496282072,5.37228340743956,7.09131193161011,65,1,0,0,1,0.277786254882813,31.7693061828613,2,1,1,196.017547607422,0,196.017547607422,,,,,,,,,,,,,,,,,,,,,,,,,,,,,,,,,
,3865922644.66084,227.022506713867,26.4500465393066,2.19776197508727E-5,6.89316055532906E-9,1,5,12.9061126708984,4.98969916766243,40.5000001192093,0.0286219398623833,0.00414681938274398,1,-4.36505441552109E-8,,,,,,,,,,,,,,,,,,,,,227.022506713867,227.022506713867,26.4500465393066,26.4500465393066,49.7268155792072,5.3769273938102,7.21912431716919,64,1,64,0,0,0.280075073242187,31.2805480957031,2,1,1,227.022506713867,0,227.022506713867,,,,,,,,,,,,,,,,,,,,,,,,,,,,,,,,,
,3865922831.93955,258.014587402344,26.4500465393066,1.9264848460952E-5,7.07866751902265E-9,1,5,12.9061126708984,4.98885736568623,40.6600013375282,0.025082154844547,0.00364051796612069,1,-3.33341224345329E-8,,,,,,,,,,,,,,,,,,,,,258.014587402344,258.014587402344,26.4500465393066,26.4500465393066,49.8100590165053,5.38098058950509,7.47243595123291,63,1,64,0,0,0.282058715820313,31.7693061828613,2,1,1,258.014587402344,0,258.014587402344,,,,,,,,,,,,,,,,,,,,,,,,,,,,,,,,,
,3865923018.55536,289.017150878906,26.4500465393066,1.68316859610516E-5,7.25385541253912E-9,1,5,12.9061126708984,4.98955827915214,40.8399999141693,0.0219188446309634,0.00317957384276478,1,-3.04848266897388E-8,,,,,,,,,,,,,,,,,,,,,289.017150878906,289.017150878906,26.4500465393066,26.4500465393066,49.7760581759187,5.37867048336148,7.40401315689087,63,1,64,0,0,0.2801513671875,30.7917900085449,2,1,1,289.017150878906,0,289.017150878906,,,,,,,,,,,,,,,,,,,,,,,,,,,,,,,,,
,3865923320.00083,300.006362915039,43851.732421875,0.0149175347809651,4.16719419484943E-6,1,2,12.9061126708984,4.99089815110607,40.8999994397163,19.4341592039907,2.81446833072926,100,-3.05319758422002E-5,,,,,,,,,,,,,,,,,,,,,300.006011962891,300.006713867188,43761.87890625,43941.5859375,49.7608164197937,5.37256691901135,7.42288017272949,24,1,68,0,0,0.273895263671875,31.2805480957031,1,6,1,300.006713867188,0,300.006362915039,,,,,,,,,,,,,,,,,,,,,,,,,,,,,,,,,
,3865923384.7228,300.004531860352,37387.79296875,0.0127490306626659,4.36499370274535E-6,1,2,12.9061126708984,4.99085757200678,40.8999994397163,16.6084455543932,2.4084157620366,100,-2.37109163316705E-5,,,,,,,,,,,,,,,,,,,,,300.004516601562,300.004547119141,37322.93359375,37452.65234375,49.751436877563,5.37305059557066,7.47020101547241,25,1,68,0,0,0.277938842773438,31.7693061828613,1,6,1,300.004547119141,0,300.004531860352,,,,,,,,,,,,,,,,,,,,,,,,,,,,,,,,,
,3865923452.23687,300.0029296875,30647.9873046875,0.0104518505252349,3.58331111799814E-6,1,2,12.9061126708984,4.99107714215693,40.8999994397163,13.6163847327568,1.97671326036359,100,-1.77991457833494E-5,,,,,,,,,,,,,,,,,,,,,300.002899169922,300.002960205078,30483.15234375,30812.822265625,49.7877826037072,5.37208296976088,7.54832887649536,26,1,0,0,1,0.277328491210938,29.8142719268799,1,6,1,300.002960205078,0,300.0029296875,,,,,,,,,,,,,,,,,,,,,,,,,,,,,,,,,
,3865923518.81658,300.002822875977,23999.3798828125,0.00822011607020237,4.67484085085753E-6,1,2,12.9061126708984,4.99093077259452,40.8999994397163,10.7088244857266,1.55237280083432,100,-1.56864029110062E-5,,,,,,,,,,,,,,,,,,,,,300.002746582031,300.002899169922,23844.677734375,24154.08203125,49.807323316688,5.37280729886949,7.66150426864624,24,1,68,0,0,0.274124145507813,31.2805480957031,1,6,1,300.002899169922,0,300.002822875977,,,,,,,,,,,,,,,,,,,,,,,,,,,,,,,,,
,3865923585.90667,300.001434326172,17300.046875,0.00598705316634998,4.38294056421668E-6,1,2,12.9061126708984,4.99103547682054,40.8999994397163,7.8001273868953,1.12923060957441,100,-1.25464165201323E-5,,,,,,,,,,,,,,,,,,,,,300.001190185547,300.001678466797,17205.240234375,17394.853515625,49.7627704910918,5.37296022576424,7.81257343292236,26,1,0,0,1,0.275802612304687,31.7693061828613,1,6,1,300.001678466797,0,300.001434326172,,,,,,,,,,,,,,,,,,,,,,,,,,,,,,,,,
,3865923652.43782,300.002700805664,10659.3120117187,0.00374829121927004,3.75893323591602E-6,1,2,12.9061126708984,4.990887202645,40.8999994397163,4.88374885781256,0.703153336583632,100,-1.07651300588674E-5,,,,,,,,,,,,,,,,,,,,,300.002593994141,300.002807617188,10564.38671875,10754.2373046875,49.7756673616591,5.37391963462295,7.97765207290649,26,1,0,0,1,0.278167724609375,31.7693061828613,1,6,1,300.002593994141,0,300.002700805664,,,,,,,,,,,,,,,,,,,,,,,,,,,,,,,,,
,3865923719.09702,300.000091552734,3994.47705078125,0.00149748729325498,3.84618458137503E-6,1,2,12.9061126708984,4.99069824819664,40.8999994397163,1.95341079009417,0.264579090576782,100,-1.68356032711714E-5,,,,,,,,,,,,,,,,,,,,,300.000061035156,300.000122070313,3879.48193359375,4109.47216796875,49.9452807503322,5.37464880455679,8.15919780731201,26,1,0,0,1,0.276718139648438,31.7693061828613,1,6,1,300.000122070313,0,300.000091552734,,,,,,,,,,,,,,,,,,,,,,,,,,,,,,,,,
,3865923797.44614,299.999496459961,-3837.26867675781,-0.00143366817345936,4.02949890413708E-6,1,2,12.9061126708984,4.99055680338785,40.8999994397163,-1.86641452762772,-0.278291216860281,100,-3.07771868436055E-6,,,,,,,,,,,,,,,,,,,,,299.999481201172,299.99951171875,-3927.16748046875,-3747.36987304687,49.7866101609283,5.37480502056261,8.20817852020264,26,1,0,0,1,0.275726318359375,31.7693061828613,1,6,1,299.999481201172,0,299.999496459961,,,,,,,,,,,,,,,,,,,,,,,,,,,,,,,,,
,3865923869.29206,299.999862670898,-11016.6635742187,-0.00389189262369619,4.00081679849441E-6,1,2,12.9061126708984,4.99046238999209,40.8999994397163,-5.06841785736073,-0.742444201228703,10,1.6250820108751E-6,,,,,,,,,,,,,,,,,,,,,299.999694824219,300.000030517578,-11177.0244140625,-10856.302734375,49.7408848925533,5.37555723470473,8.13784694671631,25,1,68,0,0,0.278167724609375,31.7693061828613,1,6,1,300.000030517578,0,299.999862670898,,,,,,,,,,,,,,,,,,,,,,,,,,,,,,,,,
,3865923968.8174,300.002059936523,-20972.19140625,-0.00722452818670873,3.7711084148969E-6,1,2,12.9061126708984,4.99018443238826,40.8999994397163,-9.40907957872521,-1.36924029415903,100,9.81530184134074E-6,,,,,,,,,,,,,,,,,,,,,300.001953125,300.002166748047,-21047.12890625,-20897.25390625,49.9374644651399,5.37600395283779,8.08878517150879,26,1,0,0,1,0.2789306640625,32.2580642700195,1,6,1,300.001953125,0,300.002059936523,,,,,,,,,,,,,,,,,,,,,,,,,,,,,,,,,
,3865924037.18439,300.001342773438,-27811.5849609375,-0.00952916306523797,4.27976639533594E-6,1,2,12.9061126708984,4.99007536537411,40.8999994397163,-12.4099080866901,-1.80802175310552,100,1.13741211325179E-5,,,,,,,,,,,,,,,,,,,,,300.001129150391,300.001556396484,-27901.69140625,-27721.478515625,49.7444022208899,5.37590320753409,8.05124282836914,26,1,0,0,1,0.279388427734375,31.7693061828613,1,6,1,300.001129150391,0,300.001342773438,,,,,,,,,,,,,,,,,,,,,,,,,,,,,,,,,
,3865924105.92632,300.000396728516,-34698.826171875,-0.011833052718515,4.09876993356602E-6,1,2,12.9061126708984,4.99023623379984,40.8999994397163,-15.4094970300391,-2.25534654139364,100,6.3727739211869E-6,,,,,,,,,,,,,,,,,,,,,300.000213623047,300.000579833984,-34814.015625,-34583.63671875,49.697504509736,5.37501967822228,8.02529621124268,26,1,0,0,1,0.276718139648438,31.7693061828613,1,6,1,300.000579833984,0,300.000396728516,,,,,,,,,,,,,,,,,,,,,,,,,,,,,,,,,
,3865924182.21401,300.000030517578,-42343.064453125,-0.0144098950441857,4.3821212659674E-6,1,2,12.9061126708984,4.98982395141966,40.8999994397163,-18.7632096572905,-2.74469543024048,100,8.89080833059192E-6,,,,,,,,,,,,,,,,,,,,,299.999969482422,300.000091552734,-42438.1953125,-42247.93359375,49.7530001346014,5.37660830041828,8.0114688873291,26,1,0,0,1,0.279388427734375,31.2805480957031,1,6,1,300.000091552734,0,300.000030517578,,,,,,,,,,,,,,,,,,,,,,,,,,,,,,,,,
,3865924258.77944,300.001251220703,-49960.40625,-0.0169738870300811,2.61779994898925E-6,1,2,12.9061126708984,4.98994592644425,40.8999994397163,-22.1023325670434,-3.23470525773764,100,9.29940781168447E-6,,,,,,,,,,,,,,,,,,,,,300.001159667969,300.001342773438,-49999.7109375,-49921.1015625,49.6885157817649,5.3758296253237,7.99092864990234,26,1,0,0,1,0.278396606445313,31.2805480957031,1,6,1,300.001342773438,0,300.001251220703,,,,,,,,,,,,,,,,,,,,,,,,,,,,,,,,,
,3865924329.44515,299.999771118164,-43493.595703125,-0.0148145576355408,4.39025870549725E-6,1,2,12.9061126708984,4.99005714339874,40.8999994397163,-19.2963261150154,-2.78834715325654,100,3.49536413972305E-5,,,,,,,,,,,,,,,,,,,,,299.999481201172,300.000061035156,-43573.41796875,-43413.7734375,49.7784030614764,5.37630956086254,7.98109531402588,25,1,68,0,0,0.278854370117187,31.2805480957031,1,6,1,300.000061035156,0,299.999771118164,,,,,,,,,,,,,,,,,,,,,,,,,,,,,,,,,
,3865924397.78421,300.000503540039,-36671.47265625,-0.0125156121939287,4.58843924521018E-6,1,2,12.9061126708984,4.98998084993119,40.8999994397163,-16.300250270995,-2.36439813014219,100,2.27697764281292E-5,,,,,,,,,,,,,,,,,,,,,300.000305175781,300.000701904297,-36766.60546875,-36576.33984375,49.7803571327745,5.37652604899056,7.97233819961548,24,1,68,0,0,0.27740478515625,31.7693061828613,1,6,1,300.000701904297,0,300.000503540039,,,,,,,,,,,,,,,,,,,,,,,,,,,,,,,,,
,3865924466.52564,300.000686645508,-29809.6396484375,-0.0102157463073571,4.4887998163583E-6,1,2,12.9061126708984,4.99004836907963,40.8999994397163,-13.3054808946143,-1.92785668337591,100,2.01960136992806E-5,,,,,,,,,,,,,,,,,,,,,300.000244140625,300.001129150391,-29929.4921875,-29689.787109375,49.7154819656783,5.37634928803853,7.9647707939148,26,1,0,0,1,0.277938842773438,31.2805480957031,1,6,1,300.000244140625,0,300.000686645508,,,,,,,,,,,,,,,,,,,,,,,,,,,,,,,,,
,3865924535.09684,300.000762939453,-22966.794921875,-0.00791387875950523,3.86210391393259E-6,1,2,12.9061126708984,4.98998732102328,40.8999994397163,-10.3073949362588,-1.49238517363882,100,1.64523061016795E-5,,,,,,,,,,,,,,,,,,,,,300.000732421875,300.000793457031,-23021.58203125,-22912.0078125,49.8272548439284,5.37766600700317,7.94757127761841,26,1,0,0,1,0.278701782226562,31.2805480957031,1,6,1,300.000732421875,0,300.000762939453,,,,,,,,,,,,,,,,,,,,,,,,,,,,,,,,,
,3865924607.53783,299.99934387207,-15734.4301757813,-0.0054744456603338,4.12171972212452E-6,1,2,12.9061126708984,4.98997589876949,40.8999994397163,-7.13038656264044,-1.0307042917683,100,1.26509377926345E-5,,,,,,,,,,,,,,,,,,,,,299.999237060547,299.999450683594,-15804.2529296875,-15664.607421875,49.7377583784764,5.37709061203803,7.93893384933472,26,1,0,0,1,0.2789306640625,31.7693061828613,1,6,1,299.999450683594,0,299.99934387207,,,,,,,,,,,,,,,,,,,,,,,,,,,,,,,,,
,3865924675.81901,300.000854492188,-8913.08837890625,-0.0031625792686307,3.78747627978615E-6,1,2,12.9061126708984,4.99003027046717,40.8999994397163,-4.12017603331189,-0.589325199565553,100,1.20088677807205E-5,,,,,,,,,,,,,,,,,,,,,300.000732421875,300.0009765625,-9003.03125,-8823.1455078125,49.8057600596495,5.3772380728502,7.94141578674316,26,1,0,0,1,0.278396606445313,31.7693061828613,1,6,1,300.0009765625,0,300.000854492188,,,,,,,,,,,,,,,,,,,,,,,,,,,,,,,,,
,3865924744.38343,300.00032043457,-2063.65521240234,-0.00082806557488632,4.17019391602925E-6,1,2,12.9061126708984,4.99010300870779,40.8999994397163,-1.08181987091194,-0.133870601675078,100,1.88398132581928E-5,,,,,,,,,,,,,,,,,,,,,300.000030517578,300.000610351562,-2168.52783203125,-1958.78259277344,49.8800147689764,5.37647103136241,7.92818450927734,26,1,0,0,1,0.2789306640625,32.7468223571777,1,6,1,300.000030517578,0,300.00032043457,,,,,,,,,,,,,,,,,,,,,,,,,,,,,,,,,
,3865924818.99993,299.999862670898,5393.70971679687,0.00196285662096799,3.98738694777585E-6,1,2,12.9061126708984,4.99011069429117,40.8999994397163,2.55508441446181,0.380496630810269,100,3.85412990169524E-6,,,,,,,,,,,,,,,,,,,,,299.999816894531,299.999908447266,5278.76513671875,5508.654296875,49.7088381232649,5.37594786643143,7.92676019668579,26,1,0,0,1,0.278167724609375,31.2805480957031,1,6,1,299.999816894531,0,299.999862670898,,,,,,,,,,,,,,,,,,,,,,,,,,,,,,,,,
,3865924889.32906,300.00114440918,12429.3901367188,0.00434993806176869,3.66268999876296E-6,1,2,12.9061126708984,4.9897709957164,40.8999994397163,5.66378473071443,0.829969607046214,10,-1.58066971469303E-6,,,,,,,,,,,,,,,,,,,,,300.000915527344,300.001373291016,12339.234375,12519.5458984375,49.9984314896399,5.37698415989766,7.91465091705322,26,1,0,0,1,0.280532836914062,31.2805480957031,1,6,1,300.001373291016,0,300.00114440918,,,,,,,,,,,,,,,,,,,,,,,,,,,,,,,,,
,3865924992.12462,300.000030517578,22711.7958984375,0.00782187244198371,3.85813838097064E-6,1,2,12.9061126708984,4.98998129442571,40.8999994397163,10.1867945009849,1.48013717560796,100,-1.23403634301145E-5,,,,,,,,,,,,,,,,,,,,,299.999969482422,300.000091552734,22611.84375,22811.748046875,49.7561266486783,5.37751510274668,7.91024875640869,26,1,0,0,1,0.278472900390625,31.7693061828613,1,6,1,300.000091552734,0,300.000030517578,,,,,,,,,,,,,,,,,,,,,,,,,,,,,,,,,
,3865925061.91835,300.000900268555,29699.6787109375,0.0101950072122687,4.2132677470524E-6,1,2,12.9061126708984,4.98990441693369,40.8999994397163,13.2759928389992,1.93706282808074,100,-1.00185937228437E-5,,,,,,,,,,,,,,,,,,,,,300.000610351562,300.001190185547,29539.22265625,29860.134765625,49.7393216355149,5.37690080247182,7.9069447517395,26,1,0,0,1,0.27740478515625,32.2580642700195,1,6,1,300.001190185547,0,300.000900268555,,,,,,,,,,,,,,,,,,,,,,,,,,,,,,,,,
,3865925131.14573,300.000274658203,36639.234375,0.0125023677133239,3.91991300368943E-6,1,2,12.9061126708984,4.99003074226037,40.8999994397163,16.2814210782057,2.37423691461862,100,-1.32931956297231E-5,,,,,,,,,,,,,,,,,,,,,300.000244140625,300.000305175781,36543.76953125,36734.69921875,49.7287696505053,5.3764192035933,7.90241003036499,26,1,0,0,1,0.277633666992187,31.2805480957031,1,6,1,300.000305175781,0,300.000274658203,,,,,,,,,,,,,,,,,,,,,,,,,,,,,,,,,
,3865925199.84709,299.999206542969,43523.21875,0.0148088939272605,4.09395719858638E-6,1,2,12.9061126708984,4.98993428637886,40.8999994397163,19.2838966869956,2.81703873152018,100,-1.20115256251055E-5,,,,,,,,,,,,,,,,,,,,,299.999053955078,299.999359130859,43457.98828125,43588.44921875,49.7557358344187,5.37662998665608,7.89739036560059,26,1,0,0,1,0.279922485351562,30.7917900085449,1,6,1,299.999053955078,0,299.999206542969,,,,,,,,,,,,,,,,,,,,,,,,,,,,,,,,,
,3865925266.64467,300.000198364258,50000.3828125,0.0169952107045541,2.01166097194889E-6,1,2,12.9061126708984,4.98996777785416,40.8999994397163,22.130381603782,3.23779034309154,100,-1.00779330321465E-5,,,,,,,,,,,,,,,,,,,,,300.000122070313,300.000274658203,50000.3515625,50000.4140625,49.7701959620245,5.37650889776296,7.89078617095947,26,1,0,0,1,0.27984619140625,31.7693061828613,1,4,1,300.000274658203,0,300.000198364258,,,,,,,,,,,,,,,,,,,,,,,,,,,,,,,,,